2019-06-07 08:10:27,485 INFO org.apache.hadoop.yarn.server.resourcemanager.ResourceManager: STARTUP_MSG: 
/************************************************************
STARTUP_MSG: Starting ResourceManager
STARTUP_MSG:   user = root
STARTUP_MSG:   host = master/172.17.0.2
STARTUP_MSG:   args = []
STARTUP_MSG:   version = 2.8.5
STARTUP_MSG:   build = https://git-wip-us.apache.org/repos/asf/hadoop.git -r 0b8464d75227fcee2c6e7f2410377b3d53d3d5f8; compiled by 'jdu' on 2018-09-10T03:32Z
STARTUP_MSG:   java = 1.8.0_191
************************************************************/
2019-06-07 08:10:27,485 INFO org.apache.hadoop.yarn.server.resourcemanager.ResourceManager: STARTUP_MSG: 
/************************************************************
STARTUP_MSG: Starting ResourceManager
STARTUP_MSG:   user = root
STARTUP_MSG:   host = master/172.17.0.2
STARTUP_MSG:   args = []
STARTUP_MSG:   version = 2.8.5
STARTUP_MSG:   build = https://git-wip-us.apache.org/repos/asf/hadoop.git -r 0b8464d75227fcee2c6e7f2410377b3d53d3d5f8; compiled by 'jdu' on 2018-09-10T03:32Z
STARTUP_MSG:   java = 1.8.0_191
************************************************************/
2019-06-07 08:10:27,494 INFO org.apache.hadoop.yarn.server.resourcemanager.ResourceManager: registered UNIX signal handlers for [TERM, HUP, INT]
2019-06-07 08:10:27,494 INFO org.apache.hadoop.yarn.server.resourcemanager.ResourceManager: registered UNIX signal handlers for [TERM, HUP, INT]
2019-06-07 08:10:27,804 INFO org.apache.hadoop.conf.Configuration: found resource core-site.xml at file:/hadoop-2.8.5/etc/hadoop/core-site.xml
2019-06-07 08:10:27,906 WARN org.apache.hadoop.conf.Configuration: core-site.xml:an attempt to override final parameter: fs.defaultFS;  Ignoring.
2019-06-07 08:10:27,924 INFO org.apache.hadoop.security.Groups: clearing userToGroupsMap cache
2019-06-07 08:10:27,979 INFO org.apache.hadoop.conf.Configuration: found resource yarn-site.xml at file:/hadoop-2.8.5/etc/hadoop/yarn-site.xml
2019-06-07 08:10:28,153 INFO org.apache.hadoop.yarn.event.AsyncDispatcher: Registering class org.apache.hadoop.yarn.server.resourcemanager.RMFatalEventType for class org.apache.hadoop.yarn.server.resourcemanager.ResourceManager$RMFatalEventDispatcher
2019-06-07 08:10:28,204 INFO org.apache.hadoop.yarn.server.resourcemanager.security.NMTokenSecretManagerInRM: NMTokenKeyRollingInterval: 86400000ms and NMTokenKeyActivationDelay: 900000ms
2019-06-07 08:10:28,204 INFO org.apache.hadoop.yarn.server.resourcemanager.security.NMTokenSecretManagerInRM: NMTokenKeyRollingInterval: 86400000ms and NMTokenKeyActivationDelay: 900000ms
2019-06-07 08:10:28,207 INFO org.apache.hadoop.yarn.server.resourcemanager.security.RMContainerTokenSecretManager: ContainerTokenKeyRollingInterval: 86400000ms and ContainerTokenKeyActivationDelay: 900000ms
2019-06-07 08:10:28,207 INFO org.apache.hadoop.yarn.server.resourcemanager.security.RMContainerTokenSecretManager: ContainerTokenKeyRollingInterval: 86400000ms and ContainerTokenKeyActivationDelay: 900000ms
2019-06-07 08:10:28,210 INFO org.apache.hadoop.yarn.server.resourcemanager.security.AMRMTokenSecretManager: AMRMTokenKeyRollingInterval: 86400000ms and AMRMTokenKeyActivationDelay: 900000 ms
2019-06-07 08:10:28,210 INFO org.apache.hadoop.yarn.server.resourcemanager.security.AMRMTokenSecretManager: AMRMTokenKeyRollingInterval: 86400000ms and AMRMTokenKeyActivationDelay: 900000 ms
2019-06-07 08:10:28,234 INFO org.apache.hadoop.yarn.event.AsyncDispatcher: Registering class org.apache.hadoop.yarn.server.resourcemanager.recovery.RMStateStoreEventType for class org.apache.hadoop.yarn.server.resourcemanager.recovery.RMStateStore$ForwardingEventHandler
2019-06-07 08:10:28,236 INFO org.apache.hadoop.yarn.event.AsyncDispatcher: Registering class org.apache.hadoop.yarn.server.resourcemanager.NodesListManagerEventType for class org.apache.hadoop.yarn.server.resourcemanager.NodesListManager
2019-06-07 08:10:28,236 INFO org.apache.hadoop.yarn.server.resourcemanager.ResourceManager: Using Scheduler: org.apache.hadoop.yarn.server.resourcemanager.scheduler.capacity.CapacityScheduler
2019-06-07 08:10:28,236 INFO org.apache.hadoop.yarn.server.resourcemanager.ResourceManager: Using Scheduler: org.apache.hadoop.yarn.server.resourcemanager.scheduler.capacity.CapacityScheduler
2019-06-07 08:10:28,256 INFO org.apache.hadoop.yarn.event.AsyncDispatcher: Registering class org.apache.hadoop.yarn.server.resourcemanager.scheduler.event.SchedulerEventType for class org.apache.hadoop.yarn.server.resourcemanager.ResourceManager$SchedulerEventDispatcher
2019-06-07 08:10:28,257 INFO org.apache.hadoop.yarn.event.AsyncDispatcher: Registering class org.apache.hadoop.yarn.server.resourcemanager.rmapp.RMAppEventType for class org.apache.hadoop.yarn.server.resourcemanager.ResourceManager$ApplicationEventDispatcher
2019-06-07 08:10:28,258 INFO org.apache.hadoop.yarn.event.AsyncDispatcher: Registering class org.apache.hadoop.yarn.server.resourcemanager.rmapp.attempt.RMAppAttemptEventType for class org.apache.hadoop.yarn.server.resourcemanager.ResourceManager$ApplicationAttemptEventDispatcher
2019-06-07 08:10:28,259 INFO org.apache.hadoop.yarn.event.AsyncDispatcher: Registering class org.apache.hadoop.yarn.server.resourcemanager.rmnode.RMNodeEventType for class org.apache.hadoop.yarn.server.resourcemanager.ResourceManager$NodeEventDispatcher
2019-06-07 08:10:28,293 INFO org.apache.hadoop.metrics2.impl.MetricsConfig: loaded properties from hadoop-metrics2.properties
2019-06-07 08:10:28,355 INFO org.apache.hadoop.metrics2.impl.MetricsSystemImpl: Scheduled Metric snapshot period at 10 second(s).
2019-06-07 08:10:28,355 INFO org.apache.hadoop.metrics2.impl.MetricsSystemImpl: ResourceManager metrics system started
2019-06-07 08:10:28,366 INFO org.apache.hadoop.yarn.event.AsyncDispatcher: Registering class org.apache.hadoop.yarn.server.resourcemanager.RMAppManagerEventType for class org.apache.hadoop.yarn.server.resourcemanager.RMAppManager
2019-06-07 08:10:28,383 INFO org.apache.hadoop.yarn.event.AsyncDispatcher: Registering class org.apache.hadoop.yarn.server.resourcemanager.amlauncher.AMLauncherEventType for class org.apache.hadoop.yarn.server.resourcemanager.amlauncher.ApplicationMasterLauncher
2019-06-07 08:10:28,385 INFO org.apache.hadoop.yarn.server.resourcemanager.RMNMInfo: Registered RMNMInfo MBean
2019-06-07 08:10:28,385 INFO org.apache.hadoop.yarn.server.resourcemanager.RMNMInfo: Registered RMNMInfo MBean
2019-06-07 08:10:28,389 INFO org.apache.hadoop.yarn.security.YarnAuthorizationProvider: org.apache.hadoop.yarn.security.ConfiguredYarnAuthorizer is instiantiated.
2019-06-07 08:10:28,391 INFO org.apache.hadoop.util.HostsFileReader: Refreshing hosts (include/exclude) list
2019-06-07 08:10:28,391 DEBUG org.apache.hadoop.yarn.server.resourcemanager.NodesListManager: hostsReader: in= out=
2019-06-07 08:10:28,391 DEBUG org.apache.hadoop.yarn.server.resourcemanager.NodesListManager: hostsReader: in= out=
2019-06-07 08:10:28,396 INFO org.apache.hadoop.conf.Configuration: found resource capacity-scheduler.xml at file:/hadoop-2.8.5/etc/hadoop/capacity-scheduler.xml
2019-06-07 08:10:28,432 DEBUG org.apache.hadoop.yarn.server.resourcemanager.scheduler.capacity.CapacitySchedulerConfiguration: CSConf - getQueues called for: queuePrefix=yarn.scheduler.capacity.root.
2019-06-07 08:10:28,432 DEBUG org.apache.hadoop.yarn.server.resourcemanager.scheduler.capacity.CapacitySchedulerConfiguration: CSConf - getQueues called for: queuePrefix=yarn.scheduler.capacity.root.
2019-06-07 08:10:28,432 DEBUG org.apache.hadoop.yarn.server.resourcemanager.scheduler.capacity.CapacitySchedulerConfiguration: CSConf - getQueues: queuePrefix=yarn.scheduler.capacity.root., queues=default
2019-06-07 08:10:28,432 DEBUG org.apache.hadoop.yarn.server.resourcemanager.scheduler.capacity.CapacitySchedulerConfiguration: CSConf - getQueues: queuePrefix=yarn.scheduler.capacity.root., queues=default
2019-06-07 08:10:28,454 DEBUG org.apache.hadoop.yarn.server.resourcemanager.scheduler.capacity.CapacitySchedulerConfiguration: CSConf - getCapacity: queuePrefix=yarn.scheduler.capacity.root., capacity=100.0
2019-06-07 08:10:28,454 DEBUG org.apache.hadoop.yarn.server.resourcemanager.scheduler.capacity.CapacitySchedulerConfiguration: CSConf - getCapacity: queuePrefix=yarn.scheduler.capacity.root., capacity=100.0
2019-06-07 08:10:28,456 DEBUG org.apache.hadoop.yarn.server.resourcemanager.scheduler.capacity.CapacitySchedulerConfiguration: CSConf - getCapacity: queuePrefix=yarn.scheduler.capacity.root., capacity=100.0
2019-06-07 08:10:28,456 DEBUG org.apache.hadoop.yarn.server.resourcemanager.scheduler.capacity.CapacitySchedulerConfiguration: CSConf - getCapacity: queuePrefix=yarn.scheduler.capacity.root., capacity=100.0
2019-06-07 08:10:28,457 DEBUG org.apache.hadoop.yarn.server.resourcemanager.scheduler.capacity.CapacitySchedulerConfiguration: max alloc mb per queue for root is -1
2019-06-07 08:10:28,457 DEBUG org.apache.hadoop.yarn.server.resourcemanager.scheduler.capacity.CapacitySchedulerConfiguration: max alloc mb per queue for root is -1
2019-06-07 08:10:28,457 DEBUG org.apache.hadoop.yarn.server.resourcemanager.scheduler.capacity.CapacitySchedulerConfiguration: max alloc vcores per queue for root is -1
2019-06-07 08:10:28,457 DEBUG org.apache.hadoop.yarn.server.resourcemanager.scheduler.capacity.CapacitySchedulerConfiguration: max alloc vcores per queue for root is -1
2019-06-07 08:10:28,457 INFO org.apache.hadoop.yarn.server.resourcemanager.scheduler.capacity.CapacitySchedulerConfiguration: max alloc mb per queue for root is undefined
2019-06-07 08:10:28,457 INFO org.apache.hadoop.yarn.server.resourcemanager.scheduler.capacity.CapacitySchedulerConfiguration: max alloc mb per queue for root is undefined
2019-06-07 08:10:28,457 INFO org.apache.hadoop.yarn.server.resourcemanager.scheduler.capacity.CapacitySchedulerConfiguration: max alloc vcore per queue for root is undefined
2019-06-07 08:10:28,457 INFO org.apache.hadoop.yarn.server.resourcemanager.scheduler.capacity.CapacitySchedulerConfiguration: max alloc vcore per queue for root is undefined
2019-06-07 08:10:28,464 INFO org.apache.hadoop.yarn.server.resourcemanager.scheduler.capacity.ParentQueue: root, capacity=1.0, asboluteCapacity=1.0, maxCapacity=1.0, asboluteMaxCapacity=1.0, state=RUNNING, acls=ADMINISTER_QUEUE:*SUBMIT_APP:*, labels=*,, offswitchPerHeartbeatLimit = 1, reservationsContinueLooking=true
2019-06-07 08:10:28,464 INFO org.apache.hadoop.yarn.server.resourcemanager.scheduler.capacity.ParentQueue: root, capacity=1.0, asboluteCapacity=1.0, maxCapacity=1.0, asboluteMaxCapacity=1.0, state=RUNNING, acls=ADMINISTER_QUEUE:*SUBMIT_APP:*, labels=*,, offswitchPerHeartbeatLimit = 1, reservationsContinueLooking=true
2019-06-07 08:10:28,464 INFO org.apache.hadoop.yarn.server.resourcemanager.scheduler.capacity.ParentQueue: Initialized parent-queue root name=root, fullname=root
2019-06-07 08:10:28,464 INFO org.apache.hadoop.yarn.server.resourcemanager.scheduler.capacity.ParentQueue: Initialized parent-queue root name=root, fullname=root
2019-06-07 08:10:28,464 DEBUG org.apache.hadoop.yarn.server.resourcemanager.scheduler.capacity.CapacitySchedulerConfiguration: CSConf - getQueues called for: queuePrefix=yarn.scheduler.capacity.root.default.
2019-06-07 08:10:28,464 DEBUG org.apache.hadoop.yarn.server.resourcemanager.scheduler.capacity.CapacitySchedulerConfiguration: CSConf - getQueues called for: queuePrefix=yarn.scheduler.capacity.root.default.
2019-06-07 08:10:28,464 DEBUG org.apache.hadoop.yarn.server.resourcemanager.scheduler.capacity.CapacitySchedulerConfiguration: CSConf - getQueues: queuePrefix=yarn.scheduler.capacity.root.default., queues=
2019-06-07 08:10:28,464 DEBUG org.apache.hadoop.yarn.server.resourcemanager.scheduler.capacity.CapacitySchedulerConfiguration: CSConf - getQueues: queuePrefix=yarn.scheduler.capacity.root.default., queues=
2019-06-07 08:10:28,475 DEBUG org.apache.hadoop.yarn.server.resourcemanager.scheduler.capacity.LeafQueue: LeafQueue: name=default, fullname=root.default
2019-06-07 08:10:28,475 DEBUG org.apache.hadoop.yarn.server.resourcemanager.scheduler.capacity.LeafQueue: LeafQueue: name=default, fullname=root.default
2019-06-07 08:10:28,476 DEBUG org.apache.hadoop.yarn.server.resourcemanager.scheduler.capacity.CapacitySchedulerConfiguration: CSConf - getCapacity: queuePrefix=yarn.scheduler.capacity.root.default., capacity=100.0
2019-06-07 08:10:28,476 DEBUG org.apache.hadoop.yarn.server.resourcemanager.scheduler.capacity.CapacitySchedulerConfiguration: CSConf - getCapacity: queuePrefix=yarn.scheduler.capacity.root.default., capacity=100.0
2019-06-07 08:10:28,476 DEBUG org.apache.hadoop.yarn.server.resourcemanager.scheduler.capacity.CapacitySchedulerConfiguration: max alloc mb per queue for root.default is -1
2019-06-07 08:10:28,476 DEBUG org.apache.hadoop.yarn.server.resourcemanager.scheduler.capacity.CapacitySchedulerConfiguration: max alloc mb per queue for root.default is -1
2019-06-07 08:10:28,477 DEBUG org.apache.hadoop.yarn.server.resourcemanager.scheduler.capacity.CapacitySchedulerConfiguration: max alloc vcores per queue for root.default is -1
2019-06-07 08:10:28,477 DEBUG org.apache.hadoop.yarn.server.resourcemanager.scheduler.capacity.CapacitySchedulerConfiguration: max alloc vcores per queue for root.default is -1
2019-06-07 08:10:28,477 INFO org.apache.hadoop.yarn.server.resourcemanager.scheduler.capacity.CapacitySchedulerConfiguration: max alloc mb per queue for root.default is undefined
2019-06-07 08:10:28,477 INFO org.apache.hadoop.yarn.server.resourcemanager.scheduler.capacity.CapacitySchedulerConfiguration: max alloc mb per queue for root.default is undefined
2019-06-07 08:10:28,477 INFO org.apache.hadoop.yarn.server.resourcemanager.scheduler.capacity.CapacitySchedulerConfiguration: max alloc vcore per queue for root.default is undefined
2019-06-07 08:10:28,477 INFO org.apache.hadoop.yarn.server.resourcemanager.scheduler.capacity.CapacitySchedulerConfiguration: max alloc vcore per queue for root.default is undefined
2019-06-07 08:10:28,481 INFO org.apache.hadoop.yarn.server.resourcemanager.scheduler.capacity.LeafQueue: Initializing default
capacity = 1.0 [= (float) configuredCapacity / 100 ]
asboluteCapacity = 1.0 [= parentAbsoluteCapacity * capacity ]
maxCapacity = 1.0 [= configuredMaxCapacity ]
absoluteMaxCapacity = 1.0 [= 1.0 maximumCapacity undefined, (parentAbsoluteMaxCapacity * maximumCapacity) / 100 otherwise ]
userLimit = 100 [= configuredUserLimit ]
userLimitFactor = 1.0 [= configuredUserLimitFactor ]
maxApplications = 10000 [= configuredMaximumSystemApplicationsPerQueue or (int)(configuredMaximumSystemApplications * absoluteCapacity)]
maxApplicationsPerUser = 10000 [= (int)(maxApplications * (userLimit / 100.0f) * userLimitFactor) ]
usedCapacity = 0.0 [= usedResourcesMemory / (clusterResourceMemory * absoluteCapacity)]
absoluteUsedCapacity = 0.0 [= usedResourcesMemory / clusterResourceMemory]
maxAMResourcePerQueuePercent = 0.1 [= configuredMaximumAMResourcePercent ]
minimumAllocationFactor = 0.875 [= (float)(maximumAllocationMemory - minimumAllocationMemory) / maximumAllocationMemory ]
maximumAllocation = <memory:8192, vCores:4> [= configuredMaxAllocation ]
numContainers = 0 [= currentNumContainers ]
state = RUNNING [= configuredState ]
acls = ADMINISTER_QUEUE:*SUBMIT_APP:* [= configuredAcls ]
nodeLocalityDelay = 40
labels=*,
reservationsContinueLooking = true
preemptionDisabled = true
defaultAppPriorityPerQueue = 0
2019-06-07 08:10:28,481 INFO org.apache.hadoop.yarn.server.resourcemanager.scheduler.capacity.LeafQueue: Initializing default
capacity = 1.0 [= (float) configuredCapacity / 100 ]
asboluteCapacity = 1.0 [= parentAbsoluteCapacity * capacity ]
maxCapacity = 1.0 [= configuredMaxCapacity ]
absoluteMaxCapacity = 1.0 [= 1.0 maximumCapacity undefined, (parentAbsoluteMaxCapacity * maximumCapacity) / 100 otherwise ]
userLimit = 100 [= configuredUserLimit ]
userLimitFactor = 1.0 [= configuredUserLimitFactor ]
maxApplications = 10000 [= configuredMaximumSystemApplicationsPerQueue or (int)(configuredMaximumSystemApplications * absoluteCapacity)]
maxApplicationsPerUser = 10000 [= (int)(maxApplications * (userLimit / 100.0f) * userLimitFactor) ]
usedCapacity = 0.0 [= usedResourcesMemory / (clusterResourceMemory * absoluteCapacity)]
absoluteUsedCapacity = 0.0 [= usedResourcesMemory / clusterResourceMemory]
maxAMResourcePerQueuePercent = 0.1 [= configuredMaximumAMResourcePercent ]
minimumAllocationFactor = 0.875 [= (float)(maximumAllocationMemory - minimumAllocationMemory) / maximumAllocationMemory ]
maximumAllocation = <memory:8192, vCores:4> [= configuredMaxAllocation ]
numContainers = 0 [= currentNumContainers ]
state = RUNNING [= configuredState ]
acls = ADMINISTER_QUEUE:*SUBMIT_APP:* [= configuredAcls ]
nodeLocalityDelay = 40
labels=*,
reservationsContinueLooking = true
preemptionDisabled = true
defaultAppPriorityPerQueue = 0
2019-06-07 08:10:28,482 INFO org.apache.hadoop.yarn.server.resourcemanager.scheduler.capacity.CapacityScheduler: Initialized queue: default: capacity=1.0, absoluteCapacity=1.0, usedResources=<memory:0, vCores:0>, usedCapacity=0.0, absoluteUsedCapacity=0.0, numApps=0, numContainers=0
2019-06-07 08:10:28,482 INFO org.apache.hadoop.yarn.server.resourcemanager.scheduler.capacity.CapacityScheduler: Initialized queue: default: capacity=1.0, absoluteCapacity=1.0, usedResources=<memory:0, vCores:0>, usedCapacity=0.0, absoluteUsedCapacity=0.0, numApps=0, numContainers=0
2019-06-07 08:10:28,483 DEBUG org.apache.hadoop.yarn.server.resourcemanager.scheduler.capacity.ParentQueue: setChildQueues: root.defaultusedCapacity=(0.0),  label=(*)
2019-06-07 08:10:28,483 DEBUG org.apache.hadoop.yarn.server.resourcemanager.scheduler.capacity.ParentQueue: setChildQueues: root.defaultusedCapacity=(0.0),  label=(*)
2019-06-07 08:10:28,483 INFO org.apache.hadoop.yarn.server.resourcemanager.scheduler.capacity.CapacityScheduler: Initialized queue: root: numChildQueue= 1, capacity=1.0, absoluteCapacity=1.0, usedResources=<memory:0, vCores:0>usedCapacity=0.0, numApps=0, numContainers=0
2019-06-07 08:10:28,483 INFO org.apache.hadoop.yarn.server.resourcemanager.scheduler.capacity.CapacityScheduler: Initialized queue: root: numChildQueue= 1, capacity=1.0, absoluteCapacity=1.0, usedResources=<memory:0, vCores:0>usedCapacity=0.0, numApps=0, numContainers=0
2019-06-07 08:10:28,484 INFO org.apache.hadoop.yarn.server.resourcemanager.scheduler.capacity.CapacityScheduler: Initialized root queue root: numChildQueue= 1, capacity=1.0, absoluteCapacity=1.0, usedResources=<memory:0, vCores:0>usedCapacity=0.0, numApps=0, numContainers=0
2019-06-07 08:10:28,484 INFO org.apache.hadoop.yarn.server.resourcemanager.scheduler.capacity.CapacityScheduler: Initialized root queue root: numChildQueue= 1, capacity=1.0, absoluteCapacity=1.0, usedResources=<memory:0, vCores:0>usedCapacity=0.0, numApps=0, numContainers=0
2019-06-07 08:10:28,484 INFO org.apache.hadoop.yarn.server.resourcemanager.scheduler.capacity.CapacityScheduler: Initialized queue mappings, override: false
2019-06-07 08:10:28,484 INFO org.apache.hadoop.yarn.server.resourcemanager.scheduler.capacity.CapacityScheduler: Initialized queue mappings, override: false
2019-06-07 08:10:28,485 INFO org.apache.hadoop.yarn.server.resourcemanager.scheduler.capacity.CapacityScheduler: Initialized CapacityScheduler with calculator=class org.apache.hadoop.yarn.util.resource.DefaultResourceCalculator, minimumAllocation=<<memory:1024, vCores:1>>, maximumAllocation=<<memory:8192, vCores:4>>, asynchronousScheduling=false, asyncScheduleInterval=5ms
2019-06-07 08:10:28,485 INFO org.apache.hadoop.yarn.server.resourcemanager.scheduler.capacity.CapacityScheduler: Initialized CapacityScheduler with calculator=class org.apache.hadoop.yarn.util.resource.DefaultResourceCalculator, minimumAllocation=<<memory:1024, vCores:1>>, maximumAllocation=<<memory:8192, vCores:4>>, asynchronousScheduling=false, asyncScheduleInterval=5ms
2019-06-07 08:10:28,490 INFO org.apache.hadoop.conf.Configuration: dynamic-resources.xml not found
2019-06-07 08:10:28,499 INFO org.apache.hadoop.yarn.server.resourcemanager.metrics.SystemMetricsPublisher: YARN system metrics publishing service is not enabled
2019-06-07 08:10:28,499 INFO org.apache.hadoop.yarn.server.resourcemanager.metrics.SystemMetricsPublisher: YARN system metrics publishing service is not enabled
2019-06-07 08:10:28,499 INFO org.apache.hadoop.yarn.server.resourcemanager.ResourceManager: Transitioning to active state
2019-06-07 08:10:28,499 INFO org.apache.hadoop.yarn.server.resourcemanager.ResourceManager: Transitioning to active state
2019-06-07 08:10:28,552 INFO org.apache.hadoop.util.JvmPauseMonitor: Starting JVM pause monitor
2019-06-07 08:10:28,554 DEBUG org.apache.hadoop.yarn.server.resourcemanager.recovery.RMStateStore: Processing event of type UPDATE_AMRM_TOKEN
2019-06-07 08:10:28,554 DEBUG org.apache.hadoop.yarn.server.resourcemanager.recovery.RMStateStore: Processing event of type UPDATE_AMRM_TOKEN
2019-06-07 08:10:28,554 INFO org.apache.hadoop.yarn.server.resourcemanager.recovery.RMStateStore: Updating AMRMToken
2019-06-07 08:10:28,554 INFO org.apache.hadoop.yarn.server.resourcemanager.recovery.RMStateStore: Updating AMRMToken
2019-06-07 08:10:28,555 INFO org.apache.hadoop.yarn.server.resourcemanager.security.RMContainerTokenSecretManager: Rolling master-key for container-tokens
2019-06-07 08:10:28,555 INFO org.apache.hadoop.yarn.server.resourcemanager.security.RMContainerTokenSecretManager: Rolling master-key for container-tokens
2019-06-07 08:10:28,555 INFO org.apache.hadoop.yarn.server.resourcemanager.security.NMTokenSecretManagerInRM: Rolling master-key for nm-tokens
2019-06-07 08:10:28,555 INFO org.apache.hadoop.yarn.server.resourcemanager.security.NMTokenSecretManagerInRM: Rolling master-key for nm-tokens
2019-06-07 08:10:28,555 INFO org.apache.hadoop.security.token.delegation.AbstractDelegationTokenSecretManager: Updating the current master key for generating delegation tokens
2019-06-07 08:10:28,555 INFO org.apache.hadoop.yarn.server.resourcemanager.security.RMDelegationTokenSecretManager: storing master key with keyID 1
2019-06-07 08:10:28,555 INFO org.apache.hadoop.yarn.server.resourcemanager.security.RMDelegationTokenSecretManager: storing master key with keyID 1
2019-06-07 08:10:28,556 DEBUG org.apache.hadoop.yarn.server.resourcemanager.recovery.RMStateStore: Processing event of type STORE_MASTERKEY
2019-06-07 08:10:28,556 DEBUG org.apache.hadoop.yarn.server.resourcemanager.recovery.RMStateStore: Processing event of type STORE_MASTERKEY
2019-06-07 08:10:28,563 INFO org.apache.hadoop.yarn.server.resourcemanager.recovery.RMStateStore: Storing RMDTMasterKey.
2019-06-07 08:10:28,563 INFO org.apache.hadoop.yarn.server.resourcemanager.recovery.RMStateStore: Storing RMDTMasterKey.
2019-06-07 08:10:28,565 INFO org.apache.hadoop.security.token.delegation.AbstractDelegationTokenSecretManager: Starting expired delegation token remover thread, tokenRemoverScanInterval=60 min(s)
2019-06-07 08:10:28,565 INFO org.apache.hadoop.security.token.delegation.AbstractDelegationTokenSecretManager: Updating the current master key for generating delegation tokens
2019-06-07 08:10:28,565 INFO org.apache.hadoop.yarn.server.resourcemanager.security.RMDelegationTokenSecretManager: storing master key with keyID 2
2019-06-07 08:10:28,565 INFO org.apache.hadoop.yarn.server.resourcemanager.security.RMDelegationTokenSecretManager: storing master key with keyID 2
2019-06-07 08:10:28,565 DEBUG org.apache.hadoop.yarn.server.resourcemanager.recovery.RMStateStore: Processing event of type STORE_MASTERKEY
2019-06-07 08:10:28,565 DEBUG org.apache.hadoop.yarn.server.resourcemanager.recovery.RMStateStore: Processing event of type STORE_MASTERKEY
2019-06-07 08:10:28,565 INFO org.apache.hadoop.yarn.server.resourcemanager.recovery.RMStateStore: Storing RMDTMasterKey.
2019-06-07 08:10:28,565 INFO org.apache.hadoop.yarn.server.resourcemanager.recovery.RMStateStore: Storing RMDTMasterKey.
2019-06-07 08:10:28,566 INFO org.apache.hadoop.yarn.event.AsyncDispatcher: Registering class org.apache.hadoop.yarn.nodelabels.event.NodeLabelsStoreEventType for class org.apache.hadoop.yarn.nodelabels.CommonNodeLabelsManager$ForwardingEventHandler
2019-06-07 08:10:28,620 INFO org.apache.hadoop.ipc.CallQueueManager: Using callQueue: class java.util.concurrent.LinkedBlockingQueue queueCapacity: 5000 scheduler: class org.apache.hadoop.ipc.DefaultRpcScheduler
2019-06-07 08:10:28,647 INFO org.apache.hadoop.ipc.Server: Starting Socket Reader #1 for port 8031
2019-06-07 08:10:29,039 INFO org.apache.hadoop.yarn.factories.impl.pb.RpcServerFactoryPBImpl: Adding protocol org.apache.hadoop.yarn.server.api.ResourceTrackerPB to the server
2019-06-07 08:10:29,047 INFO org.apache.hadoop.ipc.Server: IPC Server Responder: starting
2019-06-07 08:10:29,048 INFO org.apache.hadoop.ipc.Server: IPC Server listener on 8031: starting
2019-06-07 08:10:29,076 INFO org.apache.hadoop.ipc.CallQueueManager: Using callQueue: class java.util.concurrent.LinkedBlockingQueue queueCapacity: 5000 scheduler: class org.apache.hadoop.ipc.DefaultRpcScheduler
2019-06-07 08:10:29,145 INFO org.apache.hadoop.ipc.Server: Starting Socket Reader #1 for port 8030
2019-06-07 08:10:29,207 INFO org.apache.hadoop.yarn.factories.impl.pb.RpcServerFactoryPBImpl: Adding protocol org.apache.hadoop.yarn.api.ApplicationMasterProtocolPB to the server
2019-06-07 08:10:29,219 INFO org.apache.hadoop.ipc.Server: IPC Server Responder: starting
2019-06-07 08:10:29,220 INFO org.apache.hadoop.ipc.Server: IPC Server listener on 8030: starting
2019-06-07 08:10:29,623 INFO org.apache.hadoop.ipc.CallQueueManager: Using callQueue: class java.util.concurrent.LinkedBlockingQueue queueCapacity: 5000 scheduler: class org.apache.hadoop.ipc.DefaultRpcScheduler
2019-06-07 08:10:29,623 INFO org.apache.hadoop.ipc.Server: Starting Socket Reader #1 for port 8032
2019-06-07 08:10:29,633 INFO org.apache.hadoop.yarn.factories.impl.pb.RpcServerFactoryPBImpl: Adding protocol org.apache.hadoop.yarn.api.ApplicationClientProtocolPB to the server
2019-06-07 08:10:29,633 INFO org.apache.hadoop.ipc.Server: IPC Server Responder: starting
2019-06-07 08:10:29,634 INFO org.apache.hadoop.ipc.Server: IPC Server listener on 8032: starting
2019-06-07 08:10:29,644 INFO org.apache.hadoop.yarn.server.resourcemanager.ResourceManager: Transitioned to active state
2019-06-07 08:10:29,644 INFO org.apache.hadoop.yarn.server.resourcemanager.ResourceManager: Transitioned to active state
2019-06-07 08:10:29,911 INFO org.mortbay.log: Logging to org.slf4j.impl.Log4jLoggerAdapter(org.mortbay.log) via org.mortbay.log.Slf4jLog
2019-06-07 08:10:29,948 INFO org.apache.hadoop.security.authentication.server.AuthenticationFilter: Unable to initialize FileSignerSecretProvider, falling back to use random secrets.
2019-06-07 08:10:29,982 INFO org.apache.hadoop.http.HttpRequestLog: Http request log for http.requests.resourcemanager is not defined
2019-06-07 08:10:30,036 INFO org.apache.hadoop.http.HttpServer2: Added global filter 'safety' (class=org.apache.hadoop.http.HttpServer2$QuotingInputFilter)
2019-06-07 08:10:30,040 INFO org.apache.hadoop.http.HttpServer2: Added filter RMAuthenticationFilter (class=org.apache.hadoop.yarn.server.security.http.RMAuthenticationFilter) to context cluster
2019-06-07 08:10:30,040 INFO org.apache.hadoop.http.HttpServer2: Added filter RMAuthenticationFilter (class=org.apache.hadoop.yarn.server.security.http.RMAuthenticationFilter) to context static
2019-06-07 08:10:30,040 INFO org.apache.hadoop.http.HttpServer2: Added filter RMAuthenticationFilter (class=org.apache.hadoop.yarn.server.security.http.RMAuthenticationFilter) to context logs
2019-06-07 08:10:30,040 INFO org.apache.hadoop.http.HttpServer2: Added filter static_user_filter (class=org.apache.hadoop.http.lib.StaticUserWebFilter$StaticUserFilter) to context cluster
2019-06-07 08:10:30,043 INFO org.apache.hadoop.http.HttpServer2: Added filter static_user_filter (class=org.apache.hadoop.http.lib.StaticUserWebFilter$StaticUserFilter) to context static
2019-06-07 08:10:30,044 INFO org.apache.hadoop.http.HttpServer2: Added filter static_user_filter (class=org.apache.hadoop.http.lib.StaticUserWebFilter$StaticUserFilter) to context logs
2019-06-07 08:10:30,051 INFO org.apache.hadoop.http.HttpServer2: adding path spec: /cluster/*
2019-06-07 08:10:30,056 INFO org.apache.hadoop.http.HttpServer2: adding path spec: /ws/*
2019-06-07 08:10:32,256 INFO org.apache.hadoop.yarn.webapp.WebApps: Registered webapp guice modules
2019-06-07 08:10:32,258 INFO org.apache.hadoop.http.HttpServer2: Jetty bound to port 8088
2019-06-07 08:10:32,271 INFO org.mortbay.log: jetty-6.1.26
2019-06-07 08:10:32,339 INFO org.mortbay.log: Extract jar:file:/hadoop-2.8.5/share/hadoop/yarn/hadoop-yarn-common-2.8.5.jar!/webapps/cluster to /tmp/Jetty_master_8088_cluster____i4ls4w/webapp
2019-06-07 08:10:33,136 INFO org.apache.hadoop.security.token.delegation.AbstractDelegationTokenSecretManager: Updating the current master key for generating delegation tokens
2019-06-07 08:10:33,161 INFO org.apache.hadoop.security.token.delegation.AbstractDelegationTokenSecretManager: Starting expired delegation token remover thread, tokenRemoverScanInterval=60 min(s)
2019-06-07 08:10:33,167 INFO org.apache.hadoop.security.token.delegation.AbstractDelegationTokenSecretManager: Updating the current master key for generating delegation tokens
2019-06-07 08:10:36,371 INFO org.apache.hadoop.yarn.server.resourcemanager.ResourceTrackerService: NodeManager from node slave2(cmPort: 40331 httpPort: 8042) registered with capability: <memory:4096, vCores:1>, assigned nodeId slave2:40331
2019-06-07 08:10:36,371 INFO org.apache.hadoop.yarn.server.resourcemanager.ResourceTrackerService: NodeManager from node slave2(cmPort: 40331 httpPort: 8042) registered with capability: <memory:4096, vCores:1>, assigned nodeId slave2:40331
2019-06-07 08:10:36,510 INFO org.apache.hadoop.yarn.server.resourcemanager.ResourceTrackerService: NodeManager from node slave1(cmPort: 41069 httpPort: 8042) registered with capability: <memory:4096, vCores:1>, assigned nodeId slave1:41069
2019-06-07 08:10:36,510 INFO org.apache.hadoop.yarn.server.resourcemanager.ResourceTrackerService: NodeManager from node slave1(cmPort: 41069 httpPort: 8042) registered with capability: <memory:4096, vCores:1>, assigned nodeId slave1:41069
2019-06-07 08:10:36,836 INFO org.mortbay.log: Started HttpServer2$SelectChannelConnectorWithSafeStartup@master:8088
2019-06-07 08:10:36,836 INFO org.apache.hadoop.yarn.webapp.WebApps: Web app cluster started at 8088
2019-06-07 08:10:36,862 DEBUG org.apache.hadoop.yarn.server.resourcemanager.rmnode.RMNodeImpl: Processing slave2:40331 of type STARTED
2019-06-07 08:10:36,862 DEBUG org.apache.hadoop.yarn.server.resourcemanager.rmnode.RMNodeImpl: Processing slave2:40331 of type STARTED
2019-06-07 08:10:36,882 INFO org.apache.hadoop.yarn.server.resourcemanager.rmnode.RMNodeImpl: slave2:40331 Node Transitioned from NEW to RUNNING
2019-06-07 08:10:36,882 INFO org.apache.hadoop.yarn.server.resourcemanager.rmnode.RMNodeImpl: slave2:40331 Node Transitioned from NEW to RUNNING
2019-06-07 08:10:36,882 DEBUG org.apache.hadoop.yarn.server.resourcemanager.rmnode.RMNodeImpl: Processing slave1:41069 of type STARTED
2019-06-07 08:10:36,882 DEBUG org.apache.hadoop.yarn.server.resourcemanager.rmnode.RMNodeImpl: Processing slave1:41069 of type STARTED
2019-06-07 08:10:36,883 INFO org.apache.hadoop.yarn.server.resourcemanager.rmnode.RMNodeImpl: slave1:41069 Node Transitioned from NEW to RUNNING
2019-06-07 08:10:36,883 INFO org.apache.hadoop.yarn.server.resourcemanager.rmnode.RMNodeImpl: slave1:41069 Node Transitioned from NEW to RUNNING
2019-06-07 08:10:36,883 DEBUG org.apache.hadoop.yarn.server.resourcemanager.rmnode.RMNodeImpl: Processing slave2:40331 of type STATUS_UPDATE
2019-06-07 08:10:36,883 DEBUG org.apache.hadoop.yarn.server.resourcemanager.rmnode.RMNodeImpl: Processing slave2:40331 of type STATUS_UPDATE
2019-06-07 08:10:36,886 DEBUG org.apache.hadoop.yarn.server.resourcemanager.rmnode.RMNodeImpl: Processing slave1:41069 of type STATUS_UPDATE
2019-06-07 08:10:36,886 DEBUG org.apache.hadoop.yarn.server.resourcemanager.rmnode.RMNodeImpl: Processing slave1:41069 of type STATUS_UPDATE
2019-06-07 08:10:36,890 INFO org.apache.hadoop.yarn.server.resourcemanager.scheduler.capacity.CapacityScheduler: Added node slave2:40331 clusterResource: <memory:4096, vCores:1>
2019-06-07 08:10:36,890 INFO org.apache.hadoop.yarn.server.resourcemanager.scheduler.capacity.CapacityScheduler: Added node slave2:40331 clusterResource: <memory:4096, vCores:1>
2019-06-07 08:10:36,891 DEBUG org.apache.hadoop.yarn.server.resourcemanager.NodesListManager: slave2:40331 reported usable
2019-06-07 08:10:36,891 DEBUG org.apache.hadoop.yarn.server.resourcemanager.NodesListManager: slave2:40331 reported usable
2019-06-07 08:10:36,896 INFO org.apache.hadoop.yarn.server.resourcemanager.scheduler.capacity.CapacityScheduler: Added node slave1:41069 clusterResource: <memory:8192, vCores:2>
2019-06-07 08:10:36,896 INFO org.apache.hadoop.yarn.server.resourcemanager.scheduler.capacity.CapacityScheduler: Added node slave1:41069 clusterResource: <memory:8192, vCores:2>
2019-06-07 08:10:36,897 DEBUG org.apache.hadoop.yarn.server.resourcemanager.NodesListManager: slave1:41069 reported usable
2019-06-07 08:10:36,897 DEBUG org.apache.hadoop.yarn.server.resourcemanager.NodesListManager: slave1:41069 reported usable
2019-06-07 08:10:36,897 DEBUG org.apache.hadoop.yarn.server.resourcemanager.scheduler.capacity.CapacityScheduler: nodeUpdate: slave2:40331 clusterResources: <memory:8192, vCores:2>
2019-06-07 08:10:36,897 DEBUG org.apache.hadoop.yarn.server.resourcemanager.scheduler.capacity.CapacityScheduler: nodeUpdate: slave2:40331 clusterResources: <memory:8192, vCores:2>
2019-06-07 08:10:36,903 DEBUG org.apache.hadoop.yarn.server.resourcemanager.scheduler.capacity.CapacityScheduler: Node being looked for scheduling slave2:40331 availableResource: <memory:4096, vCores:1>
2019-06-07 08:10:36,903 DEBUG org.apache.hadoop.yarn.server.resourcemanager.scheduler.capacity.CapacityScheduler: Node being looked for scheduling slave2:40331 availableResource: <memory:4096, vCores:1>
2019-06-07 08:10:36,905 DEBUG org.apache.hadoop.yarn.server.resourcemanager.scheduler.capacity.CapacityScheduler: Trying to schedule on node: slave2, available: <memory:4096, vCores:1>
2019-06-07 08:10:36,905 DEBUG org.apache.hadoop.yarn.server.resourcemanager.scheduler.capacity.CapacityScheduler: Trying to schedule on node: slave2, available: <memory:4096, vCores:1>
2019-06-07 08:10:36,906 DEBUG org.apache.hadoop.yarn.server.resourcemanager.scheduler.capacity.ParentQueue: Skip this queue=root, because it doesn't need more resource, schedulingMode=RESPECT_PARTITION_EXCLUSIVITY node-partition=
2019-06-07 08:10:36,906 DEBUG org.apache.hadoop.yarn.server.resourcemanager.scheduler.capacity.ParentQueue: Skip this queue=root, because it doesn't need more resource, schedulingMode=RESPECT_PARTITION_EXCLUSIVITY node-partition=
2019-06-07 08:10:36,906 DEBUG org.apache.hadoop.yarn.server.resourcemanager.scheduler.capacity.CapacityScheduler: nodeUpdate: slave1:41069 clusterResources: <memory:8192, vCores:2>
2019-06-07 08:10:36,906 DEBUG org.apache.hadoop.yarn.server.resourcemanager.scheduler.capacity.CapacityScheduler: nodeUpdate: slave1:41069 clusterResources: <memory:8192, vCores:2>
2019-06-07 08:10:36,910 DEBUG org.apache.hadoop.yarn.server.resourcemanager.scheduler.capacity.CapacityScheduler: Node being looked for scheduling slave1:41069 availableResource: <memory:4096, vCores:1>
2019-06-07 08:10:36,910 DEBUG org.apache.hadoop.yarn.server.resourcemanager.scheduler.capacity.CapacityScheduler: Node being looked for scheduling slave1:41069 availableResource: <memory:4096, vCores:1>
2019-06-07 08:10:36,910 DEBUG org.apache.hadoop.yarn.server.resourcemanager.scheduler.capacity.CapacityScheduler: Trying to schedule on node: slave1, available: <memory:4096, vCores:1>
2019-06-07 08:10:36,910 DEBUG org.apache.hadoop.yarn.server.resourcemanager.scheduler.capacity.CapacityScheduler: Trying to schedule on node: slave1, available: <memory:4096, vCores:1>
2019-06-07 08:10:36,910 DEBUG org.apache.hadoop.yarn.server.resourcemanager.scheduler.capacity.ParentQueue: Skip this queue=root, because it doesn't need more resource, schedulingMode=RESPECT_PARTITION_EXCLUSIVITY node-partition=
2019-06-07 08:10:36,910 DEBUG org.apache.hadoop.yarn.server.resourcemanager.scheduler.capacity.ParentQueue: Skip this queue=root, because it doesn't need more resource, schedulingMode=RESPECT_PARTITION_EXCLUSIVITY node-partition=
2019-06-07 08:10:36,923 INFO org.apache.hadoop.ipc.CallQueueManager: Using callQueue: class java.util.concurrent.LinkedBlockingQueue queueCapacity: 100 scheduler: class org.apache.hadoop.ipc.DefaultRpcScheduler
2019-06-07 08:10:36,931 INFO org.apache.hadoop.ipc.Server: Starting Socket Reader #1 for port 8033
2019-06-07 08:10:36,948 INFO org.apache.hadoop.yarn.factories.impl.pb.RpcServerFactoryPBImpl: Adding protocol org.apache.hadoop.yarn.server.api.ResourceManagerAdministrationProtocolPB to the server
2019-06-07 08:10:36,959 INFO org.apache.hadoop.ipc.Server: IPC Server Responder: starting
2019-06-07 08:10:36,967 INFO org.apache.hadoop.ipc.Server: IPC Server listener on 8033: starting
2019-06-07 08:10:37,663 DEBUG org.apache.hadoop.yarn.server.resourcemanager.rmnode.RMNodeImpl: Processing slave2:40331 of type STATUS_UPDATE
2019-06-07 08:10:37,663 DEBUG org.apache.hadoop.yarn.server.resourcemanager.rmnode.RMNodeImpl: Processing slave2:40331 of type STATUS_UPDATE
2019-06-07 08:10:37,664 DEBUG org.apache.hadoop.yarn.server.resourcemanager.scheduler.capacity.CapacityScheduler: nodeUpdate: slave2:40331 clusterResources: <memory:8192, vCores:2>
2019-06-07 08:10:37,664 DEBUG org.apache.hadoop.yarn.server.resourcemanager.scheduler.capacity.CapacityScheduler: nodeUpdate: slave2:40331 clusterResources: <memory:8192, vCores:2>
2019-06-07 08:10:37,665 DEBUG org.apache.hadoop.yarn.server.resourcemanager.scheduler.capacity.CapacityScheduler: Node being looked for scheduling slave2:40331 availableResource: <memory:4096, vCores:1>
2019-06-07 08:10:37,665 DEBUG org.apache.hadoop.yarn.server.resourcemanager.scheduler.capacity.CapacityScheduler: Node being looked for scheduling slave2:40331 availableResource: <memory:4096, vCores:1>
2019-06-07 08:10:37,665 DEBUG org.apache.hadoop.yarn.server.resourcemanager.scheduler.capacity.CapacityScheduler: Trying to schedule on node: slave2, available: <memory:4096, vCores:1>
2019-06-07 08:10:37,665 DEBUG org.apache.hadoop.yarn.server.resourcemanager.scheduler.capacity.CapacityScheduler: Trying to schedule on node: slave2, available: <memory:4096, vCores:1>
2019-06-07 08:10:37,665 DEBUG org.apache.hadoop.yarn.server.resourcemanager.scheduler.capacity.ParentQueue: Skip this queue=root, because it doesn't need more resource, schedulingMode=RESPECT_PARTITION_EXCLUSIVITY node-partition=
2019-06-07 08:10:37,665 DEBUG org.apache.hadoop.yarn.server.resourcemanager.scheduler.capacity.ParentQueue: Skip this queue=root, because it doesn't need more resource, schedulingMode=RESPECT_PARTITION_EXCLUSIVITY node-partition=
2019-06-07 08:10:37,693 DEBUG org.apache.hadoop.yarn.server.resourcemanager.rmnode.RMNodeImpl: Processing slave1:41069 of type STATUS_UPDATE
2019-06-07 08:10:37,693 DEBUG org.apache.hadoop.yarn.server.resourcemanager.rmnode.RMNodeImpl: Processing slave1:41069 of type STATUS_UPDATE
2019-06-07 08:10:37,694 DEBUG org.apache.hadoop.yarn.server.resourcemanager.scheduler.capacity.CapacityScheduler: nodeUpdate: slave1:41069 clusterResources: <memory:8192, vCores:2>
2019-06-07 08:10:37,694 DEBUG org.apache.hadoop.yarn.server.resourcemanager.scheduler.capacity.CapacityScheduler: nodeUpdate: slave1:41069 clusterResources: <memory:8192, vCores:2>
2019-06-07 08:10:37,694 DEBUG org.apache.hadoop.yarn.server.resourcemanager.scheduler.capacity.CapacityScheduler: Node being looked for scheduling slave1:41069 availableResource: <memory:4096, vCores:1>
2019-06-07 08:10:37,694 DEBUG org.apache.hadoop.yarn.server.resourcemanager.scheduler.capacity.CapacityScheduler: Node being looked for scheduling slave1:41069 availableResource: <memory:4096, vCores:1>
2019-06-07 08:10:37,694 DEBUG org.apache.hadoop.yarn.server.resourcemanager.scheduler.capacity.CapacityScheduler: Trying to schedule on node: slave1, available: <memory:4096, vCores:1>
2019-06-07 08:10:37,694 DEBUG org.apache.hadoop.yarn.server.resourcemanager.scheduler.capacity.CapacityScheduler: Trying to schedule on node: slave1, available: <memory:4096, vCores:1>
2019-06-07 08:10:37,694 DEBUG org.apache.hadoop.yarn.server.resourcemanager.scheduler.capacity.ParentQueue: Skip this queue=root, because it doesn't need more resource, schedulingMode=RESPECT_PARTITION_EXCLUSIVITY node-partition=
2019-06-07 08:10:37,694 DEBUG org.apache.hadoop.yarn.server.resourcemanager.scheduler.capacity.ParentQueue: Skip this queue=root, because it doesn't need more resource, schedulingMode=RESPECT_PARTITION_EXCLUSIVITY node-partition=
2019-06-07 08:10:38,666 DEBUG org.apache.hadoop.yarn.server.resourcemanager.rmnode.RMNodeImpl: Processing slave2:40331 of type STATUS_UPDATE
2019-06-07 08:10:38,666 DEBUG org.apache.hadoop.yarn.server.resourcemanager.rmnode.RMNodeImpl: Processing slave2:40331 of type STATUS_UPDATE
2019-06-07 08:10:38,667 DEBUG org.apache.hadoop.yarn.server.resourcemanager.scheduler.capacity.CapacityScheduler: nodeUpdate: slave2:40331 clusterResources: <memory:8192, vCores:2>
2019-06-07 08:10:38,667 DEBUG org.apache.hadoop.yarn.server.resourcemanager.scheduler.capacity.CapacityScheduler: nodeUpdate: slave2:40331 clusterResources: <memory:8192, vCores:2>
2019-06-07 08:10:38,667 DEBUG org.apache.hadoop.yarn.server.resourcemanager.scheduler.capacity.CapacityScheduler: Node being looked for scheduling slave2:40331 availableResource: <memory:4096, vCores:1>
2019-06-07 08:10:38,667 DEBUG org.apache.hadoop.yarn.server.resourcemanager.scheduler.capacity.CapacityScheduler: Node being looked for scheduling slave2:40331 availableResource: <memory:4096, vCores:1>
2019-06-07 08:10:38,667 DEBUG org.apache.hadoop.yarn.server.resourcemanager.scheduler.capacity.CapacityScheduler: Trying to schedule on node: slave2, available: <memory:4096, vCores:1>
2019-06-07 08:10:38,667 DEBUG org.apache.hadoop.yarn.server.resourcemanager.scheduler.capacity.CapacityScheduler: Trying to schedule on node: slave2, available: <memory:4096, vCores:1>
2019-06-07 08:10:38,667 DEBUG org.apache.hadoop.yarn.server.resourcemanager.scheduler.capacity.ParentQueue: Skip this queue=root, because it doesn't need more resource, schedulingMode=RESPECT_PARTITION_EXCLUSIVITY node-partition=
2019-06-07 08:10:38,667 DEBUG org.apache.hadoop.yarn.server.resourcemanager.scheduler.capacity.ParentQueue: Skip this queue=root, because it doesn't need more resource, schedulingMode=RESPECT_PARTITION_EXCLUSIVITY node-partition=
2019-06-07 08:10:38,697 DEBUG org.apache.hadoop.yarn.server.resourcemanager.rmnode.RMNodeImpl: Processing slave1:41069 of type STATUS_UPDATE
2019-06-07 08:10:38,697 DEBUG org.apache.hadoop.yarn.server.resourcemanager.rmnode.RMNodeImpl: Processing slave1:41069 of type STATUS_UPDATE
2019-06-07 08:10:38,698 DEBUG org.apache.hadoop.yarn.server.resourcemanager.scheduler.capacity.CapacityScheduler: nodeUpdate: slave1:41069 clusterResources: <memory:8192, vCores:2>
2019-06-07 08:10:38,698 DEBUG org.apache.hadoop.yarn.server.resourcemanager.scheduler.capacity.CapacityScheduler: nodeUpdate: slave1:41069 clusterResources: <memory:8192, vCores:2>
2019-06-07 08:10:38,699 DEBUG org.apache.hadoop.yarn.server.resourcemanager.scheduler.capacity.CapacityScheduler: Node being looked for scheduling slave1:41069 availableResource: <memory:4096, vCores:1>
2019-06-07 08:10:38,699 DEBUG org.apache.hadoop.yarn.server.resourcemanager.scheduler.capacity.CapacityScheduler: Node being looked for scheduling slave1:41069 availableResource: <memory:4096, vCores:1>
2019-06-07 08:10:38,699 DEBUG org.apache.hadoop.yarn.server.resourcemanager.scheduler.capacity.CapacityScheduler: Trying to schedule on node: slave1, available: <memory:4096, vCores:1>
2019-06-07 08:10:38,699 DEBUG org.apache.hadoop.yarn.server.resourcemanager.scheduler.capacity.CapacityScheduler: Trying to schedule on node: slave1, available: <memory:4096, vCores:1>
2019-06-07 08:10:38,699 DEBUG org.apache.hadoop.yarn.server.resourcemanager.scheduler.capacity.ParentQueue: Skip this queue=root, because it doesn't need more resource, schedulingMode=RESPECT_PARTITION_EXCLUSIVITY node-partition=
2019-06-07 08:10:38,699 DEBUG org.apache.hadoop.yarn.server.resourcemanager.scheduler.capacity.ParentQueue: Skip this queue=root, because it doesn't need more resource, schedulingMode=RESPECT_PARTITION_EXCLUSIVITY node-partition=
2019-06-07 08:10:39,668 DEBUG org.apache.hadoop.yarn.server.resourcemanager.rmnode.RMNodeImpl: Processing slave2:40331 of type STATUS_UPDATE
2019-06-07 08:10:39,668 DEBUG org.apache.hadoop.yarn.server.resourcemanager.rmnode.RMNodeImpl: Processing slave2:40331 of type STATUS_UPDATE
2019-06-07 08:10:39,669 DEBUG org.apache.hadoop.yarn.server.resourcemanager.scheduler.capacity.CapacityScheduler: nodeUpdate: slave2:40331 clusterResources: <memory:8192, vCores:2>
2019-06-07 08:10:39,669 DEBUG org.apache.hadoop.yarn.server.resourcemanager.scheduler.capacity.CapacityScheduler: nodeUpdate: slave2:40331 clusterResources: <memory:8192, vCores:2>
2019-06-07 08:10:39,669 DEBUG org.apache.hadoop.yarn.server.resourcemanager.scheduler.capacity.CapacityScheduler: Node being looked for scheduling slave2:40331 availableResource: <memory:4096, vCores:1>
2019-06-07 08:10:39,669 DEBUG org.apache.hadoop.yarn.server.resourcemanager.scheduler.capacity.CapacityScheduler: Node being looked for scheduling slave2:40331 availableResource: <memory:4096, vCores:1>
2019-06-07 08:10:39,669 DEBUG org.apache.hadoop.yarn.server.resourcemanager.scheduler.capacity.CapacityScheduler: Trying to schedule on node: slave2, available: <memory:4096, vCores:1>
2019-06-07 08:10:39,669 DEBUG org.apache.hadoop.yarn.server.resourcemanager.scheduler.capacity.CapacityScheduler: Trying to schedule on node: slave2, available: <memory:4096, vCores:1>
2019-06-07 08:10:39,669 DEBUG org.apache.hadoop.yarn.server.resourcemanager.scheduler.capacity.ParentQueue: Skip this queue=root, because it doesn't need more resource, schedulingMode=RESPECT_PARTITION_EXCLUSIVITY node-partition=
2019-06-07 08:10:39,669 DEBUG org.apache.hadoop.yarn.server.resourcemanager.scheduler.capacity.ParentQueue: Skip this queue=root, because it doesn't need more resource, schedulingMode=RESPECT_PARTITION_EXCLUSIVITY node-partition=
2019-06-07 08:10:39,700 DEBUG org.apache.hadoop.yarn.server.resourcemanager.rmnode.RMNodeImpl: Processing slave1:41069 of type STATUS_UPDATE
2019-06-07 08:10:39,700 DEBUG org.apache.hadoop.yarn.server.resourcemanager.rmnode.RMNodeImpl: Processing slave1:41069 of type STATUS_UPDATE
2019-06-07 08:10:39,701 DEBUG org.apache.hadoop.yarn.server.resourcemanager.scheduler.capacity.CapacityScheduler: nodeUpdate: slave1:41069 clusterResources: <memory:8192, vCores:2>
2019-06-07 08:10:39,701 DEBUG org.apache.hadoop.yarn.server.resourcemanager.scheduler.capacity.CapacityScheduler: nodeUpdate: slave1:41069 clusterResources: <memory:8192, vCores:2>
2019-06-07 08:10:39,701 DEBUG org.apache.hadoop.yarn.server.resourcemanager.scheduler.capacity.CapacityScheduler: Node being looked for scheduling slave1:41069 availableResource: <memory:4096, vCores:1>
2019-06-07 08:10:39,701 DEBUG org.apache.hadoop.yarn.server.resourcemanager.scheduler.capacity.CapacityScheduler: Node being looked for scheduling slave1:41069 availableResource: <memory:4096, vCores:1>
2019-06-07 08:10:39,701 DEBUG org.apache.hadoop.yarn.server.resourcemanager.scheduler.capacity.CapacityScheduler: Trying to schedule on node: slave1, available: <memory:4096, vCores:1>
2019-06-07 08:10:39,701 DEBUG org.apache.hadoop.yarn.server.resourcemanager.scheduler.capacity.CapacityScheduler: Trying to schedule on node: slave1, available: <memory:4096, vCores:1>
2019-06-07 08:10:39,701 DEBUG org.apache.hadoop.yarn.server.resourcemanager.scheduler.capacity.ParentQueue: Skip this queue=root, because it doesn't need more resource, schedulingMode=RESPECT_PARTITION_EXCLUSIVITY node-partition=
2019-06-07 08:10:39,701 DEBUG org.apache.hadoop.yarn.server.resourcemanager.scheduler.capacity.ParentQueue: Skip this queue=root, because it doesn't need more resource, schedulingMode=RESPECT_PARTITION_EXCLUSIVITY node-partition=
2019-06-07 08:10:40,670 DEBUG org.apache.hadoop.yarn.server.resourcemanager.rmnode.RMNodeImpl: Processing slave2:40331 of type STATUS_UPDATE
2019-06-07 08:10:40,670 DEBUG org.apache.hadoop.yarn.server.resourcemanager.rmnode.RMNodeImpl: Processing slave2:40331 of type STATUS_UPDATE
2019-06-07 08:10:40,673 DEBUG org.apache.hadoop.yarn.server.resourcemanager.scheduler.capacity.CapacityScheduler: nodeUpdate: slave2:40331 clusterResources: <memory:8192, vCores:2>
2019-06-07 08:10:40,673 DEBUG org.apache.hadoop.yarn.server.resourcemanager.scheduler.capacity.CapacityScheduler: nodeUpdate: slave2:40331 clusterResources: <memory:8192, vCores:2>
2019-06-07 08:10:40,673 DEBUG org.apache.hadoop.yarn.server.resourcemanager.scheduler.capacity.CapacityScheduler: Node being looked for scheduling slave2:40331 availableResource: <memory:4096, vCores:1>
2019-06-07 08:10:40,673 DEBUG org.apache.hadoop.yarn.server.resourcemanager.scheduler.capacity.CapacityScheduler: Node being looked for scheduling slave2:40331 availableResource: <memory:4096, vCores:1>
2019-06-07 08:10:40,673 DEBUG org.apache.hadoop.yarn.server.resourcemanager.scheduler.capacity.CapacityScheduler: Trying to schedule on node: slave2, available: <memory:4096, vCores:1>
2019-06-07 08:10:40,673 DEBUG org.apache.hadoop.yarn.server.resourcemanager.scheduler.capacity.CapacityScheduler: Trying to schedule on node: slave2, available: <memory:4096, vCores:1>
2019-06-07 08:10:40,673 DEBUG org.apache.hadoop.yarn.server.resourcemanager.scheduler.capacity.ParentQueue: Skip this queue=root, because it doesn't need more resource, schedulingMode=RESPECT_PARTITION_EXCLUSIVITY node-partition=
2019-06-07 08:10:40,673 DEBUG org.apache.hadoop.yarn.server.resourcemanager.scheduler.capacity.ParentQueue: Skip this queue=root, because it doesn't need more resource, schedulingMode=RESPECT_PARTITION_EXCLUSIVITY node-partition=
2019-06-07 08:10:40,703 DEBUG org.apache.hadoop.yarn.server.resourcemanager.rmnode.RMNodeImpl: Processing slave1:41069 of type STATUS_UPDATE
2019-06-07 08:10:40,703 DEBUG org.apache.hadoop.yarn.server.resourcemanager.rmnode.RMNodeImpl: Processing slave1:41069 of type STATUS_UPDATE
2019-06-07 08:10:40,703 DEBUG org.apache.hadoop.yarn.server.resourcemanager.scheduler.capacity.CapacityScheduler: nodeUpdate: slave1:41069 clusterResources: <memory:8192, vCores:2>
2019-06-07 08:10:40,703 DEBUG org.apache.hadoop.yarn.server.resourcemanager.scheduler.capacity.CapacityScheduler: nodeUpdate: slave1:41069 clusterResources: <memory:8192, vCores:2>
2019-06-07 08:10:40,704 DEBUG org.apache.hadoop.yarn.server.resourcemanager.scheduler.capacity.CapacityScheduler: Node being looked for scheduling slave1:41069 availableResource: <memory:4096, vCores:1>
2019-06-07 08:10:40,704 DEBUG org.apache.hadoop.yarn.server.resourcemanager.scheduler.capacity.CapacityScheduler: Node being looked for scheduling slave1:41069 availableResource: <memory:4096, vCores:1>
2019-06-07 08:10:40,704 DEBUG org.apache.hadoop.yarn.server.resourcemanager.scheduler.capacity.CapacityScheduler: Trying to schedule on node: slave1, available: <memory:4096, vCores:1>
2019-06-07 08:10:40,704 DEBUG org.apache.hadoop.yarn.server.resourcemanager.scheduler.capacity.CapacityScheduler: Trying to schedule on node: slave1, available: <memory:4096, vCores:1>
2019-06-07 08:10:40,704 DEBUG org.apache.hadoop.yarn.server.resourcemanager.scheduler.capacity.ParentQueue: Skip this queue=root, because it doesn't need more resource, schedulingMode=RESPECT_PARTITION_EXCLUSIVITY node-partition=
2019-06-07 08:10:40,704 DEBUG org.apache.hadoop.yarn.server.resourcemanager.scheduler.capacity.ParentQueue: Skip this queue=root, because it doesn't need more resource, schedulingMode=RESPECT_PARTITION_EXCLUSIVITY node-partition=
2019-06-07 08:10:41,421 INFO org.apache.hadoop.yarn.server.resourcemanager.ClientRMService: Allocated new applicationId: 1
2019-06-07 08:10:41,421 INFO org.apache.hadoop.yarn.server.resourcemanager.ClientRMService: Allocated new applicationId: 1
2019-06-07 08:10:41,673 DEBUG org.apache.hadoop.yarn.server.resourcemanager.rmnode.RMNodeImpl: Processing slave2:40331 of type STATUS_UPDATE
2019-06-07 08:10:41,673 DEBUG org.apache.hadoop.yarn.server.resourcemanager.rmnode.RMNodeImpl: Processing slave2:40331 of type STATUS_UPDATE
2019-06-07 08:10:41,679 DEBUG org.apache.hadoop.yarn.server.resourcemanager.scheduler.capacity.CapacityScheduler: nodeUpdate: slave2:40331 clusterResources: <memory:8192, vCores:2>
2019-06-07 08:10:41,679 DEBUG org.apache.hadoop.yarn.server.resourcemanager.scheduler.capacity.CapacityScheduler: nodeUpdate: slave2:40331 clusterResources: <memory:8192, vCores:2>
2019-06-07 08:10:41,679 DEBUG org.apache.hadoop.yarn.server.resourcemanager.scheduler.capacity.CapacityScheduler: Node being looked for scheduling slave2:40331 availableResource: <memory:4096, vCores:1>
2019-06-07 08:10:41,679 DEBUG org.apache.hadoop.yarn.server.resourcemanager.scheduler.capacity.CapacityScheduler: Node being looked for scheduling slave2:40331 availableResource: <memory:4096, vCores:1>
2019-06-07 08:10:41,680 DEBUG org.apache.hadoop.yarn.server.resourcemanager.scheduler.capacity.CapacityScheduler: Trying to schedule on node: slave2, available: <memory:4096, vCores:1>
2019-06-07 08:10:41,680 DEBUG org.apache.hadoop.yarn.server.resourcemanager.scheduler.capacity.CapacityScheduler: Trying to schedule on node: slave2, available: <memory:4096, vCores:1>
2019-06-07 08:10:41,680 DEBUG org.apache.hadoop.yarn.server.resourcemanager.scheduler.capacity.ParentQueue: Skip this queue=root, because it doesn't need more resource, schedulingMode=RESPECT_PARTITION_EXCLUSIVITY node-partition=
2019-06-07 08:10:41,680 DEBUG org.apache.hadoop.yarn.server.resourcemanager.scheduler.capacity.ParentQueue: Skip this queue=root, because it doesn't need more resource, schedulingMode=RESPECT_PARTITION_EXCLUSIVITY node-partition=
2019-06-07 08:10:41,705 DEBUG org.apache.hadoop.yarn.server.resourcemanager.rmnode.RMNodeImpl: Processing slave1:41069 of type STATUS_UPDATE
2019-06-07 08:10:41,705 DEBUG org.apache.hadoop.yarn.server.resourcemanager.rmnode.RMNodeImpl: Processing slave1:41069 of type STATUS_UPDATE
2019-06-07 08:10:41,707 DEBUG org.apache.hadoop.yarn.server.resourcemanager.scheduler.capacity.CapacityScheduler: nodeUpdate: slave1:41069 clusterResources: <memory:8192, vCores:2>
2019-06-07 08:10:41,707 DEBUG org.apache.hadoop.yarn.server.resourcemanager.scheduler.capacity.CapacityScheduler: nodeUpdate: slave1:41069 clusterResources: <memory:8192, vCores:2>
2019-06-07 08:10:41,707 DEBUG org.apache.hadoop.yarn.server.resourcemanager.scheduler.capacity.CapacityScheduler: Node being looked for scheduling slave1:41069 availableResource: <memory:4096, vCores:1>
2019-06-07 08:10:41,707 DEBUG org.apache.hadoop.yarn.server.resourcemanager.scheduler.capacity.CapacityScheduler: Node being looked for scheduling slave1:41069 availableResource: <memory:4096, vCores:1>
2019-06-07 08:10:41,707 DEBUG org.apache.hadoop.yarn.server.resourcemanager.scheduler.capacity.CapacityScheduler: Trying to schedule on node: slave1, available: <memory:4096, vCores:1>
2019-06-07 08:10:41,707 DEBUG org.apache.hadoop.yarn.server.resourcemanager.scheduler.capacity.CapacityScheduler: Trying to schedule on node: slave1, available: <memory:4096, vCores:1>
2019-06-07 08:10:41,707 DEBUG org.apache.hadoop.yarn.server.resourcemanager.scheduler.capacity.ParentQueue: Skip this queue=root, because it doesn't need more resource, schedulingMode=RESPECT_PARTITION_EXCLUSIVITY node-partition=
2019-06-07 08:10:41,707 DEBUG org.apache.hadoop.yarn.server.resourcemanager.scheduler.capacity.ParentQueue: Skip this queue=root, because it doesn't need more resource, schedulingMode=RESPECT_PARTITION_EXCLUSIVITY node-partition=
2019-06-07 08:10:42,678 DEBUG org.apache.hadoop.yarn.server.resourcemanager.rmnode.RMNodeImpl: Processing slave2:40331 of type STATUS_UPDATE
2019-06-07 08:10:42,678 DEBUG org.apache.hadoop.yarn.server.resourcemanager.rmnode.RMNodeImpl: Processing slave2:40331 of type STATUS_UPDATE
2019-06-07 08:10:42,679 DEBUG org.apache.hadoop.yarn.server.resourcemanager.scheduler.capacity.CapacityScheduler: nodeUpdate: slave2:40331 clusterResources: <memory:8192, vCores:2>
2019-06-07 08:10:42,679 DEBUG org.apache.hadoop.yarn.server.resourcemanager.scheduler.capacity.CapacityScheduler: nodeUpdate: slave2:40331 clusterResources: <memory:8192, vCores:2>
2019-06-07 08:10:42,679 DEBUG org.apache.hadoop.yarn.server.resourcemanager.scheduler.capacity.CapacityScheduler: Node being looked for scheduling slave2:40331 availableResource: <memory:4096, vCores:1>
2019-06-07 08:10:42,679 DEBUG org.apache.hadoop.yarn.server.resourcemanager.scheduler.capacity.CapacityScheduler: Node being looked for scheduling slave2:40331 availableResource: <memory:4096, vCores:1>
2019-06-07 08:10:42,679 DEBUG org.apache.hadoop.yarn.server.resourcemanager.scheduler.capacity.CapacityScheduler: Trying to schedule on node: slave2, available: <memory:4096, vCores:1>
2019-06-07 08:10:42,679 DEBUG org.apache.hadoop.yarn.server.resourcemanager.scheduler.capacity.CapacityScheduler: Trying to schedule on node: slave2, available: <memory:4096, vCores:1>
2019-06-07 08:10:42,679 DEBUG org.apache.hadoop.yarn.server.resourcemanager.scheduler.capacity.ParentQueue: Skip this queue=root, because it doesn't need more resource, schedulingMode=RESPECT_PARTITION_EXCLUSIVITY node-partition=
2019-06-07 08:10:42,679 DEBUG org.apache.hadoop.yarn.server.resourcemanager.scheduler.capacity.ParentQueue: Skip this queue=root, because it doesn't need more resource, schedulingMode=RESPECT_PARTITION_EXCLUSIVITY node-partition=
2019-06-07 08:10:42,710 DEBUG org.apache.hadoop.yarn.server.resourcemanager.rmnode.RMNodeImpl: Processing slave1:41069 of type STATUS_UPDATE
2019-06-07 08:10:42,710 DEBUG org.apache.hadoop.yarn.server.resourcemanager.rmnode.RMNodeImpl: Processing slave1:41069 of type STATUS_UPDATE
2019-06-07 08:10:42,715 DEBUG org.apache.hadoop.yarn.server.resourcemanager.scheduler.capacity.CapacityScheduler: nodeUpdate: slave1:41069 clusterResources: <memory:8192, vCores:2>
2019-06-07 08:10:42,715 DEBUG org.apache.hadoop.yarn.server.resourcemanager.scheduler.capacity.CapacityScheduler: nodeUpdate: slave1:41069 clusterResources: <memory:8192, vCores:2>
2019-06-07 08:10:42,715 DEBUG org.apache.hadoop.yarn.server.resourcemanager.scheduler.capacity.CapacityScheduler: Node being looked for scheduling slave1:41069 availableResource: <memory:4096, vCores:1>
2019-06-07 08:10:42,715 DEBUG org.apache.hadoop.yarn.server.resourcemanager.scheduler.capacity.CapacityScheduler: Node being looked for scheduling slave1:41069 availableResource: <memory:4096, vCores:1>
2019-06-07 08:10:42,715 DEBUG org.apache.hadoop.yarn.server.resourcemanager.scheduler.capacity.CapacityScheduler: Trying to schedule on node: slave1, available: <memory:4096, vCores:1>
2019-06-07 08:10:42,715 DEBUG org.apache.hadoop.yarn.server.resourcemanager.scheduler.capacity.CapacityScheduler: Trying to schedule on node: slave1, available: <memory:4096, vCores:1>
2019-06-07 08:10:42,715 DEBUG org.apache.hadoop.yarn.server.resourcemanager.scheduler.capacity.ParentQueue: Skip this queue=root, because it doesn't need more resource, schedulingMode=RESPECT_PARTITION_EXCLUSIVITY node-partition=
2019-06-07 08:10:42,715 DEBUG org.apache.hadoop.yarn.server.resourcemanager.scheduler.capacity.ParentQueue: Skip this queue=root, because it doesn't need more resource, schedulingMode=RESPECT_PARTITION_EXCLUSIVITY node-partition=
2019-06-07 08:10:43,684 DEBUG org.apache.hadoop.yarn.server.resourcemanager.rmnode.RMNodeImpl: Processing slave2:40331 of type STATUS_UPDATE
2019-06-07 08:10:43,684 DEBUG org.apache.hadoop.yarn.server.resourcemanager.rmnode.RMNodeImpl: Processing slave2:40331 of type STATUS_UPDATE
2019-06-07 08:10:43,685 DEBUG org.apache.hadoop.yarn.server.resourcemanager.scheduler.capacity.CapacityScheduler: nodeUpdate: slave2:40331 clusterResources: <memory:8192, vCores:2>
2019-06-07 08:10:43,685 DEBUG org.apache.hadoop.yarn.server.resourcemanager.scheduler.capacity.CapacityScheduler: nodeUpdate: slave2:40331 clusterResources: <memory:8192, vCores:2>
2019-06-07 08:10:43,685 DEBUG org.apache.hadoop.yarn.server.resourcemanager.scheduler.capacity.CapacityScheduler: Node being looked for scheduling slave2:40331 availableResource: <memory:4096, vCores:1>
2019-06-07 08:10:43,685 DEBUG org.apache.hadoop.yarn.server.resourcemanager.scheduler.capacity.CapacityScheduler: Node being looked for scheduling slave2:40331 availableResource: <memory:4096, vCores:1>
2019-06-07 08:10:43,685 DEBUG org.apache.hadoop.yarn.server.resourcemanager.scheduler.capacity.CapacityScheduler: Trying to schedule on node: slave2, available: <memory:4096, vCores:1>
2019-06-07 08:10:43,685 DEBUG org.apache.hadoop.yarn.server.resourcemanager.scheduler.capacity.CapacityScheduler: Trying to schedule on node: slave2, available: <memory:4096, vCores:1>
2019-06-07 08:10:43,685 DEBUG org.apache.hadoop.yarn.server.resourcemanager.scheduler.capacity.ParentQueue: Skip this queue=root, because it doesn't need more resource, schedulingMode=RESPECT_PARTITION_EXCLUSIVITY node-partition=
2019-06-07 08:10:43,685 DEBUG org.apache.hadoop.yarn.server.resourcemanager.scheduler.capacity.ParentQueue: Skip this queue=root, because it doesn't need more resource, schedulingMode=RESPECT_PARTITION_EXCLUSIVITY node-partition=
2019-06-07 08:10:43,718 DEBUG org.apache.hadoop.yarn.server.resourcemanager.rmnode.RMNodeImpl: Processing slave1:41069 of type STATUS_UPDATE
2019-06-07 08:10:43,718 DEBUG org.apache.hadoop.yarn.server.resourcemanager.rmnode.RMNodeImpl: Processing slave1:41069 of type STATUS_UPDATE
2019-06-07 08:10:43,718 DEBUG org.apache.hadoop.yarn.server.resourcemanager.scheduler.capacity.CapacityScheduler: nodeUpdate: slave1:41069 clusterResources: <memory:8192, vCores:2>
2019-06-07 08:10:43,718 DEBUG org.apache.hadoop.yarn.server.resourcemanager.scheduler.capacity.CapacityScheduler: nodeUpdate: slave1:41069 clusterResources: <memory:8192, vCores:2>
2019-06-07 08:10:43,718 DEBUG org.apache.hadoop.yarn.server.resourcemanager.scheduler.capacity.CapacityScheduler: Node being looked for scheduling slave1:41069 availableResource: <memory:4096, vCores:1>
2019-06-07 08:10:43,718 DEBUG org.apache.hadoop.yarn.server.resourcemanager.scheduler.capacity.CapacityScheduler: Node being looked for scheduling slave1:41069 availableResource: <memory:4096, vCores:1>
2019-06-07 08:10:43,718 DEBUG org.apache.hadoop.yarn.server.resourcemanager.scheduler.capacity.CapacityScheduler: Trying to schedule on node: slave1, available: <memory:4096, vCores:1>
2019-06-07 08:10:43,718 DEBUG org.apache.hadoop.yarn.server.resourcemanager.scheduler.capacity.CapacityScheduler: Trying to schedule on node: slave1, available: <memory:4096, vCores:1>
2019-06-07 08:10:43,718 DEBUG org.apache.hadoop.yarn.server.resourcemanager.scheduler.capacity.ParentQueue: Skip this queue=root, because it doesn't need more resource, schedulingMode=RESPECT_PARTITION_EXCLUSIVITY node-partition=
2019-06-07 08:10:43,718 DEBUG org.apache.hadoop.yarn.server.resourcemanager.scheduler.capacity.ParentQueue: Skip this queue=root, because it doesn't need more resource, schedulingMode=RESPECT_PARTITION_EXCLUSIVITY node-partition=
2019-06-07 08:10:44,687 DEBUG org.apache.hadoop.yarn.server.resourcemanager.rmnode.RMNodeImpl: Processing slave2:40331 of type STATUS_UPDATE
2019-06-07 08:10:44,687 DEBUG org.apache.hadoop.yarn.server.resourcemanager.rmnode.RMNodeImpl: Processing slave2:40331 of type STATUS_UPDATE
2019-06-07 08:10:44,688 DEBUG org.apache.hadoop.yarn.server.resourcemanager.scheduler.capacity.CapacityScheduler: nodeUpdate: slave2:40331 clusterResources: <memory:8192, vCores:2>
2019-06-07 08:10:44,688 DEBUG org.apache.hadoop.yarn.server.resourcemanager.scheduler.capacity.CapacityScheduler: nodeUpdate: slave2:40331 clusterResources: <memory:8192, vCores:2>
2019-06-07 08:10:44,689 DEBUG org.apache.hadoop.yarn.server.resourcemanager.scheduler.capacity.CapacityScheduler: Node being looked for scheduling slave2:40331 availableResource: <memory:4096, vCores:1>
2019-06-07 08:10:44,689 DEBUG org.apache.hadoop.yarn.server.resourcemanager.scheduler.capacity.CapacityScheduler: Node being looked for scheduling slave2:40331 availableResource: <memory:4096, vCores:1>
2019-06-07 08:10:44,689 DEBUG org.apache.hadoop.yarn.server.resourcemanager.scheduler.capacity.CapacityScheduler: Trying to schedule on node: slave2, available: <memory:4096, vCores:1>
2019-06-07 08:10:44,689 DEBUG org.apache.hadoop.yarn.server.resourcemanager.scheduler.capacity.CapacityScheduler: Trying to schedule on node: slave2, available: <memory:4096, vCores:1>
2019-06-07 08:10:44,689 DEBUG org.apache.hadoop.yarn.server.resourcemanager.scheduler.capacity.ParentQueue: Skip this queue=root, because it doesn't need more resource, schedulingMode=RESPECT_PARTITION_EXCLUSIVITY node-partition=
2019-06-07 08:10:44,689 DEBUG org.apache.hadoop.yarn.server.resourcemanager.scheduler.capacity.ParentQueue: Skip this queue=root, because it doesn't need more resource, schedulingMode=RESPECT_PARTITION_EXCLUSIVITY node-partition=
2019-06-07 08:10:44,721 DEBUG org.apache.hadoop.yarn.server.resourcemanager.rmnode.RMNodeImpl: Processing slave1:41069 of type STATUS_UPDATE
2019-06-07 08:10:44,721 DEBUG org.apache.hadoop.yarn.server.resourcemanager.rmnode.RMNodeImpl: Processing slave1:41069 of type STATUS_UPDATE
2019-06-07 08:10:44,722 DEBUG org.apache.hadoop.yarn.server.resourcemanager.scheduler.capacity.CapacityScheduler: nodeUpdate: slave1:41069 clusterResources: <memory:8192, vCores:2>
2019-06-07 08:10:44,722 DEBUG org.apache.hadoop.yarn.server.resourcemanager.scheduler.capacity.CapacityScheduler: nodeUpdate: slave1:41069 clusterResources: <memory:8192, vCores:2>
2019-06-07 08:10:44,722 DEBUG org.apache.hadoop.yarn.server.resourcemanager.scheduler.capacity.CapacityScheduler: Node being looked for scheduling slave1:41069 availableResource: <memory:4096, vCores:1>
2019-06-07 08:10:44,722 DEBUG org.apache.hadoop.yarn.server.resourcemanager.scheduler.capacity.CapacityScheduler: Node being looked for scheduling slave1:41069 availableResource: <memory:4096, vCores:1>
2019-06-07 08:10:44,723 DEBUG org.apache.hadoop.yarn.server.resourcemanager.scheduler.capacity.CapacityScheduler: Trying to schedule on node: slave1, available: <memory:4096, vCores:1>
2019-06-07 08:10:44,723 DEBUG org.apache.hadoop.yarn.server.resourcemanager.scheduler.capacity.CapacityScheduler: Trying to schedule on node: slave1, available: <memory:4096, vCores:1>
2019-06-07 08:10:44,723 DEBUG org.apache.hadoop.yarn.server.resourcemanager.scheduler.capacity.ParentQueue: Skip this queue=root, because it doesn't need more resource, schedulingMode=RESPECT_PARTITION_EXCLUSIVITY node-partition=
2019-06-07 08:10:44,723 DEBUG org.apache.hadoop.yarn.server.resourcemanager.scheduler.capacity.ParentQueue: Skip this queue=root, because it doesn't need more resource, schedulingMode=RESPECT_PARTITION_EXCLUSIVITY node-partition=
2019-06-07 08:10:45,690 DEBUG org.apache.hadoop.yarn.server.resourcemanager.rmnode.RMNodeImpl: Processing slave2:40331 of type STATUS_UPDATE
2019-06-07 08:10:45,690 DEBUG org.apache.hadoop.yarn.server.resourcemanager.rmnode.RMNodeImpl: Processing slave2:40331 of type STATUS_UPDATE
2019-06-07 08:10:45,691 DEBUG org.apache.hadoop.yarn.server.resourcemanager.scheduler.capacity.CapacityScheduler: nodeUpdate: slave2:40331 clusterResources: <memory:8192, vCores:2>
2019-06-07 08:10:45,691 DEBUG org.apache.hadoop.yarn.server.resourcemanager.scheduler.capacity.CapacityScheduler: nodeUpdate: slave2:40331 clusterResources: <memory:8192, vCores:2>
2019-06-07 08:10:45,691 DEBUG org.apache.hadoop.yarn.server.resourcemanager.scheduler.capacity.CapacityScheduler: Node being looked for scheduling slave2:40331 availableResource: <memory:4096, vCores:1>
2019-06-07 08:10:45,691 DEBUG org.apache.hadoop.yarn.server.resourcemanager.scheduler.capacity.CapacityScheduler: Node being looked for scheduling slave2:40331 availableResource: <memory:4096, vCores:1>
2019-06-07 08:10:45,691 DEBUG org.apache.hadoop.yarn.server.resourcemanager.scheduler.capacity.CapacityScheduler: Trying to schedule on node: slave2, available: <memory:4096, vCores:1>
2019-06-07 08:10:45,691 DEBUG org.apache.hadoop.yarn.server.resourcemanager.scheduler.capacity.CapacityScheduler: Trying to schedule on node: slave2, available: <memory:4096, vCores:1>
2019-06-07 08:10:45,691 DEBUG org.apache.hadoop.yarn.server.resourcemanager.scheduler.capacity.ParentQueue: Skip this queue=root, because it doesn't need more resource, schedulingMode=RESPECT_PARTITION_EXCLUSIVITY node-partition=
2019-06-07 08:10:45,691 DEBUG org.apache.hadoop.yarn.server.resourcemanager.scheduler.capacity.ParentQueue: Skip this queue=root, because it doesn't need more resource, schedulingMode=RESPECT_PARTITION_EXCLUSIVITY node-partition=
2019-06-07 08:10:45,724 DEBUG org.apache.hadoop.yarn.server.resourcemanager.rmnode.RMNodeImpl: Processing slave1:41069 of type STATUS_UPDATE
2019-06-07 08:10:45,724 DEBUG org.apache.hadoop.yarn.server.resourcemanager.rmnode.RMNodeImpl: Processing slave1:41069 of type STATUS_UPDATE
2019-06-07 08:10:45,726 DEBUG org.apache.hadoop.yarn.server.resourcemanager.scheduler.capacity.CapacityScheduler: nodeUpdate: slave1:41069 clusterResources: <memory:8192, vCores:2>
2019-06-07 08:10:45,726 DEBUG org.apache.hadoop.yarn.server.resourcemanager.scheduler.capacity.CapacityScheduler: nodeUpdate: slave1:41069 clusterResources: <memory:8192, vCores:2>
2019-06-07 08:10:45,726 DEBUG org.apache.hadoop.yarn.server.resourcemanager.scheduler.capacity.CapacityScheduler: Node being looked for scheduling slave1:41069 availableResource: <memory:4096, vCores:1>
2019-06-07 08:10:45,726 DEBUG org.apache.hadoop.yarn.server.resourcemanager.scheduler.capacity.CapacityScheduler: Node being looked for scheduling slave1:41069 availableResource: <memory:4096, vCores:1>
2019-06-07 08:10:45,726 DEBUG org.apache.hadoop.yarn.server.resourcemanager.scheduler.capacity.CapacityScheduler: Trying to schedule on node: slave1, available: <memory:4096, vCores:1>
2019-06-07 08:10:45,726 DEBUG org.apache.hadoop.yarn.server.resourcemanager.scheduler.capacity.CapacityScheduler: Trying to schedule on node: slave1, available: <memory:4096, vCores:1>
2019-06-07 08:10:45,726 DEBUG org.apache.hadoop.yarn.server.resourcemanager.scheduler.capacity.ParentQueue: Skip this queue=root, because it doesn't need more resource, schedulingMode=RESPECT_PARTITION_EXCLUSIVITY node-partition=
2019-06-07 08:10:45,726 DEBUG org.apache.hadoop.yarn.server.resourcemanager.scheduler.capacity.ParentQueue: Skip this queue=root, because it doesn't need more resource, schedulingMode=RESPECT_PARTITION_EXCLUSIVITY node-partition=
2019-06-07 08:10:46,699 DEBUG org.apache.hadoop.yarn.server.resourcemanager.rmnode.RMNodeImpl: Processing slave2:40331 of type STATUS_UPDATE
2019-06-07 08:10:46,699 DEBUG org.apache.hadoop.yarn.server.resourcemanager.rmnode.RMNodeImpl: Processing slave2:40331 of type STATUS_UPDATE
2019-06-07 08:10:46,701 DEBUG org.apache.hadoop.yarn.server.resourcemanager.scheduler.capacity.CapacityScheduler: nodeUpdate: slave2:40331 clusterResources: <memory:8192, vCores:2>
2019-06-07 08:10:46,701 DEBUG org.apache.hadoop.yarn.server.resourcemanager.scheduler.capacity.CapacityScheduler: nodeUpdate: slave2:40331 clusterResources: <memory:8192, vCores:2>
2019-06-07 08:10:46,701 DEBUG org.apache.hadoop.yarn.server.resourcemanager.scheduler.capacity.CapacityScheduler: Node being looked for scheduling slave2:40331 availableResource: <memory:4096, vCores:1>
2019-06-07 08:10:46,701 DEBUG org.apache.hadoop.yarn.server.resourcemanager.scheduler.capacity.CapacityScheduler: Node being looked for scheduling slave2:40331 availableResource: <memory:4096, vCores:1>
2019-06-07 08:10:46,701 DEBUG org.apache.hadoop.yarn.server.resourcemanager.scheduler.capacity.CapacityScheduler: Trying to schedule on node: slave2, available: <memory:4096, vCores:1>
2019-06-07 08:10:46,701 DEBUG org.apache.hadoop.yarn.server.resourcemanager.scheduler.capacity.CapacityScheduler: Trying to schedule on node: slave2, available: <memory:4096, vCores:1>
2019-06-07 08:10:46,701 DEBUG org.apache.hadoop.yarn.server.resourcemanager.scheduler.capacity.ParentQueue: Skip this queue=root, because it doesn't need more resource, schedulingMode=RESPECT_PARTITION_EXCLUSIVITY node-partition=
2019-06-07 08:10:46,701 DEBUG org.apache.hadoop.yarn.server.resourcemanager.scheduler.capacity.ParentQueue: Skip this queue=root, because it doesn't need more resource, schedulingMode=RESPECT_PARTITION_EXCLUSIVITY node-partition=
2019-06-07 08:10:46,727 DEBUG org.apache.hadoop.yarn.server.resourcemanager.rmnode.RMNodeImpl: Processing slave1:41069 of type STATUS_UPDATE
2019-06-07 08:10:46,727 DEBUG org.apache.hadoop.yarn.server.resourcemanager.rmnode.RMNodeImpl: Processing slave1:41069 of type STATUS_UPDATE
2019-06-07 08:10:46,738 DEBUG org.apache.hadoop.yarn.server.resourcemanager.scheduler.capacity.CapacityScheduler: nodeUpdate: slave1:41069 clusterResources: <memory:8192, vCores:2>
2019-06-07 08:10:46,738 DEBUG org.apache.hadoop.yarn.server.resourcemanager.scheduler.capacity.CapacityScheduler: nodeUpdate: slave1:41069 clusterResources: <memory:8192, vCores:2>
2019-06-07 08:10:46,738 DEBUG org.apache.hadoop.yarn.server.resourcemanager.scheduler.capacity.CapacityScheduler: Node being looked for scheduling slave1:41069 availableResource: <memory:4096, vCores:1>
2019-06-07 08:10:46,738 DEBUG org.apache.hadoop.yarn.server.resourcemanager.scheduler.capacity.CapacityScheduler: Node being looked for scheduling slave1:41069 availableResource: <memory:4096, vCores:1>
2019-06-07 08:10:46,738 DEBUG org.apache.hadoop.yarn.server.resourcemanager.scheduler.capacity.CapacityScheduler: Trying to schedule on node: slave1, available: <memory:4096, vCores:1>
2019-06-07 08:10:46,738 DEBUG org.apache.hadoop.yarn.server.resourcemanager.scheduler.capacity.CapacityScheduler: Trying to schedule on node: slave1, available: <memory:4096, vCores:1>
2019-06-07 08:10:46,738 DEBUG org.apache.hadoop.yarn.server.resourcemanager.scheduler.capacity.ParentQueue: Skip this queue=root, because it doesn't need more resource, schedulingMode=RESPECT_PARTITION_EXCLUSIVITY node-partition=
2019-06-07 08:10:46,738 DEBUG org.apache.hadoop.yarn.server.resourcemanager.scheduler.capacity.ParentQueue: Skip this queue=root, because it doesn't need more resource, schedulingMode=RESPECT_PARTITION_EXCLUSIVITY node-partition=
2019-06-07 08:10:47,717 DEBUG org.apache.hadoop.yarn.server.resourcemanager.rmnode.RMNodeImpl: Processing slave2:40331 of type STATUS_UPDATE
2019-06-07 08:10:47,717 DEBUG org.apache.hadoop.yarn.server.resourcemanager.rmnode.RMNodeImpl: Processing slave2:40331 of type STATUS_UPDATE
2019-06-07 08:10:47,727 DEBUG org.apache.hadoop.yarn.server.resourcemanager.scheduler.capacity.CapacityScheduler: nodeUpdate: slave2:40331 clusterResources: <memory:8192, vCores:2>
2019-06-07 08:10:47,727 DEBUG org.apache.hadoop.yarn.server.resourcemanager.scheduler.capacity.CapacityScheduler: nodeUpdate: slave2:40331 clusterResources: <memory:8192, vCores:2>
2019-06-07 08:10:47,727 DEBUG org.apache.hadoop.yarn.server.resourcemanager.scheduler.capacity.CapacityScheduler: Node being looked for scheduling slave2:40331 availableResource: <memory:4096, vCores:1>
2019-06-07 08:10:47,727 DEBUG org.apache.hadoop.yarn.server.resourcemanager.scheduler.capacity.CapacityScheduler: Node being looked for scheduling slave2:40331 availableResource: <memory:4096, vCores:1>
2019-06-07 08:10:47,727 DEBUG org.apache.hadoop.yarn.server.resourcemanager.scheduler.capacity.CapacityScheduler: Trying to schedule on node: slave2, available: <memory:4096, vCores:1>
2019-06-07 08:10:47,727 DEBUG org.apache.hadoop.yarn.server.resourcemanager.scheduler.capacity.CapacityScheduler: Trying to schedule on node: slave2, available: <memory:4096, vCores:1>
2019-06-07 08:10:47,727 DEBUG org.apache.hadoop.yarn.server.resourcemanager.scheduler.capacity.ParentQueue: Skip this queue=root, because it doesn't need more resource, schedulingMode=RESPECT_PARTITION_EXCLUSIVITY node-partition=
2019-06-07 08:10:47,727 DEBUG org.apache.hadoop.yarn.server.resourcemanager.scheduler.capacity.ParentQueue: Skip this queue=root, because it doesn't need more resource, schedulingMode=RESPECT_PARTITION_EXCLUSIVITY node-partition=
2019-06-07 08:10:47,739 DEBUG org.apache.hadoop.yarn.server.resourcemanager.rmnode.RMNodeImpl: Processing slave1:41069 of type STATUS_UPDATE
2019-06-07 08:10:47,739 DEBUG org.apache.hadoop.yarn.server.resourcemanager.rmnode.RMNodeImpl: Processing slave1:41069 of type STATUS_UPDATE
2019-06-07 08:10:47,741 DEBUG org.apache.hadoop.yarn.server.resourcemanager.scheduler.capacity.CapacityScheduler: nodeUpdate: slave1:41069 clusterResources: <memory:8192, vCores:2>
2019-06-07 08:10:47,741 DEBUG org.apache.hadoop.yarn.server.resourcemanager.scheduler.capacity.CapacityScheduler: nodeUpdate: slave1:41069 clusterResources: <memory:8192, vCores:2>
2019-06-07 08:10:47,741 DEBUG org.apache.hadoop.yarn.server.resourcemanager.scheduler.capacity.CapacityScheduler: Node being looked for scheduling slave1:41069 availableResource: <memory:4096, vCores:1>
2019-06-07 08:10:47,741 DEBUG org.apache.hadoop.yarn.server.resourcemanager.scheduler.capacity.CapacityScheduler: Node being looked for scheduling slave1:41069 availableResource: <memory:4096, vCores:1>
2019-06-07 08:10:47,741 DEBUG org.apache.hadoop.yarn.server.resourcemanager.scheduler.capacity.CapacityScheduler: Trying to schedule on node: slave1, available: <memory:4096, vCores:1>
2019-06-07 08:10:47,741 DEBUG org.apache.hadoop.yarn.server.resourcemanager.scheduler.capacity.CapacityScheduler: Trying to schedule on node: slave1, available: <memory:4096, vCores:1>
2019-06-07 08:10:47,741 DEBUG org.apache.hadoop.yarn.server.resourcemanager.scheduler.capacity.ParentQueue: Skip this queue=root, because it doesn't need more resource, schedulingMode=RESPECT_PARTITION_EXCLUSIVITY node-partition=
2019-06-07 08:10:47,741 DEBUG org.apache.hadoop.yarn.server.resourcemanager.scheduler.capacity.ParentQueue: Skip this queue=root, because it doesn't need more resource, schedulingMode=RESPECT_PARTITION_EXCLUSIVITY node-partition=
2019-06-07 08:10:48,728 DEBUG org.apache.hadoop.yarn.server.resourcemanager.rmnode.RMNodeImpl: Processing slave2:40331 of type STATUS_UPDATE
2019-06-07 08:10:48,728 DEBUG org.apache.hadoop.yarn.server.resourcemanager.rmnode.RMNodeImpl: Processing slave2:40331 of type STATUS_UPDATE
2019-06-07 08:10:48,729 DEBUG org.apache.hadoop.yarn.server.resourcemanager.scheduler.capacity.CapacityScheduler: nodeUpdate: slave2:40331 clusterResources: <memory:8192, vCores:2>
2019-06-07 08:10:48,729 DEBUG org.apache.hadoop.yarn.server.resourcemanager.scheduler.capacity.CapacityScheduler: nodeUpdate: slave2:40331 clusterResources: <memory:8192, vCores:2>
2019-06-07 08:10:48,729 DEBUG org.apache.hadoop.yarn.server.resourcemanager.scheduler.capacity.CapacityScheduler: Node being looked for scheduling slave2:40331 availableResource: <memory:4096, vCores:1>
2019-06-07 08:10:48,729 DEBUG org.apache.hadoop.yarn.server.resourcemanager.scheduler.capacity.CapacityScheduler: Node being looked for scheduling slave2:40331 availableResource: <memory:4096, vCores:1>
2019-06-07 08:10:48,729 DEBUG org.apache.hadoop.yarn.server.resourcemanager.scheduler.capacity.CapacityScheduler: Trying to schedule on node: slave2, available: <memory:4096, vCores:1>
2019-06-07 08:10:48,729 DEBUG org.apache.hadoop.yarn.server.resourcemanager.scheduler.capacity.CapacityScheduler: Trying to schedule on node: slave2, available: <memory:4096, vCores:1>
2019-06-07 08:10:48,729 DEBUG org.apache.hadoop.yarn.server.resourcemanager.scheduler.capacity.ParentQueue: Skip this queue=root, because it doesn't need more resource, schedulingMode=RESPECT_PARTITION_EXCLUSIVITY node-partition=
2019-06-07 08:10:48,729 DEBUG org.apache.hadoop.yarn.server.resourcemanager.scheduler.capacity.ParentQueue: Skip this queue=root, because it doesn't need more resource, schedulingMode=RESPECT_PARTITION_EXCLUSIVITY node-partition=
2019-06-07 08:10:48,750 DEBUG org.apache.hadoop.yarn.server.resourcemanager.rmnode.RMNodeImpl: Processing slave1:41069 of type STATUS_UPDATE
2019-06-07 08:10:48,750 DEBUG org.apache.hadoop.yarn.server.resourcemanager.rmnode.RMNodeImpl: Processing slave1:41069 of type STATUS_UPDATE
2019-06-07 08:10:48,751 DEBUG org.apache.hadoop.yarn.server.resourcemanager.scheduler.capacity.CapacityScheduler: nodeUpdate: slave1:41069 clusterResources: <memory:8192, vCores:2>
2019-06-07 08:10:48,751 DEBUG org.apache.hadoop.yarn.server.resourcemanager.scheduler.capacity.CapacityScheduler: nodeUpdate: slave1:41069 clusterResources: <memory:8192, vCores:2>
2019-06-07 08:10:48,752 DEBUG org.apache.hadoop.yarn.server.resourcemanager.scheduler.capacity.CapacityScheduler: Node being looked for scheduling slave1:41069 availableResource: <memory:4096, vCores:1>
2019-06-07 08:10:48,752 DEBUG org.apache.hadoop.yarn.server.resourcemanager.scheduler.capacity.CapacityScheduler: Node being looked for scheduling slave1:41069 availableResource: <memory:4096, vCores:1>
2019-06-07 08:10:48,752 DEBUG org.apache.hadoop.yarn.server.resourcemanager.scheduler.capacity.CapacityScheduler: Trying to schedule on node: slave1, available: <memory:4096, vCores:1>
2019-06-07 08:10:48,752 DEBUG org.apache.hadoop.yarn.server.resourcemanager.scheduler.capacity.CapacityScheduler: Trying to schedule on node: slave1, available: <memory:4096, vCores:1>
2019-06-07 08:10:48,752 DEBUG org.apache.hadoop.yarn.server.resourcemanager.scheduler.capacity.ParentQueue: Skip this queue=root, because it doesn't need more resource, schedulingMode=RESPECT_PARTITION_EXCLUSIVITY node-partition=
2019-06-07 08:10:48,752 DEBUG org.apache.hadoop.yarn.server.resourcemanager.scheduler.capacity.ParentQueue: Skip this queue=root, because it doesn't need more resource, schedulingMode=RESPECT_PARTITION_EXCLUSIVITY node-partition=
2019-06-07 08:10:49,741 DEBUG org.apache.hadoop.yarn.server.resourcemanager.rmnode.RMNodeImpl: Processing slave2:40331 of type STATUS_UPDATE
2019-06-07 08:10:49,741 DEBUG org.apache.hadoop.yarn.server.resourcemanager.rmnode.RMNodeImpl: Processing slave2:40331 of type STATUS_UPDATE
2019-06-07 08:10:49,742 DEBUG org.apache.hadoop.yarn.server.resourcemanager.scheduler.capacity.CapacityScheduler: nodeUpdate: slave2:40331 clusterResources: <memory:8192, vCores:2>
2019-06-07 08:10:49,742 DEBUG org.apache.hadoop.yarn.server.resourcemanager.scheduler.capacity.CapacityScheduler: nodeUpdate: slave2:40331 clusterResources: <memory:8192, vCores:2>
2019-06-07 08:10:49,743 DEBUG org.apache.hadoop.yarn.server.resourcemanager.scheduler.capacity.CapacityScheduler: Node being looked for scheduling slave2:40331 availableResource: <memory:4096, vCores:1>
2019-06-07 08:10:49,743 DEBUG org.apache.hadoop.yarn.server.resourcemanager.scheduler.capacity.CapacityScheduler: Node being looked for scheduling slave2:40331 availableResource: <memory:4096, vCores:1>
2019-06-07 08:10:49,743 DEBUG org.apache.hadoop.yarn.server.resourcemanager.scheduler.capacity.CapacityScheduler: Trying to schedule on node: slave2, available: <memory:4096, vCores:1>
2019-06-07 08:10:49,743 DEBUG org.apache.hadoop.yarn.server.resourcemanager.scheduler.capacity.CapacityScheduler: Trying to schedule on node: slave2, available: <memory:4096, vCores:1>
2019-06-07 08:10:49,743 DEBUG org.apache.hadoop.yarn.server.resourcemanager.scheduler.capacity.ParentQueue: Skip this queue=root, because it doesn't need more resource, schedulingMode=RESPECT_PARTITION_EXCLUSIVITY node-partition=
2019-06-07 08:10:49,743 DEBUG org.apache.hadoop.yarn.server.resourcemanager.scheduler.capacity.ParentQueue: Skip this queue=root, because it doesn't need more resource, schedulingMode=RESPECT_PARTITION_EXCLUSIVITY node-partition=
2019-06-07 08:10:49,760 DEBUG org.apache.hadoop.yarn.server.resourcemanager.rmnode.RMNodeImpl: Processing slave1:41069 of type STATUS_UPDATE
2019-06-07 08:10:49,760 DEBUG org.apache.hadoop.yarn.server.resourcemanager.rmnode.RMNodeImpl: Processing slave1:41069 of type STATUS_UPDATE
2019-06-07 08:10:49,761 DEBUG org.apache.hadoop.yarn.server.resourcemanager.scheduler.capacity.CapacityScheduler: nodeUpdate: slave1:41069 clusterResources: <memory:8192, vCores:2>
2019-06-07 08:10:49,761 DEBUG org.apache.hadoop.yarn.server.resourcemanager.scheduler.capacity.CapacityScheduler: nodeUpdate: slave1:41069 clusterResources: <memory:8192, vCores:2>
2019-06-07 08:10:49,761 DEBUG org.apache.hadoop.yarn.server.resourcemanager.scheduler.capacity.CapacityScheduler: Node being looked for scheduling slave1:41069 availableResource: <memory:4096, vCores:1>
2019-06-07 08:10:49,761 DEBUG org.apache.hadoop.yarn.server.resourcemanager.scheduler.capacity.CapacityScheduler: Node being looked for scheduling slave1:41069 availableResource: <memory:4096, vCores:1>
2019-06-07 08:10:49,762 DEBUG org.apache.hadoop.yarn.server.resourcemanager.scheduler.capacity.CapacityScheduler: Trying to schedule on node: slave1, available: <memory:4096, vCores:1>
2019-06-07 08:10:49,762 DEBUG org.apache.hadoop.yarn.server.resourcemanager.scheduler.capacity.CapacityScheduler: Trying to schedule on node: slave1, available: <memory:4096, vCores:1>
2019-06-07 08:10:49,762 DEBUG org.apache.hadoop.yarn.server.resourcemanager.scheduler.capacity.ParentQueue: Skip this queue=root, because it doesn't need more resource, schedulingMode=RESPECT_PARTITION_EXCLUSIVITY node-partition=
2019-06-07 08:10:49,762 DEBUG org.apache.hadoop.yarn.server.resourcemanager.scheduler.capacity.ParentQueue: Skip this queue=root, because it doesn't need more resource, schedulingMode=RESPECT_PARTITION_EXCLUSIVITY node-partition=
2019-06-07 08:10:50,745 DEBUG org.apache.hadoop.yarn.server.resourcemanager.rmnode.RMNodeImpl: Processing slave2:40331 of type STATUS_UPDATE
2019-06-07 08:10:50,745 DEBUG org.apache.hadoop.yarn.server.resourcemanager.rmnode.RMNodeImpl: Processing slave2:40331 of type STATUS_UPDATE
2019-06-07 08:10:50,746 DEBUG org.apache.hadoop.yarn.server.resourcemanager.scheduler.capacity.CapacityScheduler: nodeUpdate: slave2:40331 clusterResources: <memory:8192, vCores:2>
2019-06-07 08:10:50,746 DEBUG org.apache.hadoop.yarn.server.resourcemanager.scheduler.capacity.CapacityScheduler: nodeUpdate: slave2:40331 clusterResources: <memory:8192, vCores:2>
2019-06-07 08:10:50,746 DEBUG org.apache.hadoop.yarn.server.resourcemanager.scheduler.capacity.CapacityScheduler: Node being looked for scheduling slave2:40331 availableResource: <memory:4096, vCores:1>
2019-06-07 08:10:50,746 DEBUG org.apache.hadoop.yarn.server.resourcemanager.scheduler.capacity.CapacityScheduler: Node being looked for scheduling slave2:40331 availableResource: <memory:4096, vCores:1>
2019-06-07 08:10:50,746 DEBUG org.apache.hadoop.yarn.server.resourcemanager.scheduler.capacity.CapacityScheduler: Trying to schedule on node: slave2, available: <memory:4096, vCores:1>
2019-06-07 08:10:50,746 DEBUG org.apache.hadoop.yarn.server.resourcemanager.scheduler.capacity.CapacityScheduler: Trying to schedule on node: slave2, available: <memory:4096, vCores:1>
2019-06-07 08:10:50,746 DEBUG org.apache.hadoop.yarn.server.resourcemanager.scheduler.capacity.ParentQueue: Skip this queue=root, because it doesn't need more resource, schedulingMode=RESPECT_PARTITION_EXCLUSIVITY node-partition=
2019-06-07 08:10:50,746 DEBUG org.apache.hadoop.yarn.server.resourcemanager.scheduler.capacity.ParentQueue: Skip this queue=root, because it doesn't need more resource, schedulingMode=RESPECT_PARTITION_EXCLUSIVITY node-partition=
2019-06-07 08:10:50,763 DEBUG org.apache.hadoop.yarn.server.resourcemanager.rmnode.RMNodeImpl: Processing slave1:41069 of type STATUS_UPDATE
2019-06-07 08:10:50,763 DEBUG org.apache.hadoop.yarn.server.resourcemanager.rmnode.RMNodeImpl: Processing slave1:41069 of type STATUS_UPDATE
2019-06-07 08:10:50,771 DEBUG org.apache.hadoop.yarn.server.resourcemanager.scheduler.capacity.CapacityScheduler: nodeUpdate: slave1:41069 clusterResources: <memory:8192, vCores:2>
2019-06-07 08:10:50,771 DEBUG org.apache.hadoop.yarn.server.resourcemanager.scheduler.capacity.CapacityScheduler: nodeUpdate: slave1:41069 clusterResources: <memory:8192, vCores:2>
2019-06-07 08:10:50,771 DEBUG org.apache.hadoop.yarn.server.resourcemanager.scheduler.capacity.CapacityScheduler: Node being looked for scheduling slave1:41069 availableResource: <memory:4096, vCores:1>
2019-06-07 08:10:50,771 DEBUG org.apache.hadoop.yarn.server.resourcemanager.scheduler.capacity.CapacityScheduler: Node being looked for scheduling slave1:41069 availableResource: <memory:4096, vCores:1>
2019-06-07 08:10:50,771 DEBUG org.apache.hadoop.yarn.server.resourcemanager.scheduler.capacity.CapacityScheduler: Trying to schedule on node: slave1, available: <memory:4096, vCores:1>
2019-06-07 08:10:50,771 DEBUG org.apache.hadoop.yarn.server.resourcemanager.scheduler.capacity.CapacityScheduler: Trying to schedule on node: slave1, available: <memory:4096, vCores:1>
2019-06-07 08:10:50,771 DEBUG org.apache.hadoop.yarn.server.resourcemanager.scheduler.capacity.ParentQueue: Skip this queue=root, because it doesn't need more resource, schedulingMode=RESPECT_PARTITION_EXCLUSIVITY node-partition=
2019-06-07 08:10:50,771 DEBUG org.apache.hadoop.yarn.server.resourcemanager.scheduler.capacity.ParentQueue: Skip this queue=root, because it doesn't need more resource, schedulingMode=RESPECT_PARTITION_EXCLUSIVITY node-partition=
2019-06-07 08:10:51,756 DEBUG org.apache.hadoop.yarn.server.resourcemanager.rmnode.RMNodeImpl: Processing slave2:40331 of type STATUS_UPDATE
2019-06-07 08:10:51,756 DEBUG org.apache.hadoop.yarn.server.resourcemanager.rmnode.RMNodeImpl: Processing slave2:40331 of type STATUS_UPDATE
2019-06-07 08:10:51,757 DEBUG org.apache.hadoop.yarn.server.resourcemanager.scheduler.capacity.CapacityScheduler: nodeUpdate: slave2:40331 clusterResources: <memory:8192, vCores:2>
2019-06-07 08:10:51,757 DEBUG org.apache.hadoop.yarn.server.resourcemanager.scheduler.capacity.CapacityScheduler: nodeUpdate: slave2:40331 clusterResources: <memory:8192, vCores:2>
2019-06-07 08:10:51,757 DEBUG org.apache.hadoop.yarn.server.resourcemanager.scheduler.capacity.CapacityScheduler: Node being looked for scheduling slave2:40331 availableResource: <memory:4096, vCores:1>
2019-06-07 08:10:51,757 DEBUG org.apache.hadoop.yarn.server.resourcemanager.scheduler.capacity.CapacityScheduler: Node being looked for scheduling slave2:40331 availableResource: <memory:4096, vCores:1>
2019-06-07 08:10:51,757 DEBUG org.apache.hadoop.yarn.server.resourcemanager.scheduler.capacity.CapacityScheduler: Trying to schedule on node: slave2, available: <memory:4096, vCores:1>
2019-06-07 08:10:51,757 DEBUG org.apache.hadoop.yarn.server.resourcemanager.scheduler.capacity.CapacityScheduler: Trying to schedule on node: slave2, available: <memory:4096, vCores:1>
2019-06-07 08:10:51,757 DEBUG org.apache.hadoop.yarn.server.resourcemanager.scheduler.capacity.ParentQueue: Skip this queue=root, because it doesn't need more resource, schedulingMode=RESPECT_PARTITION_EXCLUSIVITY node-partition=
2019-06-07 08:10:51,757 DEBUG org.apache.hadoop.yarn.server.resourcemanager.scheduler.capacity.ParentQueue: Skip this queue=root, because it doesn't need more resource, schedulingMode=RESPECT_PARTITION_EXCLUSIVITY node-partition=
2019-06-07 08:10:51,775 DEBUG org.apache.hadoop.yarn.server.resourcemanager.rmnode.RMNodeImpl: Processing slave1:41069 of type STATUS_UPDATE
2019-06-07 08:10:51,775 DEBUG org.apache.hadoop.yarn.server.resourcemanager.rmnode.RMNodeImpl: Processing slave1:41069 of type STATUS_UPDATE
2019-06-07 08:10:51,775 DEBUG org.apache.hadoop.yarn.server.resourcemanager.scheduler.capacity.CapacityScheduler: nodeUpdate: slave1:41069 clusterResources: <memory:8192, vCores:2>
2019-06-07 08:10:51,775 DEBUG org.apache.hadoop.yarn.server.resourcemanager.scheduler.capacity.CapacityScheduler: nodeUpdate: slave1:41069 clusterResources: <memory:8192, vCores:2>
2019-06-07 08:10:51,775 DEBUG org.apache.hadoop.yarn.server.resourcemanager.scheduler.capacity.CapacityScheduler: Node being looked for scheduling slave1:41069 availableResource: <memory:4096, vCores:1>
2019-06-07 08:10:51,775 DEBUG org.apache.hadoop.yarn.server.resourcemanager.scheduler.capacity.CapacityScheduler: Node being looked for scheduling slave1:41069 availableResource: <memory:4096, vCores:1>
2019-06-07 08:10:51,776 DEBUG org.apache.hadoop.yarn.server.resourcemanager.scheduler.capacity.CapacityScheduler: Trying to schedule on node: slave1, available: <memory:4096, vCores:1>
2019-06-07 08:10:51,776 DEBUG org.apache.hadoop.yarn.server.resourcemanager.scheduler.capacity.CapacityScheduler: Trying to schedule on node: slave1, available: <memory:4096, vCores:1>
2019-06-07 08:10:51,776 DEBUG org.apache.hadoop.yarn.server.resourcemanager.scheduler.capacity.ParentQueue: Skip this queue=root, because it doesn't need more resource, schedulingMode=RESPECT_PARTITION_EXCLUSIVITY node-partition=
2019-06-07 08:10:51,776 DEBUG org.apache.hadoop.yarn.server.resourcemanager.scheduler.capacity.ParentQueue: Skip this queue=root, because it doesn't need more resource, schedulingMode=RESPECT_PARTITION_EXCLUSIVITY node-partition=
2019-06-07 08:10:52,307 INFO org.apache.hadoop.yarn.server.resourcemanager.scheduler.capacity.CapacityScheduler: Application 'application_1559895028500_0001' is submitted without priority hence considering default queue/cluster priority: 0
2019-06-07 08:10:52,307 INFO org.apache.hadoop.yarn.server.resourcemanager.scheduler.capacity.CapacityScheduler: Application 'application_1559895028500_0001' is submitted without priority hence considering default queue/cluster priority: 0
2019-06-07 08:10:52,307 INFO org.apache.hadoop.yarn.server.resourcemanager.scheduler.capacity.CapacityScheduler: Priority '0' is acceptable in queue : default for application: application_1559895028500_0001 for the user: root
2019-06-07 08:10:52,307 INFO org.apache.hadoop.yarn.server.resourcemanager.scheduler.capacity.CapacityScheduler: Priority '0' is acceptable in queue : default for application: application_1559895028500_0001 for the user: root
2019-06-07 08:10:52,322 WARN org.apache.hadoop.yarn.server.resourcemanager.rmapp.RMAppImpl: The specific max attempts: 0 for application: 1 is invalid, because it is out of the range [1, 2]. Use the global max attempts instead.
2019-06-07 08:10:52,322 WARN org.apache.hadoop.yarn.server.resourcemanager.rmapp.RMAppImpl: The specific max attempts: 0 for application: 1 is invalid, because it is out of the range [1, 2]. Use the global max attempts instead.
2019-06-07 08:10:52,330 DEBUG org.apache.hadoop.yarn.server.resourcemanager.rmapp.RMAppImpl: Processing event for application_1559895028500_0001 of type START
2019-06-07 08:10:52,330 DEBUG org.apache.hadoop.yarn.server.resourcemanager.rmapp.RMAppImpl: Processing event for application_1559895028500_0001 of type START
2019-06-07 08:10:52,330 INFO org.apache.hadoop.yarn.server.resourcemanager.rmapp.RMAppImpl: Storing application with id application_1559895028500_0001
2019-06-07 08:10:52,330 INFO org.apache.hadoop.yarn.server.resourcemanager.rmapp.RMAppImpl: Storing application with id application_1559895028500_0001
2019-06-07 08:10:52,330 INFO org.apache.hadoop.yarn.server.resourcemanager.ClientRMService: Application with id 1 submitted by user root
2019-06-07 08:10:52,330 INFO org.apache.hadoop.yarn.server.resourcemanager.ClientRMService: Application with id 1 submitted by user root
2019-06-07 08:10:52,334 INFO org.apache.hadoop.yarn.server.resourcemanager.RMAuditLogger: USER=root	IP=172.17.0.2	OPERATION=Submit Application Request	TARGET=ClientRMService	RESULT=SUCCESS	APPID=application_1559895028500_0001
2019-06-07 08:10:52,334 INFO org.apache.hadoop.yarn.server.resourcemanager.RMAuditLogger: USER=root	IP=172.17.0.2	OPERATION=Submit Application Request	TARGET=ClientRMService	RESULT=SUCCESS	APPID=application_1559895028500_0001
2019-06-07 08:10:52,350 DEBUG org.apache.hadoop.yarn.server.resourcemanager.recovery.RMStateStore: Processing event of type STORE_APP
2019-06-07 08:10:52,350 DEBUG org.apache.hadoop.yarn.server.resourcemanager.recovery.RMStateStore: Processing event of type STORE_APP
2019-06-07 08:10:52,350 INFO org.apache.hadoop.yarn.server.resourcemanager.recovery.RMStateStore: Storing info for app: application_1559895028500_0001
2019-06-07 08:10:52,350 INFO org.apache.hadoop.yarn.server.resourcemanager.recovery.RMStateStore: Storing info for app: application_1559895028500_0001
2019-06-07 08:10:52,350 INFO org.apache.hadoop.yarn.server.resourcemanager.rmapp.RMAppImpl: application_1559895028500_0001 State change from NEW to NEW_SAVING on event=START
2019-06-07 08:10:52,350 INFO org.apache.hadoop.yarn.server.resourcemanager.rmapp.RMAppImpl: application_1559895028500_0001 State change from NEW to NEW_SAVING on event=START
2019-06-07 08:10:52,350 DEBUG org.apache.hadoop.yarn.server.resourcemanager.rmapp.RMAppImpl: Processing event for application_1559895028500_0001 of type APP_NEW_SAVED
2019-06-07 08:10:52,350 DEBUG org.apache.hadoop.yarn.server.resourcemanager.rmapp.RMAppImpl: Processing event for application_1559895028500_0001 of type APP_NEW_SAVED
2019-06-07 08:10:52,353 INFO org.apache.hadoop.yarn.server.resourcemanager.rmapp.RMAppImpl: application_1559895028500_0001 State change from NEW_SAVING to SUBMITTED on event=APP_NEW_SAVED
2019-06-07 08:10:52,353 INFO org.apache.hadoop.yarn.server.resourcemanager.rmapp.RMAppImpl: application_1559895028500_0001 State change from NEW_SAVING to SUBMITTED on event=APP_NEW_SAVED
2019-06-07 08:10:52,359 INFO org.apache.hadoop.yarn.server.resourcemanager.scheduler.capacity.ParentQueue: Application added - appId: application_1559895028500_0001 user: root leaf-queue of parent: root #applications: 1
2019-06-07 08:10:52,359 INFO org.apache.hadoop.yarn.server.resourcemanager.scheduler.capacity.ParentQueue: Application added - appId: application_1559895028500_0001 user: root leaf-queue of parent: root #applications: 1
2019-06-07 08:10:52,360 INFO org.apache.hadoop.yarn.server.resourcemanager.scheduler.capacity.CapacityScheduler: Accepted application application_1559895028500_0001 from user: root, in queue: default
2019-06-07 08:10:52,360 INFO org.apache.hadoop.yarn.server.resourcemanager.scheduler.capacity.CapacityScheduler: Accepted application application_1559895028500_0001 from user: root, in queue: default
2019-06-07 08:10:52,378 DEBUG org.apache.hadoop.yarn.server.resourcemanager.rmapp.RMAppImpl: Processing event for application_1559895028500_0001 of type APP_ACCEPTED
2019-06-07 08:10:52,378 DEBUG org.apache.hadoop.yarn.server.resourcemanager.rmapp.RMAppImpl: Processing event for application_1559895028500_0001 of type APP_ACCEPTED
2019-06-07 08:10:52,400 INFO org.apache.hadoop.yarn.server.resourcemanager.rmapp.RMAppImpl: application_1559895028500_0001 State change from SUBMITTED to ACCEPTED on event=APP_ACCEPTED
2019-06-07 08:10:52,400 INFO org.apache.hadoop.yarn.server.resourcemanager.rmapp.RMAppImpl: application_1559895028500_0001 State change from SUBMITTED to ACCEPTED on event=APP_ACCEPTED
2019-06-07 08:10:52,400 DEBUG org.apache.hadoop.yarn.server.resourcemanager.rmapp.attempt.RMAppAttemptImpl: Processing event for appattempt_1559895028500_0001_000001 of type START
2019-06-07 08:10:52,400 DEBUG org.apache.hadoop.yarn.server.resourcemanager.rmapp.attempt.RMAppAttemptImpl: Processing event for appattempt_1559895028500_0001_000001 of type START
2019-06-07 08:10:52,428 INFO org.apache.hadoop.yarn.server.resourcemanager.ApplicationMasterService: Registering app attempt : appattempt_1559895028500_0001_000001
2019-06-07 08:10:52,428 INFO org.apache.hadoop.yarn.server.resourcemanager.ApplicationMasterService: Registering app attempt : appattempt_1559895028500_0001_000001
2019-06-07 08:10:52,428 INFO org.apache.hadoop.yarn.server.resourcemanager.rmapp.attempt.RMAppAttemptImpl: appattempt_1559895028500_0001_000001 State change from NEW to SUBMITTED
2019-06-07 08:10:52,428 INFO org.apache.hadoop.yarn.server.resourcemanager.rmapp.attempt.RMAppAttemptImpl: appattempt_1559895028500_0001_000001 State change from NEW to SUBMITTED
2019-06-07 08:10:52,462 DEBUG org.apache.hadoop.yarn.server.resourcemanager.scheduler.capacity.LeafQueue: application application_1559895028500_0001 AMResource <memory:1024, vCores:1> maxAMResourcePerQueuePercent 0.1 amLimit <memory:1024, vCores:1> lastClusterResource <memory:8192, vCores:2> amIfStarted <memory:1024, vCores:1> AM node-partition name 
2019-06-07 08:10:52,462 DEBUG org.apache.hadoop.yarn.server.resourcemanager.scheduler.capacity.LeafQueue: application application_1559895028500_0001 AMResource <memory:1024, vCores:1> maxAMResourcePerQueuePercent 0.1 amLimit <memory:1024, vCores:1> lastClusterResource <memory:8192, vCores:2> amIfStarted <memory:1024, vCores:1> AM node-partition name 
2019-06-07 08:10:52,462 DEBUG org.apache.hadoop.yarn.server.resourcemanager.scheduler.capacity.LeafQueue: Effective user AM limit for "root":<memory:1024, vCores:1>. Effective weighted user AM limit: <memory:1024, vCores:1>. User weight: 1.0
2019-06-07 08:10:52,462 DEBUG org.apache.hadoop.yarn.server.resourcemanager.scheduler.capacity.LeafQueue: Effective user AM limit for "root":<memory:1024, vCores:1>. Effective weighted user AM limit: <memory:1024, vCores:1>. User weight: 1.0
2019-06-07 08:10:52,465 INFO org.apache.hadoop.yarn.server.resourcemanager.scheduler.capacity.LeafQueue: Application application_1559895028500_0001 from user: root activated in queue: default
2019-06-07 08:10:52,465 INFO org.apache.hadoop.yarn.server.resourcemanager.scheduler.capacity.LeafQueue: Application application_1559895028500_0001 from user: root activated in queue: default
2019-06-07 08:10:52,465 INFO org.apache.hadoop.yarn.server.resourcemanager.scheduler.capacity.LeafQueue: Application added - appId: application_1559895028500_0001 user: root, leaf-queue: default #user-pending-applications: 0 #user-active-applications: 1 #queue-pending-applications: 0 #queue-active-applications: 1
2019-06-07 08:10:52,465 INFO org.apache.hadoop.yarn.server.resourcemanager.scheduler.capacity.LeafQueue: Application added - appId: application_1559895028500_0001 user: root, leaf-queue: default #user-pending-applications: 0 #user-active-applications: 1 #queue-pending-applications: 0 #queue-active-applications: 1
2019-06-07 08:10:52,465 INFO org.apache.hadoop.yarn.server.resourcemanager.scheduler.capacity.CapacityScheduler: Added Application Attempt appattempt_1559895028500_0001_000001 to scheduler from user root in queue default
2019-06-07 08:10:52,465 INFO org.apache.hadoop.yarn.server.resourcemanager.scheduler.capacity.CapacityScheduler: Added Application Attempt appattempt_1559895028500_0001_000001 to scheduler from user root in queue default
2019-06-07 08:10:52,465 DEBUG org.apache.hadoop.yarn.server.resourcemanager.rmapp.attempt.RMAppAttemptImpl: Processing event for appattempt_1559895028500_0001_000001 of type ATTEMPT_ADDED
2019-06-07 08:10:52,465 DEBUG org.apache.hadoop.yarn.server.resourcemanager.rmapp.attempt.RMAppAttemptImpl: Processing event for appattempt_1559895028500_0001_000001 of type ATTEMPT_ADDED
2019-06-07 08:10:52,466 DEBUG org.apache.hadoop.yarn.server.resourcemanager.rmapp.attempt.RMAppAttemptImpl: Using blacklist for AM: additions([]) and removals([])
2019-06-07 08:10:52,466 DEBUG org.apache.hadoop.yarn.server.resourcemanager.rmapp.attempt.RMAppAttemptImpl: Using blacklist for AM: additions([]) and removals([])
2019-06-07 08:10:52,466 DEBUG org.apache.hadoop.yarn.server.resourcemanager.scheduler.capacity.CapacityScheduler: allocate: pre-update appattempt_1559895028500_0001_000001 ask size =1
2019-06-07 08:10:52,466 DEBUG org.apache.hadoop.yarn.server.resourcemanager.scheduler.capacity.CapacityScheduler: allocate: pre-update appattempt_1559895028500_0001_000001 ask size =1
2019-06-07 08:10:52,468 DEBUG org.apache.hadoop.yarn.server.resourcemanager.scheduler.ActiveUsersManager: User root added to activeUsers, currently: 1
2019-06-07 08:10:52,468 DEBUG org.apache.hadoop.yarn.server.resourcemanager.scheduler.ActiveUsersManager: User root added to activeUsers, currently: 1
2019-06-07 08:10:52,468 DEBUG org.apache.hadoop.yarn.server.resourcemanager.scheduler.capacity.CapacityScheduler: allocate: post-update
2019-06-07 08:10:52,468 DEBUG org.apache.hadoop.yarn.server.resourcemanager.scheduler.capacity.CapacityScheduler: allocate: post-update
2019-06-07 08:10:52,468 DEBUG org.apache.hadoop.yarn.server.resourcemanager.scheduler.SchedulerApplicationAttempt: showRequests: application=application_1559895028500_0001 headRoom=<memory:0, vCores:0> currentConsumption=0
2019-06-07 08:10:52,468 DEBUG org.apache.hadoop.yarn.server.resourcemanager.scheduler.SchedulerApplicationAttempt: showRequests: application=application_1559895028500_0001 headRoom=<memory:0, vCores:0> currentConsumption=0
2019-06-07 08:10:52,469 DEBUG org.apache.hadoop.yarn.server.resourcemanager.scheduler.SchedulerApplicationAttempt: showRequests: application=application_1559895028500_0001 request={Priority: 0, Capability: <memory:1024, vCores:1>, # Containers: 1, Location: *, Relax Locality: true, Node Label Expression: }
2019-06-07 08:10:52,469 DEBUG org.apache.hadoop.yarn.server.resourcemanager.scheduler.SchedulerApplicationAttempt: showRequests: application=application_1559895028500_0001 request={Priority: 0, Capability: <memory:1024, vCores:1>, # Containers: 1, Location: *, Relax Locality: true, Node Label Expression: }
2019-06-07 08:10:52,469 INFO org.apache.hadoop.yarn.server.resourcemanager.rmapp.attempt.RMAppAttemptImpl: appattempt_1559895028500_0001_000001 State change from SUBMITTED to SCHEDULED
2019-06-07 08:10:52,469 INFO org.apache.hadoop.yarn.server.resourcemanager.rmapp.attempt.RMAppAttemptImpl: appattempt_1559895028500_0001_000001 State change from SUBMITTED to SCHEDULED
2019-06-07 08:10:52,760 DEBUG org.apache.hadoop.yarn.server.resourcemanager.rmnode.RMNodeImpl: Processing slave2:40331 of type STATUS_UPDATE
2019-06-07 08:10:52,760 DEBUG org.apache.hadoop.yarn.server.resourcemanager.rmnode.RMNodeImpl: Processing slave2:40331 of type STATUS_UPDATE
2019-06-07 08:10:52,762 DEBUG org.apache.hadoop.yarn.server.resourcemanager.scheduler.capacity.CapacityScheduler: nodeUpdate: slave2:40331 clusterResources: <memory:8192, vCores:2>
2019-06-07 08:10:52,762 DEBUG org.apache.hadoop.yarn.server.resourcemanager.scheduler.capacity.CapacityScheduler: nodeUpdate: slave2:40331 clusterResources: <memory:8192, vCores:2>
2019-06-07 08:10:52,762 DEBUG org.apache.hadoop.yarn.server.resourcemanager.scheduler.capacity.CapacityScheduler: Node being looked for scheduling slave2:40331 availableResource: <memory:4096, vCores:1>
2019-06-07 08:10:52,762 DEBUG org.apache.hadoop.yarn.server.resourcemanager.scheduler.capacity.CapacityScheduler: Node being looked for scheduling slave2:40331 availableResource: <memory:4096, vCores:1>
2019-06-07 08:10:52,762 DEBUG org.apache.hadoop.yarn.server.resourcemanager.scheduler.capacity.CapacityScheduler: Trying to schedule on node: slave2, available: <memory:4096, vCores:1>
2019-06-07 08:10:52,762 DEBUG org.apache.hadoop.yarn.server.resourcemanager.scheduler.capacity.CapacityScheduler: Trying to schedule on node: slave2, available: <memory:4096, vCores:1>
2019-06-07 08:10:52,762 DEBUG org.apache.hadoop.yarn.server.resourcemanager.scheduler.capacity.ParentQueue: Trying to assign containers to child-queue of root
2019-06-07 08:10:52,762 DEBUG org.apache.hadoop.yarn.server.resourcemanager.scheduler.capacity.ParentQueue: Trying to assign containers to child-queue of root
2019-06-07 08:10:52,762 DEBUG org.apache.hadoop.yarn.server.resourcemanager.scheduler.capacity.ParentQueue: printChildQueues - queue: root child-queues: root.defaultusedCapacity=(0.0),  label=(*)
2019-06-07 08:10:52,762 DEBUG org.apache.hadoop.yarn.server.resourcemanager.scheduler.capacity.ParentQueue: printChildQueues - queue: root child-queues: root.defaultusedCapacity=(0.0),  label=(*)
2019-06-07 08:10:52,762 DEBUG org.apache.hadoop.yarn.server.resourcemanager.scheduler.capacity.ParentQueue: Trying to assign to queue: root.default stats: default: capacity=1.0, absoluteCapacity=1.0, usedResources=<memory:0, vCores:0>, usedCapacity=0.0, absoluteUsedCapacity=0.0, numApps=1, numContainers=0
2019-06-07 08:10:52,762 DEBUG org.apache.hadoop.yarn.server.resourcemanager.scheduler.capacity.ParentQueue: Trying to assign to queue: root.default stats: default: capacity=1.0, absoluteCapacity=1.0, usedResources=<memory:0, vCores:0>, usedCapacity=0.0, absoluteUsedCapacity=0.0, numApps=1, numContainers=0
2019-06-07 08:10:52,762 DEBUG org.apache.hadoop.yarn.server.resourcemanager.scheduler.capacity.LeafQueue: assignContainers: node=slave2 #applications=1
2019-06-07 08:10:52,762 DEBUG org.apache.hadoop.yarn.server.resourcemanager.scheduler.capacity.LeafQueue: assignContainers: node=slave2 #applications=1
2019-06-07 08:10:52,763 DEBUG org.apache.hadoop.yarn.server.resourcemanager.scheduler.capacity.LeafQueue: User limit computation for root in queue default userLimitPercent=100 userLimitFactor=1.0 required: <memory:1024, vCores:1> consumed: <memory:0, vCores:0> user-limit-resource: <memory:8192, vCores:1> queueCapacity: <memory:8192, vCores:1> qconsumed: <memory:0, vCores:0> consumedRatio: 0.0 currentCapacity: <memory:8192, vCores:1> activeUsers: 1.0 clusterCapacity: <memory:8192, vCores:2> resourceByLabel: <memory:8192, vCores:2> usageratio: 0.0 Partition:  maxUserLimit=<memory:8192, vCores:1> userWeight=1.0
2019-06-07 08:10:52,763 DEBUG org.apache.hadoop.yarn.server.resourcemanager.scheduler.capacity.LeafQueue: User limit computation for root in queue default userLimitPercent=100 userLimitFactor=1.0 required: <memory:1024, vCores:1> consumed: <memory:0, vCores:0> user-limit-resource: <memory:8192, vCores:1> queueCapacity: <memory:8192, vCores:1> qconsumed: <memory:0, vCores:0> consumedRatio: 0.0 currentCapacity: <memory:8192, vCores:1> activeUsers: 1.0 clusterCapacity: <memory:8192, vCores:2> resourceByLabel: <memory:8192, vCores:2> usageratio: 0.0 Partition:  maxUserLimit=<memory:8192, vCores:1> userWeight=1.0
2019-06-07 08:10:52,763 DEBUG org.apache.hadoop.yarn.server.resourcemanager.scheduler.capacity.LeafQueue: Headroom calculation for user root:  userLimit=<memory:8192, vCores:1> queueMaxAvailRes=<memory:8192, vCores:1> consumed=<memory:0, vCores:0>
2019-06-07 08:10:52,763 DEBUG org.apache.hadoop.yarn.server.resourcemanager.scheduler.capacity.LeafQueue: Headroom calculation for user root:  userLimit=<memory:8192, vCores:1> queueMaxAvailRes=<memory:8192, vCores:1> consumed=<memory:0, vCores:0>
2019-06-07 08:10:52,765 DEBUG org.apache.hadoop.yarn.server.resourcemanager.scheduler.common.fica.FiCaSchedulerApp: pre-assignContainers for application application_1559895028500_0001
2019-06-07 08:10:52,765 DEBUG org.apache.hadoop.yarn.server.resourcemanager.scheduler.common.fica.FiCaSchedulerApp: pre-assignContainers for application application_1559895028500_0001
2019-06-07 08:10:52,765 DEBUG org.apache.hadoop.yarn.server.resourcemanager.scheduler.capacity.LeafQueue: User limit computation for root in queue default userLimitPercent=100 userLimitFactor=1.0 required: <memory:1024, vCores:1> consumed: <memory:0, vCores:0> user-limit-resource: <memory:8192, vCores:1> queueCapacity: <memory:8192, vCores:1> qconsumed: <memory:0, vCores:0> consumedRatio: 0.0 currentCapacity: <memory:8192, vCores:1> activeUsers: 1.0 clusterCapacity: <memory:8192, vCores:2> resourceByLabel: <memory:8192, vCores:2> usageratio: 0.0 Partition:  maxUserLimit=<memory:8192, vCores:1> userWeight=1.0
2019-06-07 08:10:52,765 DEBUG org.apache.hadoop.yarn.server.resourcemanager.scheduler.capacity.LeafQueue: User limit computation for root in queue default userLimitPercent=100 userLimitFactor=1.0 required: <memory:1024, vCores:1> consumed: <memory:0, vCores:0> user-limit-resource: <memory:8192, vCores:1> queueCapacity: <memory:8192, vCores:1> qconsumed: <memory:0, vCores:0> consumedRatio: 0.0 currentCapacity: <memory:8192, vCores:1> activeUsers: 1.0 clusterCapacity: <memory:8192, vCores:2> resourceByLabel: <memory:8192, vCores:2> usageratio: 0.0 Partition:  maxUserLimit=<memory:8192, vCores:1> userWeight=1.0
2019-06-07 08:10:52,765 DEBUG org.apache.hadoop.yarn.server.resourcemanager.scheduler.SchedulerApplicationAttempt: showRequests: application=application_1559895028500_0001 headRoom=<memory:8192, vCores:2> currentConsumption=0
2019-06-07 08:10:52,765 DEBUG org.apache.hadoop.yarn.server.resourcemanager.scheduler.SchedulerApplicationAttempt: showRequests: application=application_1559895028500_0001 headRoom=<memory:8192, vCores:2> currentConsumption=0
2019-06-07 08:10:52,766 DEBUG org.apache.hadoop.yarn.server.resourcemanager.scheduler.SchedulerApplicationAttempt: showRequests: application=application_1559895028500_0001 request={Priority: 0, Capability: <memory:1024, vCores:1>, # Containers: 1, Location: *, Relax Locality: true, Node Label Expression: }
2019-06-07 08:10:52,766 DEBUG org.apache.hadoop.yarn.server.resourcemanager.scheduler.SchedulerApplicationAttempt: showRequests: application=application_1559895028500_0001 request={Priority: 0, Capability: <memory:1024, vCores:1>, # Containers: 1, Location: *, Relax Locality: true, Node Label Expression: }
2019-06-07 08:10:52,767 DEBUG org.apache.hadoop.yarn.server.resourcemanager.scheduler.capacity.allocator.IncreaseContainerAllocator: Skip allocating increase request since we don't have any increase request on this node=slave2:40331
2019-06-07 08:10:52,767 DEBUG org.apache.hadoop.yarn.server.resourcemanager.scheduler.capacity.allocator.IncreaseContainerAllocator: Skip allocating increase request since we don't have any increase request on this node=slave2:40331
2019-06-07 08:10:52,770 DEBUG org.apache.hadoop.yarn.server.resourcemanager.scheduler.capacity.allocator.RegularContainerAllocator: assignContainers: node=slave2 application=application_1559895028500_0001 priority=0 request={Priority: 0, Capability: <memory:1024, vCores:1>, # Containers: 1, Location: *, Relax Locality: true, Node Label Expression: } type=OFF_SWITCH
2019-06-07 08:10:52,770 DEBUG org.apache.hadoop.yarn.server.resourcemanager.scheduler.capacity.allocator.RegularContainerAllocator: assignContainers: node=slave2 application=application_1559895028500_0001 priority=0 request={Priority: 0, Capability: <memory:1024, vCores:1>, # Containers: 1, Location: *, Relax Locality: true, Node Label Expression: } type=OFF_SWITCH
2019-06-07 08:10:52,777 DEBUG org.apache.hadoop.yarn.server.resourcemanager.rmnode.RMNodeImpl: Processing slave1:41069 of type STATUS_UPDATE
2019-06-07 08:10:52,777 DEBUG org.apache.hadoop.yarn.server.resourcemanager.rmnode.RMNodeImpl: Processing slave1:41069 of type STATUS_UPDATE
2019-06-07 08:10:52,877 DEBUG org.apache.hadoop.yarn.server.resourcemanager.scheduler.ActiveUsersManager: User root removed from activeUsers, currently: 0
2019-06-07 08:10:52,877 DEBUG org.apache.hadoop.yarn.server.resourcemanager.scheduler.ActiveUsersManager: User root removed from activeUsers, currently: 0
2019-06-07 08:10:52,877 DEBUG org.apache.hadoop.yarn.server.resourcemanager.scheduler.AppSchedulingInfo: allocate: applicationId=application_1559895028500_0001 container=container_1559895028500_0001_01_000001 host=slave2:40331 user=root resource=<memory:1024, vCores:1> type=OFF_SWITCH
2019-06-07 08:10:52,877 DEBUG org.apache.hadoop.yarn.server.resourcemanager.scheduler.AppSchedulingInfo: allocate: applicationId=application_1559895028500_0001 container=container_1559895028500_0001_01_000001 host=slave2:40331 user=root resource=<memory:1024, vCores:1> type=OFF_SWITCH
2019-06-07 08:10:52,878 DEBUG org.apache.hadoop.yarn.server.resourcemanager.rmcontainer.RMContainerImpl: Processing container_1559895028500_0001_01_000001 of type START
2019-06-07 08:10:52,878 DEBUG org.apache.hadoop.yarn.server.resourcemanager.rmcontainer.RMContainerImpl: Processing container_1559895028500_0001_01_000001 of type START
2019-06-07 08:10:52,878 INFO org.apache.hadoop.yarn.server.resourcemanager.rmcontainer.RMContainerImpl: container_1559895028500_0001_01_000001 Container Transitioned from NEW to ALLOCATED
2019-06-07 08:10:52,878 INFO org.apache.hadoop.yarn.server.resourcemanager.rmcontainer.RMContainerImpl: container_1559895028500_0001_01_000001 Container Transitioned from NEW to ALLOCATED
2019-06-07 08:10:52,878 DEBUG org.apache.hadoop.yarn.server.resourcemanager.rmapp.attempt.RMAppAttemptImpl: Processing event for appattempt_1559895028500_0001_000001 of type CONTAINER_ALLOCATED
2019-06-07 08:10:52,878 DEBUG org.apache.hadoop.yarn.server.resourcemanager.rmapp.attempt.RMAppAttemptImpl: Processing event for appattempt_1559895028500_0001_000001 of type CONTAINER_ALLOCATED
2019-06-07 08:10:52,878 DEBUG org.apache.hadoop.yarn.server.resourcemanager.scheduler.common.fica.FiCaSchedulerApp: allocate: applicationAttemptId=appattempt_1559895028500_0001_000001 container=container_1559895028500_0001_01_000001 host=slave2 type=OFF_SWITCH
2019-06-07 08:10:52,878 DEBUG org.apache.hadoop.yarn.server.resourcemanager.scheduler.common.fica.FiCaSchedulerApp: allocate: applicationAttemptId=appattempt_1559895028500_0001_000001 container=container_1559895028500_0001_01_000001 host=slave2 type=OFF_SWITCH
2019-06-07 08:10:52,878 INFO org.apache.hadoop.yarn.server.resourcemanager.RMAuditLogger: USER=root	OPERATION=AM Allocated Container	TARGET=SchedulerApp	RESULT=SUCCESS	APPID=application_1559895028500_0001	CONTAINERID=container_1559895028500_0001_01_000001
2019-06-07 08:10:52,878 INFO org.apache.hadoop.yarn.server.resourcemanager.RMAuditLogger: USER=root	OPERATION=AM Allocated Container	TARGET=SchedulerApp	RESULT=SUCCESS	APPID=application_1559895028500_0001	CONTAINERID=container_1559895028500_0001_01_000001
2019-06-07 08:10:52,879 INFO org.apache.hadoop.yarn.server.resourcemanager.scheduler.SchedulerNode: Assigned container container_1559895028500_0001_01_000001 of capacity <memory:1024, vCores:1> on host slave2:40331, which has 1 containers, <memory:1024, vCores:1> used and <memory:3072, vCores:0> available after allocation
2019-06-07 08:10:52,879 INFO org.apache.hadoop.yarn.server.resourcemanager.scheduler.SchedulerNode: Assigned container container_1559895028500_0001_01_000001 of capacity <memory:1024, vCores:1> on host slave2:40331, which has 1 containers, <memory:1024, vCores:1> used and <memory:3072, vCores:0> available after allocation
2019-06-07 08:10:52,880 INFO org.apache.hadoop.yarn.server.resourcemanager.scheduler.capacity.allocator.AbstractContainerAllocator: assignedContainer application attempt=appattempt_1559895028500_0001_000001 container=container_1559895028500_0001_01_000001 queue=org.apache.hadoop.yarn.server.resourcemanager.scheduler.capacity.allocator.RegularContainerAllocator@fd9a5af clusterResource=<memory:8192, vCores:2> type=OFF_SWITCH requestedPartition=
2019-06-07 08:10:52,880 INFO org.apache.hadoop.yarn.server.resourcemanager.scheduler.capacity.allocator.AbstractContainerAllocator: assignedContainer application attempt=appattempt_1559895028500_0001_000001 container=container_1559895028500_0001_01_000001 queue=org.apache.hadoop.yarn.server.resourcemanager.scheduler.capacity.allocator.RegularContainerAllocator@fd9a5af clusterResource=<memory:8192, vCores:2> type=OFF_SWITCH requestedPartition=
2019-06-07 08:10:52,885 DEBUG org.apache.hadoop.yarn.server.resourcemanager.scheduler.capacity.LeafQueue: post-assignContainers for application application_1559895028500_0001
2019-06-07 08:10:52,885 DEBUG org.apache.hadoop.yarn.server.resourcemanager.scheduler.capacity.LeafQueue: post-assignContainers for application application_1559895028500_0001
2019-06-07 08:10:52,899 INFO org.apache.hadoop.yarn.server.resourcemanager.security.NMTokenSecretManagerInRM: Sending NMToken for nodeId : slave2:40331 for container : container_1559895028500_0001_01_000001
2019-06-07 08:10:52,899 INFO org.apache.hadoop.yarn.server.resourcemanager.security.NMTokenSecretManagerInRM: Sending NMToken for nodeId : slave2:40331 for container : container_1559895028500_0001_01_000001
2019-06-07 08:10:52,906 DEBUG org.apache.hadoop.yarn.server.resourcemanager.rmcontainer.RMContainerImpl: Processing container_1559895028500_0001_01_000001 of type ACQUIRED
2019-06-07 08:10:52,906 DEBUG org.apache.hadoop.yarn.server.resourcemanager.rmcontainer.RMContainerImpl: Processing container_1559895028500_0001_01_000001 of type ACQUIRED
2019-06-07 08:10:52,908 INFO org.apache.hadoop.yarn.server.resourcemanager.rmcontainer.RMContainerImpl: container_1559895028500_0001_01_000001 Container Transitioned from ALLOCATED to ACQUIRED
2019-06-07 08:10:52,908 INFO org.apache.hadoop.yarn.server.resourcemanager.rmcontainer.RMContainerImpl: container_1559895028500_0001_01_000001 Container Transitioned from ALLOCATED to ACQUIRED
2019-06-07 08:10:52,908 DEBUG org.apache.hadoop.yarn.server.resourcemanager.scheduler.capacity.LeafQueue: User limit computation for root in queue default userLimitPercent=100 userLimitFactor=1.0 required: <memory:1024, vCores:1> consumed: <memory:0, vCores:0> user-limit-resource: <memory:8192, vCores:1> queueCapacity: <memory:8192, vCores:1> qconsumed: <memory:0, vCores:0> consumedRatio: 0.0 currentCapacity: <memory:8192, vCores:1> activeUsers: 0.0 clusterCapacity: <memory:8192, vCores:2> resourceByLabel: <memory:8192, vCores:2> usageratio: 0.0 Partition:  maxUserLimit=<memory:8192, vCores:1> userWeight=1.0
2019-06-07 08:10:52,908 DEBUG org.apache.hadoop.yarn.server.resourcemanager.scheduler.capacity.LeafQueue: User limit computation for root in queue default userLimitPercent=100 userLimitFactor=1.0 required: <memory:1024, vCores:1> consumed: <memory:0, vCores:0> user-limit-resource: <memory:8192, vCores:1> queueCapacity: <memory:8192, vCores:1> qconsumed: <memory:0, vCores:0> consumedRatio: 0.0 currentCapacity: <memory:8192, vCores:1> activeUsers: 0.0 clusterCapacity: <memory:8192, vCores:2> resourceByLabel: <memory:8192, vCores:2> usageratio: 0.0 Partition:  maxUserLimit=<memory:8192, vCores:1> userWeight=1.0
2019-06-07 08:10:52,908 INFO org.apache.hadoop.yarn.server.resourcemanager.security.NMTokenSecretManagerInRM: Clear node set for appattempt_1559895028500_0001_000001
2019-06-07 08:10:52,908 INFO org.apache.hadoop.yarn.server.resourcemanager.security.NMTokenSecretManagerInRM: Clear node set for appattempt_1559895028500_0001_000001
2019-06-07 08:10:52,908 INFO org.apache.hadoop.yarn.server.resourcemanager.rmapp.attempt.RMAppAttemptImpl: Storing attempt: AppId: application_1559895028500_0001 AttemptId: appattempt_1559895028500_0001_000001 MasterContainer: Container: [ContainerId: container_1559895028500_0001_01_000001, Version: 0, NodeId: slave2:40331, NodeHttpAddress: slave2:8042, Resource: <memory:1024, vCores:1>, Priority: 0, Token: Token { kind: ContainerToken, service: 172.17.0.4:40331 }, ]
2019-06-07 08:10:52,908 INFO org.apache.hadoop.yarn.server.resourcemanager.rmapp.attempt.RMAppAttemptImpl: Storing attempt: AppId: application_1559895028500_0001 AttemptId: appattempt_1559895028500_0001_000001 MasterContainer: Container: [ContainerId: container_1559895028500_0001_01_000001, Version: 0, NodeId: slave2:40331, NodeHttpAddress: slave2:8042, Resource: <memory:1024, vCores:1>, Priority: 0, Token: Token { kind: ContainerToken, service: 172.17.0.4:40331 }, ]
2019-06-07 08:10:52,909 DEBUG org.apache.hadoop.yarn.server.resourcemanager.scheduler.capacity.LeafQueue: User limit computation for root in queue default userLimitPercent=100 userLimitFactor=1.0 required: <memory:1024, vCores:1> consumed: <memory:1024, vCores:1> user-limit-resource: <memory:8192, vCores:1> queueCapacity: <memory:8192, vCores:1> qconsumed: <memory:1024, vCores:1> consumedRatio: 0.0 currentCapacity: <memory:8192, vCores:1> activeUsers: 0.0 clusterCapacity: <memory:8192, vCores:2> resourceByLabel: <memory:8192, vCores:2> usageratio: 0.125 Partition:  maxUserLimit=<memory:8192, vCores:1> userWeight=1.0
2019-06-07 08:10:52,909 DEBUG org.apache.hadoop.yarn.server.resourcemanager.scheduler.capacity.LeafQueue: User limit computation for root in queue default userLimitPercent=100 userLimitFactor=1.0 required: <memory:1024, vCores:1> consumed: <memory:1024, vCores:1> user-limit-resource: <memory:8192, vCores:1> queueCapacity: <memory:8192, vCores:1> qconsumed: <memory:1024, vCores:1> consumedRatio: 0.0 currentCapacity: <memory:8192, vCores:1> activeUsers: 0.0 clusterCapacity: <memory:8192, vCores:2> resourceByLabel: <memory:8192, vCores:2> usageratio: 0.125 Partition:  maxUserLimit=<memory:8192, vCores:1> userWeight=1.0
2019-06-07 08:10:52,910 DEBUG org.apache.hadoop.yarn.server.resourcemanager.scheduler.capacity.LeafQueue: User limit computation for root in queue default userLimitPercent=100 userLimitFactor=1.0 required: <memory:1024, vCores:1> consumed: <memory:1024, vCores:1> user-limit-resource: <memory:8192, vCores:1> queueCapacity: <memory:8192, vCores:1> qconsumed: <memory:1024, vCores:1> consumedRatio: 0.0 currentCapacity: <memory:8192, vCores:1> activeUsers: 0.0 clusterCapacity: <memory:8192, vCores:2> resourceByLabel: <memory:8192, vCores:2> usageratio: 0.125 Partition:  maxUserLimit=<memory:8192, vCores:1> userWeight=1.0
2019-06-07 08:10:52,910 DEBUG org.apache.hadoop.yarn.server.resourcemanager.scheduler.capacity.LeafQueue: User limit computation for root in queue default userLimitPercent=100 userLimitFactor=1.0 required: <memory:1024, vCores:1> consumed: <memory:1024, vCores:1> user-limit-resource: <memory:8192, vCores:1> queueCapacity: <memory:8192, vCores:1> qconsumed: <memory:1024, vCores:1> consumedRatio: 0.0 currentCapacity: <memory:8192, vCores:1> activeUsers: 0.0 clusterCapacity: <memory:8192, vCores:2> resourceByLabel: <memory:8192, vCores:2> usageratio: 0.125 Partition:  maxUserLimit=<memory:8192, vCores:1> userWeight=1.0
2019-06-07 08:10:52,910 DEBUG org.apache.hadoop.yarn.server.resourcemanager.scheduler.capacity.LeafQueue: User limit computation for root in queue default userLimitPercent=100 userLimitFactor=1.0 required: <memory:1024, vCores:1> consumed: <memory:1024, vCores:1> user-limit-resource: <memory:8192, vCores:1> queueCapacity: <memory:8192, vCores:1> qconsumed: <memory:1024, vCores:1> consumedRatio: 0.0 currentCapacity: <memory:8192, vCores:1> activeUsers: 0.0 clusterCapacity: <memory:8192, vCores:2> resourceByLabel: <memory:8192, vCores:2> usageratio: 0.125 Partition:  maxUserLimit=<memory:8192, vCores:1> userWeight=1.0
2019-06-07 08:10:52,910 DEBUG org.apache.hadoop.yarn.server.resourcemanager.scheduler.capacity.LeafQueue: User limit computation for root in queue default userLimitPercent=100 userLimitFactor=1.0 required: <memory:1024, vCores:1> consumed: <memory:1024, vCores:1> user-limit-resource: <memory:8192, vCores:1> queueCapacity: <memory:8192, vCores:1> qconsumed: <memory:1024, vCores:1> consumedRatio: 0.0 currentCapacity: <memory:8192, vCores:1> activeUsers: 0.0 clusterCapacity: <memory:8192, vCores:2> resourceByLabel: <memory:8192, vCores:2> usageratio: 0.125 Partition:  maxUserLimit=<memory:8192, vCores:1> userWeight=1.0
2019-06-07 08:10:52,910 DEBUG org.apache.hadoop.yarn.server.resourcemanager.scheduler.capacity.LeafQueue: default user=root used=<memory:1024, vCores:1> numContainers=1 headroom = <memory:7168, vCores:1> user-resources=<memory:1024, vCores:1>
2019-06-07 08:10:52,910 DEBUG org.apache.hadoop.yarn.server.resourcemanager.scheduler.capacity.LeafQueue: default user=root used=<memory:1024, vCores:1> numContainers=1 headroom = <memory:7168, vCores:1> user-resources=<memory:1024, vCores:1>
2019-06-07 08:10:52,910 DEBUG org.apache.hadoop.yarn.server.resourcemanager.scheduler.capacity.ParentQueue: Assigned to queue: root.default stats: default: capacity=1.0, absoluteCapacity=1.0, usedResources=<memory:1024, vCores:1>, usedCapacity=0.125, absoluteUsedCapacity=0.125, numApps=1, numContainers=1 --> <memory:1024, vCores:1>, OFF_SWITCH
2019-06-07 08:10:52,910 DEBUG org.apache.hadoop.yarn.server.resourcemanager.scheduler.capacity.ParentQueue: Assigned to queue: root.default stats: default: capacity=1.0, absoluteCapacity=1.0, usedResources=<memory:1024, vCores:1>, usedCapacity=0.125, absoluteUsedCapacity=0.125, numApps=1, numContainers=1 --> <memory:1024, vCores:1>, OFF_SWITCH
2019-06-07 08:10:52,910 INFO org.apache.hadoop.yarn.server.resourcemanager.scheduler.capacity.ParentQueue: Re-sorting assigned queue: root.default stats: default: capacity=1.0, absoluteCapacity=1.0, usedResources=<memory:1024, vCores:1>, usedCapacity=0.125, absoluteUsedCapacity=0.125, numApps=1, numContainers=1
2019-06-07 08:10:52,910 INFO org.apache.hadoop.yarn.server.resourcemanager.scheduler.capacity.ParentQueue: Re-sorting assigned queue: root.default stats: default: capacity=1.0, absoluteCapacity=1.0, usedResources=<memory:1024, vCores:1>, usedCapacity=0.125, absoluteUsedCapacity=0.125, numApps=1, numContainers=1
2019-06-07 08:10:52,910 DEBUG org.apache.hadoop.yarn.server.resourcemanager.scheduler.capacity.ParentQueue: printChildQueues - queue: root child-queues: root.defaultusedCapacity=(0.125),  label=(*)
2019-06-07 08:10:52,910 DEBUG org.apache.hadoop.yarn.server.resourcemanager.scheduler.capacity.ParentQueue: printChildQueues - queue: root child-queues: root.defaultusedCapacity=(0.125),  label=(*)
2019-06-07 08:10:52,910 INFO org.apache.hadoop.yarn.server.resourcemanager.scheduler.capacity.ParentQueue: assignedContainer queue=root usedCapacity=0.125 absoluteUsedCapacity=0.125 used=<memory:1024, vCores:1> cluster=<memory:8192, vCores:2>
2019-06-07 08:10:52,910 INFO org.apache.hadoop.yarn.server.resourcemanager.scheduler.capacity.ParentQueue: assignedContainer queue=root usedCapacity=0.125 absoluteUsedCapacity=0.125 used=<memory:1024, vCores:1> cluster=<memory:8192, vCores:2>
2019-06-07 08:10:52,910 DEBUG org.apache.hadoop.yarn.server.resourcemanager.scheduler.capacity.ParentQueue: ParentQ=root assignedSoFarInThisIteration=<memory:1024, vCores:1> usedCapacity=0.125 absoluteUsedCapacity=0.125
2019-06-07 08:10:52,910 DEBUG org.apache.hadoop.yarn.server.resourcemanager.scheduler.capacity.ParentQueue: ParentQ=root assignedSoFarInThisIteration=<memory:1024, vCores:1> usedCapacity=0.125 absoluteUsedCapacity=0.125
2019-06-07 08:10:52,911 DEBUG org.apache.hadoop.yarn.server.resourcemanager.scheduler.capacity.ParentQueue: Assigned maximum number of off-switch containers: 1, assignments so far: resource:<memory:1024, vCores:1>; type:OFF_SWITCH; excessReservation:null; applicationid:null; skipped:NONE; fulfilled reservation:false; allocations(count/resource):1/<memory:1024, vCores:1>; reservations(count/resource):0/<memory:0, vCores:0>
2019-06-07 08:10:52,911 DEBUG org.apache.hadoop.yarn.server.resourcemanager.scheduler.capacity.ParentQueue: Assigned maximum number of off-switch containers: 1, assignments so far: resource:<memory:1024, vCores:1>; type:OFF_SWITCH; excessReservation:null; applicationid:null; skipped:NONE; fulfilled reservation:false; allocations(count/resource):1/<memory:1024, vCores:1>; reservations(count/resource):0/<memory:0, vCores:0>
2019-06-07 08:10:52,911 DEBUG org.apache.hadoop.yarn.server.resourcemanager.scheduler.capacity.CapacityScheduler: nodeUpdate: slave1:41069 clusterResources: <memory:8192, vCores:2>
2019-06-07 08:10:52,911 DEBUG org.apache.hadoop.yarn.server.resourcemanager.scheduler.capacity.CapacityScheduler: nodeUpdate: slave1:41069 clusterResources: <memory:8192, vCores:2>
2019-06-07 08:10:52,911 DEBUG org.apache.hadoop.yarn.server.resourcemanager.scheduler.capacity.CapacityScheduler: Node being looked for scheduling slave1:41069 availableResource: <memory:4096, vCores:1>
2019-06-07 08:10:52,911 DEBUG org.apache.hadoop.yarn.server.resourcemanager.scheduler.capacity.CapacityScheduler: Node being looked for scheduling slave1:41069 availableResource: <memory:4096, vCores:1>
2019-06-07 08:10:52,911 DEBUG org.apache.hadoop.yarn.server.resourcemanager.scheduler.capacity.CapacityScheduler: Trying to schedule on node: slave1, available: <memory:4096, vCores:1>
2019-06-07 08:10:52,911 DEBUG org.apache.hadoop.yarn.server.resourcemanager.scheduler.capacity.CapacityScheduler: Trying to schedule on node: slave1, available: <memory:4096, vCores:1>
2019-06-07 08:10:52,911 DEBUG org.apache.hadoop.yarn.server.resourcemanager.scheduler.capacity.ParentQueue: Skip this queue=root, because it doesn't need more resource, schedulingMode=RESPECT_PARTITION_EXCLUSIVITY node-partition=
2019-06-07 08:10:52,911 DEBUG org.apache.hadoop.yarn.server.resourcemanager.scheduler.capacity.ParentQueue: Skip this queue=root, because it doesn't need more resource, schedulingMode=RESPECT_PARTITION_EXCLUSIVITY node-partition=
2019-06-07 08:10:52,919 INFO org.apache.hadoop.yarn.server.resourcemanager.rmapp.attempt.RMAppAttemptImpl: appattempt_1559895028500_0001_000001 State change from SCHEDULED to ALLOCATED_SAVING
2019-06-07 08:10:52,919 DEBUG org.apache.hadoop.yarn.server.resourcemanager.recovery.RMStateStore: Processing event of type STORE_APP_ATTEMPT
2019-06-07 08:10:52,919 DEBUG org.apache.hadoop.yarn.server.resourcemanager.recovery.RMStateStore: Processing event of type STORE_APP_ATTEMPT
2019-06-07 08:10:52,931 DEBUG org.apache.hadoop.yarn.server.resourcemanager.recovery.RMStateStore: Storing info for attempt: appattempt_1559895028500_0001_000001
2019-06-07 08:10:52,931 DEBUG org.apache.hadoop.yarn.server.resourcemanager.recovery.RMStateStore: Storing info for attempt: appattempt_1559895028500_0001_000001
2019-06-07 08:10:52,919 INFO org.apache.hadoop.yarn.server.resourcemanager.rmapp.attempt.RMAppAttemptImpl: appattempt_1559895028500_0001_000001 State change from SCHEDULED to ALLOCATED_SAVING
2019-06-07 08:10:52,932 DEBUG org.apache.hadoop.yarn.server.resourcemanager.rmapp.RMAppImpl: Processing event for application_1559895028500_0001 of type APP_RUNNING_ON_NODE
2019-06-07 08:10:52,932 DEBUG org.apache.hadoop.yarn.server.resourcemanager.rmapp.RMAppImpl: Processing event for application_1559895028500_0001 of type APP_RUNNING_ON_NODE
2019-06-07 08:10:52,937 DEBUG org.apache.hadoop.yarn.server.resourcemanager.rmapp.attempt.RMAppAttemptImpl: Processing event for appattempt_1559895028500_0001_000001 of type ATTEMPT_NEW_SAVED
2019-06-07 08:10:52,937 DEBUG org.apache.hadoop.yarn.server.resourcemanager.rmapp.attempt.RMAppAttemptImpl: Processing event for appattempt_1559895028500_0001_000001 of type ATTEMPT_NEW_SAVED
2019-06-07 08:10:52,938 INFO org.apache.hadoop.yarn.server.resourcemanager.rmapp.attempt.RMAppAttemptImpl: appattempt_1559895028500_0001_000001 State change from ALLOCATED_SAVING to ALLOCATED
2019-06-07 08:10:52,938 INFO org.apache.hadoop.yarn.server.resourcemanager.rmapp.attempt.RMAppAttemptImpl: appattempt_1559895028500_0001_000001 State change from ALLOCATED_SAVING to ALLOCATED
2019-06-07 08:10:52,941 INFO org.apache.hadoop.yarn.server.resourcemanager.amlauncher.AMLauncher: Launching masterappattempt_1559895028500_0001_000001
2019-06-07 08:10:52,941 INFO org.apache.hadoop.yarn.server.resourcemanager.amlauncher.AMLauncher: Launching masterappattempt_1559895028500_0001_000001
2019-06-07 08:10:53,013 INFO org.apache.hadoop.yarn.server.resourcemanager.amlauncher.AMLauncher: Setting up container Container: [ContainerId: container_1559895028500_0001_01_000001, Version: 0, NodeId: slave2:40331, NodeHttpAddress: slave2:8042, Resource: <memory:1024, vCores:1>, Priority: 0, Token: Token { kind: ContainerToken, service: 172.17.0.4:40331 }, ] for AM appattempt_1559895028500_0001_000001
2019-06-07 08:10:53,013 INFO org.apache.hadoop.yarn.server.resourcemanager.amlauncher.AMLauncher: Setting up container Container: [ContainerId: container_1559895028500_0001_01_000001, Version: 0, NodeId: slave2:40331, NodeHttpAddress: slave2:8042, Resource: <memory:1024, vCores:1>, Priority: 0, Token: Token { kind: ContainerToken, service: 172.17.0.4:40331 }, ] for AM appattempt_1559895028500_0001_000001
2019-06-07 08:10:53,014 INFO org.apache.hadoop.yarn.server.resourcemanager.security.AMRMTokenSecretManager: Create AMRMToken for ApplicationAttempt: appattempt_1559895028500_0001_000001
2019-06-07 08:10:53,014 INFO org.apache.hadoop.yarn.server.resourcemanager.security.AMRMTokenSecretManager: Create AMRMToken for ApplicationAttempt: appattempt_1559895028500_0001_000001
2019-06-07 08:10:53,017 INFO org.apache.hadoop.yarn.server.resourcemanager.security.AMRMTokenSecretManager: Creating password for appattempt_1559895028500_0001_000001
2019-06-07 08:10:53,017 INFO org.apache.hadoop.yarn.server.resourcemanager.security.AMRMTokenSecretManager: Creating password for appattempt_1559895028500_0001_000001
2019-06-07 08:10:53,293 INFO org.apache.hadoop.yarn.server.resourcemanager.amlauncher.AMLauncher: Done launching container Container: [ContainerId: container_1559895028500_0001_01_000001, Version: 0, NodeId: slave2:40331, NodeHttpAddress: slave2:8042, Resource: <memory:1024, vCores:1>, Priority: 0, Token: Token { kind: ContainerToken, service: 172.17.0.4:40331 }, ] for AM appattempt_1559895028500_0001_000001
2019-06-07 08:10:53,293 INFO org.apache.hadoop.yarn.server.resourcemanager.amlauncher.AMLauncher: Done launching container Container: [ContainerId: container_1559895028500_0001_01_000001, Version: 0, NodeId: slave2:40331, NodeHttpAddress: slave2:8042, Resource: <memory:1024, vCores:1>, Priority: 0, Token: Token { kind: ContainerToken, service: 172.17.0.4:40331 }, ] for AM appattempt_1559895028500_0001_000001
2019-06-07 08:10:53,299 DEBUG org.apache.hadoop.yarn.server.resourcemanager.rmapp.attempt.RMAppAttemptImpl: Processing event for appattempt_1559895028500_0001_000001 of type LAUNCHED
2019-06-07 08:10:53,299 DEBUG org.apache.hadoop.yarn.server.resourcemanager.rmapp.attempt.RMAppAttemptImpl: Processing event for appattempt_1559895028500_0001_000001 of type LAUNCHED
2019-06-07 08:10:53,299 INFO org.apache.hadoop.yarn.server.resourcemanager.rmapp.attempt.RMAppAttemptImpl: appattempt_1559895028500_0001_000001 State change from ALLOCATED to LAUNCHED
2019-06-07 08:10:53,299 INFO org.apache.hadoop.yarn.server.resourcemanager.rmapp.attempt.RMAppAttemptImpl: appattempt_1559895028500_0001_000001 State change from ALLOCATED to LAUNCHED
2019-06-07 08:10:53,782 DEBUG org.apache.hadoop.yarn.server.resourcemanager.rmnode.RMNodeImpl: Processing slave1:41069 of type STATUS_UPDATE
2019-06-07 08:10:53,782 DEBUG org.apache.hadoop.yarn.server.resourcemanager.rmnode.RMNodeImpl: Processing slave1:41069 of type STATUS_UPDATE
2019-06-07 08:10:53,782 DEBUG org.apache.hadoop.yarn.server.resourcemanager.scheduler.capacity.CapacityScheduler: nodeUpdate: slave1:41069 clusterResources: <memory:8192, vCores:2>
2019-06-07 08:10:53,782 DEBUG org.apache.hadoop.yarn.server.resourcemanager.scheduler.capacity.CapacityScheduler: nodeUpdate: slave1:41069 clusterResources: <memory:8192, vCores:2>
2019-06-07 08:10:53,782 DEBUG org.apache.hadoop.yarn.server.resourcemanager.scheduler.capacity.CapacityScheduler: Node being looked for scheduling slave1:41069 availableResource: <memory:4096, vCores:1>
2019-06-07 08:10:53,782 DEBUG org.apache.hadoop.yarn.server.resourcemanager.scheduler.capacity.CapacityScheduler: Node being looked for scheduling slave1:41069 availableResource: <memory:4096, vCores:1>
2019-06-07 08:10:53,782 DEBUG org.apache.hadoop.yarn.server.resourcemanager.scheduler.capacity.CapacityScheduler: Trying to schedule on node: slave1, available: <memory:4096, vCores:1>
2019-06-07 08:10:53,782 DEBUG org.apache.hadoop.yarn.server.resourcemanager.scheduler.capacity.CapacityScheduler: Trying to schedule on node: slave1, available: <memory:4096, vCores:1>
2019-06-07 08:10:53,782 DEBUG org.apache.hadoop.yarn.server.resourcemanager.scheduler.capacity.ParentQueue: Skip this queue=root, because it doesn't need more resource, schedulingMode=RESPECT_PARTITION_EXCLUSIVITY node-partition=
2019-06-07 08:10:53,782 DEBUG org.apache.hadoop.yarn.server.resourcemanager.scheduler.capacity.ParentQueue: Skip this queue=root, because it doesn't need more resource, schedulingMode=RESPECT_PARTITION_EXCLUSIVITY node-partition=
2019-06-07 08:10:53,791 DEBUG org.apache.hadoop.yarn.server.resourcemanager.rmnode.RMNodeImpl: Processing slave2:40331 of type STATUS_UPDATE
2019-06-07 08:10:53,791 DEBUG org.apache.hadoop.yarn.server.resourcemanager.rmnode.RMNodeImpl: Processing slave2:40331 of type STATUS_UPDATE
2019-06-07 08:10:53,796 DEBUG org.apache.hadoop.yarn.server.resourcemanager.rmnode.RMNodeImpl: Container container_1559895028500_0001_01_000001 is the first container get launched for application application_1559895028500_0001
2019-06-07 08:10:53,796 DEBUG org.apache.hadoop.yarn.server.resourcemanager.rmnode.RMNodeImpl: Container container_1559895028500_0001_01_000001 is the first container get launched for application application_1559895028500_0001
2019-06-07 08:10:53,797 DEBUG org.apache.hadoop.yarn.server.resourcemanager.rmapp.RMAppImpl: Processing event for application_1559895028500_0001 of type APP_RUNNING_ON_NODE
2019-06-07 08:10:53,797 DEBUG org.apache.hadoop.yarn.server.resourcemanager.rmapp.RMAppImpl: Processing event for application_1559895028500_0001 of type APP_RUNNING_ON_NODE
2019-06-07 08:10:53,797 DEBUG org.apache.hadoop.yarn.server.resourcemanager.scheduler.capacity.CapacityScheduler: nodeUpdate: slave2:40331 clusterResources: <memory:8192, vCores:2>
2019-06-07 08:10:53,797 DEBUG org.apache.hadoop.yarn.server.resourcemanager.scheduler.capacity.CapacityScheduler: nodeUpdate: slave2:40331 clusterResources: <memory:8192, vCores:2>
2019-06-07 08:10:53,803 DEBUG org.apache.hadoop.yarn.server.resourcemanager.rmcontainer.RMContainerImpl: Processing container_1559895028500_0001_01_000001 of type LAUNCHED
2019-06-07 08:10:53,803 DEBUG org.apache.hadoop.yarn.server.resourcemanager.rmcontainer.RMContainerImpl: Processing container_1559895028500_0001_01_000001 of type LAUNCHED
2019-06-07 08:10:53,803 INFO org.apache.hadoop.yarn.server.resourcemanager.rmcontainer.RMContainerImpl: container_1559895028500_0001_01_000001 Container Transitioned from ACQUIRED to RUNNING
2019-06-07 08:10:53,803 INFO org.apache.hadoop.yarn.server.resourcemanager.rmcontainer.RMContainerImpl: container_1559895028500_0001_01_000001 Container Transitioned from ACQUIRED to RUNNING
2019-06-07 08:10:53,803 DEBUG org.apache.hadoop.yarn.server.resourcemanager.scheduler.capacity.CapacityScheduler: Node being looked for scheduling slave2:40331 availableResource: <memory:3072, vCores:0>
2019-06-07 08:10:53,803 DEBUG org.apache.hadoop.yarn.server.resourcemanager.scheduler.capacity.CapacityScheduler: Node being looked for scheduling slave2:40331 availableResource: <memory:3072, vCores:0>
2019-06-07 08:10:53,803 DEBUG org.apache.hadoop.yarn.server.resourcemanager.scheduler.capacity.CapacityScheduler: Trying to schedule on node: slave2, available: <memory:3072, vCores:0>
2019-06-07 08:10:53,803 DEBUG org.apache.hadoop.yarn.server.resourcemanager.scheduler.capacity.CapacityScheduler: Trying to schedule on node: slave2, available: <memory:3072, vCores:0>
2019-06-07 08:10:53,803 DEBUG org.apache.hadoop.yarn.server.resourcemanager.scheduler.capacity.ParentQueue: Skip this queue=root, because it doesn't need more resource, schedulingMode=RESPECT_PARTITION_EXCLUSIVITY node-partition=
2019-06-07 08:10:53,803 DEBUG org.apache.hadoop.yarn.server.resourcemanager.scheduler.capacity.ParentQueue: Skip this queue=root, because it doesn't need more resource, schedulingMode=RESPECT_PARTITION_EXCLUSIVITY node-partition=
2019-06-07 08:10:54,784 DEBUG org.apache.hadoop.yarn.server.resourcemanager.rmnode.RMNodeImpl: Processing slave1:41069 of type STATUS_UPDATE
2019-06-07 08:10:54,784 DEBUG org.apache.hadoop.yarn.server.resourcemanager.rmnode.RMNodeImpl: Processing slave1:41069 of type STATUS_UPDATE
2019-06-07 08:10:54,784 DEBUG org.apache.hadoop.yarn.server.resourcemanager.scheduler.capacity.CapacityScheduler: nodeUpdate: slave1:41069 clusterResources: <memory:8192, vCores:2>
2019-06-07 08:10:54,784 DEBUG org.apache.hadoop.yarn.server.resourcemanager.scheduler.capacity.CapacityScheduler: nodeUpdate: slave1:41069 clusterResources: <memory:8192, vCores:2>
2019-06-07 08:10:54,784 DEBUG org.apache.hadoop.yarn.server.resourcemanager.scheduler.capacity.CapacityScheduler: Node being looked for scheduling slave1:41069 availableResource: <memory:4096, vCores:1>
2019-06-07 08:10:54,784 DEBUG org.apache.hadoop.yarn.server.resourcemanager.scheduler.capacity.CapacityScheduler: Node being looked for scheduling slave1:41069 availableResource: <memory:4096, vCores:1>
2019-06-07 08:10:54,785 DEBUG org.apache.hadoop.yarn.server.resourcemanager.scheduler.capacity.CapacityScheduler: Trying to schedule on node: slave1, available: <memory:4096, vCores:1>
2019-06-07 08:10:54,785 DEBUG org.apache.hadoop.yarn.server.resourcemanager.scheduler.capacity.CapacityScheduler: Trying to schedule on node: slave1, available: <memory:4096, vCores:1>
2019-06-07 08:10:54,785 DEBUG org.apache.hadoop.yarn.server.resourcemanager.scheduler.capacity.ParentQueue: Skip this queue=root, because it doesn't need more resource, schedulingMode=RESPECT_PARTITION_EXCLUSIVITY node-partition=
2019-06-07 08:10:54,785 DEBUG org.apache.hadoop.yarn.server.resourcemanager.scheduler.capacity.ParentQueue: Skip this queue=root, because it doesn't need more resource, schedulingMode=RESPECT_PARTITION_EXCLUSIVITY node-partition=
2019-06-07 08:10:54,807 DEBUG org.apache.hadoop.yarn.server.resourcemanager.rmnode.RMNodeImpl: Processing slave2:40331 of type STATUS_UPDATE
2019-06-07 08:10:54,807 DEBUG org.apache.hadoop.yarn.server.resourcemanager.rmnode.RMNodeImpl: Processing slave2:40331 of type STATUS_UPDATE
2019-06-07 08:10:54,808 DEBUG org.apache.hadoop.yarn.server.resourcemanager.scheduler.capacity.CapacityScheduler: nodeUpdate: slave2:40331 clusterResources: <memory:8192, vCores:2>
2019-06-07 08:10:54,808 DEBUG org.apache.hadoop.yarn.server.resourcemanager.scheduler.capacity.CapacityScheduler: nodeUpdate: slave2:40331 clusterResources: <memory:8192, vCores:2>
2019-06-07 08:10:54,808 DEBUG org.apache.hadoop.yarn.server.resourcemanager.scheduler.capacity.CapacityScheduler: Node being looked for scheduling slave2:40331 availableResource: <memory:3072, vCores:0>
2019-06-07 08:10:54,808 DEBUG org.apache.hadoop.yarn.server.resourcemanager.scheduler.capacity.CapacityScheduler: Node being looked for scheduling slave2:40331 availableResource: <memory:3072, vCores:0>
2019-06-07 08:10:54,808 DEBUG org.apache.hadoop.yarn.server.resourcemanager.scheduler.capacity.CapacityScheduler: Trying to schedule on node: slave2, available: <memory:3072, vCores:0>
2019-06-07 08:10:54,808 DEBUG org.apache.hadoop.yarn.server.resourcemanager.scheduler.capacity.CapacityScheduler: Trying to schedule on node: slave2, available: <memory:3072, vCores:0>
2019-06-07 08:10:54,808 DEBUG org.apache.hadoop.yarn.server.resourcemanager.scheduler.capacity.ParentQueue: Skip this queue=root, because it doesn't need more resource, schedulingMode=RESPECT_PARTITION_EXCLUSIVITY node-partition=
2019-06-07 08:10:54,808 DEBUG org.apache.hadoop.yarn.server.resourcemanager.scheduler.capacity.ParentQueue: Skip this queue=root, because it doesn't need more resource, schedulingMode=RESPECT_PARTITION_EXCLUSIVITY node-partition=
2019-06-07 08:10:55,788 DEBUG org.apache.hadoop.yarn.server.resourcemanager.rmnode.RMNodeImpl: Processing slave1:41069 of type STATUS_UPDATE
2019-06-07 08:10:55,788 DEBUG org.apache.hadoop.yarn.server.resourcemanager.rmnode.RMNodeImpl: Processing slave1:41069 of type STATUS_UPDATE
2019-06-07 08:10:55,789 DEBUG org.apache.hadoop.yarn.server.resourcemanager.scheduler.capacity.CapacityScheduler: nodeUpdate: slave1:41069 clusterResources: <memory:8192, vCores:2>
2019-06-07 08:10:55,789 DEBUG org.apache.hadoop.yarn.server.resourcemanager.scheduler.capacity.CapacityScheduler: nodeUpdate: slave1:41069 clusterResources: <memory:8192, vCores:2>
2019-06-07 08:10:55,789 DEBUG org.apache.hadoop.yarn.server.resourcemanager.scheduler.capacity.CapacityScheduler: Node being looked for scheduling slave1:41069 availableResource: <memory:4096, vCores:1>
2019-06-07 08:10:55,789 DEBUG org.apache.hadoop.yarn.server.resourcemanager.scheduler.capacity.CapacityScheduler: Node being looked for scheduling slave1:41069 availableResource: <memory:4096, vCores:1>
2019-06-07 08:10:55,789 DEBUG org.apache.hadoop.yarn.server.resourcemanager.scheduler.capacity.CapacityScheduler: Trying to schedule on node: slave1, available: <memory:4096, vCores:1>
2019-06-07 08:10:55,789 DEBUG org.apache.hadoop.yarn.server.resourcemanager.scheduler.capacity.CapacityScheduler: Trying to schedule on node: slave1, available: <memory:4096, vCores:1>
2019-06-07 08:10:55,789 DEBUG org.apache.hadoop.yarn.server.resourcemanager.scheduler.capacity.ParentQueue: Skip this queue=root, because it doesn't need more resource, schedulingMode=RESPECT_PARTITION_EXCLUSIVITY node-partition=
2019-06-07 08:10:55,789 DEBUG org.apache.hadoop.yarn.server.resourcemanager.scheduler.capacity.ParentQueue: Skip this queue=root, because it doesn't need more resource, schedulingMode=RESPECT_PARTITION_EXCLUSIVITY node-partition=
2019-06-07 08:10:55,811 DEBUG org.apache.hadoop.yarn.server.resourcemanager.rmnode.RMNodeImpl: Processing slave2:40331 of type STATUS_UPDATE
2019-06-07 08:10:55,811 DEBUG org.apache.hadoop.yarn.server.resourcemanager.rmnode.RMNodeImpl: Processing slave2:40331 of type STATUS_UPDATE
2019-06-07 08:10:55,813 DEBUG org.apache.hadoop.yarn.server.resourcemanager.scheduler.capacity.CapacityScheduler: nodeUpdate: slave2:40331 clusterResources: <memory:8192, vCores:2>
2019-06-07 08:10:55,813 DEBUG org.apache.hadoop.yarn.server.resourcemanager.scheduler.capacity.CapacityScheduler: nodeUpdate: slave2:40331 clusterResources: <memory:8192, vCores:2>
2019-06-07 08:10:55,813 DEBUG org.apache.hadoop.yarn.server.resourcemanager.scheduler.capacity.CapacityScheduler: Node being looked for scheduling slave2:40331 availableResource: <memory:3072, vCores:0>
2019-06-07 08:10:55,813 DEBUG org.apache.hadoop.yarn.server.resourcemanager.scheduler.capacity.CapacityScheduler: Node being looked for scheduling slave2:40331 availableResource: <memory:3072, vCores:0>
2019-06-07 08:10:55,813 DEBUG org.apache.hadoop.yarn.server.resourcemanager.scheduler.capacity.CapacityScheduler: Trying to schedule on node: slave2, available: <memory:3072, vCores:0>
2019-06-07 08:10:55,813 DEBUG org.apache.hadoop.yarn.server.resourcemanager.scheduler.capacity.CapacityScheduler: Trying to schedule on node: slave2, available: <memory:3072, vCores:0>
2019-06-07 08:10:55,813 DEBUG org.apache.hadoop.yarn.server.resourcemanager.scheduler.capacity.ParentQueue: Skip this queue=root, because it doesn't need more resource, schedulingMode=RESPECT_PARTITION_EXCLUSIVITY node-partition=
2019-06-07 08:10:55,813 DEBUG org.apache.hadoop.yarn.server.resourcemanager.scheduler.capacity.ParentQueue: Skip this queue=root, because it doesn't need more resource, schedulingMode=RESPECT_PARTITION_EXCLUSIVITY node-partition=
2019-06-07 08:10:56,793 DEBUG org.apache.hadoop.yarn.server.resourcemanager.rmnode.RMNodeImpl: Processing slave1:41069 of type STATUS_UPDATE
2019-06-07 08:10:56,793 DEBUG org.apache.hadoop.yarn.server.resourcemanager.rmnode.RMNodeImpl: Processing slave1:41069 of type STATUS_UPDATE
2019-06-07 08:10:56,793 DEBUG org.apache.hadoop.yarn.server.resourcemanager.scheduler.capacity.CapacityScheduler: nodeUpdate: slave1:41069 clusterResources: <memory:8192, vCores:2>
2019-06-07 08:10:56,793 DEBUG org.apache.hadoop.yarn.server.resourcemanager.scheduler.capacity.CapacityScheduler: nodeUpdate: slave1:41069 clusterResources: <memory:8192, vCores:2>
2019-06-07 08:10:56,793 DEBUG org.apache.hadoop.yarn.server.resourcemanager.scheduler.capacity.CapacityScheduler: Node being looked for scheduling slave1:41069 availableResource: <memory:4096, vCores:1>
2019-06-07 08:10:56,793 DEBUG org.apache.hadoop.yarn.server.resourcemanager.scheduler.capacity.CapacityScheduler: Node being looked for scheduling slave1:41069 availableResource: <memory:4096, vCores:1>
2019-06-07 08:10:56,793 DEBUG org.apache.hadoop.yarn.server.resourcemanager.scheduler.capacity.CapacityScheduler: Trying to schedule on node: slave1, available: <memory:4096, vCores:1>
2019-06-07 08:10:56,793 DEBUG org.apache.hadoop.yarn.server.resourcemanager.scheduler.capacity.CapacityScheduler: Trying to schedule on node: slave1, available: <memory:4096, vCores:1>
2019-06-07 08:10:56,793 DEBUG org.apache.hadoop.yarn.server.resourcemanager.scheduler.capacity.ParentQueue: Skip this queue=root, because it doesn't need more resource, schedulingMode=RESPECT_PARTITION_EXCLUSIVITY node-partition=
2019-06-07 08:10:56,793 DEBUG org.apache.hadoop.yarn.server.resourcemanager.scheduler.capacity.ParentQueue: Skip this queue=root, because it doesn't need more resource, schedulingMode=RESPECT_PARTITION_EXCLUSIVITY node-partition=
2019-06-07 08:10:56,815 DEBUG org.apache.hadoop.yarn.server.resourcemanager.rmnode.RMNodeImpl: Processing slave2:40331 of type STATUS_UPDATE
2019-06-07 08:10:56,815 DEBUG org.apache.hadoop.yarn.server.resourcemanager.rmnode.RMNodeImpl: Processing slave2:40331 of type STATUS_UPDATE
2019-06-07 08:10:56,816 DEBUG org.apache.hadoop.yarn.server.resourcemanager.scheduler.capacity.CapacityScheduler: nodeUpdate: slave2:40331 clusterResources: <memory:8192, vCores:2>
2019-06-07 08:10:56,816 DEBUG org.apache.hadoop.yarn.server.resourcemanager.scheduler.capacity.CapacityScheduler: nodeUpdate: slave2:40331 clusterResources: <memory:8192, vCores:2>
2019-06-07 08:10:56,816 DEBUG org.apache.hadoop.yarn.server.resourcemanager.scheduler.capacity.CapacityScheduler: Node being looked for scheduling slave2:40331 availableResource: <memory:3072, vCores:0>
2019-06-07 08:10:56,816 DEBUG org.apache.hadoop.yarn.server.resourcemanager.scheduler.capacity.CapacityScheduler: Node being looked for scheduling slave2:40331 availableResource: <memory:3072, vCores:0>
2019-06-07 08:10:56,816 DEBUG org.apache.hadoop.yarn.server.resourcemanager.scheduler.capacity.CapacityScheduler: Trying to schedule on node: slave2, available: <memory:3072, vCores:0>
2019-06-07 08:10:56,816 DEBUG org.apache.hadoop.yarn.server.resourcemanager.scheduler.capacity.CapacityScheduler: Trying to schedule on node: slave2, available: <memory:3072, vCores:0>
2019-06-07 08:10:56,816 DEBUG org.apache.hadoop.yarn.server.resourcemanager.scheduler.capacity.ParentQueue: Skip this queue=root, because it doesn't need more resource, schedulingMode=RESPECT_PARTITION_EXCLUSIVITY node-partition=
2019-06-07 08:10:56,816 DEBUG org.apache.hadoop.yarn.server.resourcemanager.scheduler.capacity.ParentQueue: Skip this queue=root, because it doesn't need more resource, schedulingMode=RESPECT_PARTITION_EXCLUSIVITY node-partition=
2019-06-07 08:10:57,796 DEBUG org.apache.hadoop.yarn.server.resourcemanager.rmnode.RMNodeImpl: Processing slave1:41069 of type STATUS_UPDATE
2019-06-07 08:10:57,796 DEBUG org.apache.hadoop.yarn.server.resourcemanager.rmnode.RMNodeImpl: Processing slave1:41069 of type STATUS_UPDATE
2019-06-07 08:10:57,796 DEBUG org.apache.hadoop.yarn.server.resourcemanager.scheduler.capacity.CapacityScheduler: nodeUpdate: slave1:41069 clusterResources: <memory:8192, vCores:2>
2019-06-07 08:10:57,796 DEBUG org.apache.hadoop.yarn.server.resourcemanager.scheduler.capacity.CapacityScheduler: nodeUpdate: slave1:41069 clusterResources: <memory:8192, vCores:2>
2019-06-07 08:10:57,796 DEBUG org.apache.hadoop.yarn.server.resourcemanager.scheduler.capacity.CapacityScheduler: Node being looked for scheduling slave1:41069 availableResource: <memory:4096, vCores:1>
2019-06-07 08:10:57,796 DEBUG org.apache.hadoop.yarn.server.resourcemanager.scheduler.capacity.CapacityScheduler: Node being looked for scheduling slave1:41069 availableResource: <memory:4096, vCores:1>
2019-06-07 08:10:57,796 DEBUG org.apache.hadoop.yarn.server.resourcemanager.scheduler.capacity.CapacityScheduler: Trying to schedule on node: slave1, available: <memory:4096, vCores:1>
2019-06-07 08:10:57,796 DEBUG org.apache.hadoop.yarn.server.resourcemanager.scheduler.capacity.CapacityScheduler: Trying to schedule on node: slave1, available: <memory:4096, vCores:1>
2019-06-07 08:10:57,796 DEBUG org.apache.hadoop.yarn.server.resourcemanager.scheduler.capacity.ParentQueue: Skip this queue=root, because it doesn't need more resource, schedulingMode=RESPECT_PARTITION_EXCLUSIVITY node-partition=
2019-06-07 08:10:57,796 DEBUG org.apache.hadoop.yarn.server.resourcemanager.scheduler.capacity.ParentQueue: Skip this queue=root, because it doesn't need more resource, schedulingMode=RESPECT_PARTITION_EXCLUSIVITY node-partition=
2019-06-07 08:10:57,819 DEBUG org.apache.hadoop.yarn.server.resourcemanager.rmnode.RMNodeImpl: Processing slave2:40331 of type STATUS_UPDATE
2019-06-07 08:10:57,819 DEBUG org.apache.hadoop.yarn.server.resourcemanager.rmnode.RMNodeImpl: Processing slave2:40331 of type STATUS_UPDATE
2019-06-07 08:10:57,819 DEBUG org.apache.hadoop.yarn.server.resourcemanager.scheduler.capacity.CapacityScheduler: nodeUpdate: slave2:40331 clusterResources: <memory:8192, vCores:2>
2019-06-07 08:10:57,819 DEBUG org.apache.hadoop.yarn.server.resourcemanager.scheduler.capacity.CapacityScheduler: nodeUpdate: slave2:40331 clusterResources: <memory:8192, vCores:2>
2019-06-07 08:10:57,820 DEBUG org.apache.hadoop.yarn.server.resourcemanager.scheduler.capacity.CapacityScheduler: Node being looked for scheduling slave2:40331 availableResource: <memory:3072, vCores:0>
2019-06-07 08:10:57,820 DEBUG org.apache.hadoop.yarn.server.resourcemanager.scheduler.capacity.CapacityScheduler: Node being looked for scheduling slave2:40331 availableResource: <memory:3072, vCores:0>
2019-06-07 08:10:57,820 DEBUG org.apache.hadoop.yarn.server.resourcemanager.scheduler.capacity.CapacityScheduler: Trying to schedule on node: slave2, available: <memory:3072, vCores:0>
2019-06-07 08:10:57,820 DEBUG org.apache.hadoop.yarn.server.resourcemanager.scheduler.capacity.CapacityScheduler: Trying to schedule on node: slave2, available: <memory:3072, vCores:0>
2019-06-07 08:10:57,820 DEBUG org.apache.hadoop.yarn.server.resourcemanager.scheduler.capacity.ParentQueue: Skip this queue=root, because it doesn't need more resource, schedulingMode=RESPECT_PARTITION_EXCLUSIVITY node-partition=
2019-06-07 08:10:57,820 DEBUG org.apache.hadoop.yarn.server.resourcemanager.scheduler.capacity.ParentQueue: Skip this queue=root, because it doesn't need more resource, schedulingMode=RESPECT_PARTITION_EXCLUSIVITY node-partition=
2019-06-07 08:10:58,798 DEBUG org.apache.hadoop.yarn.server.resourcemanager.rmnode.RMNodeImpl: Processing slave1:41069 of type STATUS_UPDATE
2019-06-07 08:10:58,798 DEBUG org.apache.hadoop.yarn.server.resourcemanager.rmnode.RMNodeImpl: Processing slave1:41069 of type STATUS_UPDATE
2019-06-07 08:10:58,798 DEBUG org.apache.hadoop.yarn.server.resourcemanager.scheduler.capacity.CapacityScheduler: nodeUpdate: slave1:41069 clusterResources: <memory:8192, vCores:2>
2019-06-07 08:10:58,798 DEBUG org.apache.hadoop.yarn.server.resourcemanager.scheduler.capacity.CapacityScheduler: nodeUpdate: slave1:41069 clusterResources: <memory:8192, vCores:2>
2019-06-07 08:10:58,798 DEBUG org.apache.hadoop.yarn.server.resourcemanager.scheduler.capacity.CapacityScheduler: Node being looked for scheduling slave1:41069 availableResource: <memory:4096, vCores:1>
2019-06-07 08:10:58,798 DEBUG org.apache.hadoop.yarn.server.resourcemanager.scheduler.capacity.CapacityScheduler: Node being looked for scheduling slave1:41069 availableResource: <memory:4096, vCores:1>
2019-06-07 08:10:58,798 DEBUG org.apache.hadoop.yarn.server.resourcemanager.scheduler.capacity.CapacityScheduler: Trying to schedule on node: slave1, available: <memory:4096, vCores:1>
2019-06-07 08:10:58,798 DEBUG org.apache.hadoop.yarn.server.resourcemanager.scheduler.capacity.CapacityScheduler: Trying to schedule on node: slave1, available: <memory:4096, vCores:1>
2019-06-07 08:10:58,798 DEBUG org.apache.hadoop.yarn.server.resourcemanager.scheduler.capacity.ParentQueue: Skip this queue=root, because it doesn't need more resource, schedulingMode=RESPECT_PARTITION_EXCLUSIVITY node-partition=
2019-06-07 08:10:58,798 DEBUG org.apache.hadoop.yarn.server.resourcemanager.scheduler.capacity.ParentQueue: Skip this queue=root, because it doesn't need more resource, schedulingMode=RESPECT_PARTITION_EXCLUSIVITY node-partition=
2019-06-07 08:10:58,831 DEBUG org.apache.hadoop.yarn.server.resourcemanager.rmnode.RMNodeImpl: Processing slave2:40331 of type STATUS_UPDATE
2019-06-07 08:10:58,831 DEBUG org.apache.hadoop.yarn.server.resourcemanager.rmnode.RMNodeImpl: Processing slave2:40331 of type STATUS_UPDATE
2019-06-07 08:10:58,832 DEBUG org.apache.hadoop.yarn.server.resourcemanager.scheduler.capacity.CapacityScheduler: nodeUpdate: slave2:40331 clusterResources: <memory:8192, vCores:2>
2019-06-07 08:10:58,832 DEBUG org.apache.hadoop.yarn.server.resourcemanager.scheduler.capacity.CapacityScheduler: nodeUpdate: slave2:40331 clusterResources: <memory:8192, vCores:2>
2019-06-07 08:10:58,832 DEBUG org.apache.hadoop.yarn.server.resourcemanager.scheduler.capacity.CapacityScheduler: Node being looked for scheduling slave2:40331 availableResource: <memory:3072, vCores:0>
2019-06-07 08:10:58,832 DEBUG org.apache.hadoop.yarn.server.resourcemanager.scheduler.capacity.CapacityScheduler: Node being looked for scheduling slave2:40331 availableResource: <memory:3072, vCores:0>
2019-06-07 08:10:58,832 DEBUG org.apache.hadoop.yarn.server.resourcemanager.scheduler.capacity.CapacityScheduler: Trying to schedule on node: slave2, available: <memory:3072, vCores:0>
2019-06-07 08:10:58,832 DEBUG org.apache.hadoop.yarn.server.resourcemanager.scheduler.capacity.CapacityScheduler: Trying to schedule on node: slave2, available: <memory:3072, vCores:0>
2019-06-07 08:10:58,832 DEBUG org.apache.hadoop.yarn.server.resourcemanager.scheduler.capacity.ParentQueue: Skip this queue=root, because it doesn't need more resource, schedulingMode=RESPECT_PARTITION_EXCLUSIVITY node-partition=
2019-06-07 08:10:58,832 DEBUG org.apache.hadoop.yarn.server.resourcemanager.scheduler.capacity.ParentQueue: Skip this queue=root, because it doesn't need more resource, schedulingMode=RESPECT_PARTITION_EXCLUSIVITY node-partition=
2019-06-07 08:10:59,164 DEBUG org.apache.hadoop.yarn.server.resourcemanager.security.AMRMTokenSecretManager: Trying to retrieve password for appattempt_1559895028500_0001_000001
2019-06-07 08:10:59,164 DEBUG org.apache.hadoop.yarn.server.resourcemanager.security.AMRMTokenSecretManager: Trying to retrieve password for appattempt_1559895028500_0001_000001
2019-06-07 08:10:59,165 INFO SecurityLogger.org.apache.hadoop.ipc.Server: Auth successful for appattempt_1559895028500_0001_000001 (auth:SIMPLE)
2019-06-07 08:10:59,173 INFO org.apache.hadoop.yarn.server.resourcemanager.ApplicationMasterService: AM registration appattempt_1559895028500_0001_000001
2019-06-07 08:10:59,173 INFO org.apache.hadoop.yarn.server.resourcemanager.ApplicationMasterService: AM registration appattempt_1559895028500_0001_000001
2019-06-07 08:10:59,174 DEBUG org.apache.hadoop.yarn.server.resourcemanager.rmapp.attempt.RMAppAttemptImpl: Processing event for appattempt_1559895028500_0001_000001 of type REGISTERED
2019-06-07 08:10:59,174 DEBUG org.apache.hadoop.yarn.server.resourcemanager.rmapp.attempt.RMAppAttemptImpl: Processing event for appattempt_1559895028500_0001_000001 of type REGISTERED
2019-06-07 08:10:59,174 INFO org.apache.hadoop.yarn.server.resourcemanager.rmapp.attempt.RMAppAttemptImpl: appattempt_1559895028500_0001_000001 State change from LAUNCHED to RUNNING
2019-06-07 08:10:59,174 INFO org.apache.hadoop.yarn.server.resourcemanager.rmapp.attempt.RMAppAttemptImpl: appattempt_1559895028500_0001_000001 State change from LAUNCHED to RUNNING
2019-06-07 08:10:59,174 DEBUG org.apache.hadoop.yarn.server.resourcemanager.rmapp.RMAppImpl: Processing event for application_1559895028500_0001 of type ATTEMPT_REGISTERED
2019-06-07 08:10:59,174 DEBUG org.apache.hadoop.yarn.server.resourcemanager.rmapp.RMAppImpl: Processing event for application_1559895028500_0001 of type ATTEMPT_REGISTERED
2019-06-07 08:10:59,174 INFO org.apache.hadoop.yarn.server.resourcemanager.rmapp.RMAppImpl: application_1559895028500_0001 State change from ACCEPTED to RUNNING on event=ATTEMPT_REGISTERED
2019-06-07 08:10:59,174 INFO org.apache.hadoop.yarn.server.resourcemanager.rmapp.RMAppImpl: application_1559895028500_0001 State change from ACCEPTED to RUNNING on event=ATTEMPT_REGISTERED
2019-06-07 08:10:59,174 INFO org.apache.hadoop.yarn.server.resourcemanager.RMAuditLogger: USER=root	IP=172.17.0.4	OPERATION=Register App Master	TARGET=ApplicationMasterService	RESULT=SUCCESS	APPID=application_1559895028500_0001	APPATTEMPTID=appattempt_1559895028500_0001_000001
2019-06-07 08:10:59,174 INFO org.apache.hadoop.yarn.server.resourcemanager.RMAuditLogger: USER=root	IP=172.17.0.4	OPERATION=Register App Master	TARGET=ApplicationMasterService	RESULT=SUCCESS	APPID=application_1559895028500_0001	APPATTEMPTID=appattempt_1559895028500_0001_000001
2019-06-07 08:10:59,271 DEBUG org.apache.hadoop.yarn.server.resourcemanager.rmapp.attempt.RMAppAttemptImpl: Processing event for appattempt_1559895028500_0001_000001 of type STATUS_UPDATE
2019-06-07 08:10:59,271 DEBUG org.apache.hadoop.yarn.server.resourcemanager.rmapp.attempt.RMAppAttemptImpl: Processing event for appattempt_1559895028500_0001_000001 of type STATUS_UPDATE
2019-06-07 08:10:59,271 DEBUG org.apache.hadoop.yarn.server.resourcemanager.scheduler.capacity.CapacityScheduler: allocate: pre-update appattempt_1559895028500_0001_000001 ask size =1
2019-06-07 08:10:59,271 DEBUG org.apache.hadoop.yarn.server.resourcemanager.scheduler.capacity.CapacityScheduler: allocate: pre-update appattempt_1559895028500_0001_000001 ask size =1
2019-06-07 08:10:59,271 DEBUG org.apache.hadoop.yarn.server.resourcemanager.scheduler.ActiveUsersManager: User root added to activeUsers, currently: 1
2019-06-07 08:10:59,271 DEBUG org.apache.hadoop.yarn.server.resourcemanager.scheduler.ActiveUsersManager: User root added to activeUsers, currently: 1
2019-06-07 08:10:59,271 DEBUG org.apache.hadoop.yarn.server.resourcemanager.scheduler.capacity.CapacityScheduler: allocate: post-update
2019-06-07 08:10:59,271 DEBUG org.apache.hadoop.yarn.server.resourcemanager.scheduler.capacity.CapacityScheduler: allocate: post-update
2019-06-07 08:10:59,273 DEBUG org.apache.hadoop.yarn.server.resourcemanager.scheduler.capacity.LeafQueue: User limit computation for root in queue default userLimitPercent=100 userLimitFactor=1.0 required: <memory:1024, vCores:1> consumed: <memory:1024, vCores:1> user-limit-resource: <memory:8192, vCores:1> queueCapacity: <memory:8192, vCores:1> qconsumed: <memory:1024, vCores:1> consumedRatio: 0.0 currentCapacity: <memory:8192, vCores:1> activeUsers: 1.0 clusterCapacity: <memory:8192, vCores:2> resourceByLabel: <memory:8192, vCores:2> usageratio: 0.125 Partition:  maxUserLimit=<memory:8192, vCores:1> userWeight=1.0
2019-06-07 08:10:59,273 DEBUG org.apache.hadoop.yarn.server.resourcemanager.scheduler.capacity.LeafQueue: User limit computation for root in queue default userLimitPercent=100 userLimitFactor=1.0 required: <memory:1024, vCores:1> consumed: <memory:1024, vCores:1> user-limit-resource: <memory:8192, vCores:1> queueCapacity: <memory:8192, vCores:1> qconsumed: <memory:1024, vCores:1> consumedRatio: 0.0 currentCapacity: <memory:8192, vCores:1> activeUsers: 1.0 clusterCapacity: <memory:8192, vCores:2> resourceByLabel: <memory:8192, vCores:2> usageratio: 0.125 Partition:  maxUserLimit=<memory:8192, vCores:1> userWeight=1.0
2019-06-07 08:10:59,273 DEBUG org.apache.hadoop.yarn.server.resourcemanager.scheduler.SchedulerApplicationAttempt: showRequests: application=application_1559895028500_0001 headRoom=<memory:7168, vCores:1> currentConsumption=1024
2019-06-07 08:10:59,273 DEBUG org.apache.hadoop.yarn.server.resourcemanager.scheduler.SchedulerApplicationAttempt: showRequests: application=application_1559895028500_0001 headRoom=<memory:7168, vCores:1> currentConsumption=1024
2019-06-07 08:10:59,273 DEBUG org.apache.hadoop.yarn.server.resourcemanager.scheduler.SchedulerApplicationAttempt: showRequests: application=application_1559895028500_0001 request={Priority: 1, Capability: <memory:3072, vCores:1>, # Containers: 2, Location: *, Relax Locality: true, Node Label Expression: }
2019-06-07 08:10:59,273 DEBUG org.apache.hadoop.yarn.server.resourcemanager.scheduler.SchedulerApplicationAttempt: showRequests: application=application_1559895028500_0001 request={Priority: 1, Capability: <memory:3072, vCores:1>, # Containers: 2, Location: *, Relax Locality: true, Node Label Expression: }
2019-06-07 08:10:59,273 DEBUG org.apache.hadoop.yarn.server.resourcemanager.scheduler.capacity.LeafQueue: User limit computation for root in queue default userLimitPercent=100 userLimitFactor=1.0 required: <memory:1024, vCores:1> consumed: <memory:1024, vCores:1> user-limit-resource: <memory:8192, vCores:1> queueCapacity: <memory:8192, vCores:1> qconsumed: <memory:1024, vCores:1> consumedRatio: 0.0 currentCapacity: <memory:8192, vCores:1> activeUsers: 1.0 clusterCapacity: <memory:8192, vCores:2> resourceByLabel: <memory:8192, vCores:2> usageratio: 0.125 Partition:  maxUserLimit=<memory:8192, vCores:1> userWeight=1.0
2019-06-07 08:10:59,273 DEBUG org.apache.hadoop.yarn.server.resourcemanager.scheduler.capacity.LeafQueue: User limit computation for root in queue default userLimitPercent=100 userLimitFactor=1.0 required: <memory:1024, vCores:1> consumed: <memory:1024, vCores:1> user-limit-resource: <memory:8192, vCores:1> queueCapacity: <memory:8192, vCores:1> qconsumed: <memory:1024, vCores:1> consumedRatio: 0.0 currentCapacity: <memory:8192, vCores:1> activeUsers: 1.0 clusterCapacity: <memory:8192, vCores:2> resourceByLabel: <memory:8192, vCores:2> usageratio: 0.125 Partition:  maxUserLimit=<memory:8192, vCores:1> userWeight=1.0
2019-06-07 08:10:59,298 DEBUG org.apache.hadoop.yarn.server.resourcemanager.rmapp.attempt.RMAppAttemptImpl: Processing event for appattempt_1559895028500_0001_000001 of type STATUS_UPDATE
2019-06-07 08:10:59,298 DEBUG org.apache.hadoop.yarn.server.resourcemanager.rmapp.attempt.RMAppAttemptImpl: Processing event for appattempt_1559895028500_0001_000001 of type STATUS_UPDATE
2019-06-07 08:10:59,299 DEBUG org.apache.hadoop.yarn.server.resourcemanager.scheduler.capacity.LeafQueue: User limit computation for root in queue default userLimitPercent=100 userLimitFactor=1.0 required: <memory:1024, vCores:1> consumed: <memory:1024, vCores:1> user-limit-resource: <memory:8192, vCores:1> queueCapacity: <memory:8192, vCores:1> qconsumed: <memory:1024, vCores:1> consumedRatio: 0.0 currentCapacity: <memory:8192, vCores:1> activeUsers: 1.0 clusterCapacity: <memory:8192, vCores:2> resourceByLabel: <memory:8192, vCores:2> usageratio: 0.125 Partition:  maxUserLimit=<memory:8192, vCores:1> userWeight=1.0
2019-06-07 08:10:59,299 DEBUG org.apache.hadoop.yarn.server.resourcemanager.scheduler.capacity.LeafQueue: User limit computation for root in queue default userLimitPercent=100 userLimitFactor=1.0 required: <memory:1024, vCores:1> consumed: <memory:1024, vCores:1> user-limit-resource: <memory:8192, vCores:1> queueCapacity: <memory:8192, vCores:1> qconsumed: <memory:1024, vCores:1> consumedRatio: 0.0 currentCapacity: <memory:8192, vCores:1> activeUsers: 1.0 clusterCapacity: <memory:8192, vCores:2> resourceByLabel: <memory:8192, vCores:2> usageratio: 0.125 Partition:  maxUserLimit=<memory:8192, vCores:1> userWeight=1.0
2019-06-07 08:10:59,510 DEBUG org.apache.hadoop.yarn.server.resourcemanager.scheduler.capacity.LeafQueue: User limit computation for root in queue default userLimitPercent=100 userLimitFactor=1.0 required: <memory:1024, vCores:1> consumed: <memory:1024, vCores:1> user-limit-resource: <memory:8192, vCores:1> queueCapacity: <memory:8192, vCores:1> qconsumed: <memory:1024, vCores:1> consumedRatio: 0.0 currentCapacity: <memory:8192, vCores:1> activeUsers: 1.0 clusterCapacity: <memory:8192, vCores:2> resourceByLabel: <memory:8192, vCores:2> usageratio: 0.125 Partition:  maxUserLimit=<memory:8192, vCores:1> userWeight=1.0
2019-06-07 08:10:59,510 DEBUG org.apache.hadoop.yarn.server.resourcemanager.scheduler.capacity.LeafQueue: User limit computation for root in queue default userLimitPercent=100 userLimitFactor=1.0 required: <memory:1024, vCores:1> consumed: <memory:1024, vCores:1> user-limit-resource: <memory:8192, vCores:1> queueCapacity: <memory:8192, vCores:1> qconsumed: <memory:1024, vCores:1> consumedRatio: 0.0 currentCapacity: <memory:8192, vCores:1> activeUsers: 1.0 clusterCapacity: <memory:8192, vCores:2> resourceByLabel: <memory:8192, vCores:2> usageratio: 0.125 Partition:  maxUserLimit=<memory:8192, vCores:1> userWeight=1.0
2019-06-07 08:10:59,510 DEBUG org.apache.hadoop.yarn.server.resourcemanager.rmapp.attempt.RMAppAttemptImpl: Processing event for appattempt_1559895028500_0001_000001 of type STATUS_UPDATE
2019-06-07 08:10:59,510 DEBUG org.apache.hadoop.yarn.server.resourcemanager.rmapp.attempt.RMAppAttemptImpl: Processing event for appattempt_1559895028500_0001_000001 of type STATUS_UPDATE
2019-06-07 08:10:59,800 DEBUG org.apache.hadoop.yarn.server.resourcemanager.rmnode.RMNodeImpl: Processing slave1:41069 of type STATUS_UPDATE
2019-06-07 08:10:59,800 DEBUG org.apache.hadoop.yarn.server.resourcemanager.rmnode.RMNodeImpl: Processing slave1:41069 of type STATUS_UPDATE
2019-06-07 08:10:59,801 DEBUG org.apache.hadoop.yarn.server.resourcemanager.scheduler.capacity.CapacityScheduler: nodeUpdate: slave1:41069 clusterResources: <memory:8192, vCores:2>
2019-06-07 08:10:59,801 DEBUG org.apache.hadoop.yarn.server.resourcemanager.scheduler.capacity.CapacityScheduler: nodeUpdate: slave1:41069 clusterResources: <memory:8192, vCores:2>
2019-06-07 08:10:59,802 DEBUG org.apache.hadoop.yarn.server.resourcemanager.scheduler.capacity.CapacityScheduler: Node being looked for scheduling slave1:41069 availableResource: <memory:4096, vCores:1>
2019-06-07 08:10:59,802 DEBUG org.apache.hadoop.yarn.server.resourcemanager.scheduler.capacity.CapacityScheduler: Node being looked for scheduling slave1:41069 availableResource: <memory:4096, vCores:1>
2019-06-07 08:10:59,802 DEBUG org.apache.hadoop.yarn.server.resourcemanager.scheduler.capacity.CapacityScheduler: Trying to schedule on node: slave1, available: <memory:4096, vCores:1>
2019-06-07 08:10:59,802 DEBUG org.apache.hadoop.yarn.server.resourcemanager.scheduler.capacity.CapacityScheduler: Trying to schedule on node: slave1, available: <memory:4096, vCores:1>
2019-06-07 08:10:59,802 DEBUG org.apache.hadoop.yarn.server.resourcemanager.scheduler.capacity.ParentQueue: Trying to assign containers to child-queue of root
2019-06-07 08:10:59,802 DEBUG org.apache.hadoop.yarn.server.resourcemanager.scheduler.capacity.ParentQueue: Trying to assign containers to child-queue of root
2019-06-07 08:10:59,802 DEBUG org.apache.hadoop.yarn.server.resourcemanager.scheduler.capacity.ParentQueue: printChildQueues - queue: root child-queues: root.defaultusedCapacity=(0.125),  label=(*)
2019-06-07 08:10:59,802 DEBUG org.apache.hadoop.yarn.server.resourcemanager.scheduler.capacity.ParentQueue: printChildQueues - queue: root child-queues: root.defaultusedCapacity=(0.125),  label=(*)
2019-06-07 08:10:59,802 DEBUG org.apache.hadoop.yarn.server.resourcemanager.scheduler.capacity.ParentQueue: Trying to assign to queue: root.default stats: default: capacity=1.0, absoluteCapacity=1.0, usedResources=<memory:1024, vCores:1>, usedCapacity=0.125, absoluteUsedCapacity=0.125, numApps=1, numContainers=1
2019-06-07 08:10:59,802 DEBUG org.apache.hadoop.yarn.server.resourcemanager.scheduler.capacity.ParentQueue: Trying to assign to queue: root.default stats: default: capacity=1.0, absoluteCapacity=1.0, usedResources=<memory:1024, vCores:1>, usedCapacity=0.125, absoluteUsedCapacity=0.125, numApps=1, numContainers=1
2019-06-07 08:10:59,802 DEBUG org.apache.hadoop.yarn.server.resourcemanager.scheduler.capacity.LeafQueue: assignContainers: node=slave1 #applications=1
2019-06-07 08:10:59,802 DEBUG org.apache.hadoop.yarn.server.resourcemanager.scheduler.capacity.LeafQueue: assignContainers: node=slave1 #applications=1
2019-06-07 08:10:59,802 DEBUG org.apache.hadoop.yarn.server.resourcemanager.scheduler.capacity.LeafQueue: User limit computation for root in queue default userLimitPercent=100 userLimitFactor=1.0 required: <memory:1024, vCores:1> consumed: <memory:1024, vCores:1> user-limit-resource: <memory:8192, vCores:1> queueCapacity: <memory:8192, vCores:1> qconsumed: <memory:1024, vCores:1> consumedRatio: 0.0 currentCapacity: <memory:8192, vCores:1> activeUsers: 1.0 clusterCapacity: <memory:8192, vCores:2> resourceByLabel: <memory:8192, vCores:2> usageratio: 0.125 Partition:  maxUserLimit=<memory:8192, vCores:1> userWeight=1.0
2019-06-07 08:10:59,802 DEBUG org.apache.hadoop.yarn.server.resourcemanager.scheduler.capacity.LeafQueue: User limit computation for root in queue default userLimitPercent=100 userLimitFactor=1.0 required: <memory:1024, vCores:1> consumed: <memory:1024, vCores:1> user-limit-resource: <memory:8192, vCores:1> queueCapacity: <memory:8192, vCores:1> qconsumed: <memory:1024, vCores:1> consumedRatio: 0.0 currentCapacity: <memory:8192, vCores:1> activeUsers: 1.0 clusterCapacity: <memory:8192, vCores:2> resourceByLabel: <memory:8192, vCores:2> usageratio: 0.125 Partition:  maxUserLimit=<memory:8192, vCores:1> userWeight=1.0
2019-06-07 08:10:59,802 DEBUG org.apache.hadoop.yarn.server.resourcemanager.scheduler.capacity.LeafQueue: Headroom calculation for user root:  userLimit=<memory:8192, vCores:1> queueMaxAvailRes=<memory:8192, vCores:1> consumed=<memory:1024, vCores:1>
2019-06-07 08:10:59,802 DEBUG org.apache.hadoop.yarn.server.resourcemanager.scheduler.capacity.LeafQueue: Headroom calculation for user root:  userLimit=<memory:8192, vCores:1> queueMaxAvailRes=<memory:8192, vCores:1> consumed=<memory:1024, vCores:1>
2019-06-07 08:10:59,802 DEBUG org.apache.hadoop.yarn.server.resourcemanager.scheduler.common.fica.FiCaSchedulerApp: pre-assignContainers for application application_1559895028500_0001
2019-06-07 08:10:59,802 DEBUG org.apache.hadoop.yarn.server.resourcemanager.scheduler.common.fica.FiCaSchedulerApp: pre-assignContainers for application application_1559895028500_0001
2019-06-07 08:10:59,802 DEBUG org.apache.hadoop.yarn.server.resourcemanager.scheduler.capacity.LeafQueue: User limit computation for root in queue default userLimitPercent=100 userLimitFactor=1.0 required: <memory:1024, vCores:1> consumed: <memory:1024, vCores:1> user-limit-resource: <memory:8192, vCores:1> queueCapacity: <memory:8192, vCores:1> qconsumed: <memory:1024, vCores:1> consumedRatio: 0.0 currentCapacity: <memory:8192, vCores:1> activeUsers: 1.0 clusterCapacity: <memory:8192, vCores:2> resourceByLabel: <memory:8192, vCores:2> usageratio: 0.125 Partition:  maxUserLimit=<memory:8192, vCores:1> userWeight=1.0
2019-06-07 08:10:59,802 DEBUG org.apache.hadoop.yarn.server.resourcemanager.scheduler.capacity.LeafQueue: User limit computation for root in queue default userLimitPercent=100 userLimitFactor=1.0 required: <memory:1024, vCores:1> consumed: <memory:1024, vCores:1> user-limit-resource: <memory:8192, vCores:1> queueCapacity: <memory:8192, vCores:1> qconsumed: <memory:1024, vCores:1> consumedRatio: 0.0 currentCapacity: <memory:8192, vCores:1> activeUsers: 1.0 clusterCapacity: <memory:8192, vCores:2> resourceByLabel: <memory:8192, vCores:2> usageratio: 0.125 Partition:  maxUserLimit=<memory:8192, vCores:1> userWeight=1.0
2019-06-07 08:10:59,802 DEBUG org.apache.hadoop.yarn.server.resourcemanager.scheduler.SchedulerApplicationAttempt: showRequests: application=application_1559895028500_0001 headRoom=<memory:7168, vCores:1> currentConsumption=1024
2019-06-07 08:10:59,802 DEBUG org.apache.hadoop.yarn.server.resourcemanager.scheduler.SchedulerApplicationAttempt: showRequests: application=application_1559895028500_0001 headRoom=<memory:7168, vCores:1> currentConsumption=1024
2019-06-07 08:10:59,812 DEBUG org.apache.hadoop.yarn.server.resourcemanager.scheduler.SchedulerApplicationAttempt: showRequests: application=application_1559895028500_0001 request={Priority: 1, Capability: <memory:3072, vCores:1>, # Containers: 2, Location: *, Relax Locality: true, Node Label Expression: }
2019-06-07 08:10:59,812 DEBUG org.apache.hadoop.yarn.server.resourcemanager.scheduler.SchedulerApplicationAttempt: showRequests: application=application_1559895028500_0001 request={Priority: 1, Capability: <memory:3072, vCores:1>, # Containers: 2, Location: *, Relax Locality: true, Node Label Expression: }
2019-06-07 08:10:59,812 DEBUG org.apache.hadoop.yarn.server.resourcemanager.scheduler.capacity.allocator.IncreaseContainerAllocator: Skip allocating increase request since we don't have any increase request on this node=slave1:41069
2019-06-07 08:10:59,812 DEBUG org.apache.hadoop.yarn.server.resourcemanager.scheduler.capacity.allocator.IncreaseContainerAllocator: Skip allocating increase request since we don't have any increase request on this node=slave1:41069
2019-06-07 08:10:59,812 DEBUG org.apache.hadoop.yarn.server.resourcemanager.scheduler.capacity.allocator.RegularContainerAllocator: assignContainers: node=slave1 application=application_1559895028500_0001 priority=1 request={Priority: 1, Capability: <memory:3072, vCores:1>, # Containers: 2, Location: *, Relax Locality: true, Node Label Expression: } type=OFF_SWITCH
2019-06-07 08:10:59,812 DEBUG org.apache.hadoop.yarn.server.resourcemanager.scheduler.capacity.allocator.RegularContainerAllocator: assignContainers: node=slave1 application=application_1559895028500_0001 priority=1 request={Priority: 1, Capability: <memory:3072, vCores:1>, # Containers: 2, Location: *, Relax Locality: true, Node Label Expression: } type=OFF_SWITCH
2019-06-07 08:10:59,812 DEBUG org.apache.hadoop.yarn.server.resourcemanager.scheduler.AppSchedulingInfo: allocate: applicationId=application_1559895028500_0001 container=container_1559895028500_0001_01_000002 host=slave1:41069 user=root resource=<memory:3072, vCores:1> type=OFF_SWITCH
2019-06-07 08:10:59,812 DEBUG org.apache.hadoop.yarn.server.resourcemanager.scheduler.AppSchedulingInfo: allocate: applicationId=application_1559895028500_0001 container=container_1559895028500_0001_01_000002 host=slave1:41069 user=root resource=<memory:3072, vCores:1> type=OFF_SWITCH
2019-06-07 08:10:59,812 DEBUG org.apache.hadoop.yarn.server.resourcemanager.rmcontainer.RMContainerImpl: Processing container_1559895028500_0001_01_000002 of type START
2019-06-07 08:10:59,812 DEBUG org.apache.hadoop.yarn.server.resourcemanager.rmcontainer.RMContainerImpl: Processing container_1559895028500_0001_01_000002 of type START
2019-06-07 08:10:59,812 INFO org.apache.hadoop.yarn.server.resourcemanager.rmcontainer.RMContainerImpl: container_1559895028500_0001_01_000002 Container Transitioned from NEW to ALLOCATED
2019-06-07 08:10:59,812 INFO org.apache.hadoop.yarn.server.resourcemanager.rmcontainer.RMContainerImpl: container_1559895028500_0001_01_000002 Container Transitioned from NEW to ALLOCATED
2019-06-07 08:10:59,812 DEBUG org.apache.hadoop.yarn.server.resourcemanager.scheduler.common.fica.FiCaSchedulerApp: allocate: applicationAttemptId=appattempt_1559895028500_0001_000001 container=container_1559895028500_0001_01_000002 host=slave1 type=OFF_SWITCH
2019-06-07 08:10:59,812 DEBUG org.apache.hadoop.yarn.server.resourcemanager.scheduler.common.fica.FiCaSchedulerApp: allocate: applicationAttemptId=appattempt_1559895028500_0001_000001 container=container_1559895028500_0001_01_000002 host=slave1 type=OFF_SWITCH
2019-06-07 08:10:59,812 INFO org.apache.hadoop.yarn.server.resourcemanager.RMAuditLogger: USER=root	OPERATION=AM Allocated Container	TARGET=SchedulerApp	RESULT=SUCCESS	APPID=application_1559895028500_0001	CONTAINERID=container_1559895028500_0001_01_000002
2019-06-07 08:10:59,812 INFO org.apache.hadoop.yarn.server.resourcemanager.RMAuditLogger: USER=root	OPERATION=AM Allocated Container	TARGET=SchedulerApp	RESULT=SUCCESS	APPID=application_1559895028500_0001	CONTAINERID=container_1559895028500_0001_01_000002
2019-06-07 08:10:59,812 DEBUG org.apache.hadoop.yarn.server.resourcemanager.rmapp.attempt.RMAppAttemptImpl: Processing event for appattempt_1559895028500_0001_000001 of type CONTAINER_ALLOCATED
2019-06-07 08:10:59,812 DEBUG org.apache.hadoop.yarn.server.resourcemanager.rmapp.attempt.RMAppAttemptImpl: Processing event for appattempt_1559895028500_0001_000001 of type CONTAINER_ALLOCATED
2019-06-07 08:10:59,812 INFO org.apache.hadoop.yarn.server.resourcemanager.scheduler.SchedulerNode: Assigned container container_1559895028500_0001_01_000002 of capacity <memory:3072, vCores:1> on host slave1:41069, which has 1 containers, <memory:3072, vCores:1> used and <memory:1024, vCores:0> available after allocation
2019-06-07 08:10:59,812 INFO org.apache.hadoop.yarn.server.resourcemanager.scheduler.SchedulerNode: Assigned container container_1559895028500_0001_01_000002 of capacity <memory:3072, vCores:1> on host slave1:41069, which has 1 containers, <memory:3072, vCores:1> used and <memory:1024, vCores:0> available after allocation
2019-06-07 08:10:59,814 INFO org.apache.hadoop.yarn.server.resourcemanager.scheduler.capacity.allocator.AbstractContainerAllocator: assignedContainer application attempt=appattempt_1559895028500_0001_000001 container=container_1559895028500_0001_01_000002 queue=org.apache.hadoop.yarn.server.resourcemanager.scheduler.capacity.allocator.RegularContainerAllocator@fd9a5af clusterResource=<memory:8192, vCores:2> type=OFF_SWITCH requestedPartition=
2019-06-07 08:10:59,814 INFO org.apache.hadoop.yarn.server.resourcemanager.scheduler.capacity.allocator.AbstractContainerAllocator: assignedContainer application attempt=appattempt_1559895028500_0001_000001 container=container_1559895028500_0001_01_000002 queue=org.apache.hadoop.yarn.server.resourcemanager.scheduler.capacity.allocator.RegularContainerAllocator@fd9a5af clusterResource=<memory:8192, vCores:2> type=OFF_SWITCH requestedPartition=
2019-06-07 08:10:59,814 DEBUG org.apache.hadoop.yarn.server.resourcemanager.scheduler.capacity.LeafQueue: post-assignContainers for application application_1559895028500_0001
2019-06-07 08:10:59,814 DEBUG org.apache.hadoop.yarn.server.resourcemanager.scheduler.capacity.LeafQueue: post-assignContainers for application application_1559895028500_0001
2019-06-07 08:10:59,814 DEBUG org.apache.hadoop.yarn.server.resourcemanager.scheduler.capacity.LeafQueue: User limit computation for root in queue default userLimitPercent=100 userLimitFactor=1.0 required: <memory:1024, vCores:1> consumed: <memory:1024, vCores:1> user-limit-resource: <memory:8192, vCores:1> queueCapacity: <memory:8192, vCores:1> qconsumed: <memory:1024, vCores:1> consumedRatio: 0.0 currentCapacity: <memory:8192, vCores:1> activeUsers: 1.0 clusterCapacity: <memory:8192, vCores:2> resourceByLabel: <memory:8192, vCores:2> usageratio: 0.125 Partition:  maxUserLimit=<memory:8192, vCores:1> userWeight=1.0
2019-06-07 08:10:59,814 DEBUG org.apache.hadoop.yarn.server.resourcemanager.scheduler.capacity.LeafQueue: User limit computation for root in queue default userLimitPercent=100 userLimitFactor=1.0 required: <memory:1024, vCores:1> consumed: <memory:1024, vCores:1> user-limit-resource: <memory:8192, vCores:1> queueCapacity: <memory:8192, vCores:1> qconsumed: <memory:1024, vCores:1> consumedRatio: 0.0 currentCapacity: <memory:8192, vCores:1> activeUsers: 1.0 clusterCapacity: <memory:8192, vCores:2> resourceByLabel: <memory:8192, vCores:2> usageratio: 0.125 Partition:  maxUserLimit=<memory:8192, vCores:1> userWeight=1.0
2019-06-07 08:10:59,814 DEBUG org.apache.hadoop.yarn.server.resourcemanager.scheduler.SchedulerApplicationAttempt: showRequests: application=application_1559895028500_0001 headRoom=<memory:7168, vCores:1> currentConsumption=4096
2019-06-07 08:10:59,814 DEBUG org.apache.hadoop.yarn.server.resourcemanager.scheduler.SchedulerApplicationAttempt: showRequests: application=application_1559895028500_0001 headRoom=<memory:7168, vCores:1> currentConsumption=4096
2019-06-07 08:10:59,814 DEBUG org.apache.hadoop.yarn.server.resourcemanager.scheduler.SchedulerApplicationAttempt: showRequests: application=application_1559895028500_0001 request={Priority: 1, Capability: <memory:3072, vCores:1>, # Containers: 1, Location: *, Relax Locality: true, Node Label Expression: }
2019-06-07 08:10:59,814 DEBUG org.apache.hadoop.yarn.server.resourcemanager.scheduler.SchedulerApplicationAttempt: showRequests: application=application_1559895028500_0001 request={Priority: 1, Capability: <memory:3072, vCores:1>, # Containers: 1, Location: *, Relax Locality: true, Node Label Expression: }
2019-06-07 08:10:59,814 DEBUG org.apache.hadoop.yarn.server.resourcemanager.scheduler.capacity.LeafQueue: User limit computation for root in queue default userLimitPercent=100 userLimitFactor=1.0 required: <memory:1024, vCores:1> consumed: <memory:4096, vCores:1> user-limit-resource: <memory:8192, vCores:1> queueCapacity: <memory:8192, vCores:1> qconsumed: <memory:4096, vCores:2> consumedRatio: 0.0 currentCapacity: <memory:8192, vCores:1> activeUsers: 1.0 clusterCapacity: <memory:8192, vCores:2> resourceByLabel: <memory:8192, vCores:2> usageratio: 0.5 Partition:  maxUserLimit=<memory:8192, vCores:1> userWeight=1.0
2019-06-07 08:10:59,814 DEBUG org.apache.hadoop.yarn.server.resourcemanager.scheduler.capacity.LeafQueue: User limit computation for root in queue default userLimitPercent=100 userLimitFactor=1.0 required: <memory:1024, vCores:1> consumed: <memory:4096, vCores:1> user-limit-resource: <memory:8192, vCores:1> queueCapacity: <memory:8192, vCores:1> qconsumed: <memory:4096, vCores:2> consumedRatio: 0.0 currentCapacity: <memory:8192, vCores:1> activeUsers: 1.0 clusterCapacity: <memory:8192, vCores:2> resourceByLabel: <memory:8192, vCores:2> usageratio: 0.5 Partition:  maxUserLimit=<memory:8192, vCores:1> userWeight=1.0
2019-06-07 08:10:59,814 DEBUG org.apache.hadoop.yarn.server.resourcemanager.scheduler.capacity.LeafQueue: User limit computation for root in queue default userLimitPercent=100 userLimitFactor=1.0 required: <memory:1024, vCores:1> consumed: <memory:4096, vCores:1> user-limit-resource: <memory:8192, vCores:1> queueCapacity: <memory:8192, vCores:1> qconsumed: <memory:4096, vCores:2> consumedRatio: 0.0 currentCapacity: <memory:8192, vCores:1> activeUsers: 1.0 clusterCapacity: <memory:8192, vCores:2> resourceByLabel: <memory:8192, vCores:2> usageratio: 0.5 Partition:  maxUserLimit=<memory:8192, vCores:1> userWeight=1.0
2019-06-07 08:10:59,814 DEBUG org.apache.hadoop.yarn.server.resourcemanager.scheduler.capacity.LeafQueue: User limit computation for root in queue default userLimitPercent=100 userLimitFactor=1.0 required: <memory:1024, vCores:1> consumed: <memory:4096, vCores:1> user-limit-resource: <memory:8192, vCores:1> queueCapacity: <memory:8192, vCores:1> qconsumed: <memory:4096, vCores:2> consumedRatio: 0.0 currentCapacity: <memory:8192, vCores:1> activeUsers: 1.0 clusterCapacity: <memory:8192, vCores:2> resourceByLabel: <memory:8192, vCores:2> usageratio: 0.5 Partition:  maxUserLimit=<memory:8192, vCores:1> userWeight=1.0
2019-06-07 08:10:59,814 DEBUG org.apache.hadoop.yarn.server.resourcemanager.scheduler.capacity.LeafQueue: User limit computation for root in queue default userLimitPercent=100 userLimitFactor=1.0 required: <memory:1024, vCores:1> consumed: <memory:4096, vCores:1> user-limit-resource: <memory:8192, vCores:1> queueCapacity: <memory:8192, vCores:1> qconsumed: <memory:4096, vCores:2> consumedRatio: 0.0 currentCapacity: <memory:8192, vCores:1> activeUsers: 1.0 clusterCapacity: <memory:8192, vCores:2> resourceByLabel: <memory:8192, vCores:2> usageratio: 0.5 Partition:  maxUserLimit=<memory:8192, vCores:1> userWeight=1.0
2019-06-07 08:10:59,814 DEBUG org.apache.hadoop.yarn.server.resourcemanager.scheduler.capacity.LeafQueue: User limit computation for root in queue default userLimitPercent=100 userLimitFactor=1.0 required: <memory:1024, vCores:1> consumed: <memory:4096, vCores:1> user-limit-resource: <memory:8192, vCores:1> queueCapacity: <memory:8192, vCores:1> qconsumed: <memory:4096, vCores:2> consumedRatio: 0.0 currentCapacity: <memory:8192, vCores:1> activeUsers: 1.0 clusterCapacity: <memory:8192, vCores:2> resourceByLabel: <memory:8192, vCores:2> usageratio: 0.5 Partition:  maxUserLimit=<memory:8192, vCores:1> userWeight=1.0
2019-06-07 08:10:59,814 DEBUG org.apache.hadoop.yarn.server.resourcemanager.scheduler.capacity.LeafQueue: default user=root used=<memory:4096, vCores:2> numContainers=2 headroom = <memory:4096, vCores:1> user-resources=<memory:4096, vCores:2>
2019-06-07 08:10:59,814 DEBUG org.apache.hadoop.yarn.server.resourcemanager.scheduler.capacity.LeafQueue: default user=root used=<memory:4096, vCores:2> numContainers=2 headroom = <memory:4096, vCores:1> user-resources=<memory:4096, vCores:2>
2019-06-07 08:10:59,814 DEBUG org.apache.hadoop.yarn.server.resourcemanager.scheduler.capacity.ParentQueue: Assigned to queue: root.default stats: default: capacity=1.0, absoluteCapacity=1.0, usedResources=<memory:4096, vCores:2>, usedCapacity=0.5, absoluteUsedCapacity=0.5, numApps=1, numContainers=2 --> <memory:3072, vCores:1>, OFF_SWITCH
2019-06-07 08:10:59,814 DEBUG org.apache.hadoop.yarn.server.resourcemanager.scheduler.capacity.ParentQueue: Assigned to queue: root.default stats: default: capacity=1.0, absoluteCapacity=1.0, usedResources=<memory:4096, vCores:2>, usedCapacity=0.5, absoluteUsedCapacity=0.5, numApps=1, numContainers=2 --> <memory:3072, vCores:1>, OFF_SWITCH
2019-06-07 08:10:59,814 INFO org.apache.hadoop.yarn.server.resourcemanager.scheduler.capacity.ParentQueue: Re-sorting assigned queue: root.default stats: default: capacity=1.0, absoluteCapacity=1.0, usedResources=<memory:4096, vCores:2>, usedCapacity=0.5, absoluteUsedCapacity=0.5, numApps=1, numContainers=2
2019-06-07 08:10:59,814 INFO org.apache.hadoop.yarn.server.resourcemanager.scheduler.capacity.ParentQueue: Re-sorting assigned queue: root.default stats: default: capacity=1.0, absoluteCapacity=1.0, usedResources=<memory:4096, vCores:2>, usedCapacity=0.5, absoluteUsedCapacity=0.5, numApps=1, numContainers=2
2019-06-07 08:10:59,815 DEBUG org.apache.hadoop.yarn.server.resourcemanager.scheduler.capacity.ParentQueue: printChildQueues - queue: root child-queues: root.defaultusedCapacity=(0.5),  label=(*)
2019-06-07 08:10:59,815 DEBUG org.apache.hadoop.yarn.server.resourcemanager.scheduler.capacity.ParentQueue: printChildQueues - queue: root child-queues: root.defaultusedCapacity=(0.5),  label=(*)
2019-06-07 08:10:59,815 INFO org.apache.hadoop.yarn.server.resourcemanager.scheduler.capacity.ParentQueue: assignedContainer queue=root usedCapacity=0.5 absoluteUsedCapacity=0.5 used=<memory:4096, vCores:2> cluster=<memory:8192, vCores:2>
2019-06-07 08:10:59,815 INFO org.apache.hadoop.yarn.server.resourcemanager.scheduler.capacity.ParentQueue: assignedContainer queue=root usedCapacity=0.5 absoluteUsedCapacity=0.5 used=<memory:4096, vCores:2> cluster=<memory:8192, vCores:2>
2019-06-07 08:10:59,815 DEBUG org.apache.hadoop.yarn.server.resourcemanager.scheduler.capacity.ParentQueue: ParentQ=root assignedSoFarInThisIteration=<memory:3072, vCores:1> usedCapacity=0.5 absoluteUsedCapacity=0.5
2019-06-07 08:10:59,815 DEBUG org.apache.hadoop.yarn.server.resourcemanager.scheduler.capacity.ParentQueue: ParentQ=root assignedSoFarInThisIteration=<memory:3072, vCores:1> usedCapacity=0.5 absoluteUsedCapacity=0.5
2019-06-07 08:10:59,815 DEBUG org.apache.hadoop.yarn.server.resourcemanager.scheduler.capacity.ParentQueue: Assigned maximum number of off-switch containers: 1, assignments so far: resource:<memory:3072, vCores:1>; type:OFF_SWITCH; excessReservation:null; applicationid:null; skipped:NONE; fulfilled reservation:false; allocations(count/resource):1/<memory:3072, vCores:1>; reservations(count/resource):0/<memory:0, vCores:0>
2019-06-07 08:10:59,815 DEBUG org.apache.hadoop.yarn.server.resourcemanager.scheduler.capacity.ParentQueue: Assigned maximum number of off-switch containers: 1, assignments so far: resource:<memory:3072, vCores:1>; type:OFF_SWITCH; excessReservation:null; applicationid:null; skipped:NONE; fulfilled reservation:false; allocations(count/resource):1/<memory:3072, vCores:1>; reservations(count/resource):0/<memory:0, vCores:0>
2019-06-07 08:10:59,842 DEBUG org.apache.hadoop.yarn.server.resourcemanager.rmnode.RMNodeImpl: Processing slave2:40331 of type STATUS_UPDATE
2019-06-07 08:10:59,842 DEBUG org.apache.hadoop.yarn.server.resourcemanager.rmnode.RMNodeImpl: Processing slave2:40331 of type STATUS_UPDATE
2019-06-07 08:10:59,844 DEBUG org.apache.hadoop.yarn.server.resourcemanager.scheduler.capacity.CapacityScheduler: nodeUpdate: slave2:40331 clusterResources: <memory:8192, vCores:2>
2019-06-07 08:10:59,844 DEBUG org.apache.hadoop.yarn.server.resourcemanager.scheduler.capacity.CapacityScheduler: nodeUpdate: slave2:40331 clusterResources: <memory:8192, vCores:2>
2019-06-07 08:10:59,844 DEBUG org.apache.hadoop.yarn.server.resourcemanager.scheduler.capacity.CapacityScheduler: Node being looked for scheduling slave2:40331 availableResource: <memory:3072, vCores:0>
2019-06-07 08:10:59,844 DEBUG org.apache.hadoop.yarn.server.resourcemanager.scheduler.capacity.CapacityScheduler: Node being looked for scheduling slave2:40331 availableResource: <memory:3072, vCores:0>
2019-06-07 08:10:59,844 DEBUG org.apache.hadoop.yarn.server.resourcemanager.scheduler.capacity.CapacityScheduler: Trying to schedule on node: slave2, available: <memory:3072, vCores:0>
2019-06-07 08:10:59,844 DEBUG org.apache.hadoop.yarn.server.resourcemanager.scheduler.capacity.CapacityScheduler: Trying to schedule on node: slave2, available: <memory:3072, vCores:0>
2019-06-07 08:10:59,844 DEBUG org.apache.hadoop.yarn.server.resourcemanager.scheduler.capacity.ParentQueue: Trying to assign containers to child-queue of root
2019-06-07 08:10:59,844 DEBUG org.apache.hadoop.yarn.server.resourcemanager.scheduler.capacity.ParentQueue: Trying to assign containers to child-queue of root
2019-06-07 08:10:59,844 DEBUG org.apache.hadoop.yarn.server.resourcemanager.scheduler.capacity.ParentQueue: printChildQueues - queue: root child-queues: root.defaultusedCapacity=(0.5),  label=(*)
2019-06-07 08:10:59,844 DEBUG org.apache.hadoop.yarn.server.resourcemanager.scheduler.capacity.ParentQueue: printChildQueues - queue: root child-queues: root.defaultusedCapacity=(0.5),  label=(*)
2019-06-07 08:10:59,844 DEBUG org.apache.hadoop.yarn.server.resourcemanager.scheduler.capacity.ParentQueue: Trying to assign to queue: root.default stats: default: capacity=1.0, absoluteCapacity=1.0, usedResources=<memory:4096, vCores:2>, usedCapacity=0.5, absoluteUsedCapacity=0.5, numApps=1, numContainers=2
2019-06-07 08:10:59,844 DEBUG org.apache.hadoop.yarn.server.resourcemanager.scheduler.capacity.ParentQueue: Trying to assign to queue: root.default stats: default: capacity=1.0, absoluteCapacity=1.0, usedResources=<memory:4096, vCores:2>, usedCapacity=0.5, absoluteUsedCapacity=0.5, numApps=1, numContainers=2
2019-06-07 08:10:59,844 DEBUG org.apache.hadoop.yarn.server.resourcemanager.scheduler.capacity.LeafQueue: assignContainers: node=slave2 #applications=1
2019-06-07 08:10:59,844 DEBUG org.apache.hadoop.yarn.server.resourcemanager.scheduler.capacity.LeafQueue: assignContainers: node=slave2 #applications=1
2019-06-07 08:10:59,844 DEBUG org.apache.hadoop.yarn.server.resourcemanager.scheduler.capacity.LeafQueue: User limit computation for root in queue default userLimitPercent=100 userLimitFactor=1.0 required: <memory:1024, vCores:1> consumed: <memory:4096, vCores:1> user-limit-resource: <memory:8192, vCores:1> queueCapacity: <memory:8192, vCores:1> qconsumed: <memory:4096, vCores:2> consumedRatio: 0.0 currentCapacity: <memory:8192, vCores:1> activeUsers: 1.0 clusterCapacity: <memory:8192, vCores:2> resourceByLabel: <memory:8192, vCores:2> usageratio: 0.5 Partition:  maxUserLimit=<memory:8192, vCores:1> userWeight=1.0
2019-06-07 08:10:59,844 DEBUG org.apache.hadoop.yarn.server.resourcemanager.scheduler.capacity.LeafQueue: User limit computation for root in queue default userLimitPercent=100 userLimitFactor=1.0 required: <memory:1024, vCores:1> consumed: <memory:4096, vCores:1> user-limit-resource: <memory:8192, vCores:1> queueCapacity: <memory:8192, vCores:1> qconsumed: <memory:4096, vCores:2> consumedRatio: 0.0 currentCapacity: <memory:8192, vCores:1> activeUsers: 1.0 clusterCapacity: <memory:8192, vCores:2> resourceByLabel: <memory:8192, vCores:2> usageratio: 0.5 Partition:  maxUserLimit=<memory:8192, vCores:1> userWeight=1.0
2019-06-07 08:10:59,844 DEBUG org.apache.hadoop.yarn.server.resourcemanager.scheduler.capacity.LeafQueue: Headroom calculation for user root:  userLimit=<memory:8192, vCores:1> queueMaxAvailRes=<memory:8192, vCores:1> consumed=<memory:4096, vCores:2>
2019-06-07 08:10:59,844 DEBUG org.apache.hadoop.yarn.server.resourcemanager.scheduler.capacity.LeafQueue: Headroom calculation for user root:  userLimit=<memory:8192, vCores:1> queueMaxAvailRes=<memory:8192, vCores:1> consumed=<memory:4096, vCores:2>
2019-06-07 08:10:59,844 DEBUG org.apache.hadoop.yarn.server.resourcemanager.scheduler.common.fica.FiCaSchedulerApp: pre-assignContainers for application application_1559895028500_0001
2019-06-07 08:10:59,844 DEBUG org.apache.hadoop.yarn.server.resourcemanager.scheduler.common.fica.FiCaSchedulerApp: pre-assignContainers for application application_1559895028500_0001
2019-06-07 08:10:59,844 DEBUG org.apache.hadoop.yarn.server.resourcemanager.scheduler.capacity.LeafQueue: User limit computation for root in queue default userLimitPercent=100 userLimitFactor=1.0 required: <memory:1024, vCores:1> consumed: <memory:4096, vCores:1> user-limit-resource: <memory:8192, vCores:1> queueCapacity: <memory:8192, vCores:1> qconsumed: <memory:4096, vCores:2> consumedRatio: 0.0 currentCapacity: <memory:8192, vCores:1> activeUsers: 1.0 clusterCapacity: <memory:8192, vCores:2> resourceByLabel: <memory:8192, vCores:2> usageratio: 0.5 Partition:  maxUserLimit=<memory:8192, vCores:1> userWeight=1.0
2019-06-07 08:10:59,844 DEBUG org.apache.hadoop.yarn.server.resourcemanager.scheduler.capacity.LeafQueue: User limit computation for root in queue default userLimitPercent=100 userLimitFactor=1.0 required: <memory:1024, vCores:1> consumed: <memory:4096, vCores:1> user-limit-resource: <memory:8192, vCores:1> queueCapacity: <memory:8192, vCores:1> qconsumed: <memory:4096, vCores:2> consumedRatio: 0.0 currentCapacity: <memory:8192, vCores:1> activeUsers: 1.0 clusterCapacity: <memory:8192, vCores:2> resourceByLabel: <memory:8192, vCores:2> usageratio: 0.5 Partition:  maxUserLimit=<memory:8192, vCores:1> userWeight=1.0
2019-06-07 08:10:59,844 DEBUG org.apache.hadoop.yarn.server.resourcemanager.scheduler.SchedulerApplicationAttempt: showRequests: application=application_1559895028500_0001 headRoom=<memory:4096, vCores:0> currentConsumption=4096
2019-06-07 08:10:59,844 DEBUG org.apache.hadoop.yarn.server.resourcemanager.scheduler.SchedulerApplicationAttempt: showRequests: application=application_1559895028500_0001 headRoom=<memory:4096, vCores:0> currentConsumption=4096
2019-06-07 08:10:59,844 DEBUG org.apache.hadoop.yarn.server.resourcemanager.scheduler.SchedulerApplicationAttempt: showRequests: application=application_1559895028500_0001 request={Priority: 1, Capability: <memory:3072, vCores:1>, # Containers: 1, Location: *, Relax Locality: true, Node Label Expression: }
2019-06-07 08:10:59,844 DEBUG org.apache.hadoop.yarn.server.resourcemanager.scheduler.SchedulerApplicationAttempt: showRequests: application=application_1559895028500_0001 request={Priority: 1, Capability: <memory:3072, vCores:1>, # Containers: 1, Location: *, Relax Locality: true, Node Label Expression: }
2019-06-07 08:10:59,844 DEBUG org.apache.hadoop.yarn.server.resourcemanager.scheduler.capacity.allocator.IncreaseContainerAllocator: Skip allocating increase request since we don't have any increase request on this node=slave2:40331
2019-06-07 08:10:59,844 DEBUG org.apache.hadoop.yarn.server.resourcemanager.scheduler.capacity.allocator.IncreaseContainerAllocator: Skip allocating increase request since we don't have any increase request on this node=slave2:40331
2019-06-07 08:10:59,844 DEBUG org.apache.hadoop.yarn.server.resourcemanager.scheduler.capacity.allocator.RegularContainerAllocator: assignContainers: node=slave2 application=application_1559895028500_0001 priority=1 request={Priority: 1, Capability: <memory:3072, vCores:1>, # Containers: 1, Location: *, Relax Locality: true, Node Label Expression: } type=OFF_SWITCH
2019-06-07 08:10:59,844 DEBUG org.apache.hadoop.yarn.server.resourcemanager.scheduler.capacity.allocator.RegularContainerAllocator: assignContainers: node=slave2 application=application_1559895028500_0001 priority=1 request={Priority: 1, Capability: <memory:3072, vCores:1>, # Containers: 1, Location: *, Relax Locality: true, Node Label Expression: } type=OFF_SWITCH
2019-06-07 08:10:59,844 DEBUG org.apache.hadoop.yarn.server.resourcemanager.scheduler.ActiveUsersManager: User root removed from activeUsers, currently: 0
2019-06-07 08:10:59,844 DEBUG org.apache.hadoop.yarn.server.resourcemanager.scheduler.ActiveUsersManager: User root removed from activeUsers, currently: 0
2019-06-07 08:10:59,844 DEBUG org.apache.hadoop.yarn.server.resourcemanager.scheduler.AppSchedulingInfo: allocate: applicationId=application_1559895028500_0001 container=container_1559895028500_0001_01_000003 host=slave2:40331 user=root resource=<memory:3072, vCores:1> type=OFF_SWITCH
2019-06-07 08:10:59,844 DEBUG org.apache.hadoop.yarn.server.resourcemanager.scheduler.AppSchedulingInfo: allocate: applicationId=application_1559895028500_0001 container=container_1559895028500_0001_01_000003 host=slave2:40331 user=root resource=<memory:3072, vCores:1> type=OFF_SWITCH
2019-06-07 08:10:59,844 DEBUG org.apache.hadoop.yarn.server.resourcemanager.rmcontainer.RMContainerImpl: Processing container_1559895028500_0001_01_000003 of type START
2019-06-07 08:10:59,844 DEBUG org.apache.hadoop.yarn.server.resourcemanager.rmcontainer.RMContainerImpl: Processing container_1559895028500_0001_01_000003 of type START
2019-06-07 08:10:59,845 INFO org.apache.hadoop.yarn.server.resourcemanager.rmcontainer.RMContainerImpl: container_1559895028500_0001_01_000003 Container Transitioned from NEW to ALLOCATED
2019-06-07 08:10:59,845 INFO org.apache.hadoop.yarn.server.resourcemanager.rmcontainer.RMContainerImpl: container_1559895028500_0001_01_000003 Container Transitioned from NEW to ALLOCATED
2019-06-07 08:10:59,845 DEBUG org.apache.hadoop.yarn.server.resourcemanager.scheduler.common.fica.FiCaSchedulerApp: allocate: applicationAttemptId=appattempt_1559895028500_0001_000001 container=container_1559895028500_0001_01_000003 host=slave2 type=OFF_SWITCH
2019-06-07 08:10:59,845 DEBUG org.apache.hadoop.yarn.server.resourcemanager.scheduler.common.fica.FiCaSchedulerApp: allocate: applicationAttemptId=appattempt_1559895028500_0001_000001 container=container_1559895028500_0001_01_000003 host=slave2 type=OFF_SWITCH
2019-06-07 08:10:59,845 INFO org.apache.hadoop.yarn.server.resourcemanager.RMAuditLogger: USER=root	OPERATION=AM Allocated Container	TARGET=SchedulerApp	RESULT=SUCCESS	APPID=application_1559895028500_0001	CONTAINERID=container_1559895028500_0001_01_000003
2019-06-07 08:10:59,845 INFO org.apache.hadoop.yarn.server.resourcemanager.RMAuditLogger: USER=root	OPERATION=AM Allocated Container	TARGET=SchedulerApp	RESULT=SUCCESS	APPID=application_1559895028500_0001	CONTAINERID=container_1559895028500_0001_01_000003
2019-06-07 08:10:59,845 DEBUG org.apache.hadoop.yarn.server.resourcemanager.rmapp.attempt.RMAppAttemptImpl: Processing event for appattempt_1559895028500_0001_000001 of type CONTAINER_ALLOCATED
2019-06-07 08:10:59,845 DEBUG org.apache.hadoop.yarn.server.resourcemanager.rmapp.attempt.RMAppAttemptImpl: Processing event for appattempt_1559895028500_0001_000001 of type CONTAINER_ALLOCATED
2019-06-07 08:10:59,845 INFO org.apache.hadoop.yarn.server.resourcemanager.scheduler.SchedulerNode: Assigned container container_1559895028500_0001_01_000003 of capacity <memory:3072, vCores:1> on host slave2:40331, which has 2 containers, <memory:4096, vCores:2> used and <memory:0, vCores:-1> available after allocation
2019-06-07 08:10:59,845 INFO org.apache.hadoop.yarn.server.resourcemanager.scheduler.SchedulerNode: Assigned container container_1559895028500_0001_01_000003 of capacity <memory:3072, vCores:1> on host slave2:40331, which has 2 containers, <memory:4096, vCores:2> used and <memory:0, vCores:-1> available after allocation
2019-06-07 08:10:59,856 INFO org.apache.hadoop.yarn.server.resourcemanager.scheduler.capacity.allocator.AbstractContainerAllocator: assignedContainer application attempt=appattempt_1559895028500_0001_000001 container=container_1559895028500_0001_01_000003 queue=org.apache.hadoop.yarn.server.resourcemanager.scheduler.capacity.allocator.RegularContainerAllocator@fd9a5af clusterResource=<memory:8192, vCores:2> type=OFF_SWITCH requestedPartition=
2019-06-07 08:10:59,856 INFO org.apache.hadoop.yarn.server.resourcemanager.scheduler.capacity.allocator.AbstractContainerAllocator: assignedContainer application attempt=appattempt_1559895028500_0001_000001 container=container_1559895028500_0001_01_000003 queue=org.apache.hadoop.yarn.server.resourcemanager.scheduler.capacity.allocator.RegularContainerAllocator@fd9a5af clusterResource=<memory:8192, vCores:2> type=OFF_SWITCH requestedPartition=
2019-06-07 08:10:59,856 DEBUG org.apache.hadoop.yarn.server.resourcemanager.scheduler.capacity.LeafQueue: post-assignContainers for application application_1559895028500_0001
2019-06-07 08:10:59,856 DEBUG org.apache.hadoop.yarn.server.resourcemanager.scheduler.capacity.LeafQueue: post-assignContainers for application application_1559895028500_0001
2019-06-07 08:10:59,856 DEBUG org.apache.hadoop.yarn.server.resourcemanager.scheduler.capacity.LeafQueue: User limit computation for root in queue default userLimitPercent=100 userLimitFactor=1.0 required: <memory:1024, vCores:1> consumed: <memory:7168, vCores:1> user-limit-resource: <memory:8192, vCores:1> queueCapacity: <memory:8192, vCores:1> qconsumed: <memory:7168, vCores:3> consumedRatio: 0.0 currentCapacity: <memory:8192, vCores:1> activeUsers: 0.0 clusterCapacity: <memory:8192, vCores:2> resourceByLabel: <memory:8192, vCores:2> usageratio: 0.875 Partition:  maxUserLimit=<memory:8192, vCores:1> userWeight=1.0
2019-06-07 08:10:59,856 DEBUG org.apache.hadoop.yarn.server.resourcemanager.scheduler.capacity.LeafQueue: User limit computation for root in queue default userLimitPercent=100 userLimitFactor=1.0 required: <memory:1024, vCores:1> consumed: <memory:7168, vCores:1> user-limit-resource: <memory:8192, vCores:1> queueCapacity: <memory:8192, vCores:1> qconsumed: <memory:7168, vCores:3> consumedRatio: 0.0 currentCapacity: <memory:8192, vCores:1> activeUsers: 0.0 clusterCapacity: <memory:8192, vCores:2> resourceByLabel: <memory:8192, vCores:2> usageratio: 0.875 Partition:  maxUserLimit=<memory:8192, vCores:1> userWeight=1.0
2019-06-07 08:10:59,856 DEBUG org.apache.hadoop.yarn.server.resourcemanager.scheduler.capacity.LeafQueue: User limit computation for root in queue default userLimitPercent=100 userLimitFactor=1.0 required: <memory:1024, vCores:1> consumed: <memory:7168, vCores:1> user-limit-resource: <memory:8192, vCores:1> queueCapacity: <memory:8192, vCores:1> qconsumed: <memory:7168, vCores:3> consumedRatio: 0.0 currentCapacity: <memory:8192, vCores:1> activeUsers: 0.0 clusterCapacity: <memory:8192, vCores:2> resourceByLabel: <memory:8192, vCores:2> usageratio: 0.875 Partition:  maxUserLimit=<memory:8192, vCores:1> userWeight=1.0
2019-06-07 08:10:59,856 DEBUG org.apache.hadoop.yarn.server.resourcemanager.scheduler.capacity.LeafQueue: User limit computation for root in queue default userLimitPercent=100 userLimitFactor=1.0 required: <memory:1024, vCores:1> consumed: <memory:7168, vCores:1> user-limit-resource: <memory:8192, vCores:1> queueCapacity: <memory:8192, vCores:1> qconsumed: <memory:7168, vCores:3> consumedRatio: 0.0 currentCapacity: <memory:8192, vCores:1> activeUsers: 0.0 clusterCapacity: <memory:8192, vCores:2> resourceByLabel: <memory:8192, vCores:2> usageratio: 0.875 Partition:  maxUserLimit=<memory:8192, vCores:1> userWeight=1.0
2019-06-07 08:10:59,856 DEBUG org.apache.hadoop.yarn.server.resourcemanager.scheduler.capacity.LeafQueue: User limit computation for root in queue default userLimitPercent=100 userLimitFactor=1.0 required: <memory:1024, vCores:1> consumed: <memory:7168, vCores:1> user-limit-resource: <memory:8192, vCores:1> queueCapacity: <memory:8192, vCores:1> qconsumed: <memory:7168, vCores:3> consumedRatio: 0.0 currentCapacity: <memory:8192, vCores:1> activeUsers: 0.0 clusterCapacity: <memory:8192, vCores:2> resourceByLabel: <memory:8192, vCores:2> usageratio: 0.875 Partition:  maxUserLimit=<memory:8192, vCores:1> userWeight=1.0
2019-06-07 08:10:59,856 DEBUG org.apache.hadoop.yarn.server.resourcemanager.scheduler.capacity.LeafQueue: User limit computation for root in queue default userLimitPercent=100 userLimitFactor=1.0 required: <memory:1024, vCores:1> consumed: <memory:7168, vCores:1> user-limit-resource: <memory:8192, vCores:1> queueCapacity: <memory:8192, vCores:1> qconsumed: <memory:7168, vCores:3> consumedRatio: 0.0 currentCapacity: <memory:8192, vCores:1> activeUsers: 0.0 clusterCapacity: <memory:8192, vCores:2> resourceByLabel: <memory:8192, vCores:2> usageratio: 0.875 Partition:  maxUserLimit=<memory:8192, vCores:1> userWeight=1.0
2019-06-07 08:10:59,857 DEBUG org.apache.hadoop.yarn.server.resourcemanager.scheduler.capacity.LeafQueue: default user=root used=<memory:7168, vCores:3> numContainers=3 headroom = <memory:1024, vCores:1> user-resources=<memory:7168, vCores:3>
2019-06-07 08:10:59,857 DEBUG org.apache.hadoop.yarn.server.resourcemanager.scheduler.capacity.LeafQueue: default user=root used=<memory:7168, vCores:3> numContainers=3 headroom = <memory:1024, vCores:1> user-resources=<memory:7168, vCores:3>
2019-06-07 08:10:59,857 DEBUG org.apache.hadoop.yarn.server.resourcemanager.scheduler.capacity.ParentQueue: Assigned to queue: root.default stats: default: capacity=1.0, absoluteCapacity=1.0, usedResources=<memory:7168, vCores:3>, usedCapacity=0.875, absoluteUsedCapacity=0.875, numApps=1, numContainers=3 --> <memory:3072, vCores:1>, OFF_SWITCH
2019-06-07 08:10:59,857 DEBUG org.apache.hadoop.yarn.server.resourcemanager.scheduler.capacity.ParentQueue: Assigned to queue: root.default stats: default: capacity=1.0, absoluteCapacity=1.0, usedResources=<memory:7168, vCores:3>, usedCapacity=0.875, absoluteUsedCapacity=0.875, numApps=1, numContainers=3 --> <memory:3072, vCores:1>, OFF_SWITCH
2019-06-07 08:10:59,857 INFO org.apache.hadoop.yarn.server.resourcemanager.scheduler.capacity.ParentQueue: Re-sorting assigned queue: root.default stats: default: capacity=1.0, absoluteCapacity=1.0, usedResources=<memory:7168, vCores:3>, usedCapacity=0.875, absoluteUsedCapacity=0.875, numApps=1, numContainers=3
2019-06-07 08:10:59,857 INFO org.apache.hadoop.yarn.server.resourcemanager.scheduler.capacity.ParentQueue: Re-sorting assigned queue: root.default stats: default: capacity=1.0, absoluteCapacity=1.0, usedResources=<memory:7168, vCores:3>, usedCapacity=0.875, absoluteUsedCapacity=0.875, numApps=1, numContainers=3
2019-06-07 08:10:59,857 DEBUG org.apache.hadoop.yarn.server.resourcemanager.scheduler.capacity.ParentQueue: printChildQueues - queue: root child-queues: root.defaultusedCapacity=(0.875),  label=(*)
2019-06-07 08:10:59,857 DEBUG org.apache.hadoop.yarn.server.resourcemanager.scheduler.capacity.ParentQueue: printChildQueues - queue: root child-queues: root.defaultusedCapacity=(0.875),  label=(*)
2019-06-07 08:10:59,857 INFO org.apache.hadoop.yarn.server.resourcemanager.scheduler.capacity.ParentQueue: assignedContainer queue=root usedCapacity=0.875 absoluteUsedCapacity=0.875 used=<memory:7168, vCores:3> cluster=<memory:8192, vCores:2>
2019-06-07 08:10:59,857 INFO org.apache.hadoop.yarn.server.resourcemanager.scheduler.capacity.ParentQueue: assignedContainer queue=root usedCapacity=0.875 absoluteUsedCapacity=0.875 used=<memory:7168, vCores:3> cluster=<memory:8192, vCores:2>
2019-06-07 08:10:59,858 DEBUG org.apache.hadoop.yarn.server.resourcemanager.scheduler.capacity.ParentQueue: ParentQ=root assignedSoFarInThisIteration=<memory:3072, vCores:1> usedCapacity=0.875 absoluteUsedCapacity=0.875
2019-06-07 08:10:59,858 DEBUG org.apache.hadoop.yarn.server.resourcemanager.scheduler.capacity.ParentQueue: ParentQ=root assignedSoFarInThisIteration=<memory:3072, vCores:1> usedCapacity=0.875 absoluteUsedCapacity=0.875
2019-06-07 08:10:59,858 DEBUG org.apache.hadoop.yarn.server.resourcemanager.scheduler.capacity.ParentQueue: Assigned maximum number of off-switch containers: 1, assignments so far: resource:<memory:3072, vCores:1>; type:OFF_SWITCH; excessReservation:null; applicationid:null; skipped:NONE; fulfilled reservation:false; allocations(count/resource):1/<memory:3072, vCores:1>; reservations(count/resource):0/<memory:0, vCores:0>
2019-06-07 08:10:59,858 DEBUG org.apache.hadoop.yarn.server.resourcemanager.scheduler.capacity.ParentQueue: Assigned maximum number of off-switch containers: 1, assignments so far: resource:<memory:3072, vCores:1>; type:OFF_SWITCH; excessReservation:null; applicationid:null; skipped:NONE; fulfilled reservation:false; allocations(count/resource):1/<memory:3072, vCores:1>; reservations(count/resource):0/<memory:0, vCores:0>
2019-06-07 08:10:59,924 INFO org.apache.hadoop.yarn.server.resourcemanager.security.NMTokenSecretManagerInRM: Sending NMToken for nodeId : slave1:41069 for container : container_1559895028500_0001_01_000002
2019-06-07 08:10:59,924 DEBUG org.apache.hadoop.yarn.server.resourcemanager.rmapp.attempt.RMAppAttemptImpl: Processing event for appattempt_1559895028500_0001_000001 of type STATUS_UPDATE
2019-06-07 08:10:59,924 INFO org.apache.hadoop.yarn.server.resourcemanager.security.NMTokenSecretManagerInRM: Sending NMToken for nodeId : slave1:41069 for container : container_1559895028500_0001_01_000002
2019-06-07 08:10:59,928 DEBUG org.apache.hadoop.yarn.server.resourcemanager.rmcontainer.RMContainerImpl: Processing container_1559895028500_0001_01_000002 of type ACQUIRED
2019-06-07 08:10:59,928 DEBUG org.apache.hadoop.yarn.server.resourcemanager.rmcontainer.RMContainerImpl: Processing container_1559895028500_0001_01_000002 of type ACQUIRED
2019-06-07 08:10:59,924 DEBUG org.apache.hadoop.yarn.server.resourcemanager.rmapp.attempt.RMAppAttemptImpl: Processing event for appattempt_1559895028500_0001_000001 of type STATUS_UPDATE
2019-06-07 08:10:59,928 DEBUG org.apache.hadoop.yarn.server.resourcemanager.rmapp.RMAppImpl: Processing event for application_1559895028500_0001 of type APP_RUNNING_ON_NODE
2019-06-07 08:10:59,928 DEBUG org.apache.hadoop.yarn.server.resourcemanager.rmapp.RMAppImpl: Processing event for application_1559895028500_0001 of type APP_RUNNING_ON_NODE
2019-06-07 08:10:59,928 INFO org.apache.hadoop.yarn.server.resourcemanager.rmcontainer.RMContainerImpl: container_1559895028500_0001_01_000002 Container Transitioned from ALLOCATED to ACQUIRED
2019-06-07 08:10:59,928 INFO org.apache.hadoop.yarn.server.resourcemanager.rmcontainer.RMContainerImpl: container_1559895028500_0001_01_000002 Container Transitioned from ALLOCATED to ACQUIRED
2019-06-07 08:10:59,929 INFO org.apache.hadoop.yarn.server.resourcemanager.security.NMTokenSecretManagerInRM: Sending NMToken for nodeId : slave2:40331 for container : container_1559895028500_0001_01_000003
2019-06-07 08:10:59,929 INFO org.apache.hadoop.yarn.server.resourcemanager.security.NMTokenSecretManagerInRM: Sending NMToken for nodeId : slave2:40331 for container : container_1559895028500_0001_01_000003
2019-06-07 08:10:59,929 DEBUG org.apache.hadoop.yarn.server.resourcemanager.rmcontainer.RMContainerImpl: Processing container_1559895028500_0001_01_000003 of type ACQUIRED
2019-06-07 08:10:59,929 DEBUG org.apache.hadoop.yarn.server.resourcemanager.rmcontainer.RMContainerImpl: Processing container_1559895028500_0001_01_000003 of type ACQUIRED
2019-06-07 08:10:59,932 DEBUG org.apache.hadoop.yarn.server.resourcemanager.rmapp.RMAppImpl: Processing event for application_1559895028500_0001 of type APP_RUNNING_ON_NODE
2019-06-07 08:10:59,932 DEBUG org.apache.hadoop.yarn.server.resourcemanager.rmapp.RMAppImpl: Processing event for application_1559895028500_0001 of type APP_RUNNING_ON_NODE
2019-06-07 08:10:59,932 INFO org.apache.hadoop.yarn.server.resourcemanager.rmcontainer.RMContainerImpl: container_1559895028500_0001_01_000003 Container Transitioned from ALLOCATED to ACQUIRED
2019-06-07 08:10:59,932 INFO org.apache.hadoop.yarn.server.resourcemanager.rmcontainer.RMContainerImpl: container_1559895028500_0001_01_000003 Container Transitioned from ALLOCATED to ACQUIRED
2019-06-07 08:10:59,932 DEBUG org.apache.hadoop.yarn.server.resourcemanager.scheduler.capacity.LeafQueue: User limit computation for root in queue default userLimitPercent=100 userLimitFactor=1.0 required: <memory:1024, vCores:1> consumed: <memory:7168, vCores:1> user-limit-resource: <memory:8192, vCores:1> queueCapacity: <memory:8192, vCores:1> qconsumed: <memory:7168, vCores:3> consumedRatio: 0.0 currentCapacity: <memory:8192, vCores:1> activeUsers: 0.0 clusterCapacity: <memory:8192, vCores:2> resourceByLabel: <memory:8192, vCores:2> usageratio: 0.875 Partition:  maxUserLimit=<memory:8192, vCores:1> userWeight=1.0
2019-06-07 08:10:59,932 DEBUG org.apache.hadoop.yarn.server.resourcemanager.scheduler.capacity.LeafQueue: User limit computation for root in queue default userLimitPercent=100 userLimitFactor=1.0 required: <memory:1024, vCores:1> consumed: <memory:7168, vCores:1> user-limit-resource: <memory:8192, vCores:1> queueCapacity: <memory:8192, vCores:1> qconsumed: <memory:7168, vCores:3> consumedRatio: 0.0 currentCapacity: <memory:8192, vCores:1> activeUsers: 0.0 clusterCapacity: <memory:8192, vCores:2> resourceByLabel: <memory:8192, vCores:2> usageratio: 0.875 Partition:  maxUserLimit=<memory:8192, vCores:1> userWeight=1.0
2019-06-07 08:11:00,834 DEBUG org.apache.hadoop.yarn.server.resourcemanager.rmnode.RMNodeImpl: Processing slave1:41069 of type STATUS_UPDATE
2019-06-07 08:11:00,834 DEBUG org.apache.hadoop.yarn.server.resourcemanager.rmnode.RMNodeImpl: Processing slave1:41069 of type STATUS_UPDATE
2019-06-07 08:11:00,835 DEBUG org.apache.hadoop.yarn.server.resourcemanager.rmnode.RMNodeImpl: Container container_1559895028500_0001_01_000002 is the first container get launched for application application_1559895028500_0001
2019-06-07 08:11:00,835 DEBUG org.apache.hadoop.yarn.server.resourcemanager.rmnode.RMNodeImpl: Container container_1559895028500_0001_01_000002 is the first container get launched for application application_1559895028500_0001
2019-06-07 08:11:00,835 DEBUG org.apache.hadoop.yarn.server.resourcemanager.rmapp.RMAppImpl: Processing event for application_1559895028500_0001 of type APP_RUNNING_ON_NODE
2019-06-07 08:11:00,835 DEBUG org.apache.hadoop.yarn.server.resourcemanager.rmapp.RMAppImpl: Processing event for application_1559895028500_0001 of type APP_RUNNING_ON_NODE
2019-06-07 08:11:00,835 DEBUG org.apache.hadoop.yarn.server.resourcemanager.scheduler.capacity.CapacityScheduler: nodeUpdate: slave1:41069 clusterResources: <memory:8192, vCores:2>
2019-06-07 08:11:00,835 DEBUG org.apache.hadoop.yarn.server.resourcemanager.scheduler.capacity.CapacityScheduler: nodeUpdate: slave1:41069 clusterResources: <memory:8192, vCores:2>
2019-06-07 08:11:00,836 DEBUG org.apache.hadoop.yarn.server.resourcemanager.rmcontainer.RMContainerImpl: Processing container_1559895028500_0001_01_000002 of type LAUNCHED
2019-06-07 08:11:00,836 DEBUG org.apache.hadoop.yarn.server.resourcemanager.rmcontainer.RMContainerImpl: Processing container_1559895028500_0001_01_000002 of type LAUNCHED
2019-06-07 08:11:00,836 INFO org.apache.hadoop.yarn.server.resourcemanager.rmcontainer.RMContainerImpl: container_1559895028500_0001_01_000002 Container Transitioned from ACQUIRED to RUNNING
2019-06-07 08:11:00,836 INFO org.apache.hadoop.yarn.server.resourcemanager.rmcontainer.RMContainerImpl: container_1559895028500_0001_01_000002 Container Transitioned from ACQUIRED to RUNNING
2019-06-07 08:11:00,836 DEBUG org.apache.hadoop.yarn.server.resourcemanager.scheduler.capacity.CapacityScheduler: Node being looked for scheduling slave1:41069 availableResource: <memory:1024, vCores:0>
2019-06-07 08:11:00,836 DEBUG org.apache.hadoop.yarn.server.resourcemanager.scheduler.capacity.CapacityScheduler: Node being looked for scheduling slave1:41069 availableResource: <memory:1024, vCores:0>
2019-06-07 08:11:00,836 DEBUG org.apache.hadoop.yarn.server.resourcemanager.scheduler.capacity.CapacityScheduler: Trying to schedule on node: slave1, available: <memory:1024, vCores:0>
2019-06-07 08:11:00,836 DEBUG org.apache.hadoop.yarn.server.resourcemanager.scheduler.capacity.CapacityScheduler: Trying to schedule on node: slave1, available: <memory:1024, vCores:0>
2019-06-07 08:11:00,836 DEBUG org.apache.hadoop.yarn.server.resourcemanager.scheduler.capacity.ParentQueue: Skip this queue=root, because it doesn't need more resource, schedulingMode=RESPECT_PARTITION_EXCLUSIVITY node-partition=
2019-06-07 08:11:00,836 DEBUG org.apache.hadoop.yarn.server.resourcemanager.scheduler.capacity.ParentQueue: Skip this queue=root, because it doesn't need more resource, schedulingMode=RESPECT_PARTITION_EXCLUSIVITY node-partition=
2019-06-07 08:11:00,848 DEBUG org.apache.hadoop.yarn.server.resourcemanager.rmnode.RMNodeImpl: Processing slave2:40331 of type STATUS_UPDATE
2019-06-07 08:11:00,848 DEBUG org.apache.hadoop.yarn.server.resourcemanager.rmnode.RMNodeImpl: Processing slave2:40331 of type STATUS_UPDATE
2019-06-07 08:11:00,848 DEBUG org.apache.hadoop.yarn.server.resourcemanager.scheduler.capacity.CapacityScheduler: nodeUpdate: slave2:40331 clusterResources: <memory:8192, vCores:2>
2019-06-07 08:11:00,848 DEBUG org.apache.hadoop.yarn.server.resourcemanager.scheduler.capacity.CapacityScheduler: nodeUpdate: slave2:40331 clusterResources: <memory:8192, vCores:2>
2019-06-07 08:11:00,849 DEBUG org.apache.hadoop.yarn.server.resourcemanager.rmcontainer.RMContainerImpl: Processing container_1559895028500_0001_01_000003 of type LAUNCHED
2019-06-07 08:11:00,849 DEBUG org.apache.hadoop.yarn.server.resourcemanager.rmcontainer.RMContainerImpl: Processing container_1559895028500_0001_01_000003 of type LAUNCHED
2019-06-07 08:11:00,849 INFO org.apache.hadoop.yarn.server.resourcemanager.rmcontainer.RMContainerImpl: container_1559895028500_0001_01_000003 Container Transitioned from ACQUIRED to RUNNING
2019-06-07 08:11:00,849 INFO org.apache.hadoop.yarn.server.resourcemanager.rmcontainer.RMContainerImpl: container_1559895028500_0001_01_000003 Container Transitioned from ACQUIRED to RUNNING
2019-06-07 08:11:00,849 DEBUG org.apache.hadoop.yarn.server.resourcemanager.scheduler.capacity.CapacityScheduler: Node being looked for scheduling slave2:40331 availableResource: <memory:0, vCores:-1>
2019-06-07 08:11:00,849 DEBUG org.apache.hadoop.yarn.server.resourcemanager.scheduler.capacity.CapacityScheduler: Node being looked for scheduling slave2:40331 availableResource: <memory:0, vCores:-1>
2019-06-07 08:11:01,840 DEBUG org.apache.hadoop.yarn.server.resourcemanager.rmnode.RMNodeImpl: Processing slave1:41069 of type STATUS_UPDATE
2019-06-07 08:11:01,840 DEBUG org.apache.hadoop.yarn.server.resourcemanager.rmnode.RMNodeImpl: Processing slave1:41069 of type STATUS_UPDATE
2019-06-07 08:11:01,840 DEBUG org.apache.hadoop.yarn.server.resourcemanager.scheduler.capacity.CapacityScheduler: nodeUpdate: slave1:41069 clusterResources: <memory:8192, vCores:2>
2019-06-07 08:11:01,840 DEBUG org.apache.hadoop.yarn.server.resourcemanager.scheduler.capacity.CapacityScheduler: nodeUpdate: slave1:41069 clusterResources: <memory:8192, vCores:2>
2019-06-07 08:11:01,840 DEBUG org.apache.hadoop.yarn.server.resourcemanager.scheduler.capacity.CapacityScheduler: Node being looked for scheduling slave1:41069 availableResource: <memory:1024, vCores:0>
2019-06-07 08:11:01,840 DEBUG org.apache.hadoop.yarn.server.resourcemanager.scheduler.capacity.CapacityScheduler: Node being looked for scheduling slave1:41069 availableResource: <memory:1024, vCores:0>
2019-06-07 08:11:01,840 DEBUG org.apache.hadoop.yarn.server.resourcemanager.scheduler.capacity.CapacityScheduler: Trying to schedule on node: slave1, available: <memory:1024, vCores:0>
2019-06-07 08:11:01,840 DEBUG org.apache.hadoop.yarn.server.resourcemanager.scheduler.capacity.CapacityScheduler: Trying to schedule on node: slave1, available: <memory:1024, vCores:0>
2019-06-07 08:11:01,840 DEBUG org.apache.hadoop.yarn.server.resourcemanager.scheduler.capacity.ParentQueue: Skip this queue=root, because it doesn't need more resource, schedulingMode=RESPECT_PARTITION_EXCLUSIVITY node-partition=
2019-06-07 08:11:01,840 DEBUG org.apache.hadoop.yarn.server.resourcemanager.scheduler.capacity.ParentQueue: Skip this queue=root, because it doesn't need more resource, schedulingMode=RESPECT_PARTITION_EXCLUSIVITY node-partition=
2019-06-07 08:11:01,859 DEBUG org.apache.hadoop.yarn.server.resourcemanager.rmnode.RMNodeImpl: Processing slave2:40331 of type STATUS_UPDATE
2019-06-07 08:11:01,859 DEBUG org.apache.hadoop.yarn.server.resourcemanager.rmnode.RMNodeImpl: Processing slave2:40331 of type STATUS_UPDATE
2019-06-07 08:11:01,861 DEBUG org.apache.hadoop.yarn.server.resourcemanager.scheduler.capacity.CapacityScheduler: nodeUpdate: slave2:40331 clusterResources: <memory:8192, vCores:2>
2019-06-07 08:11:01,861 DEBUG org.apache.hadoop.yarn.server.resourcemanager.scheduler.capacity.CapacityScheduler: nodeUpdate: slave2:40331 clusterResources: <memory:8192, vCores:2>
2019-06-07 08:11:01,862 DEBUG org.apache.hadoop.yarn.server.resourcemanager.scheduler.capacity.CapacityScheduler: Node being looked for scheduling slave2:40331 availableResource: <memory:0, vCores:-1>
2019-06-07 08:11:01,862 DEBUG org.apache.hadoop.yarn.server.resourcemanager.scheduler.capacity.CapacityScheduler: Node being looked for scheduling slave2:40331 availableResource: <memory:0, vCores:-1>
2019-06-07 08:11:02,875 DEBUG org.apache.hadoop.yarn.server.resourcemanager.rmnode.RMNodeImpl: Processing slave1:41069 of type STATUS_UPDATE
2019-06-07 08:11:02,875 DEBUG org.apache.hadoop.yarn.server.resourcemanager.rmnode.RMNodeImpl: Processing slave1:41069 of type STATUS_UPDATE
2019-06-07 08:11:02,876 DEBUG org.apache.hadoop.yarn.server.resourcemanager.scheduler.capacity.CapacityScheduler: nodeUpdate: slave1:41069 clusterResources: <memory:8192, vCores:2>
2019-06-07 08:11:02,876 DEBUG org.apache.hadoop.yarn.server.resourcemanager.scheduler.capacity.CapacityScheduler: nodeUpdate: slave1:41069 clusterResources: <memory:8192, vCores:2>
2019-06-07 08:11:02,876 DEBUG org.apache.hadoop.yarn.server.resourcemanager.scheduler.capacity.CapacityScheduler: Node being looked for scheduling slave1:41069 availableResource: <memory:1024, vCores:0>
2019-06-07 08:11:02,876 DEBUG org.apache.hadoop.yarn.server.resourcemanager.scheduler.capacity.CapacityScheduler: Node being looked for scheduling slave1:41069 availableResource: <memory:1024, vCores:0>
2019-06-07 08:11:02,876 DEBUG org.apache.hadoop.yarn.server.resourcemanager.scheduler.capacity.CapacityScheduler: Trying to schedule on node: slave1, available: <memory:1024, vCores:0>
2019-06-07 08:11:02,876 DEBUG org.apache.hadoop.yarn.server.resourcemanager.scheduler.capacity.CapacityScheduler: Trying to schedule on node: slave1, available: <memory:1024, vCores:0>
2019-06-07 08:11:02,876 DEBUG org.apache.hadoop.yarn.server.resourcemanager.scheduler.capacity.ParentQueue: Skip this queue=root, because it doesn't need more resource, schedulingMode=RESPECT_PARTITION_EXCLUSIVITY node-partition=
2019-06-07 08:11:02,876 DEBUG org.apache.hadoop.yarn.server.resourcemanager.scheduler.capacity.ParentQueue: Skip this queue=root, because it doesn't need more resource, schedulingMode=RESPECT_PARTITION_EXCLUSIVITY node-partition=
2019-06-07 08:11:02,878 DEBUG org.apache.hadoop.yarn.server.resourcemanager.rmnode.RMNodeImpl: Processing slave2:40331 of type STATUS_UPDATE
2019-06-07 08:11:02,878 DEBUG org.apache.hadoop.yarn.server.resourcemanager.rmnode.RMNodeImpl: Processing slave2:40331 of type STATUS_UPDATE
2019-06-07 08:11:02,878 DEBUG org.apache.hadoop.yarn.server.resourcemanager.scheduler.capacity.CapacityScheduler: nodeUpdate: slave2:40331 clusterResources: <memory:8192, vCores:2>
2019-06-07 08:11:02,878 DEBUG org.apache.hadoop.yarn.server.resourcemanager.scheduler.capacity.CapacityScheduler: nodeUpdate: slave2:40331 clusterResources: <memory:8192, vCores:2>
2019-06-07 08:11:02,878 DEBUG org.apache.hadoop.yarn.server.resourcemanager.scheduler.capacity.CapacityScheduler: Node being looked for scheduling slave2:40331 availableResource: <memory:0, vCores:-1>
2019-06-07 08:11:02,878 DEBUG org.apache.hadoop.yarn.server.resourcemanager.scheduler.capacity.CapacityScheduler: Node being looked for scheduling slave2:40331 availableResource: <memory:0, vCores:-1>
2019-06-07 08:11:02,961 DEBUG org.apache.hadoop.yarn.server.resourcemanager.scheduler.capacity.CapacityScheduler: allocate: pre-update appattempt_1559895028500_0001_000001 ask size =1
2019-06-07 08:11:02,961 DEBUG org.apache.hadoop.yarn.server.resourcemanager.scheduler.capacity.CapacityScheduler: allocate: pre-update appattempt_1559895028500_0001_000001 ask size =1
2019-06-07 08:11:02,962 DEBUG org.apache.hadoop.yarn.server.resourcemanager.rmapp.attempt.RMAppAttemptImpl: Processing event for appattempt_1559895028500_0001_000001 of type STATUS_UPDATE
2019-06-07 08:11:02,962 DEBUG org.apache.hadoop.yarn.server.resourcemanager.rmapp.attempt.RMAppAttemptImpl: Processing event for appattempt_1559895028500_0001_000001 of type STATUS_UPDATE
2019-06-07 08:11:02,962 INFO org.apache.hadoop.yarn.server.resourcemanager.scheduler.AppSchedulingInfo: checking for deactivate of application :application_1559895028500_0001
2019-06-07 08:11:02,962 INFO org.apache.hadoop.yarn.server.resourcemanager.scheduler.AppSchedulingInfo: checking for deactivate of application :application_1559895028500_0001
2019-06-07 08:11:02,962 DEBUG org.apache.hadoop.yarn.server.resourcemanager.scheduler.capacity.CapacityScheduler: allocate: post-update
2019-06-07 08:11:02,962 DEBUG org.apache.hadoop.yarn.server.resourcemanager.scheduler.capacity.CapacityScheduler: allocate: post-update
2019-06-07 08:11:02,962 DEBUG org.apache.hadoop.yarn.server.resourcemanager.scheduler.capacity.LeafQueue: User limit computation for root in queue default userLimitPercent=100 userLimitFactor=1.0 required: <memory:1024, vCores:1> consumed: <memory:7168, vCores:1> user-limit-resource: <memory:8192, vCores:1> queueCapacity: <memory:8192, vCores:1> qconsumed: <memory:7168, vCores:3> consumedRatio: 0.0 currentCapacity: <memory:8192, vCores:1> activeUsers: 0.0 clusterCapacity: <memory:8192, vCores:2> resourceByLabel: <memory:8192, vCores:2> usageratio: 0.875 Partition:  maxUserLimit=<memory:8192, vCores:1> userWeight=1.0
2019-06-07 08:11:02,962 DEBUG org.apache.hadoop.yarn.server.resourcemanager.scheduler.capacity.LeafQueue: User limit computation for root in queue default userLimitPercent=100 userLimitFactor=1.0 required: <memory:1024, vCores:1> consumed: <memory:7168, vCores:1> user-limit-resource: <memory:8192, vCores:1> queueCapacity: <memory:8192, vCores:1> qconsumed: <memory:7168, vCores:3> consumedRatio: 0.0 currentCapacity: <memory:8192, vCores:1> activeUsers: 0.0 clusterCapacity: <memory:8192, vCores:2> resourceByLabel: <memory:8192, vCores:2> usageratio: 0.875 Partition:  maxUserLimit=<memory:8192, vCores:1> userWeight=1.0
2019-06-07 08:11:03,879 DEBUG org.apache.hadoop.yarn.server.resourcemanager.rmnode.RMNodeImpl: Processing slave1:41069 of type STATUS_UPDATE
2019-06-07 08:11:03,879 DEBUG org.apache.hadoop.yarn.server.resourcemanager.rmnode.RMNodeImpl: Processing slave1:41069 of type STATUS_UPDATE
2019-06-07 08:11:03,880 DEBUG org.apache.hadoop.yarn.server.resourcemanager.scheduler.capacity.CapacityScheduler: nodeUpdate: slave1:41069 clusterResources: <memory:8192, vCores:2>
2019-06-07 08:11:03,880 DEBUG org.apache.hadoop.yarn.server.resourcemanager.scheduler.capacity.CapacityScheduler: nodeUpdate: slave1:41069 clusterResources: <memory:8192, vCores:2>
2019-06-07 08:11:03,880 DEBUG org.apache.hadoop.yarn.server.resourcemanager.scheduler.capacity.CapacityScheduler: Node being looked for scheduling slave1:41069 availableResource: <memory:1024, vCores:0>
2019-06-07 08:11:03,880 DEBUG org.apache.hadoop.yarn.server.resourcemanager.scheduler.capacity.CapacityScheduler: Node being looked for scheduling slave1:41069 availableResource: <memory:1024, vCores:0>
2019-06-07 08:11:03,880 DEBUG org.apache.hadoop.yarn.server.resourcemanager.scheduler.capacity.CapacityScheduler: Trying to schedule on node: slave1, available: <memory:1024, vCores:0>
2019-06-07 08:11:03,880 DEBUG org.apache.hadoop.yarn.server.resourcemanager.scheduler.capacity.CapacityScheduler: Trying to schedule on node: slave1, available: <memory:1024, vCores:0>
2019-06-07 08:11:03,880 DEBUG org.apache.hadoop.yarn.server.resourcemanager.scheduler.capacity.ParentQueue: Skip this queue=root, because it doesn't need more resource, schedulingMode=RESPECT_PARTITION_EXCLUSIVITY node-partition=
2019-06-07 08:11:03,880 DEBUG org.apache.hadoop.yarn.server.resourcemanager.scheduler.capacity.ParentQueue: Skip this queue=root, because it doesn't need more resource, schedulingMode=RESPECT_PARTITION_EXCLUSIVITY node-partition=
2019-06-07 08:11:03,884 DEBUG org.apache.hadoop.yarn.server.resourcemanager.rmnode.RMNodeImpl: Processing slave2:40331 of type STATUS_UPDATE
2019-06-07 08:11:03,884 DEBUG org.apache.hadoop.yarn.server.resourcemanager.rmnode.RMNodeImpl: Processing slave2:40331 of type STATUS_UPDATE
2019-06-07 08:11:03,885 DEBUG org.apache.hadoop.yarn.server.resourcemanager.scheduler.capacity.CapacityScheduler: nodeUpdate: slave2:40331 clusterResources: <memory:8192, vCores:2>
2019-06-07 08:11:03,885 DEBUG org.apache.hadoop.yarn.server.resourcemanager.scheduler.capacity.CapacityScheduler: nodeUpdate: slave2:40331 clusterResources: <memory:8192, vCores:2>
2019-06-07 08:11:03,885 DEBUG org.apache.hadoop.yarn.server.resourcemanager.scheduler.capacity.CapacityScheduler: Node being looked for scheduling slave2:40331 availableResource: <memory:0, vCores:-1>
2019-06-07 08:11:03,885 DEBUG org.apache.hadoop.yarn.server.resourcemanager.scheduler.capacity.CapacityScheduler: Node being looked for scheduling slave2:40331 availableResource: <memory:0, vCores:-1>
2019-06-07 08:11:04,885 DEBUG org.apache.hadoop.yarn.server.resourcemanager.rmnode.RMNodeImpl: Processing slave1:41069 of type STATUS_UPDATE
2019-06-07 08:11:04,885 DEBUG org.apache.hadoop.yarn.server.resourcemanager.rmnode.RMNodeImpl: Processing slave1:41069 of type STATUS_UPDATE
2019-06-07 08:11:04,886 DEBUG org.apache.hadoop.yarn.server.resourcemanager.scheduler.capacity.CapacityScheduler: nodeUpdate: slave1:41069 clusterResources: <memory:8192, vCores:2>
2019-06-07 08:11:04,886 DEBUG org.apache.hadoop.yarn.server.resourcemanager.scheduler.capacity.CapacityScheduler: nodeUpdate: slave1:41069 clusterResources: <memory:8192, vCores:2>
2019-06-07 08:11:04,886 DEBUG org.apache.hadoop.yarn.server.resourcemanager.scheduler.capacity.CapacityScheduler: Node being looked for scheduling slave1:41069 availableResource: <memory:1024, vCores:0>
2019-06-07 08:11:04,886 DEBUG org.apache.hadoop.yarn.server.resourcemanager.scheduler.capacity.CapacityScheduler: Node being looked for scheduling slave1:41069 availableResource: <memory:1024, vCores:0>
2019-06-07 08:11:04,886 DEBUG org.apache.hadoop.yarn.server.resourcemanager.scheduler.capacity.CapacityScheduler: Trying to schedule on node: slave1, available: <memory:1024, vCores:0>
2019-06-07 08:11:04,886 DEBUG org.apache.hadoop.yarn.server.resourcemanager.scheduler.capacity.CapacityScheduler: Trying to schedule on node: slave1, available: <memory:1024, vCores:0>
2019-06-07 08:11:04,886 DEBUG org.apache.hadoop.yarn.server.resourcemanager.scheduler.capacity.ParentQueue: Skip this queue=root, because it doesn't need more resource, schedulingMode=RESPECT_PARTITION_EXCLUSIVITY node-partition=
2019-06-07 08:11:04,886 DEBUG org.apache.hadoop.yarn.server.resourcemanager.scheduler.capacity.ParentQueue: Skip this queue=root, because it doesn't need more resource, schedulingMode=RESPECT_PARTITION_EXCLUSIVITY node-partition=
2019-06-07 08:11:04,889 DEBUG org.apache.hadoop.yarn.server.resourcemanager.rmnode.RMNodeImpl: Processing slave2:40331 of type STATUS_UPDATE
2019-06-07 08:11:04,889 DEBUG org.apache.hadoop.yarn.server.resourcemanager.rmnode.RMNodeImpl: Processing slave2:40331 of type STATUS_UPDATE
2019-06-07 08:11:04,889 DEBUG org.apache.hadoop.yarn.server.resourcemanager.scheduler.capacity.CapacityScheduler: nodeUpdate: slave2:40331 clusterResources: <memory:8192, vCores:2>
2019-06-07 08:11:04,889 DEBUG org.apache.hadoop.yarn.server.resourcemanager.scheduler.capacity.CapacityScheduler: nodeUpdate: slave2:40331 clusterResources: <memory:8192, vCores:2>
2019-06-07 08:11:04,889 DEBUG org.apache.hadoop.yarn.server.resourcemanager.scheduler.capacity.CapacityScheduler: Node being looked for scheduling slave2:40331 availableResource: <memory:0, vCores:-1>
2019-06-07 08:11:04,889 DEBUG org.apache.hadoop.yarn.server.resourcemanager.scheduler.capacity.CapacityScheduler: Node being looked for scheduling slave2:40331 availableResource: <memory:0, vCores:-1>
2019-06-07 08:11:05,890 DEBUG org.apache.hadoop.yarn.server.resourcemanager.rmnode.RMNodeImpl: Processing slave1:41069 of type STATUS_UPDATE
2019-06-07 08:11:05,890 DEBUG org.apache.hadoop.yarn.server.resourcemanager.rmnode.RMNodeImpl: Processing slave1:41069 of type STATUS_UPDATE
2019-06-07 08:11:05,890 DEBUG org.apache.hadoop.yarn.server.resourcemanager.scheduler.capacity.CapacityScheduler: nodeUpdate: slave1:41069 clusterResources: <memory:8192, vCores:2>
2019-06-07 08:11:05,890 DEBUG org.apache.hadoop.yarn.server.resourcemanager.scheduler.capacity.CapacityScheduler: nodeUpdate: slave1:41069 clusterResources: <memory:8192, vCores:2>
2019-06-07 08:11:05,890 DEBUG org.apache.hadoop.yarn.server.resourcemanager.scheduler.capacity.CapacityScheduler: Node being looked for scheduling slave1:41069 availableResource: <memory:1024, vCores:0>
2019-06-07 08:11:05,890 DEBUG org.apache.hadoop.yarn.server.resourcemanager.scheduler.capacity.CapacityScheduler: Node being looked for scheduling slave1:41069 availableResource: <memory:1024, vCores:0>
2019-06-07 08:11:05,890 DEBUG org.apache.hadoop.yarn.server.resourcemanager.scheduler.capacity.CapacityScheduler: Trying to schedule on node: slave1, available: <memory:1024, vCores:0>
2019-06-07 08:11:05,890 DEBUG org.apache.hadoop.yarn.server.resourcemanager.scheduler.capacity.CapacityScheduler: Trying to schedule on node: slave1, available: <memory:1024, vCores:0>
2019-06-07 08:11:05,890 DEBUG org.apache.hadoop.yarn.server.resourcemanager.scheduler.capacity.ParentQueue: Skip this queue=root, because it doesn't need more resource, schedulingMode=RESPECT_PARTITION_EXCLUSIVITY node-partition=
2019-06-07 08:11:05,890 DEBUG org.apache.hadoop.yarn.server.resourcemanager.scheduler.capacity.ParentQueue: Skip this queue=root, because it doesn't need more resource, schedulingMode=RESPECT_PARTITION_EXCLUSIVITY node-partition=
2019-06-07 08:11:05,892 DEBUG org.apache.hadoop.yarn.server.resourcemanager.rmnode.RMNodeImpl: Processing slave2:40331 of type STATUS_UPDATE
2019-06-07 08:11:05,892 DEBUG org.apache.hadoop.yarn.server.resourcemanager.rmnode.RMNodeImpl: Processing slave2:40331 of type STATUS_UPDATE
2019-06-07 08:11:05,893 DEBUG org.apache.hadoop.yarn.server.resourcemanager.scheduler.capacity.CapacityScheduler: nodeUpdate: slave2:40331 clusterResources: <memory:8192, vCores:2>
2019-06-07 08:11:05,893 DEBUG org.apache.hadoop.yarn.server.resourcemanager.scheduler.capacity.CapacityScheduler: nodeUpdate: slave2:40331 clusterResources: <memory:8192, vCores:2>
2019-06-07 08:11:05,893 DEBUG org.apache.hadoop.yarn.server.resourcemanager.scheduler.capacity.CapacityScheduler: Node being looked for scheduling slave2:40331 availableResource: <memory:0, vCores:-1>
2019-06-07 08:11:05,893 DEBUG org.apache.hadoop.yarn.server.resourcemanager.scheduler.capacity.CapacityScheduler: Node being looked for scheduling slave2:40331 availableResource: <memory:0, vCores:-1>
2019-06-07 08:11:05,973 DEBUG org.apache.hadoop.yarn.server.resourcemanager.rmapp.attempt.RMAppAttemptImpl: Processing event for appattempt_1559895028500_0001_000001 of type STATUS_UPDATE
2019-06-07 08:11:05,973 DEBUG org.apache.hadoop.yarn.server.resourcemanager.rmapp.attempt.RMAppAttemptImpl: Processing event for appattempt_1559895028500_0001_000001 of type STATUS_UPDATE
2019-06-07 08:11:05,974 DEBUG org.apache.hadoop.yarn.server.resourcemanager.scheduler.capacity.LeafQueue: User limit computation for root in queue default userLimitPercent=100 userLimitFactor=1.0 required: <memory:1024, vCores:1> consumed: <memory:7168, vCores:1> user-limit-resource: <memory:8192, vCores:1> queueCapacity: <memory:8192, vCores:1> qconsumed: <memory:7168, vCores:3> consumedRatio: 0.0 currentCapacity: <memory:8192, vCores:1> activeUsers: 0.0 clusterCapacity: <memory:8192, vCores:2> resourceByLabel: <memory:8192, vCores:2> usageratio: 0.875 Partition:  maxUserLimit=<memory:8192, vCores:1> userWeight=1.0
2019-06-07 08:11:05,974 DEBUG org.apache.hadoop.yarn.server.resourcemanager.scheduler.capacity.LeafQueue: User limit computation for root in queue default userLimitPercent=100 userLimitFactor=1.0 required: <memory:1024, vCores:1> consumed: <memory:7168, vCores:1> user-limit-resource: <memory:8192, vCores:1> queueCapacity: <memory:8192, vCores:1> qconsumed: <memory:7168, vCores:3> consumedRatio: 0.0 currentCapacity: <memory:8192, vCores:1> activeUsers: 0.0 clusterCapacity: <memory:8192, vCores:2> resourceByLabel: <memory:8192, vCores:2> usageratio: 0.875 Partition:  maxUserLimit=<memory:8192, vCores:1> userWeight=1.0
2019-06-07 08:11:06,899 DEBUG org.apache.hadoop.yarn.server.resourcemanager.rmnode.RMNodeImpl: Processing slave2:40331 of type STATUS_UPDATE
2019-06-07 08:11:06,899 DEBUG org.apache.hadoop.yarn.server.resourcemanager.rmnode.RMNodeImpl: Processing slave2:40331 of type STATUS_UPDATE
2019-06-07 08:11:06,899 DEBUG org.apache.hadoop.yarn.server.resourcemanager.scheduler.capacity.CapacityScheduler: nodeUpdate: slave2:40331 clusterResources: <memory:8192, vCores:2>
2019-06-07 08:11:06,899 DEBUG org.apache.hadoop.yarn.server.resourcemanager.scheduler.capacity.CapacityScheduler: nodeUpdate: slave2:40331 clusterResources: <memory:8192, vCores:2>
2019-06-07 08:11:06,900 DEBUG org.apache.hadoop.yarn.server.resourcemanager.scheduler.capacity.CapacityScheduler: Node being looked for scheduling slave2:40331 availableResource: <memory:0, vCores:-1>
2019-06-07 08:11:06,900 DEBUG org.apache.hadoop.yarn.server.resourcemanager.scheduler.capacity.CapacityScheduler: Node being looked for scheduling slave2:40331 availableResource: <memory:0, vCores:-1>
2019-06-07 08:11:06,903 DEBUG org.apache.hadoop.yarn.server.resourcemanager.rmnode.RMNodeImpl: Processing slave1:41069 of type STATUS_UPDATE
2019-06-07 08:11:06,903 DEBUG org.apache.hadoop.yarn.server.resourcemanager.rmnode.RMNodeImpl: Processing slave1:41069 of type STATUS_UPDATE
2019-06-07 08:11:06,903 DEBUG org.apache.hadoop.yarn.server.resourcemanager.scheduler.capacity.CapacityScheduler: nodeUpdate: slave1:41069 clusterResources: <memory:8192, vCores:2>
2019-06-07 08:11:06,903 DEBUG org.apache.hadoop.yarn.server.resourcemanager.scheduler.capacity.CapacityScheduler: nodeUpdate: slave1:41069 clusterResources: <memory:8192, vCores:2>
2019-06-07 08:11:06,903 DEBUG org.apache.hadoop.yarn.server.resourcemanager.scheduler.capacity.CapacityScheduler: Node being looked for scheduling slave1:41069 availableResource: <memory:1024, vCores:0>
2019-06-07 08:11:06,903 DEBUG org.apache.hadoop.yarn.server.resourcemanager.scheduler.capacity.CapacityScheduler: Node being looked for scheduling slave1:41069 availableResource: <memory:1024, vCores:0>
2019-06-07 08:11:06,903 DEBUG org.apache.hadoop.yarn.server.resourcemanager.scheduler.capacity.CapacityScheduler: Trying to schedule on node: slave1, available: <memory:1024, vCores:0>
2019-06-07 08:11:06,903 DEBUG org.apache.hadoop.yarn.server.resourcemanager.scheduler.capacity.CapacityScheduler: Trying to schedule on node: slave1, available: <memory:1024, vCores:0>
2019-06-07 08:11:06,904 DEBUG org.apache.hadoop.yarn.server.resourcemanager.scheduler.capacity.ParentQueue: Skip this queue=root, because it doesn't need more resource, schedulingMode=RESPECT_PARTITION_EXCLUSIVITY node-partition=
2019-06-07 08:11:06,904 DEBUG org.apache.hadoop.yarn.server.resourcemanager.scheduler.capacity.ParentQueue: Skip this queue=root, because it doesn't need more resource, schedulingMode=RESPECT_PARTITION_EXCLUSIVITY node-partition=
2019-06-07 08:11:07,904 DEBUG org.apache.hadoop.yarn.server.resourcemanager.rmnode.RMNodeImpl: Processing slave2:40331 of type STATUS_UPDATE
2019-06-07 08:11:07,904 DEBUG org.apache.hadoop.yarn.server.resourcemanager.rmnode.RMNodeImpl: Processing slave2:40331 of type STATUS_UPDATE
2019-06-07 08:11:07,904 DEBUG org.apache.hadoop.yarn.server.resourcemanager.scheduler.capacity.CapacityScheduler: nodeUpdate: slave2:40331 clusterResources: <memory:8192, vCores:2>
2019-06-07 08:11:07,904 DEBUG org.apache.hadoop.yarn.server.resourcemanager.scheduler.capacity.CapacityScheduler: nodeUpdate: slave2:40331 clusterResources: <memory:8192, vCores:2>
2019-06-07 08:11:07,904 DEBUG org.apache.hadoop.yarn.server.resourcemanager.scheduler.capacity.CapacityScheduler: Node being looked for scheduling slave2:40331 availableResource: <memory:0, vCores:-1>
2019-06-07 08:11:07,904 DEBUG org.apache.hadoop.yarn.server.resourcemanager.scheduler.capacity.CapacityScheduler: Node being looked for scheduling slave2:40331 availableResource: <memory:0, vCores:-1>
2019-06-07 08:11:07,907 DEBUG org.apache.hadoop.yarn.server.resourcemanager.rmnode.RMNodeImpl: Processing slave1:41069 of type STATUS_UPDATE
2019-06-07 08:11:07,907 DEBUG org.apache.hadoop.yarn.server.resourcemanager.rmnode.RMNodeImpl: Processing slave1:41069 of type STATUS_UPDATE
2019-06-07 08:11:07,907 DEBUG org.apache.hadoop.yarn.server.resourcemanager.scheduler.capacity.CapacityScheduler: nodeUpdate: slave1:41069 clusterResources: <memory:8192, vCores:2>
2019-06-07 08:11:07,907 DEBUG org.apache.hadoop.yarn.server.resourcemanager.scheduler.capacity.CapacityScheduler: nodeUpdate: slave1:41069 clusterResources: <memory:8192, vCores:2>
2019-06-07 08:11:07,907 DEBUG org.apache.hadoop.yarn.server.resourcemanager.scheduler.capacity.CapacityScheduler: Node being looked for scheduling slave1:41069 availableResource: <memory:1024, vCores:0>
2019-06-07 08:11:07,907 DEBUG org.apache.hadoop.yarn.server.resourcemanager.scheduler.capacity.CapacityScheduler: Node being looked for scheduling slave1:41069 availableResource: <memory:1024, vCores:0>
2019-06-07 08:11:07,907 DEBUG org.apache.hadoop.yarn.server.resourcemanager.scheduler.capacity.CapacityScheduler: Trying to schedule on node: slave1, available: <memory:1024, vCores:0>
2019-06-07 08:11:07,907 DEBUG org.apache.hadoop.yarn.server.resourcemanager.scheduler.capacity.CapacityScheduler: Trying to schedule on node: slave1, available: <memory:1024, vCores:0>
2019-06-07 08:11:07,907 DEBUG org.apache.hadoop.yarn.server.resourcemanager.scheduler.capacity.ParentQueue: Skip this queue=root, because it doesn't need more resource, schedulingMode=RESPECT_PARTITION_EXCLUSIVITY node-partition=
2019-06-07 08:11:07,907 DEBUG org.apache.hadoop.yarn.server.resourcemanager.scheduler.capacity.ParentQueue: Skip this queue=root, because it doesn't need more resource, schedulingMode=RESPECT_PARTITION_EXCLUSIVITY node-partition=
2019-06-07 08:11:08,907 DEBUG org.apache.hadoop.yarn.server.resourcemanager.rmnode.RMNodeImpl: Processing slave2:40331 of type STATUS_UPDATE
2019-06-07 08:11:08,907 DEBUG org.apache.hadoop.yarn.server.resourcemanager.rmnode.RMNodeImpl: Processing slave2:40331 of type STATUS_UPDATE
2019-06-07 08:11:08,907 DEBUG org.apache.hadoop.yarn.server.resourcemanager.scheduler.capacity.CapacityScheduler: nodeUpdate: slave2:40331 clusterResources: <memory:8192, vCores:2>
2019-06-07 08:11:08,907 DEBUG org.apache.hadoop.yarn.server.resourcemanager.scheduler.capacity.CapacityScheduler: nodeUpdate: slave2:40331 clusterResources: <memory:8192, vCores:2>
2019-06-07 08:11:08,907 DEBUG org.apache.hadoop.yarn.server.resourcemanager.scheduler.capacity.CapacityScheduler: Node being looked for scheduling slave2:40331 availableResource: <memory:0, vCores:-1>
2019-06-07 08:11:08,907 DEBUG org.apache.hadoop.yarn.server.resourcemanager.scheduler.capacity.CapacityScheduler: Node being looked for scheduling slave2:40331 availableResource: <memory:0, vCores:-1>
2019-06-07 08:11:08,911 DEBUG org.apache.hadoop.yarn.server.resourcemanager.rmnode.RMNodeImpl: Processing slave1:41069 of type STATUS_UPDATE
2019-06-07 08:11:08,911 DEBUG org.apache.hadoop.yarn.server.resourcemanager.rmnode.RMNodeImpl: Processing slave1:41069 of type STATUS_UPDATE
2019-06-07 08:11:08,911 DEBUG org.apache.hadoop.yarn.server.resourcemanager.scheduler.capacity.CapacityScheduler: nodeUpdate: slave1:41069 clusterResources: <memory:8192, vCores:2>
2019-06-07 08:11:08,911 DEBUG org.apache.hadoop.yarn.server.resourcemanager.scheduler.capacity.CapacityScheduler: nodeUpdate: slave1:41069 clusterResources: <memory:8192, vCores:2>
2019-06-07 08:11:08,911 DEBUG org.apache.hadoop.yarn.server.resourcemanager.scheduler.capacity.CapacityScheduler: Node being looked for scheduling slave1:41069 availableResource: <memory:1024, vCores:0>
2019-06-07 08:11:08,911 DEBUG org.apache.hadoop.yarn.server.resourcemanager.scheduler.capacity.CapacityScheduler: Node being looked for scheduling slave1:41069 availableResource: <memory:1024, vCores:0>
2019-06-07 08:11:08,911 DEBUG org.apache.hadoop.yarn.server.resourcemanager.scheduler.capacity.CapacityScheduler: Trying to schedule on node: slave1, available: <memory:1024, vCores:0>
2019-06-07 08:11:08,911 DEBUG org.apache.hadoop.yarn.server.resourcemanager.scheduler.capacity.CapacityScheduler: Trying to schedule on node: slave1, available: <memory:1024, vCores:0>
2019-06-07 08:11:08,911 DEBUG org.apache.hadoop.yarn.server.resourcemanager.scheduler.capacity.ParentQueue: Skip this queue=root, because it doesn't need more resource, schedulingMode=RESPECT_PARTITION_EXCLUSIVITY node-partition=
2019-06-07 08:11:08,911 DEBUG org.apache.hadoop.yarn.server.resourcemanager.scheduler.capacity.ParentQueue: Skip this queue=root, because it doesn't need more resource, schedulingMode=RESPECT_PARTITION_EXCLUSIVITY node-partition=
2019-06-07 08:11:08,980 DEBUG org.apache.hadoop.yarn.server.resourcemanager.rmapp.attempt.RMAppAttemptImpl: Processing event for appattempt_1559895028500_0001_000001 of type STATUS_UPDATE
2019-06-07 08:11:08,980 DEBUG org.apache.hadoop.yarn.server.resourcemanager.rmapp.attempt.RMAppAttemptImpl: Processing event for appattempt_1559895028500_0001_000001 of type STATUS_UPDATE
2019-06-07 08:11:08,981 DEBUG org.apache.hadoop.yarn.server.resourcemanager.scheduler.capacity.LeafQueue: User limit computation for root in queue default userLimitPercent=100 userLimitFactor=1.0 required: <memory:1024, vCores:1> consumed: <memory:7168, vCores:1> user-limit-resource: <memory:8192, vCores:1> queueCapacity: <memory:8192, vCores:1> qconsumed: <memory:7168, vCores:3> consumedRatio: 0.0 currentCapacity: <memory:8192, vCores:1> activeUsers: 0.0 clusterCapacity: <memory:8192, vCores:2> resourceByLabel: <memory:8192, vCores:2> usageratio: 0.875 Partition:  maxUserLimit=<memory:8192, vCores:1> userWeight=1.0
2019-06-07 08:11:08,981 DEBUG org.apache.hadoop.yarn.server.resourcemanager.scheduler.capacity.LeafQueue: User limit computation for root in queue default userLimitPercent=100 userLimitFactor=1.0 required: <memory:1024, vCores:1> consumed: <memory:7168, vCores:1> user-limit-resource: <memory:8192, vCores:1> queueCapacity: <memory:8192, vCores:1> qconsumed: <memory:7168, vCores:3> consumedRatio: 0.0 currentCapacity: <memory:8192, vCores:1> activeUsers: 0.0 clusterCapacity: <memory:8192, vCores:2> resourceByLabel: <memory:8192, vCores:2> usageratio: 0.875 Partition:  maxUserLimit=<memory:8192, vCores:1> userWeight=1.0
2019-06-07 08:11:09,910 DEBUG org.apache.hadoop.yarn.server.resourcemanager.rmnode.RMNodeImpl: Processing slave2:40331 of type STATUS_UPDATE
2019-06-07 08:11:09,910 DEBUG org.apache.hadoop.yarn.server.resourcemanager.rmnode.RMNodeImpl: Processing slave2:40331 of type STATUS_UPDATE
2019-06-07 08:11:09,910 DEBUG org.apache.hadoop.yarn.server.resourcemanager.scheduler.capacity.CapacityScheduler: nodeUpdate: slave2:40331 clusterResources: <memory:8192, vCores:2>
2019-06-07 08:11:09,910 DEBUG org.apache.hadoop.yarn.server.resourcemanager.scheduler.capacity.CapacityScheduler: nodeUpdate: slave2:40331 clusterResources: <memory:8192, vCores:2>
2019-06-07 08:11:09,910 DEBUG org.apache.hadoop.yarn.server.resourcemanager.scheduler.capacity.CapacityScheduler: Node being looked for scheduling slave2:40331 availableResource: <memory:0, vCores:-1>
2019-06-07 08:11:09,910 DEBUG org.apache.hadoop.yarn.server.resourcemanager.scheduler.capacity.CapacityScheduler: Node being looked for scheduling slave2:40331 availableResource: <memory:0, vCores:-1>
2019-06-07 08:11:09,913 DEBUG org.apache.hadoop.yarn.server.resourcemanager.rmnode.RMNodeImpl: Processing slave1:41069 of type STATUS_UPDATE
2019-06-07 08:11:09,913 DEBUG org.apache.hadoop.yarn.server.resourcemanager.rmnode.RMNodeImpl: Processing slave1:41069 of type STATUS_UPDATE
2019-06-07 08:11:09,914 DEBUG org.apache.hadoop.yarn.server.resourcemanager.scheduler.capacity.CapacityScheduler: nodeUpdate: slave1:41069 clusterResources: <memory:8192, vCores:2>
2019-06-07 08:11:09,914 DEBUG org.apache.hadoop.yarn.server.resourcemanager.scheduler.capacity.CapacityScheduler: nodeUpdate: slave1:41069 clusterResources: <memory:8192, vCores:2>
2019-06-07 08:11:09,914 DEBUG org.apache.hadoop.yarn.server.resourcemanager.scheduler.capacity.CapacityScheduler: Node being looked for scheduling slave1:41069 availableResource: <memory:1024, vCores:0>
2019-06-07 08:11:09,914 DEBUG org.apache.hadoop.yarn.server.resourcemanager.scheduler.capacity.CapacityScheduler: Node being looked for scheduling slave1:41069 availableResource: <memory:1024, vCores:0>
2019-06-07 08:11:09,914 DEBUG org.apache.hadoop.yarn.server.resourcemanager.scheduler.capacity.CapacityScheduler: Trying to schedule on node: slave1, available: <memory:1024, vCores:0>
2019-06-07 08:11:09,914 DEBUG org.apache.hadoop.yarn.server.resourcemanager.scheduler.capacity.CapacityScheduler: Trying to schedule on node: slave1, available: <memory:1024, vCores:0>
2019-06-07 08:11:09,914 DEBUG org.apache.hadoop.yarn.server.resourcemanager.scheduler.capacity.ParentQueue: Skip this queue=root, because it doesn't need more resource, schedulingMode=RESPECT_PARTITION_EXCLUSIVITY node-partition=
2019-06-07 08:11:09,914 DEBUG org.apache.hadoop.yarn.server.resourcemanager.scheduler.capacity.ParentQueue: Skip this queue=root, because it doesn't need more resource, schedulingMode=RESPECT_PARTITION_EXCLUSIVITY node-partition=
2019-06-07 08:11:10,914 DEBUG org.apache.hadoop.yarn.server.resourcemanager.rmnode.RMNodeImpl: Processing slave2:40331 of type STATUS_UPDATE
2019-06-07 08:11:10,914 DEBUG org.apache.hadoop.yarn.server.resourcemanager.rmnode.RMNodeImpl: Processing slave2:40331 of type STATUS_UPDATE
2019-06-07 08:11:10,914 DEBUG org.apache.hadoop.yarn.server.resourcemanager.scheduler.capacity.CapacityScheduler: nodeUpdate: slave2:40331 clusterResources: <memory:8192, vCores:2>
2019-06-07 08:11:10,914 DEBUG org.apache.hadoop.yarn.server.resourcemanager.scheduler.capacity.CapacityScheduler: nodeUpdate: slave2:40331 clusterResources: <memory:8192, vCores:2>
2019-06-07 08:11:10,914 DEBUG org.apache.hadoop.yarn.server.resourcemanager.scheduler.capacity.CapacityScheduler: Node being looked for scheduling slave2:40331 availableResource: <memory:0, vCores:-1>
2019-06-07 08:11:10,914 DEBUG org.apache.hadoop.yarn.server.resourcemanager.scheduler.capacity.CapacityScheduler: Node being looked for scheduling slave2:40331 availableResource: <memory:0, vCores:-1>
2019-06-07 08:11:10,928 DEBUG org.apache.hadoop.yarn.server.resourcemanager.rmnode.RMNodeImpl: Processing slave1:41069 of type STATUS_UPDATE
2019-06-07 08:11:10,928 DEBUG org.apache.hadoop.yarn.server.resourcemanager.rmnode.RMNodeImpl: Processing slave1:41069 of type STATUS_UPDATE
2019-06-07 08:11:10,929 DEBUG org.apache.hadoop.yarn.server.resourcemanager.scheduler.capacity.CapacityScheduler: nodeUpdate: slave1:41069 clusterResources: <memory:8192, vCores:2>
2019-06-07 08:11:10,929 DEBUG org.apache.hadoop.yarn.server.resourcemanager.scheduler.capacity.CapacityScheduler: nodeUpdate: slave1:41069 clusterResources: <memory:8192, vCores:2>
2019-06-07 08:11:10,929 DEBUG org.apache.hadoop.yarn.server.resourcemanager.scheduler.capacity.CapacityScheduler: Node being looked for scheduling slave1:41069 availableResource: <memory:1024, vCores:0>
2019-06-07 08:11:10,929 DEBUG org.apache.hadoop.yarn.server.resourcemanager.scheduler.capacity.CapacityScheduler: Node being looked for scheduling slave1:41069 availableResource: <memory:1024, vCores:0>
2019-06-07 08:11:10,929 DEBUG org.apache.hadoop.yarn.server.resourcemanager.scheduler.capacity.CapacityScheduler: Trying to schedule on node: slave1, available: <memory:1024, vCores:0>
2019-06-07 08:11:10,929 DEBUG org.apache.hadoop.yarn.server.resourcemanager.scheduler.capacity.CapacityScheduler: Trying to schedule on node: slave1, available: <memory:1024, vCores:0>
2019-06-07 08:11:10,929 DEBUG org.apache.hadoop.yarn.server.resourcemanager.scheduler.capacity.ParentQueue: Skip this queue=root, because it doesn't need more resource, schedulingMode=RESPECT_PARTITION_EXCLUSIVITY node-partition=
2019-06-07 08:11:10,929 DEBUG org.apache.hadoop.yarn.server.resourcemanager.scheduler.capacity.ParentQueue: Skip this queue=root, because it doesn't need more resource, schedulingMode=RESPECT_PARTITION_EXCLUSIVITY node-partition=
2019-06-07 08:11:11,924 DEBUG org.apache.hadoop.yarn.server.resourcemanager.rmnode.RMNodeImpl: Processing slave2:40331 of type STATUS_UPDATE
2019-06-07 08:11:11,924 DEBUG org.apache.hadoop.yarn.server.resourcemanager.rmnode.RMNodeImpl: Processing slave2:40331 of type STATUS_UPDATE
2019-06-07 08:11:11,924 DEBUG org.apache.hadoop.yarn.server.resourcemanager.scheduler.capacity.CapacityScheduler: nodeUpdate: slave2:40331 clusterResources: <memory:8192, vCores:2>
2019-06-07 08:11:11,924 DEBUG org.apache.hadoop.yarn.server.resourcemanager.scheduler.capacity.CapacityScheduler: nodeUpdate: slave2:40331 clusterResources: <memory:8192, vCores:2>
2019-06-07 08:11:11,924 DEBUG org.apache.hadoop.yarn.server.resourcemanager.scheduler.capacity.CapacityScheduler: Node being looked for scheduling slave2:40331 availableResource: <memory:0, vCores:-1>
2019-06-07 08:11:11,924 DEBUG org.apache.hadoop.yarn.server.resourcemanager.scheduler.capacity.CapacityScheduler: Node being looked for scheduling slave2:40331 availableResource: <memory:0, vCores:-1>
2019-06-07 08:11:11,933 DEBUG org.apache.hadoop.yarn.server.resourcemanager.rmnode.RMNodeImpl: Processing slave1:41069 of type STATUS_UPDATE
2019-06-07 08:11:11,933 DEBUG org.apache.hadoop.yarn.server.resourcemanager.rmnode.RMNodeImpl: Processing slave1:41069 of type STATUS_UPDATE
2019-06-07 08:11:11,933 DEBUG org.apache.hadoop.yarn.server.resourcemanager.scheduler.capacity.CapacityScheduler: nodeUpdate: slave1:41069 clusterResources: <memory:8192, vCores:2>
2019-06-07 08:11:11,933 DEBUG org.apache.hadoop.yarn.server.resourcemanager.scheduler.capacity.CapacityScheduler: nodeUpdate: slave1:41069 clusterResources: <memory:8192, vCores:2>
2019-06-07 08:11:11,934 DEBUG org.apache.hadoop.yarn.server.resourcemanager.scheduler.capacity.CapacityScheduler: Node being looked for scheduling slave1:41069 availableResource: <memory:1024, vCores:0>
2019-06-07 08:11:11,934 DEBUG org.apache.hadoop.yarn.server.resourcemanager.scheduler.capacity.CapacityScheduler: Node being looked for scheduling slave1:41069 availableResource: <memory:1024, vCores:0>
2019-06-07 08:11:11,934 DEBUG org.apache.hadoop.yarn.server.resourcemanager.scheduler.capacity.CapacityScheduler: Trying to schedule on node: slave1, available: <memory:1024, vCores:0>
2019-06-07 08:11:11,934 DEBUG org.apache.hadoop.yarn.server.resourcemanager.scheduler.capacity.CapacityScheduler: Trying to schedule on node: slave1, available: <memory:1024, vCores:0>
2019-06-07 08:11:11,934 DEBUG org.apache.hadoop.yarn.server.resourcemanager.scheduler.capacity.ParentQueue: Skip this queue=root, because it doesn't need more resource, schedulingMode=RESPECT_PARTITION_EXCLUSIVITY node-partition=
2019-06-07 08:11:11,934 DEBUG org.apache.hadoop.yarn.server.resourcemanager.scheduler.capacity.ParentQueue: Skip this queue=root, because it doesn't need more resource, schedulingMode=RESPECT_PARTITION_EXCLUSIVITY node-partition=
2019-06-07 08:11:12,004 DEBUG org.apache.hadoop.yarn.server.resourcemanager.scheduler.capacity.LeafQueue: User limit computation for root in queue default userLimitPercent=100 userLimitFactor=1.0 required: <memory:1024, vCores:1> consumed: <memory:7168, vCores:1> user-limit-resource: <memory:8192, vCores:1> queueCapacity: <memory:8192, vCores:1> qconsumed: <memory:7168, vCores:3> consumedRatio: 0.0 currentCapacity: <memory:8192, vCores:1> activeUsers: 0.0 clusterCapacity: <memory:8192, vCores:2> resourceByLabel: <memory:8192, vCores:2> usageratio: 0.875 Partition:  maxUserLimit=<memory:8192, vCores:1> userWeight=1.0
2019-06-07 08:11:12,004 DEBUG org.apache.hadoop.yarn.server.resourcemanager.scheduler.capacity.LeafQueue: User limit computation for root in queue default userLimitPercent=100 userLimitFactor=1.0 required: <memory:1024, vCores:1> consumed: <memory:7168, vCores:1> user-limit-resource: <memory:8192, vCores:1> queueCapacity: <memory:8192, vCores:1> qconsumed: <memory:7168, vCores:3> consumedRatio: 0.0 currentCapacity: <memory:8192, vCores:1> activeUsers: 0.0 clusterCapacity: <memory:8192, vCores:2> resourceByLabel: <memory:8192, vCores:2> usageratio: 0.875 Partition:  maxUserLimit=<memory:8192, vCores:1> userWeight=1.0
2019-06-07 08:11:12,005 DEBUG org.apache.hadoop.yarn.server.resourcemanager.rmapp.attempt.RMAppAttemptImpl: Processing event for appattempt_1559895028500_0001_000001 of type STATUS_UPDATE
2019-06-07 08:11:12,005 DEBUG org.apache.hadoop.yarn.server.resourcemanager.rmapp.attempt.RMAppAttemptImpl: Processing event for appattempt_1559895028500_0001_000001 of type STATUS_UPDATE
2019-06-07 08:11:12,935 DEBUG org.apache.hadoop.yarn.server.resourcemanager.rmnode.RMNodeImpl: Processing slave2:40331 of type STATUS_UPDATE
2019-06-07 08:11:12,935 DEBUG org.apache.hadoop.yarn.server.resourcemanager.rmnode.RMNodeImpl: Processing slave2:40331 of type STATUS_UPDATE
2019-06-07 08:11:12,935 DEBUG org.apache.hadoop.yarn.server.resourcemanager.scheduler.capacity.CapacityScheduler: nodeUpdate: slave2:40331 clusterResources: <memory:8192, vCores:2>
2019-06-07 08:11:12,945 DEBUG org.apache.hadoop.yarn.server.resourcemanager.rmnode.RMNodeImpl: Processing slave1:41069 of type STATUS_UPDATE
2019-06-07 08:11:12,935 DEBUG org.apache.hadoop.yarn.server.resourcemanager.scheduler.capacity.CapacityScheduler: nodeUpdate: slave2:40331 clusterResources: <memory:8192, vCores:2>
2019-06-07 08:11:12,945 DEBUG org.apache.hadoop.yarn.server.resourcemanager.scheduler.capacity.CapacityScheduler: Node being looked for scheduling slave2:40331 availableResource: <memory:0, vCores:-1>
2019-06-07 08:11:12,945 DEBUG org.apache.hadoop.yarn.server.resourcemanager.scheduler.capacity.CapacityScheduler: Node being looked for scheduling slave2:40331 availableResource: <memory:0, vCores:-1>
2019-06-07 08:11:12,945 DEBUG org.apache.hadoop.yarn.server.resourcemanager.rmnode.RMNodeImpl: Processing slave1:41069 of type STATUS_UPDATE
2019-06-07 08:11:12,945 DEBUG org.apache.hadoop.yarn.server.resourcemanager.scheduler.capacity.CapacityScheduler: nodeUpdate: slave1:41069 clusterResources: <memory:8192, vCores:2>
2019-06-07 08:11:12,945 DEBUG org.apache.hadoop.yarn.server.resourcemanager.scheduler.capacity.CapacityScheduler: nodeUpdate: slave1:41069 clusterResources: <memory:8192, vCores:2>
2019-06-07 08:11:12,945 DEBUG org.apache.hadoop.yarn.server.resourcemanager.scheduler.capacity.CapacityScheduler: Node being looked for scheduling slave1:41069 availableResource: <memory:1024, vCores:0>
2019-06-07 08:11:12,945 DEBUG org.apache.hadoop.yarn.server.resourcemanager.scheduler.capacity.CapacityScheduler: Node being looked for scheduling slave1:41069 availableResource: <memory:1024, vCores:0>
2019-06-07 08:11:12,945 DEBUG org.apache.hadoop.yarn.server.resourcemanager.scheduler.capacity.CapacityScheduler: Trying to schedule on node: slave1, available: <memory:1024, vCores:0>
2019-06-07 08:11:12,945 DEBUG org.apache.hadoop.yarn.server.resourcemanager.scheduler.capacity.CapacityScheduler: Trying to schedule on node: slave1, available: <memory:1024, vCores:0>
2019-06-07 08:11:12,945 DEBUG org.apache.hadoop.yarn.server.resourcemanager.scheduler.capacity.ParentQueue: Skip this queue=root, because it doesn't need more resource, schedulingMode=RESPECT_PARTITION_EXCLUSIVITY node-partition=
2019-06-07 08:11:12,945 DEBUG org.apache.hadoop.yarn.server.resourcemanager.scheduler.capacity.ParentQueue: Skip this queue=root, because it doesn't need more resource, schedulingMode=RESPECT_PARTITION_EXCLUSIVITY node-partition=
2019-06-07 08:11:13,941 DEBUG org.apache.hadoop.yarn.server.resourcemanager.rmnode.RMNodeImpl: Processing slave2:40331 of type STATUS_UPDATE
2019-06-07 08:11:13,941 DEBUG org.apache.hadoop.yarn.server.resourcemanager.rmnode.RMNodeImpl: Processing slave2:40331 of type STATUS_UPDATE
2019-06-07 08:11:13,942 DEBUG org.apache.hadoop.yarn.server.resourcemanager.scheduler.capacity.CapacityScheduler: nodeUpdate: slave2:40331 clusterResources: <memory:8192, vCores:2>
2019-06-07 08:11:13,942 DEBUG org.apache.hadoop.yarn.server.resourcemanager.scheduler.capacity.CapacityScheduler: nodeUpdate: slave2:40331 clusterResources: <memory:8192, vCores:2>
2019-06-07 08:11:13,942 DEBUG org.apache.hadoop.yarn.server.resourcemanager.scheduler.capacity.CapacityScheduler: Node being looked for scheduling slave2:40331 availableResource: <memory:0, vCores:-1>
2019-06-07 08:11:13,942 DEBUG org.apache.hadoop.yarn.server.resourcemanager.scheduler.capacity.CapacityScheduler: Node being looked for scheduling slave2:40331 availableResource: <memory:0, vCores:-1>
2019-06-07 08:11:13,960 DEBUG org.apache.hadoop.yarn.server.resourcemanager.rmnode.RMNodeImpl: Processing slave1:41069 of type STATUS_UPDATE
2019-06-07 08:11:13,960 DEBUG org.apache.hadoop.yarn.server.resourcemanager.rmnode.RMNodeImpl: Processing slave1:41069 of type STATUS_UPDATE
2019-06-07 08:11:13,960 DEBUG org.apache.hadoop.yarn.server.resourcemanager.scheduler.capacity.CapacityScheduler: nodeUpdate: slave1:41069 clusterResources: <memory:8192, vCores:2>
2019-06-07 08:11:13,960 DEBUG org.apache.hadoop.yarn.server.resourcemanager.scheduler.capacity.CapacityScheduler: nodeUpdate: slave1:41069 clusterResources: <memory:8192, vCores:2>
2019-06-07 08:11:13,960 DEBUG org.apache.hadoop.yarn.server.resourcemanager.scheduler.capacity.CapacityScheduler: Node being looked for scheduling slave1:41069 availableResource: <memory:1024, vCores:0>
2019-06-07 08:11:13,960 DEBUG org.apache.hadoop.yarn.server.resourcemanager.scheduler.capacity.CapacityScheduler: Node being looked for scheduling slave1:41069 availableResource: <memory:1024, vCores:0>
2019-06-07 08:11:13,960 DEBUG org.apache.hadoop.yarn.server.resourcemanager.scheduler.capacity.CapacityScheduler: Trying to schedule on node: slave1, available: <memory:1024, vCores:0>
2019-06-07 08:11:13,960 DEBUG org.apache.hadoop.yarn.server.resourcemanager.scheduler.capacity.CapacityScheduler: Trying to schedule on node: slave1, available: <memory:1024, vCores:0>
2019-06-07 08:11:13,960 DEBUG org.apache.hadoop.yarn.server.resourcemanager.scheduler.capacity.ParentQueue: Skip this queue=root, because it doesn't need more resource, schedulingMode=RESPECT_PARTITION_EXCLUSIVITY node-partition=
2019-06-07 08:11:13,960 DEBUG org.apache.hadoop.yarn.server.resourcemanager.scheduler.capacity.ParentQueue: Skip this queue=root, because it doesn't need more resource, schedulingMode=RESPECT_PARTITION_EXCLUSIVITY node-partition=
2019-06-07 08:11:14,950 DEBUG org.apache.hadoop.yarn.server.resourcemanager.rmnode.RMNodeImpl: Processing slave2:40331 of type STATUS_UPDATE
2019-06-07 08:11:14,950 DEBUG org.apache.hadoop.yarn.server.resourcemanager.rmnode.RMNodeImpl: Processing slave2:40331 of type STATUS_UPDATE
2019-06-07 08:11:14,965 DEBUG org.apache.hadoop.yarn.server.resourcemanager.scheduler.capacity.CapacityScheduler: nodeUpdate: slave2:40331 clusterResources: <memory:8192, vCores:2>
2019-06-07 08:11:14,965 DEBUG org.apache.hadoop.yarn.server.resourcemanager.scheduler.capacity.CapacityScheduler: nodeUpdate: slave2:40331 clusterResources: <memory:8192, vCores:2>
2019-06-07 08:11:14,965 DEBUG org.apache.hadoop.yarn.server.resourcemanager.scheduler.capacity.CapacityScheduler: Node being looked for scheduling slave2:40331 availableResource: <memory:0, vCores:-1>
2019-06-07 08:11:14,965 DEBUG org.apache.hadoop.yarn.server.resourcemanager.scheduler.capacity.CapacityScheduler: Node being looked for scheduling slave2:40331 availableResource: <memory:0, vCores:-1>
2019-06-07 08:11:14,968 DEBUG org.apache.hadoop.yarn.server.resourcemanager.rmnode.RMNodeImpl: Processing slave1:41069 of type STATUS_UPDATE
2019-06-07 08:11:14,968 DEBUG org.apache.hadoop.yarn.server.resourcemanager.rmnode.RMNodeImpl: Processing slave1:41069 of type STATUS_UPDATE
2019-06-07 08:11:14,968 DEBUG org.apache.hadoop.yarn.server.resourcemanager.scheduler.capacity.CapacityScheduler: nodeUpdate: slave1:41069 clusterResources: <memory:8192, vCores:2>
2019-06-07 08:11:14,968 DEBUG org.apache.hadoop.yarn.server.resourcemanager.scheduler.capacity.CapacityScheduler: nodeUpdate: slave1:41069 clusterResources: <memory:8192, vCores:2>
2019-06-07 08:11:14,968 DEBUG org.apache.hadoop.yarn.server.resourcemanager.scheduler.capacity.CapacityScheduler: Node being looked for scheduling slave1:41069 availableResource: <memory:1024, vCores:0>
2019-06-07 08:11:14,968 DEBUG org.apache.hadoop.yarn.server.resourcemanager.scheduler.capacity.CapacityScheduler: Node being looked for scheduling slave1:41069 availableResource: <memory:1024, vCores:0>
2019-06-07 08:11:14,968 DEBUG org.apache.hadoop.yarn.server.resourcemanager.scheduler.capacity.CapacityScheduler: Trying to schedule on node: slave1, available: <memory:1024, vCores:0>
2019-06-07 08:11:14,968 DEBUG org.apache.hadoop.yarn.server.resourcemanager.scheduler.capacity.CapacityScheduler: Trying to schedule on node: slave1, available: <memory:1024, vCores:0>
2019-06-07 08:11:14,968 DEBUG org.apache.hadoop.yarn.server.resourcemanager.scheduler.capacity.ParentQueue: Skip this queue=root, because it doesn't need more resource, schedulingMode=RESPECT_PARTITION_EXCLUSIVITY node-partition=
2019-06-07 08:11:14,968 DEBUG org.apache.hadoop.yarn.server.resourcemanager.scheduler.capacity.ParentQueue: Skip this queue=root, because it doesn't need more resource, schedulingMode=RESPECT_PARTITION_EXCLUSIVITY node-partition=
2019-06-07 08:11:15,023 DEBUG org.apache.hadoop.yarn.server.resourcemanager.scheduler.capacity.LeafQueue: User limit computation for root in queue default userLimitPercent=100 userLimitFactor=1.0 required: <memory:1024, vCores:1> consumed: <memory:7168, vCores:1> user-limit-resource: <memory:8192, vCores:1> queueCapacity: <memory:8192, vCores:1> qconsumed: <memory:7168, vCores:3> consumedRatio: 0.0 currentCapacity: <memory:8192, vCores:1> activeUsers: 0.0 clusterCapacity: <memory:8192, vCores:2> resourceByLabel: <memory:8192, vCores:2> usageratio: 0.875 Partition:  maxUserLimit=<memory:8192, vCores:1> userWeight=1.0
2019-06-07 08:11:15,023 DEBUG org.apache.hadoop.yarn.server.resourcemanager.scheduler.capacity.LeafQueue: User limit computation for root in queue default userLimitPercent=100 userLimitFactor=1.0 required: <memory:1024, vCores:1> consumed: <memory:7168, vCores:1> user-limit-resource: <memory:8192, vCores:1> queueCapacity: <memory:8192, vCores:1> qconsumed: <memory:7168, vCores:3> consumedRatio: 0.0 currentCapacity: <memory:8192, vCores:1> activeUsers: 0.0 clusterCapacity: <memory:8192, vCores:2> resourceByLabel: <memory:8192, vCores:2> usageratio: 0.875 Partition:  maxUserLimit=<memory:8192, vCores:1> userWeight=1.0
2019-06-07 08:11:15,024 DEBUG org.apache.hadoop.yarn.server.resourcemanager.rmapp.attempt.RMAppAttemptImpl: Processing event for appattempt_1559895028500_0001_000001 of type STATUS_UPDATE
2019-06-07 08:11:15,024 DEBUG org.apache.hadoop.yarn.server.resourcemanager.rmapp.attempt.RMAppAttemptImpl: Processing event for appattempt_1559895028500_0001_000001 of type STATUS_UPDATE
2019-06-07 08:11:15,955 DEBUG org.apache.hadoop.yarn.server.resourcemanager.rmnode.RMNodeImpl: Processing slave2:40331 of type STATUS_UPDATE
2019-06-07 08:11:15,955 DEBUG org.apache.hadoop.yarn.server.resourcemanager.rmnode.RMNodeImpl: Processing slave2:40331 of type STATUS_UPDATE
2019-06-07 08:11:15,955 DEBUG org.apache.hadoop.yarn.server.resourcemanager.scheduler.capacity.CapacityScheduler: nodeUpdate: slave2:40331 clusterResources: <memory:8192, vCores:2>
2019-06-07 08:11:15,955 DEBUG org.apache.hadoop.yarn.server.resourcemanager.scheduler.capacity.CapacityScheduler: nodeUpdate: slave2:40331 clusterResources: <memory:8192, vCores:2>
2019-06-07 08:11:15,956 DEBUG org.apache.hadoop.yarn.server.resourcemanager.scheduler.capacity.CapacityScheduler: Node being looked for scheduling slave2:40331 availableResource: <memory:0, vCores:-1>
2019-06-07 08:11:15,956 DEBUG org.apache.hadoop.yarn.server.resourcemanager.scheduler.capacity.CapacityScheduler: Node being looked for scheduling slave2:40331 availableResource: <memory:0, vCores:-1>
2019-06-07 08:11:15,982 DEBUG org.apache.hadoop.yarn.server.resourcemanager.rmnode.RMNodeImpl: Processing slave1:41069 of type STATUS_UPDATE
2019-06-07 08:11:15,982 DEBUG org.apache.hadoop.yarn.server.resourcemanager.rmnode.RMNodeImpl: Processing slave1:41069 of type STATUS_UPDATE
2019-06-07 08:11:15,983 DEBUG org.apache.hadoop.yarn.server.resourcemanager.scheduler.capacity.CapacityScheduler: nodeUpdate: slave1:41069 clusterResources: <memory:8192, vCores:2>
2019-06-07 08:11:15,983 DEBUG org.apache.hadoop.yarn.server.resourcemanager.scheduler.capacity.CapacityScheduler: nodeUpdate: slave1:41069 clusterResources: <memory:8192, vCores:2>
2019-06-07 08:11:15,983 DEBUG org.apache.hadoop.yarn.server.resourcemanager.scheduler.capacity.CapacityScheduler: Node being looked for scheduling slave1:41069 availableResource: <memory:1024, vCores:0>
2019-06-07 08:11:15,983 DEBUG org.apache.hadoop.yarn.server.resourcemanager.scheduler.capacity.CapacityScheduler: Node being looked for scheduling slave1:41069 availableResource: <memory:1024, vCores:0>
2019-06-07 08:11:15,983 DEBUG org.apache.hadoop.yarn.server.resourcemanager.scheduler.capacity.CapacityScheduler: Trying to schedule on node: slave1, available: <memory:1024, vCores:0>
2019-06-07 08:11:15,983 DEBUG org.apache.hadoop.yarn.server.resourcemanager.scheduler.capacity.CapacityScheduler: Trying to schedule on node: slave1, available: <memory:1024, vCores:0>
2019-06-07 08:11:15,983 DEBUG org.apache.hadoop.yarn.server.resourcemanager.scheduler.capacity.ParentQueue: Skip this queue=root, because it doesn't need more resource, schedulingMode=RESPECT_PARTITION_EXCLUSIVITY node-partition=
2019-06-07 08:11:15,983 DEBUG org.apache.hadoop.yarn.server.resourcemanager.scheduler.capacity.ParentQueue: Skip this queue=root, because it doesn't need more resource, schedulingMode=RESPECT_PARTITION_EXCLUSIVITY node-partition=
2019-06-07 08:11:16,962 DEBUG org.apache.hadoop.yarn.server.resourcemanager.rmnode.RMNodeImpl: Processing slave2:40331 of type STATUS_UPDATE
2019-06-07 08:11:16,962 DEBUG org.apache.hadoop.yarn.server.resourcemanager.rmnode.RMNodeImpl: Processing slave2:40331 of type STATUS_UPDATE
2019-06-07 08:11:16,962 DEBUG org.apache.hadoop.yarn.server.resourcemanager.scheduler.capacity.CapacityScheduler: nodeUpdate: slave2:40331 clusterResources: <memory:8192, vCores:2>
2019-06-07 08:11:16,962 DEBUG org.apache.hadoop.yarn.server.resourcemanager.scheduler.capacity.CapacityScheduler: nodeUpdate: slave2:40331 clusterResources: <memory:8192, vCores:2>
2019-06-07 08:11:16,963 DEBUG org.apache.hadoop.yarn.server.resourcemanager.scheduler.capacity.CapacityScheduler: Node being looked for scheduling slave2:40331 availableResource: <memory:0, vCores:-1>
2019-06-07 08:11:16,963 DEBUG org.apache.hadoop.yarn.server.resourcemanager.scheduler.capacity.CapacityScheduler: Node being looked for scheduling slave2:40331 availableResource: <memory:0, vCores:-1>
2019-06-07 08:11:16,992 DEBUG org.apache.hadoop.yarn.server.resourcemanager.rmnode.RMNodeImpl: Processing slave1:41069 of type STATUS_UPDATE
2019-06-07 08:11:16,992 DEBUG org.apache.hadoop.yarn.server.resourcemanager.rmnode.RMNodeImpl: Processing slave1:41069 of type STATUS_UPDATE
2019-06-07 08:11:16,992 DEBUG org.apache.hadoop.yarn.server.resourcemanager.scheduler.capacity.CapacityScheduler: nodeUpdate: slave1:41069 clusterResources: <memory:8192, vCores:2>
2019-06-07 08:11:16,992 DEBUG org.apache.hadoop.yarn.server.resourcemanager.scheduler.capacity.CapacityScheduler: nodeUpdate: slave1:41069 clusterResources: <memory:8192, vCores:2>
2019-06-07 08:11:16,992 DEBUG org.apache.hadoop.yarn.server.resourcemanager.scheduler.capacity.CapacityScheduler: Node being looked for scheduling slave1:41069 availableResource: <memory:1024, vCores:0>
2019-06-07 08:11:16,992 DEBUG org.apache.hadoop.yarn.server.resourcemanager.scheduler.capacity.CapacityScheduler: Node being looked for scheduling slave1:41069 availableResource: <memory:1024, vCores:0>
2019-06-07 08:11:16,992 DEBUG org.apache.hadoop.yarn.server.resourcemanager.scheduler.capacity.CapacityScheduler: Trying to schedule on node: slave1, available: <memory:1024, vCores:0>
2019-06-07 08:11:16,992 DEBUG org.apache.hadoop.yarn.server.resourcemanager.scheduler.capacity.CapacityScheduler: Trying to schedule on node: slave1, available: <memory:1024, vCores:0>
2019-06-07 08:11:16,992 DEBUG org.apache.hadoop.yarn.server.resourcemanager.scheduler.capacity.ParentQueue: Skip this queue=root, because it doesn't need more resource, schedulingMode=RESPECT_PARTITION_EXCLUSIVITY node-partition=
2019-06-07 08:11:16,992 DEBUG org.apache.hadoop.yarn.server.resourcemanager.scheduler.capacity.ParentQueue: Skip this queue=root, because it doesn't need more resource, schedulingMode=RESPECT_PARTITION_EXCLUSIVITY node-partition=
2019-06-07 08:11:17,969 DEBUG org.apache.hadoop.yarn.server.resourcemanager.rmnode.RMNodeImpl: Processing slave2:40331 of type STATUS_UPDATE
2019-06-07 08:11:17,969 DEBUG org.apache.hadoop.yarn.server.resourcemanager.rmnode.RMNodeImpl: Processing slave2:40331 of type STATUS_UPDATE
2019-06-07 08:11:17,970 DEBUG org.apache.hadoop.yarn.server.resourcemanager.scheduler.capacity.CapacityScheduler: nodeUpdate: slave2:40331 clusterResources: <memory:8192, vCores:2>
2019-06-07 08:11:17,970 DEBUG org.apache.hadoop.yarn.server.resourcemanager.scheduler.capacity.CapacityScheduler: nodeUpdate: slave2:40331 clusterResources: <memory:8192, vCores:2>
2019-06-07 08:11:17,970 DEBUG org.apache.hadoop.yarn.server.resourcemanager.scheduler.capacity.CapacityScheduler: Node being looked for scheduling slave2:40331 availableResource: <memory:0, vCores:-1>
2019-06-07 08:11:17,970 DEBUG org.apache.hadoop.yarn.server.resourcemanager.scheduler.capacity.CapacityScheduler: Node being looked for scheduling slave2:40331 availableResource: <memory:0, vCores:-1>
2019-06-07 08:11:17,998 DEBUG org.apache.hadoop.yarn.server.resourcemanager.rmnode.RMNodeImpl: Processing slave1:41069 of type STATUS_UPDATE
2019-06-07 08:11:17,998 DEBUG org.apache.hadoop.yarn.server.resourcemanager.rmnode.RMNodeImpl: Processing slave1:41069 of type STATUS_UPDATE
2019-06-07 08:11:17,999 DEBUG org.apache.hadoop.yarn.server.resourcemanager.scheduler.capacity.CapacityScheduler: nodeUpdate: slave1:41069 clusterResources: <memory:8192, vCores:2>
2019-06-07 08:11:17,999 DEBUG org.apache.hadoop.yarn.server.resourcemanager.scheduler.capacity.CapacityScheduler: nodeUpdate: slave1:41069 clusterResources: <memory:8192, vCores:2>
2019-06-07 08:11:17,999 DEBUG org.apache.hadoop.yarn.server.resourcemanager.scheduler.capacity.CapacityScheduler: Node being looked for scheduling slave1:41069 availableResource: <memory:1024, vCores:0>
2019-06-07 08:11:17,999 DEBUG org.apache.hadoop.yarn.server.resourcemanager.scheduler.capacity.CapacityScheduler: Node being looked for scheduling slave1:41069 availableResource: <memory:1024, vCores:0>
2019-06-07 08:11:17,999 DEBUG org.apache.hadoop.yarn.server.resourcemanager.scheduler.capacity.CapacityScheduler: Trying to schedule on node: slave1, available: <memory:1024, vCores:0>
2019-06-07 08:11:17,999 DEBUG org.apache.hadoop.yarn.server.resourcemanager.scheduler.capacity.CapacityScheduler: Trying to schedule on node: slave1, available: <memory:1024, vCores:0>
2019-06-07 08:11:17,999 DEBUG org.apache.hadoop.yarn.server.resourcemanager.scheduler.capacity.ParentQueue: Skip this queue=root, because it doesn't need more resource, schedulingMode=RESPECT_PARTITION_EXCLUSIVITY node-partition=
2019-06-07 08:11:17,999 DEBUG org.apache.hadoop.yarn.server.resourcemanager.scheduler.capacity.ParentQueue: Skip this queue=root, because it doesn't need more resource, schedulingMode=RESPECT_PARTITION_EXCLUSIVITY node-partition=
2019-06-07 08:11:18,031 DEBUG org.apache.hadoop.yarn.server.resourcemanager.scheduler.capacity.LeafQueue: User limit computation for root in queue default userLimitPercent=100 userLimitFactor=1.0 required: <memory:1024, vCores:1> consumed: <memory:7168, vCores:1> user-limit-resource: <memory:8192, vCores:1> queueCapacity: <memory:8192, vCores:1> qconsumed: <memory:7168, vCores:3> consumedRatio: 0.0 currentCapacity: <memory:8192, vCores:1> activeUsers: 0.0 clusterCapacity: <memory:8192, vCores:2> resourceByLabel: <memory:8192, vCores:2> usageratio: 0.875 Partition:  maxUserLimit=<memory:8192, vCores:1> userWeight=1.0
2019-06-07 08:11:18,031 DEBUG org.apache.hadoop.yarn.server.resourcemanager.scheduler.capacity.LeafQueue: User limit computation for root in queue default userLimitPercent=100 userLimitFactor=1.0 required: <memory:1024, vCores:1> consumed: <memory:7168, vCores:1> user-limit-resource: <memory:8192, vCores:1> queueCapacity: <memory:8192, vCores:1> qconsumed: <memory:7168, vCores:3> consumedRatio: 0.0 currentCapacity: <memory:8192, vCores:1> activeUsers: 0.0 clusterCapacity: <memory:8192, vCores:2> resourceByLabel: <memory:8192, vCores:2> usageratio: 0.875 Partition:  maxUserLimit=<memory:8192, vCores:1> userWeight=1.0
2019-06-07 08:11:18,035 DEBUG org.apache.hadoop.yarn.server.resourcemanager.rmapp.attempt.RMAppAttemptImpl: Processing event for appattempt_1559895028500_0001_000001 of type STATUS_UPDATE
2019-06-07 08:11:18,035 DEBUG org.apache.hadoop.yarn.server.resourcemanager.rmapp.attempt.RMAppAttemptImpl: Processing event for appattempt_1559895028500_0001_000001 of type STATUS_UPDATE
2019-06-07 08:11:18,979 DEBUG org.apache.hadoop.yarn.server.resourcemanager.rmnode.RMNodeImpl: Processing slave2:40331 of type STATUS_UPDATE
2019-06-07 08:11:18,979 DEBUG org.apache.hadoop.yarn.server.resourcemanager.rmnode.RMNodeImpl: Processing slave2:40331 of type STATUS_UPDATE
2019-06-07 08:11:18,980 DEBUG org.apache.hadoop.yarn.server.resourcemanager.scheduler.capacity.CapacityScheduler: nodeUpdate: slave2:40331 clusterResources: <memory:8192, vCores:2>
2019-06-07 08:11:18,980 DEBUG org.apache.hadoop.yarn.server.resourcemanager.scheduler.capacity.CapacityScheduler: nodeUpdate: slave2:40331 clusterResources: <memory:8192, vCores:2>
2019-06-07 08:11:18,980 DEBUG org.apache.hadoop.yarn.server.resourcemanager.scheduler.capacity.CapacityScheduler: Node being looked for scheduling slave2:40331 availableResource: <memory:0, vCores:-1>
2019-06-07 08:11:18,980 DEBUG org.apache.hadoop.yarn.server.resourcemanager.scheduler.capacity.CapacityScheduler: Node being looked for scheduling slave2:40331 availableResource: <memory:0, vCores:-1>
2019-06-07 08:11:19,008 DEBUG org.apache.hadoop.yarn.server.resourcemanager.rmnode.RMNodeImpl: Processing slave1:41069 of type STATUS_UPDATE
2019-06-07 08:11:19,008 DEBUG org.apache.hadoop.yarn.server.resourcemanager.rmnode.RMNodeImpl: Processing slave1:41069 of type STATUS_UPDATE
2019-06-07 08:11:19,009 DEBUG org.apache.hadoop.yarn.server.resourcemanager.scheduler.capacity.CapacityScheduler: nodeUpdate: slave1:41069 clusterResources: <memory:8192, vCores:2>
2019-06-07 08:11:19,009 DEBUG org.apache.hadoop.yarn.server.resourcemanager.scheduler.capacity.CapacityScheduler: nodeUpdate: slave1:41069 clusterResources: <memory:8192, vCores:2>
2019-06-07 08:11:19,009 DEBUG org.apache.hadoop.yarn.server.resourcemanager.scheduler.capacity.CapacityScheduler: Node being looked for scheduling slave1:41069 availableResource: <memory:1024, vCores:0>
2019-06-07 08:11:19,009 DEBUG org.apache.hadoop.yarn.server.resourcemanager.scheduler.capacity.CapacityScheduler: Node being looked for scheduling slave1:41069 availableResource: <memory:1024, vCores:0>
2019-06-07 08:11:19,009 DEBUG org.apache.hadoop.yarn.server.resourcemanager.scheduler.capacity.CapacityScheduler: Trying to schedule on node: slave1, available: <memory:1024, vCores:0>
2019-06-07 08:11:19,009 DEBUG org.apache.hadoop.yarn.server.resourcemanager.scheduler.capacity.CapacityScheduler: Trying to schedule on node: slave1, available: <memory:1024, vCores:0>
2019-06-07 08:11:19,009 DEBUG org.apache.hadoop.yarn.server.resourcemanager.scheduler.capacity.ParentQueue: Skip this queue=root, because it doesn't need more resource, schedulingMode=RESPECT_PARTITION_EXCLUSIVITY node-partition=
2019-06-07 08:11:19,009 DEBUG org.apache.hadoop.yarn.server.resourcemanager.scheduler.capacity.ParentQueue: Skip this queue=root, because it doesn't need more resource, schedulingMode=RESPECT_PARTITION_EXCLUSIVITY node-partition=
2019-06-07 08:11:19,983 DEBUG org.apache.hadoop.yarn.server.resourcemanager.rmnode.RMNodeImpl: Processing slave2:40331 of type STATUS_UPDATE
2019-06-07 08:11:19,983 DEBUG org.apache.hadoop.yarn.server.resourcemanager.rmnode.RMNodeImpl: Processing slave2:40331 of type STATUS_UPDATE
2019-06-07 08:11:19,983 DEBUG org.apache.hadoop.yarn.server.resourcemanager.scheduler.capacity.CapacityScheduler: nodeUpdate: slave2:40331 clusterResources: <memory:8192, vCores:2>
2019-06-07 08:11:19,983 DEBUG org.apache.hadoop.yarn.server.resourcemanager.scheduler.capacity.CapacityScheduler: nodeUpdate: slave2:40331 clusterResources: <memory:8192, vCores:2>
2019-06-07 08:11:19,983 DEBUG org.apache.hadoop.yarn.server.resourcemanager.scheduler.capacity.CapacityScheduler: Node being looked for scheduling slave2:40331 availableResource: <memory:0, vCores:-1>
2019-06-07 08:11:19,983 DEBUG org.apache.hadoop.yarn.server.resourcemanager.scheduler.capacity.CapacityScheduler: Node being looked for scheduling slave2:40331 availableResource: <memory:0, vCores:-1>
2019-06-07 08:11:20,027 DEBUG org.apache.hadoop.yarn.server.resourcemanager.rmnode.RMNodeImpl: Processing slave1:41069 of type STATUS_UPDATE
2019-06-07 08:11:20,027 DEBUG org.apache.hadoop.yarn.server.resourcemanager.rmnode.RMNodeImpl: Processing slave1:41069 of type STATUS_UPDATE
2019-06-07 08:11:20,042 DEBUG org.apache.hadoop.yarn.server.resourcemanager.scheduler.capacity.CapacityScheduler: nodeUpdate: slave1:41069 clusterResources: <memory:8192, vCores:2>
2019-06-07 08:11:20,042 DEBUG org.apache.hadoop.yarn.server.resourcemanager.scheduler.capacity.CapacityScheduler: nodeUpdate: slave1:41069 clusterResources: <memory:8192, vCores:2>
2019-06-07 08:11:20,042 DEBUG org.apache.hadoop.yarn.server.resourcemanager.scheduler.capacity.CapacityScheduler: Node being looked for scheduling slave1:41069 availableResource: <memory:1024, vCores:0>
2019-06-07 08:11:20,042 DEBUG org.apache.hadoop.yarn.server.resourcemanager.scheduler.capacity.CapacityScheduler: Node being looked for scheduling slave1:41069 availableResource: <memory:1024, vCores:0>
2019-06-07 08:11:20,042 DEBUG org.apache.hadoop.yarn.server.resourcemanager.scheduler.capacity.CapacityScheduler: Trying to schedule on node: slave1, available: <memory:1024, vCores:0>
2019-06-07 08:11:20,042 DEBUG org.apache.hadoop.yarn.server.resourcemanager.scheduler.capacity.CapacityScheduler: Trying to schedule on node: slave1, available: <memory:1024, vCores:0>
2019-06-07 08:11:20,042 DEBUG org.apache.hadoop.yarn.server.resourcemanager.scheduler.capacity.ParentQueue: Skip this queue=root, because it doesn't need more resource, schedulingMode=RESPECT_PARTITION_EXCLUSIVITY node-partition=
2019-06-07 08:11:20,042 DEBUG org.apache.hadoop.yarn.server.resourcemanager.scheduler.capacity.ParentQueue: Skip this queue=root, because it doesn't need more resource, schedulingMode=RESPECT_PARTITION_EXCLUSIVITY node-partition=
2019-06-07 08:11:20,987 DEBUG org.apache.hadoop.yarn.server.resourcemanager.rmnode.RMNodeImpl: Processing slave2:40331 of type STATUS_UPDATE
2019-06-07 08:11:20,987 DEBUG org.apache.hadoop.yarn.server.resourcemanager.rmnode.RMNodeImpl: Processing slave2:40331 of type STATUS_UPDATE
2019-06-07 08:11:20,988 DEBUG org.apache.hadoop.yarn.server.resourcemanager.scheduler.capacity.CapacityScheduler: nodeUpdate: slave2:40331 clusterResources: <memory:8192, vCores:2>
2019-06-07 08:11:20,988 DEBUG org.apache.hadoop.yarn.server.resourcemanager.scheduler.capacity.CapacityScheduler: nodeUpdate: slave2:40331 clusterResources: <memory:8192, vCores:2>
2019-06-07 08:11:20,988 DEBUG org.apache.hadoop.yarn.server.resourcemanager.scheduler.capacity.CapacityScheduler: Node being looked for scheduling slave2:40331 availableResource: <memory:0, vCores:-1>
2019-06-07 08:11:20,988 DEBUG org.apache.hadoop.yarn.server.resourcemanager.scheduler.capacity.CapacityScheduler: Node being looked for scheduling slave2:40331 availableResource: <memory:0, vCores:-1>
2019-06-07 08:11:21,022 DEBUG org.apache.hadoop.yarn.server.resourcemanager.rmnode.RMNodeImpl: Processing slave1:41069 of type STATUS_UPDATE
2019-06-07 08:11:21,022 DEBUG org.apache.hadoop.yarn.server.resourcemanager.rmnode.RMNodeImpl: Processing slave1:41069 of type STATUS_UPDATE
2019-06-07 08:11:21,022 DEBUG org.apache.hadoop.yarn.server.resourcemanager.scheduler.capacity.CapacityScheduler: nodeUpdate: slave1:41069 clusterResources: <memory:8192, vCores:2>
2019-06-07 08:11:21,022 DEBUG org.apache.hadoop.yarn.server.resourcemanager.scheduler.capacity.CapacityScheduler: nodeUpdate: slave1:41069 clusterResources: <memory:8192, vCores:2>
2019-06-07 08:11:21,022 DEBUG org.apache.hadoop.yarn.server.resourcemanager.scheduler.capacity.CapacityScheduler: Node being looked for scheduling slave1:41069 availableResource: <memory:1024, vCores:0>
2019-06-07 08:11:21,022 DEBUG org.apache.hadoop.yarn.server.resourcemanager.scheduler.capacity.CapacityScheduler: Node being looked for scheduling slave1:41069 availableResource: <memory:1024, vCores:0>
2019-06-07 08:11:21,022 DEBUG org.apache.hadoop.yarn.server.resourcemanager.scheduler.capacity.CapacityScheduler: Trying to schedule on node: slave1, available: <memory:1024, vCores:0>
2019-06-07 08:11:21,022 DEBUG org.apache.hadoop.yarn.server.resourcemanager.scheduler.capacity.CapacityScheduler: Trying to schedule on node: slave1, available: <memory:1024, vCores:0>
2019-06-07 08:11:21,022 DEBUG org.apache.hadoop.yarn.server.resourcemanager.scheduler.capacity.ParentQueue: Skip this queue=root, because it doesn't need more resource, schedulingMode=RESPECT_PARTITION_EXCLUSIVITY node-partition=
2019-06-07 08:11:21,022 DEBUG org.apache.hadoop.yarn.server.resourcemanager.scheduler.capacity.ParentQueue: Skip this queue=root, because it doesn't need more resource, schedulingMode=RESPECT_PARTITION_EXCLUSIVITY node-partition=
2019-06-07 08:11:21,041 DEBUG org.apache.hadoop.yarn.server.resourcemanager.scheduler.capacity.LeafQueue: User limit computation for root in queue default userLimitPercent=100 userLimitFactor=1.0 required: <memory:1024, vCores:1> consumed: <memory:7168, vCores:1> user-limit-resource: <memory:8192, vCores:1> queueCapacity: <memory:8192, vCores:1> qconsumed: <memory:7168, vCores:3> consumedRatio: 0.0 currentCapacity: <memory:8192, vCores:1> activeUsers: 0.0 clusterCapacity: <memory:8192, vCores:2> resourceByLabel: <memory:8192, vCores:2> usageratio: 0.875 Partition:  maxUserLimit=<memory:8192, vCores:1> userWeight=1.0
2019-06-07 08:11:21,041 DEBUG org.apache.hadoop.yarn.server.resourcemanager.scheduler.capacity.LeafQueue: User limit computation for root in queue default userLimitPercent=100 userLimitFactor=1.0 required: <memory:1024, vCores:1> consumed: <memory:7168, vCores:1> user-limit-resource: <memory:8192, vCores:1> queueCapacity: <memory:8192, vCores:1> qconsumed: <memory:7168, vCores:3> consumedRatio: 0.0 currentCapacity: <memory:8192, vCores:1> activeUsers: 0.0 clusterCapacity: <memory:8192, vCores:2> resourceByLabel: <memory:8192, vCores:2> usageratio: 0.875 Partition:  maxUserLimit=<memory:8192, vCores:1> userWeight=1.0
2019-06-07 08:11:21,042 DEBUG org.apache.hadoop.yarn.server.resourcemanager.rmapp.attempt.RMAppAttemptImpl: Processing event for appattempt_1559895028500_0001_000001 of type STATUS_UPDATE
2019-06-07 08:11:21,042 DEBUG org.apache.hadoop.yarn.server.resourcemanager.rmapp.attempt.RMAppAttemptImpl: Processing event for appattempt_1559895028500_0001_000001 of type STATUS_UPDATE
2019-06-07 08:11:21,989 DEBUG org.apache.hadoop.yarn.server.resourcemanager.rmnode.RMNodeImpl: Processing slave2:40331 of type STATUS_UPDATE
2019-06-07 08:11:21,989 DEBUG org.apache.hadoop.yarn.server.resourcemanager.rmnode.RMNodeImpl: Processing slave2:40331 of type STATUS_UPDATE
2019-06-07 08:11:21,989 DEBUG org.apache.hadoop.yarn.server.resourcemanager.scheduler.capacity.CapacityScheduler: nodeUpdate: slave2:40331 clusterResources: <memory:8192, vCores:2>
2019-06-07 08:11:21,989 DEBUG org.apache.hadoop.yarn.server.resourcemanager.scheduler.capacity.CapacityScheduler: nodeUpdate: slave2:40331 clusterResources: <memory:8192, vCores:2>
2019-06-07 08:11:21,991 DEBUG org.apache.hadoop.yarn.server.resourcemanager.scheduler.capacity.CapacityScheduler: Node being looked for scheduling slave2:40331 availableResource: <memory:0, vCores:-1>
2019-06-07 08:11:21,991 DEBUG org.apache.hadoop.yarn.server.resourcemanager.scheduler.capacity.CapacityScheduler: Node being looked for scheduling slave2:40331 availableResource: <memory:0, vCores:-1>
2019-06-07 08:11:22,030 DEBUG org.apache.hadoop.yarn.server.resourcemanager.rmnode.RMNodeImpl: Processing slave1:41069 of type STATUS_UPDATE
2019-06-07 08:11:22,030 DEBUG org.apache.hadoop.yarn.server.resourcemanager.rmnode.RMNodeImpl: Processing slave1:41069 of type STATUS_UPDATE
2019-06-07 08:11:22,031 DEBUG org.apache.hadoop.yarn.server.resourcemanager.scheduler.capacity.CapacityScheduler: nodeUpdate: slave1:41069 clusterResources: <memory:8192, vCores:2>
2019-06-07 08:11:22,031 DEBUG org.apache.hadoop.yarn.server.resourcemanager.scheduler.capacity.CapacityScheduler: nodeUpdate: slave1:41069 clusterResources: <memory:8192, vCores:2>
2019-06-07 08:11:22,031 DEBUG org.apache.hadoop.yarn.server.resourcemanager.scheduler.capacity.CapacityScheduler: Node being looked for scheduling slave1:41069 availableResource: <memory:1024, vCores:0>
2019-06-07 08:11:22,031 DEBUG org.apache.hadoop.yarn.server.resourcemanager.scheduler.capacity.CapacityScheduler: Node being looked for scheduling slave1:41069 availableResource: <memory:1024, vCores:0>
2019-06-07 08:11:22,031 DEBUG org.apache.hadoop.yarn.server.resourcemanager.scheduler.capacity.CapacityScheduler: Trying to schedule on node: slave1, available: <memory:1024, vCores:0>
2019-06-07 08:11:22,031 DEBUG org.apache.hadoop.yarn.server.resourcemanager.scheduler.capacity.CapacityScheduler: Trying to schedule on node: slave1, available: <memory:1024, vCores:0>
2019-06-07 08:11:22,031 DEBUG org.apache.hadoop.yarn.server.resourcemanager.scheduler.capacity.ParentQueue: Skip this queue=root, because it doesn't need more resource, schedulingMode=RESPECT_PARTITION_EXCLUSIVITY node-partition=
2019-06-07 08:11:22,031 DEBUG org.apache.hadoop.yarn.server.resourcemanager.scheduler.capacity.ParentQueue: Skip this queue=root, because it doesn't need more resource, schedulingMode=RESPECT_PARTITION_EXCLUSIVITY node-partition=
2019-06-07 08:11:25,306 DEBUG org.apache.hadoop.yarn.server.resourcemanager.rmnode.RMNodeImpl: Processing slave2:40331 of type STATUS_UPDATE
2019-06-07 08:11:25,306 DEBUG org.apache.hadoop.yarn.server.resourcemanager.rmnode.RMNodeImpl: Processing slave2:40331 of type STATUS_UPDATE
2019-06-07 08:11:25,306 DEBUG org.apache.hadoop.yarn.server.resourcemanager.rmnode.RMNodeImpl: Processing slave1:41069 of type STATUS_UPDATE
2019-06-07 08:11:25,306 DEBUG org.apache.hadoop.yarn.server.resourcemanager.rmnode.RMNodeImpl: Processing slave1:41069 of type STATUS_UPDATE
2019-06-07 08:11:25,307 DEBUG org.apache.hadoop.yarn.server.resourcemanager.scheduler.capacity.CapacityScheduler: nodeUpdate: slave2:40331 clusterResources: <memory:8192, vCores:2>
2019-06-07 08:11:25,307 DEBUG org.apache.hadoop.yarn.server.resourcemanager.scheduler.capacity.CapacityScheduler: nodeUpdate: slave2:40331 clusterResources: <memory:8192, vCores:2>
2019-06-07 08:11:25,307 DEBUG org.apache.hadoop.yarn.server.resourcemanager.scheduler.capacity.CapacityScheduler: Node being looked for scheduling slave2:40331 availableResource: <memory:0, vCores:-1>
2019-06-07 08:11:25,307 DEBUG org.apache.hadoop.yarn.server.resourcemanager.scheduler.capacity.CapacityScheduler: Node being looked for scheduling slave2:40331 availableResource: <memory:0, vCores:-1>
2019-06-07 08:11:25,307 DEBUG org.apache.hadoop.yarn.server.resourcemanager.scheduler.capacity.CapacityScheduler: nodeUpdate: slave1:41069 clusterResources: <memory:8192, vCores:2>
2019-06-07 08:11:25,307 DEBUG org.apache.hadoop.yarn.server.resourcemanager.scheduler.capacity.CapacityScheduler: nodeUpdate: slave1:41069 clusterResources: <memory:8192, vCores:2>
2019-06-07 08:11:25,307 DEBUG org.apache.hadoop.yarn.server.resourcemanager.scheduler.capacity.CapacityScheduler: Node being looked for scheduling slave1:41069 availableResource: <memory:1024, vCores:0>
2019-06-07 08:11:25,307 DEBUG org.apache.hadoop.yarn.server.resourcemanager.scheduler.capacity.CapacityScheduler: Node being looked for scheduling slave1:41069 availableResource: <memory:1024, vCores:0>
2019-06-07 08:11:25,307 DEBUG org.apache.hadoop.yarn.server.resourcemanager.scheduler.capacity.CapacityScheduler: Trying to schedule on node: slave1, available: <memory:1024, vCores:0>
2019-06-07 08:11:25,307 DEBUG org.apache.hadoop.yarn.server.resourcemanager.scheduler.capacity.CapacityScheduler: Trying to schedule on node: slave1, available: <memory:1024, vCores:0>
2019-06-07 08:11:25,307 DEBUG org.apache.hadoop.yarn.server.resourcemanager.scheduler.capacity.ParentQueue: Skip this queue=root, because it doesn't need more resource, schedulingMode=RESPECT_PARTITION_EXCLUSIVITY node-partition=
2019-06-07 08:11:25,307 DEBUG org.apache.hadoop.yarn.server.resourcemanager.scheduler.capacity.ParentQueue: Skip this queue=root, because it doesn't need more resource, schedulingMode=RESPECT_PARTITION_EXCLUSIVITY node-partition=
2019-06-07 08:11:25,320 DEBUG org.apache.hadoop.yarn.server.resourcemanager.scheduler.capacity.LeafQueue: User limit computation for root in queue default userLimitPercent=100 userLimitFactor=1.0 required: <memory:1024, vCores:1> consumed: <memory:7168, vCores:1> user-limit-resource: <memory:8192, vCores:1> queueCapacity: <memory:8192, vCores:1> qconsumed: <memory:7168, vCores:3> consumedRatio: 0.0 currentCapacity: <memory:8192, vCores:1> activeUsers: 0.0 clusterCapacity: <memory:8192, vCores:2> resourceByLabel: <memory:8192, vCores:2> usageratio: 0.875 Partition:  maxUserLimit=<memory:8192, vCores:1> userWeight=1.0
2019-06-07 08:11:25,320 DEBUG org.apache.hadoop.yarn.server.resourcemanager.scheduler.capacity.LeafQueue: User limit computation for root in queue default userLimitPercent=100 userLimitFactor=1.0 required: <memory:1024, vCores:1> consumed: <memory:7168, vCores:1> user-limit-resource: <memory:8192, vCores:1> queueCapacity: <memory:8192, vCores:1> qconsumed: <memory:7168, vCores:3> consumedRatio: 0.0 currentCapacity: <memory:8192, vCores:1> activeUsers: 0.0 clusterCapacity: <memory:8192, vCores:2> resourceByLabel: <memory:8192, vCores:2> usageratio: 0.875 Partition:  maxUserLimit=<memory:8192, vCores:1> userWeight=1.0
2019-06-07 08:11:25,321 DEBUG org.apache.hadoop.yarn.server.resourcemanager.rmapp.attempt.RMAppAttemptImpl: Processing event for appattempt_1559895028500_0001_000001 of type STATUS_UPDATE
2019-06-07 08:11:25,321 DEBUG org.apache.hadoop.yarn.server.resourcemanager.rmapp.attempt.RMAppAttemptImpl: Processing event for appattempt_1559895028500_0001_000001 of type STATUS_UPDATE
2019-06-07 08:11:26,310 DEBUG org.apache.hadoop.yarn.server.resourcemanager.rmnode.RMNodeImpl: Processing slave1:41069 of type STATUS_UPDATE
2019-06-07 08:11:26,310 DEBUG org.apache.hadoop.yarn.server.resourcemanager.rmnode.RMNodeImpl: Processing slave1:41069 of type STATUS_UPDATE
2019-06-07 08:11:26,311 DEBUG org.apache.hadoop.yarn.server.resourcemanager.scheduler.capacity.CapacityScheduler: nodeUpdate: slave1:41069 clusterResources: <memory:8192, vCores:2>
2019-06-07 08:11:26,311 DEBUG org.apache.hadoop.yarn.server.resourcemanager.scheduler.capacity.CapacityScheduler: nodeUpdate: slave1:41069 clusterResources: <memory:8192, vCores:2>
2019-06-07 08:11:26,312 DEBUG org.apache.hadoop.yarn.server.resourcemanager.scheduler.capacity.CapacityScheduler: Node being looked for scheduling slave1:41069 availableResource: <memory:1024, vCores:0>
2019-06-07 08:11:26,312 DEBUG org.apache.hadoop.yarn.server.resourcemanager.scheduler.capacity.CapacityScheduler: Node being looked for scheduling slave1:41069 availableResource: <memory:1024, vCores:0>
2019-06-07 08:11:26,312 DEBUG org.apache.hadoop.yarn.server.resourcemanager.scheduler.capacity.CapacityScheduler: Trying to schedule on node: slave1, available: <memory:1024, vCores:0>
2019-06-07 08:11:26,312 DEBUG org.apache.hadoop.yarn.server.resourcemanager.scheduler.capacity.CapacityScheduler: Trying to schedule on node: slave1, available: <memory:1024, vCores:0>
2019-06-07 08:11:26,312 DEBUG org.apache.hadoop.yarn.server.resourcemanager.scheduler.capacity.ParentQueue: Skip this queue=root, because it doesn't need more resource, schedulingMode=RESPECT_PARTITION_EXCLUSIVITY node-partition=
2019-06-07 08:11:26,312 DEBUG org.apache.hadoop.yarn.server.resourcemanager.scheduler.capacity.ParentQueue: Skip this queue=root, because it doesn't need more resource, schedulingMode=RESPECT_PARTITION_EXCLUSIVITY node-partition=
2019-06-07 08:11:26,317 DEBUG org.apache.hadoop.yarn.server.resourcemanager.rmnode.RMNodeImpl: Processing slave2:40331 of type STATUS_UPDATE
2019-06-07 08:11:26,317 DEBUG org.apache.hadoop.yarn.server.resourcemanager.rmnode.RMNodeImpl: Processing slave2:40331 of type STATUS_UPDATE
2019-06-07 08:11:26,317 DEBUG org.apache.hadoop.yarn.server.resourcemanager.scheduler.capacity.CapacityScheduler: nodeUpdate: slave2:40331 clusterResources: <memory:8192, vCores:2>
2019-06-07 08:11:26,317 DEBUG org.apache.hadoop.yarn.server.resourcemanager.scheduler.capacity.CapacityScheduler: nodeUpdate: slave2:40331 clusterResources: <memory:8192, vCores:2>
2019-06-07 08:11:26,318 DEBUG org.apache.hadoop.yarn.server.resourcemanager.scheduler.capacity.CapacityScheduler: Node being looked for scheduling slave2:40331 availableResource: <memory:0, vCores:-1>
2019-06-07 08:11:26,318 DEBUG org.apache.hadoop.yarn.server.resourcemanager.scheduler.capacity.CapacityScheduler: Node being looked for scheduling slave2:40331 availableResource: <memory:0, vCores:-1>
2019-06-07 08:11:27,318 DEBUG org.apache.hadoop.yarn.server.resourcemanager.rmnode.RMNodeImpl: Processing slave1:41069 of type STATUS_UPDATE
2019-06-07 08:11:27,318 DEBUG org.apache.hadoop.yarn.server.resourcemanager.rmnode.RMNodeImpl: Processing slave1:41069 of type STATUS_UPDATE
2019-06-07 08:11:27,318 DEBUG org.apache.hadoop.yarn.server.resourcemanager.scheduler.capacity.CapacityScheduler: nodeUpdate: slave1:41069 clusterResources: <memory:8192, vCores:2>
2019-06-07 08:11:27,318 DEBUG org.apache.hadoop.yarn.server.resourcemanager.scheduler.capacity.CapacityScheduler: nodeUpdate: slave1:41069 clusterResources: <memory:8192, vCores:2>
2019-06-07 08:11:27,319 DEBUG org.apache.hadoop.yarn.server.resourcemanager.scheduler.capacity.CapacityScheduler: Node being looked for scheduling slave1:41069 availableResource: <memory:1024, vCores:0>
2019-06-07 08:11:27,319 DEBUG org.apache.hadoop.yarn.server.resourcemanager.scheduler.capacity.CapacityScheduler: Node being looked for scheduling slave1:41069 availableResource: <memory:1024, vCores:0>
2019-06-07 08:11:27,319 DEBUG org.apache.hadoop.yarn.server.resourcemanager.scheduler.capacity.CapacityScheduler: Trying to schedule on node: slave1, available: <memory:1024, vCores:0>
2019-06-07 08:11:27,319 DEBUG org.apache.hadoop.yarn.server.resourcemanager.scheduler.capacity.CapacityScheduler: Trying to schedule on node: slave1, available: <memory:1024, vCores:0>
2019-06-07 08:11:27,319 DEBUG org.apache.hadoop.yarn.server.resourcemanager.scheduler.capacity.ParentQueue: Skip this queue=root, because it doesn't need more resource, schedulingMode=RESPECT_PARTITION_EXCLUSIVITY node-partition=
2019-06-07 08:11:27,319 DEBUG org.apache.hadoop.yarn.server.resourcemanager.scheduler.capacity.ParentQueue: Skip this queue=root, because it doesn't need more resource, schedulingMode=RESPECT_PARTITION_EXCLUSIVITY node-partition=
2019-06-07 08:11:27,319 DEBUG org.apache.hadoop.yarn.server.resourcemanager.rmnode.RMNodeImpl: Processing slave2:40331 of type STATUS_UPDATE
2019-06-07 08:11:27,319 DEBUG org.apache.hadoop.yarn.server.resourcemanager.rmnode.RMNodeImpl: Processing slave2:40331 of type STATUS_UPDATE
2019-06-07 08:11:27,320 DEBUG org.apache.hadoop.yarn.server.resourcemanager.scheduler.capacity.CapacityScheduler: nodeUpdate: slave2:40331 clusterResources: <memory:8192, vCores:2>
2019-06-07 08:11:27,320 DEBUG org.apache.hadoop.yarn.server.resourcemanager.scheduler.capacity.CapacityScheduler: nodeUpdate: slave2:40331 clusterResources: <memory:8192, vCores:2>
2019-06-07 08:11:27,320 DEBUG org.apache.hadoop.yarn.server.resourcemanager.scheduler.capacity.CapacityScheduler: Node being looked for scheduling slave2:40331 availableResource: <memory:0, vCores:-1>
2019-06-07 08:11:27,320 DEBUG org.apache.hadoop.yarn.server.resourcemanager.scheduler.capacity.CapacityScheduler: Node being looked for scheduling slave2:40331 availableResource: <memory:0, vCores:-1>
2019-06-07 08:11:28,320 DEBUG org.apache.hadoop.yarn.server.resourcemanager.rmnode.RMNodeImpl: Processing slave1:41069 of type STATUS_UPDATE
2019-06-07 08:11:28,320 DEBUG org.apache.hadoop.yarn.server.resourcemanager.rmnode.RMNodeImpl: Processing slave1:41069 of type STATUS_UPDATE
2019-06-07 08:11:28,321 DEBUG org.apache.hadoop.yarn.server.resourcemanager.scheduler.capacity.CapacityScheduler: nodeUpdate: slave1:41069 clusterResources: <memory:8192, vCores:2>
2019-06-07 08:11:28,321 DEBUG org.apache.hadoop.yarn.server.resourcemanager.scheduler.capacity.CapacityScheduler: nodeUpdate: slave1:41069 clusterResources: <memory:8192, vCores:2>
2019-06-07 08:11:28,321 DEBUG org.apache.hadoop.yarn.server.resourcemanager.scheduler.capacity.CapacityScheduler: Node being looked for scheduling slave1:41069 availableResource: <memory:1024, vCores:0>
2019-06-07 08:11:28,321 DEBUG org.apache.hadoop.yarn.server.resourcemanager.scheduler.capacity.CapacityScheduler: Node being looked for scheduling slave1:41069 availableResource: <memory:1024, vCores:0>
2019-06-07 08:11:28,321 DEBUG org.apache.hadoop.yarn.server.resourcemanager.scheduler.capacity.CapacityScheduler: Trying to schedule on node: slave1, available: <memory:1024, vCores:0>
2019-06-07 08:11:28,321 DEBUG org.apache.hadoop.yarn.server.resourcemanager.scheduler.capacity.CapacityScheduler: Trying to schedule on node: slave1, available: <memory:1024, vCores:0>
2019-06-07 08:11:28,321 DEBUG org.apache.hadoop.yarn.server.resourcemanager.scheduler.capacity.ParentQueue: Skip this queue=root, because it doesn't need more resource, schedulingMode=RESPECT_PARTITION_EXCLUSIVITY node-partition=
2019-06-07 08:11:28,321 DEBUG org.apache.hadoop.yarn.server.resourcemanager.scheduler.capacity.ParentQueue: Skip this queue=root, because it doesn't need more resource, schedulingMode=RESPECT_PARTITION_EXCLUSIVITY node-partition=
2019-06-07 08:11:28,327 DEBUG org.apache.hadoop.yarn.server.resourcemanager.rmnode.RMNodeImpl: Processing slave2:40331 of type STATUS_UPDATE
2019-06-07 08:11:28,327 DEBUG org.apache.hadoop.yarn.server.resourcemanager.rmnode.RMNodeImpl: Processing slave2:40331 of type STATUS_UPDATE
2019-06-07 08:11:28,328 DEBUG org.apache.hadoop.yarn.server.resourcemanager.scheduler.capacity.CapacityScheduler: nodeUpdate: slave2:40331 clusterResources: <memory:8192, vCores:2>
2019-06-07 08:11:28,328 DEBUG org.apache.hadoop.yarn.server.resourcemanager.scheduler.capacity.CapacityScheduler: nodeUpdate: slave2:40331 clusterResources: <memory:8192, vCores:2>
2019-06-07 08:11:28,328 DEBUG org.apache.hadoop.yarn.server.resourcemanager.scheduler.capacity.CapacityScheduler: Node being looked for scheduling slave2:40331 availableResource: <memory:0, vCores:-1>
2019-06-07 08:11:28,328 DEBUG org.apache.hadoop.yarn.server.resourcemanager.scheduler.capacity.CapacityScheduler: Node being looked for scheduling slave2:40331 availableResource: <memory:0, vCores:-1>
2019-06-07 08:11:28,344 DEBUG org.apache.hadoop.yarn.server.resourcemanager.scheduler.capacity.LeafQueue: User limit computation for root in queue default userLimitPercent=100 userLimitFactor=1.0 required: <memory:1024, vCores:1> consumed: <memory:7168, vCores:1> user-limit-resource: <memory:8192, vCores:1> queueCapacity: <memory:8192, vCores:1> qconsumed: <memory:7168, vCores:3> consumedRatio: 0.0 currentCapacity: <memory:8192, vCores:1> activeUsers: 0.0 clusterCapacity: <memory:8192, vCores:2> resourceByLabel: <memory:8192, vCores:2> usageratio: 0.875 Partition:  maxUserLimit=<memory:8192, vCores:1> userWeight=1.0
2019-06-07 08:11:28,344 DEBUG org.apache.hadoop.yarn.server.resourcemanager.scheduler.capacity.LeafQueue: User limit computation for root in queue default userLimitPercent=100 userLimitFactor=1.0 required: <memory:1024, vCores:1> consumed: <memory:7168, vCores:1> user-limit-resource: <memory:8192, vCores:1> queueCapacity: <memory:8192, vCores:1> qconsumed: <memory:7168, vCores:3> consumedRatio: 0.0 currentCapacity: <memory:8192, vCores:1> activeUsers: 0.0 clusterCapacity: <memory:8192, vCores:2> resourceByLabel: <memory:8192, vCores:2> usageratio: 0.875 Partition:  maxUserLimit=<memory:8192, vCores:1> userWeight=1.0
2019-06-07 08:11:28,344 DEBUG org.apache.hadoop.yarn.server.resourcemanager.rmapp.attempt.RMAppAttemptImpl: Processing event for appattempt_1559895028500_0001_000001 of type STATUS_UPDATE
2019-06-07 08:11:28,344 DEBUG org.apache.hadoop.yarn.server.resourcemanager.rmapp.attempt.RMAppAttemptImpl: Processing event for appattempt_1559895028500_0001_000001 of type STATUS_UPDATE
2019-06-07 08:11:29,329 DEBUG org.apache.hadoop.yarn.server.resourcemanager.rmnode.RMNodeImpl: Processing slave1:41069 of type STATUS_UPDATE
2019-06-07 08:11:29,329 DEBUG org.apache.hadoop.yarn.server.resourcemanager.rmnode.RMNodeImpl: Processing slave1:41069 of type STATUS_UPDATE
2019-06-07 08:11:29,330 DEBUG org.apache.hadoop.yarn.server.resourcemanager.scheduler.capacity.CapacityScheduler: nodeUpdate: slave1:41069 clusterResources: <memory:8192, vCores:2>
2019-06-07 08:11:29,330 DEBUG org.apache.hadoop.yarn.server.resourcemanager.scheduler.capacity.CapacityScheduler: nodeUpdate: slave1:41069 clusterResources: <memory:8192, vCores:2>
2019-06-07 08:11:29,330 DEBUG org.apache.hadoop.yarn.server.resourcemanager.scheduler.capacity.CapacityScheduler: Node being looked for scheduling slave1:41069 availableResource: <memory:1024, vCores:0>
2019-06-07 08:11:29,330 DEBUG org.apache.hadoop.yarn.server.resourcemanager.scheduler.capacity.CapacityScheduler: Node being looked for scheduling slave1:41069 availableResource: <memory:1024, vCores:0>
2019-06-07 08:11:29,330 DEBUG org.apache.hadoop.yarn.server.resourcemanager.scheduler.capacity.CapacityScheduler: Trying to schedule on node: slave1, available: <memory:1024, vCores:0>
2019-06-07 08:11:29,330 DEBUG org.apache.hadoop.yarn.server.resourcemanager.scheduler.capacity.CapacityScheduler: Trying to schedule on node: slave1, available: <memory:1024, vCores:0>
2019-06-07 08:11:29,330 DEBUG org.apache.hadoop.yarn.server.resourcemanager.scheduler.capacity.ParentQueue: Skip this queue=root, because it doesn't need more resource, schedulingMode=RESPECT_PARTITION_EXCLUSIVITY node-partition=
2019-06-07 08:11:29,330 DEBUG org.apache.hadoop.yarn.server.resourcemanager.scheduler.capacity.ParentQueue: Skip this queue=root, because it doesn't need more resource, schedulingMode=RESPECT_PARTITION_EXCLUSIVITY node-partition=
2019-06-07 08:11:29,333 DEBUG org.apache.hadoop.yarn.server.resourcemanager.rmnode.RMNodeImpl: Processing slave2:40331 of type STATUS_UPDATE
2019-06-07 08:11:29,333 DEBUG org.apache.hadoop.yarn.server.resourcemanager.rmnode.RMNodeImpl: Processing slave2:40331 of type STATUS_UPDATE
2019-06-07 08:11:29,334 DEBUG org.apache.hadoop.yarn.server.resourcemanager.scheduler.capacity.CapacityScheduler: nodeUpdate: slave2:40331 clusterResources: <memory:8192, vCores:2>
2019-06-07 08:11:29,334 DEBUG org.apache.hadoop.yarn.server.resourcemanager.scheduler.capacity.CapacityScheduler: nodeUpdate: slave2:40331 clusterResources: <memory:8192, vCores:2>
2019-06-07 08:11:29,334 DEBUG org.apache.hadoop.yarn.server.resourcemanager.scheduler.capacity.CapacityScheduler: Node being looked for scheduling slave2:40331 availableResource: <memory:0, vCores:-1>
2019-06-07 08:11:29,334 DEBUG org.apache.hadoop.yarn.server.resourcemanager.scheduler.capacity.CapacityScheduler: Node being looked for scheduling slave2:40331 availableResource: <memory:0, vCores:-1>
2019-06-07 08:11:30,333 DEBUG org.apache.hadoop.yarn.server.resourcemanager.rmnode.RMNodeImpl: Processing slave1:41069 of type STATUS_UPDATE
2019-06-07 08:11:30,333 DEBUG org.apache.hadoop.yarn.server.resourcemanager.rmnode.RMNodeImpl: Processing slave1:41069 of type STATUS_UPDATE
2019-06-07 08:11:30,334 DEBUG org.apache.hadoop.yarn.server.resourcemanager.scheduler.capacity.CapacityScheduler: nodeUpdate: slave1:41069 clusterResources: <memory:8192, vCores:2>
2019-06-07 08:11:30,334 DEBUG org.apache.hadoop.yarn.server.resourcemanager.scheduler.capacity.CapacityScheduler: nodeUpdate: slave1:41069 clusterResources: <memory:8192, vCores:2>
2019-06-07 08:11:30,334 DEBUG org.apache.hadoop.yarn.server.resourcemanager.scheduler.capacity.CapacityScheduler: Node being looked for scheduling slave1:41069 availableResource: <memory:1024, vCores:0>
2019-06-07 08:11:30,334 DEBUG org.apache.hadoop.yarn.server.resourcemanager.scheduler.capacity.CapacityScheduler: Node being looked for scheduling slave1:41069 availableResource: <memory:1024, vCores:0>
2019-06-07 08:11:30,334 DEBUG org.apache.hadoop.yarn.server.resourcemanager.scheduler.capacity.CapacityScheduler: Trying to schedule on node: slave1, available: <memory:1024, vCores:0>
2019-06-07 08:11:30,334 DEBUG org.apache.hadoop.yarn.server.resourcemanager.scheduler.capacity.CapacityScheduler: Trying to schedule on node: slave1, available: <memory:1024, vCores:0>
2019-06-07 08:11:30,334 DEBUG org.apache.hadoop.yarn.server.resourcemanager.scheduler.capacity.ParentQueue: Skip this queue=root, because it doesn't need more resource, schedulingMode=RESPECT_PARTITION_EXCLUSIVITY node-partition=
2019-06-07 08:11:30,334 DEBUG org.apache.hadoop.yarn.server.resourcemanager.scheduler.capacity.ParentQueue: Skip this queue=root, because it doesn't need more resource, schedulingMode=RESPECT_PARTITION_EXCLUSIVITY node-partition=
2019-06-07 08:11:30,339 DEBUG org.apache.hadoop.yarn.server.resourcemanager.rmnode.RMNodeImpl: Processing slave2:40331 of type STATUS_UPDATE
2019-06-07 08:11:30,339 DEBUG org.apache.hadoop.yarn.server.resourcemanager.rmnode.RMNodeImpl: Processing slave2:40331 of type STATUS_UPDATE
2019-06-07 08:11:30,342 DEBUG org.apache.hadoop.yarn.server.resourcemanager.scheduler.capacity.CapacityScheduler: nodeUpdate: slave2:40331 clusterResources: <memory:8192, vCores:2>
2019-06-07 08:11:30,342 DEBUG org.apache.hadoop.yarn.server.resourcemanager.scheduler.capacity.CapacityScheduler: nodeUpdate: slave2:40331 clusterResources: <memory:8192, vCores:2>
2019-06-07 08:11:30,342 DEBUG org.apache.hadoop.yarn.server.resourcemanager.scheduler.capacity.CapacityScheduler: Node being looked for scheduling slave2:40331 availableResource: <memory:0, vCores:-1>
2019-06-07 08:11:30,342 DEBUG org.apache.hadoop.yarn.server.resourcemanager.scheduler.capacity.CapacityScheduler: Node being looked for scheduling slave2:40331 availableResource: <memory:0, vCores:-1>
2019-06-07 08:11:31,337 DEBUG org.apache.hadoop.yarn.server.resourcemanager.rmnode.RMNodeImpl: Processing slave1:41069 of type STATUS_UPDATE
2019-06-07 08:11:31,337 DEBUG org.apache.hadoop.yarn.server.resourcemanager.rmnode.RMNodeImpl: Processing slave1:41069 of type STATUS_UPDATE
2019-06-07 08:11:31,337 DEBUG org.apache.hadoop.yarn.server.resourcemanager.scheduler.capacity.CapacityScheduler: nodeUpdate: slave1:41069 clusterResources: <memory:8192, vCores:2>
2019-06-07 08:11:31,337 DEBUG org.apache.hadoop.yarn.server.resourcemanager.scheduler.capacity.CapacityScheduler: nodeUpdate: slave1:41069 clusterResources: <memory:8192, vCores:2>
2019-06-07 08:11:31,337 DEBUG org.apache.hadoop.yarn.server.resourcemanager.scheduler.capacity.CapacityScheduler: Node being looked for scheduling slave1:41069 availableResource: <memory:1024, vCores:0>
2019-06-07 08:11:31,337 DEBUG org.apache.hadoop.yarn.server.resourcemanager.scheduler.capacity.CapacityScheduler: Node being looked for scheduling slave1:41069 availableResource: <memory:1024, vCores:0>
2019-06-07 08:11:31,337 DEBUG org.apache.hadoop.yarn.server.resourcemanager.scheduler.capacity.CapacityScheduler: Trying to schedule on node: slave1, available: <memory:1024, vCores:0>
2019-06-07 08:11:31,337 DEBUG org.apache.hadoop.yarn.server.resourcemanager.scheduler.capacity.CapacityScheduler: Trying to schedule on node: slave1, available: <memory:1024, vCores:0>
2019-06-07 08:11:31,337 DEBUG org.apache.hadoop.yarn.server.resourcemanager.scheduler.capacity.ParentQueue: Skip this queue=root, because it doesn't need more resource, schedulingMode=RESPECT_PARTITION_EXCLUSIVITY node-partition=
2019-06-07 08:11:31,337 DEBUG org.apache.hadoop.yarn.server.resourcemanager.scheduler.capacity.ParentQueue: Skip this queue=root, because it doesn't need more resource, schedulingMode=RESPECT_PARTITION_EXCLUSIVITY node-partition=
2019-06-07 08:11:31,352 DEBUG org.apache.hadoop.yarn.server.resourcemanager.rmnode.RMNodeImpl: Processing slave2:40331 of type STATUS_UPDATE
2019-06-07 08:11:31,352 DEBUG org.apache.hadoop.yarn.server.resourcemanager.rmnode.RMNodeImpl: Processing slave2:40331 of type STATUS_UPDATE
2019-06-07 08:11:31,352 DEBUG org.apache.hadoop.yarn.server.resourcemanager.scheduler.capacity.CapacityScheduler: nodeUpdate: slave2:40331 clusterResources: <memory:8192, vCores:2>
2019-06-07 08:11:31,352 DEBUG org.apache.hadoop.yarn.server.resourcemanager.scheduler.capacity.CapacityScheduler: nodeUpdate: slave2:40331 clusterResources: <memory:8192, vCores:2>
2019-06-07 08:11:31,352 DEBUG org.apache.hadoop.yarn.server.resourcemanager.scheduler.capacity.CapacityScheduler: Node being looked for scheduling slave2:40331 availableResource: <memory:0, vCores:-1>
2019-06-07 08:11:31,352 DEBUG org.apache.hadoop.yarn.server.resourcemanager.scheduler.capacity.CapacityScheduler: Node being looked for scheduling slave2:40331 availableResource: <memory:0, vCores:-1>
2019-06-07 08:11:31,353 DEBUG org.apache.hadoop.yarn.server.resourcemanager.scheduler.capacity.LeafQueue: User limit computation for root in queue default userLimitPercent=100 userLimitFactor=1.0 required: <memory:1024, vCores:1> consumed: <memory:7168, vCores:1> user-limit-resource: <memory:8192, vCores:1> queueCapacity: <memory:8192, vCores:1> qconsumed: <memory:7168, vCores:3> consumedRatio: 0.0 currentCapacity: <memory:8192, vCores:1> activeUsers: 0.0 clusterCapacity: <memory:8192, vCores:2> resourceByLabel: <memory:8192, vCores:2> usageratio: 0.875 Partition:  maxUserLimit=<memory:8192, vCores:1> userWeight=1.0
2019-06-07 08:11:31,353 DEBUG org.apache.hadoop.yarn.server.resourcemanager.scheduler.capacity.LeafQueue: User limit computation for root in queue default userLimitPercent=100 userLimitFactor=1.0 required: <memory:1024, vCores:1> consumed: <memory:7168, vCores:1> user-limit-resource: <memory:8192, vCores:1> queueCapacity: <memory:8192, vCores:1> qconsumed: <memory:7168, vCores:3> consumedRatio: 0.0 currentCapacity: <memory:8192, vCores:1> activeUsers: 0.0 clusterCapacity: <memory:8192, vCores:2> resourceByLabel: <memory:8192, vCores:2> usageratio: 0.875 Partition:  maxUserLimit=<memory:8192, vCores:1> userWeight=1.0
2019-06-07 08:11:31,357 DEBUG org.apache.hadoop.yarn.server.resourcemanager.rmapp.attempt.RMAppAttemptImpl: Processing event for appattempt_1559895028500_0001_000001 of type STATUS_UPDATE
2019-06-07 08:11:31,357 DEBUG org.apache.hadoop.yarn.server.resourcemanager.rmapp.attempt.RMAppAttemptImpl: Processing event for appattempt_1559895028500_0001_000001 of type STATUS_UPDATE
2019-06-07 08:11:32,350 DEBUG org.apache.hadoop.yarn.server.resourcemanager.rmnode.RMNodeImpl: Processing slave1:41069 of type STATUS_UPDATE
2019-06-07 08:11:32,350 DEBUG org.apache.hadoop.yarn.server.resourcemanager.rmnode.RMNodeImpl: Processing slave1:41069 of type STATUS_UPDATE
2019-06-07 08:11:32,350 DEBUG org.apache.hadoop.yarn.server.resourcemanager.scheduler.capacity.CapacityScheduler: nodeUpdate: slave1:41069 clusterResources: <memory:8192, vCores:2>
2019-06-07 08:11:32,363 DEBUG org.apache.hadoop.yarn.server.resourcemanager.rmnode.RMNodeImpl: Processing slave2:40331 of type STATUS_UPDATE
2019-06-07 08:11:32,350 DEBUG org.apache.hadoop.yarn.server.resourcemanager.scheduler.capacity.CapacityScheduler: nodeUpdate: slave1:41069 clusterResources: <memory:8192, vCores:2>
2019-06-07 08:11:32,375 DEBUG org.apache.hadoop.yarn.server.resourcemanager.scheduler.capacity.CapacityScheduler: Node being looked for scheduling slave1:41069 availableResource: <memory:1024, vCores:0>
2019-06-07 08:11:32,375 DEBUG org.apache.hadoop.yarn.server.resourcemanager.scheduler.capacity.CapacityScheduler: Node being looked for scheduling slave1:41069 availableResource: <memory:1024, vCores:0>
2019-06-07 08:11:32,375 DEBUG org.apache.hadoop.yarn.server.resourcemanager.scheduler.capacity.CapacityScheduler: Trying to schedule on node: slave1, available: <memory:1024, vCores:0>
2019-06-07 08:11:32,375 DEBUG org.apache.hadoop.yarn.server.resourcemanager.scheduler.capacity.CapacityScheduler: Trying to schedule on node: slave1, available: <memory:1024, vCores:0>
2019-06-07 08:11:32,375 DEBUG org.apache.hadoop.yarn.server.resourcemanager.scheduler.capacity.ParentQueue: Skip this queue=root, because it doesn't need more resource, schedulingMode=RESPECT_PARTITION_EXCLUSIVITY node-partition=
2019-06-07 08:11:32,375 DEBUG org.apache.hadoop.yarn.server.resourcemanager.scheduler.capacity.ParentQueue: Skip this queue=root, because it doesn't need more resource, schedulingMode=RESPECT_PARTITION_EXCLUSIVITY node-partition=
2019-06-07 08:11:32,363 DEBUG org.apache.hadoop.yarn.server.resourcemanager.rmnode.RMNodeImpl: Processing slave2:40331 of type STATUS_UPDATE
2019-06-07 08:11:32,375 DEBUG org.apache.hadoop.yarn.server.resourcemanager.scheduler.capacity.CapacityScheduler: nodeUpdate: slave2:40331 clusterResources: <memory:8192, vCores:2>
2019-06-07 08:11:32,375 DEBUG org.apache.hadoop.yarn.server.resourcemanager.scheduler.capacity.CapacityScheduler: nodeUpdate: slave2:40331 clusterResources: <memory:8192, vCores:2>
2019-06-07 08:11:32,375 DEBUG org.apache.hadoop.yarn.server.resourcemanager.scheduler.capacity.CapacityScheduler: Node being looked for scheduling slave2:40331 availableResource: <memory:0, vCores:-1>
2019-06-07 08:11:32,375 DEBUG org.apache.hadoop.yarn.server.resourcemanager.scheduler.capacity.CapacityScheduler: Node being looked for scheduling slave2:40331 availableResource: <memory:0, vCores:-1>
2019-06-07 08:11:33,355 DEBUG org.apache.hadoop.yarn.server.resourcemanager.rmnode.RMNodeImpl: Processing slave1:41069 of type STATUS_UPDATE
2019-06-07 08:11:33,355 DEBUG org.apache.hadoop.yarn.server.resourcemanager.rmnode.RMNodeImpl: Processing slave1:41069 of type STATUS_UPDATE
2019-06-07 08:11:33,366 DEBUG org.apache.hadoop.yarn.server.resourcemanager.scheduler.capacity.CapacityScheduler: nodeUpdate: slave1:41069 clusterResources: <memory:8192, vCores:2>
2019-06-07 08:11:33,366 DEBUG org.apache.hadoop.yarn.server.resourcemanager.scheduler.capacity.CapacityScheduler: nodeUpdate: slave1:41069 clusterResources: <memory:8192, vCores:2>
2019-06-07 08:11:33,367 DEBUG org.apache.hadoop.yarn.server.resourcemanager.scheduler.capacity.CapacityScheduler: Node being looked for scheduling slave1:41069 availableResource: <memory:1024, vCores:0>
2019-06-07 08:11:33,367 DEBUG org.apache.hadoop.yarn.server.resourcemanager.scheduler.capacity.CapacityScheduler: Node being looked for scheduling slave1:41069 availableResource: <memory:1024, vCores:0>
2019-06-07 08:11:33,367 DEBUG org.apache.hadoop.yarn.server.resourcemanager.scheduler.capacity.CapacityScheduler: Trying to schedule on node: slave1, available: <memory:1024, vCores:0>
2019-06-07 08:11:33,367 DEBUG org.apache.hadoop.yarn.server.resourcemanager.scheduler.capacity.CapacityScheduler: Trying to schedule on node: slave1, available: <memory:1024, vCores:0>
2019-06-07 08:11:33,367 DEBUG org.apache.hadoop.yarn.server.resourcemanager.scheduler.capacity.ParentQueue: Skip this queue=root, because it doesn't need more resource, schedulingMode=RESPECT_PARTITION_EXCLUSIVITY node-partition=
2019-06-07 08:11:33,367 DEBUG org.apache.hadoop.yarn.server.resourcemanager.scheduler.capacity.ParentQueue: Skip this queue=root, because it doesn't need more resource, schedulingMode=RESPECT_PARTITION_EXCLUSIVITY node-partition=
2019-06-07 08:11:33,369 DEBUG org.apache.hadoop.yarn.server.resourcemanager.rmnode.RMNodeImpl: Processing slave2:40331 of type STATUS_UPDATE
2019-06-07 08:11:33,369 DEBUG org.apache.hadoop.yarn.server.resourcemanager.rmnode.RMNodeImpl: Processing slave2:40331 of type STATUS_UPDATE
2019-06-07 08:11:33,375 DEBUG org.apache.hadoop.yarn.server.resourcemanager.scheduler.capacity.CapacityScheduler: nodeUpdate: slave2:40331 clusterResources: <memory:8192, vCores:2>
2019-06-07 08:11:33,375 DEBUG org.apache.hadoop.yarn.server.resourcemanager.scheduler.capacity.CapacityScheduler: nodeUpdate: slave2:40331 clusterResources: <memory:8192, vCores:2>
2019-06-07 08:11:33,375 DEBUG org.apache.hadoop.yarn.server.resourcemanager.scheduler.capacity.CapacityScheduler: Node being looked for scheduling slave2:40331 availableResource: <memory:0, vCores:-1>
2019-06-07 08:11:33,375 DEBUG org.apache.hadoop.yarn.server.resourcemanager.scheduler.capacity.CapacityScheduler: Node being looked for scheduling slave2:40331 availableResource: <memory:0, vCores:-1>
2019-06-07 08:11:34,361 DEBUG org.apache.hadoop.yarn.server.resourcemanager.rmnode.RMNodeImpl: Processing slave1:41069 of type STATUS_UPDATE
2019-06-07 08:11:34,361 DEBUG org.apache.hadoop.yarn.server.resourcemanager.rmnode.RMNodeImpl: Processing slave1:41069 of type STATUS_UPDATE
2019-06-07 08:11:34,365 DEBUG org.apache.hadoop.yarn.server.resourcemanager.scheduler.capacity.CapacityScheduler: nodeUpdate: slave1:41069 clusterResources: <memory:8192, vCores:2>
2019-06-07 08:11:34,365 DEBUG org.apache.hadoop.yarn.server.resourcemanager.scheduler.capacity.CapacityScheduler: nodeUpdate: slave1:41069 clusterResources: <memory:8192, vCores:2>
2019-06-07 08:11:34,365 DEBUG org.apache.hadoop.yarn.server.resourcemanager.scheduler.capacity.CapacityScheduler: Node being looked for scheduling slave1:41069 availableResource: <memory:1024, vCores:0>
2019-06-07 08:11:34,365 DEBUG org.apache.hadoop.yarn.server.resourcemanager.scheduler.capacity.CapacityScheduler: Node being looked for scheduling slave1:41069 availableResource: <memory:1024, vCores:0>
2019-06-07 08:11:34,365 DEBUG org.apache.hadoop.yarn.server.resourcemanager.scheduler.capacity.CapacityScheduler: Trying to schedule on node: slave1, available: <memory:1024, vCores:0>
2019-06-07 08:11:34,365 DEBUG org.apache.hadoop.yarn.server.resourcemanager.scheduler.capacity.CapacityScheduler: Trying to schedule on node: slave1, available: <memory:1024, vCores:0>
2019-06-07 08:11:34,365 DEBUG org.apache.hadoop.yarn.server.resourcemanager.scheduler.capacity.ParentQueue: Skip this queue=root, because it doesn't need more resource, schedulingMode=RESPECT_PARTITION_EXCLUSIVITY node-partition=
2019-06-07 08:11:34,365 DEBUG org.apache.hadoop.yarn.server.resourcemanager.scheduler.capacity.ParentQueue: Skip this queue=root, because it doesn't need more resource, schedulingMode=RESPECT_PARTITION_EXCLUSIVITY node-partition=
2019-06-07 08:11:34,365 DEBUG org.apache.hadoop.yarn.server.resourcemanager.scheduler.capacity.LeafQueue: User limit computation for root in queue default userLimitPercent=100 userLimitFactor=1.0 required: <memory:1024, vCores:1> consumed: <memory:7168, vCores:1> user-limit-resource: <memory:8192, vCores:1> queueCapacity: <memory:8192, vCores:1> qconsumed: <memory:7168, vCores:3> consumedRatio: 0.0 currentCapacity: <memory:8192, vCores:1> activeUsers: 0.0 clusterCapacity: <memory:8192, vCores:2> resourceByLabel: <memory:8192, vCores:2> usageratio: 0.875 Partition:  maxUserLimit=<memory:8192, vCores:1> userWeight=1.0
2019-06-07 08:11:34,365 DEBUG org.apache.hadoop.yarn.server.resourcemanager.scheduler.capacity.LeafQueue: User limit computation for root in queue default userLimitPercent=100 userLimitFactor=1.0 required: <memory:1024, vCores:1> consumed: <memory:7168, vCores:1> user-limit-resource: <memory:8192, vCores:1> queueCapacity: <memory:8192, vCores:1> qconsumed: <memory:7168, vCores:3> consumedRatio: 0.0 currentCapacity: <memory:8192, vCores:1> activeUsers: 0.0 clusterCapacity: <memory:8192, vCores:2> resourceByLabel: <memory:8192, vCores:2> usageratio: 0.875 Partition:  maxUserLimit=<memory:8192, vCores:1> userWeight=1.0
2019-06-07 08:11:34,366 DEBUG org.apache.hadoop.yarn.server.resourcemanager.rmapp.attempt.RMAppAttemptImpl: Processing event for appattempt_1559895028500_0001_000001 of type STATUS_UPDATE
2019-06-07 08:11:34,366 DEBUG org.apache.hadoop.yarn.server.resourcemanager.rmapp.attempt.RMAppAttemptImpl: Processing event for appattempt_1559895028500_0001_000001 of type STATUS_UPDATE
2019-06-07 08:11:34,392 DEBUG org.apache.hadoop.yarn.server.resourcemanager.rmnode.RMNodeImpl: Processing slave2:40331 of type STATUS_UPDATE
2019-06-07 08:11:34,392 DEBUG org.apache.hadoop.yarn.server.resourcemanager.rmnode.RMNodeImpl: Processing slave2:40331 of type STATUS_UPDATE
2019-06-07 08:11:34,392 DEBUG org.apache.hadoop.yarn.server.resourcemanager.scheduler.capacity.CapacityScheduler: nodeUpdate: slave2:40331 clusterResources: <memory:8192, vCores:2>
2019-06-07 08:11:34,392 DEBUG org.apache.hadoop.yarn.server.resourcemanager.scheduler.capacity.CapacityScheduler: nodeUpdate: slave2:40331 clusterResources: <memory:8192, vCores:2>
2019-06-07 08:11:34,403 DEBUG org.apache.hadoop.yarn.server.resourcemanager.scheduler.capacity.CapacityScheduler: Node being looked for scheduling slave2:40331 availableResource: <memory:0, vCores:-1>
2019-06-07 08:11:34,403 DEBUG org.apache.hadoop.yarn.server.resourcemanager.scheduler.capacity.CapacityScheduler: Node being looked for scheduling slave2:40331 availableResource: <memory:0, vCores:-1>
2019-06-07 08:11:35,372 DEBUG org.apache.hadoop.yarn.server.resourcemanager.rmnode.RMNodeImpl: Processing slave1:41069 of type STATUS_UPDATE
2019-06-07 08:11:35,372 DEBUG org.apache.hadoop.yarn.server.resourcemanager.rmnode.RMNodeImpl: Processing slave1:41069 of type STATUS_UPDATE
2019-06-07 08:11:35,372 DEBUG org.apache.hadoop.yarn.server.resourcemanager.scheduler.capacity.CapacityScheduler: nodeUpdate: slave1:41069 clusterResources: <memory:8192, vCores:2>
2019-06-07 08:11:35,372 DEBUG org.apache.hadoop.yarn.server.resourcemanager.scheduler.capacity.CapacityScheduler: nodeUpdate: slave1:41069 clusterResources: <memory:8192, vCores:2>
2019-06-07 08:11:35,372 DEBUG org.apache.hadoop.yarn.server.resourcemanager.scheduler.capacity.CapacityScheduler: Node being looked for scheduling slave1:41069 availableResource: <memory:1024, vCores:0>
2019-06-07 08:11:35,372 DEBUG org.apache.hadoop.yarn.server.resourcemanager.scheduler.capacity.CapacityScheduler: Node being looked for scheduling slave1:41069 availableResource: <memory:1024, vCores:0>
2019-06-07 08:11:35,373 DEBUG org.apache.hadoop.yarn.server.resourcemanager.scheduler.capacity.CapacityScheduler: Trying to schedule on node: slave1, available: <memory:1024, vCores:0>
2019-06-07 08:11:35,373 DEBUG org.apache.hadoop.yarn.server.resourcemanager.scheduler.capacity.CapacityScheduler: Trying to schedule on node: slave1, available: <memory:1024, vCores:0>
2019-06-07 08:11:35,373 DEBUG org.apache.hadoop.yarn.server.resourcemanager.scheduler.capacity.ParentQueue: Skip this queue=root, because it doesn't need more resource, schedulingMode=RESPECT_PARTITION_EXCLUSIVITY node-partition=
2019-06-07 08:11:35,373 DEBUG org.apache.hadoop.yarn.server.resourcemanager.scheduler.capacity.ParentQueue: Skip this queue=root, because it doesn't need more resource, schedulingMode=RESPECT_PARTITION_EXCLUSIVITY node-partition=
2019-06-07 08:11:35,405 DEBUG org.apache.hadoop.yarn.server.resourcemanager.rmnode.RMNodeImpl: Processing slave2:40331 of type STATUS_UPDATE
2019-06-07 08:11:35,405 DEBUG org.apache.hadoop.yarn.server.resourcemanager.rmnode.RMNodeImpl: Processing slave2:40331 of type STATUS_UPDATE
2019-06-07 08:11:35,410 DEBUG org.apache.hadoop.yarn.server.resourcemanager.scheduler.capacity.CapacityScheduler: nodeUpdate: slave2:40331 clusterResources: <memory:8192, vCores:2>
2019-06-07 08:11:35,410 DEBUG org.apache.hadoop.yarn.server.resourcemanager.scheduler.capacity.CapacityScheduler: nodeUpdate: slave2:40331 clusterResources: <memory:8192, vCores:2>
2019-06-07 08:11:35,411 DEBUG org.apache.hadoop.yarn.server.resourcemanager.scheduler.capacity.CapacityScheduler: Node being looked for scheduling slave2:40331 availableResource: <memory:0, vCores:-1>
2019-06-07 08:11:35,411 DEBUG org.apache.hadoop.yarn.server.resourcemanager.scheduler.capacity.CapacityScheduler: Node being looked for scheduling slave2:40331 availableResource: <memory:0, vCores:-1>
2019-06-07 08:11:36,375 DEBUG org.apache.hadoop.yarn.server.resourcemanager.rmnode.RMNodeImpl: Processing slave1:41069 of type STATUS_UPDATE
2019-06-07 08:11:36,375 DEBUG org.apache.hadoop.yarn.server.resourcemanager.rmnode.RMNodeImpl: Processing slave1:41069 of type STATUS_UPDATE
2019-06-07 08:11:36,375 DEBUG org.apache.hadoop.yarn.server.resourcemanager.scheduler.capacity.CapacityScheduler: nodeUpdate: slave1:41069 clusterResources: <memory:8192, vCores:2>
2019-06-07 08:11:36,375 DEBUG org.apache.hadoop.yarn.server.resourcemanager.scheduler.capacity.CapacityScheduler: nodeUpdate: slave1:41069 clusterResources: <memory:8192, vCores:2>
2019-06-07 08:11:36,376 DEBUG org.apache.hadoop.yarn.server.resourcemanager.scheduler.capacity.CapacityScheduler: Node being looked for scheduling slave1:41069 availableResource: <memory:1024, vCores:0>
2019-06-07 08:11:36,376 DEBUG org.apache.hadoop.yarn.server.resourcemanager.scheduler.capacity.CapacityScheduler: Node being looked for scheduling slave1:41069 availableResource: <memory:1024, vCores:0>
2019-06-07 08:11:36,376 DEBUG org.apache.hadoop.yarn.server.resourcemanager.scheduler.capacity.CapacityScheduler: Trying to schedule on node: slave1, available: <memory:1024, vCores:0>
2019-06-07 08:11:36,376 DEBUG org.apache.hadoop.yarn.server.resourcemanager.scheduler.capacity.CapacityScheduler: Trying to schedule on node: slave1, available: <memory:1024, vCores:0>
2019-06-07 08:11:36,376 DEBUG org.apache.hadoop.yarn.server.resourcemanager.scheduler.capacity.ParentQueue: Skip this queue=root, because it doesn't need more resource, schedulingMode=RESPECT_PARTITION_EXCLUSIVITY node-partition=
2019-06-07 08:11:36,376 DEBUG org.apache.hadoop.yarn.server.resourcemanager.scheduler.capacity.ParentQueue: Skip this queue=root, because it doesn't need more resource, schedulingMode=RESPECT_PARTITION_EXCLUSIVITY node-partition=
2019-06-07 08:11:36,415 DEBUG org.apache.hadoop.yarn.server.resourcemanager.rmnode.RMNodeImpl: Processing slave2:40331 of type STATUS_UPDATE
2019-06-07 08:11:36,415 DEBUG org.apache.hadoop.yarn.server.resourcemanager.rmnode.RMNodeImpl: Processing slave2:40331 of type STATUS_UPDATE
2019-06-07 08:11:36,417 DEBUG org.apache.hadoop.yarn.server.resourcemanager.scheduler.capacity.CapacityScheduler: nodeUpdate: slave2:40331 clusterResources: <memory:8192, vCores:2>
2019-06-07 08:11:36,417 DEBUG org.apache.hadoop.yarn.server.resourcemanager.scheduler.capacity.CapacityScheduler: nodeUpdate: slave2:40331 clusterResources: <memory:8192, vCores:2>
2019-06-07 08:11:36,417 DEBUG org.apache.hadoop.yarn.server.resourcemanager.scheduler.capacity.CapacityScheduler: Node being looked for scheduling slave2:40331 availableResource: <memory:0, vCores:-1>
2019-06-07 08:11:36,417 DEBUG org.apache.hadoop.yarn.server.resourcemanager.scheduler.capacity.CapacityScheduler: Node being looked for scheduling slave2:40331 availableResource: <memory:0, vCores:-1>
2019-06-07 08:11:37,375 DEBUG org.apache.hadoop.yarn.server.resourcemanager.rmapp.attempt.RMAppAttemptImpl: Processing event for appattempt_1559895028500_0001_000001 of type STATUS_UPDATE
2019-06-07 08:11:37,375 DEBUG org.apache.hadoop.yarn.server.resourcemanager.rmapp.attempt.RMAppAttemptImpl: Processing event for appattempt_1559895028500_0001_000001 of type STATUS_UPDATE
2019-06-07 08:11:37,376 DEBUG org.apache.hadoop.yarn.server.resourcemanager.scheduler.capacity.LeafQueue: User limit computation for root in queue default userLimitPercent=100 userLimitFactor=1.0 required: <memory:1024, vCores:1> consumed: <memory:7168, vCores:1> user-limit-resource: <memory:8192, vCores:1> queueCapacity: <memory:8192, vCores:1> qconsumed: <memory:7168, vCores:3> consumedRatio: 0.0 currentCapacity: <memory:8192, vCores:1> activeUsers: 0.0 clusterCapacity: <memory:8192, vCores:2> resourceByLabel: <memory:8192, vCores:2> usageratio: 0.875 Partition:  maxUserLimit=<memory:8192, vCores:1> userWeight=1.0
2019-06-07 08:11:37,376 DEBUG org.apache.hadoop.yarn.server.resourcemanager.scheduler.capacity.LeafQueue: User limit computation for root in queue default userLimitPercent=100 userLimitFactor=1.0 required: <memory:1024, vCores:1> consumed: <memory:7168, vCores:1> user-limit-resource: <memory:8192, vCores:1> queueCapacity: <memory:8192, vCores:1> qconsumed: <memory:7168, vCores:3> consumedRatio: 0.0 currentCapacity: <memory:8192, vCores:1> activeUsers: 0.0 clusterCapacity: <memory:8192, vCores:2> resourceByLabel: <memory:8192, vCores:2> usageratio: 0.875 Partition:  maxUserLimit=<memory:8192, vCores:1> userWeight=1.0
2019-06-07 08:11:37,388 DEBUG org.apache.hadoop.yarn.server.resourcemanager.rmnode.RMNodeImpl: Processing slave1:41069 of type STATUS_UPDATE
2019-06-07 08:11:37,388 DEBUG org.apache.hadoop.yarn.server.resourcemanager.rmnode.RMNodeImpl: Processing slave1:41069 of type STATUS_UPDATE
2019-06-07 08:11:37,388 DEBUG org.apache.hadoop.yarn.server.resourcemanager.scheduler.capacity.CapacityScheduler: nodeUpdate: slave1:41069 clusterResources: <memory:8192, vCores:2>
2019-06-07 08:11:37,388 DEBUG org.apache.hadoop.yarn.server.resourcemanager.scheduler.capacity.CapacityScheduler: nodeUpdate: slave1:41069 clusterResources: <memory:8192, vCores:2>
2019-06-07 08:11:37,389 DEBUG org.apache.hadoop.yarn.server.resourcemanager.scheduler.capacity.CapacityScheduler: Node being looked for scheduling slave1:41069 availableResource: <memory:1024, vCores:0>
2019-06-07 08:11:37,389 DEBUG org.apache.hadoop.yarn.server.resourcemanager.scheduler.capacity.CapacityScheduler: Node being looked for scheduling slave1:41069 availableResource: <memory:1024, vCores:0>
2019-06-07 08:11:37,389 DEBUG org.apache.hadoop.yarn.server.resourcemanager.scheduler.capacity.CapacityScheduler: Trying to schedule on node: slave1, available: <memory:1024, vCores:0>
2019-06-07 08:11:37,389 DEBUG org.apache.hadoop.yarn.server.resourcemanager.scheduler.capacity.CapacityScheduler: Trying to schedule on node: slave1, available: <memory:1024, vCores:0>
2019-06-07 08:11:37,389 DEBUG org.apache.hadoop.yarn.server.resourcemanager.scheduler.capacity.ParentQueue: Skip this queue=root, because it doesn't need more resource, schedulingMode=RESPECT_PARTITION_EXCLUSIVITY node-partition=
2019-06-07 08:11:37,389 DEBUG org.apache.hadoop.yarn.server.resourcemanager.scheduler.capacity.ParentQueue: Skip this queue=root, because it doesn't need more resource, schedulingMode=RESPECT_PARTITION_EXCLUSIVITY node-partition=
2019-06-07 08:11:37,418 DEBUG org.apache.hadoop.yarn.server.resourcemanager.rmnode.RMNodeImpl: Processing slave2:40331 of type STATUS_UPDATE
2019-06-07 08:11:37,418 DEBUG org.apache.hadoop.yarn.server.resourcemanager.rmnode.RMNodeImpl: Processing slave2:40331 of type STATUS_UPDATE
2019-06-07 08:11:37,418 DEBUG org.apache.hadoop.yarn.server.resourcemanager.scheduler.capacity.CapacityScheduler: nodeUpdate: slave2:40331 clusterResources: <memory:8192, vCores:2>
2019-06-07 08:11:37,418 DEBUG org.apache.hadoop.yarn.server.resourcemanager.scheduler.capacity.CapacityScheduler: nodeUpdate: slave2:40331 clusterResources: <memory:8192, vCores:2>
2019-06-07 08:11:37,418 DEBUG org.apache.hadoop.yarn.server.resourcemanager.scheduler.capacity.CapacityScheduler: Node being looked for scheduling slave2:40331 availableResource: <memory:0, vCores:-1>
2019-06-07 08:11:37,418 DEBUG org.apache.hadoop.yarn.server.resourcemanager.scheduler.capacity.CapacityScheduler: Node being looked for scheduling slave2:40331 availableResource: <memory:0, vCores:-1>
2019-06-07 08:11:38,391 DEBUG org.apache.hadoop.yarn.server.resourcemanager.rmnode.RMNodeImpl: Processing slave1:41069 of type STATUS_UPDATE
2019-06-07 08:11:38,391 DEBUG org.apache.hadoop.yarn.server.resourcemanager.rmnode.RMNodeImpl: Processing slave1:41069 of type STATUS_UPDATE
2019-06-07 08:11:38,392 DEBUG org.apache.hadoop.yarn.server.resourcemanager.scheduler.capacity.CapacityScheduler: nodeUpdate: slave1:41069 clusterResources: <memory:8192, vCores:2>
2019-06-07 08:11:38,392 DEBUG org.apache.hadoop.yarn.server.resourcemanager.scheduler.capacity.CapacityScheduler: nodeUpdate: slave1:41069 clusterResources: <memory:8192, vCores:2>
2019-06-07 08:11:38,392 DEBUG org.apache.hadoop.yarn.server.resourcemanager.scheduler.capacity.CapacityScheduler: Node being looked for scheduling slave1:41069 availableResource: <memory:1024, vCores:0>
2019-06-07 08:11:38,392 DEBUG org.apache.hadoop.yarn.server.resourcemanager.scheduler.capacity.CapacityScheduler: Node being looked for scheduling slave1:41069 availableResource: <memory:1024, vCores:0>
2019-06-07 08:11:38,392 DEBUG org.apache.hadoop.yarn.server.resourcemanager.scheduler.capacity.CapacityScheduler: Trying to schedule on node: slave1, available: <memory:1024, vCores:0>
2019-06-07 08:11:38,392 DEBUG org.apache.hadoop.yarn.server.resourcemanager.scheduler.capacity.CapacityScheduler: Trying to schedule on node: slave1, available: <memory:1024, vCores:0>
2019-06-07 08:11:38,392 DEBUG org.apache.hadoop.yarn.server.resourcemanager.scheduler.capacity.ParentQueue: Skip this queue=root, because it doesn't need more resource, schedulingMode=RESPECT_PARTITION_EXCLUSIVITY node-partition=
2019-06-07 08:11:38,392 DEBUG org.apache.hadoop.yarn.server.resourcemanager.scheduler.capacity.ParentQueue: Skip this queue=root, because it doesn't need more resource, schedulingMode=RESPECT_PARTITION_EXCLUSIVITY node-partition=
2019-06-07 08:11:38,426 DEBUG org.apache.hadoop.yarn.server.resourcemanager.rmnode.RMNodeImpl: Processing slave2:40331 of type STATUS_UPDATE
2019-06-07 08:11:38,426 DEBUG org.apache.hadoop.yarn.server.resourcemanager.rmnode.RMNodeImpl: Processing slave2:40331 of type STATUS_UPDATE
2019-06-07 08:11:38,427 DEBUG org.apache.hadoop.yarn.server.resourcemanager.scheduler.capacity.CapacityScheduler: nodeUpdate: slave2:40331 clusterResources: <memory:8192, vCores:2>
2019-06-07 08:11:38,427 DEBUG org.apache.hadoop.yarn.server.resourcemanager.scheduler.capacity.CapacityScheduler: nodeUpdate: slave2:40331 clusterResources: <memory:8192, vCores:2>
2019-06-07 08:11:38,427 DEBUG org.apache.hadoop.yarn.server.resourcemanager.scheduler.capacity.CapacityScheduler: Node being looked for scheduling slave2:40331 availableResource: <memory:0, vCores:-1>
2019-06-07 08:11:38,427 DEBUG org.apache.hadoop.yarn.server.resourcemanager.scheduler.capacity.CapacityScheduler: Node being looked for scheduling slave2:40331 availableResource: <memory:0, vCores:-1>
2019-06-07 08:11:39,394 DEBUG org.apache.hadoop.yarn.server.resourcemanager.rmnode.RMNodeImpl: Processing slave1:41069 of type STATUS_UPDATE
2019-06-07 08:11:39,394 DEBUG org.apache.hadoop.yarn.server.resourcemanager.rmnode.RMNodeImpl: Processing slave1:41069 of type STATUS_UPDATE
2019-06-07 08:11:39,395 DEBUG org.apache.hadoop.yarn.server.resourcemanager.scheduler.capacity.CapacityScheduler: nodeUpdate: slave1:41069 clusterResources: <memory:8192, vCores:2>
2019-06-07 08:11:39,395 DEBUG org.apache.hadoop.yarn.server.resourcemanager.scheduler.capacity.CapacityScheduler: nodeUpdate: slave1:41069 clusterResources: <memory:8192, vCores:2>
2019-06-07 08:11:39,395 DEBUG org.apache.hadoop.yarn.server.resourcemanager.scheduler.capacity.CapacityScheduler: Node being looked for scheduling slave1:41069 availableResource: <memory:1024, vCores:0>
2019-06-07 08:11:39,395 DEBUG org.apache.hadoop.yarn.server.resourcemanager.scheduler.capacity.CapacityScheduler: Node being looked for scheduling slave1:41069 availableResource: <memory:1024, vCores:0>
2019-06-07 08:11:39,395 DEBUG org.apache.hadoop.yarn.server.resourcemanager.scheduler.capacity.CapacityScheduler: Trying to schedule on node: slave1, available: <memory:1024, vCores:0>
2019-06-07 08:11:39,395 DEBUG org.apache.hadoop.yarn.server.resourcemanager.scheduler.capacity.CapacityScheduler: Trying to schedule on node: slave1, available: <memory:1024, vCores:0>
2019-06-07 08:11:39,395 DEBUG org.apache.hadoop.yarn.server.resourcemanager.scheduler.capacity.ParentQueue: Skip this queue=root, because it doesn't need more resource, schedulingMode=RESPECT_PARTITION_EXCLUSIVITY node-partition=
2019-06-07 08:11:39,395 DEBUG org.apache.hadoop.yarn.server.resourcemanager.scheduler.capacity.ParentQueue: Skip this queue=root, because it doesn't need more resource, schedulingMode=RESPECT_PARTITION_EXCLUSIVITY node-partition=
2019-06-07 08:11:39,429 DEBUG org.apache.hadoop.yarn.server.resourcemanager.rmnode.RMNodeImpl: Processing slave2:40331 of type STATUS_UPDATE
2019-06-07 08:11:39,429 DEBUG org.apache.hadoop.yarn.server.resourcemanager.rmnode.RMNodeImpl: Processing slave2:40331 of type STATUS_UPDATE
2019-06-07 08:11:39,429 DEBUG org.apache.hadoop.yarn.server.resourcemanager.scheduler.capacity.CapacityScheduler: nodeUpdate: slave2:40331 clusterResources: <memory:8192, vCores:2>
2019-06-07 08:11:39,429 DEBUG org.apache.hadoop.yarn.server.resourcemanager.scheduler.capacity.CapacityScheduler: nodeUpdate: slave2:40331 clusterResources: <memory:8192, vCores:2>
2019-06-07 08:11:39,429 DEBUG org.apache.hadoop.yarn.server.resourcemanager.scheduler.capacity.CapacityScheduler: Node being looked for scheduling slave2:40331 availableResource: <memory:0, vCores:-1>
2019-06-07 08:11:39,429 DEBUG org.apache.hadoop.yarn.server.resourcemanager.scheduler.capacity.CapacityScheduler: Node being looked for scheduling slave2:40331 availableResource: <memory:0, vCores:-1>
2019-06-07 08:11:40,381 DEBUG org.apache.hadoop.yarn.server.resourcemanager.rmapp.attempt.RMAppAttemptImpl: Processing event for appattempt_1559895028500_0001_000001 of type STATUS_UPDATE
2019-06-07 08:11:40,381 DEBUG org.apache.hadoop.yarn.server.resourcemanager.rmapp.attempt.RMAppAttemptImpl: Processing event for appattempt_1559895028500_0001_000001 of type STATUS_UPDATE
2019-06-07 08:11:40,384 DEBUG org.apache.hadoop.yarn.server.resourcemanager.scheduler.capacity.LeafQueue: User limit computation for root in queue default userLimitPercent=100 userLimitFactor=1.0 required: <memory:1024, vCores:1> consumed: <memory:7168, vCores:1> user-limit-resource: <memory:8192, vCores:1> queueCapacity: <memory:8192, vCores:1> qconsumed: <memory:7168, vCores:3> consumedRatio: 0.0 currentCapacity: <memory:8192, vCores:1> activeUsers: 0.0 clusterCapacity: <memory:8192, vCores:2> resourceByLabel: <memory:8192, vCores:2> usageratio: 0.875 Partition:  maxUserLimit=<memory:8192, vCores:1> userWeight=1.0
2019-06-07 08:11:40,384 DEBUG org.apache.hadoop.yarn.server.resourcemanager.scheduler.capacity.LeafQueue: User limit computation for root in queue default userLimitPercent=100 userLimitFactor=1.0 required: <memory:1024, vCores:1> consumed: <memory:7168, vCores:1> user-limit-resource: <memory:8192, vCores:1> queueCapacity: <memory:8192, vCores:1> qconsumed: <memory:7168, vCores:3> consumedRatio: 0.0 currentCapacity: <memory:8192, vCores:1> activeUsers: 0.0 clusterCapacity: <memory:8192, vCores:2> resourceByLabel: <memory:8192, vCores:2> usageratio: 0.875 Partition:  maxUserLimit=<memory:8192, vCores:1> userWeight=1.0
2019-06-07 08:11:40,410 DEBUG org.apache.hadoop.yarn.server.resourcemanager.rmnode.RMNodeImpl: Processing slave1:41069 of type STATUS_UPDATE
2019-06-07 08:11:40,410 DEBUG org.apache.hadoop.yarn.server.resourcemanager.rmnode.RMNodeImpl: Processing slave1:41069 of type STATUS_UPDATE
2019-06-07 08:11:40,410 DEBUG org.apache.hadoop.yarn.server.resourcemanager.scheduler.capacity.CapacityScheduler: nodeUpdate: slave1:41069 clusterResources: <memory:8192, vCores:2>
2019-06-07 08:11:40,410 DEBUG org.apache.hadoop.yarn.server.resourcemanager.scheduler.capacity.CapacityScheduler: nodeUpdate: slave1:41069 clusterResources: <memory:8192, vCores:2>
2019-06-07 08:11:40,413 DEBUG org.apache.hadoop.yarn.server.resourcemanager.scheduler.capacity.CapacityScheduler: Node being looked for scheduling slave1:41069 availableResource: <memory:1024, vCores:0>
2019-06-07 08:11:40,413 DEBUG org.apache.hadoop.yarn.server.resourcemanager.scheduler.capacity.CapacityScheduler: Node being looked for scheduling slave1:41069 availableResource: <memory:1024, vCores:0>
2019-06-07 08:11:40,414 DEBUG org.apache.hadoop.yarn.server.resourcemanager.scheduler.capacity.CapacityScheduler: Trying to schedule on node: slave1, available: <memory:1024, vCores:0>
2019-06-07 08:11:40,414 DEBUG org.apache.hadoop.yarn.server.resourcemanager.scheduler.capacity.CapacityScheduler: Trying to schedule on node: slave1, available: <memory:1024, vCores:0>
2019-06-07 08:11:40,414 DEBUG org.apache.hadoop.yarn.server.resourcemanager.scheduler.capacity.ParentQueue: Skip this queue=root, because it doesn't need more resource, schedulingMode=RESPECT_PARTITION_EXCLUSIVITY node-partition=
2019-06-07 08:11:40,414 DEBUG org.apache.hadoop.yarn.server.resourcemanager.scheduler.capacity.ParentQueue: Skip this queue=root, because it doesn't need more resource, schedulingMode=RESPECT_PARTITION_EXCLUSIVITY node-partition=
2019-06-07 08:11:40,434 DEBUG org.apache.hadoop.yarn.server.resourcemanager.rmnode.RMNodeImpl: Processing slave2:40331 of type STATUS_UPDATE
2019-06-07 08:11:40,434 DEBUG org.apache.hadoop.yarn.server.resourcemanager.rmnode.RMNodeImpl: Processing slave2:40331 of type STATUS_UPDATE
2019-06-07 08:11:40,434 DEBUG org.apache.hadoop.yarn.server.resourcemanager.scheduler.capacity.CapacityScheduler: nodeUpdate: slave2:40331 clusterResources: <memory:8192, vCores:2>
2019-06-07 08:11:40,434 DEBUG org.apache.hadoop.yarn.server.resourcemanager.scheduler.capacity.CapacityScheduler: nodeUpdate: slave2:40331 clusterResources: <memory:8192, vCores:2>
2019-06-07 08:11:40,434 DEBUG org.apache.hadoop.yarn.server.resourcemanager.scheduler.capacity.CapacityScheduler: Node being looked for scheduling slave2:40331 availableResource: <memory:0, vCores:-1>
2019-06-07 08:11:40,434 DEBUG org.apache.hadoop.yarn.server.resourcemanager.scheduler.capacity.CapacityScheduler: Node being looked for scheduling slave2:40331 availableResource: <memory:0, vCores:-1>
2019-06-07 08:11:41,413 DEBUG org.apache.hadoop.yarn.server.resourcemanager.rmnode.RMNodeImpl: Processing slave1:41069 of type STATUS_UPDATE
2019-06-07 08:11:41,413 DEBUG org.apache.hadoop.yarn.server.resourcemanager.rmnode.RMNodeImpl: Processing slave1:41069 of type STATUS_UPDATE
2019-06-07 08:11:41,414 DEBUG org.apache.hadoop.yarn.server.resourcemanager.scheduler.capacity.CapacityScheduler: nodeUpdate: slave1:41069 clusterResources: <memory:8192, vCores:2>
2019-06-07 08:11:41,414 DEBUG org.apache.hadoop.yarn.server.resourcemanager.scheduler.capacity.CapacityScheduler: nodeUpdate: slave1:41069 clusterResources: <memory:8192, vCores:2>
2019-06-07 08:11:41,414 DEBUG org.apache.hadoop.yarn.server.resourcemanager.scheduler.capacity.CapacityScheduler: Node being looked for scheduling slave1:41069 availableResource: <memory:1024, vCores:0>
2019-06-07 08:11:41,414 DEBUG org.apache.hadoop.yarn.server.resourcemanager.scheduler.capacity.CapacityScheduler: Node being looked for scheduling slave1:41069 availableResource: <memory:1024, vCores:0>
2019-06-07 08:11:41,414 DEBUG org.apache.hadoop.yarn.server.resourcemanager.scheduler.capacity.CapacityScheduler: Trying to schedule on node: slave1, available: <memory:1024, vCores:0>
2019-06-07 08:11:41,414 DEBUG org.apache.hadoop.yarn.server.resourcemanager.scheduler.capacity.CapacityScheduler: Trying to schedule on node: slave1, available: <memory:1024, vCores:0>
2019-06-07 08:11:41,414 DEBUG org.apache.hadoop.yarn.server.resourcemanager.scheduler.capacity.ParentQueue: Skip this queue=root, because it doesn't need more resource, schedulingMode=RESPECT_PARTITION_EXCLUSIVITY node-partition=
2019-06-07 08:11:41,414 DEBUG org.apache.hadoop.yarn.server.resourcemanager.scheduler.capacity.ParentQueue: Skip this queue=root, because it doesn't need more resource, schedulingMode=RESPECT_PARTITION_EXCLUSIVITY node-partition=
2019-06-07 08:11:41,434 DEBUG org.apache.hadoop.yarn.server.resourcemanager.rmnode.RMNodeImpl: Processing slave2:40331 of type STATUS_UPDATE
2019-06-07 08:11:41,434 DEBUG org.apache.hadoop.yarn.server.resourcemanager.rmnode.RMNodeImpl: Processing slave2:40331 of type STATUS_UPDATE
2019-06-07 08:11:41,435 DEBUG org.apache.hadoop.yarn.server.resourcemanager.scheduler.capacity.CapacityScheduler: nodeUpdate: slave2:40331 clusterResources: <memory:8192, vCores:2>
2019-06-07 08:11:41,435 DEBUG org.apache.hadoop.yarn.server.resourcemanager.scheduler.capacity.CapacityScheduler: nodeUpdate: slave2:40331 clusterResources: <memory:8192, vCores:2>
2019-06-07 08:11:41,435 DEBUG org.apache.hadoop.yarn.server.resourcemanager.scheduler.capacity.CapacityScheduler: Node being looked for scheduling slave2:40331 availableResource: <memory:0, vCores:-1>
2019-06-07 08:11:41,435 DEBUG org.apache.hadoop.yarn.server.resourcemanager.scheduler.capacity.CapacityScheduler: Node being looked for scheduling slave2:40331 availableResource: <memory:0, vCores:-1>
2019-06-07 08:11:42,417 DEBUG org.apache.hadoop.yarn.server.resourcemanager.rmnode.RMNodeImpl: Processing slave1:41069 of type STATUS_UPDATE
2019-06-07 08:11:42,417 DEBUG org.apache.hadoop.yarn.server.resourcemanager.rmnode.RMNodeImpl: Processing slave1:41069 of type STATUS_UPDATE
2019-06-07 08:11:42,417 DEBUG org.apache.hadoop.yarn.server.resourcemanager.scheduler.capacity.CapacityScheduler: nodeUpdate: slave1:41069 clusterResources: <memory:8192, vCores:2>
2019-06-07 08:11:42,417 DEBUG org.apache.hadoop.yarn.server.resourcemanager.scheduler.capacity.CapacityScheduler: nodeUpdate: slave1:41069 clusterResources: <memory:8192, vCores:2>
2019-06-07 08:11:42,418 DEBUG org.apache.hadoop.yarn.server.resourcemanager.scheduler.capacity.CapacityScheduler: Node being looked for scheduling slave1:41069 availableResource: <memory:1024, vCores:0>
2019-06-07 08:11:42,418 DEBUG org.apache.hadoop.yarn.server.resourcemanager.scheduler.capacity.CapacityScheduler: Node being looked for scheduling slave1:41069 availableResource: <memory:1024, vCores:0>
2019-06-07 08:11:42,418 DEBUG org.apache.hadoop.yarn.server.resourcemanager.scheduler.capacity.CapacityScheduler: Trying to schedule on node: slave1, available: <memory:1024, vCores:0>
2019-06-07 08:11:42,418 DEBUG org.apache.hadoop.yarn.server.resourcemanager.scheduler.capacity.CapacityScheduler: Trying to schedule on node: slave1, available: <memory:1024, vCores:0>
2019-06-07 08:11:42,418 DEBUG org.apache.hadoop.yarn.server.resourcemanager.scheduler.capacity.ParentQueue: Skip this queue=root, because it doesn't need more resource, schedulingMode=RESPECT_PARTITION_EXCLUSIVITY node-partition=
2019-06-07 08:11:42,418 DEBUG org.apache.hadoop.yarn.server.resourcemanager.scheduler.capacity.ParentQueue: Skip this queue=root, because it doesn't need more resource, schedulingMode=RESPECT_PARTITION_EXCLUSIVITY node-partition=
2019-06-07 08:11:42,438 DEBUG org.apache.hadoop.yarn.server.resourcemanager.rmnode.RMNodeImpl: Processing slave2:40331 of type STATUS_UPDATE
2019-06-07 08:11:42,438 DEBUG org.apache.hadoop.yarn.server.resourcemanager.rmnode.RMNodeImpl: Processing slave2:40331 of type STATUS_UPDATE
2019-06-07 08:11:42,440 DEBUG org.apache.hadoop.yarn.server.resourcemanager.scheduler.capacity.CapacityScheduler: nodeUpdate: slave2:40331 clusterResources: <memory:8192, vCores:2>
2019-06-07 08:11:42,440 DEBUG org.apache.hadoop.yarn.server.resourcemanager.scheduler.capacity.CapacityScheduler: nodeUpdate: slave2:40331 clusterResources: <memory:8192, vCores:2>
2019-06-07 08:11:42,440 DEBUG org.apache.hadoop.yarn.server.resourcemanager.scheduler.capacity.CapacityScheduler: Node being looked for scheduling slave2:40331 availableResource: <memory:0, vCores:-1>
2019-06-07 08:11:42,440 DEBUG org.apache.hadoop.yarn.server.resourcemanager.scheduler.capacity.CapacityScheduler: Node being looked for scheduling slave2:40331 availableResource: <memory:0, vCores:-1>
2019-06-07 08:11:43,390 DEBUG org.apache.hadoop.yarn.server.resourcemanager.rmapp.attempt.RMAppAttemptImpl: Processing event for appattempt_1559895028500_0001_000001 of type STATUS_UPDATE
2019-06-07 08:11:43,390 DEBUG org.apache.hadoop.yarn.server.resourcemanager.rmapp.attempt.RMAppAttemptImpl: Processing event for appattempt_1559895028500_0001_000001 of type STATUS_UPDATE
2019-06-07 08:11:43,391 DEBUG org.apache.hadoop.yarn.server.resourcemanager.scheduler.capacity.LeafQueue: User limit computation for root in queue default userLimitPercent=100 userLimitFactor=1.0 required: <memory:1024, vCores:1> consumed: <memory:7168, vCores:1> user-limit-resource: <memory:8192, vCores:1> queueCapacity: <memory:8192, vCores:1> qconsumed: <memory:7168, vCores:3> consumedRatio: 0.0 currentCapacity: <memory:8192, vCores:1> activeUsers: 0.0 clusterCapacity: <memory:8192, vCores:2> resourceByLabel: <memory:8192, vCores:2> usageratio: 0.875 Partition:  maxUserLimit=<memory:8192, vCores:1> userWeight=1.0
2019-06-07 08:11:43,391 DEBUG org.apache.hadoop.yarn.server.resourcemanager.scheduler.capacity.LeafQueue: User limit computation for root in queue default userLimitPercent=100 userLimitFactor=1.0 required: <memory:1024, vCores:1> consumed: <memory:7168, vCores:1> user-limit-resource: <memory:8192, vCores:1> queueCapacity: <memory:8192, vCores:1> qconsumed: <memory:7168, vCores:3> consumedRatio: 0.0 currentCapacity: <memory:8192, vCores:1> activeUsers: 0.0 clusterCapacity: <memory:8192, vCores:2> resourceByLabel: <memory:8192, vCores:2> usageratio: 0.875 Partition:  maxUserLimit=<memory:8192, vCores:1> userWeight=1.0
2019-06-07 08:11:43,423 DEBUG org.apache.hadoop.yarn.server.resourcemanager.rmnode.RMNodeImpl: Processing slave1:41069 of type STATUS_UPDATE
2019-06-07 08:11:43,423 DEBUG org.apache.hadoop.yarn.server.resourcemanager.rmnode.RMNodeImpl: Processing slave1:41069 of type STATUS_UPDATE
2019-06-07 08:11:43,424 DEBUG org.apache.hadoop.yarn.server.resourcemanager.scheduler.capacity.CapacityScheduler: nodeUpdate: slave1:41069 clusterResources: <memory:8192, vCores:2>
2019-06-07 08:11:43,424 DEBUG org.apache.hadoop.yarn.server.resourcemanager.scheduler.capacity.CapacityScheduler: nodeUpdate: slave1:41069 clusterResources: <memory:8192, vCores:2>
2019-06-07 08:11:43,425 DEBUG org.apache.hadoop.yarn.server.resourcemanager.scheduler.capacity.CapacityScheduler: Node being looked for scheduling slave1:41069 availableResource: <memory:1024, vCores:0>
2019-06-07 08:11:43,425 DEBUG org.apache.hadoop.yarn.server.resourcemanager.scheduler.capacity.CapacityScheduler: Node being looked for scheduling slave1:41069 availableResource: <memory:1024, vCores:0>
2019-06-07 08:11:43,425 DEBUG org.apache.hadoop.yarn.server.resourcemanager.scheduler.capacity.CapacityScheduler: Trying to schedule on node: slave1, available: <memory:1024, vCores:0>
2019-06-07 08:11:43,425 DEBUG org.apache.hadoop.yarn.server.resourcemanager.scheduler.capacity.CapacityScheduler: Trying to schedule on node: slave1, available: <memory:1024, vCores:0>
2019-06-07 08:11:43,425 DEBUG org.apache.hadoop.yarn.server.resourcemanager.scheduler.capacity.ParentQueue: Skip this queue=root, because it doesn't need more resource, schedulingMode=RESPECT_PARTITION_EXCLUSIVITY node-partition=
2019-06-07 08:11:43,425 DEBUG org.apache.hadoop.yarn.server.resourcemanager.scheduler.capacity.ParentQueue: Skip this queue=root, because it doesn't need more resource, schedulingMode=RESPECT_PARTITION_EXCLUSIVITY node-partition=
2019-06-07 08:11:43,441 DEBUG org.apache.hadoop.yarn.server.resourcemanager.rmnode.RMNodeImpl: Processing slave2:40331 of type STATUS_UPDATE
2019-06-07 08:11:43,441 DEBUG org.apache.hadoop.yarn.server.resourcemanager.rmnode.RMNodeImpl: Processing slave2:40331 of type STATUS_UPDATE
2019-06-07 08:11:43,441 DEBUG org.apache.hadoop.yarn.server.resourcemanager.scheduler.capacity.CapacityScheduler: nodeUpdate: slave2:40331 clusterResources: <memory:8192, vCores:2>
2019-06-07 08:11:43,441 DEBUG org.apache.hadoop.yarn.server.resourcemanager.scheduler.capacity.CapacityScheduler: nodeUpdate: slave2:40331 clusterResources: <memory:8192, vCores:2>
2019-06-07 08:11:43,441 DEBUG org.apache.hadoop.yarn.server.resourcemanager.scheduler.capacity.CapacityScheduler: Node being looked for scheduling slave2:40331 availableResource: <memory:0, vCores:-1>
2019-06-07 08:11:43,441 DEBUG org.apache.hadoop.yarn.server.resourcemanager.scheduler.capacity.CapacityScheduler: Node being looked for scheduling slave2:40331 availableResource: <memory:0, vCores:-1>
2019-06-07 08:11:44,426 DEBUG org.apache.hadoop.yarn.server.resourcemanager.rmnode.RMNodeImpl: Processing slave1:41069 of type STATUS_UPDATE
2019-06-07 08:11:44,426 DEBUG org.apache.hadoop.yarn.server.resourcemanager.rmnode.RMNodeImpl: Processing slave1:41069 of type STATUS_UPDATE
2019-06-07 08:11:44,426 DEBUG org.apache.hadoop.yarn.server.resourcemanager.scheduler.capacity.CapacityScheduler: nodeUpdate: slave1:41069 clusterResources: <memory:8192, vCores:2>
2019-06-07 08:11:44,426 DEBUG org.apache.hadoop.yarn.server.resourcemanager.scheduler.capacity.CapacityScheduler: nodeUpdate: slave1:41069 clusterResources: <memory:8192, vCores:2>
2019-06-07 08:11:44,427 DEBUG org.apache.hadoop.yarn.server.resourcemanager.scheduler.capacity.CapacityScheduler: Node being looked for scheduling slave1:41069 availableResource: <memory:1024, vCores:0>
2019-06-07 08:11:44,427 DEBUG org.apache.hadoop.yarn.server.resourcemanager.scheduler.capacity.CapacityScheduler: Node being looked for scheduling slave1:41069 availableResource: <memory:1024, vCores:0>
2019-06-07 08:11:44,427 DEBUG org.apache.hadoop.yarn.server.resourcemanager.scheduler.capacity.CapacityScheduler: Trying to schedule on node: slave1, available: <memory:1024, vCores:0>
2019-06-07 08:11:44,427 DEBUG org.apache.hadoop.yarn.server.resourcemanager.scheduler.capacity.CapacityScheduler: Trying to schedule on node: slave1, available: <memory:1024, vCores:0>
2019-06-07 08:11:44,427 DEBUG org.apache.hadoop.yarn.server.resourcemanager.scheduler.capacity.ParentQueue: Skip this queue=root, because it doesn't need more resource, schedulingMode=RESPECT_PARTITION_EXCLUSIVITY node-partition=
2019-06-07 08:11:44,427 DEBUG org.apache.hadoop.yarn.server.resourcemanager.scheduler.capacity.ParentQueue: Skip this queue=root, because it doesn't need more resource, schedulingMode=RESPECT_PARTITION_EXCLUSIVITY node-partition=
2019-06-07 08:11:44,444 DEBUG org.apache.hadoop.yarn.server.resourcemanager.rmnode.RMNodeImpl: Processing slave2:40331 of type STATUS_UPDATE
2019-06-07 08:11:44,444 DEBUG org.apache.hadoop.yarn.server.resourcemanager.rmnode.RMNodeImpl: Processing slave2:40331 of type STATUS_UPDATE
2019-06-07 08:11:44,444 DEBUG org.apache.hadoop.yarn.server.resourcemanager.scheduler.capacity.CapacityScheduler: nodeUpdate: slave2:40331 clusterResources: <memory:8192, vCores:2>
2019-06-07 08:11:44,444 DEBUG org.apache.hadoop.yarn.server.resourcemanager.scheduler.capacity.CapacityScheduler: nodeUpdate: slave2:40331 clusterResources: <memory:8192, vCores:2>
2019-06-07 08:11:44,444 DEBUG org.apache.hadoop.yarn.server.resourcemanager.scheduler.capacity.CapacityScheduler: Node being looked for scheduling slave2:40331 availableResource: <memory:0, vCores:-1>
2019-06-07 08:11:44,444 DEBUG org.apache.hadoop.yarn.server.resourcemanager.scheduler.capacity.CapacityScheduler: Node being looked for scheduling slave2:40331 availableResource: <memory:0, vCores:-1>
2019-06-07 08:11:45,432 DEBUG org.apache.hadoop.yarn.server.resourcemanager.rmnode.RMNodeImpl: Processing slave1:41069 of type STATUS_UPDATE
2019-06-07 08:11:45,432 DEBUG org.apache.hadoop.yarn.server.resourcemanager.rmnode.RMNodeImpl: Processing slave1:41069 of type STATUS_UPDATE
2019-06-07 08:11:45,432 DEBUG org.apache.hadoop.yarn.server.resourcemanager.scheduler.capacity.CapacityScheduler: nodeUpdate: slave1:41069 clusterResources: <memory:8192, vCores:2>
2019-06-07 08:11:45,432 DEBUG org.apache.hadoop.yarn.server.resourcemanager.scheduler.capacity.CapacityScheduler: nodeUpdate: slave1:41069 clusterResources: <memory:8192, vCores:2>
2019-06-07 08:11:45,432 DEBUG org.apache.hadoop.yarn.server.resourcemanager.scheduler.capacity.CapacityScheduler: Node being looked for scheduling slave1:41069 availableResource: <memory:1024, vCores:0>
2019-06-07 08:11:45,432 DEBUG org.apache.hadoop.yarn.server.resourcemanager.scheduler.capacity.CapacityScheduler: Node being looked for scheduling slave1:41069 availableResource: <memory:1024, vCores:0>
2019-06-07 08:11:45,432 DEBUG org.apache.hadoop.yarn.server.resourcemanager.scheduler.capacity.CapacityScheduler: Trying to schedule on node: slave1, available: <memory:1024, vCores:0>
2019-06-07 08:11:45,432 DEBUG org.apache.hadoop.yarn.server.resourcemanager.scheduler.capacity.CapacityScheduler: Trying to schedule on node: slave1, available: <memory:1024, vCores:0>
2019-06-07 08:11:45,432 DEBUG org.apache.hadoop.yarn.server.resourcemanager.scheduler.capacity.ParentQueue: Skip this queue=root, because it doesn't need more resource, schedulingMode=RESPECT_PARTITION_EXCLUSIVITY node-partition=
2019-06-07 08:11:45,432 DEBUG org.apache.hadoop.yarn.server.resourcemanager.scheduler.capacity.ParentQueue: Skip this queue=root, because it doesn't need more resource, schedulingMode=RESPECT_PARTITION_EXCLUSIVITY node-partition=
2019-06-07 08:11:45,450 DEBUG org.apache.hadoop.yarn.server.resourcemanager.rmnode.RMNodeImpl: Processing slave2:40331 of type STATUS_UPDATE
2019-06-07 08:11:45,450 DEBUG org.apache.hadoop.yarn.server.resourcemanager.rmnode.RMNodeImpl: Processing slave2:40331 of type STATUS_UPDATE
2019-06-07 08:11:45,451 DEBUG org.apache.hadoop.yarn.server.resourcemanager.scheduler.capacity.CapacityScheduler: nodeUpdate: slave2:40331 clusterResources: <memory:8192, vCores:2>
2019-06-07 08:11:45,451 DEBUG org.apache.hadoop.yarn.server.resourcemanager.scheduler.capacity.CapacityScheduler: nodeUpdate: slave2:40331 clusterResources: <memory:8192, vCores:2>
2019-06-07 08:11:45,451 DEBUG org.apache.hadoop.yarn.server.resourcemanager.scheduler.capacity.CapacityScheduler: Node being looked for scheduling slave2:40331 availableResource: <memory:0, vCores:-1>
2019-06-07 08:11:45,451 DEBUG org.apache.hadoop.yarn.server.resourcemanager.scheduler.capacity.CapacityScheduler: Node being looked for scheduling slave2:40331 availableResource: <memory:0, vCores:-1>
2019-06-07 08:11:46,398 DEBUG org.apache.hadoop.yarn.server.resourcemanager.scheduler.capacity.LeafQueue: User limit computation for root in queue default userLimitPercent=100 userLimitFactor=1.0 required: <memory:1024, vCores:1> consumed: <memory:7168, vCores:1> user-limit-resource: <memory:8192, vCores:1> queueCapacity: <memory:8192, vCores:1> qconsumed: <memory:7168, vCores:3> consumedRatio: 0.0 currentCapacity: <memory:8192, vCores:1> activeUsers: 0.0 clusterCapacity: <memory:8192, vCores:2> resourceByLabel: <memory:8192, vCores:2> usageratio: 0.875 Partition:  maxUserLimit=<memory:8192, vCores:1> userWeight=1.0
2019-06-07 08:11:46,398 DEBUG org.apache.hadoop.yarn.server.resourcemanager.scheduler.capacity.LeafQueue: User limit computation for root in queue default userLimitPercent=100 userLimitFactor=1.0 required: <memory:1024, vCores:1> consumed: <memory:7168, vCores:1> user-limit-resource: <memory:8192, vCores:1> queueCapacity: <memory:8192, vCores:1> qconsumed: <memory:7168, vCores:3> consumedRatio: 0.0 currentCapacity: <memory:8192, vCores:1> activeUsers: 0.0 clusterCapacity: <memory:8192, vCores:2> resourceByLabel: <memory:8192, vCores:2> usageratio: 0.875 Partition:  maxUserLimit=<memory:8192, vCores:1> userWeight=1.0
2019-06-07 08:11:46,405 DEBUG org.apache.hadoop.yarn.server.resourcemanager.rmapp.attempt.RMAppAttemptImpl: Processing event for appattempt_1559895028500_0001_000001 of type STATUS_UPDATE
2019-06-07 08:11:46,405 DEBUG org.apache.hadoop.yarn.server.resourcemanager.rmapp.attempt.RMAppAttemptImpl: Processing event for appattempt_1559895028500_0001_000001 of type STATUS_UPDATE
2019-06-07 08:11:46,432 DEBUG org.apache.hadoop.yarn.server.resourcemanager.rmnode.RMNodeImpl: Processing slave1:41069 of type STATUS_UPDATE
2019-06-07 08:11:46,432 DEBUG org.apache.hadoop.yarn.server.resourcemanager.rmnode.RMNodeImpl: Processing slave1:41069 of type STATUS_UPDATE
2019-06-07 08:11:46,432 DEBUG org.apache.hadoop.yarn.server.resourcemanager.scheduler.capacity.CapacityScheduler: nodeUpdate: slave1:41069 clusterResources: <memory:8192, vCores:2>
2019-06-07 08:11:46,432 DEBUG org.apache.hadoop.yarn.server.resourcemanager.scheduler.capacity.CapacityScheduler: nodeUpdate: slave1:41069 clusterResources: <memory:8192, vCores:2>
2019-06-07 08:11:46,435 DEBUG org.apache.hadoop.yarn.server.resourcemanager.scheduler.capacity.CapacityScheduler: Node being looked for scheduling slave1:41069 availableResource: <memory:1024, vCores:0>
2019-06-07 08:11:46,435 DEBUG org.apache.hadoop.yarn.server.resourcemanager.scheduler.capacity.CapacityScheduler: Node being looked for scheduling slave1:41069 availableResource: <memory:1024, vCores:0>
2019-06-07 08:11:46,435 DEBUG org.apache.hadoop.yarn.server.resourcemanager.scheduler.capacity.CapacityScheduler: Trying to schedule on node: slave1, available: <memory:1024, vCores:0>
2019-06-07 08:11:46,435 DEBUG org.apache.hadoop.yarn.server.resourcemanager.scheduler.capacity.CapacityScheduler: Trying to schedule on node: slave1, available: <memory:1024, vCores:0>
2019-06-07 08:11:46,435 DEBUG org.apache.hadoop.yarn.server.resourcemanager.scheduler.capacity.ParentQueue: Skip this queue=root, because it doesn't need more resource, schedulingMode=RESPECT_PARTITION_EXCLUSIVITY node-partition=
2019-06-07 08:11:46,435 DEBUG org.apache.hadoop.yarn.server.resourcemanager.scheduler.capacity.ParentQueue: Skip this queue=root, because it doesn't need more resource, schedulingMode=RESPECT_PARTITION_EXCLUSIVITY node-partition=
2019-06-07 08:11:46,453 DEBUG org.apache.hadoop.yarn.server.resourcemanager.rmnode.RMNodeImpl: Processing slave2:40331 of type STATUS_UPDATE
2019-06-07 08:11:46,453 DEBUG org.apache.hadoop.yarn.server.resourcemanager.rmnode.RMNodeImpl: Processing slave2:40331 of type STATUS_UPDATE
2019-06-07 08:11:46,458 DEBUG org.apache.hadoop.yarn.server.resourcemanager.scheduler.capacity.CapacityScheduler: nodeUpdate: slave2:40331 clusterResources: <memory:8192, vCores:2>
2019-06-07 08:11:46,458 DEBUG org.apache.hadoop.yarn.server.resourcemanager.scheduler.capacity.CapacityScheduler: nodeUpdate: slave2:40331 clusterResources: <memory:8192, vCores:2>
2019-06-07 08:11:46,458 DEBUG org.apache.hadoop.yarn.server.resourcemanager.scheduler.capacity.CapacityScheduler: Node being looked for scheduling slave2:40331 availableResource: <memory:0, vCores:-1>
2019-06-07 08:11:46,458 DEBUG org.apache.hadoop.yarn.server.resourcemanager.scheduler.capacity.CapacityScheduler: Node being looked for scheduling slave2:40331 availableResource: <memory:0, vCores:-1>
2019-06-07 08:11:47,433 DEBUG org.apache.hadoop.yarn.server.resourcemanager.rmnode.RMNodeImpl: Processing slave1:41069 of type STATUS_UPDATE
2019-06-07 08:11:47,433 DEBUG org.apache.hadoop.yarn.server.resourcemanager.rmnode.RMNodeImpl: Processing slave1:41069 of type STATUS_UPDATE
2019-06-07 08:11:47,434 DEBUG org.apache.hadoop.yarn.server.resourcemanager.scheduler.capacity.CapacityScheduler: nodeUpdate: slave1:41069 clusterResources: <memory:8192, vCores:2>
2019-06-07 08:11:47,434 DEBUG org.apache.hadoop.yarn.server.resourcemanager.scheduler.capacity.CapacityScheduler: nodeUpdate: slave1:41069 clusterResources: <memory:8192, vCores:2>
2019-06-07 08:11:47,434 DEBUG org.apache.hadoop.yarn.server.resourcemanager.scheduler.capacity.CapacityScheduler: Node being looked for scheduling slave1:41069 availableResource: <memory:1024, vCores:0>
2019-06-07 08:11:47,434 DEBUG org.apache.hadoop.yarn.server.resourcemanager.scheduler.capacity.CapacityScheduler: Node being looked for scheduling slave1:41069 availableResource: <memory:1024, vCores:0>
2019-06-07 08:11:47,434 DEBUG org.apache.hadoop.yarn.server.resourcemanager.scheduler.capacity.CapacityScheduler: Trying to schedule on node: slave1, available: <memory:1024, vCores:0>
2019-06-07 08:11:47,434 DEBUG org.apache.hadoop.yarn.server.resourcemanager.scheduler.capacity.CapacityScheduler: Trying to schedule on node: slave1, available: <memory:1024, vCores:0>
2019-06-07 08:11:47,434 DEBUG org.apache.hadoop.yarn.server.resourcemanager.scheduler.capacity.ParentQueue: Skip this queue=root, because it doesn't need more resource, schedulingMode=RESPECT_PARTITION_EXCLUSIVITY node-partition=
2019-06-07 08:11:47,434 DEBUG org.apache.hadoop.yarn.server.resourcemanager.scheduler.capacity.ParentQueue: Skip this queue=root, because it doesn't need more resource, schedulingMode=RESPECT_PARTITION_EXCLUSIVITY node-partition=
2019-06-07 08:11:47,454 DEBUG org.apache.hadoop.yarn.server.resourcemanager.rmnode.RMNodeImpl: Processing slave2:40331 of type STATUS_UPDATE
2019-06-07 08:11:47,454 DEBUG org.apache.hadoop.yarn.server.resourcemanager.rmnode.RMNodeImpl: Processing slave2:40331 of type STATUS_UPDATE
2019-06-07 08:11:47,455 DEBUG org.apache.hadoop.yarn.server.resourcemanager.scheduler.capacity.CapacityScheduler: nodeUpdate: slave2:40331 clusterResources: <memory:8192, vCores:2>
2019-06-07 08:11:47,455 DEBUG org.apache.hadoop.yarn.server.resourcemanager.scheduler.capacity.CapacityScheduler: nodeUpdate: slave2:40331 clusterResources: <memory:8192, vCores:2>
2019-06-07 08:11:47,455 DEBUG org.apache.hadoop.yarn.server.resourcemanager.scheduler.capacity.CapacityScheduler: Node being looked for scheduling slave2:40331 availableResource: <memory:0, vCores:-1>
2019-06-07 08:11:47,455 DEBUG org.apache.hadoop.yarn.server.resourcemanager.scheduler.capacity.CapacityScheduler: Node being looked for scheduling slave2:40331 availableResource: <memory:0, vCores:-1>
2019-06-07 08:11:48,436 DEBUG org.apache.hadoop.yarn.server.resourcemanager.rmnode.RMNodeImpl: Processing slave1:41069 of type STATUS_UPDATE
2019-06-07 08:11:48,436 DEBUG org.apache.hadoop.yarn.server.resourcemanager.rmnode.RMNodeImpl: Processing slave1:41069 of type STATUS_UPDATE
2019-06-07 08:11:48,437 DEBUG org.apache.hadoop.yarn.server.resourcemanager.scheduler.capacity.CapacityScheduler: nodeUpdate: slave1:41069 clusterResources: <memory:8192, vCores:2>
2019-06-07 08:11:48,437 DEBUG org.apache.hadoop.yarn.server.resourcemanager.scheduler.capacity.CapacityScheduler: nodeUpdate: slave1:41069 clusterResources: <memory:8192, vCores:2>
2019-06-07 08:11:48,437 DEBUG org.apache.hadoop.yarn.server.resourcemanager.scheduler.capacity.CapacityScheduler: Node being looked for scheduling slave1:41069 availableResource: <memory:1024, vCores:0>
2019-06-07 08:11:48,437 DEBUG org.apache.hadoop.yarn.server.resourcemanager.scheduler.capacity.CapacityScheduler: Node being looked for scheduling slave1:41069 availableResource: <memory:1024, vCores:0>
2019-06-07 08:11:48,437 DEBUG org.apache.hadoop.yarn.server.resourcemanager.scheduler.capacity.CapacityScheduler: Trying to schedule on node: slave1, available: <memory:1024, vCores:0>
2019-06-07 08:11:48,437 DEBUG org.apache.hadoop.yarn.server.resourcemanager.scheduler.capacity.CapacityScheduler: Trying to schedule on node: slave1, available: <memory:1024, vCores:0>
2019-06-07 08:11:48,437 DEBUG org.apache.hadoop.yarn.server.resourcemanager.scheduler.capacity.ParentQueue: Skip this queue=root, because it doesn't need more resource, schedulingMode=RESPECT_PARTITION_EXCLUSIVITY node-partition=
2019-06-07 08:11:48,437 DEBUG org.apache.hadoop.yarn.server.resourcemanager.scheduler.capacity.ParentQueue: Skip this queue=root, because it doesn't need more resource, schedulingMode=RESPECT_PARTITION_EXCLUSIVITY node-partition=
2019-06-07 08:11:48,458 DEBUG org.apache.hadoop.yarn.server.resourcemanager.rmnode.RMNodeImpl: Processing slave2:40331 of type STATUS_UPDATE
2019-06-07 08:11:48,458 DEBUG org.apache.hadoop.yarn.server.resourcemanager.rmnode.RMNodeImpl: Processing slave2:40331 of type STATUS_UPDATE
2019-06-07 08:11:48,458 DEBUG org.apache.hadoop.yarn.server.resourcemanager.scheduler.capacity.CapacityScheduler: nodeUpdate: slave2:40331 clusterResources: <memory:8192, vCores:2>
2019-06-07 08:11:48,458 DEBUG org.apache.hadoop.yarn.server.resourcemanager.scheduler.capacity.CapacityScheduler: nodeUpdate: slave2:40331 clusterResources: <memory:8192, vCores:2>
2019-06-07 08:11:48,458 DEBUG org.apache.hadoop.yarn.server.resourcemanager.scheduler.capacity.CapacityScheduler: Node being looked for scheduling slave2:40331 availableResource: <memory:0, vCores:-1>
2019-06-07 08:11:48,458 DEBUG org.apache.hadoop.yarn.server.resourcemanager.scheduler.capacity.CapacityScheduler: Node being looked for scheduling slave2:40331 availableResource: <memory:0, vCores:-1>
2019-06-07 08:11:49,404 DEBUG org.apache.hadoop.yarn.server.resourcemanager.rmapp.attempt.RMAppAttemptImpl: Processing event for appattempt_1559895028500_0001_000001 of type STATUS_UPDATE
2019-06-07 08:11:49,404 DEBUG org.apache.hadoop.yarn.server.resourcemanager.rmapp.attempt.RMAppAttemptImpl: Processing event for appattempt_1559895028500_0001_000001 of type STATUS_UPDATE
2019-06-07 08:11:49,405 DEBUG org.apache.hadoop.yarn.server.resourcemanager.scheduler.capacity.LeafQueue: User limit computation for root in queue default userLimitPercent=100 userLimitFactor=1.0 required: <memory:1024, vCores:1> consumed: <memory:7168, vCores:1> user-limit-resource: <memory:8192, vCores:1> queueCapacity: <memory:8192, vCores:1> qconsumed: <memory:7168, vCores:3> consumedRatio: 0.0 currentCapacity: <memory:8192, vCores:1> activeUsers: 0.0 clusterCapacity: <memory:8192, vCores:2> resourceByLabel: <memory:8192, vCores:2> usageratio: 0.875 Partition:  maxUserLimit=<memory:8192, vCores:1> userWeight=1.0
2019-06-07 08:11:49,405 DEBUG org.apache.hadoop.yarn.server.resourcemanager.scheduler.capacity.LeafQueue: User limit computation for root in queue default userLimitPercent=100 userLimitFactor=1.0 required: <memory:1024, vCores:1> consumed: <memory:7168, vCores:1> user-limit-resource: <memory:8192, vCores:1> queueCapacity: <memory:8192, vCores:1> qconsumed: <memory:7168, vCores:3> consumedRatio: 0.0 currentCapacity: <memory:8192, vCores:1> activeUsers: 0.0 clusterCapacity: <memory:8192, vCores:2> resourceByLabel: <memory:8192, vCores:2> usageratio: 0.875 Partition:  maxUserLimit=<memory:8192, vCores:1> userWeight=1.0
2019-06-07 08:11:49,441 DEBUG org.apache.hadoop.yarn.server.resourcemanager.rmnode.RMNodeImpl: Processing slave1:41069 of type STATUS_UPDATE
2019-06-07 08:11:49,441 DEBUG org.apache.hadoop.yarn.server.resourcemanager.rmnode.RMNodeImpl: Processing slave1:41069 of type STATUS_UPDATE
2019-06-07 08:11:49,442 DEBUG org.apache.hadoop.yarn.server.resourcemanager.scheduler.capacity.CapacityScheduler: nodeUpdate: slave1:41069 clusterResources: <memory:8192, vCores:2>
2019-06-07 08:11:49,442 DEBUG org.apache.hadoop.yarn.server.resourcemanager.scheduler.capacity.CapacityScheduler: nodeUpdate: slave1:41069 clusterResources: <memory:8192, vCores:2>
2019-06-07 08:11:49,444 DEBUG org.apache.hadoop.yarn.server.resourcemanager.scheduler.capacity.CapacityScheduler: Node being looked for scheduling slave1:41069 availableResource: <memory:1024, vCores:0>
2019-06-07 08:11:49,444 DEBUG org.apache.hadoop.yarn.server.resourcemanager.scheduler.capacity.CapacityScheduler: Node being looked for scheduling slave1:41069 availableResource: <memory:1024, vCores:0>
2019-06-07 08:11:49,444 DEBUG org.apache.hadoop.yarn.server.resourcemanager.scheduler.capacity.CapacityScheduler: Trying to schedule on node: slave1, available: <memory:1024, vCores:0>
2019-06-07 08:11:49,444 DEBUG org.apache.hadoop.yarn.server.resourcemanager.scheduler.capacity.CapacityScheduler: Trying to schedule on node: slave1, available: <memory:1024, vCores:0>
2019-06-07 08:11:49,444 DEBUG org.apache.hadoop.yarn.server.resourcemanager.scheduler.capacity.ParentQueue: Skip this queue=root, because it doesn't need more resource, schedulingMode=RESPECT_PARTITION_EXCLUSIVITY node-partition=
2019-06-07 08:11:49,444 DEBUG org.apache.hadoop.yarn.server.resourcemanager.scheduler.capacity.ParentQueue: Skip this queue=root, because it doesn't need more resource, schedulingMode=RESPECT_PARTITION_EXCLUSIVITY node-partition=
2019-06-07 08:11:49,461 DEBUG org.apache.hadoop.yarn.server.resourcemanager.rmnode.RMNodeImpl: Processing slave2:40331 of type STATUS_UPDATE
2019-06-07 08:11:49,461 DEBUG org.apache.hadoop.yarn.server.resourcemanager.rmnode.RMNodeImpl: Processing slave2:40331 of type STATUS_UPDATE
2019-06-07 08:11:49,461 DEBUG org.apache.hadoop.yarn.server.resourcemanager.scheduler.capacity.CapacityScheduler: nodeUpdate: slave2:40331 clusterResources: <memory:8192, vCores:2>
2019-06-07 08:11:49,461 DEBUG org.apache.hadoop.yarn.server.resourcemanager.scheduler.capacity.CapacityScheduler: nodeUpdate: slave2:40331 clusterResources: <memory:8192, vCores:2>
2019-06-07 08:11:49,461 DEBUG org.apache.hadoop.yarn.server.resourcemanager.scheduler.capacity.CapacityScheduler: Node being looked for scheduling slave2:40331 availableResource: <memory:0, vCores:-1>
2019-06-07 08:11:49,461 DEBUG org.apache.hadoop.yarn.server.resourcemanager.scheduler.capacity.CapacityScheduler: Node being looked for scheduling slave2:40331 availableResource: <memory:0, vCores:-1>
2019-06-07 08:11:50,445 DEBUG org.apache.hadoop.yarn.server.resourcemanager.rmnode.RMNodeImpl: Processing slave1:41069 of type STATUS_UPDATE
2019-06-07 08:11:50,445 DEBUG org.apache.hadoop.yarn.server.resourcemanager.rmnode.RMNodeImpl: Processing slave1:41069 of type STATUS_UPDATE
2019-06-07 08:11:50,445 DEBUG org.apache.hadoop.yarn.server.resourcemanager.scheduler.capacity.CapacityScheduler: nodeUpdate: slave1:41069 clusterResources: <memory:8192, vCores:2>
2019-06-07 08:11:50,445 DEBUG org.apache.hadoop.yarn.server.resourcemanager.scheduler.capacity.CapacityScheduler: nodeUpdate: slave1:41069 clusterResources: <memory:8192, vCores:2>
2019-06-07 08:11:50,445 DEBUG org.apache.hadoop.yarn.server.resourcemanager.scheduler.capacity.CapacityScheduler: Node being looked for scheduling slave1:41069 availableResource: <memory:1024, vCores:0>
2019-06-07 08:11:50,445 DEBUG org.apache.hadoop.yarn.server.resourcemanager.scheduler.capacity.CapacityScheduler: Node being looked for scheduling slave1:41069 availableResource: <memory:1024, vCores:0>
2019-06-07 08:11:50,445 DEBUG org.apache.hadoop.yarn.server.resourcemanager.scheduler.capacity.CapacityScheduler: Trying to schedule on node: slave1, available: <memory:1024, vCores:0>
2019-06-07 08:11:50,445 DEBUG org.apache.hadoop.yarn.server.resourcemanager.scheduler.capacity.CapacityScheduler: Trying to schedule on node: slave1, available: <memory:1024, vCores:0>
2019-06-07 08:11:50,445 DEBUG org.apache.hadoop.yarn.server.resourcemanager.scheduler.capacity.ParentQueue: Skip this queue=root, because it doesn't need more resource, schedulingMode=RESPECT_PARTITION_EXCLUSIVITY node-partition=
2019-06-07 08:11:50,445 DEBUG org.apache.hadoop.yarn.server.resourcemanager.scheduler.capacity.ParentQueue: Skip this queue=root, because it doesn't need more resource, schedulingMode=RESPECT_PARTITION_EXCLUSIVITY node-partition=
2019-06-07 08:11:50,464 DEBUG org.apache.hadoop.yarn.server.resourcemanager.rmnode.RMNodeImpl: Processing slave2:40331 of type STATUS_UPDATE
2019-06-07 08:11:50,464 DEBUG org.apache.hadoop.yarn.server.resourcemanager.rmnode.RMNodeImpl: Processing slave2:40331 of type STATUS_UPDATE
2019-06-07 08:11:50,465 DEBUG org.apache.hadoop.yarn.server.resourcemanager.scheduler.capacity.CapacityScheduler: nodeUpdate: slave2:40331 clusterResources: <memory:8192, vCores:2>
2019-06-07 08:11:50,465 DEBUG org.apache.hadoop.yarn.server.resourcemanager.scheduler.capacity.CapacityScheduler: nodeUpdate: slave2:40331 clusterResources: <memory:8192, vCores:2>
2019-06-07 08:11:50,465 DEBUG org.apache.hadoop.yarn.server.resourcemanager.scheduler.capacity.CapacityScheduler: Node being looked for scheduling slave2:40331 availableResource: <memory:0, vCores:-1>
2019-06-07 08:11:50,465 DEBUG org.apache.hadoop.yarn.server.resourcemanager.scheduler.capacity.CapacityScheduler: Node being looked for scheduling slave2:40331 availableResource: <memory:0, vCores:-1>
2019-06-07 08:11:51,448 DEBUG org.apache.hadoop.yarn.server.resourcemanager.rmnode.RMNodeImpl: Processing slave1:41069 of type STATUS_UPDATE
2019-06-07 08:11:51,448 DEBUG org.apache.hadoop.yarn.server.resourcemanager.rmnode.RMNodeImpl: Processing slave1:41069 of type STATUS_UPDATE
2019-06-07 08:11:51,448 DEBUG org.apache.hadoop.yarn.server.resourcemanager.scheduler.capacity.CapacityScheduler: nodeUpdate: slave1:41069 clusterResources: <memory:8192, vCores:2>
2019-06-07 08:11:51,448 DEBUG org.apache.hadoop.yarn.server.resourcemanager.scheduler.capacity.CapacityScheduler: nodeUpdate: slave1:41069 clusterResources: <memory:8192, vCores:2>
2019-06-07 08:11:51,448 DEBUG org.apache.hadoop.yarn.server.resourcemanager.scheduler.capacity.CapacityScheduler: Node being looked for scheduling slave1:41069 availableResource: <memory:1024, vCores:0>
2019-06-07 08:11:51,448 DEBUG org.apache.hadoop.yarn.server.resourcemanager.scheduler.capacity.CapacityScheduler: Node being looked for scheduling slave1:41069 availableResource: <memory:1024, vCores:0>
2019-06-07 08:11:51,449 DEBUG org.apache.hadoop.yarn.server.resourcemanager.scheduler.capacity.CapacityScheduler: Trying to schedule on node: slave1, available: <memory:1024, vCores:0>
2019-06-07 08:11:51,449 DEBUG org.apache.hadoop.yarn.server.resourcemanager.scheduler.capacity.CapacityScheduler: Trying to schedule on node: slave1, available: <memory:1024, vCores:0>
2019-06-07 08:11:51,449 DEBUG org.apache.hadoop.yarn.server.resourcemanager.scheduler.capacity.ParentQueue: Skip this queue=root, because it doesn't need more resource, schedulingMode=RESPECT_PARTITION_EXCLUSIVITY node-partition=
2019-06-07 08:11:51,449 DEBUG org.apache.hadoop.yarn.server.resourcemanager.scheduler.capacity.ParentQueue: Skip this queue=root, because it doesn't need more resource, schedulingMode=RESPECT_PARTITION_EXCLUSIVITY node-partition=
2019-06-07 08:11:51,470 DEBUG org.apache.hadoop.yarn.server.resourcemanager.rmnode.RMNodeImpl: Processing slave2:40331 of type STATUS_UPDATE
2019-06-07 08:11:51,470 DEBUG org.apache.hadoop.yarn.server.resourcemanager.rmnode.RMNodeImpl: Processing slave2:40331 of type STATUS_UPDATE
2019-06-07 08:11:51,471 DEBUG org.apache.hadoop.yarn.server.resourcemanager.scheduler.capacity.CapacityScheduler: nodeUpdate: slave2:40331 clusterResources: <memory:8192, vCores:2>
2019-06-07 08:11:51,471 DEBUG org.apache.hadoop.yarn.server.resourcemanager.scheduler.capacity.CapacityScheduler: nodeUpdate: slave2:40331 clusterResources: <memory:8192, vCores:2>
2019-06-07 08:11:51,471 DEBUG org.apache.hadoop.yarn.server.resourcemanager.scheduler.capacity.CapacityScheduler: Node being looked for scheduling slave2:40331 availableResource: <memory:0, vCores:-1>
2019-06-07 08:11:51,471 DEBUG org.apache.hadoop.yarn.server.resourcemanager.scheduler.capacity.CapacityScheduler: Node being looked for scheduling slave2:40331 availableResource: <memory:0, vCores:-1>
2019-06-07 08:11:52,413 DEBUG org.apache.hadoop.yarn.server.resourcemanager.scheduler.capacity.LeafQueue: User limit computation for root in queue default userLimitPercent=100 userLimitFactor=1.0 required: <memory:1024, vCores:1> consumed: <memory:7168, vCores:1> user-limit-resource: <memory:8192, vCores:1> queueCapacity: <memory:8192, vCores:1> qconsumed: <memory:7168, vCores:3> consumedRatio: 0.0 currentCapacity: <memory:8192, vCores:1> activeUsers: 0.0 clusterCapacity: <memory:8192, vCores:2> resourceByLabel: <memory:8192, vCores:2> usageratio: 0.875 Partition:  maxUserLimit=<memory:8192, vCores:1> userWeight=1.0
2019-06-07 08:11:52,413 DEBUG org.apache.hadoop.yarn.server.resourcemanager.scheduler.capacity.LeafQueue: User limit computation for root in queue default userLimitPercent=100 userLimitFactor=1.0 required: <memory:1024, vCores:1> consumed: <memory:7168, vCores:1> user-limit-resource: <memory:8192, vCores:1> queueCapacity: <memory:8192, vCores:1> qconsumed: <memory:7168, vCores:3> consumedRatio: 0.0 currentCapacity: <memory:8192, vCores:1> activeUsers: 0.0 clusterCapacity: <memory:8192, vCores:2> resourceByLabel: <memory:8192, vCores:2> usageratio: 0.875 Partition:  maxUserLimit=<memory:8192, vCores:1> userWeight=1.0
2019-06-07 08:11:52,414 DEBUG org.apache.hadoop.yarn.server.resourcemanager.rmapp.attempt.RMAppAttemptImpl: Processing event for appattempt_1559895028500_0001_000001 of type STATUS_UPDATE
2019-06-07 08:11:52,414 DEBUG org.apache.hadoop.yarn.server.resourcemanager.rmapp.attempt.RMAppAttemptImpl: Processing event for appattempt_1559895028500_0001_000001 of type STATUS_UPDATE
2019-06-07 08:11:52,453 DEBUG org.apache.hadoop.yarn.server.resourcemanager.rmnode.RMNodeImpl: Processing slave1:41069 of type STATUS_UPDATE
2019-06-07 08:11:52,453 DEBUG org.apache.hadoop.yarn.server.resourcemanager.rmnode.RMNodeImpl: Processing slave1:41069 of type STATUS_UPDATE
2019-06-07 08:11:52,454 DEBUG org.apache.hadoop.yarn.server.resourcemanager.scheduler.capacity.CapacityScheduler: nodeUpdate: slave1:41069 clusterResources: <memory:8192, vCores:2>
2019-06-07 08:11:52,454 DEBUG org.apache.hadoop.yarn.server.resourcemanager.scheduler.capacity.CapacityScheduler: nodeUpdate: slave1:41069 clusterResources: <memory:8192, vCores:2>
2019-06-07 08:11:52,455 DEBUG org.apache.hadoop.yarn.server.resourcemanager.scheduler.capacity.CapacityScheduler: Node being looked for scheduling slave1:41069 availableResource: <memory:1024, vCores:0>
2019-06-07 08:11:52,455 DEBUG org.apache.hadoop.yarn.server.resourcemanager.scheduler.capacity.CapacityScheduler: Node being looked for scheduling slave1:41069 availableResource: <memory:1024, vCores:0>
2019-06-07 08:11:52,455 DEBUG org.apache.hadoop.yarn.server.resourcemanager.scheduler.capacity.CapacityScheduler: Trying to schedule on node: slave1, available: <memory:1024, vCores:0>
2019-06-07 08:11:52,455 DEBUG org.apache.hadoop.yarn.server.resourcemanager.scheduler.capacity.CapacityScheduler: Trying to schedule on node: slave1, available: <memory:1024, vCores:0>
2019-06-07 08:11:52,455 DEBUG org.apache.hadoop.yarn.server.resourcemanager.scheduler.capacity.ParentQueue: Skip this queue=root, because it doesn't need more resource, schedulingMode=RESPECT_PARTITION_EXCLUSIVITY node-partition=
2019-06-07 08:11:52,455 DEBUG org.apache.hadoop.yarn.server.resourcemanager.scheduler.capacity.ParentQueue: Skip this queue=root, because it doesn't need more resource, schedulingMode=RESPECT_PARTITION_EXCLUSIVITY node-partition=
2019-06-07 08:11:52,474 DEBUG org.apache.hadoop.yarn.server.resourcemanager.rmnode.RMNodeImpl: Processing slave2:40331 of type STATUS_UPDATE
2019-06-07 08:11:52,474 DEBUG org.apache.hadoop.yarn.server.resourcemanager.rmnode.RMNodeImpl: Processing slave2:40331 of type STATUS_UPDATE
2019-06-07 08:11:52,475 DEBUG org.apache.hadoop.yarn.server.resourcemanager.scheduler.capacity.CapacityScheduler: nodeUpdate: slave2:40331 clusterResources: <memory:8192, vCores:2>
