2019-06-07 07:57:19,828 INFO org.apache.hadoop.yarn.server.resourcemanager.ResourceManager: STARTUP_MSG: 
/************************************************************
STARTUP_MSG: Starting ResourceManager
STARTUP_MSG:   user = root
STARTUP_MSG:   host = master/172.17.0.2
STARTUP_MSG:   args = []
STARTUP_MSG:   version = 2.8.5
STARTUP_MSG:   build = https://git-wip-us.apache.org/repos/asf/hadoop.git -r 0b8464d75227fcee2c6e7f2410377b3d53d3d5f8; compiled by 'jdu' on 2018-09-10T03:32Z
STARTUP_MSG:   java = 1.8.0_191
************************************************************/
2019-06-07 07:57:19,828 INFO org.apache.hadoop.yarn.server.resourcemanager.ResourceManager: STARTUP_MSG: 
/************************************************************
STARTUP_MSG: Starting ResourceManager
STARTUP_MSG:   user = root
STARTUP_MSG:   host = master/172.17.0.2
STARTUP_MSG:   args = []
STARTUP_MSG:   version = 2.8.5
STARTUP_MSG:   build = https://git-wip-us.apache.org/repos/asf/hadoop.git -r 0b8464d75227fcee2c6e7f2410377b3d53d3d5f8; compiled by 'jdu' on 2018-09-10T03:32Z
STARTUP_MSG:   java = 1.8.0_191
************************************************************/
2019-06-07 07:57:19,836 INFO org.apache.hadoop.yarn.server.resourcemanager.ResourceManager: registered UNIX signal handlers for [TERM, HUP, INT]
2019-06-07 07:57:19,836 INFO org.apache.hadoop.yarn.server.resourcemanager.ResourceManager: registered UNIX signal handlers for [TERM, HUP, INT]
2019-06-07 07:57:20,147 INFO org.apache.hadoop.conf.Configuration: found resource core-site.xml at file:/hadoop-2.8.5/etc/hadoop/core-site.xml
2019-06-07 07:57:20,264 WARN org.apache.hadoop.conf.Configuration: core-site.xml:an attempt to override final parameter: fs.defaultFS;  Ignoring.
2019-06-07 07:57:20,284 INFO org.apache.hadoop.security.Groups: clearing userToGroupsMap cache
2019-06-07 07:57:20,351 INFO org.apache.hadoop.conf.Configuration: found resource yarn-site.xml at file:/hadoop-2.8.5/etc/hadoop/yarn-site.xml
2019-06-07 07:57:20,580 INFO org.apache.hadoop.yarn.event.AsyncDispatcher: Registering class org.apache.hadoop.yarn.server.resourcemanager.RMFatalEventType for class org.apache.hadoop.yarn.server.resourcemanager.ResourceManager$RMFatalEventDispatcher
2019-06-07 07:57:20,655 INFO org.apache.hadoop.yarn.server.resourcemanager.security.NMTokenSecretManagerInRM: NMTokenKeyRollingInterval: 86400000ms and NMTokenKeyActivationDelay: 900000ms
2019-06-07 07:57:20,655 INFO org.apache.hadoop.yarn.server.resourcemanager.security.NMTokenSecretManagerInRM: NMTokenKeyRollingInterval: 86400000ms and NMTokenKeyActivationDelay: 900000ms
2019-06-07 07:57:20,662 INFO org.apache.hadoop.yarn.server.resourcemanager.security.RMContainerTokenSecretManager: ContainerTokenKeyRollingInterval: 86400000ms and ContainerTokenKeyActivationDelay: 900000ms
2019-06-07 07:57:20,662 INFO org.apache.hadoop.yarn.server.resourcemanager.security.RMContainerTokenSecretManager: ContainerTokenKeyRollingInterval: 86400000ms and ContainerTokenKeyActivationDelay: 900000ms
2019-06-07 07:57:20,666 INFO org.apache.hadoop.yarn.server.resourcemanager.security.AMRMTokenSecretManager: AMRMTokenKeyRollingInterval: 86400000ms and AMRMTokenKeyActivationDelay: 900000 ms
2019-06-07 07:57:20,666 INFO org.apache.hadoop.yarn.server.resourcemanager.security.AMRMTokenSecretManager: AMRMTokenKeyRollingInterval: 86400000ms and AMRMTokenKeyActivationDelay: 900000 ms
2019-06-07 07:57:20,699 INFO org.apache.hadoop.yarn.event.AsyncDispatcher: Registering class org.apache.hadoop.yarn.server.resourcemanager.recovery.RMStateStoreEventType for class org.apache.hadoop.yarn.server.resourcemanager.recovery.RMStateStore$ForwardingEventHandler
2019-06-07 07:57:20,703 INFO org.apache.hadoop.yarn.event.AsyncDispatcher: Registering class org.apache.hadoop.yarn.server.resourcemanager.NodesListManagerEventType for class org.apache.hadoop.yarn.server.resourcemanager.NodesListManager
2019-06-07 07:57:20,704 INFO org.apache.hadoop.yarn.server.resourcemanager.ResourceManager: Using Scheduler: org.apache.hadoop.yarn.server.resourcemanager.scheduler.capacity.CapacityScheduler
2019-06-07 07:57:20,704 INFO org.apache.hadoop.yarn.server.resourcemanager.ResourceManager: Using Scheduler: org.apache.hadoop.yarn.server.resourcemanager.scheduler.capacity.CapacityScheduler
2019-06-07 07:57:20,736 INFO org.apache.hadoop.yarn.event.AsyncDispatcher: Registering class org.apache.hadoop.yarn.server.resourcemanager.scheduler.event.SchedulerEventType for class org.apache.hadoop.yarn.server.resourcemanager.ResourceManager$SchedulerEventDispatcher
2019-06-07 07:57:20,737 INFO org.apache.hadoop.yarn.event.AsyncDispatcher: Registering class org.apache.hadoop.yarn.server.resourcemanager.rmapp.RMAppEventType for class org.apache.hadoop.yarn.server.resourcemanager.ResourceManager$ApplicationEventDispatcher
2019-06-07 07:57:20,737 INFO org.apache.hadoop.yarn.event.AsyncDispatcher: Registering class org.apache.hadoop.yarn.server.resourcemanager.rmapp.attempt.RMAppAttemptEventType for class org.apache.hadoop.yarn.server.resourcemanager.ResourceManager$ApplicationAttemptEventDispatcher
2019-06-07 07:57:20,738 INFO org.apache.hadoop.yarn.event.AsyncDispatcher: Registering class org.apache.hadoop.yarn.server.resourcemanager.rmnode.RMNodeEventType for class org.apache.hadoop.yarn.server.resourcemanager.ResourceManager$NodeEventDispatcher
2019-06-07 07:57:20,808 INFO org.apache.hadoop.metrics2.impl.MetricsConfig: loaded properties from hadoop-metrics2.properties
2019-06-07 07:57:20,979 INFO org.apache.hadoop.metrics2.impl.MetricsSystemImpl: Scheduled Metric snapshot period at 10 second(s).
2019-06-07 07:57:20,979 INFO org.apache.hadoop.metrics2.impl.MetricsSystemImpl: ResourceManager metrics system started
2019-06-07 07:57:21,002 INFO org.apache.hadoop.yarn.event.AsyncDispatcher: Registering class org.apache.hadoop.yarn.server.resourcemanager.RMAppManagerEventType for class org.apache.hadoop.yarn.server.resourcemanager.RMAppManager
2019-06-07 07:57:21,036 INFO org.apache.hadoop.yarn.event.AsyncDispatcher: Registering class org.apache.hadoop.yarn.server.resourcemanager.amlauncher.AMLauncherEventType for class org.apache.hadoop.yarn.server.resourcemanager.amlauncher.ApplicationMasterLauncher
2019-06-07 07:57:21,038 INFO org.apache.hadoop.yarn.server.resourcemanager.RMNMInfo: Registered RMNMInfo MBean
2019-06-07 07:57:21,038 INFO org.apache.hadoop.yarn.server.resourcemanager.RMNMInfo: Registered RMNMInfo MBean
2019-06-07 07:57:21,059 INFO org.apache.hadoop.yarn.security.YarnAuthorizationProvider: org.apache.hadoop.yarn.security.ConfiguredYarnAuthorizer is instiantiated.
2019-06-07 07:57:21,064 INFO org.apache.hadoop.util.HostsFileReader: Refreshing hosts (include/exclude) list
2019-06-07 07:57:21,067 DEBUG org.apache.hadoop.yarn.server.resourcemanager.NodesListManager: hostsReader: in= out=
2019-06-07 07:57:21,067 DEBUG org.apache.hadoop.yarn.server.resourcemanager.NodesListManager: hostsReader: in= out=
2019-06-07 07:57:21,089 INFO org.apache.hadoop.conf.Configuration: found resource capacity-scheduler.xml at file:/hadoop-2.8.5/etc/hadoop/capacity-scheduler.xml
2019-06-07 07:57:21,185 DEBUG org.apache.hadoop.yarn.server.resourcemanager.scheduler.capacity.CapacitySchedulerConfiguration: CSConf - getQueues called for: queuePrefix=yarn.scheduler.capacity.root.
2019-06-07 07:57:21,185 DEBUG org.apache.hadoop.yarn.server.resourcemanager.scheduler.capacity.CapacitySchedulerConfiguration: CSConf - getQueues called for: queuePrefix=yarn.scheduler.capacity.root.
2019-06-07 07:57:21,195 DEBUG org.apache.hadoop.yarn.server.resourcemanager.scheduler.capacity.CapacitySchedulerConfiguration: CSConf - getQueues: queuePrefix=yarn.scheduler.capacity.root., queues=default
2019-06-07 07:57:21,195 DEBUG org.apache.hadoop.yarn.server.resourcemanager.scheduler.capacity.CapacitySchedulerConfiguration: CSConf - getQueues: queuePrefix=yarn.scheduler.capacity.root., queues=default
2019-06-07 07:57:21,256 DEBUG org.apache.hadoop.yarn.server.resourcemanager.scheduler.capacity.CapacitySchedulerConfiguration: CSConf - getCapacity: queuePrefix=yarn.scheduler.capacity.root., capacity=100.0
2019-06-07 07:57:21,256 DEBUG org.apache.hadoop.yarn.server.resourcemanager.scheduler.capacity.CapacitySchedulerConfiguration: CSConf - getCapacity: queuePrefix=yarn.scheduler.capacity.root., capacity=100.0
2019-06-07 07:57:21,263 DEBUG org.apache.hadoop.yarn.server.resourcemanager.scheduler.capacity.CapacitySchedulerConfiguration: CSConf - getCapacity: queuePrefix=yarn.scheduler.capacity.root., capacity=100.0
2019-06-07 07:57:21,263 DEBUG org.apache.hadoop.yarn.server.resourcemanager.scheduler.capacity.CapacitySchedulerConfiguration: CSConf - getCapacity: queuePrefix=yarn.scheduler.capacity.root., capacity=100.0
2019-06-07 07:57:21,264 DEBUG org.apache.hadoop.yarn.server.resourcemanager.scheduler.capacity.CapacitySchedulerConfiguration: max alloc mb per queue for root is -1
2019-06-07 07:57:21,264 DEBUG org.apache.hadoop.yarn.server.resourcemanager.scheduler.capacity.CapacitySchedulerConfiguration: max alloc mb per queue for root is -1
2019-06-07 07:57:21,271 DEBUG org.apache.hadoop.yarn.server.resourcemanager.scheduler.capacity.CapacitySchedulerConfiguration: max alloc vcores per queue for root is -1
2019-06-07 07:57:21,271 DEBUG org.apache.hadoop.yarn.server.resourcemanager.scheduler.capacity.CapacitySchedulerConfiguration: max alloc vcores per queue for root is -1
2019-06-07 07:57:21,271 INFO org.apache.hadoop.yarn.server.resourcemanager.scheduler.capacity.CapacitySchedulerConfiguration: max alloc mb per queue for root is undefined
2019-06-07 07:57:21,271 INFO org.apache.hadoop.yarn.server.resourcemanager.scheduler.capacity.CapacitySchedulerConfiguration: max alloc mb per queue for root is undefined
2019-06-07 07:57:21,271 INFO org.apache.hadoop.yarn.server.resourcemanager.scheduler.capacity.CapacitySchedulerConfiguration: max alloc vcore per queue for root is undefined
2019-06-07 07:57:21,271 INFO org.apache.hadoop.yarn.server.resourcemanager.scheduler.capacity.CapacitySchedulerConfiguration: max alloc vcore per queue for root is undefined
2019-06-07 07:57:21,304 INFO org.apache.hadoop.yarn.server.resourcemanager.scheduler.capacity.ParentQueue: root, capacity=1.0, asboluteCapacity=1.0, maxCapacity=1.0, asboluteMaxCapacity=1.0, state=RUNNING, acls=ADMINISTER_QUEUE:*SUBMIT_APP:*, labels=*,, offswitchPerHeartbeatLimit = 1, reservationsContinueLooking=true
2019-06-07 07:57:21,304 INFO org.apache.hadoop.yarn.server.resourcemanager.scheduler.capacity.ParentQueue: root, capacity=1.0, asboluteCapacity=1.0, maxCapacity=1.0, asboluteMaxCapacity=1.0, state=RUNNING, acls=ADMINISTER_QUEUE:*SUBMIT_APP:*, labels=*,, offswitchPerHeartbeatLimit = 1, reservationsContinueLooking=true
2019-06-07 07:57:21,304 INFO org.apache.hadoop.yarn.server.resourcemanager.scheduler.capacity.ParentQueue: Initialized parent-queue root name=root, fullname=root
2019-06-07 07:57:21,304 INFO org.apache.hadoop.yarn.server.resourcemanager.scheduler.capacity.ParentQueue: Initialized parent-queue root name=root, fullname=root
2019-06-07 07:57:21,304 DEBUG org.apache.hadoop.yarn.server.resourcemanager.scheduler.capacity.CapacitySchedulerConfiguration: CSConf - getQueues called for: queuePrefix=yarn.scheduler.capacity.root.default.
2019-06-07 07:57:21,304 DEBUG org.apache.hadoop.yarn.server.resourcemanager.scheduler.capacity.CapacitySchedulerConfiguration: CSConf - getQueues called for: queuePrefix=yarn.scheduler.capacity.root.default.
2019-06-07 07:57:21,305 DEBUG org.apache.hadoop.yarn.server.resourcemanager.scheduler.capacity.CapacitySchedulerConfiguration: CSConf - getQueues: queuePrefix=yarn.scheduler.capacity.root.default., queues=
2019-06-07 07:57:21,305 DEBUG org.apache.hadoop.yarn.server.resourcemanager.scheduler.capacity.CapacitySchedulerConfiguration: CSConf - getQueues: queuePrefix=yarn.scheduler.capacity.root.default., queues=
2019-06-07 07:57:21,332 DEBUG org.apache.hadoop.yarn.server.resourcemanager.scheduler.capacity.LeafQueue: LeafQueue: name=default, fullname=root.default
2019-06-07 07:57:21,332 DEBUG org.apache.hadoop.yarn.server.resourcemanager.scheduler.capacity.LeafQueue: LeafQueue: name=default, fullname=root.default
2019-06-07 07:57:21,340 DEBUG org.apache.hadoop.yarn.server.resourcemanager.scheduler.capacity.CapacitySchedulerConfiguration: CSConf - getCapacity: queuePrefix=yarn.scheduler.capacity.root.default., capacity=100.0
2019-06-07 07:57:21,340 DEBUG org.apache.hadoop.yarn.server.resourcemanager.scheduler.capacity.CapacitySchedulerConfiguration: CSConf - getCapacity: queuePrefix=yarn.scheduler.capacity.root.default., capacity=100.0
2019-06-07 07:57:21,340 DEBUG org.apache.hadoop.yarn.server.resourcemanager.scheduler.capacity.CapacitySchedulerConfiguration: max alloc mb per queue for root.default is -1
2019-06-07 07:57:21,340 DEBUG org.apache.hadoop.yarn.server.resourcemanager.scheduler.capacity.CapacitySchedulerConfiguration: max alloc mb per queue for root.default is -1
2019-06-07 07:57:21,341 DEBUG org.apache.hadoop.yarn.server.resourcemanager.scheduler.capacity.CapacitySchedulerConfiguration: max alloc vcores per queue for root.default is -1
2019-06-07 07:57:21,341 DEBUG org.apache.hadoop.yarn.server.resourcemanager.scheduler.capacity.CapacitySchedulerConfiguration: max alloc vcores per queue for root.default is -1
2019-06-07 07:57:21,341 INFO org.apache.hadoop.yarn.server.resourcemanager.scheduler.capacity.CapacitySchedulerConfiguration: max alloc mb per queue for root.default is undefined
2019-06-07 07:57:21,341 INFO org.apache.hadoop.yarn.server.resourcemanager.scheduler.capacity.CapacitySchedulerConfiguration: max alloc mb per queue for root.default is undefined
2019-06-07 07:57:21,341 INFO org.apache.hadoop.yarn.server.resourcemanager.scheduler.capacity.CapacitySchedulerConfiguration: max alloc vcore per queue for root.default is undefined
2019-06-07 07:57:21,341 INFO org.apache.hadoop.yarn.server.resourcemanager.scheduler.capacity.CapacitySchedulerConfiguration: max alloc vcore per queue for root.default is undefined
2019-06-07 07:57:21,352 INFO org.apache.hadoop.yarn.server.resourcemanager.scheduler.capacity.LeafQueue: Initializing default
capacity = 1.0 [= (float) configuredCapacity / 100 ]
asboluteCapacity = 1.0 [= parentAbsoluteCapacity * capacity ]
maxCapacity = 1.0 [= configuredMaxCapacity ]
absoluteMaxCapacity = 1.0 [= 1.0 maximumCapacity undefined, (parentAbsoluteMaxCapacity * maximumCapacity) / 100 otherwise ]
userLimit = 100 [= configuredUserLimit ]
userLimitFactor = 1.0 [= configuredUserLimitFactor ]
maxApplications = 10000 [= configuredMaximumSystemApplicationsPerQueue or (int)(configuredMaximumSystemApplications * absoluteCapacity)]
maxApplicationsPerUser = 10000 [= (int)(maxApplications * (userLimit / 100.0f) * userLimitFactor) ]
usedCapacity = 0.0 [= usedResourcesMemory / (clusterResourceMemory * absoluteCapacity)]
absoluteUsedCapacity = 0.0 [= usedResourcesMemory / clusterResourceMemory]
maxAMResourcePerQueuePercent = 0.1 [= configuredMaximumAMResourcePercent ]
minimumAllocationFactor = 0.875 [= (float)(maximumAllocationMemory - minimumAllocationMemory) / maximumAllocationMemory ]
maximumAllocation = <memory:8192, vCores:4> [= configuredMaxAllocation ]
numContainers = 0 [= currentNumContainers ]
state = RUNNING [= configuredState ]
acls = ADMINISTER_QUEUE:*SUBMIT_APP:* [= configuredAcls ]
nodeLocalityDelay = 40
labels=*,
reservationsContinueLooking = true
preemptionDisabled = true
defaultAppPriorityPerQueue = 0
2019-06-07 07:57:21,352 INFO org.apache.hadoop.yarn.server.resourcemanager.scheduler.capacity.LeafQueue: Initializing default
capacity = 1.0 [= (float) configuredCapacity / 100 ]
asboluteCapacity = 1.0 [= parentAbsoluteCapacity * capacity ]
maxCapacity = 1.0 [= configuredMaxCapacity ]
absoluteMaxCapacity = 1.0 [= 1.0 maximumCapacity undefined, (parentAbsoluteMaxCapacity * maximumCapacity) / 100 otherwise ]
userLimit = 100 [= configuredUserLimit ]
userLimitFactor = 1.0 [= configuredUserLimitFactor ]
maxApplications = 10000 [= configuredMaximumSystemApplicationsPerQueue or (int)(configuredMaximumSystemApplications * absoluteCapacity)]
maxApplicationsPerUser = 10000 [= (int)(maxApplications * (userLimit / 100.0f) * userLimitFactor) ]
usedCapacity = 0.0 [= usedResourcesMemory / (clusterResourceMemory * absoluteCapacity)]
absoluteUsedCapacity = 0.0 [= usedResourcesMemory / clusterResourceMemory]
maxAMResourcePerQueuePercent = 0.1 [= configuredMaximumAMResourcePercent ]
minimumAllocationFactor = 0.875 [= (float)(maximumAllocationMemory - minimumAllocationMemory) / maximumAllocationMemory ]
maximumAllocation = <memory:8192, vCores:4> [= configuredMaxAllocation ]
numContainers = 0 [= currentNumContainers ]
state = RUNNING [= configuredState ]
acls = ADMINISTER_QUEUE:*SUBMIT_APP:* [= configuredAcls ]
nodeLocalityDelay = 40
labels=*,
reservationsContinueLooking = true
preemptionDisabled = true
defaultAppPriorityPerQueue = 0
2019-06-07 07:57:21,352 INFO org.apache.hadoop.yarn.server.resourcemanager.scheduler.capacity.CapacityScheduler: Initialized queue: default: capacity=1.0, absoluteCapacity=1.0, usedResources=<memory:0, vCores:0>, usedCapacity=0.0, absoluteUsedCapacity=0.0, numApps=0, numContainers=0
2019-06-07 07:57:21,352 INFO org.apache.hadoop.yarn.server.resourcemanager.scheduler.capacity.CapacityScheduler: Initialized queue: default: capacity=1.0, absoluteCapacity=1.0, usedResources=<memory:0, vCores:0>, usedCapacity=0.0, absoluteUsedCapacity=0.0, numApps=0, numContainers=0
2019-06-07 07:57:21,353 DEBUG org.apache.hadoop.yarn.server.resourcemanager.scheduler.capacity.ParentQueue: setChildQueues: root.defaultusedCapacity=(0.0),  label=(*)
2019-06-07 07:57:21,353 DEBUG org.apache.hadoop.yarn.server.resourcemanager.scheduler.capacity.ParentQueue: setChildQueues: root.defaultusedCapacity=(0.0),  label=(*)
2019-06-07 07:57:21,353 INFO org.apache.hadoop.yarn.server.resourcemanager.scheduler.capacity.CapacityScheduler: Initialized queue: root: numChildQueue= 1, capacity=1.0, absoluteCapacity=1.0, usedResources=<memory:0, vCores:0>usedCapacity=0.0, numApps=0, numContainers=0
2019-06-07 07:57:21,353 INFO org.apache.hadoop.yarn.server.resourcemanager.scheduler.capacity.CapacityScheduler: Initialized queue: root: numChildQueue= 1, capacity=1.0, absoluteCapacity=1.0, usedResources=<memory:0, vCores:0>usedCapacity=0.0, numApps=0, numContainers=0
2019-06-07 07:57:21,354 INFO org.apache.hadoop.yarn.server.resourcemanager.scheduler.capacity.CapacityScheduler: Initialized root queue root: numChildQueue= 1, capacity=1.0, absoluteCapacity=1.0, usedResources=<memory:0, vCores:0>usedCapacity=0.0, numApps=0, numContainers=0
2019-06-07 07:57:21,354 INFO org.apache.hadoop.yarn.server.resourcemanager.scheduler.capacity.CapacityScheduler: Initialized root queue root: numChildQueue= 1, capacity=1.0, absoluteCapacity=1.0, usedResources=<memory:0, vCores:0>usedCapacity=0.0, numApps=0, numContainers=0
2019-06-07 07:57:21,354 INFO org.apache.hadoop.yarn.server.resourcemanager.scheduler.capacity.CapacityScheduler: Initialized queue mappings, override: false
2019-06-07 07:57:21,354 INFO org.apache.hadoop.yarn.server.resourcemanager.scheduler.capacity.CapacityScheduler: Initialized queue mappings, override: false
2019-06-07 07:57:21,355 INFO org.apache.hadoop.yarn.server.resourcemanager.scheduler.capacity.CapacityScheduler: Initialized CapacityScheduler with calculator=class org.apache.hadoop.yarn.util.resource.DefaultResourceCalculator, minimumAllocation=<<memory:1024, vCores:1>>, maximumAllocation=<<memory:8192, vCores:4>>, asynchronousScheduling=false, asyncScheduleInterval=5ms
2019-06-07 07:57:21,355 INFO org.apache.hadoop.yarn.server.resourcemanager.scheduler.capacity.CapacityScheduler: Initialized CapacityScheduler with calculator=class org.apache.hadoop.yarn.util.resource.DefaultResourceCalculator, minimumAllocation=<<memory:1024, vCores:1>>, maximumAllocation=<<memory:8192, vCores:4>>, asynchronousScheduling=false, asyncScheduleInterval=5ms
2019-06-07 07:57:21,371 INFO org.apache.hadoop.conf.Configuration: dynamic-resources.xml not found
2019-06-07 07:57:21,398 INFO org.apache.hadoop.yarn.server.resourcemanager.metrics.SystemMetricsPublisher: YARN system metrics publishing service is not enabled
2019-06-07 07:57:21,398 INFO org.apache.hadoop.yarn.server.resourcemanager.metrics.SystemMetricsPublisher: YARN system metrics publishing service is not enabled
2019-06-07 07:57:21,407 INFO org.apache.hadoop.yarn.server.resourcemanager.ResourceManager: Transitioning to active state
2019-06-07 07:57:21,407 INFO org.apache.hadoop.yarn.server.resourcemanager.ResourceManager: Transitioning to active state
2019-06-07 07:57:21,468 INFO org.apache.hadoop.util.JvmPauseMonitor: Starting JVM pause monitor
2019-06-07 07:57:21,486 DEBUG org.apache.hadoop.yarn.server.resourcemanager.recovery.RMStateStore: Processing event of type UPDATE_AMRM_TOKEN
2019-06-07 07:57:21,486 DEBUG org.apache.hadoop.yarn.server.resourcemanager.recovery.RMStateStore: Processing event of type UPDATE_AMRM_TOKEN
2019-06-07 07:57:21,486 INFO org.apache.hadoop.yarn.server.resourcemanager.recovery.RMStateStore: Updating AMRMToken
2019-06-07 07:57:21,486 INFO org.apache.hadoop.yarn.server.resourcemanager.recovery.RMStateStore: Updating AMRMToken
2019-06-07 07:57:21,502 INFO org.apache.hadoop.yarn.server.resourcemanager.security.RMContainerTokenSecretManager: Rolling master-key for container-tokens
2019-06-07 07:57:21,502 INFO org.apache.hadoop.yarn.server.resourcemanager.security.RMContainerTokenSecretManager: Rolling master-key for container-tokens
2019-06-07 07:57:21,503 INFO org.apache.hadoop.yarn.server.resourcemanager.security.NMTokenSecretManagerInRM: Rolling master-key for nm-tokens
2019-06-07 07:57:21,503 INFO org.apache.hadoop.yarn.server.resourcemanager.security.NMTokenSecretManagerInRM: Rolling master-key for nm-tokens
2019-06-07 07:57:21,503 INFO org.apache.hadoop.security.token.delegation.AbstractDelegationTokenSecretManager: Updating the current master key for generating delegation tokens
2019-06-07 07:57:21,504 INFO org.apache.hadoop.yarn.server.resourcemanager.security.RMDelegationTokenSecretManager: storing master key with keyID 1
2019-06-07 07:57:21,504 INFO org.apache.hadoop.yarn.server.resourcemanager.security.RMDelegationTokenSecretManager: storing master key with keyID 1
2019-06-07 07:57:21,504 DEBUG org.apache.hadoop.yarn.server.resourcemanager.recovery.RMStateStore: Processing event of type STORE_MASTERKEY
2019-06-07 07:57:21,504 DEBUG org.apache.hadoop.yarn.server.resourcemanager.recovery.RMStateStore: Processing event of type STORE_MASTERKEY
2019-06-07 07:57:21,505 INFO org.apache.hadoop.yarn.server.resourcemanager.recovery.RMStateStore: Storing RMDTMasterKey.
2019-06-07 07:57:21,505 INFO org.apache.hadoop.yarn.server.resourcemanager.recovery.RMStateStore: Storing RMDTMasterKey.
2019-06-07 07:57:21,506 INFO org.apache.hadoop.security.token.delegation.AbstractDelegationTokenSecretManager: Starting expired delegation token remover thread, tokenRemoverScanInterval=60 min(s)
2019-06-07 07:57:21,506 INFO org.apache.hadoop.security.token.delegation.AbstractDelegationTokenSecretManager: Updating the current master key for generating delegation tokens
2019-06-07 07:57:21,506 INFO org.apache.hadoop.yarn.server.resourcemanager.security.RMDelegationTokenSecretManager: storing master key with keyID 2
2019-06-07 07:57:21,506 INFO org.apache.hadoop.yarn.server.resourcemanager.security.RMDelegationTokenSecretManager: storing master key with keyID 2
2019-06-07 07:57:21,515 DEBUG org.apache.hadoop.yarn.server.resourcemanager.recovery.RMStateStore: Processing event of type STORE_MASTERKEY
2019-06-07 07:57:21,515 DEBUG org.apache.hadoop.yarn.server.resourcemanager.recovery.RMStateStore: Processing event of type STORE_MASTERKEY
2019-06-07 07:57:21,515 INFO org.apache.hadoop.yarn.server.resourcemanager.recovery.RMStateStore: Storing RMDTMasterKey.
2019-06-07 07:57:21,515 INFO org.apache.hadoop.yarn.server.resourcemanager.recovery.RMStateStore: Storing RMDTMasterKey.
2019-06-07 07:57:21,516 INFO org.apache.hadoop.yarn.event.AsyncDispatcher: Registering class org.apache.hadoop.yarn.nodelabels.event.NodeLabelsStoreEventType for class org.apache.hadoop.yarn.nodelabels.CommonNodeLabelsManager$ForwardingEventHandler
2019-06-07 07:57:21,598 INFO org.apache.hadoop.ipc.CallQueueManager: Using callQueue: class java.util.concurrent.LinkedBlockingQueue queueCapacity: 5000 scheduler: class org.apache.hadoop.ipc.DefaultRpcScheduler
2019-06-07 07:57:21,641 INFO org.apache.hadoop.ipc.Server: Starting Socket Reader #1 for port 8031
2019-06-07 07:57:22,142 INFO org.apache.hadoop.yarn.factories.impl.pb.RpcServerFactoryPBImpl: Adding protocol org.apache.hadoop.yarn.server.api.ResourceTrackerPB to the server
2019-06-07 07:57:22,156 INFO org.apache.hadoop.ipc.Server: IPC Server Responder: starting
2019-06-07 07:57:22,170 INFO org.apache.hadoop.ipc.Server: IPC Server listener on 8031: starting
2019-06-07 07:57:22,230 INFO org.apache.hadoop.ipc.CallQueueManager: Using callQueue: class java.util.concurrent.LinkedBlockingQueue queueCapacity: 5000 scheduler: class org.apache.hadoop.ipc.DefaultRpcScheduler
2019-06-07 07:57:22,333 INFO org.apache.hadoop.ipc.Server: Starting Socket Reader #1 for port 8030
2019-06-07 07:57:22,408 INFO org.apache.hadoop.yarn.factories.impl.pb.RpcServerFactoryPBImpl: Adding protocol org.apache.hadoop.yarn.api.ApplicationMasterProtocolPB to the server
2019-06-07 07:57:22,411 INFO org.apache.hadoop.ipc.Server: IPC Server Responder: starting
2019-06-07 07:57:22,415 INFO org.apache.hadoop.ipc.Server: IPC Server listener on 8030: starting
2019-06-07 07:57:22,694 INFO org.apache.hadoop.ipc.CallQueueManager: Using callQueue: class java.util.concurrent.LinkedBlockingQueue queueCapacity: 5000 scheduler: class org.apache.hadoop.ipc.DefaultRpcScheduler
2019-06-07 07:57:22,716 INFO org.apache.hadoop.ipc.Server: Starting Socket Reader #1 for port 8032
2019-06-07 07:57:22,740 INFO org.apache.hadoop.yarn.factories.impl.pb.RpcServerFactoryPBImpl: Adding protocol org.apache.hadoop.yarn.api.ApplicationClientProtocolPB to the server
2019-06-07 07:57:22,747 INFO org.apache.hadoop.ipc.Server: IPC Server Responder: starting
2019-06-07 07:57:22,747 INFO org.apache.hadoop.ipc.Server: IPC Server listener on 8032: starting
2019-06-07 07:57:22,771 INFO org.apache.hadoop.yarn.server.resourcemanager.ResourceManager: Transitioned to active state
2019-06-07 07:57:22,771 INFO org.apache.hadoop.yarn.server.resourcemanager.ResourceManager: Transitioned to active state
2019-06-07 07:57:23,057 INFO org.mortbay.log: Logging to org.slf4j.impl.Log4jLoggerAdapter(org.mortbay.log) via org.mortbay.log.Slf4jLog
2019-06-07 07:57:23,092 INFO org.apache.hadoop.security.authentication.server.AuthenticationFilter: Unable to initialize FileSignerSecretProvider, falling back to use random secrets.
2019-06-07 07:57:23,098 INFO org.apache.hadoop.http.HttpRequestLog: Http request log for http.requests.resourcemanager is not defined
2019-06-07 07:57:23,106 INFO org.apache.hadoop.http.HttpServer2: Added global filter 'safety' (class=org.apache.hadoop.http.HttpServer2$QuotingInputFilter)
2019-06-07 07:57:23,110 INFO org.apache.hadoop.http.HttpServer2: Added filter RMAuthenticationFilter (class=org.apache.hadoop.yarn.server.security.http.RMAuthenticationFilter) to context cluster
2019-06-07 07:57:23,110 INFO org.apache.hadoop.http.HttpServer2: Added filter RMAuthenticationFilter (class=org.apache.hadoop.yarn.server.security.http.RMAuthenticationFilter) to context logs
2019-06-07 07:57:23,110 INFO org.apache.hadoop.http.HttpServer2: Added filter RMAuthenticationFilter (class=org.apache.hadoop.yarn.server.security.http.RMAuthenticationFilter) to context static
2019-06-07 07:57:23,110 INFO org.apache.hadoop.http.HttpServer2: Added filter static_user_filter (class=org.apache.hadoop.http.lib.StaticUserWebFilter$StaticUserFilter) to context cluster
2019-06-07 07:57:23,110 INFO org.apache.hadoop.http.HttpServer2: Added filter static_user_filter (class=org.apache.hadoop.http.lib.StaticUserWebFilter$StaticUserFilter) to context logs
2019-06-07 07:57:23,110 INFO org.apache.hadoop.http.HttpServer2: Added filter static_user_filter (class=org.apache.hadoop.http.lib.StaticUserWebFilter$StaticUserFilter) to context static
2019-06-07 07:57:23,114 INFO org.apache.hadoop.http.HttpServer2: adding path spec: /cluster/*
2019-06-07 07:57:23,114 INFO org.apache.hadoop.http.HttpServer2: adding path spec: /ws/*
2019-06-07 07:57:25,304 INFO org.apache.hadoop.yarn.webapp.WebApps: Registered webapp guice modules
2019-06-07 07:57:25,333 INFO org.apache.hadoop.http.HttpServer2: Jetty bound to port 8088
2019-06-07 07:57:25,333 INFO org.mortbay.log: jetty-6.1.26
2019-06-07 07:57:25,456 INFO org.mortbay.log: Extract jar:file:/hadoop-2.8.5/share/hadoop/yarn/hadoop-yarn-common-2.8.5.jar!/webapps/cluster to /tmp/Jetty_master_8088_cluster____i4ls4w/webapp
2019-06-07 07:57:26,045 INFO org.apache.hadoop.security.token.delegation.AbstractDelegationTokenSecretManager: Updating the current master key for generating delegation tokens
2019-06-07 07:57:26,058 INFO org.apache.hadoop.security.token.delegation.AbstractDelegationTokenSecretManager: Starting expired delegation token remover thread, tokenRemoverScanInterval=60 min(s)
2019-06-07 07:57:26,089 INFO org.apache.hadoop.security.token.delegation.AbstractDelegationTokenSecretManager: Updating the current master key for generating delegation tokens
2019-06-07 07:57:29,981 INFO org.apache.hadoop.yarn.server.resourcemanager.ResourceTrackerService: NodeManager from node slave1(cmPort: 34830 httpPort: 8042) registered with capability: <memory:4096, vCores:1>, assigned nodeId slave1:34830
2019-06-07 07:57:29,981 INFO org.apache.hadoop.yarn.server.resourcemanager.ResourceTrackerService: NodeManager from node slave1(cmPort: 34830 httpPort: 8042) registered with capability: <memory:4096, vCores:1>, assigned nodeId slave1:34830
2019-06-07 07:57:29,983 INFO org.apache.hadoop.yarn.server.resourcemanager.ResourceTrackerService: NodeManager from node slave2(cmPort: 42768 httpPort: 8042) registered with capability: <memory:4096, vCores:1>, assigned nodeId slave2:42768
2019-06-07 07:57:29,983 INFO org.apache.hadoop.yarn.server.resourcemanager.ResourceTrackerService: NodeManager from node slave2(cmPort: 42768 httpPort: 8042) registered with capability: <memory:4096, vCores:1>, assigned nodeId slave2:42768
2019-06-07 07:57:30,223 INFO org.mortbay.log: Started HttpServer2$SelectChannelConnectorWithSafeStartup@master:8088
2019-06-07 07:57:30,223 INFO org.apache.hadoop.yarn.webapp.WebApps: Web app cluster started at 8088
2019-06-07 07:57:30,237 DEBUG org.apache.hadoop.yarn.server.resourcemanager.rmnode.RMNodeImpl: Processing slave1:34830 of type STARTED
2019-06-07 07:57:30,237 DEBUG org.apache.hadoop.yarn.server.resourcemanager.rmnode.RMNodeImpl: Processing slave1:34830 of type STARTED
2019-06-07 07:57:30,244 INFO org.apache.hadoop.yarn.server.resourcemanager.rmnode.RMNodeImpl: slave1:34830 Node Transitioned from NEW to RUNNING
2019-06-07 07:57:30,244 INFO org.apache.hadoop.yarn.server.resourcemanager.rmnode.RMNodeImpl: slave1:34830 Node Transitioned from NEW to RUNNING
2019-06-07 07:57:30,244 DEBUG org.apache.hadoop.yarn.server.resourcemanager.rmnode.RMNodeImpl: Processing slave2:42768 of type STARTED
2019-06-07 07:57:30,244 DEBUG org.apache.hadoop.yarn.server.resourcemanager.rmnode.RMNodeImpl: Processing slave2:42768 of type STARTED
2019-06-07 07:57:30,244 INFO org.apache.hadoop.yarn.server.resourcemanager.rmnode.RMNodeImpl: slave2:42768 Node Transitioned from NEW to RUNNING
2019-06-07 07:57:30,244 INFO org.apache.hadoop.yarn.server.resourcemanager.rmnode.RMNodeImpl: slave2:42768 Node Transitioned from NEW to RUNNING
2019-06-07 07:57:30,251 DEBUG org.apache.hadoop.yarn.server.resourcemanager.rmnode.RMNodeImpl: Processing slave1:34830 of type STATUS_UPDATE
2019-06-07 07:57:30,251 DEBUG org.apache.hadoop.yarn.server.resourcemanager.rmnode.RMNodeImpl: Processing slave1:34830 of type STATUS_UPDATE
2019-06-07 07:57:30,253 DEBUG org.apache.hadoop.yarn.server.resourcemanager.rmnode.RMNodeImpl: Processing slave2:42768 of type STATUS_UPDATE
2019-06-07 07:57:30,253 DEBUG org.apache.hadoop.yarn.server.resourcemanager.rmnode.RMNodeImpl: Processing slave2:42768 of type STATUS_UPDATE
2019-06-07 07:57:30,255 DEBUG org.apache.hadoop.yarn.server.resourcemanager.NodesListManager: slave1:34830 reported usable
2019-06-07 07:57:30,255 DEBUG org.apache.hadoop.yarn.server.resourcemanager.NodesListManager: slave1:34830 reported usable
2019-06-07 07:57:30,256 DEBUG org.apache.hadoop.yarn.server.resourcemanager.NodesListManager: slave2:42768 reported usable
2019-06-07 07:57:30,256 DEBUG org.apache.hadoop.yarn.server.resourcemanager.NodesListManager: slave2:42768 reported usable
2019-06-07 07:57:30,260 INFO org.apache.hadoop.yarn.server.resourcemanager.scheduler.capacity.CapacityScheduler: Added node slave1:34830 clusterResource: <memory:4096, vCores:1>
2019-06-07 07:57:30,260 INFO org.apache.hadoop.yarn.server.resourcemanager.scheduler.capacity.CapacityScheduler: Added node slave1:34830 clusterResource: <memory:4096, vCores:1>
2019-06-07 07:57:30,260 INFO org.apache.hadoop.yarn.server.resourcemanager.scheduler.capacity.CapacityScheduler: Added node slave2:42768 clusterResource: <memory:8192, vCores:2>
2019-06-07 07:57:30,260 INFO org.apache.hadoop.yarn.server.resourcemanager.scheduler.capacity.CapacityScheduler: Added node slave2:42768 clusterResource: <memory:8192, vCores:2>
2019-06-07 07:57:30,260 DEBUG org.apache.hadoop.yarn.server.resourcemanager.scheduler.capacity.CapacityScheduler: nodeUpdate: slave1:34830 clusterResources: <memory:8192, vCores:2>
2019-06-07 07:57:30,260 DEBUG org.apache.hadoop.yarn.server.resourcemanager.scheduler.capacity.CapacityScheduler: nodeUpdate: slave1:34830 clusterResources: <memory:8192, vCores:2>
2019-06-07 07:57:30,263 DEBUG org.apache.hadoop.yarn.server.resourcemanager.scheduler.capacity.CapacityScheduler: Node being looked for scheduling slave1:34830 availableResource: <memory:4096, vCores:1>
2019-06-07 07:57:30,263 DEBUG org.apache.hadoop.yarn.server.resourcemanager.scheduler.capacity.CapacityScheduler: Node being looked for scheduling slave1:34830 availableResource: <memory:4096, vCores:1>
2019-06-07 07:57:30,265 DEBUG org.apache.hadoop.yarn.server.resourcemanager.scheduler.capacity.CapacityScheduler: Trying to schedule on node: slave1, available: <memory:4096, vCores:1>
2019-06-07 07:57:30,265 DEBUG org.apache.hadoop.yarn.server.resourcemanager.scheduler.capacity.CapacityScheduler: Trying to schedule on node: slave1, available: <memory:4096, vCores:1>
2019-06-07 07:57:30,266 DEBUG org.apache.hadoop.yarn.server.resourcemanager.scheduler.capacity.ParentQueue: Skip this queue=root, because it doesn't need more resource, schedulingMode=RESPECT_PARTITION_EXCLUSIVITY node-partition=
2019-06-07 07:57:30,266 DEBUG org.apache.hadoop.yarn.server.resourcemanager.scheduler.capacity.ParentQueue: Skip this queue=root, because it doesn't need more resource, schedulingMode=RESPECT_PARTITION_EXCLUSIVITY node-partition=
2019-06-07 07:57:30,266 DEBUG org.apache.hadoop.yarn.server.resourcemanager.scheduler.capacity.CapacityScheduler: nodeUpdate: slave2:42768 clusterResources: <memory:8192, vCores:2>
2019-06-07 07:57:30,266 DEBUG org.apache.hadoop.yarn.server.resourcemanager.scheduler.capacity.CapacityScheduler: nodeUpdate: slave2:42768 clusterResources: <memory:8192, vCores:2>
2019-06-07 07:57:30,268 DEBUG org.apache.hadoop.yarn.server.resourcemanager.scheduler.capacity.CapacityScheduler: Node being looked for scheduling slave2:42768 availableResource: <memory:4096, vCores:1>
2019-06-07 07:57:30,268 DEBUG org.apache.hadoop.yarn.server.resourcemanager.scheduler.capacity.CapacityScheduler: Node being looked for scheduling slave2:42768 availableResource: <memory:4096, vCores:1>
2019-06-07 07:57:30,268 DEBUG org.apache.hadoop.yarn.server.resourcemanager.scheduler.capacity.CapacityScheduler: Trying to schedule on node: slave2, available: <memory:4096, vCores:1>
2019-06-07 07:57:30,268 DEBUG org.apache.hadoop.yarn.server.resourcemanager.scheduler.capacity.CapacityScheduler: Trying to schedule on node: slave2, available: <memory:4096, vCores:1>
2019-06-07 07:57:30,268 DEBUG org.apache.hadoop.yarn.server.resourcemanager.scheduler.capacity.ParentQueue: Skip this queue=root, because it doesn't need more resource, schedulingMode=RESPECT_PARTITION_EXCLUSIVITY node-partition=
2019-06-07 07:57:30,268 DEBUG org.apache.hadoop.yarn.server.resourcemanager.scheduler.capacity.ParentQueue: Skip this queue=root, because it doesn't need more resource, schedulingMode=RESPECT_PARTITION_EXCLUSIVITY node-partition=
2019-06-07 07:57:30,281 INFO org.apache.hadoop.ipc.CallQueueManager: Using callQueue: class java.util.concurrent.LinkedBlockingQueue queueCapacity: 100 scheduler: class org.apache.hadoop.ipc.DefaultRpcScheduler
2019-06-07 07:57:30,283 INFO org.apache.hadoop.ipc.Server: Starting Socket Reader #1 for port 8033
2019-06-07 07:57:30,285 INFO org.apache.hadoop.yarn.factories.impl.pb.RpcServerFactoryPBImpl: Adding protocol org.apache.hadoop.yarn.server.api.ResourceManagerAdministrationProtocolPB to the server
2019-06-07 07:57:30,290 INFO org.apache.hadoop.ipc.Server: IPC Server Responder: starting
2019-06-07 07:57:30,291 INFO org.apache.hadoop.ipc.Server: IPC Server listener on 8033: starting
2019-06-07 07:57:31,210 DEBUG org.apache.hadoop.yarn.server.resourcemanager.rmnode.RMNodeImpl: Processing slave2:42768 of type STATUS_UPDATE
2019-06-07 07:57:31,210 DEBUG org.apache.hadoop.yarn.server.resourcemanager.rmnode.RMNodeImpl: Processing slave2:42768 of type STATUS_UPDATE
2019-06-07 07:57:31,211 DEBUG org.apache.hadoop.yarn.server.resourcemanager.rmnode.RMNodeImpl: Processing slave1:34830 of type STATUS_UPDATE
2019-06-07 07:57:31,211 DEBUG org.apache.hadoop.yarn.server.resourcemanager.rmnode.RMNodeImpl: Processing slave1:34830 of type STATUS_UPDATE
2019-06-07 07:57:31,215 DEBUG org.apache.hadoop.yarn.server.resourcemanager.scheduler.capacity.CapacityScheduler: nodeUpdate: slave2:42768 clusterResources: <memory:8192, vCores:2>
2019-06-07 07:57:31,215 DEBUG org.apache.hadoop.yarn.server.resourcemanager.scheduler.capacity.CapacityScheduler: nodeUpdate: slave2:42768 clusterResources: <memory:8192, vCores:2>
2019-06-07 07:57:31,215 DEBUG org.apache.hadoop.yarn.server.resourcemanager.scheduler.capacity.CapacityScheduler: Node being looked for scheduling slave2:42768 availableResource: <memory:4096, vCores:1>
2019-06-07 07:57:31,215 DEBUG org.apache.hadoop.yarn.server.resourcemanager.scheduler.capacity.CapacityScheduler: Node being looked for scheduling slave2:42768 availableResource: <memory:4096, vCores:1>
2019-06-07 07:57:31,215 DEBUG org.apache.hadoop.yarn.server.resourcemanager.scheduler.capacity.CapacityScheduler: Trying to schedule on node: slave2, available: <memory:4096, vCores:1>
2019-06-07 07:57:31,215 DEBUG org.apache.hadoop.yarn.server.resourcemanager.scheduler.capacity.CapacityScheduler: Trying to schedule on node: slave2, available: <memory:4096, vCores:1>
2019-06-07 07:57:31,215 DEBUG org.apache.hadoop.yarn.server.resourcemanager.scheduler.capacity.ParentQueue: Skip this queue=root, because it doesn't need more resource, schedulingMode=RESPECT_PARTITION_EXCLUSIVITY node-partition=
2019-06-07 07:57:31,215 DEBUG org.apache.hadoop.yarn.server.resourcemanager.scheduler.capacity.ParentQueue: Skip this queue=root, because it doesn't need more resource, schedulingMode=RESPECT_PARTITION_EXCLUSIVITY node-partition=
2019-06-07 07:57:31,215 DEBUG org.apache.hadoop.yarn.server.resourcemanager.scheduler.capacity.CapacityScheduler: nodeUpdate: slave1:34830 clusterResources: <memory:8192, vCores:2>
2019-06-07 07:57:31,215 DEBUG org.apache.hadoop.yarn.server.resourcemanager.scheduler.capacity.CapacityScheduler: nodeUpdate: slave1:34830 clusterResources: <memory:8192, vCores:2>
2019-06-07 07:57:31,215 DEBUG org.apache.hadoop.yarn.server.resourcemanager.scheduler.capacity.CapacityScheduler: Node being looked for scheduling slave1:34830 availableResource: <memory:4096, vCores:1>
2019-06-07 07:57:31,215 DEBUG org.apache.hadoop.yarn.server.resourcemanager.scheduler.capacity.CapacityScheduler: Node being looked for scheduling slave1:34830 availableResource: <memory:4096, vCores:1>
2019-06-07 07:57:31,215 DEBUG org.apache.hadoop.yarn.server.resourcemanager.scheduler.capacity.CapacityScheduler: Trying to schedule on node: slave1, available: <memory:4096, vCores:1>
2019-06-07 07:57:31,215 DEBUG org.apache.hadoop.yarn.server.resourcemanager.scheduler.capacity.CapacityScheduler: Trying to schedule on node: slave1, available: <memory:4096, vCores:1>
2019-06-07 07:57:31,215 DEBUG org.apache.hadoop.yarn.server.resourcemanager.scheduler.capacity.ParentQueue: Skip this queue=root, because it doesn't need more resource, schedulingMode=RESPECT_PARTITION_EXCLUSIVITY node-partition=
2019-06-07 07:57:31,215 DEBUG org.apache.hadoop.yarn.server.resourcemanager.scheduler.capacity.ParentQueue: Skip this queue=root, because it doesn't need more resource, schedulingMode=RESPECT_PARTITION_EXCLUSIVITY node-partition=
2019-06-07 07:57:32,212 DEBUG org.apache.hadoop.yarn.server.resourcemanager.rmnode.RMNodeImpl: Processing slave2:42768 of type STATUS_UPDATE
2019-06-07 07:57:32,212 DEBUG org.apache.hadoop.yarn.server.resourcemanager.rmnode.RMNodeImpl: Processing slave2:42768 of type STATUS_UPDATE
2019-06-07 07:57:32,226 DEBUG org.apache.hadoop.yarn.server.resourcemanager.rmnode.RMNodeImpl: Processing slave1:34830 of type STATUS_UPDATE
2019-06-07 07:57:32,226 DEBUG org.apache.hadoop.yarn.server.resourcemanager.rmnode.RMNodeImpl: Processing slave1:34830 of type STATUS_UPDATE
2019-06-07 07:57:32,227 DEBUG org.apache.hadoop.yarn.server.resourcemanager.scheduler.capacity.CapacityScheduler: nodeUpdate: slave2:42768 clusterResources: <memory:8192, vCores:2>
2019-06-07 07:57:32,227 DEBUG org.apache.hadoop.yarn.server.resourcemanager.scheduler.capacity.CapacityScheduler: nodeUpdate: slave2:42768 clusterResources: <memory:8192, vCores:2>
2019-06-07 07:57:32,227 DEBUG org.apache.hadoop.yarn.server.resourcemanager.scheduler.capacity.CapacityScheduler: Node being looked for scheduling slave2:42768 availableResource: <memory:4096, vCores:1>
2019-06-07 07:57:32,227 DEBUG org.apache.hadoop.yarn.server.resourcemanager.scheduler.capacity.CapacityScheduler: Node being looked for scheduling slave2:42768 availableResource: <memory:4096, vCores:1>
2019-06-07 07:57:32,227 DEBUG org.apache.hadoop.yarn.server.resourcemanager.scheduler.capacity.CapacityScheduler: Trying to schedule on node: slave2, available: <memory:4096, vCores:1>
2019-06-07 07:57:32,227 DEBUG org.apache.hadoop.yarn.server.resourcemanager.scheduler.capacity.CapacityScheduler: Trying to schedule on node: slave2, available: <memory:4096, vCores:1>
2019-06-07 07:57:32,227 DEBUG org.apache.hadoop.yarn.server.resourcemanager.scheduler.capacity.ParentQueue: Skip this queue=root, because it doesn't need more resource, schedulingMode=RESPECT_PARTITION_EXCLUSIVITY node-partition=
2019-06-07 07:57:32,227 DEBUG org.apache.hadoop.yarn.server.resourcemanager.scheduler.capacity.ParentQueue: Skip this queue=root, because it doesn't need more resource, schedulingMode=RESPECT_PARTITION_EXCLUSIVITY node-partition=
2019-06-07 07:57:32,227 DEBUG org.apache.hadoop.yarn.server.resourcemanager.scheduler.capacity.CapacityScheduler: nodeUpdate: slave1:34830 clusterResources: <memory:8192, vCores:2>
2019-06-07 07:57:32,227 DEBUG org.apache.hadoop.yarn.server.resourcemanager.scheduler.capacity.CapacityScheduler: nodeUpdate: slave1:34830 clusterResources: <memory:8192, vCores:2>
2019-06-07 07:57:32,227 DEBUG org.apache.hadoop.yarn.server.resourcemanager.scheduler.capacity.CapacityScheduler: Node being looked for scheduling slave1:34830 availableResource: <memory:4096, vCores:1>
2019-06-07 07:57:32,227 DEBUG org.apache.hadoop.yarn.server.resourcemanager.scheduler.capacity.CapacityScheduler: Node being looked for scheduling slave1:34830 availableResource: <memory:4096, vCores:1>
2019-06-07 07:57:32,227 DEBUG org.apache.hadoop.yarn.server.resourcemanager.scheduler.capacity.CapacityScheduler: Trying to schedule on node: slave1, available: <memory:4096, vCores:1>
2019-06-07 07:57:32,227 DEBUG org.apache.hadoop.yarn.server.resourcemanager.scheduler.capacity.CapacityScheduler: Trying to schedule on node: slave1, available: <memory:4096, vCores:1>
2019-06-07 07:57:32,227 DEBUG org.apache.hadoop.yarn.server.resourcemanager.scheduler.capacity.ParentQueue: Skip this queue=root, because it doesn't need more resource, schedulingMode=RESPECT_PARTITION_EXCLUSIVITY node-partition=
2019-06-07 07:57:32,227 DEBUG org.apache.hadoop.yarn.server.resourcemanager.scheduler.capacity.ParentQueue: Skip this queue=root, because it doesn't need more resource, schedulingMode=RESPECT_PARTITION_EXCLUSIVITY node-partition=
2019-06-07 07:57:33,215 DEBUG org.apache.hadoop.yarn.server.resourcemanager.rmnode.RMNodeImpl: Processing slave2:42768 of type STATUS_UPDATE
2019-06-07 07:57:33,215 DEBUG org.apache.hadoop.yarn.server.resourcemanager.rmnode.RMNodeImpl: Processing slave2:42768 of type STATUS_UPDATE
2019-06-07 07:57:33,217 DEBUG org.apache.hadoop.yarn.server.resourcemanager.scheduler.capacity.CapacityScheduler: nodeUpdate: slave2:42768 clusterResources: <memory:8192, vCores:2>
2019-06-07 07:57:33,217 DEBUG org.apache.hadoop.yarn.server.resourcemanager.scheduler.capacity.CapacityScheduler: nodeUpdate: slave2:42768 clusterResources: <memory:8192, vCores:2>
2019-06-07 07:57:33,217 DEBUG org.apache.hadoop.yarn.server.resourcemanager.scheduler.capacity.CapacityScheduler: Node being looked for scheduling slave2:42768 availableResource: <memory:4096, vCores:1>
2019-06-07 07:57:33,217 DEBUG org.apache.hadoop.yarn.server.resourcemanager.scheduler.capacity.CapacityScheduler: Node being looked for scheduling slave2:42768 availableResource: <memory:4096, vCores:1>
2019-06-07 07:57:33,217 DEBUG org.apache.hadoop.yarn.server.resourcemanager.scheduler.capacity.CapacityScheduler: Trying to schedule on node: slave2, available: <memory:4096, vCores:1>
2019-06-07 07:57:33,217 DEBUG org.apache.hadoop.yarn.server.resourcemanager.scheduler.capacity.CapacityScheduler: Trying to schedule on node: slave2, available: <memory:4096, vCores:1>
2019-06-07 07:57:33,217 DEBUG org.apache.hadoop.yarn.server.resourcemanager.scheduler.capacity.ParentQueue: Skip this queue=root, because it doesn't need more resource, schedulingMode=RESPECT_PARTITION_EXCLUSIVITY node-partition=
2019-06-07 07:57:33,217 DEBUG org.apache.hadoop.yarn.server.resourcemanager.scheduler.capacity.ParentQueue: Skip this queue=root, because it doesn't need more resource, schedulingMode=RESPECT_PARTITION_EXCLUSIVITY node-partition=
2019-06-07 07:57:33,227 DEBUG org.apache.hadoop.yarn.server.resourcemanager.rmnode.RMNodeImpl: Processing slave1:34830 of type STATUS_UPDATE
2019-06-07 07:57:33,227 DEBUG org.apache.hadoop.yarn.server.resourcemanager.rmnode.RMNodeImpl: Processing slave1:34830 of type STATUS_UPDATE
2019-06-07 07:57:33,229 DEBUG org.apache.hadoop.yarn.server.resourcemanager.scheduler.capacity.CapacityScheduler: nodeUpdate: slave1:34830 clusterResources: <memory:8192, vCores:2>
2019-06-07 07:57:33,229 DEBUG org.apache.hadoop.yarn.server.resourcemanager.scheduler.capacity.CapacityScheduler: nodeUpdate: slave1:34830 clusterResources: <memory:8192, vCores:2>
2019-06-07 07:57:33,229 DEBUG org.apache.hadoop.yarn.server.resourcemanager.scheduler.capacity.CapacityScheduler: Node being looked for scheduling slave1:34830 availableResource: <memory:4096, vCores:1>
2019-06-07 07:57:33,229 DEBUG org.apache.hadoop.yarn.server.resourcemanager.scheduler.capacity.CapacityScheduler: Node being looked for scheduling slave1:34830 availableResource: <memory:4096, vCores:1>
2019-06-07 07:57:33,229 DEBUG org.apache.hadoop.yarn.server.resourcemanager.scheduler.capacity.CapacityScheduler: Trying to schedule on node: slave1, available: <memory:4096, vCores:1>
2019-06-07 07:57:33,229 DEBUG org.apache.hadoop.yarn.server.resourcemanager.scheduler.capacity.CapacityScheduler: Trying to schedule on node: slave1, available: <memory:4096, vCores:1>
2019-06-07 07:57:33,229 DEBUG org.apache.hadoop.yarn.server.resourcemanager.scheduler.capacity.ParentQueue: Skip this queue=root, because it doesn't need more resource, schedulingMode=RESPECT_PARTITION_EXCLUSIVITY node-partition=
2019-06-07 07:57:33,229 DEBUG org.apache.hadoop.yarn.server.resourcemanager.scheduler.capacity.ParentQueue: Skip this queue=root, because it doesn't need more resource, schedulingMode=RESPECT_PARTITION_EXCLUSIVITY node-partition=
2019-06-07 07:57:34,218 DEBUG org.apache.hadoop.yarn.server.resourcemanager.rmnode.RMNodeImpl: Processing slave2:42768 of type STATUS_UPDATE
2019-06-07 07:57:34,218 DEBUG org.apache.hadoop.yarn.server.resourcemanager.rmnode.RMNodeImpl: Processing slave2:42768 of type STATUS_UPDATE
2019-06-07 07:57:34,219 DEBUG org.apache.hadoop.yarn.server.resourcemanager.scheduler.capacity.CapacityScheduler: nodeUpdate: slave2:42768 clusterResources: <memory:8192, vCores:2>
2019-06-07 07:57:34,219 DEBUG org.apache.hadoop.yarn.server.resourcemanager.scheduler.capacity.CapacityScheduler: nodeUpdate: slave2:42768 clusterResources: <memory:8192, vCores:2>
2019-06-07 07:57:34,219 DEBUG org.apache.hadoop.yarn.server.resourcemanager.scheduler.capacity.CapacityScheduler: Node being looked for scheduling slave2:42768 availableResource: <memory:4096, vCores:1>
2019-06-07 07:57:34,219 DEBUG org.apache.hadoop.yarn.server.resourcemanager.scheduler.capacity.CapacityScheduler: Node being looked for scheduling slave2:42768 availableResource: <memory:4096, vCores:1>
2019-06-07 07:57:34,219 DEBUG org.apache.hadoop.yarn.server.resourcemanager.scheduler.capacity.CapacityScheduler: Trying to schedule on node: slave2, available: <memory:4096, vCores:1>
2019-06-07 07:57:34,219 DEBUG org.apache.hadoop.yarn.server.resourcemanager.scheduler.capacity.CapacityScheduler: Trying to schedule on node: slave2, available: <memory:4096, vCores:1>
2019-06-07 07:57:34,219 DEBUG org.apache.hadoop.yarn.server.resourcemanager.scheduler.capacity.ParentQueue: Skip this queue=root, because it doesn't need more resource, schedulingMode=RESPECT_PARTITION_EXCLUSIVITY node-partition=
2019-06-07 07:57:34,219 DEBUG org.apache.hadoop.yarn.server.resourcemanager.scheduler.capacity.ParentQueue: Skip this queue=root, because it doesn't need more resource, schedulingMode=RESPECT_PARTITION_EXCLUSIVITY node-partition=
2019-06-07 07:57:34,231 DEBUG org.apache.hadoop.yarn.server.resourcemanager.rmnode.RMNodeImpl: Processing slave1:34830 of type STATUS_UPDATE
2019-06-07 07:57:34,231 DEBUG org.apache.hadoop.yarn.server.resourcemanager.rmnode.RMNodeImpl: Processing slave1:34830 of type STATUS_UPDATE
2019-06-07 07:57:34,232 DEBUG org.apache.hadoop.yarn.server.resourcemanager.scheduler.capacity.CapacityScheduler: nodeUpdate: slave1:34830 clusterResources: <memory:8192, vCores:2>
2019-06-07 07:57:34,232 DEBUG org.apache.hadoop.yarn.server.resourcemanager.scheduler.capacity.CapacityScheduler: nodeUpdate: slave1:34830 clusterResources: <memory:8192, vCores:2>
2019-06-07 07:57:34,232 DEBUG org.apache.hadoop.yarn.server.resourcemanager.scheduler.capacity.CapacityScheduler: Node being looked for scheduling slave1:34830 availableResource: <memory:4096, vCores:1>
2019-06-07 07:57:34,232 DEBUG org.apache.hadoop.yarn.server.resourcemanager.scheduler.capacity.CapacityScheduler: Node being looked for scheduling slave1:34830 availableResource: <memory:4096, vCores:1>
2019-06-07 07:57:34,232 DEBUG org.apache.hadoop.yarn.server.resourcemanager.scheduler.capacity.CapacityScheduler: Trying to schedule on node: slave1, available: <memory:4096, vCores:1>
2019-06-07 07:57:34,232 DEBUG org.apache.hadoop.yarn.server.resourcemanager.scheduler.capacity.CapacityScheduler: Trying to schedule on node: slave1, available: <memory:4096, vCores:1>
2019-06-07 07:57:34,232 DEBUG org.apache.hadoop.yarn.server.resourcemanager.scheduler.capacity.ParentQueue: Skip this queue=root, because it doesn't need more resource, schedulingMode=RESPECT_PARTITION_EXCLUSIVITY node-partition=
2019-06-07 07:57:34,232 DEBUG org.apache.hadoop.yarn.server.resourcemanager.scheduler.capacity.ParentQueue: Skip this queue=root, because it doesn't need more resource, schedulingMode=RESPECT_PARTITION_EXCLUSIVITY node-partition=
2019-06-07 07:57:34,923 INFO org.apache.hadoop.yarn.server.resourcemanager.ClientRMService: Allocated new applicationId: 1
2019-06-07 07:57:34,923 INFO org.apache.hadoop.yarn.server.resourcemanager.ClientRMService: Allocated new applicationId: 1
2019-06-07 07:57:35,221 DEBUG org.apache.hadoop.yarn.server.resourcemanager.rmnode.RMNodeImpl: Processing slave2:42768 of type STATUS_UPDATE
2019-06-07 07:57:35,221 DEBUG org.apache.hadoop.yarn.server.resourcemanager.rmnode.RMNodeImpl: Processing slave2:42768 of type STATUS_UPDATE
2019-06-07 07:57:35,221 DEBUG org.apache.hadoop.yarn.server.resourcemanager.scheduler.capacity.CapacityScheduler: nodeUpdate: slave2:42768 clusterResources: <memory:8192, vCores:2>
2019-06-07 07:57:35,221 DEBUG org.apache.hadoop.yarn.server.resourcemanager.scheduler.capacity.CapacityScheduler: nodeUpdate: slave2:42768 clusterResources: <memory:8192, vCores:2>
2019-06-07 07:57:35,225 DEBUG org.apache.hadoop.yarn.server.resourcemanager.scheduler.capacity.CapacityScheduler: Node being looked for scheduling slave2:42768 availableResource: <memory:4096, vCores:1>
2019-06-07 07:57:35,225 DEBUG org.apache.hadoop.yarn.server.resourcemanager.scheduler.capacity.CapacityScheduler: Node being looked for scheduling slave2:42768 availableResource: <memory:4096, vCores:1>
2019-06-07 07:57:35,225 DEBUG org.apache.hadoop.yarn.server.resourcemanager.scheduler.capacity.CapacityScheduler: Trying to schedule on node: slave2, available: <memory:4096, vCores:1>
2019-06-07 07:57:35,225 DEBUG org.apache.hadoop.yarn.server.resourcemanager.scheduler.capacity.CapacityScheduler: Trying to schedule on node: slave2, available: <memory:4096, vCores:1>
2019-06-07 07:57:35,225 DEBUG org.apache.hadoop.yarn.server.resourcemanager.scheduler.capacity.ParentQueue: Skip this queue=root, because it doesn't need more resource, schedulingMode=RESPECT_PARTITION_EXCLUSIVITY node-partition=
2019-06-07 07:57:35,225 DEBUG org.apache.hadoop.yarn.server.resourcemanager.scheduler.capacity.ParentQueue: Skip this queue=root, because it doesn't need more resource, schedulingMode=RESPECT_PARTITION_EXCLUSIVITY node-partition=
2019-06-07 07:57:35,234 DEBUG org.apache.hadoop.yarn.server.resourcemanager.rmnode.RMNodeImpl: Processing slave1:34830 of type STATUS_UPDATE
2019-06-07 07:57:35,234 DEBUG org.apache.hadoop.yarn.server.resourcemanager.rmnode.RMNodeImpl: Processing slave1:34830 of type STATUS_UPDATE
2019-06-07 07:57:35,235 DEBUG org.apache.hadoop.yarn.server.resourcemanager.scheduler.capacity.CapacityScheduler: nodeUpdate: slave1:34830 clusterResources: <memory:8192, vCores:2>
2019-06-07 07:57:35,235 DEBUG org.apache.hadoop.yarn.server.resourcemanager.scheduler.capacity.CapacityScheduler: nodeUpdate: slave1:34830 clusterResources: <memory:8192, vCores:2>
2019-06-07 07:57:35,235 DEBUG org.apache.hadoop.yarn.server.resourcemanager.scheduler.capacity.CapacityScheduler: Node being looked for scheduling slave1:34830 availableResource: <memory:4096, vCores:1>
2019-06-07 07:57:35,235 DEBUG org.apache.hadoop.yarn.server.resourcemanager.scheduler.capacity.CapacityScheduler: Node being looked for scheduling slave1:34830 availableResource: <memory:4096, vCores:1>
2019-06-07 07:57:35,235 DEBUG org.apache.hadoop.yarn.server.resourcemanager.scheduler.capacity.CapacityScheduler: Trying to schedule on node: slave1, available: <memory:4096, vCores:1>
2019-06-07 07:57:35,235 DEBUG org.apache.hadoop.yarn.server.resourcemanager.scheduler.capacity.CapacityScheduler: Trying to schedule on node: slave1, available: <memory:4096, vCores:1>
2019-06-07 07:57:35,235 DEBUG org.apache.hadoop.yarn.server.resourcemanager.scheduler.capacity.ParentQueue: Skip this queue=root, because it doesn't need more resource, schedulingMode=RESPECT_PARTITION_EXCLUSIVITY node-partition=
2019-06-07 07:57:35,235 DEBUG org.apache.hadoop.yarn.server.resourcemanager.scheduler.capacity.ParentQueue: Skip this queue=root, because it doesn't need more resource, schedulingMode=RESPECT_PARTITION_EXCLUSIVITY node-partition=
2019-06-07 07:57:36,225 DEBUG org.apache.hadoop.yarn.server.resourcemanager.rmnode.RMNodeImpl: Processing slave2:42768 of type STATUS_UPDATE
2019-06-07 07:57:36,225 DEBUG org.apache.hadoop.yarn.server.resourcemanager.rmnode.RMNodeImpl: Processing slave2:42768 of type STATUS_UPDATE
2019-06-07 07:57:36,226 DEBUG org.apache.hadoop.yarn.server.resourcemanager.scheduler.capacity.CapacityScheduler: nodeUpdate: slave2:42768 clusterResources: <memory:8192, vCores:2>
2019-06-07 07:57:36,226 DEBUG org.apache.hadoop.yarn.server.resourcemanager.scheduler.capacity.CapacityScheduler: nodeUpdate: slave2:42768 clusterResources: <memory:8192, vCores:2>
2019-06-07 07:57:36,226 DEBUG org.apache.hadoop.yarn.server.resourcemanager.scheduler.capacity.CapacityScheduler: Node being looked for scheduling slave2:42768 availableResource: <memory:4096, vCores:1>
2019-06-07 07:57:36,226 DEBUG org.apache.hadoop.yarn.server.resourcemanager.scheduler.capacity.CapacityScheduler: Node being looked for scheduling slave2:42768 availableResource: <memory:4096, vCores:1>
2019-06-07 07:57:36,226 DEBUG org.apache.hadoop.yarn.server.resourcemanager.scheduler.capacity.CapacityScheduler: Trying to schedule on node: slave2, available: <memory:4096, vCores:1>
2019-06-07 07:57:36,226 DEBUG org.apache.hadoop.yarn.server.resourcemanager.scheduler.capacity.CapacityScheduler: Trying to schedule on node: slave2, available: <memory:4096, vCores:1>
2019-06-07 07:57:36,226 DEBUG org.apache.hadoop.yarn.server.resourcemanager.scheduler.capacity.ParentQueue: Skip this queue=root, because it doesn't need more resource, schedulingMode=RESPECT_PARTITION_EXCLUSIVITY node-partition=
2019-06-07 07:57:36,226 DEBUG org.apache.hadoop.yarn.server.resourcemanager.scheduler.capacity.ParentQueue: Skip this queue=root, because it doesn't need more resource, schedulingMode=RESPECT_PARTITION_EXCLUSIVITY node-partition=
2019-06-07 07:57:36,237 DEBUG org.apache.hadoop.yarn.server.resourcemanager.rmnode.RMNodeImpl: Processing slave1:34830 of type STATUS_UPDATE
2019-06-07 07:57:36,237 DEBUG org.apache.hadoop.yarn.server.resourcemanager.rmnode.RMNodeImpl: Processing slave1:34830 of type STATUS_UPDATE
2019-06-07 07:57:36,238 DEBUG org.apache.hadoop.yarn.server.resourcemanager.scheduler.capacity.CapacityScheduler: nodeUpdate: slave1:34830 clusterResources: <memory:8192, vCores:2>
2019-06-07 07:57:36,238 DEBUG org.apache.hadoop.yarn.server.resourcemanager.scheduler.capacity.CapacityScheduler: nodeUpdate: slave1:34830 clusterResources: <memory:8192, vCores:2>
2019-06-07 07:57:36,238 DEBUG org.apache.hadoop.yarn.server.resourcemanager.scheduler.capacity.CapacityScheduler: Node being looked for scheduling slave1:34830 availableResource: <memory:4096, vCores:1>
2019-06-07 07:57:36,238 DEBUG org.apache.hadoop.yarn.server.resourcemanager.scheduler.capacity.CapacityScheduler: Node being looked for scheduling slave1:34830 availableResource: <memory:4096, vCores:1>
2019-06-07 07:57:36,238 DEBUG org.apache.hadoop.yarn.server.resourcemanager.scheduler.capacity.CapacityScheduler: Trying to schedule on node: slave1, available: <memory:4096, vCores:1>
2019-06-07 07:57:36,238 DEBUG org.apache.hadoop.yarn.server.resourcemanager.scheduler.capacity.CapacityScheduler: Trying to schedule on node: slave1, available: <memory:4096, vCores:1>
2019-06-07 07:57:36,238 DEBUG org.apache.hadoop.yarn.server.resourcemanager.scheduler.capacity.ParentQueue: Skip this queue=root, because it doesn't need more resource, schedulingMode=RESPECT_PARTITION_EXCLUSIVITY node-partition=
2019-06-07 07:57:36,238 DEBUG org.apache.hadoop.yarn.server.resourcemanager.scheduler.capacity.ParentQueue: Skip this queue=root, because it doesn't need more resource, schedulingMode=RESPECT_PARTITION_EXCLUSIVITY node-partition=
2019-06-07 07:57:37,229 DEBUG org.apache.hadoop.yarn.server.resourcemanager.rmnode.RMNodeImpl: Processing slave2:42768 of type STATUS_UPDATE
2019-06-07 07:57:37,229 DEBUG org.apache.hadoop.yarn.server.resourcemanager.rmnode.RMNodeImpl: Processing slave2:42768 of type STATUS_UPDATE
2019-06-07 07:57:37,230 DEBUG org.apache.hadoop.yarn.server.resourcemanager.scheduler.capacity.CapacityScheduler: nodeUpdate: slave2:42768 clusterResources: <memory:8192, vCores:2>
2019-06-07 07:57:37,230 DEBUG org.apache.hadoop.yarn.server.resourcemanager.scheduler.capacity.CapacityScheduler: nodeUpdate: slave2:42768 clusterResources: <memory:8192, vCores:2>
2019-06-07 07:57:37,230 DEBUG org.apache.hadoop.yarn.server.resourcemanager.scheduler.capacity.CapacityScheduler: Node being looked for scheduling slave2:42768 availableResource: <memory:4096, vCores:1>
2019-06-07 07:57:37,230 DEBUG org.apache.hadoop.yarn.server.resourcemanager.scheduler.capacity.CapacityScheduler: Node being looked for scheduling slave2:42768 availableResource: <memory:4096, vCores:1>
2019-06-07 07:57:37,230 DEBUG org.apache.hadoop.yarn.server.resourcemanager.scheduler.capacity.CapacityScheduler: Trying to schedule on node: slave2, available: <memory:4096, vCores:1>
2019-06-07 07:57:37,230 DEBUG org.apache.hadoop.yarn.server.resourcemanager.scheduler.capacity.CapacityScheduler: Trying to schedule on node: slave2, available: <memory:4096, vCores:1>
2019-06-07 07:57:37,230 DEBUG org.apache.hadoop.yarn.server.resourcemanager.scheduler.capacity.ParentQueue: Skip this queue=root, because it doesn't need more resource, schedulingMode=RESPECT_PARTITION_EXCLUSIVITY node-partition=
2019-06-07 07:57:37,230 DEBUG org.apache.hadoop.yarn.server.resourcemanager.scheduler.capacity.ParentQueue: Skip this queue=root, because it doesn't need more resource, schedulingMode=RESPECT_PARTITION_EXCLUSIVITY node-partition=
2019-06-07 07:57:37,244 DEBUG org.apache.hadoop.yarn.server.resourcemanager.rmnode.RMNodeImpl: Processing slave1:34830 of type STATUS_UPDATE
2019-06-07 07:57:37,244 DEBUG org.apache.hadoop.yarn.server.resourcemanager.rmnode.RMNodeImpl: Processing slave1:34830 of type STATUS_UPDATE
2019-06-07 07:57:37,244 DEBUG org.apache.hadoop.yarn.server.resourcemanager.scheduler.capacity.CapacityScheduler: nodeUpdate: slave1:34830 clusterResources: <memory:8192, vCores:2>
2019-06-07 07:57:37,244 DEBUG org.apache.hadoop.yarn.server.resourcemanager.scheduler.capacity.CapacityScheduler: nodeUpdate: slave1:34830 clusterResources: <memory:8192, vCores:2>
2019-06-07 07:57:37,244 DEBUG org.apache.hadoop.yarn.server.resourcemanager.scheduler.capacity.CapacityScheduler: Node being looked for scheduling slave1:34830 availableResource: <memory:4096, vCores:1>
2019-06-07 07:57:37,244 DEBUG org.apache.hadoop.yarn.server.resourcemanager.scheduler.capacity.CapacityScheduler: Node being looked for scheduling slave1:34830 availableResource: <memory:4096, vCores:1>
2019-06-07 07:57:37,245 DEBUG org.apache.hadoop.yarn.server.resourcemanager.scheduler.capacity.CapacityScheduler: Trying to schedule on node: slave1, available: <memory:4096, vCores:1>
2019-06-07 07:57:37,245 DEBUG org.apache.hadoop.yarn.server.resourcemanager.scheduler.capacity.CapacityScheduler: Trying to schedule on node: slave1, available: <memory:4096, vCores:1>
2019-06-07 07:57:37,245 DEBUG org.apache.hadoop.yarn.server.resourcemanager.scheduler.capacity.ParentQueue: Skip this queue=root, because it doesn't need more resource, schedulingMode=RESPECT_PARTITION_EXCLUSIVITY node-partition=
2019-06-07 07:57:37,245 DEBUG org.apache.hadoop.yarn.server.resourcemanager.scheduler.capacity.ParentQueue: Skip this queue=root, because it doesn't need more resource, schedulingMode=RESPECT_PARTITION_EXCLUSIVITY node-partition=
2019-06-07 07:57:38,232 DEBUG org.apache.hadoop.yarn.server.resourcemanager.rmnode.RMNodeImpl: Processing slave2:42768 of type STATUS_UPDATE
2019-06-07 07:57:38,232 DEBUG org.apache.hadoop.yarn.server.resourcemanager.rmnode.RMNodeImpl: Processing slave2:42768 of type STATUS_UPDATE
2019-06-07 07:57:38,233 DEBUG org.apache.hadoop.yarn.server.resourcemanager.scheduler.capacity.CapacityScheduler: nodeUpdate: slave2:42768 clusterResources: <memory:8192, vCores:2>
2019-06-07 07:57:38,233 DEBUG org.apache.hadoop.yarn.server.resourcemanager.scheduler.capacity.CapacityScheduler: nodeUpdate: slave2:42768 clusterResources: <memory:8192, vCores:2>
2019-06-07 07:57:38,233 DEBUG org.apache.hadoop.yarn.server.resourcemanager.scheduler.capacity.CapacityScheduler: Node being looked for scheduling slave2:42768 availableResource: <memory:4096, vCores:1>
2019-06-07 07:57:38,233 DEBUG org.apache.hadoop.yarn.server.resourcemanager.scheduler.capacity.CapacityScheduler: Node being looked for scheduling slave2:42768 availableResource: <memory:4096, vCores:1>
2019-06-07 07:57:38,233 DEBUG org.apache.hadoop.yarn.server.resourcemanager.scheduler.capacity.CapacityScheduler: Trying to schedule on node: slave2, available: <memory:4096, vCores:1>
2019-06-07 07:57:38,233 DEBUG org.apache.hadoop.yarn.server.resourcemanager.scheduler.capacity.CapacityScheduler: Trying to schedule on node: slave2, available: <memory:4096, vCores:1>
2019-06-07 07:57:38,233 DEBUG org.apache.hadoop.yarn.server.resourcemanager.scheduler.capacity.ParentQueue: Skip this queue=root, because it doesn't need more resource, schedulingMode=RESPECT_PARTITION_EXCLUSIVITY node-partition=
2019-06-07 07:57:38,233 DEBUG org.apache.hadoop.yarn.server.resourcemanager.scheduler.capacity.ParentQueue: Skip this queue=root, because it doesn't need more resource, schedulingMode=RESPECT_PARTITION_EXCLUSIVITY node-partition=
2019-06-07 07:57:38,249 DEBUG org.apache.hadoop.yarn.server.resourcemanager.rmnode.RMNodeImpl: Processing slave1:34830 of type STATUS_UPDATE
2019-06-07 07:57:38,249 DEBUG org.apache.hadoop.yarn.server.resourcemanager.rmnode.RMNodeImpl: Processing slave1:34830 of type STATUS_UPDATE
2019-06-07 07:57:38,250 DEBUG org.apache.hadoop.yarn.server.resourcemanager.scheduler.capacity.CapacityScheduler: nodeUpdate: slave1:34830 clusterResources: <memory:8192, vCores:2>
2019-06-07 07:57:38,250 DEBUG org.apache.hadoop.yarn.server.resourcemanager.scheduler.capacity.CapacityScheduler: nodeUpdate: slave1:34830 clusterResources: <memory:8192, vCores:2>
2019-06-07 07:57:38,250 DEBUG org.apache.hadoop.yarn.server.resourcemanager.scheduler.capacity.CapacityScheduler: Node being looked for scheduling slave1:34830 availableResource: <memory:4096, vCores:1>
2019-06-07 07:57:38,250 DEBUG org.apache.hadoop.yarn.server.resourcemanager.scheduler.capacity.CapacityScheduler: Node being looked for scheduling slave1:34830 availableResource: <memory:4096, vCores:1>
2019-06-07 07:57:38,250 DEBUG org.apache.hadoop.yarn.server.resourcemanager.scheduler.capacity.CapacityScheduler: Trying to schedule on node: slave1, available: <memory:4096, vCores:1>
2019-06-07 07:57:38,250 DEBUG org.apache.hadoop.yarn.server.resourcemanager.scheduler.capacity.CapacityScheduler: Trying to schedule on node: slave1, available: <memory:4096, vCores:1>
2019-06-07 07:57:38,250 DEBUG org.apache.hadoop.yarn.server.resourcemanager.scheduler.capacity.ParentQueue: Skip this queue=root, because it doesn't need more resource, schedulingMode=RESPECT_PARTITION_EXCLUSIVITY node-partition=
2019-06-07 07:57:38,250 DEBUG org.apache.hadoop.yarn.server.resourcemanager.scheduler.capacity.ParentQueue: Skip this queue=root, because it doesn't need more resource, schedulingMode=RESPECT_PARTITION_EXCLUSIVITY node-partition=
2019-06-07 07:57:39,238 DEBUG org.apache.hadoop.yarn.server.resourcemanager.rmnode.RMNodeImpl: Processing slave2:42768 of type STATUS_UPDATE
2019-06-07 07:57:39,238 DEBUG org.apache.hadoop.yarn.server.resourcemanager.rmnode.RMNodeImpl: Processing slave2:42768 of type STATUS_UPDATE
2019-06-07 07:57:39,239 DEBUG org.apache.hadoop.yarn.server.resourcemanager.scheduler.capacity.CapacityScheduler: nodeUpdate: slave2:42768 clusterResources: <memory:8192, vCores:2>
2019-06-07 07:57:39,239 DEBUG org.apache.hadoop.yarn.server.resourcemanager.scheduler.capacity.CapacityScheduler: nodeUpdate: slave2:42768 clusterResources: <memory:8192, vCores:2>
2019-06-07 07:57:39,239 DEBUG org.apache.hadoop.yarn.server.resourcemanager.scheduler.capacity.CapacityScheduler: Node being looked for scheduling slave2:42768 availableResource: <memory:4096, vCores:1>
2019-06-07 07:57:39,239 DEBUG org.apache.hadoop.yarn.server.resourcemanager.scheduler.capacity.CapacityScheduler: Node being looked for scheduling slave2:42768 availableResource: <memory:4096, vCores:1>
2019-06-07 07:57:39,239 DEBUG org.apache.hadoop.yarn.server.resourcemanager.scheduler.capacity.CapacityScheduler: Trying to schedule on node: slave2, available: <memory:4096, vCores:1>
2019-06-07 07:57:39,239 DEBUG org.apache.hadoop.yarn.server.resourcemanager.scheduler.capacity.CapacityScheduler: Trying to schedule on node: slave2, available: <memory:4096, vCores:1>
2019-06-07 07:57:39,240 DEBUG org.apache.hadoop.yarn.server.resourcemanager.scheduler.capacity.ParentQueue: Skip this queue=root, because it doesn't need more resource, schedulingMode=RESPECT_PARTITION_EXCLUSIVITY node-partition=
2019-06-07 07:57:39,240 DEBUG org.apache.hadoop.yarn.server.resourcemanager.scheduler.capacity.ParentQueue: Skip this queue=root, because it doesn't need more resource, schedulingMode=RESPECT_PARTITION_EXCLUSIVITY node-partition=
2019-06-07 07:57:39,252 DEBUG org.apache.hadoop.yarn.server.resourcemanager.rmnode.RMNodeImpl: Processing slave1:34830 of type STATUS_UPDATE
2019-06-07 07:57:39,252 DEBUG org.apache.hadoop.yarn.server.resourcemanager.rmnode.RMNodeImpl: Processing slave1:34830 of type STATUS_UPDATE
2019-06-07 07:57:39,254 DEBUG org.apache.hadoop.yarn.server.resourcemanager.scheduler.capacity.CapacityScheduler: nodeUpdate: slave1:34830 clusterResources: <memory:8192, vCores:2>
2019-06-07 07:57:39,254 DEBUG org.apache.hadoop.yarn.server.resourcemanager.scheduler.capacity.CapacityScheduler: nodeUpdate: slave1:34830 clusterResources: <memory:8192, vCores:2>
2019-06-07 07:57:39,254 DEBUG org.apache.hadoop.yarn.server.resourcemanager.scheduler.capacity.CapacityScheduler: Node being looked for scheduling slave1:34830 availableResource: <memory:4096, vCores:1>
2019-06-07 07:57:39,254 DEBUG org.apache.hadoop.yarn.server.resourcemanager.scheduler.capacity.CapacityScheduler: Node being looked for scheduling slave1:34830 availableResource: <memory:4096, vCores:1>
2019-06-07 07:57:39,254 DEBUG org.apache.hadoop.yarn.server.resourcemanager.scheduler.capacity.CapacityScheduler: Trying to schedule on node: slave1, available: <memory:4096, vCores:1>
2019-06-07 07:57:39,254 DEBUG org.apache.hadoop.yarn.server.resourcemanager.scheduler.capacity.CapacityScheduler: Trying to schedule on node: slave1, available: <memory:4096, vCores:1>
2019-06-07 07:57:39,254 DEBUG org.apache.hadoop.yarn.server.resourcemanager.scheduler.capacity.ParentQueue: Skip this queue=root, because it doesn't need more resource, schedulingMode=RESPECT_PARTITION_EXCLUSIVITY node-partition=
2019-06-07 07:57:39,254 DEBUG org.apache.hadoop.yarn.server.resourcemanager.scheduler.capacity.ParentQueue: Skip this queue=root, because it doesn't need more resource, schedulingMode=RESPECT_PARTITION_EXCLUSIVITY node-partition=
2019-06-07 07:57:40,241 DEBUG org.apache.hadoop.yarn.server.resourcemanager.rmnode.RMNodeImpl: Processing slave2:42768 of type STATUS_UPDATE
2019-06-07 07:57:40,241 DEBUG org.apache.hadoop.yarn.server.resourcemanager.rmnode.RMNodeImpl: Processing slave2:42768 of type STATUS_UPDATE
2019-06-07 07:57:40,242 DEBUG org.apache.hadoop.yarn.server.resourcemanager.scheduler.capacity.CapacityScheduler: nodeUpdate: slave2:42768 clusterResources: <memory:8192, vCores:2>
2019-06-07 07:57:40,242 DEBUG org.apache.hadoop.yarn.server.resourcemanager.scheduler.capacity.CapacityScheduler: nodeUpdate: slave2:42768 clusterResources: <memory:8192, vCores:2>
2019-06-07 07:57:40,242 DEBUG org.apache.hadoop.yarn.server.resourcemanager.scheduler.capacity.CapacityScheduler: Node being looked for scheduling slave2:42768 availableResource: <memory:4096, vCores:1>
2019-06-07 07:57:40,242 DEBUG org.apache.hadoop.yarn.server.resourcemanager.scheduler.capacity.CapacityScheduler: Node being looked for scheduling slave2:42768 availableResource: <memory:4096, vCores:1>
2019-06-07 07:57:40,242 DEBUG org.apache.hadoop.yarn.server.resourcemanager.scheduler.capacity.CapacityScheduler: Trying to schedule on node: slave2, available: <memory:4096, vCores:1>
2019-06-07 07:57:40,242 DEBUG org.apache.hadoop.yarn.server.resourcemanager.scheduler.capacity.CapacityScheduler: Trying to schedule on node: slave2, available: <memory:4096, vCores:1>
2019-06-07 07:57:40,242 DEBUG org.apache.hadoop.yarn.server.resourcemanager.scheduler.capacity.ParentQueue: Skip this queue=root, because it doesn't need more resource, schedulingMode=RESPECT_PARTITION_EXCLUSIVITY node-partition=
2019-06-07 07:57:40,242 DEBUG org.apache.hadoop.yarn.server.resourcemanager.scheduler.capacity.ParentQueue: Skip this queue=root, because it doesn't need more resource, schedulingMode=RESPECT_PARTITION_EXCLUSIVITY node-partition=
2019-06-07 07:57:40,257 DEBUG org.apache.hadoop.yarn.server.resourcemanager.rmnode.RMNodeImpl: Processing slave1:34830 of type STATUS_UPDATE
2019-06-07 07:57:40,257 DEBUG org.apache.hadoop.yarn.server.resourcemanager.rmnode.RMNodeImpl: Processing slave1:34830 of type STATUS_UPDATE
2019-06-07 07:57:40,257 DEBUG org.apache.hadoop.yarn.server.resourcemanager.scheduler.capacity.CapacityScheduler: nodeUpdate: slave1:34830 clusterResources: <memory:8192, vCores:2>
2019-06-07 07:57:40,257 DEBUG org.apache.hadoop.yarn.server.resourcemanager.scheduler.capacity.CapacityScheduler: nodeUpdate: slave1:34830 clusterResources: <memory:8192, vCores:2>
2019-06-07 07:57:40,257 DEBUG org.apache.hadoop.yarn.server.resourcemanager.scheduler.capacity.CapacityScheduler: Node being looked for scheduling slave1:34830 availableResource: <memory:4096, vCores:1>
2019-06-07 07:57:40,257 DEBUG org.apache.hadoop.yarn.server.resourcemanager.scheduler.capacity.CapacityScheduler: Node being looked for scheduling slave1:34830 availableResource: <memory:4096, vCores:1>
2019-06-07 07:57:40,257 DEBUG org.apache.hadoop.yarn.server.resourcemanager.scheduler.capacity.CapacityScheduler: Trying to schedule on node: slave1, available: <memory:4096, vCores:1>
2019-06-07 07:57:40,257 DEBUG org.apache.hadoop.yarn.server.resourcemanager.scheduler.capacity.CapacityScheduler: Trying to schedule on node: slave1, available: <memory:4096, vCores:1>
2019-06-07 07:57:40,258 DEBUG org.apache.hadoop.yarn.server.resourcemanager.scheduler.capacity.ParentQueue: Skip this queue=root, because it doesn't need more resource, schedulingMode=RESPECT_PARTITION_EXCLUSIVITY node-partition=
2019-06-07 07:57:40,258 DEBUG org.apache.hadoop.yarn.server.resourcemanager.scheduler.capacity.ParentQueue: Skip this queue=root, because it doesn't need more resource, schedulingMode=RESPECT_PARTITION_EXCLUSIVITY node-partition=
2019-06-07 07:57:41,246 DEBUG org.apache.hadoop.yarn.server.resourcemanager.rmnode.RMNodeImpl: Processing slave2:42768 of type STATUS_UPDATE
2019-06-07 07:57:41,246 DEBUG org.apache.hadoop.yarn.server.resourcemanager.rmnode.RMNodeImpl: Processing slave2:42768 of type STATUS_UPDATE
2019-06-07 07:57:41,246 DEBUG org.apache.hadoop.yarn.server.resourcemanager.scheduler.capacity.CapacityScheduler: nodeUpdate: slave2:42768 clusterResources: <memory:8192, vCores:2>
2019-06-07 07:57:41,246 DEBUG org.apache.hadoop.yarn.server.resourcemanager.scheduler.capacity.CapacityScheduler: nodeUpdate: slave2:42768 clusterResources: <memory:8192, vCores:2>
2019-06-07 07:57:41,247 DEBUG org.apache.hadoop.yarn.server.resourcemanager.scheduler.capacity.CapacityScheduler: Node being looked for scheduling slave2:42768 availableResource: <memory:4096, vCores:1>
2019-06-07 07:57:41,247 DEBUG org.apache.hadoop.yarn.server.resourcemanager.scheduler.capacity.CapacityScheduler: Node being looked for scheduling slave2:42768 availableResource: <memory:4096, vCores:1>
2019-06-07 07:57:41,247 DEBUG org.apache.hadoop.yarn.server.resourcemanager.scheduler.capacity.CapacityScheduler: Trying to schedule on node: slave2, available: <memory:4096, vCores:1>
2019-06-07 07:57:41,247 DEBUG org.apache.hadoop.yarn.server.resourcemanager.scheduler.capacity.CapacityScheduler: Trying to schedule on node: slave2, available: <memory:4096, vCores:1>
2019-06-07 07:57:41,247 DEBUG org.apache.hadoop.yarn.server.resourcemanager.scheduler.capacity.ParentQueue: Skip this queue=root, because it doesn't need more resource, schedulingMode=RESPECT_PARTITION_EXCLUSIVITY node-partition=
2019-06-07 07:57:41,247 DEBUG org.apache.hadoop.yarn.server.resourcemanager.scheduler.capacity.ParentQueue: Skip this queue=root, because it doesn't need more resource, schedulingMode=RESPECT_PARTITION_EXCLUSIVITY node-partition=
2019-06-07 07:57:41,266 DEBUG org.apache.hadoop.yarn.server.resourcemanager.rmnode.RMNodeImpl: Processing slave1:34830 of type STATUS_UPDATE
2019-06-07 07:57:41,266 DEBUG org.apache.hadoop.yarn.server.resourcemanager.rmnode.RMNodeImpl: Processing slave1:34830 of type STATUS_UPDATE
2019-06-07 07:57:41,268 DEBUG org.apache.hadoop.yarn.server.resourcemanager.scheduler.capacity.CapacityScheduler: nodeUpdate: slave1:34830 clusterResources: <memory:8192, vCores:2>
2019-06-07 07:57:41,268 DEBUG org.apache.hadoop.yarn.server.resourcemanager.scheduler.capacity.CapacityScheduler: nodeUpdate: slave1:34830 clusterResources: <memory:8192, vCores:2>
2019-06-07 07:57:41,268 DEBUG org.apache.hadoop.yarn.server.resourcemanager.scheduler.capacity.CapacityScheduler: Node being looked for scheduling slave1:34830 availableResource: <memory:4096, vCores:1>
2019-06-07 07:57:41,268 DEBUG org.apache.hadoop.yarn.server.resourcemanager.scheduler.capacity.CapacityScheduler: Node being looked for scheduling slave1:34830 availableResource: <memory:4096, vCores:1>
2019-06-07 07:57:41,268 DEBUG org.apache.hadoop.yarn.server.resourcemanager.scheduler.capacity.CapacityScheduler: Trying to schedule on node: slave1, available: <memory:4096, vCores:1>
2019-06-07 07:57:41,268 DEBUG org.apache.hadoop.yarn.server.resourcemanager.scheduler.capacity.CapacityScheduler: Trying to schedule on node: slave1, available: <memory:4096, vCores:1>
2019-06-07 07:57:41,268 DEBUG org.apache.hadoop.yarn.server.resourcemanager.scheduler.capacity.ParentQueue: Skip this queue=root, because it doesn't need more resource, schedulingMode=RESPECT_PARTITION_EXCLUSIVITY node-partition=
2019-06-07 07:57:41,268 DEBUG org.apache.hadoop.yarn.server.resourcemanager.scheduler.capacity.ParentQueue: Skip this queue=root, because it doesn't need more resource, schedulingMode=RESPECT_PARTITION_EXCLUSIVITY node-partition=
2019-06-07 07:57:42,254 DEBUG org.apache.hadoop.yarn.server.resourcemanager.rmnode.RMNodeImpl: Processing slave2:42768 of type STATUS_UPDATE
2019-06-07 07:57:42,254 DEBUG org.apache.hadoop.yarn.server.resourcemanager.rmnode.RMNodeImpl: Processing slave2:42768 of type STATUS_UPDATE
2019-06-07 07:57:42,254 DEBUG org.apache.hadoop.yarn.server.resourcemanager.scheduler.capacity.CapacityScheduler: nodeUpdate: slave2:42768 clusterResources: <memory:8192, vCores:2>
2019-06-07 07:57:42,254 DEBUG org.apache.hadoop.yarn.server.resourcemanager.scheduler.capacity.CapacityScheduler: nodeUpdate: slave2:42768 clusterResources: <memory:8192, vCores:2>
2019-06-07 07:57:42,254 DEBUG org.apache.hadoop.yarn.server.resourcemanager.scheduler.capacity.CapacityScheduler: Node being looked for scheduling slave2:42768 availableResource: <memory:4096, vCores:1>
2019-06-07 07:57:42,254 DEBUG org.apache.hadoop.yarn.server.resourcemanager.scheduler.capacity.CapacityScheduler: Node being looked for scheduling slave2:42768 availableResource: <memory:4096, vCores:1>
2019-06-07 07:57:42,255 DEBUG org.apache.hadoop.yarn.server.resourcemanager.scheduler.capacity.CapacityScheduler: Trying to schedule on node: slave2, available: <memory:4096, vCores:1>
2019-06-07 07:57:42,255 DEBUG org.apache.hadoop.yarn.server.resourcemanager.scheduler.capacity.CapacityScheduler: Trying to schedule on node: slave2, available: <memory:4096, vCores:1>
2019-06-07 07:57:42,255 DEBUG org.apache.hadoop.yarn.server.resourcemanager.scheduler.capacity.ParentQueue: Skip this queue=root, because it doesn't need more resource, schedulingMode=RESPECT_PARTITION_EXCLUSIVITY node-partition=
2019-06-07 07:57:42,255 DEBUG org.apache.hadoop.yarn.server.resourcemanager.scheduler.capacity.ParentQueue: Skip this queue=root, because it doesn't need more resource, schedulingMode=RESPECT_PARTITION_EXCLUSIVITY node-partition=
2019-06-07 07:57:42,275 DEBUG org.apache.hadoop.yarn.server.resourcemanager.rmnode.RMNodeImpl: Processing slave1:34830 of type STATUS_UPDATE
2019-06-07 07:57:42,275 DEBUG org.apache.hadoop.yarn.server.resourcemanager.rmnode.RMNodeImpl: Processing slave1:34830 of type STATUS_UPDATE
2019-06-07 07:57:42,276 DEBUG org.apache.hadoop.yarn.server.resourcemanager.scheduler.capacity.CapacityScheduler: nodeUpdate: slave1:34830 clusterResources: <memory:8192, vCores:2>
2019-06-07 07:57:42,276 DEBUG org.apache.hadoop.yarn.server.resourcemanager.scheduler.capacity.CapacityScheduler: nodeUpdate: slave1:34830 clusterResources: <memory:8192, vCores:2>
2019-06-07 07:57:42,276 DEBUG org.apache.hadoop.yarn.server.resourcemanager.scheduler.capacity.CapacityScheduler: Node being looked for scheduling slave1:34830 availableResource: <memory:4096, vCores:1>
2019-06-07 07:57:42,276 DEBUG org.apache.hadoop.yarn.server.resourcemanager.scheduler.capacity.CapacityScheduler: Node being looked for scheduling slave1:34830 availableResource: <memory:4096, vCores:1>
2019-06-07 07:57:42,276 DEBUG org.apache.hadoop.yarn.server.resourcemanager.scheduler.capacity.CapacityScheduler: Trying to schedule on node: slave1, available: <memory:4096, vCores:1>
2019-06-07 07:57:42,276 DEBUG org.apache.hadoop.yarn.server.resourcemanager.scheduler.capacity.CapacityScheduler: Trying to schedule on node: slave1, available: <memory:4096, vCores:1>
2019-06-07 07:57:42,276 DEBUG org.apache.hadoop.yarn.server.resourcemanager.scheduler.capacity.ParentQueue: Skip this queue=root, because it doesn't need more resource, schedulingMode=RESPECT_PARTITION_EXCLUSIVITY node-partition=
2019-06-07 07:57:42,276 DEBUG org.apache.hadoop.yarn.server.resourcemanager.scheduler.capacity.ParentQueue: Skip this queue=root, because it doesn't need more resource, schedulingMode=RESPECT_PARTITION_EXCLUSIVITY node-partition=
2019-06-07 07:57:43,256 DEBUG org.apache.hadoop.yarn.server.resourcemanager.rmnode.RMNodeImpl: Processing slave2:42768 of type STATUS_UPDATE
2019-06-07 07:57:43,256 DEBUG org.apache.hadoop.yarn.server.resourcemanager.rmnode.RMNodeImpl: Processing slave2:42768 of type STATUS_UPDATE
2019-06-07 07:57:43,257 DEBUG org.apache.hadoop.yarn.server.resourcemanager.scheduler.capacity.CapacityScheduler: nodeUpdate: slave2:42768 clusterResources: <memory:8192, vCores:2>
2019-06-07 07:57:43,257 DEBUG org.apache.hadoop.yarn.server.resourcemanager.scheduler.capacity.CapacityScheduler: nodeUpdate: slave2:42768 clusterResources: <memory:8192, vCores:2>
2019-06-07 07:57:43,257 DEBUG org.apache.hadoop.yarn.server.resourcemanager.scheduler.capacity.CapacityScheduler: Node being looked for scheduling slave2:42768 availableResource: <memory:4096, vCores:1>
2019-06-07 07:57:43,257 DEBUG org.apache.hadoop.yarn.server.resourcemanager.scheduler.capacity.CapacityScheduler: Node being looked for scheduling slave2:42768 availableResource: <memory:4096, vCores:1>
2019-06-07 07:57:43,258 DEBUG org.apache.hadoop.yarn.server.resourcemanager.scheduler.capacity.CapacityScheduler: Trying to schedule on node: slave2, available: <memory:4096, vCores:1>
2019-06-07 07:57:43,258 DEBUG org.apache.hadoop.yarn.server.resourcemanager.scheduler.capacity.CapacityScheduler: Trying to schedule on node: slave2, available: <memory:4096, vCores:1>
2019-06-07 07:57:43,258 DEBUG org.apache.hadoop.yarn.server.resourcemanager.scheduler.capacity.ParentQueue: Skip this queue=root, because it doesn't need more resource, schedulingMode=RESPECT_PARTITION_EXCLUSIVITY node-partition=
2019-06-07 07:57:43,258 DEBUG org.apache.hadoop.yarn.server.resourcemanager.scheduler.capacity.ParentQueue: Skip this queue=root, because it doesn't need more resource, schedulingMode=RESPECT_PARTITION_EXCLUSIVITY node-partition=
2019-06-07 07:57:43,280 DEBUG org.apache.hadoop.yarn.server.resourcemanager.rmnode.RMNodeImpl: Processing slave1:34830 of type STATUS_UPDATE
2019-06-07 07:57:43,280 DEBUG org.apache.hadoop.yarn.server.resourcemanager.rmnode.RMNodeImpl: Processing slave1:34830 of type STATUS_UPDATE
2019-06-07 07:57:43,283 DEBUG org.apache.hadoop.yarn.server.resourcemanager.scheduler.capacity.CapacityScheduler: nodeUpdate: slave1:34830 clusterResources: <memory:8192, vCores:2>
2019-06-07 07:57:43,283 DEBUG org.apache.hadoop.yarn.server.resourcemanager.scheduler.capacity.CapacityScheduler: nodeUpdate: slave1:34830 clusterResources: <memory:8192, vCores:2>
2019-06-07 07:57:43,284 DEBUG org.apache.hadoop.yarn.server.resourcemanager.scheduler.capacity.CapacityScheduler: Node being looked for scheduling slave1:34830 availableResource: <memory:4096, vCores:1>
2019-06-07 07:57:43,284 DEBUG org.apache.hadoop.yarn.server.resourcemanager.scheduler.capacity.CapacityScheduler: Node being looked for scheduling slave1:34830 availableResource: <memory:4096, vCores:1>
2019-06-07 07:57:43,284 DEBUG org.apache.hadoop.yarn.server.resourcemanager.scheduler.capacity.CapacityScheduler: Trying to schedule on node: slave1, available: <memory:4096, vCores:1>
2019-06-07 07:57:43,284 DEBUG org.apache.hadoop.yarn.server.resourcemanager.scheduler.capacity.CapacityScheduler: Trying to schedule on node: slave1, available: <memory:4096, vCores:1>
2019-06-07 07:57:43,284 DEBUG org.apache.hadoop.yarn.server.resourcemanager.scheduler.capacity.ParentQueue: Skip this queue=root, because it doesn't need more resource, schedulingMode=RESPECT_PARTITION_EXCLUSIVITY node-partition=
2019-06-07 07:57:43,284 DEBUG org.apache.hadoop.yarn.server.resourcemanager.scheduler.capacity.ParentQueue: Skip this queue=root, because it doesn't need more resource, schedulingMode=RESPECT_PARTITION_EXCLUSIVITY node-partition=
2019-06-07 07:57:44,268 DEBUG org.apache.hadoop.yarn.server.resourcemanager.rmnode.RMNodeImpl: Processing slave2:42768 of type STATUS_UPDATE
2019-06-07 07:57:44,268 DEBUG org.apache.hadoop.yarn.server.resourcemanager.rmnode.RMNodeImpl: Processing slave2:42768 of type STATUS_UPDATE
2019-06-07 07:57:44,272 DEBUG org.apache.hadoop.yarn.server.resourcemanager.scheduler.capacity.CapacityScheduler: nodeUpdate: slave2:42768 clusterResources: <memory:8192, vCores:2>
2019-06-07 07:57:44,272 DEBUG org.apache.hadoop.yarn.server.resourcemanager.scheduler.capacity.CapacityScheduler: nodeUpdate: slave2:42768 clusterResources: <memory:8192, vCores:2>
2019-06-07 07:57:44,274 DEBUG org.apache.hadoop.yarn.server.resourcemanager.scheduler.capacity.CapacityScheduler: Node being looked for scheduling slave2:42768 availableResource: <memory:4096, vCores:1>
2019-06-07 07:57:44,274 DEBUG org.apache.hadoop.yarn.server.resourcemanager.scheduler.capacity.CapacityScheduler: Node being looked for scheduling slave2:42768 availableResource: <memory:4096, vCores:1>
2019-06-07 07:57:44,274 DEBUG org.apache.hadoop.yarn.server.resourcemanager.scheduler.capacity.CapacityScheduler: Trying to schedule on node: slave2, available: <memory:4096, vCores:1>
2019-06-07 07:57:44,274 DEBUG org.apache.hadoop.yarn.server.resourcemanager.scheduler.capacity.CapacityScheduler: Trying to schedule on node: slave2, available: <memory:4096, vCores:1>
2019-06-07 07:57:44,274 DEBUG org.apache.hadoop.yarn.server.resourcemanager.scheduler.capacity.ParentQueue: Skip this queue=root, because it doesn't need more resource, schedulingMode=RESPECT_PARTITION_EXCLUSIVITY node-partition=
2019-06-07 07:57:44,274 DEBUG org.apache.hadoop.yarn.server.resourcemanager.scheduler.capacity.ParentQueue: Skip this queue=root, because it doesn't need more resource, schedulingMode=RESPECT_PARTITION_EXCLUSIVITY node-partition=
2019-06-07 07:57:44,286 DEBUG org.apache.hadoop.yarn.server.resourcemanager.rmnode.RMNodeImpl: Processing slave1:34830 of type STATUS_UPDATE
2019-06-07 07:57:44,286 DEBUG org.apache.hadoop.yarn.server.resourcemanager.rmnode.RMNodeImpl: Processing slave1:34830 of type STATUS_UPDATE
2019-06-07 07:57:44,291 DEBUG org.apache.hadoop.yarn.server.resourcemanager.scheduler.capacity.CapacityScheduler: nodeUpdate: slave1:34830 clusterResources: <memory:8192, vCores:2>
2019-06-07 07:57:44,291 DEBUG org.apache.hadoop.yarn.server.resourcemanager.scheduler.capacity.CapacityScheduler: nodeUpdate: slave1:34830 clusterResources: <memory:8192, vCores:2>
2019-06-07 07:57:44,291 DEBUG org.apache.hadoop.yarn.server.resourcemanager.scheduler.capacity.CapacityScheduler: Node being looked for scheduling slave1:34830 availableResource: <memory:4096, vCores:1>
2019-06-07 07:57:44,291 DEBUG org.apache.hadoop.yarn.server.resourcemanager.scheduler.capacity.CapacityScheduler: Node being looked for scheduling slave1:34830 availableResource: <memory:4096, vCores:1>
2019-06-07 07:57:44,293 DEBUG org.apache.hadoop.yarn.server.resourcemanager.scheduler.capacity.CapacityScheduler: Trying to schedule on node: slave1, available: <memory:4096, vCores:1>
2019-06-07 07:57:44,293 DEBUG org.apache.hadoop.yarn.server.resourcemanager.scheduler.capacity.CapacityScheduler: Trying to schedule on node: slave1, available: <memory:4096, vCores:1>
2019-06-07 07:57:44,293 DEBUG org.apache.hadoop.yarn.server.resourcemanager.scheduler.capacity.ParentQueue: Skip this queue=root, because it doesn't need more resource, schedulingMode=RESPECT_PARTITION_EXCLUSIVITY node-partition=
2019-06-07 07:57:44,293 DEBUG org.apache.hadoop.yarn.server.resourcemanager.scheduler.capacity.ParentQueue: Skip this queue=root, because it doesn't need more resource, schedulingMode=RESPECT_PARTITION_EXCLUSIVITY node-partition=
2019-06-07 07:57:45,283 DEBUG org.apache.hadoop.yarn.server.resourcemanager.rmnode.RMNodeImpl: Processing slave2:42768 of type STATUS_UPDATE
2019-06-07 07:57:45,283 DEBUG org.apache.hadoop.yarn.server.resourcemanager.rmnode.RMNodeImpl: Processing slave2:42768 of type STATUS_UPDATE
2019-06-07 07:57:45,284 DEBUG org.apache.hadoop.yarn.server.resourcemanager.scheduler.capacity.CapacityScheduler: nodeUpdate: slave2:42768 clusterResources: <memory:8192, vCores:2>
2019-06-07 07:57:45,284 DEBUG org.apache.hadoop.yarn.server.resourcemanager.scheduler.capacity.CapacityScheduler: nodeUpdate: slave2:42768 clusterResources: <memory:8192, vCores:2>
2019-06-07 07:57:45,284 DEBUG org.apache.hadoop.yarn.server.resourcemanager.scheduler.capacity.CapacityScheduler: Node being looked for scheduling slave2:42768 availableResource: <memory:4096, vCores:1>
2019-06-07 07:57:45,284 DEBUG org.apache.hadoop.yarn.server.resourcemanager.scheduler.capacity.CapacityScheduler: Node being looked for scheduling slave2:42768 availableResource: <memory:4096, vCores:1>
2019-06-07 07:57:45,284 DEBUG org.apache.hadoop.yarn.server.resourcemanager.scheduler.capacity.CapacityScheduler: Trying to schedule on node: slave2, available: <memory:4096, vCores:1>
2019-06-07 07:57:45,284 DEBUG org.apache.hadoop.yarn.server.resourcemanager.scheduler.capacity.CapacityScheduler: Trying to schedule on node: slave2, available: <memory:4096, vCores:1>
2019-06-07 07:57:45,284 DEBUG org.apache.hadoop.yarn.server.resourcemanager.scheduler.capacity.ParentQueue: Skip this queue=root, because it doesn't need more resource, schedulingMode=RESPECT_PARTITION_EXCLUSIVITY node-partition=
2019-06-07 07:57:45,284 DEBUG org.apache.hadoop.yarn.server.resourcemanager.scheduler.capacity.ParentQueue: Skip this queue=root, because it doesn't need more resource, schedulingMode=RESPECT_PARTITION_EXCLUSIVITY node-partition=
2019-06-07 07:57:45,300 DEBUG org.apache.hadoop.yarn.server.resourcemanager.rmnode.RMNodeImpl: Processing slave1:34830 of type STATUS_UPDATE
2019-06-07 07:57:45,300 DEBUG org.apache.hadoop.yarn.server.resourcemanager.rmnode.RMNodeImpl: Processing slave1:34830 of type STATUS_UPDATE
2019-06-07 07:57:45,301 DEBUG org.apache.hadoop.yarn.server.resourcemanager.scheduler.capacity.CapacityScheduler: nodeUpdate: slave1:34830 clusterResources: <memory:8192, vCores:2>
2019-06-07 07:57:45,301 DEBUG org.apache.hadoop.yarn.server.resourcemanager.scheduler.capacity.CapacityScheduler: nodeUpdate: slave1:34830 clusterResources: <memory:8192, vCores:2>
2019-06-07 07:57:45,301 DEBUG org.apache.hadoop.yarn.server.resourcemanager.scheduler.capacity.CapacityScheduler: Node being looked for scheduling slave1:34830 availableResource: <memory:4096, vCores:1>
2019-06-07 07:57:45,301 DEBUG org.apache.hadoop.yarn.server.resourcemanager.scheduler.capacity.CapacityScheduler: Node being looked for scheduling slave1:34830 availableResource: <memory:4096, vCores:1>
2019-06-07 07:57:45,301 DEBUG org.apache.hadoop.yarn.server.resourcemanager.scheduler.capacity.CapacityScheduler: Trying to schedule on node: slave1, available: <memory:4096, vCores:1>
2019-06-07 07:57:45,301 DEBUG org.apache.hadoop.yarn.server.resourcemanager.scheduler.capacity.CapacityScheduler: Trying to schedule on node: slave1, available: <memory:4096, vCores:1>
2019-06-07 07:57:45,301 DEBUG org.apache.hadoop.yarn.server.resourcemanager.scheduler.capacity.ParentQueue: Skip this queue=root, because it doesn't need more resource, schedulingMode=RESPECT_PARTITION_EXCLUSIVITY node-partition=
2019-06-07 07:57:45,301 DEBUG org.apache.hadoop.yarn.server.resourcemanager.scheduler.capacity.ParentQueue: Skip this queue=root, because it doesn't need more resource, schedulingMode=RESPECT_PARTITION_EXCLUSIVITY node-partition=
2019-06-07 07:57:46,295 DEBUG org.apache.hadoop.yarn.server.resourcemanager.rmnode.RMNodeImpl: Processing slave2:42768 of type STATUS_UPDATE
2019-06-07 07:57:46,295 DEBUG org.apache.hadoop.yarn.server.resourcemanager.rmnode.RMNodeImpl: Processing slave2:42768 of type STATUS_UPDATE
2019-06-07 07:57:46,295 DEBUG org.apache.hadoop.yarn.server.resourcemanager.scheduler.capacity.CapacityScheduler: nodeUpdate: slave2:42768 clusterResources: <memory:8192, vCores:2>
2019-06-07 07:57:46,295 DEBUG org.apache.hadoop.yarn.server.resourcemanager.scheduler.capacity.CapacityScheduler: nodeUpdate: slave2:42768 clusterResources: <memory:8192, vCores:2>
2019-06-07 07:57:46,295 DEBUG org.apache.hadoop.yarn.server.resourcemanager.scheduler.capacity.CapacityScheduler: Node being looked for scheduling slave2:42768 availableResource: <memory:4096, vCores:1>
2019-06-07 07:57:46,295 DEBUG org.apache.hadoop.yarn.server.resourcemanager.scheduler.capacity.CapacityScheduler: Node being looked for scheduling slave2:42768 availableResource: <memory:4096, vCores:1>
2019-06-07 07:57:46,295 DEBUG org.apache.hadoop.yarn.server.resourcemanager.scheduler.capacity.CapacityScheduler: Trying to schedule on node: slave2, available: <memory:4096, vCores:1>
2019-06-07 07:57:46,295 DEBUG org.apache.hadoop.yarn.server.resourcemanager.scheduler.capacity.CapacityScheduler: Trying to schedule on node: slave2, available: <memory:4096, vCores:1>
2019-06-07 07:57:46,296 DEBUG org.apache.hadoop.yarn.server.resourcemanager.scheduler.capacity.ParentQueue: Skip this queue=root, because it doesn't need more resource, schedulingMode=RESPECT_PARTITION_EXCLUSIVITY node-partition=
2019-06-07 07:57:46,296 DEBUG org.apache.hadoop.yarn.server.resourcemanager.scheduler.capacity.ParentQueue: Skip this queue=root, because it doesn't need more resource, schedulingMode=RESPECT_PARTITION_EXCLUSIVITY node-partition=
2019-06-07 07:57:46,311 DEBUG org.apache.hadoop.yarn.server.resourcemanager.rmnode.RMNodeImpl: Processing slave1:34830 of type STATUS_UPDATE
2019-06-07 07:57:46,311 DEBUG org.apache.hadoop.yarn.server.resourcemanager.rmnode.RMNodeImpl: Processing slave1:34830 of type STATUS_UPDATE
2019-06-07 07:57:46,312 DEBUG org.apache.hadoop.yarn.server.resourcemanager.scheduler.capacity.CapacityScheduler: nodeUpdate: slave1:34830 clusterResources: <memory:8192, vCores:2>
2019-06-07 07:57:46,312 DEBUG org.apache.hadoop.yarn.server.resourcemanager.scheduler.capacity.CapacityScheduler: nodeUpdate: slave1:34830 clusterResources: <memory:8192, vCores:2>
2019-06-07 07:57:46,312 DEBUG org.apache.hadoop.yarn.server.resourcemanager.scheduler.capacity.CapacityScheduler: Node being looked for scheduling slave1:34830 availableResource: <memory:4096, vCores:1>
2019-06-07 07:57:46,312 DEBUG org.apache.hadoop.yarn.server.resourcemanager.scheduler.capacity.CapacityScheduler: Node being looked for scheduling slave1:34830 availableResource: <memory:4096, vCores:1>
2019-06-07 07:57:46,312 DEBUG org.apache.hadoop.yarn.server.resourcemanager.scheduler.capacity.CapacityScheduler: Trying to schedule on node: slave1, available: <memory:4096, vCores:1>
2019-06-07 07:57:46,312 DEBUG org.apache.hadoop.yarn.server.resourcemanager.scheduler.capacity.CapacityScheduler: Trying to schedule on node: slave1, available: <memory:4096, vCores:1>
2019-06-07 07:57:46,312 DEBUG org.apache.hadoop.yarn.server.resourcemanager.scheduler.capacity.ParentQueue: Skip this queue=root, because it doesn't need more resource, schedulingMode=RESPECT_PARTITION_EXCLUSIVITY node-partition=
2019-06-07 07:57:46,312 DEBUG org.apache.hadoop.yarn.server.resourcemanager.scheduler.capacity.ParentQueue: Skip this queue=root, because it doesn't need more resource, schedulingMode=RESPECT_PARTITION_EXCLUSIVITY node-partition=
2019-06-07 07:57:46,444 INFO org.apache.hadoop.yarn.server.resourcemanager.scheduler.capacity.CapacityScheduler: Application 'application_1559894241434_0001' is submitted without priority hence considering default queue/cluster priority: 0
2019-06-07 07:57:46,444 INFO org.apache.hadoop.yarn.server.resourcemanager.scheduler.capacity.CapacityScheduler: Application 'application_1559894241434_0001' is submitted without priority hence considering default queue/cluster priority: 0
2019-06-07 07:57:46,444 INFO org.apache.hadoop.yarn.server.resourcemanager.scheduler.capacity.CapacityScheduler: Priority '0' is acceptable in queue : default for application: application_1559894241434_0001 for the user: root
2019-06-07 07:57:46,444 INFO org.apache.hadoop.yarn.server.resourcemanager.scheduler.capacity.CapacityScheduler: Priority '0' is acceptable in queue : default for application: application_1559894241434_0001 for the user: root
2019-06-07 07:57:46,458 WARN org.apache.hadoop.yarn.server.resourcemanager.rmapp.RMAppImpl: The specific max attempts: 0 for application: 1 is invalid, because it is out of the range [1, 2]. Use the global max attempts instead.
2019-06-07 07:57:46,458 WARN org.apache.hadoop.yarn.server.resourcemanager.rmapp.RMAppImpl: The specific max attempts: 0 for application: 1 is invalid, because it is out of the range [1, 2]. Use the global max attempts instead.
2019-06-07 07:57:46,462 DEBUG org.apache.hadoop.yarn.server.resourcemanager.rmapp.RMAppImpl: Processing event for application_1559894241434_0001 of type START
2019-06-07 07:57:46,462 DEBUG org.apache.hadoop.yarn.server.resourcemanager.rmapp.RMAppImpl: Processing event for application_1559894241434_0001 of type START
2019-06-07 07:57:46,463 INFO org.apache.hadoop.yarn.server.resourcemanager.rmapp.RMAppImpl: Storing application with id application_1559894241434_0001
2019-06-07 07:57:46,463 INFO org.apache.hadoop.yarn.server.resourcemanager.rmapp.RMAppImpl: Storing application with id application_1559894241434_0001
2019-06-07 07:57:46,468 INFO org.apache.hadoop.yarn.server.resourcemanager.rmapp.RMAppImpl: application_1559894241434_0001 State change from NEW to NEW_SAVING on event=START
2019-06-07 07:57:46,468 INFO org.apache.hadoop.yarn.server.resourcemanager.rmapp.RMAppImpl: application_1559894241434_0001 State change from NEW to NEW_SAVING on event=START
2019-06-07 07:57:46,468 DEBUG org.apache.hadoop.yarn.server.resourcemanager.recovery.RMStateStore: Processing event of type STORE_APP
2019-06-07 07:57:46,468 DEBUG org.apache.hadoop.yarn.server.resourcemanager.recovery.RMStateStore: Processing event of type STORE_APP
2019-06-07 07:57:46,469 INFO org.apache.hadoop.yarn.server.resourcemanager.ClientRMService: Application with id 1 submitted by user root
2019-06-07 07:57:46,469 INFO org.apache.hadoop.yarn.server.resourcemanager.ClientRMService: Application with id 1 submitted by user root
2019-06-07 07:57:46,469 INFO org.apache.hadoop.yarn.server.resourcemanager.recovery.RMStateStore: Storing info for app: application_1559894241434_0001
2019-06-07 07:57:46,469 INFO org.apache.hadoop.yarn.server.resourcemanager.recovery.RMStateStore: Storing info for app: application_1559894241434_0001
2019-06-07 07:57:46,470 INFO org.apache.hadoop.yarn.server.resourcemanager.RMAuditLogger: USER=root	IP=172.17.0.2	OPERATION=Submit Application Request	TARGET=ClientRMService	RESULT=SUCCESS	APPID=application_1559894241434_0001
2019-06-07 07:57:46,470 INFO org.apache.hadoop.yarn.server.resourcemanager.RMAuditLogger: USER=root	IP=172.17.0.2	OPERATION=Submit Application Request	TARGET=ClientRMService	RESULT=SUCCESS	APPID=application_1559894241434_0001
2019-06-07 07:57:46,478 DEBUG org.apache.hadoop.yarn.server.resourcemanager.rmapp.RMAppImpl: Processing event for application_1559894241434_0001 of type APP_NEW_SAVED
2019-06-07 07:57:46,478 DEBUG org.apache.hadoop.yarn.server.resourcemanager.rmapp.RMAppImpl: Processing event for application_1559894241434_0001 of type APP_NEW_SAVED
2019-06-07 07:57:46,479 INFO org.apache.hadoop.yarn.server.resourcemanager.rmapp.RMAppImpl: application_1559894241434_0001 State change from NEW_SAVING to SUBMITTED on event=APP_NEW_SAVED
2019-06-07 07:57:46,479 INFO org.apache.hadoop.yarn.server.resourcemanager.rmapp.RMAppImpl: application_1559894241434_0001 State change from NEW_SAVING to SUBMITTED on event=APP_NEW_SAVED
2019-06-07 07:57:46,480 INFO org.apache.hadoop.yarn.server.resourcemanager.scheduler.capacity.ParentQueue: Application added - appId: application_1559894241434_0001 user: root leaf-queue of parent: root #applications: 1
2019-06-07 07:57:46,480 INFO org.apache.hadoop.yarn.server.resourcemanager.scheduler.capacity.ParentQueue: Application added - appId: application_1559894241434_0001 user: root leaf-queue of parent: root #applications: 1
2019-06-07 07:57:46,481 INFO org.apache.hadoop.yarn.server.resourcemanager.scheduler.capacity.CapacityScheduler: Accepted application application_1559894241434_0001 from user: root, in queue: default
2019-06-07 07:57:46,481 INFO org.apache.hadoop.yarn.server.resourcemanager.scheduler.capacity.CapacityScheduler: Accepted application application_1559894241434_0001 from user: root, in queue: default
2019-06-07 07:57:46,481 DEBUG org.apache.hadoop.yarn.server.resourcemanager.rmapp.RMAppImpl: Processing event for application_1559894241434_0001 of type APP_ACCEPTED
2019-06-07 07:57:46,481 DEBUG org.apache.hadoop.yarn.server.resourcemanager.rmapp.RMAppImpl: Processing event for application_1559894241434_0001 of type APP_ACCEPTED
2019-06-07 07:57:46,492 INFO org.apache.hadoop.yarn.server.resourcemanager.rmapp.RMAppImpl: application_1559894241434_0001 State change from SUBMITTED to ACCEPTED on event=APP_ACCEPTED
2019-06-07 07:57:46,492 INFO org.apache.hadoop.yarn.server.resourcemanager.rmapp.RMAppImpl: application_1559894241434_0001 State change from SUBMITTED to ACCEPTED on event=APP_ACCEPTED
2019-06-07 07:57:46,493 DEBUG org.apache.hadoop.yarn.server.resourcemanager.scheduler.AbstractYarnScheduler: Request for appInfo of unknown attempt appattempt_1559894241434_0001_000001
2019-06-07 07:57:46,493 DEBUG org.apache.hadoop.yarn.server.resourcemanager.scheduler.AbstractYarnScheduler: Request for appInfo of unknown attempt appattempt_1559894241434_0001_000001
2019-06-07 07:57:46,493 DEBUG org.apache.hadoop.yarn.server.resourcemanager.scheduler.AbstractYarnScheduler: Request for appInfo of unknown attempt appattempt_1559894241434_0001_000001
2019-06-07 07:57:46,493 DEBUG org.apache.hadoop.yarn.server.resourcemanager.scheduler.AbstractYarnScheduler: Request for appInfo of unknown attempt appattempt_1559894241434_0001_000001
2019-06-07 07:57:46,494 DEBUG org.apache.hadoop.yarn.server.resourcemanager.scheduler.AbstractYarnScheduler: Request for appInfo of unknown attempt appattempt_1559894241434_0001_000001
2019-06-07 07:57:46,494 DEBUG org.apache.hadoop.yarn.server.resourcemanager.scheduler.AbstractYarnScheduler: Request for appInfo of unknown attempt appattempt_1559894241434_0001_000001
2019-06-07 07:57:46,499 DEBUG org.apache.hadoop.yarn.server.resourcemanager.rmapp.attempt.RMAppAttemptImpl: Processing event for appattempt_1559894241434_0001_000001 of type START
2019-06-07 07:57:46,499 DEBUG org.apache.hadoop.yarn.server.resourcemanager.rmapp.attempt.RMAppAttemptImpl: Processing event for appattempt_1559894241434_0001_000001 of type START
2019-06-07 07:57:46,548 INFO org.apache.hadoop.yarn.server.resourcemanager.ApplicationMasterService: Registering app attempt : appattempt_1559894241434_0001_000001
2019-06-07 07:57:46,548 INFO org.apache.hadoop.yarn.server.resourcemanager.ApplicationMasterService: Registering app attempt : appattempt_1559894241434_0001_000001
2019-06-07 07:57:46,549 INFO org.apache.hadoop.yarn.server.resourcemanager.rmapp.attempt.RMAppAttemptImpl: appattempt_1559894241434_0001_000001 State change from NEW to SUBMITTED
2019-06-07 07:57:46,549 INFO org.apache.hadoop.yarn.server.resourcemanager.rmapp.attempt.RMAppAttemptImpl: appattempt_1559894241434_0001_000001 State change from NEW to SUBMITTED
2019-06-07 07:57:46,572 DEBUG org.apache.hadoop.yarn.server.resourcemanager.scheduler.capacity.LeafQueue: application application_1559894241434_0001 AMResource <memory:1024, vCores:1> maxAMResourcePerQueuePercent 0.1 amLimit <memory:1024, vCores:1> lastClusterResource <memory:8192, vCores:2> amIfStarted <memory:1024, vCores:1> AM node-partition name 
2019-06-07 07:57:46,572 DEBUG org.apache.hadoop.yarn.server.resourcemanager.scheduler.capacity.LeafQueue: application application_1559894241434_0001 AMResource <memory:1024, vCores:1> maxAMResourcePerQueuePercent 0.1 amLimit <memory:1024, vCores:1> lastClusterResource <memory:8192, vCores:2> amIfStarted <memory:1024, vCores:1> AM node-partition name 
2019-06-07 07:57:46,572 DEBUG org.apache.hadoop.yarn.server.resourcemanager.scheduler.capacity.LeafQueue: Effective user AM limit for "root":<memory:1024, vCores:1>. Effective weighted user AM limit: <memory:1024, vCores:1>. User weight: 1.0
2019-06-07 07:57:46,572 DEBUG org.apache.hadoop.yarn.server.resourcemanager.scheduler.capacity.LeafQueue: Effective user AM limit for "root":<memory:1024, vCores:1>. Effective weighted user AM limit: <memory:1024, vCores:1>. User weight: 1.0
2019-06-07 07:57:46,574 INFO org.apache.hadoop.yarn.server.resourcemanager.scheduler.capacity.LeafQueue: Application application_1559894241434_0001 from user: root activated in queue: default
2019-06-07 07:57:46,574 INFO org.apache.hadoop.yarn.server.resourcemanager.scheduler.capacity.LeafQueue: Application application_1559894241434_0001 from user: root activated in queue: default
2019-06-07 07:57:46,574 INFO org.apache.hadoop.yarn.server.resourcemanager.scheduler.capacity.LeafQueue: Application added - appId: application_1559894241434_0001 user: root, leaf-queue: default #user-pending-applications: 0 #user-active-applications: 1 #queue-pending-applications: 0 #queue-active-applications: 1
2019-06-07 07:57:46,574 INFO org.apache.hadoop.yarn.server.resourcemanager.scheduler.capacity.LeafQueue: Application added - appId: application_1559894241434_0001 user: root, leaf-queue: default #user-pending-applications: 0 #user-active-applications: 1 #queue-pending-applications: 0 #queue-active-applications: 1
2019-06-07 07:57:46,574 INFO org.apache.hadoop.yarn.server.resourcemanager.scheduler.capacity.CapacityScheduler: Added Application Attempt appattempt_1559894241434_0001_000001 to scheduler from user root in queue default
2019-06-07 07:57:46,574 INFO org.apache.hadoop.yarn.server.resourcemanager.scheduler.capacity.CapacityScheduler: Added Application Attempt appattempt_1559894241434_0001_000001 to scheduler from user root in queue default
2019-06-07 07:57:46,574 DEBUG org.apache.hadoop.yarn.server.resourcemanager.rmapp.attempt.RMAppAttemptImpl: Processing event for appattempt_1559894241434_0001_000001 of type ATTEMPT_ADDED
2019-06-07 07:57:46,574 DEBUG org.apache.hadoop.yarn.server.resourcemanager.rmapp.attempt.RMAppAttemptImpl: Processing event for appattempt_1559894241434_0001_000001 of type ATTEMPT_ADDED
2019-06-07 07:57:46,576 DEBUG org.apache.hadoop.yarn.server.resourcemanager.rmapp.attempt.RMAppAttemptImpl: Using blacklist for AM: additions([]) and removals([])
2019-06-07 07:57:46,576 DEBUG org.apache.hadoop.yarn.server.resourcemanager.rmapp.attempt.RMAppAttemptImpl: Using blacklist for AM: additions([]) and removals([])
2019-06-07 07:57:46,576 DEBUG org.apache.hadoop.yarn.server.resourcemanager.scheduler.capacity.CapacityScheduler: allocate: pre-update appattempt_1559894241434_0001_000001 ask size =1
2019-06-07 07:57:46,576 DEBUG org.apache.hadoop.yarn.server.resourcemanager.scheduler.capacity.CapacityScheduler: allocate: pre-update appattempt_1559894241434_0001_000001 ask size =1
2019-06-07 07:57:46,577 DEBUG org.apache.hadoop.yarn.server.resourcemanager.scheduler.ActiveUsersManager: User root added to activeUsers, currently: 1
2019-06-07 07:57:46,577 DEBUG org.apache.hadoop.yarn.server.resourcemanager.scheduler.ActiveUsersManager: User root added to activeUsers, currently: 1
2019-06-07 07:57:46,577 DEBUG org.apache.hadoop.yarn.server.resourcemanager.scheduler.capacity.CapacityScheduler: allocate: post-update
2019-06-07 07:57:46,577 DEBUG org.apache.hadoop.yarn.server.resourcemanager.scheduler.capacity.CapacityScheduler: allocate: post-update
2019-06-07 07:57:46,577 DEBUG org.apache.hadoop.yarn.server.resourcemanager.scheduler.SchedulerApplicationAttempt: showRequests: application=application_1559894241434_0001 headRoom=<memory:0, vCores:0> currentConsumption=0
2019-06-07 07:57:46,577 DEBUG org.apache.hadoop.yarn.server.resourcemanager.scheduler.SchedulerApplicationAttempt: showRequests: application=application_1559894241434_0001 headRoom=<memory:0, vCores:0> currentConsumption=0
2019-06-07 07:57:46,577 DEBUG org.apache.hadoop.yarn.server.resourcemanager.scheduler.SchedulerApplicationAttempt: showRequests: application=application_1559894241434_0001 request={Priority: 0, Capability: <memory:1024, vCores:1>, # Containers: 1, Location: *, Relax Locality: true, Node Label Expression: }
2019-06-07 07:57:46,577 DEBUG org.apache.hadoop.yarn.server.resourcemanager.scheduler.SchedulerApplicationAttempt: showRequests: application=application_1559894241434_0001 request={Priority: 0, Capability: <memory:1024, vCores:1>, # Containers: 1, Location: *, Relax Locality: true, Node Label Expression: }
2019-06-07 07:57:46,578 INFO org.apache.hadoop.yarn.server.resourcemanager.rmapp.attempt.RMAppAttemptImpl: appattempt_1559894241434_0001_000001 State change from SUBMITTED to SCHEDULED
2019-06-07 07:57:46,578 INFO org.apache.hadoop.yarn.server.resourcemanager.rmapp.attempt.RMAppAttemptImpl: appattempt_1559894241434_0001_000001 State change from SUBMITTED to SCHEDULED
2019-06-07 07:57:47,297 DEBUG org.apache.hadoop.yarn.server.resourcemanager.rmnode.RMNodeImpl: Processing slave2:42768 of type STATUS_UPDATE
2019-06-07 07:57:47,297 DEBUG org.apache.hadoop.yarn.server.resourcemanager.rmnode.RMNodeImpl: Processing slave2:42768 of type STATUS_UPDATE
2019-06-07 07:57:47,298 DEBUG org.apache.hadoop.yarn.server.resourcemanager.scheduler.capacity.CapacityScheduler: nodeUpdate: slave2:42768 clusterResources: <memory:8192, vCores:2>
2019-06-07 07:57:47,298 DEBUG org.apache.hadoop.yarn.server.resourcemanager.scheduler.capacity.CapacityScheduler: nodeUpdate: slave2:42768 clusterResources: <memory:8192, vCores:2>
2019-06-07 07:57:47,298 DEBUG org.apache.hadoop.yarn.server.resourcemanager.scheduler.capacity.CapacityScheduler: Node being looked for scheduling slave2:42768 availableResource: <memory:4096, vCores:1>
2019-06-07 07:57:47,298 DEBUG org.apache.hadoop.yarn.server.resourcemanager.scheduler.capacity.CapacityScheduler: Node being looked for scheduling slave2:42768 availableResource: <memory:4096, vCores:1>
2019-06-07 07:57:47,298 DEBUG org.apache.hadoop.yarn.server.resourcemanager.scheduler.capacity.CapacityScheduler: Trying to schedule on node: slave2, available: <memory:4096, vCores:1>
2019-06-07 07:57:47,298 DEBUG org.apache.hadoop.yarn.server.resourcemanager.scheduler.capacity.CapacityScheduler: Trying to schedule on node: slave2, available: <memory:4096, vCores:1>
2019-06-07 07:57:47,298 DEBUG org.apache.hadoop.yarn.server.resourcemanager.scheduler.capacity.ParentQueue: Trying to assign containers to child-queue of root
2019-06-07 07:57:47,298 DEBUG org.apache.hadoop.yarn.server.resourcemanager.scheduler.capacity.ParentQueue: Trying to assign containers to child-queue of root
2019-06-07 07:57:47,298 DEBUG org.apache.hadoop.yarn.server.resourcemanager.scheduler.capacity.ParentQueue: printChildQueues - queue: root child-queues: root.defaultusedCapacity=(0.0),  label=(*)
2019-06-07 07:57:47,298 DEBUG org.apache.hadoop.yarn.server.resourcemanager.scheduler.capacity.ParentQueue: printChildQueues - queue: root child-queues: root.defaultusedCapacity=(0.0),  label=(*)
2019-06-07 07:57:47,298 DEBUG org.apache.hadoop.yarn.server.resourcemanager.scheduler.capacity.ParentQueue: Trying to assign to queue: root.default stats: default: capacity=1.0, absoluteCapacity=1.0, usedResources=<memory:0, vCores:0>, usedCapacity=0.0, absoluteUsedCapacity=0.0, numApps=1, numContainers=0
2019-06-07 07:57:47,298 DEBUG org.apache.hadoop.yarn.server.resourcemanager.scheduler.capacity.ParentQueue: Trying to assign to queue: root.default stats: default: capacity=1.0, absoluteCapacity=1.0, usedResources=<memory:0, vCores:0>, usedCapacity=0.0, absoluteUsedCapacity=0.0, numApps=1, numContainers=0
2019-06-07 07:57:47,298 DEBUG org.apache.hadoop.yarn.server.resourcemanager.scheduler.capacity.LeafQueue: assignContainers: node=slave2 #applications=1
2019-06-07 07:57:47,298 DEBUG org.apache.hadoop.yarn.server.resourcemanager.scheduler.capacity.LeafQueue: assignContainers: node=slave2 #applications=1
2019-06-07 07:57:47,299 DEBUG org.apache.hadoop.yarn.server.resourcemanager.scheduler.capacity.LeafQueue: User limit computation for root in queue default userLimitPercent=100 userLimitFactor=1.0 required: <memory:1024, vCores:1> consumed: <memory:0, vCores:0> user-limit-resource: <memory:8192, vCores:1> queueCapacity: <memory:8192, vCores:1> qconsumed: <memory:0, vCores:0> consumedRatio: 0.0 currentCapacity: <memory:8192, vCores:1> activeUsers: 1.0 clusterCapacity: <memory:8192, vCores:2> resourceByLabel: <memory:8192, vCores:2> usageratio: 0.0 Partition:  maxUserLimit=<memory:8192, vCores:1> userWeight=1.0
2019-06-07 07:57:47,299 DEBUG org.apache.hadoop.yarn.server.resourcemanager.scheduler.capacity.LeafQueue: User limit computation for root in queue default userLimitPercent=100 userLimitFactor=1.0 required: <memory:1024, vCores:1> consumed: <memory:0, vCores:0> user-limit-resource: <memory:8192, vCores:1> queueCapacity: <memory:8192, vCores:1> qconsumed: <memory:0, vCores:0> consumedRatio: 0.0 currentCapacity: <memory:8192, vCores:1> activeUsers: 1.0 clusterCapacity: <memory:8192, vCores:2> resourceByLabel: <memory:8192, vCores:2> usageratio: 0.0 Partition:  maxUserLimit=<memory:8192, vCores:1> userWeight=1.0
2019-06-07 07:57:47,300 DEBUG org.apache.hadoop.yarn.server.resourcemanager.scheduler.capacity.LeafQueue: Headroom calculation for user root:  userLimit=<memory:8192, vCores:1> queueMaxAvailRes=<memory:8192, vCores:1> consumed=<memory:0, vCores:0>
2019-06-07 07:57:47,300 DEBUG org.apache.hadoop.yarn.server.resourcemanager.scheduler.capacity.LeafQueue: Headroom calculation for user root:  userLimit=<memory:8192, vCores:1> queueMaxAvailRes=<memory:8192, vCores:1> consumed=<memory:0, vCores:0>
2019-06-07 07:57:47,302 DEBUG org.apache.hadoop.yarn.server.resourcemanager.scheduler.common.fica.FiCaSchedulerApp: pre-assignContainers for application application_1559894241434_0001
2019-06-07 07:57:47,302 DEBUG org.apache.hadoop.yarn.server.resourcemanager.scheduler.common.fica.FiCaSchedulerApp: pre-assignContainers for application application_1559894241434_0001
2019-06-07 07:57:47,302 DEBUG org.apache.hadoop.yarn.server.resourcemanager.scheduler.capacity.LeafQueue: User limit computation for root in queue default userLimitPercent=100 userLimitFactor=1.0 required: <memory:1024, vCores:1> consumed: <memory:0, vCores:0> user-limit-resource: <memory:8192, vCores:1> queueCapacity: <memory:8192, vCores:1> qconsumed: <memory:0, vCores:0> consumedRatio: 0.0 currentCapacity: <memory:8192, vCores:1> activeUsers: 1.0 clusterCapacity: <memory:8192, vCores:2> resourceByLabel: <memory:8192, vCores:2> usageratio: 0.0 Partition:  maxUserLimit=<memory:8192, vCores:1> userWeight=1.0
2019-06-07 07:57:47,302 DEBUG org.apache.hadoop.yarn.server.resourcemanager.scheduler.capacity.LeafQueue: User limit computation for root in queue default userLimitPercent=100 userLimitFactor=1.0 required: <memory:1024, vCores:1> consumed: <memory:0, vCores:0> user-limit-resource: <memory:8192, vCores:1> queueCapacity: <memory:8192, vCores:1> qconsumed: <memory:0, vCores:0> consumedRatio: 0.0 currentCapacity: <memory:8192, vCores:1> activeUsers: 1.0 clusterCapacity: <memory:8192, vCores:2> resourceByLabel: <memory:8192, vCores:2> usageratio: 0.0 Partition:  maxUserLimit=<memory:8192, vCores:1> userWeight=1.0
2019-06-07 07:57:47,302 DEBUG org.apache.hadoop.yarn.server.resourcemanager.scheduler.SchedulerApplicationAttempt: showRequests: application=application_1559894241434_0001 headRoom=<memory:8192, vCores:2> currentConsumption=0
2019-06-07 07:57:47,302 DEBUG org.apache.hadoop.yarn.server.resourcemanager.scheduler.SchedulerApplicationAttempt: showRequests: application=application_1559894241434_0001 headRoom=<memory:8192, vCores:2> currentConsumption=0
2019-06-07 07:57:47,303 DEBUG org.apache.hadoop.yarn.server.resourcemanager.scheduler.SchedulerApplicationAttempt: showRequests: application=application_1559894241434_0001 request={Priority: 0, Capability: <memory:1024, vCores:1>, # Containers: 1, Location: *, Relax Locality: true, Node Label Expression: }
2019-06-07 07:57:47,303 DEBUG org.apache.hadoop.yarn.server.resourcemanager.scheduler.SchedulerApplicationAttempt: showRequests: application=application_1559894241434_0001 request={Priority: 0, Capability: <memory:1024, vCores:1>, # Containers: 1, Location: *, Relax Locality: true, Node Label Expression: }
2019-06-07 07:57:47,303 DEBUG org.apache.hadoop.yarn.server.resourcemanager.scheduler.capacity.allocator.IncreaseContainerAllocator: Skip allocating increase request since we don't have any increase request on this node=slave2:42768
2019-06-07 07:57:47,303 DEBUG org.apache.hadoop.yarn.server.resourcemanager.scheduler.capacity.allocator.IncreaseContainerAllocator: Skip allocating increase request since we don't have any increase request on this node=slave2:42768
2019-06-07 07:57:47,306 DEBUG org.apache.hadoop.yarn.server.resourcemanager.scheduler.capacity.allocator.RegularContainerAllocator: assignContainers: node=slave2 application=application_1559894241434_0001 priority=0 request={Priority: 0, Capability: <memory:1024, vCores:1>, # Containers: 1, Location: *, Relax Locality: true, Node Label Expression: } type=OFF_SWITCH
2019-06-07 07:57:47,306 DEBUG org.apache.hadoop.yarn.server.resourcemanager.scheduler.capacity.allocator.RegularContainerAllocator: assignContainers: node=slave2 application=application_1559894241434_0001 priority=0 request={Priority: 0, Capability: <memory:1024, vCores:1>, # Containers: 1, Location: *, Relax Locality: true, Node Label Expression: } type=OFF_SWITCH
2019-06-07 07:57:47,313 DEBUG org.apache.hadoop.yarn.server.resourcemanager.rmnode.RMNodeImpl: Processing slave1:34830 of type STATUS_UPDATE
2019-06-07 07:57:47,313 DEBUG org.apache.hadoop.yarn.server.resourcemanager.rmnode.RMNodeImpl: Processing slave1:34830 of type STATUS_UPDATE
2019-06-07 07:57:47,331 DEBUG org.apache.hadoop.yarn.server.resourcemanager.scheduler.ActiveUsersManager: User root removed from activeUsers, currently: 0
2019-06-07 07:57:47,331 DEBUG org.apache.hadoop.yarn.server.resourcemanager.scheduler.ActiveUsersManager: User root removed from activeUsers, currently: 0
2019-06-07 07:57:47,332 DEBUG org.apache.hadoop.yarn.server.resourcemanager.scheduler.AppSchedulingInfo: allocate: applicationId=application_1559894241434_0001 container=container_1559894241434_0001_01_000001 host=slave2:42768 user=root resource=<memory:1024, vCores:1> type=OFF_SWITCH
2019-06-07 07:57:47,332 DEBUG org.apache.hadoop.yarn.server.resourcemanager.scheduler.AppSchedulingInfo: allocate: applicationId=application_1559894241434_0001 container=container_1559894241434_0001_01_000001 host=slave2:42768 user=root resource=<memory:1024, vCores:1> type=OFF_SWITCH
2019-06-07 07:57:47,332 DEBUG org.apache.hadoop.yarn.server.resourcemanager.rmcontainer.RMContainerImpl: Processing container_1559894241434_0001_01_000001 of type START
2019-06-07 07:57:47,332 DEBUG org.apache.hadoop.yarn.server.resourcemanager.rmcontainer.RMContainerImpl: Processing container_1559894241434_0001_01_000001 of type START
2019-06-07 07:57:47,332 INFO org.apache.hadoop.yarn.server.resourcemanager.rmcontainer.RMContainerImpl: container_1559894241434_0001_01_000001 Container Transitioned from NEW to ALLOCATED
2019-06-07 07:57:47,332 INFO org.apache.hadoop.yarn.server.resourcemanager.rmcontainer.RMContainerImpl: container_1559894241434_0001_01_000001 Container Transitioned from NEW to ALLOCATED
2019-06-07 07:57:47,332 DEBUG org.apache.hadoop.yarn.server.resourcemanager.scheduler.common.fica.FiCaSchedulerApp: allocate: applicationAttemptId=appattempt_1559894241434_0001_000001 container=container_1559894241434_0001_01_000001 host=slave2 type=OFF_SWITCH
2019-06-07 07:57:47,332 DEBUG org.apache.hadoop.yarn.server.resourcemanager.scheduler.common.fica.FiCaSchedulerApp: allocate: applicationAttemptId=appattempt_1559894241434_0001_000001 container=container_1559894241434_0001_01_000001 host=slave2 type=OFF_SWITCH
2019-06-07 07:57:47,332 DEBUG org.apache.hadoop.yarn.server.resourcemanager.rmapp.attempt.RMAppAttemptImpl: Processing event for appattempt_1559894241434_0001_000001 of type CONTAINER_ALLOCATED
2019-06-07 07:57:47,332 DEBUG org.apache.hadoop.yarn.server.resourcemanager.rmapp.attempt.RMAppAttemptImpl: Processing event for appattempt_1559894241434_0001_000001 of type CONTAINER_ALLOCATED
2019-06-07 07:57:47,332 INFO org.apache.hadoop.yarn.server.resourcemanager.RMAuditLogger: USER=root	OPERATION=AM Allocated Container	TARGET=SchedulerApp	RESULT=SUCCESS	APPID=application_1559894241434_0001	CONTAINERID=container_1559894241434_0001_01_000001
2019-06-07 07:57:47,332 INFO org.apache.hadoop.yarn.server.resourcemanager.RMAuditLogger: USER=root	OPERATION=AM Allocated Container	TARGET=SchedulerApp	RESULT=SUCCESS	APPID=application_1559894241434_0001	CONTAINERID=container_1559894241434_0001_01_000001
2019-06-07 07:57:47,333 INFO org.apache.hadoop.yarn.server.resourcemanager.scheduler.SchedulerNode: Assigned container container_1559894241434_0001_01_000001 of capacity <memory:1024, vCores:1> on host slave2:42768, which has 1 containers, <memory:1024, vCores:1> used and <memory:3072, vCores:0> available after allocation
2019-06-07 07:57:47,333 INFO org.apache.hadoop.yarn.server.resourcemanager.scheduler.SchedulerNode: Assigned container container_1559894241434_0001_01_000001 of capacity <memory:1024, vCores:1> on host slave2:42768, which has 1 containers, <memory:1024, vCores:1> used and <memory:3072, vCores:0> available after allocation
2019-06-07 07:57:47,333 INFO org.apache.hadoop.yarn.server.resourcemanager.scheduler.capacity.allocator.AbstractContainerAllocator: assignedContainer application attempt=appattempt_1559894241434_0001_000001 container=container_1559894241434_0001_01_000001 queue=org.apache.hadoop.yarn.server.resourcemanager.scheduler.capacity.allocator.RegularContainerAllocator@3dce5bef clusterResource=<memory:8192, vCores:2> type=OFF_SWITCH requestedPartition=
2019-06-07 07:57:47,333 INFO org.apache.hadoop.yarn.server.resourcemanager.scheduler.capacity.allocator.AbstractContainerAllocator: assignedContainer application attempt=appattempt_1559894241434_0001_000001 container=container_1559894241434_0001_01_000001 queue=org.apache.hadoop.yarn.server.resourcemanager.scheduler.capacity.allocator.RegularContainerAllocator@3dce5bef clusterResource=<memory:8192, vCores:2> type=OFF_SWITCH requestedPartition=
2019-06-07 07:57:47,334 DEBUG org.apache.hadoop.yarn.server.resourcemanager.scheduler.capacity.LeafQueue: post-assignContainers for application application_1559894241434_0001
2019-06-07 07:57:47,334 DEBUG org.apache.hadoop.yarn.server.resourcemanager.scheduler.capacity.LeafQueue: post-assignContainers for application application_1559894241434_0001
2019-06-07 07:57:47,413 INFO org.apache.hadoop.yarn.server.resourcemanager.security.NMTokenSecretManagerInRM: Sending NMToken for nodeId : slave2:42768 for container : container_1559894241434_0001_01_000001
2019-06-07 07:57:47,413 INFO org.apache.hadoop.yarn.server.resourcemanager.security.NMTokenSecretManagerInRM: Sending NMToken for nodeId : slave2:42768 for container : container_1559894241434_0001_01_000001
2019-06-07 07:57:47,420 DEBUG org.apache.hadoop.yarn.server.resourcemanager.rmcontainer.RMContainerImpl: Processing container_1559894241434_0001_01_000001 of type ACQUIRED
2019-06-07 07:57:47,420 DEBUG org.apache.hadoop.yarn.server.resourcemanager.rmcontainer.RMContainerImpl: Processing container_1559894241434_0001_01_000001 of type ACQUIRED
2019-06-07 07:57:47,421 INFO org.apache.hadoop.yarn.server.resourcemanager.rmcontainer.RMContainerImpl: container_1559894241434_0001_01_000001 Container Transitioned from ALLOCATED to ACQUIRED
2019-06-07 07:57:47,421 INFO org.apache.hadoop.yarn.server.resourcemanager.rmcontainer.RMContainerImpl: container_1559894241434_0001_01_000001 Container Transitioned from ALLOCATED to ACQUIRED
2019-06-07 07:57:47,421 DEBUG org.apache.hadoop.yarn.server.resourcemanager.scheduler.capacity.LeafQueue: User limit computation for root in queue default userLimitPercent=100 userLimitFactor=1.0 required: <memory:1024, vCores:1> consumed: <memory:0, vCores:0> user-limit-resource: <memory:8192, vCores:1> queueCapacity: <memory:8192, vCores:1> qconsumed: <memory:0, vCores:0> consumedRatio: 0.0 currentCapacity: <memory:8192, vCores:1> activeUsers: 0.0 clusterCapacity: <memory:8192, vCores:2> resourceByLabel: <memory:8192, vCores:2> usageratio: 0.0 Partition:  maxUserLimit=<memory:8192, vCores:1> userWeight=1.0
2019-06-07 07:57:47,421 DEBUG org.apache.hadoop.yarn.server.resourcemanager.scheduler.capacity.LeafQueue: User limit computation for root in queue default userLimitPercent=100 userLimitFactor=1.0 required: <memory:1024, vCores:1> consumed: <memory:0, vCores:0> user-limit-resource: <memory:8192, vCores:1> queueCapacity: <memory:8192, vCores:1> qconsumed: <memory:0, vCores:0> consumedRatio: 0.0 currentCapacity: <memory:8192, vCores:1> activeUsers: 0.0 clusterCapacity: <memory:8192, vCores:2> resourceByLabel: <memory:8192, vCores:2> usageratio: 0.0 Partition:  maxUserLimit=<memory:8192, vCores:1> userWeight=1.0
2019-06-07 07:57:47,421 DEBUG org.apache.hadoop.yarn.server.resourcemanager.scheduler.capacity.LeafQueue: User limit computation for root in queue default userLimitPercent=100 userLimitFactor=1.0 required: <memory:1024, vCores:1> consumed: <memory:1024, vCores:1> user-limit-resource: <memory:8192, vCores:1> queueCapacity: <memory:8192, vCores:1> qconsumed: <memory:1024, vCores:1> consumedRatio: 0.0 currentCapacity: <memory:8192, vCores:1> activeUsers: 0.0 clusterCapacity: <memory:8192, vCores:2> resourceByLabel: <memory:8192, vCores:2> usageratio: 0.125 Partition:  maxUserLimit=<memory:8192, vCores:1> userWeight=1.0
2019-06-07 07:57:47,421 DEBUG org.apache.hadoop.yarn.server.resourcemanager.scheduler.capacity.LeafQueue: User limit computation for root in queue default userLimitPercent=100 userLimitFactor=1.0 required: <memory:1024, vCores:1> consumed: <memory:1024, vCores:1> user-limit-resource: <memory:8192, vCores:1> queueCapacity: <memory:8192, vCores:1> qconsumed: <memory:1024, vCores:1> consumedRatio: 0.0 currentCapacity: <memory:8192, vCores:1> activeUsers: 0.0 clusterCapacity: <memory:8192, vCores:2> resourceByLabel: <memory:8192, vCores:2> usageratio: 0.125 Partition:  maxUserLimit=<memory:8192, vCores:1> userWeight=1.0
2019-06-07 07:57:47,421 DEBUG org.apache.hadoop.yarn.server.resourcemanager.scheduler.capacity.LeafQueue: User limit computation for root in queue default userLimitPercent=100 userLimitFactor=1.0 required: <memory:1024, vCores:1> consumed: <memory:1024, vCores:1> user-limit-resource: <memory:8192, vCores:1> queueCapacity: <memory:8192, vCores:1> qconsumed: <memory:1024, vCores:1> consumedRatio: 0.0 currentCapacity: <memory:8192, vCores:1> activeUsers: 0.0 clusterCapacity: <memory:8192, vCores:2> resourceByLabel: <memory:8192, vCores:2> usageratio: 0.125 Partition:  maxUserLimit=<memory:8192, vCores:1> userWeight=1.0
2019-06-07 07:57:47,421 DEBUG org.apache.hadoop.yarn.server.resourcemanager.scheduler.capacity.LeafQueue: User limit computation for root in queue default userLimitPercent=100 userLimitFactor=1.0 required: <memory:1024, vCores:1> consumed: <memory:1024, vCores:1> user-limit-resource: <memory:8192, vCores:1> queueCapacity: <memory:8192, vCores:1> qconsumed: <memory:1024, vCores:1> consumedRatio: 0.0 currentCapacity: <memory:8192, vCores:1> activeUsers: 0.0 clusterCapacity: <memory:8192, vCores:2> resourceByLabel: <memory:8192, vCores:2> usageratio: 0.125 Partition:  maxUserLimit=<memory:8192, vCores:1> userWeight=1.0
2019-06-07 07:57:47,422 DEBUG org.apache.hadoop.yarn.server.resourcemanager.scheduler.capacity.LeafQueue: User limit computation for root in queue default userLimitPercent=100 userLimitFactor=1.0 required: <memory:1024, vCores:1> consumed: <memory:1024, vCores:1> user-limit-resource: <memory:8192, vCores:1> queueCapacity: <memory:8192, vCores:1> qconsumed: <memory:1024, vCores:1> consumedRatio: 0.0 currentCapacity: <memory:8192, vCores:1> activeUsers: 0.0 clusterCapacity: <memory:8192, vCores:2> resourceByLabel: <memory:8192, vCores:2> usageratio: 0.125 Partition:  maxUserLimit=<memory:8192, vCores:1> userWeight=1.0
2019-06-07 07:57:47,422 DEBUG org.apache.hadoop.yarn.server.resourcemanager.scheduler.capacity.LeafQueue: User limit computation for root in queue default userLimitPercent=100 userLimitFactor=1.0 required: <memory:1024, vCores:1> consumed: <memory:1024, vCores:1> user-limit-resource: <memory:8192, vCores:1> queueCapacity: <memory:8192, vCores:1> qconsumed: <memory:1024, vCores:1> consumedRatio: 0.0 currentCapacity: <memory:8192, vCores:1> activeUsers: 0.0 clusterCapacity: <memory:8192, vCores:2> resourceByLabel: <memory:8192, vCores:2> usageratio: 0.125 Partition:  maxUserLimit=<memory:8192, vCores:1> userWeight=1.0
2019-06-07 07:57:47,422 DEBUG org.apache.hadoop.yarn.server.resourcemanager.scheduler.capacity.LeafQueue: default user=root used=<memory:1024, vCores:1> numContainers=1 headroom = <memory:7168, vCores:1> user-resources=<memory:1024, vCores:1>
2019-06-07 07:57:47,422 DEBUG org.apache.hadoop.yarn.server.resourcemanager.scheduler.capacity.LeafQueue: default user=root used=<memory:1024, vCores:1> numContainers=1 headroom = <memory:7168, vCores:1> user-resources=<memory:1024, vCores:1>
2019-06-07 07:57:47,422 DEBUG org.apache.hadoop.yarn.server.resourcemanager.scheduler.capacity.ParentQueue: Assigned to queue: root.default stats: default: capacity=1.0, absoluteCapacity=1.0, usedResources=<memory:1024, vCores:1>, usedCapacity=0.125, absoluteUsedCapacity=0.125, numApps=1, numContainers=1 --> <memory:1024, vCores:1>, OFF_SWITCH
2019-06-07 07:57:47,422 DEBUG org.apache.hadoop.yarn.server.resourcemanager.scheduler.capacity.ParentQueue: Assigned to queue: root.default stats: default: capacity=1.0, absoluteCapacity=1.0, usedResources=<memory:1024, vCores:1>, usedCapacity=0.125, absoluteUsedCapacity=0.125, numApps=1, numContainers=1 --> <memory:1024, vCores:1>, OFF_SWITCH
2019-06-07 07:57:47,422 INFO org.apache.hadoop.yarn.server.resourcemanager.scheduler.capacity.ParentQueue: Re-sorting assigned queue: root.default stats: default: capacity=1.0, absoluteCapacity=1.0, usedResources=<memory:1024, vCores:1>, usedCapacity=0.125, absoluteUsedCapacity=0.125, numApps=1, numContainers=1
2019-06-07 07:57:47,422 INFO org.apache.hadoop.yarn.server.resourcemanager.scheduler.capacity.ParentQueue: Re-sorting assigned queue: root.default stats: default: capacity=1.0, absoluteCapacity=1.0, usedResources=<memory:1024, vCores:1>, usedCapacity=0.125, absoluteUsedCapacity=0.125, numApps=1, numContainers=1
2019-06-07 07:57:47,422 DEBUG org.apache.hadoop.yarn.server.resourcemanager.scheduler.capacity.ParentQueue: printChildQueues - queue: root child-queues: root.defaultusedCapacity=(0.125),  label=(*)
2019-06-07 07:57:47,422 DEBUG org.apache.hadoop.yarn.server.resourcemanager.scheduler.capacity.ParentQueue: printChildQueues - queue: root child-queues: root.defaultusedCapacity=(0.125),  label=(*)
2019-06-07 07:57:47,422 INFO org.apache.hadoop.yarn.server.resourcemanager.scheduler.capacity.ParentQueue: assignedContainer queue=root usedCapacity=0.125 absoluteUsedCapacity=0.125 used=<memory:1024, vCores:1> cluster=<memory:8192, vCores:2>
2019-06-07 07:57:47,422 INFO org.apache.hadoop.yarn.server.resourcemanager.scheduler.capacity.ParentQueue: assignedContainer queue=root usedCapacity=0.125 absoluteUsedCapacity=0.125 used=<memory:1024, vCores:1> cluster=<memory:8192, vCores:2>
2019-06-07 07:57:47,422 DEBUG org.apache.hadoop.yarn.server.resourcemanager.scheduler.capacity.ParentQueue: ParentQ=root assignedSoFarInThisIteration=<memory:1024, vCores:1> usedCapacity=0.125 absoluteUsedCapacity=0.125
2019-06-07 07:57:47,422 DEBUG org.apache.hadoop.yarn.server.resourcemanager.scheduler.capacity.ParentQueue: ParentQ=root assignedSoFarInThisIteration=<memory:1024, vCores:1> usedCapacity=0.125 absoluteUsedCapacity=0.125
2019-06-07 07:57:47,422 DEBUG org.apache.hadoop.yarn.server.resourcemanager.scheduler.capacity.ParentQueue: Assigned maximum number of off-switch containers: 1, assignments so far: resource:<memory:1024, vCores:1>; type:OFF_SWITCH; excessReservation:null; applicationid:null; skipped:NONE; fulfilled reservation:false; allocations(count/resource):1/<memory:1024, vCores:1>; reservations(count/resource):0/<memory:0, vCores:0>
2019-06-07 07:57:47,422 DEBUG org.apache.hadoop.yarn.server.resourcemanager.scheduler.capacity.ParentQueue: Assigned maximum number of off-switch containers: 1, assignments so far: resource:<memory:1024, vCores:1>; type:OFF_SWITCH; excessReservation:null; applicationid:null; skipped:NONE; fulfilled reservation:false; allocations(count/resource):1/<memory:1024, vCores:1>; reservations(count/resource):0/<memory:0, vCores:0>
2019-06-07 07:57:47,422 DEBUG org.apache.hadoop.yarn.server.resourcemanager.scheduler.capacity.CapacityScheduler: nodeUpdate: slave1:34830 clusterResources: <memory:8192, vCores:2>
2019-06-07 07:57:47,422 DEBUG org.apache.hadoop.yarn.server.resourcemanager.scheduler.capacity.CapacityScheduler: nodeUpdate: slave1:34830 clusterResources: <memory:8192, vCores:2>
2019-06-07 07:57:47,422 DEBUG org.apache.hadoop.yarn.server.resourcemanager.scheduler.capacity.CapacityScheduler: Node being looked for scheduling slave1:34830 availableResource: <memory:4096, vCores:1>
2019-06-07 07:57:47,422 DEBUG org.apache.hadoop.yarn.server.resourcemanager.scheduler.capacity.CapacityScheduler: Node being looked for scheduling slave1:34830 availableResource: <memory:4096, vCores:1>
2019-06-07 07:57:47,422 DEBUG org.apache.hadoop.yarn.server.resourcemanager.scheduler.capacity.CapacityScheduler: Trying to schedule on node: slave1, available: <memory:4096, vCores:1>
2019-06-07 07:57:47,422 DEBUG org.apache.hadoop.yarn.server.resourcemanager.scheduler.capacity.CapacityScheduler: Trying to schedule on node: slave1, available: <memory:4096, vCores:1>
2019-06-07 07:57:47,422 DEBUG org.apache.hadoop.yarn.server.resourcemanager.scheduler.capacity.ParentQueue: Skip this queue=root, because it doesn't need more resource, schedulingMode=RESPECT_PARTITION_EXCLUSIVITY node-partition=
2019-06-07 07:57:47,422 DEBUG org.apache.hadoop.yarn.server.resourcemanager.scheduler.capacity.ParentQueue: Skip this queue=root, because it doesn't need more resource, schedulingMode=RESPECT_PARTITION_EXCLUSIVITY node-partition=
2019-06-07 07:57:47,422 INFO org.apache.hadoop.yarn.server.resourcemanager.security.NMTokenSecretManagerInRM: Clear node set for appattempt_1559894241434_0001_000001
2019-06-07 07:57:47,422 INFO org.apache.hadoop.yarn.server.resourcemanager.security.NMTokenSecretManagerInRM: Clear node set for appattempt_1559894241434_0001_000001
2019-06-07 07:57:47,423 INFO org.apache.hadoop.yarn.server.resourcemanager.rmapp.attempt.RMAppAttemptImpl: Storing attempt: AppId: application_1559894241434_0001 AttemptId: appattempt_1559894241434_0001_000001 MasterContainer: Container: [ContainerId: container_1559894241434_0001_01_000001, Version: 0, NodeId: slave2:42768, NodeHttpAddress: slave2:8042, Resource: <memory:1024, vCores:1>, Priority: 0, Token: Token { kind: ContainerToken, service: 172.17.0.4:42768 }, ]
2019-06-07 07:57:47,423 INFO org.apache.hadoop.yarn.server.resourcemanager.rmapp.attempt.RMAppAttemptImpl: Storing attempt: AppId: application_1559894241434_0001 AttemptId: appattempt_1559894241434_0001_000001 MasterContainer: Container: [ContainerId: container_1559894241434_0001_01_000001, Version: 0, NodeId: slave2:42768, NodeHttpAddress: slave2:8042, Resource: <memory:1024, vCores:1>, Priority: 0, Token: Token { kind: ContainerToken, service: 172.17.0.4:42768 }, ]
2019-06-07 07:57:47,430 DEBUG org.apache.hadoop.yarn.server.resourcemanager.recovery.RMStateStore: Processing event of type STORE_APP_ATTEMPT
2019-06-07 07:57:47,430 DEBUG org.apache.hadoop.yarn.server.resourcemanager.recovery.RMStateStore: Processing event of type STORE_APP_ATTEMPT
2019-06-07 07:57:47,430 DEBUG org.apache.hadoop.yarn.server.resourcemanager.recovery.RMStateStore: Storing info for attempt: appattempt_1559894241434_0001_000001
2019-06-07 07:57:47,430 DEBUG org.apache.hadoop.yarn.server.resourcemanager.recovery.RMStateStore: Storing info for attempt: appattempt_1559894241434_0001_000001
2019-06-07 07:57:47,430 INFO org.apache.hadoop.yarn.server.resourcemanager.rmapp.attempt.RMAppAttemptImpl: appattempt_1559894241434_0001_000001 State change from SCHEDULED to ALLOCATED_SAVING
2019-06-07 07:57:47,430 INFO org.apache.hadoop.yarn.server.resourcemanager.rmapp.attempt.RMAppAttemptImpl: appattempt_1559894241434_0001_000001 State change from SCHEDULED to ALLOCATED_SAVING
2019-06-07 07:57:47,430 DEBUG org.apache.hadoop.yarn.server.resourcemanager.rmapp.RMAppImpl: Processing event for application_1559894241434_0001 of type APP_RUNNING_ON_NODE
2019-06-07 07:57:47,430 DEBUG org.apache.hadoop.yarn.server.resourcemanager.rmapp.RMAppImpl: Processing event for application_1559894241434_0001 of type APP_RUNNING_ON_NODE
2019-06-07 07:57:47,433 DEBUG org.apache.hadoop.yarn.server.resourcemanager.rmapp.attempt.RMAppAttemptImpl: Processing event for appattempt_1559894241434_0001_000001 of type ATTEMPT_NEW_SAVED
2019-06-07 07:57:47,433 DEBUG org.apache.hadoop.yarn.server.resourcemanager.rmapp.attempt.RMAppAttemptImpl: Processing event for appattempt_1559894241434_0001_000001 of type ATTEMPT_NEW_SAVED
2019-06-07 07:57:47,433 INFO org.apache.hadoop.yarn.server.resourcemanager.rmapp.attempt.RMAppAttemptImpl: appattempt_1559894241434_0001_000001 State change from ALLOCATED_SAVING to ALLOCATED
2019-06-07 07:57:47,433 INFO org.apache.hadoop.yarn.server.resourcemanager.rmapp.attempt.RMAppAttemptImpl: appattempt_1559894241434_0001_000001 State change from ALLOCATED_SAVING to ALLOCATED
2019-06-07 07:57:47,435 INFO org.apache.hadoop.yarn.server.resourcemanager.amlauncher.AMLauncher: Launching masterappattempt_1559894241434_0001_000001
2019-06-07 07:57:47,435 INFO org.apache.hadoop.yarn.server.resourcemanager.amlauncher.AMLauncher: Launching masterappattempt_1559894241434_0001_000001
2019-06-07 07:57:47,469 INFO org.apache.hadoop.yarn.server.resourcemanager.amlauncher.AMLauncher: Setting up container Container: [ContainerId: container_1559894241434_0001_01_000001, Version: 0, NodeId: slave2:42768, NodeHttpAddress: slave2:8042, Resource: <memory:1024, vCores:1>, Priority: 0, Token: Token { kind: ContainerToken, service: 172.17.0.4:42768 }, ] for AM appattempt_1559894241434_0001_000001
2019-06-07 07:57:47,469 INFO org.apache.hadoop.yarn.server.resourcemanager.amlauncher.AMLauncher: Setting up container Container: [ContainerId: container_1559894241434_0001_01_000001, Version: 0, NodeId: slave2:42768, NodeHttpAddress: slave2:8042, Resource: <memory:1024, vCores:1>, Priority: 0, Token: Token { kind: ContainerToken, service: 172.17.0.4:42768 }, ] for AM appattempt_1559894241434_0001_000001
2019-06-07 07:57:47,469 INFO org.apache.hadoop.yarn.server.resourcemanager.security.AMRMTokenSecretManager: Create AMRMToken for ApplicationAttempt: appattempt_1559894241434_0001_000001
2019-06-07 07:57:47,469 INFO org.apache.hadoop.yarn.server.resourcemanager.security.AMRMTokenSecretManager: Create AMRMToken for ApplicationAttempt: appattempt_1559894241434_0001_000001
2019-06-07 07:57:47,472 INFO org.apache.hadoop.yarn.server.resourcemanager.security.AMRMTokenSecretManager: Creating password for appattempt_1559894241434_0001_000001
2019-06-07 07:57:47,472 INFO org.apache.hadoop.yarn.server.resourcemanager.security.AMRMTokenSecretManager: Creating password for appattempt_1559894241434_0001_000001
2019-06-07 07:57:47,715 INFO org.apache.hadoop.yarn.server.resourcemanager.amlauncher.AMLauncher: Done launching container Container: [ContainerId: container_1559894241434_0001_01_000001, Version: 0, NodeId: slave2:42768, NodeHttpAddress: slave2:8042, Resource: <memory:1024, vCores:1>, Priority: 0, Token: Token { kind: ContainerToken, service: 172.17.0.4:42768 }, ] for AM appattempt_1559894241434_0001_000001
2019-06-07 07:57:47,715 INFO org.apache.hadoop.yarn.server.resourcemanager.amlauncher.AMLauncher: Done launching container Container: [ContainerId: container_1559894241434_0001_01_000001, Version: 0, NodeId: slave2:42768, NodeHttpAddress: slave2:8042, Resource: <memory:1024, vCores:1>, Priority: 0, Token: Token { kind: ContainerToken, service: 172.17.0.4:42768 }, ] for AM appattempt_1559894241434_0001_000001
2019-06-07 07:57:47,715 DEBUG org.apache.hadoop.yarn.server.resourcemanager.rmapp.attempt.RMAppAttemptImpl: Processing event for appattempt_1559894241434_0001_000001 of type LAUNCHED
2019-06-07 07:57:47,715 DEBUG org.apache.hadoop.yarn.server.resourcemanager.rmapp.attempt.RMAppAttemptImpl: Processing event for appattempt_1559894241434_0001_000001 of type LAUNCHED
2019-06-07 07:57:47,715 INFO org.apache.hadoop.yarn.server.resourcemanager.rmapp.attempt.RMAppAttemptImpl: appattempt_1559894241434_0001_000001 State change from ALLOCATED to LAUNCHED
2019-06-07 07:57:47,715 INFO org.apache.hadoop.yarn.server.resourcemanager.rmapp.attempt.RMAppAttemptImpl: appattempt_1559894241434_0001_000001 State change from ALLOCATED to LAUNCHED
2019-06-07 07:57:48,309 DEBUG org.apache.hadoop.yarn.server.resourcemanager.rmnode.RMNodeImpl: Processing slave2:42768 of type STATUS_UPDATE
2019-06-07 07:57:48,309 DEBUG org.apache.hadoop.yarn.server.resourcemanager.rmnode.RMNodeImpl: Processing slave2:42768 of type STATUS_UPDATE
2019-06-07 07:57:48,311 DEBUG org.apache.hadoop.yarn.server.resourcemanager.rmnode.RMNodeImpl: Container container_1559894241434_0001_01_000001 is the first container get launched for application application_1559894241434_0001
2019-06-07 07:57:48,311 DEBUG org.apache.hadoop.yarn.server.resourcemanager.rmnode.RMNodeImpl: Container container_1559894241434_0001_01_000001 is the first container get launched for application application_1559894241434_0001
2019-06-07 07:57:48,312 DEBUG org.apache.hadoop.yarn.server.resourcemanager.rmapp.RMAppImpl: Processing event for application_1559894241434_0001 of type APP_RUNNING_ON_NODE
2019-06-07 07:57:48,312 DEBUG org.apache.hadoop.yarn.server.resourcemanager.rmapp.RMAppImpl: Processing event for application_1559894241434_0001 of type APP_RUNNING_ON_NODE
2019-06-07 07:57:48,312 DEBUG org.apache.hadoop.yarn.server.resourcemanager.scheduler.capacity.CapacityScheduler: nodeUpdate: slave2:42768 clusterResources: <memory:8192, vCores:2>
2019-06-07 07:57:48,312 DEBUG org.apache.hadoop.yarn.server.resourcemanager.scheduler.capacity.CapacityScheduler: nodeUpdate: slave2:42768 clusterResources: <memory:8192, vCores:2>
2019-06-07 07:57:48,312 DEBUG org.apache.hadoop.yarn.server.resourcemanager.rmcontainer.RMContainerImpl: Processing container_1559894241434_0001_01_000001 of type LAUNCHED
2019-06-07 07:57:48,312 DEBUG org.apache.hadoop.yarn.server.resourcemanager.rmcontainer.RMContainerImpl: Processing container_1559894241434_0001_01_000001 of type LAUNCHED
2019-06-07 07:57:48,312 INFO org.apache.hadoop.yarn.server.resourcemanager.rmcontainer.RMContainerImpl: container_1559894241434_0001_01_000001 Container Transitioned from ACQUIRED to RUNNING
2019-06-07 07:57:48,312 INFO org.apache.hadoop.yarn.server.resourcemanager.rmcontainer.RMContainerImpl: container_1559894241434_0001_01_000001 Container Transitioned from ACQUIRED to RUNNING
2019-06-07 07:57:48,312 DEBUG org.apache.hadoop.yarn.server.resourcemanager.scheduler.capacity.CapacityScheduler: Node being looked for scheduling slave2:42768 availableResource: <memory:3072, vCores:0>
2019-06-07 07:57:48,312 DEBUG org.apache.hadoop.yarn.server.resourcemanager.scheduler.capacity.CapacityScheduler: Node being looked for scheduling slave2:42768 availableResource: <memory:3072, vCores:0>
2019-06-07 07:57:48,312 DEBUG org.apache.hadoop.yarn.server.resourcemanager.scheduler.capacity.CapacityScheduler: Trying to schedule on node: slave2, available: <memory:3072, vCores:0>
2019-06-07 07:57:48,312 DEBUG org.apache.hadoop.yarn.server.resourcemanager.scheduler.capacity.CapacityScheduler: Trying to schedule on node: slave2, available: <memory:3072, vCores:0>
2019-06-07 07:57:48,312 DEBUG org.apache.hadoop.yarn.server.resourcemanager.scheduler.capacity.ParentQueue: Skip this queue=root, because it doesn't need more resource, schedulingMode=RESPECT_PARTITION_EXCLUSIVITY node-partition=
2019-06-07 07:57:48,312 DEBUG org.apache.hadoop.yarn.server.resourcemanager.scheduler.capacity.ParentQueue: Skip this queue=root, because it doesn't need more resource, schedulingMode=RESPECT_PARTITION_EXCLUSIVITY node-partition=
2019-06-07 07:57:48,315 DEBUG org.apache.hadoop.yarn.server.resourcemanager.rmnode.RMNodeImpl: Processing slave1:34830 of type STATUS_UPDATE
2019-06-07 07:57:48,315 DEBUG org.apache.hadoop.yarn.server.resourcemanager.rmnode.RMNodeImpl: Processing slave1:34830 of type STATUS_UPDATE
2019-06-07 07:57:48,316 DEBUG org.apache.hadoop.yarn.server.resourcemanager.scheduler.capacity.CapacityScheduler: nodeUpdate: slave1:34830 clusterResources: <memory:8192, vCores:2>
2019-06-07 07:57:48,316 DEBUG org.apache.hadoop.yarn.server.resourcemanager.scheduler.capacity.CapacityScheduler: nodeUpdate: slave1:34830 clusterResources: <memory:8192, vCores:2>
2019-06-07 07:57:48,316 DEBUG org.apache.hadoop.yarn.server.resourcemanager.scheduler.capacity.CapacityScheduler: Node being looked for scheduling slave1:34830 availableResource: <memory:4096, vCores:1>
2019-06-07 07:57:48,316 DEBUG org.apache.hadoop.yarn.server.resourcemanager.scheduler.capacity.CapacityScheduler: Node being looked for scheduling slave1:34830 availableResource: <memory:4096, vCores:1>
2019-06-07 07:57:48,316 DEBUG org.apache.hadoop.yarn.server.resourcemanager.scheduler.capacity.CapacityScheduler: Trying to schedule on node: slave1, available: <memory:4096, vCores:1>
2019-06-07 07:57:48,316 DEBUG org.apache.hadoop.yarn.server.resourcemanager.scheduler.capacity.CapacityScheduler: Trying to schedule on node: slave1, available: <memory:4096, vCores:1>
2019-06-07 07:57:48,316 DEBUG org.apache.hadoop.yarn.server.resourcemanager.scheduler.capacity.ParentQueue: Skip this queue=root, because it doesn't need more resource, schedulingMode=RESPECT_PARTITION_EXCLUSIVITY node-partition=
2019-06-07 07:57:48,316 DEBUG org.apache.hadoop.yarn.server.resourcemanager.scheduler.capacity.ParentQueue: Skip this queue=root, because it doesn't need more resource, schedulingMode=RESPECT_PARTITION_EXCLUSIVITY node-partition=
2019-06-07 07:57:49,313 DEBUG org.apache.hadoop.yarn.server.resourcemanager.rmnode.RMNodeImpl: Processing slave2:42768 of type STATUS_UPDATE
2019-06-07 07:57:49,313 DEBUG org.apache.hadoop.yarn.server.resourcemanager.rmnode.RMNodeImpl: Processing slave2:42768 of type STATUS_UPDATE
2019-06-07 07:57:49,315 DEBUG org.apache.hadoop.yarn.server.resourcemanager.scheduler.capacity.CapacityScheduler: nodeUpdate: slave2:42768 clusterResources: <memory:8192, vCores:2>
2019-06-07 07:57:49,315 DEBUG org.apache.hadoop.yarn.server.resourcemanager.scheduler.capacity.CapacityScheduler: nodeUpdate: slave2:42768 clusterResources: <memory:8192, vCores:2>
2019-06-07 07:57:49,315 DEBUG org.apache.hadoop.yarn.server.resourcemanager.scheduler.capacity.CapacityScheduler: Node being looked for scheduling slave2:42768 availableResource: <memory:3072, vCores:0>
2019-06-07 07:57:49,315 DEBUG org.apache.hadoop.yarn.server.resourcemanager.scheduler.capacity.CapacityScheduler: Node being looked for scheduling slave2:42768 availableResource: <memory:3072, vCores:0>
2019-06-07 07:57:49,315 DEBUG org.apache.hadoop.yarn.server.resourcemanager.scheduler.capacity.CapacityScheduler: Trying to schedule on node: slave2, available: <memory:3072, vCores:0>
2019-06-07 07:57:49,315 DEBUG org.apache.hadoop.yarn.server.resourcemanager.scheduler.capacity.CapacityScheduler: Trying to schedule on node: slave2, available: <memory:3072, vCores:0>
2019-06-07 07:57:49,315 DEBUG org.apache.hadoop.yarn.server.resourcemanager.scheduler.capacity.ParentQueue: Skip this queue=root, because it doesn't need more resource, schedulingMode=RESPECT_PARTITION_EXCLUSIVITY node-partition=
2019-06-07 07:57:49,315 DEBUG org.apache.hadoop.yarn.server.resourcemanager.scheduler.capacity.ParentQueue: Skip this queue=root, because it doesn't need more resource, schedulingMode=RESPECT_PARTITION_EXCLUSIVITY node-partition=
2019-06-07 07:57:49,318 DEBUG org.apache.hadoop.yarn.server.resourcemanager.rmnode.RMNodeImpl: Processing slave1:34830 of type STATUS_UPDATE
2019-06-07 07:57:49,318 DEBUG org.apache.hadoop.yarn.server.resourcemanager.rmnode.RMNodeImpl: Processing slave1:34830 of type STATUS_UPDATE
2019-06-07 07:57:49,321 DEBUG org.apache.hadoop.yarn.server.resourcemanager.scheduler.capacity.CapacityScheduler: nodeUpdate: slave1:34830 clusterResources: <memory:8192, vCores:2>
2019-06-07 07:57:49,321 DEBUG org.apache.hadoop.yarn.server.resourcemanager.scheduler.capacity.CapacityScheduler: nodeUpdate: slave1:34830 clusterResources: <memory:8192, vCores:2>
2019-06-07 07:57:49,321 DEBUG org.apache.hadoop.yarn.server.resourcemanager.scheduler.capacity.CapacityScheduler: Node being looked for scheduling slave1:34830 availableResource: <memory:4096, vCores:1>
2019-06-07 07:57:49,321 DEBUG org.apache.hadoop.yarn.server.resourcemanager.scheduler.capacity.CapacityScheduler: Node being looked for scheduling slave1:34830 availableResource: <memory:4096, vCores:1>
2019-06-07 07:57:49,321 DEBUG org.apache.hadoop.yarn.server.resourcemanager.scheduler.capacity.CapacityScheduler: Trying to schedule on node: slave1, available: <memory:4096, vCores:1>
2019-06-07 07:57:49,321 DEBUG org.apache.hadoop.yarn.server.resourcemanager.scheduler.capacity.CapacityScheduler: Trying to schedule on node: slave1, available: <memory:4096, vCores:1>
2019-06-07 07:57:49,321 DEBUG org.apache.hadoop.yarn.server.resourcemanager.scheduler.capacity.ParentQueue: Skip this queue=root, because it doesn't need more resource, schedulingMode=RESPECT_PARTITION_EXCLUSIVITY node-partition=
2019-06-07 07:57:49,321 DEBUG org.apache.hadoop.yarn.server.resourcemanager.scheduler.capacity.ParentQueue: Skip this queue=root, because it doesn't need more resource, schedulingMode=RESPECT_PARTITION_EXCLUSIVITY node-partition=
2019-06-07 07:57:50,316 DEBUG org.apache.hadoop.yarn.server.resourcemanager.rmnode.RMNodeImpl: Processing slave2:42768 of type STATUS_UPDATE
2019-06-07 07:57:50,316 DEBUG org.apache.hadoop.yarn.server.resourcemanager.rmnode.RMNodeImpl: Processing slave2:42768 of type STATUS_UPDATE
2019-06-07 07:57:50,317 DEBUG org.apache.hadoop.yarn.server.resourcemanager.scheduler.capacity.CapacityScheduler: nodeUpdate: slave2:42768 clusterResources: <memory:8192, vCores:2>
2019-06-07 07:57:50,317 DEBUG org.apache.hadoop.yarn.server.resourcemanager.scheduler.capacity.CapacityScheduler: nodeUpdate: slave2:42768 clusterResources: <memory:8192, vCores:2>
2019-06-07 07:57:50,317 DEBUG org.apache.hadoop.yarn.server.resourcemanager.scheduler.capacity.CapacityScheduler: Node being looked for scheduling slave2:42768 availableResource: <memory:3072, vCores:0>
2019-06-07 07:57:50,317 DEBUG org.apache.hadoop.yarn.server.resourcemanager.scheduler.capacity.CapacityScheduler: Node being looked for scheduling slave2:42768 availableResource: <memory:3072, vCores:0>
2019-06-07 07:57:50,317 DEBUG org.apache.hadoop.yarn.server.resourcemanager.scheduler.capacity.CapacityScheduler: Trying to schedule on node: slave2, available: <memory:3072, vCores:0>
2019-06-07 07:57:50,317 DEBUG org.apache.hadoop.yarn.server.resourcemanager.scheduler.capacity.CapacityScheduler: Trying to schedule on node: slave2, available: <memory:3072, vCores:0>
2019-06-07 07:57:50,317 DEBUG org.apache.hadoop.yarn.server.resourcemanager.scheduler.capacity.ParentQueue: Skip this queue=root, because it doesn't need more resource, schedulingMode=RESPECT_PARTITION_EXCLUSIVITY node-partition=
2019-06-07 07:57:50,317 DEBUG org.apache.hadoop.yarn.server.resourcemanager.scheduler.capacity.ParentQueue: Skip this queue=root, because it doesn't need more resource, schedulingMode=RESPECT_PARTITION_EXCLUSIVITY node-partition=
2019-06-07 07:57:50,321 DEBUG org.apache.hadoop.yarn.server.resourcemanager.rmnode.RMNodeImpl: Processing slave1:34830 of type STATUS_UPDATE
2019-06-07 07:57:50,321 DEBUG org.apache.hadoop.yarn.server.resourcemanager.rmnode.RMNodeImpl: Processing slave1:34830 of type STATUS_UPDATE
2019-06-07 07:57:50,321 DEBUG org.apache.hadoop.yarn.server.resourcemanager.scheduler.capacity.CapacityScheduler: nodeUpdate: slave1:34830 clusterResources: <memory:8192, vCores:2>
2019-06-07 07:57:50,321 DEBUG org.apache.hadoop.yarn.server.resourcemanager.scheduler.capacity.CapacityScheduler: nodeUpdate: slave1:34830 clusterResources: <memory:8192, vCores:2>
2019-06-07 07:57:50,321 DEBUG org.apache.hadoop.yarn.server.resourcemanager.scheduler.capacity.CapacityScheduler: Node being looked for scheduling slave1:34830 availableResource: <memory:4096, vCores:1>
2019-06-07 07:57:50,321 DEBUG org.apache.hadoop.yarn.server.resourcemanager.scheduler.capacity.CapacityScheduler: Node being looked for scheduling slave1:34830 availableResource: <memory:4096, vCores:1>
2019-06-07 07:57:50,321 DEBUG org.apache.hadoop.yarn.server.resourcemanager.scheduler.capacity.CapacityScheduler: Trying to schedule on node: slave1, available: <memory:4096, vCores:1>
2019-06-07 07:57:50,321 DEBUG org.apache.hadoop.yarn.server.resourcemanager.scheduler.capacity.CapacityScheduler: Trying to schedule on node: slave1, available: <memory:4096, vCores:1>
2019-06-07 07:57:50,321 DEBUG org.apache.hadoop.yarn.server.resourcemanager.scheduler.capacity.ParentQueue: Skip this queue=root, because it doesn't need more resource, schedulingMode=RESPECT_PARTITION_EXCLUSIVITY node-partition=
2019-06-07 07:57:50,321 DEBUG org.apache.hadoop.yarn.server.resourcemanager.scheduler.capacity.ParentQueue: Skip this queue=root, because it doesn't need more resource, schedulingMode=RESPECT_PARTITION_EXCLUSIVITY node-partition=
2019-06-07 07:57:51,324 DEBUG org.apache.hadoop.yarn.server.resourcemanager.rmnode.RMNodeImpl: Processing slave1:34830 of type STATUS_UPDATE
2019-06-07 07:57:51,324 DEBUG org.apache.hadoop.yarn.server.resourcemanager.rmnode.RMNodeImpl: Processing slave1:34830 of type STATUS_UPDATE
2019-06-07 07:57:51,324 DEBUG org.apache.hadoop.yarn.server.resourcemanager.scheduler.capacity.CapacityScheduler: nodeUpdate: slave1:34830 clusterResources: <memory:8192, vCores:2>
2019-06-07 07:57:51,324 DEBUG org.apache.hadoop.yarn.server.resourcemanager.scheduler.capacity.CapacityScheduler: nodeUpdate: slave1:34830 clusterResources: <memory:8192, vCores:2>
2019-06-07 07:57:51,324 DEBUG org.apache.hadoop.yarn.server.resourcemanager.scheduler.capacity.CapacityScheduler: Node being looked for scheduling slave1:34830 availableResource: <memory:4096, vCores:1>
2019-06-07 07:57:51,324 DEBUG org.apache.hadoop.yarn.server.resourcemanager.scheduler.capacity.CapacityScheduler: Node being looked for scheduling slave1:34830 availableResource: <memory:4096, vCores:1>
2019-06-07 07:57:51,324 DEBUG org.apache.hadoop.yarn.server.resourcemanager.scheduler.capacity.CapacityScheduler: Trying to schedule on node: slave1, available: <memory:4096, vCores:1>
2019-06-07 07:57:51,324 DEBUG org.apache.hadoop.yarn.server.resourcemanager.scheduler.capacity.CapacityScheduler: Trying to schedule on node: slave1, available: <memory:4096, vCores:1>
2019-06-07 07:57:51,324 DEBUG org.apache.hadoop.yarn.server.resourcemanager.scheduler.capacity.ParentQueue: Skip this queue=root, because it doesn't need more resource, schedulingMode=RESPECT_PARTITION_EXCLUSIVITY node-partition=
2019-06-07 07:57:51,324 DEBUG org.apache.hadoop.yarn.server.resourcemanager.scheduler.capacity.ParentQueue: Skip this queue=root, because it doesn't need more resource, schedulingMode=RESPECT_PARTITION_EXCLUSIVITY node-partition=
2019-06-07 07:57:51,332 DEBUG org.apache.hadoop.yarn.server.resourcemanager.rmnode.RMNodeImpl: Processing slave2:42768 of type STATUS_UPDATE
2019-06-07 07:57:51,332 DEBUG org.apache.hadoop.yarn.server.resourcemanager.rmnode.RMNodeImpl: Processing slave2:42768 of type STATUS_UPDATE
2019-06-07 07:57:51,332 DEBUG org.apache.hadoop.yarn.server.resourcemanager.scheduler.capacity.CapacityScheduler: nodeUpdate: slave2:42768 clusterResources: <memory:8192, vCores:2>
2019-06-07 07:57:51,332 DEBUG org.apache.hadoop.yarn.server.resourcemanager.scheduler.capacity.CapacityScheduler: nodeUpdate: slave2:42768 clusterResources: <memory:8192, vCores:2>
2019-06-07 07:57:51,332 DEBUG org.apache.hadoop.yarn.server.resourcemanager.scheduler.capacity.CapacityScheduler: Node being looked for scheduling slave2:42768 availableResource: <memory:3072, vCores:0>
2019-06-07 07:57:51,332 DEBUG org.apache.hadoop.yarn.server.resourcemanager.scheduler.capacity.CapacityScheduler: Node being looked for scheduling slave2:42768 availableResource: <memory:3072, vCores:0>
2019-06-07 07:57:51,332 DEBUG org.apache.hadoop.yarn.server.resourcemanager.scheduler.capacity.CapacityScheduler: Trying to schedule on node: slave2, available: <memory:3072, vCores:0>
2019-06-07 07:57:51,332 DEBUG org.apache.hadoop.yarn.server.resourcemanager.scheduler.capacity.CapacityScheduler: Trying to schedule on node: slave2, available: <memory:3072, vCores:0>
2019-06-07 07:57:51,332 DEBUG org.apache.hadoop.yarn.server.resourcemanager.scheduler.capacity.ParentQueue: Skip this queue=root, because it doesn't need more resource, schedulingMode=RESPECT_PARTITION_EXCLUSIVITY node-partition=
2019-06-07 07:57:51,332 DEBUG org.apache.hadoop.yarn.server.resourcemanager.scheduler.capacity.ParentQueue: Skip this queue=root, because it doesn't need more resource, schedulingMode=RESPECT_PARTITION_EXCLUSIVITY node-partition=
2019-06-07 07:57:52,326 DEBUG org.apache.hadoop.yarn.server.resourcemanager.rmnode.RMNodeImpl: Processing slave1:34830 of type STATUS_UPDATE
2019-06-07 07:57:52,326 DEBUG org.apache.hadoop.yarn.server.resourcemanager.rmnode.RMNodeImpl: Processing slave1:34830 of type STATUS_UPDATE
2019-06-07 07:57:52,327 DEBUG org.apache.hadoop.yarn.server.resourcemanager.scheduler.capacity.CapacityScheduler: nodeUpdate: slave1:34830 clusterResources: <memory:8192, vCores:2>
2019-06-07 07:57:52,327 DEBUG org.apache.hadoop.yarn.server.resourcemanager.scheduler.capacity.CapacityScheduler: nodeUpdate: slave1:34830 clusterResources: <memory:8192, vCores:2>
2019-06-07 07:57:52,327 DEBUG org.apache.hadoop.yarn.server.resourcemanager.scheduler.capacity.CapacityScheduler: Node being looked for scheduling slave1:34830 availableResource: <memory:4096, vCores:1>
2019-06-07 07:57:52,327 DEBUG org.apache.hadoop.yarn.server.resourcemanager.scheduler.capacity.CapacityScheduler: Node being looked for scheduling slave1:34830 availableResource: <memory:4096, vCores:1>
2019-06-07 07:57:52,327 DEBUG org.apache.hadoop.yarn.server.resourcemanager.scheduler.capacity.CapacityScheduler: Trying to schedule on node: slave1, available: <memory:4096, vCores:1>
2019-06-07 07:57:52,327 DEBUG org.apache.hadoop.yarn.server.resourcemanager.scheduler.capacity.CapacityScheduler: Trying to schedule on node: slave1, available: <memory:4096, vCores:1>
2019-06-07 07:57:52,327 DEBUG org.apache.hadoop.yarn.server.resourcemanager.scheduler.capacity.ParentQueue: Skip this queue=root, because it doesn't need more resource, schedulingMode=RESPECT_PARTITION_EXCLUSIVITY node-partition=
2019-06-07 07:57:52,327 DEBUG org.apache.hadoop.yarn.server.resourcemanager.scheduler.capacity.ParentQueue: Skip this queue=root, because it doesn't need more resource, schedulingMode=RESPECT_PARTITION_EXCLUSIVITY node-partition=
2019-06-07 07:57:52,335 DEBUG org.apache.hadoop.yarn.server.resourcemanager.rmnode.RMNodeImpl: Processing slave2:42768 of type STATUS_UPDATE
2019-06-07 07:57:52,335 DEBUG org.apache.hadoop.yarn.server.resourcemanager.rmnode.RMNodeImpl: Processing slave2:42768 of type STATUS_UPDATE
2019-06-07 07:57:52,335 DEBUG org.apache.hadoop.yarn.server.resourcemanager.scheduler.capacity.CapacityScheduler: nodeUpdate: slave2:42768 clusterResources: <memory:8192, vCores:2>
2019-06-07 07:57:52,335 DEBUG org.apache.hadoop.yarn.server.resourcemanager.scheduler.capacity.CapacityScheduler: nodeUpdate: slave2:42768 clusterResources: <memory:8192, vCores:2>
2019-06-07 07:57:52,335 DEBUG org.apache.hadoop.yarn.server.resourcemanager.scheduler.capacity.CapacityScheduler: Node being looked for scheduling slave2:42768 availableResource: <memory:3072, vCores:0>
2019-06-07 07:57:52,335 DEBUG org.apache.hadoop.yarn.server.resourcemanager.scheduler.capacity.CapacityScheduler: Node being looked for scheduling slave2:42768 availableResource: <memory:3072, vCores:0>
2019-06-07 07:57:52,335 DEBUG org.apache.hadoop.yarn.server.resourcemanager.scheduler.capacity.CapacityScheduler: Trying to schedule on node: slave2, available: <memory:3072, vCores:0>
2019-06-07 07:57:52,335 DEBUG org.apache.hadoop.yarn.server.resourcemanager.scheduler.capacity.CapacityScheduler: Trying to schedule on node: slave2, available: <memory:3072, vCores:0>
2019-06-07 07:57:52,335 DEBUG org.apache.hadoop.yarn.server.resourcemanager.scheduler.capacity.ParentQueue: Skip this queue=root, because it doesn't need more resource, schedulingMode=RESPECT_PARTITION_EXCLUSIVITY node-partition=
2019-06-07 07:57:52,335 DEBUG org.apache.hadoop.yarn.server.resourcemanager.scheduler.capacity.ParentQueue: Skip this queue=root, because it doesn't need more resource, schedulingMode=RESPECT_PARTITION_EXCLUSIVITY node-partition=
2019-06-07 07:57:53,331 DEBUG org.apache.hadoop.yarn.server.resourcemanager.rmnode.RMNodeImpl: Processing slave1:34830 of type STATUS_UPDATE
2019-06-07 07:57:53,331 DEBUG org.apache.hadoop.yarn.server.resourcemanager.rmnode.RMNodeImpl: Processing slave1:34830 of type STATUS_UPDATE
2019-06-07 07:57:53,331 DEBUG org.apache.hadoop.yarn.server.resourcemanager.scheduler.capacity.CapacityScheduler: nodeUpdate: slave1:34830 clusterResources: <memory:8192, vCores:2>
2019-06-07 07:57:53,331 DEBUG org.apache.hadoop.yarn.server.resourcemanager.scheduler.capacity.CapacityScheduler: nodeUpdate: slave1:34830 clusterResources: <memory:8192, vCores:2>
2019-06-07 07:57:53,331 DEBUG org.apache.hadoop.yarn.server.resourcemanager.scheduler.capacity.CapacityScheduler: Node being looked for scheduling slave1:34830 availableResource: <memory:4096, vCores:1>
2019-06-07 07:57:53,331 DEBUG org.apache.hadoop.yarn.server.resourcemanager.scheduler.capacity.CapacityScheduler: Node being looked for scheduling slave1:34830 availableResource: <memory:4096, vCores:1>
2019-06-07 07:57:53,331 DEBUG org.apache.hadoop.yarn.server.resourcemanager.scheduler.capacity.CapacityScheduler: Trying to schedule on node: slave1, available: <memory:4096, vCores:1>
2019-06-07 07:57:53,331 DEBUG org.apache.hadoop.yarn.server.resourcemanager.scheduler.capacity.CapacityScheduler: Trying to schedule on node: slave1, available: <memory:4096, vCores:1>
2019-06-07 07:57:53,331 DEBUG org.apache.hadoop.yarn.server.resourcemanager.scheduler.capacity.ParentQueue: Skip this queue=root, because it doesn't need more resource, schedulingMode=RESPECT_PARTITION_EXCLUSIVITY node-partition=
2019-06-07 07:57:53,331 DEBUG org.apache.hadoop.yarn.server.resourcemanager.scheduler.capacity.ParentQueue: Skip this queue=root, because it doesn't need more resource, schedulingMode=RESPECT_PARTITION_EXCLUSIVITY node-partition=
2019-06-07 07:57:53,339 DEBUG org.apache.hadoop.yarn.server.resourcemanager.rmnode.RMNodeImpl: Processing slave2:42768 of type STATUS_UPDATE
2019-06-07 07:57:53,339 DEBUG org.apache.hadoop.yarn.server.resourcemanager.rmnode.RMNodeImpl: Processing slave2:42768 of type STATUS_UPDATE
2019-06-07 07:57:53,339 DEBUG org.apache.hadoop.yarn.server.resourcemanager.scheduler.capacity.CapacityScheduler: nodeUpdate: slave2:42768 clusterResources: <memory:8192, vCores:2>
2019-06-07 07:57:53,339 DEBUG org.apache.hadoop.yarn.server.resourcemanager.scheduler.capacity.CapacityScheduler: nodeUpdate: slave2:42768 clusterResources: <memory:8192, vCores:2>
2019-06-07 07:57:53,339 DEBUG org.apache.hadoop.yarn.server.resourcemanager.scheduler.capacity.CapacityScheduler: Node being looked for scheduling slave2:42768 availableResource: <memory:3072, vCores:0>
2019-06-07 07:57:53,339 DEBUG org.apache.hadoop.yarn.server.resourcemanager.scheduler.capacity.CapacityScheduler: Node being looked for scheduling slave2:42768 availableResource: <memory:3072, vCores:0>
2019-06-07 07:57:53,339 DEBUG org.apache.hadoop.yarn.server.resourcemanager.scheduler.capacity.CapacityScheduler: Trying to schedule on node: slave2, available: <memory:3072, vCores:0>
2019-06-07 07:57:53,339 DEBUG org.apache.hadoop.yarn.server.resourcemanager.scheduler.capacity.CapacityScheduler: Trying to schedule on node: slave2, available: <memory:3072, vCores:0>
2019-06-07 07:57:53,339 DEBUG org.apache.hadoop.yarn.server.resourcemanager.scheduler.capacity.ParentQueue: Skip this queue=root, because it doesn't need more resource, schedulingMode=RESPECT_PARTITION_EXCLUSIVITY node-partition=
2019-06-07 07:57:53,339 DEBUG org.apache.hadoop.yarn.server.resourcemanager.scheduler.capacity.ParentQueue: Skip this queue=root, because it doesn't need more resource, schedulingMode=RESPECT_PARTITION_EXCLUSIVITY node-partition=
2019-06-07 07:57:53,499 DEBUG org.apache.hadoop.yarn.server.resourcemanager.security.AMRMTokenSecretManager: Trying to retrieve password for appattempt_1559894241434_0001_000001
2019-06-07 07:57:53,499 DEBUG org.apache.hadoop.yarn.server.resourcemanager.security.AMRMTokenSecretManager: Trying to retrieve password for appattempt_1559894241434_0001_000001
2019-06-07 07:57:53,500 INFO SecurityLogger.org.apache.hadoop.ipc.Server: Auth successful for appattempt_1559894241434_0001_000001 (auth:SIMPLE)
2019-06-07 07:57:53,512 INFO org.apache.hadoop.yarn.server.resourcemanager.ApplicationMasterService: AM registration appattempt_1559894241434_0001_000001
2019-06-07 07:57:53,512 INFO org.apache.hadoop.yarn.server.resourcemanager.ApplicationMasterService: AM registration appattempt_1559894241434_0001_000001
2019-06-07 07:57:53,513 INFO org.apache.hadoop.yarn.server.resourcemanager.RMAuditLogger: USER=root	IP=172.17.0.4	OPERATION=Register App Master	TARGET=ApplicationMasterService	RESULT=SUCCESS	APPID=application_1559894241434_0001	APPATTEMPTID=appattempt_1559894241434_0001_000001
2019-06-07 07:57:53,513 INFO org.apache.hadoop.yarn.server.resourcemanager.RMAuditLogger: USER=root	IP=172.17.0.4	OPERATION=Register App Master	TARGET=ApplicationMasterService	RESULT=SUCCESS	APPID=application_1559894241434_0001	APPATTEMPTID=appattempt_1559894241434_0001_000001
2019-06-07 07:57:53,513 DEBUG org.apache.hadoop.yarn.server.resourcemanager.rmapp.attempt.RMAppAttemptImpl: Processing event for appattempt_1559894241434_0001_000001 of type REGISTERED
2019-06-07 07:57:53,513 DEBUG org.apache.hadoop.yarn.server.resourcemanager.rmapp.attempt.RMAppAttemptImpl: Processing event for appattempt_1559894241434_0001_000001 of type REGISTERED
2019-06-07 07:57:53,514 INFO org.apache.hadoop.yarn.server.resourcemanager.rmapp.attempt.RMAppAttemptImpl: appattempt_1559894241434_0001_000001 State change from LAUNCHED to RUNNING
2019-06-07 07:57:53,514 INFO org.apache.hadoop.yarn.server.resourcemanager.rmapp.attempt.RMAppAttemptImpl: appattempt_1559894241434_0001_000001 State change from LAUNCHED to RUNNING
2019-06-07 07:57:53,514 DEBUG org.apache.hadoop.yarn.server.resourcemanager.rmapp.RMAppImpl: Processing event for application_1559894241434_0001 of type ATTEMPT_REGISTERED
2019-06-07 07:57:53,514 DEBUG org.apache.hadoop.yarn.server.resourcemanager.rmapp.RMAppImpl: Processing event for application_1559894241434_0001 of type ATTEMPT_REGISTERED
2019-06-07 07:57:53,514 INFO org.apache.hadoop.yarn.server.resourcemanager.rmapp.RMAppImpl: application_1559894241434_0001 State change from ACCEPTED to RUNNING on event=ATTEMPT_REGISTERED
2019-06-07 07:57:53,514 INFO org.apache.hadoop.yarn.server.resourcemanager.rmapp.RMAppImpl: application_1559894241434_0001 State change from ACCEPTED to RUNNING on event=ATTEMPT_REGISTERED
2019-06-07 07:57:53,633 DEBUG org.apache.hadoop.yarn.server.resourcemanager.rmapp.attempt.RMAppAttemptImpl: Processing event for appattempt_1559894241434_0001_000001 of type STATUS_UPDATE
2019-06-07 07:57:53,633 DEBUG org.apache.hadoop.yarn.server.resourcemanager.rmapp.attempt.RMAppAttemptImpl: Processing event for appattempt_1559894241434_0001_000001 of type STATUS_UPDATE
2019-06-07 07:57:53,634 DEBUG org.apache.hadoop.yarn.server.resourcemanager.scheduler.capacity.CapacityScheduler: allocate: pre-update appattempt_1559894241434_0001_000001 ask size =1
2019-06-07 07:57:53,634 DEBUG org.apache.hadoop.yarn.server.resourcemanager.scheduler.capacity.CapacityScheduler: allocate: pre-update appattempt_1559894241434_0001_000001 ask size =1
2019-06-07 07:57:53,634 DEBUG org.apache.hadoop.yarn.server.resourcemanager.scheduler.ActiveUsersManager: User root added to activeUsers, currently: 1
2019-06-07 07:57:53,634 DEBUG org.apache.hadoop.yarn.server.resourcemanager.scheduler.ActiveUsersManager: User root added to activeUsers, currently: 1
2019-06-07 07:57:53,634 DEBUG org.apache.hadoop.yarn.server.resourcemanager.scheduler.capacity.CapacityScheduler: allocate: post-update
2019-06-07 07:57:53,634 DEBUG org.apache.hadoop.yarn.server.resourcemanager.scheduler.capacity.CapacityScheduler: allocate: post-update
2019-06-07 07:57:53,634 DEBUG org.apache.hadoop.yarn.server.resourcemanager.scheduler.capacity.LeafQueue: User limit computation for root in queue default userLimitPercent=100 userLimitFactor=1.0 required: <memory:1024, vCores:1> consumed: <memory:1024, vCores:1> user-limit-resource: <memory:8192, vCores:1> queueCapacity: <memory:8192, vCores:1> qconsumed: <memory:1024, vCores:1> consumedRatio: 0.0 currentCapacity: <memory:8192, vCores:1> activeUsers: 1.0 clusterCapacity: <memory:8192, vCores:2> resourceByLabel: <memory:8192, vCores:2> usageratio: 0.125 Partition:  maxUserLimit=<memory:8192, vCores:1> userWeight=1.0
2019-06-07 07:57:53,634 DEBUG org.apache.hadoop.yarn.server.resourcemanager.scheduler.capacity.LeafQueue: User limit computation for root in queue default userLimitPercent=100 userLimitFactor=1.0 required: <memory:1024, vCores:1> consumed: <memory:1024, vCores:1> user-limit-resource: <memory:8192, vCores:1> queueCapacity: <memory:8192, vCores:1> qconsumed: <memory:1024, vCores:1> consumedRatio: 0.0 currentCapacity: <memory:8192, vCores:1> activeUsers: 1.0 clusterCapacity: <memory:8192, vCores:2> resourceByLabel: <memory:8192, vCores:2> usageratio: 0.125 Partition:  maxUserLimit=<memory:8192, vCores:1> userWeight=1.0
2019-06-07 07:57:53,634 DEBUG org.apache.hadoop.yarn.server.resourcemanager.scheduler.SchedulerApplicationAttempt: showRequests: application=application_1559894241434_0001 headRoom=<memory:7168, vCores:1> currentConsumption=1024
2019-06-07 07:57:53,634 DEBUG org.apache.hadoop.yarn.server.resourcemanager.scheduler.SchedulerApplicationAttempt: showRequests: application=application_1559894241434_0001 headRoom=<memory:7168, vCores:1> currentConsumption=1024
2019-06-07 07:57:53,634 DEBUG org.apache.hadoop.yarn.server.resourcemanager.scheduler.SchedulerApplicationAttempt: showRequests: application=application_1559894241434_0001 request={Priority: 1, Capability: <memory:3072, vCores:1>, # Containers: 2, Location: *, Relax Locality: true, Node Label Expression: }
2019-06-07 07:57:53,634 DEBUG org.apache.hadoop.yarn.server.resourcemanager.scheduler.SchedulerApplicationAttempt: showRequests: application=application_1559894241434_0001 request={Priority: 1, Capability: <memory:3072, vCores:1>, # Containers: 2, Location: *, Relax Locality: true, Node Label Expression: }
2019-06-07 07:57:53,634 DEBUG org.apache.hadoop.yarn.server.resourcemanager.scheduler.capacity.LeafQueue: User limit computation for root in queue default userLimitPercent=100 userLimitFactor=1.0 required: <memory:1024, vCores:1> consumed: <memory:1024, vCores:1> user-limit-resource: <memory:8192, vCores:1> queueCapacity: <memory:8192, vCores:1> qconsumed: <memory:1024, vCores:1> consumedRatio: 0.0 currentCapacity: <memory:8192, vCores:1> activeUsers: 1.0 clusterCapacity: <memory:8192, vCores:2> resourceByLabel: <memory:8192, vCores:2> usageratio: 0.125 Partition:  maxUserLimit=<memory:8192, vCores:1> userWeight=1.0
2019-06-07 07:57:53,634 DEBUG org.apache.hadoop.yarn.server.resourcemanager.scheduler.capacity.LeafQueue: User limit computation for root in queue default userLimitPercent=100 userLimitFactor=1.0 required: <memory:1024, vCores:1> consumed: <memory:1024, vCores:1> user-limit-resource: <memory:8192, vCores:1> queueCapacity: <memory:8192, vCores:1> qconsumed: <memory:1024, vCores:1> consumedRatio: 0.0 currentCapacity: <memory:8192, vCores:1> activeUsers: 1.0 clusterCapacity: <memory:8192, vCores:2> resourceByLabel: <memory:8192, vCores:2> usageratio: 0.125 Partition:  maxUserLimit=<memory:8192, vCores:1> userWeight=1.0
2019-06-07 07:57:53,678 DEBUG org.apache.hadoop.yarn.server.resourcemanager.rmapp.attempt.RMAppAttemptImpl: Processing event for appattempt_1559894241434_0001_000001 of type STATUS_UPDATE
2019-06-07 07:57:53,678 DEBUG org.apache.hadoop.yarn.server.resourcemanager.rmapp.attempt.RMAppAttemptImpl: Processing event for appattempt_1559894241434_0001_000001 of type STATUS_UPDATE
2019-06-07 07:57:53,682 DEBUG org.apache.hadoop.yarn.server.resourcemanager.scheduler.capacity.LeafQueue: User limit computation for root in queue default userLimitPercent=100 userLimitFactor=1.0 required: <memory:1024, vCores:1> consumed: <memory:1024, vCores:1> user-limit-resource: <memory:8192, vCores:1> queueCapacity: <memory:8192, vCores:1> qconsumed: <memory:1024, vCores:1> consumedRatio: 0.0 currentCapacity: <memory:8192, vCores:1> activeUsers: 1.0 clusterCapacity: <memory:8192, vCores:2> resourceByLabel: <memory:8192, vCores:2> usageratio: 0.125 Partition:  maxUserLimit=<memory:8192, vCores:1> userWeight=1.0
2019-06-07 07:57:53,682 DEBUG org.apache.hadoop.yarn.server.resourcemanager.scheduler.capacity.LeafQueue: User limit computation for root in queue default userLimitPercent=100 userLimitFactor=1.0 required: <memory:1024, vCores:1> consumed: <memory:1024, vCores:1> user-limit-resource: <memory:8192, vCores:1> queueCapacity: <memory:8192, vCores:1> qconsumed: <memory:1024, vCores:1> consumedRatio: 0.0 currentCapacity: <memory:8192, vCores:1> activeUsers: 1.0 clusterCapacity: <memory:8192, vCores:2> resourceByLabel: <memory:8192, vCores:2> usageratio: 0.125 Partition:  maxUserLimit=<memory:8192, vCores:1> userWeight=1.0
2019-06-07 07:57:53,892 DEBUG org.apache.hadoop.yarn.server.resourcemanager.scheduler.capacity.LeafQueue: User limit computation for root in queue default userLimitPercent=100 userLimitFactor=1.0 required: <memory:1024, vCores:1> consumed: <memory:1024, vCores:1> user-limit-resource: <memory:8192, vCores:1> queueCapacity: <memory:8192, vCores:1> qconsumed: <memory:1024, vCores:1> consumedRatio: 0.0 currentCapacity: <memory:8192, vCores:1> activeUsers: 1.0 clusterCapacity: <memory:8192, vCores:2> resourceByLabel: <memory:8192, vCores:2> usageratio: 0.125 Partition:  maxUserLimit=<memory:8192, vCores:1> userWeight=1.0
2019-06-07 07:57:53,892 DEBUG org.apache.hadoop.yarn.server.resourcemanager.scheduler.capacity.LeafQueue: User limit computation for root in queue default userLimitPercent=100 userLimitFactor=1.0 required: <memory:1024, vCores:1> consumed: <memory:1024, vCores:1> user-limit-resource: <memory:8192, vCores:1> queueCapacity: <memory:8192, vCores:1> qconsumed: <memory:1024, vCores:1> consumedRatio: 0.0 currentCapacity: <memory:8192, vCores:1> activeUsers: 1.0 clusterCapacity: <memory:8192, vCores:2> resourceByLabel: <memory:8192, vCores:2> usageratio: 0.125 Partition:  maxUserLimit=<memory:8192, vCores:1> userWeight=1.0
2019-06-07 07:57:53,892 DEBUG org.apache.hadoop.yarn.server.resourcemanager.rmapp.attempt.RMAppAttemptImpl: Processing event for appattempt_1559894241434_0001_000001 of type STATUS_UPDATE
2019-06-07 07:57:53,892 DEBUG org.apache.hadoop.yarn.server.resourcemanager.rmapp.attempt.RMAppAttemptImpl: Processing event for appattempt_1559894241434_0001_000001 of type STATUS_UPDATE
2019-06-07 07:57:54,300 DEBUG org.apache.hadoop.yarn.server.resourcemanager.scheduler.capacity.LeafQueue: User limit computation for root in queue default userLimitPercent=100 userLimitFactor=1.0 required: <memory:1024, vCores:1> consumed: <memory:1024, vCores:1> user-limit-resource: <memory:8192, vCores:1> queueCapacity: <memory:8192, vCores:1> qconsumed: <memory:1024, vCores:1> consumedRatio: 0.0 currentCapacity: <memory:8192, vCores:1> activeUsers: 1.0 clusterCapacity: <memory:8192, vCores:2> resourceByLabel: <memory:8192, vCores:2> usageratio: 0.125 Partition:  maxUserLimit=<memory:8192, vCores:1> userWeight=1.0
2019-06-07 07:57:54,301 DEBUG org.apache.hadoop.yarn.server.resourcemanager.rmapp.attempt.RMAppAttemptImpl: Processing event for appattempt_1559894241434_0001_000001 of type STATUS_UPDATE
2019-06-07 07:57:54,300 DEBUG org.apache.hadoop.yarn.server.resourcemanager.scheduler.capacity.LeafQueue: User limit computation for root in queue default userLimitPercent=100 userLimitFactor=1.0 required: <memory:1024, vCores:1> consumed: <memory:1024, vCores:1> user-limit-resource: <memory:8192, vCores:1> queueCapacity: <memory:8192, vCores:1> qconsumed: <memory:1024, vCores:1> consumedRatio: 0.0 currentCapacity: <memory:8192, vCores:1> activeUsers: 1.0 clusterCapacity: <memory:8192, vCores:2> resourceByLabel: <memory:8192, vCores:2> usageratio: 0.125 Partition:  maxUserLimit=<memory:8192, vCores:1> userWeight=1.0
2019-06-07 07:57:54,301 DEBUG org.apache.hadoop.yarn.server.resourcemanager.rmapp.attempt.RMAppAttemptImpl: Processing event for appattempt_1559894241434_0001_000001 of type STATUS_UPDATE
2019-06-07 07:57:54,335 DEBUG org.apache.hadoop.yarn.server.resourcemanager.rmnode.RMNodeImpl: Processing slave1:34830 of type STATUS_UPDATE
2019-06-07 07:57:54,335 DEBUG org.apache.hadoop.yarn.server.resourcemanager.rmnode.RMNodeImpl: Processing slave1:34830 of type STATUS_UPDATE
2019-06-07 07:57:54,335 DEBUG org.apache.hadoop.yarn.server.resourcemanager.scheduler.capacity.CapacityScheduler: nodeUpdate: slave1:34830 clusterResources: <memory:8192, vCores:2>
2019-06-07 07:57:54,335 DEBUG org.apache.hadoop.yarn.server.resourcemanager.scheduler.capacity.CapacityScheduler: nodeUpdate: slave1:34830 clusterResources: <memory:8192, vCores:2>
2019-06-07 07:57:54,336 DEBUG org.apache.hadoop.yarn.server.resourcemanager.scheduler.capacity.CapacityScheduler: Node being looked for scheduling slave1:34830 availableResource: <memory:4096, vCores:1>
2019-06-07 07:57:54,336 DEBUG org.apache.hadoop.yarn.server.resourcemanager.scheduler.capacity.CapacityScheduler: Node being looked for scheduling slave1:34830 availableResource: <memory:4096, vCores:1>
2019-06-07 07:57:54,337 DEBUG org.apache.hadoop.yarn.server.resourcemanager.scheduler.capacity.CapacityScheduler: Trying to schedule on node: slave1, available: <memory:4096, vCores:1>
2019-06-07 07:57:54,337 DEBUG org.apache.hadoop.yarn.server.resourcemanager.scheduler.capacity.CapacityScheduler: Trying to schedule on node: slave1, available: <memory:4096, vCores:1>
2019-06-07 07:57:54,337 DEBUG org.apache.hadoop.yarn.server.resourcemanager.scheduler.capacity.ParentQueue: Trying to assign containers to child-queue of root
2019-06-07 07:57:54,337 DEBUG org.apache.hadoop.yarn.server.resourcemanager.scheduler.capacity.ParentQueue: Trying to assign containers to child-queue of root
2019-06-07 07:57:54,337 DEBUG org.apache.hadoop.yarn.server.resourcemanager.scheduler.capacity.ParentQueue: printChildQueues - queue: root child-queues: root.defaultusedCapacity=(0.125),  label=(*)
2019-06-07 07:57:54,337 DEBUG org.apache.hadoop.yarn.server.resourcemanager.scheduler.capacity.ParentQueue: printChildQueues - queue: root child-queues: root.defaultusedCapacity=(0.125),  label=(*)
2019-06-07 07:57:54,337 DEBUG org.apache.hadoop.yarn.server.resourcemanager.scheduler.capacity.ParentQueue: Trying to assign to queue: root.default stats: default: capacity=1.0, absoluteCapacity=1.0, usedResources=<memory:1024, vCores:1>, usedCapacity=0.125, absoluteUsedCapacity=0.125, numApps=1, numContainers=1
2019-06-07 07:57:54,337 DEBUG org.apache.hadoop.yarn.server.resourcemanager.scheduler.capacity.ParentQueue: Trying to assign to queue: root.default stats: default: capacity=1.0, absoluteCapacity=1.0, usedResources=<memory:1024, vCores:1>, usedCapacity=0.125, absoluteUsedCapacity=0.125, numApps=1, numContainers=1
2019-06-07 07:57:54,337 DEBUG org.apache.hadoop.yarn.server.resourcemanager.scheduler.capacity.LeafQueue: assignContainers: node=slave1 #applications=1
2019-06-07 07:57:54,337 DEBUG org.apache.hadoop.yarn.server.resourcemanager.scheduler.capacity.LeafQueue: assignContainers: node=slave1 #applications=1
2019-06-07 07:57:54,337 DEBUG org.apache.hadoop.yarn.server.resourcemanager.scheduler.capacity.LeafQueue: User limit computation for root in queue default userLimitPercent=100 userLimitFactor=1.0 required: <memory:1024, vCores:1> consumed: <memory:1024, vCores:1> user-limit-resource: <memory:8192, vCores:1> queueCapacity: <memory:8192, vCores:1> qconsumed: <memory:1024, vCores:1> consumedRatio: 0.0 currentCapacity: <memory:8192, vCores:1> activeUsers: 1.0 clusterCapacity: <memory:8192, vCores:2> resourceByLabel: <memory:8192, vCores:2> usageratio: 0.125 Partition:  maxUserLimit=<memory:8192, vCores:1> userWeight=1.0
2019-06-07 07:57:54,337 DEBUG org.apache.hadoop.yarn.server.resourcemanager.scheduler.capacity.LeafQueue: User limit computation for root in queue default userLimitPercent=100 userLimitFactor=1.0 required: <memory:1024, vCores:1> consumed: <memory:1024, vCores:1> user-limit-resource: <memory:8192, vCores:1> queueCapacity: <memory:8192, vCores:1> qconsumed: <memory:1024, vCores:1> consumedRatio: 0.0 currentCapacity: <memory:8192, vCores:1> activeUsers: 1.0 clusterCapacity: <memory:8192, vCores:2> resourceByLabel: <memory:8192, vCores:2> usageratio: 0.125 Partition:  maxUserLimit=<memory:8192, vCores:1> userWeight=1.0
2019-06-07 07:57:54,337 DEBUG org.apache.hadoop.yarn.server.resourcemanager.scheduler.capacity.LeafQueue: Headroom calculation for user root:  userLimit=<memory:8192, vCores:1> queueMaxAvailRes=<memory:8192, vCores:1> consumed=<memory:1024, vCores:1>
2019-06-07 07:57:54,337 DEBUG org.apache.hadoop.yarn.server.resourcemanager.scheduler.capacity.LeafQueue: Headroom calculation for user root:  userLimit=<memory:8192, vCores:1> queueMaxAvailRes=<memory:8192, vCores:1> consumed=<memory:1024, vCores:1>
2019-06-07 07:57:54,337 DEBUG org.apache.hadoop.yarn.server.resourcemanager.scheduler.common.fica.FiCaSchedulerApp: pre-assignContainers for application application_1559894241434_0001
2019-06-07 07:57:54,337 DEBUG org.apache.hadoop.yarn.server.resourcemanager.scheduler.common.fica.FiCaSchedulerApp: pre-assignContainers for application application_1559894241434_0001
2019-06-07 07:57:54,337 DEBUG org.apache.hadoop.yarn.server.resourcemanager.scheduler.capacity.LeafQueue: User limit computation for root in queue default userLimitPercent=100 userLimitFactor=1.0 required: <memory:1024, vCores:1> consumed: <memory:1024, vCores:1> user-limit-resource: <memory:8192, vCores:1> queueCapacity: <memory:8192, vCores:1> qconsumed: <memory:1024, vCores:1> consumedRatio: 0.0 currentCapacity: <memory:8192, vCores:1> activeUsers: 1.0 clusterCapacity: <memory:8192, vCores:2> resourceByLabel: <memory:8192, vCores:2> usageratio: 0.125 Partition:  maxUserLimit=<memory:8192, vCores:1> userWeight=1.0
2019-06-07 07:57:54,337 DEBUG org.apache.hadoop.yarn.server.resourcemanager.scheduler.capacity.LeafQueue: User limit computation for root in queue default userLimitPercent=100 userLimitFactor=1.0 required: <memory:1024, vCores:1> consumed: <memory:1024, vCores:1> user-limit-resource: <memory:8192, vCores:1> queueCapacity: <memory:8192, vCores:1> qconsumed: <memory:1024, vCores:1> consumedRatio: 0.0 currentCapacity: <memory:8192, vCores:1> activeUsers: 1.0 clusterCapacity: <memory:8192, vCores:2> resourceByLabel: <memory:8192, vCores:2> usageratio: 0.125 Partition:  maxUserLimit=<memory:8192, vCores:1> userWeight=1.0
2019-06-07 07:57:54,337 DEBUG org.apache.hadoop.yarn.server.resourcemanager.scheduler.SchedulerApplicationAttempt: showRequests: application=application_1559894241434_0001 headRoom=<memory:7168, vCores:1> currentConsumption=1024
2019-06-07 07:57:54,337 DEBUG org.apache.hadoop.yarn.server.resourcemanager.scheduler.SchedulerApplicationAttempt: showRequests: application=application_1559894241434_0001 headRoom=<memory:7168, vCores:1> currentConsumption=1024
2019-06-07 07:57:54,338 DEBUG org.apache.hadoop.yarn.server.resourcemanager.scheduler.SchedulerApplicationAttempt: showRequests: application=application_1559894241434_0001 request={Priority: 1, Capability: <memory:3072, vCores:1>, # Containers: 2, Location: *, Relax Locality: true, Node Label Expression: }
2019-06-07 07:57:54,338 DEBUG org.apache.hadoop.yarn.server.resourcemanager.scheduler.SchedulerApplicationAttempt: showRequests: application=application_1559894241434_0001 request={Priority: 1, Capability: <memory:3072, vCores:1>, # Containers: 2, Location: *, Relax Locality: true, Node Label Expression: }
2019-06-07 07:57:54,339 DEBUG org.apache.hadoop.yarn.server.resourcemanager.scheduler.capacity.allocator.IncreaseContainerAllocator: Skip allocating increase request since we don't have any increase request on this node=slave1:34830
2019-06-07 07:57:54,339 DEBUG org.apache.hadoop.yarn.server.resourcemanager.scheduler.capacity.allocator.IncreaseContainerAllocator: Skip allocating increase request since we don't have any increase request on this node=slave1:34830
2019-06-07 07:57:54,339 DEBUG org.apache.hadoop.yarn.server.resourcemanager.scheduler.capacity.allocator.RegularContainerAllocator: assignContainers: node=slave1 application=application_1559894241434_0001 priority=1 request={Priority: 1, Capability: <memory:3072, vCores:1>, # Containers: 2, Location: *, Relax Locality: true, Node Label Expression: } type=OFF_SWITCH
2019-06-07 07:57:54,339 DEBUG org.apache.hadoop.yarn.server.resourcemanager.scheduler.capacity.allocator.RegularContainerAllocator: assignContainers: node=slave1 application=application_1559894241434_0001 priority=1 request={Priority: 1, Capability: <memory:3072, vCores:1>, # Containers: 2, Location: *, Relax Locality: true, Node Label Expression: } type=OFF_SWITCH
2019-06-07 07:57:54,339 DEBUG org.apache.hadoop.yarn.server.resourcemanager.scheduler.AppSchedulingInfo: allocate: applicationId=application_1559894241434_0001 container=container_1559894241434_0001_01_000002 host=slave1:34830 user=root resource=<memory:3072, vCores:1> type=OFF_SWITCH
2019-06-07 07:57:54,339 DEBUG org.apache.hadoop.yarn.server.resourcemanager.scheduler.AppSchedulingInfo: allocate: applicationId=application_1559894241434_0001 container=container_1559894241434_0001_01_000002 host=slave1:34830 user=root resource=<memory:3072, vCores:1> type=OFF_SWITCH
2019-06-07 07:57:54,339 DEBUG org.apache.hadoop.yarn.server.resourcemanager.rmcontainer.RMContainerImpl: Processing container_1559894241434_0001_01_000002 of type START
2019-06-07 07:57:54,339 DEBUG org.apache.hadoop.yarn.server.resourcemanager.rmcontainer.RMContainerImpl: Processing container_1559894241434_0001_01_000002 of type START
2019-06-07 07:57:54,339 INFO org.apache.hadoop.yarn.server.resourcemanager.rmcontainer.RMContainerImpl: container_1559894241434_0001_01_000002 Container Transitioned from NEW to ALLOCATED
2019-06-07 07:57:54,339 INFO org.apache.hadoop.yarn.server.resourcemanager.rmcontainer.RMContainerImpl: container_1559894241434_0001_01_000002 Container Transitioned from NEW to ALLOCATED
2019-06-07 07:57:54,339 DEBUG org.apache.hadoop.yarn.server.resourcemanager.scheduler.common.fica.FiCaSchedulerApp: allocate: applicationAttemptId=appattempt_1559894241434_0001_000001 container=container_1559894241434_0001_01_000002 host=slave1 type=OFF_SWITCH
2019-06-07 07:57:54,339 DEBUG org.apache.hadoop.yarn.server.resourcemanager.scheduler.common.fica.FiCaSchedulerApp: allocate: applicationAttemptId=appattempt_1559894241434_0001_000001 container=container_1559894241434_0001_01_000002 host=slave1 type=OFF_SWITCH
2019-06-07 07:57:54,339 INFO org.apache.hadoop.yarn.server.resourcemanager.RMAuditLogger: USER=root	OPERATION=AM Allocated Container	TARGET=SchedulerApp	RESULT=SUCCESS	APPID=application_1559894241434_0001	CONTAINERID=container_1559894241434_0001_01_000002
2019-06-07 07:57:54,339 INFO org.apache.hadoop.yarn.server.resourcemanager.RMAuditLogger: USER=root	OPERATION=AM Allocated Container	TARGET=SchedulerApp	RESULT=SUCCESS	APPID=application_1559894241434_0001	CONTAINERID=container_1559894241434_0001_01_000002
2019-06-07 07:57:54,339 INFO org.apache.hadoop.yarn.server.resourcemanager.scheduler.SchedulerNode: Assigned container container_1559894241434_0001_01_000002 of capacity <memory:3072, vCores:1> on host slave1:34830, which has 1 containers, <memory:3072, vCores:1> used and <memory:1024, vCores:0> available after allocation
2019-06-07 07:57:54,339 INFO org.apache.hadoop.yarn.server.resourcemanager.scheduler.SchedulerNode: Assigned container container_1559894241434_0001_01_000002 of capacity <memory:3072, vCores:1> on host slave1:34830, which has 1 containers, <memory:3072, vCores:1> used and <memory:1024, vCores:0> available after allocation
2019-06-07 07:57:54,339 INFO org.apache.hadoop.yarn.server.resourcemanager.scheduler.capacity.allocator.AbstractContainerAllocator: assignedContainer application attempt=appattempt_1559894241434_0001_000001 container=container_1559894241434_0001_01_000002 queue=org.apache.hadoop.yarn.server.resourcemanager.scheduler.capacity.allocator.RegularContainerAllocator@3dce5bef clusterResource=<memory:8192, vCores:2> type=OFF_SWITCH requestedPartition=
2019-06-07 07:57:54,339 INFO org.apache.hadoop.yarn.server.resourcemanager.scheduler.capacity.allocator.AbstractContainerAllocator: assignedContainer application attempt=appattempt_1559894241434_0001_000001 container=container_1559894241434_0001_01_000002 queue=org.apache.hadoop.yarn.server.resourcemanager.scheduler.capacity.allocator.RegularContainerAllocator@3dce5bef clusterResource=<memory:8192, vCores:2> type=OFF_SWITCH requestedPartition=
2019-06-07 07:57:54,339 DEBUG org.apache.hadoop.yarn.server.resourcemanager.scheduler.capacity.LeafQueue: post-assignContainers for application application_1559894241434_0001
2019-06-07 07:57:54,339 DEBUG org.apache.hadoop.yarn.server.resourcemanager.scheduler.capacity.LeafQueue: post-assignContainers for application application_1559894241434_0001
2019-06-07 07:57:54,339 DEBUG org.apache.hadoop.yarn.server.resourcemanager.scheduler.capacity.LeafQueue: User limit computation for root in queue default userLimitPercent=100 userLimitFactor=1.0 required: <memory:1024, vCores:1> consumed: <memory:1024, vCores:1> user-limit-resource: <memory:8192, vCores:1> queueCapacity: <memory:8192, vCores:1> qconsumed: <memory:1024, vCores:1> consumedRatio: 0.0 currentCapacity: <memory:8192, vCores:1> activeUsers: 1.0 clusterCapacity: <memory:8192, vCores:2> resourceByLabel: <memory:8192, vCores:2> usageratio: 0.125 Partition:  maxUserLimit=<memory:8192, vCores:1> userWeight=1.0
2019-06-07 07:57:54,339 DEBUG org.apache.hadoop.yarn.server.resourcemanager.scheduler.capacity.LeafQueue: User limit computation for root in queue default userLimitPercent=100 userLimitFactor=1.0 required: <memory:1024, vCores:1> consumed: <memory:1024, vCores:1> user-limit-resource: <memory:8192, vCores:1> queueCapacity: <memory:8192, vCores:1> qconsumed: <memory:1024, vCores:1> consumedRatio: 0.0 currentCapacity: <memory:8192, vCores:1> activeUsers: 1.0 clusterCapacity: <memory:8192, vCores:2> resourceByLabel: <memory:8192, vCores:2> usageratio: 0.125 Partition:  maxUserLimit=<memory:8192, vCores:1> userWeight=1.0
2019-06-07 07:57:54,339 DEBUG org.apache.hadoop.yarn.server.resourcemanager.scheduler.SchedulerApplicationAttempt: showRequests: application=application_1559894241434_0001 headRoom=<memory:7168, vCores:1> currentConsumption=4096
2019-06-07 07:57:54,339 DEBUG org.apache.hadoop.yarn.server.resourcemanager.scheduler.SchedulerApplicationAttempt: showRequests: application=application_1559894241434_0001 headRoom=<memory:7168, vCores:1> currentConsumption=4096
2019-06-07 07:57:54,339 DEBUG org.apache.hadoop.yarn.server.resourcemanager.scheduler.SchedulerApplicationAttempt: showRequests: application=application_1559894241434_0001 request={Priority: 1, Capability: <memory:3072, vCores:1>, # Containers: 1, Location: *, Relax Locality: true, Node Label Expression: }
2019-06-07 07:57:54,339 DEBUG org.apache.hadoop.yarn.server.resourcemanager.scheduler.SchedulerApplicationAttempt: showRequests: application=application_1559894241434_0001 request={Priority: 1, Capability: <memory:3072, vCores:1>, # Containers: 1, Location: *, Relax Locality: true, Node Label Expression: }
2019-06-07 07:57:54,340 DEBUG org.apache.hadoop.yarn.server.resourcemanager.scheduler.capacity.LeafQueue: User limit computation for root in queue default userLimitPercent=100 userLimitFactor=1.0 required: <memory:1024, vCores:1> consumed: <memory:4096, vCores:1> user-limit-resource: <memory:8192, vCores:1> queueCapacity: <memory:8192, vCores:1> qconsumed: <memory:4096, vCores:2> consumedRatio: 0.0 currentCapacity: <memory:8192, vCores:1> activeUsers: 1.0 clusterCapacity: <memory:8192, vCores:2> resourceByLabel: <memory:8192, vCores:2> usageratio: 0.5 Partition:  maxUserLimit=<memory:8192, vCores:1> userWeight=1.0
2019-06-07 07:57:54,340 DEBUG org.apache.hadoop.yarn.server.resourcemanager.scheduler.capacity.LeafQueue: User limit computation for root in queue default userLimitPercent=100 userLimitFactor=1.0 required: <memory:1024, vCores:1> consumed: <memory:4096, vCores:1> user-limit-resource: <memory:8192, vCores:1> queueCapacity: <memory:8192, vCores:1> qconsumed: <memory:4096, vCores:2> consumedRatio: 0.0 currentCapacity: <memory:8192, vCores:1> activeUsers: 1.0 clusterCapacity: <memory:8192, vCores:2> resourceByLabel: <memory:8192, vCores:2> usageratio: 0.5 Partition:  maxUserLimit=<memory:8192, vCores:1> userWeight=1.0
2019-06-07 07:57:54,340 DEBUG org.apache.hadoop.yarn.server.resourcemanager.scheduler.capacity.LeafQueue: User limit computation for root in queue default userLimitPercent=100 userLimitFactor=1.0 required: <memory:1024, vCores:1> consumed: <memory:4096, vCores:1> user-limit-resource: <memory:8192, vCores:1> queueCapacity: <memory:8192, vCores:1> qconsumed: <memory:4096, vCores:2> consumedRatio: 0.0 currentCapacity: <memory:8192, vCores:1> activeUsers: 1.0 clusterCapacity: <memory:8192, vCores:2> resourceByLabel: <memory:8192, vCores:2> usageratio: 0.5 Partition:  maxUserLimit=<memory:8192, vCores:1> userWeight=1.0
2019-06-07 07:57:54,340 DEBUG org.apache.hadoop.yarn.server.resourcemanager.scheduler.capacity.LeafQueue: User limit computation for root in queue default userLimitPercent=100 userLimitFactor=1.0 required: <memory:1024, vCores:1> consumed: <memory:4096, vCores:1> user-limit-resource: <memory:8192, vCores:1> queueCapacity: <memory:8192, vCores:1> qconsumed: <memory:4096, vCores:2> consumedRatio: 0.0 currentCapacity: <memory:8192, vCores:1> activeUsers: 1.0 clusterCapacity: <memory:8192, vCores:2> resourceByLabel: <memory:8192, vCores:2> usageratio: 0.5 Partition:  maxUserLimit=<memory:8192, vCores:1> userWeight=1.0
2019-06-07 07:57:54,340 DEBUG org.apache.hadoop.yarn.server.resourcemanager.scheduler.capacity.LeafQueue: User limit computation for root in queue default userLimitPercent=100 userLimitFactor=1.0 required: <memory:1024, vCores:1> consumed: <memory:4096, vCores:1> user-limit-resource: <memory:8192, vCores:1> queueCapacity: <memory:8192, vCores:1> qconsumed: <memory:4096, vCores:2> consumedRatio: 0.0 currentCapacity: <memory:8192, vCores:1> activeUsers: 1.0 clusterCapacity: <memory:8192, vCores:2> resourceByLabel: <memory:8192, vCores:2> usageratio: 0.5 Partition:  maxUserLimit=<memory:8192, vCores:1> userWeight=1.0
2019-06-07 07:57:54,340 DEBUG org.apache.hadoop.yarn.server.resourcemanager.scheduler.capacity.LeafQueue: User limit computation for root in queue default userLimitPercent=100 userLimitFactor=1.0 required: <memory:1024, vCores:1> consumed: <memory:4096, vCores:1> user-limit-resource: <memory:8192, vCores:1> queueCapacity: <memory:8192, vCores:1> qconsumed: <memory:4096, vCores:2> consumedRatio: 0.0 currentCapacity: <memory:8192, vCores:1> activeUsers: 1.0 clusterCapacity: <memory:8192, vCores:2> resourceByLabel: <memory:8192, vCores:2> usageratio: 0.5 Partition:  maxUserLimit=<memory:8192, vCores:1> userWeight=1.0
2019-06-07 07:57:54,340 DEBUG org.apache.hadoop.yarn.server.resourcemanager.scheduler.capacity.LeafQueue: default user=root used=<memory:4096, vCores:2> numContainers=2 headroom = <memory:4096, vCores:1> user-resources=<memory:4096, vCores:2>
2019-06-07 07:57:54,340 DEBUG org.apache.hadoop.yarn.server.resourcemanager.scheduler.capacity.LeafQueue: default user=root used=<memory:4096, vCores:2> numContainers=2 headroom = <memory:4096, vCores:1> user-resources=<memory:4096, vCores:2>
2019-06-07 07:57:54,340 DEBUG org.apache.hadoop.yarn.server.resourcemanager.scheduler.capacity.ParentQueue: Assigned to queue: root.default stats: default: capacity=1.0, absoluteCapacity=1.0, usedResources=<memory:4096, vCores:2>, usedCapacity=0.5, absoluteUsedCapacity=0.5, numApps=1, numContainers=2 --> <memory:3072, vCores:1>, OFF_SWITCH
2019-06-07 07:57:54,340 DEBUG org.apache.hadoop.yarn.server.resourcemanager.scheduler.capacity.ParentQueue: Assigned to queue: root.default stats: default: capacity=1.0, absoluteCapacity=1.0, usedResources=<memory:4096, vCores:2>, usedCapacity=0.5, absoluteUsedCapacity=0.5, numApps=1, numContainers=2 --> <memory:3072, vCores:1>, OFF_SWITCH
2019-06-07 07:57:54,340 INFO org.apache.hadoop.yarn.server.resourcemanager.scheduler.capacity.ParentQueue: Re-sorting assigned queue: root.default stats: default: capacity=1.0, absoluteCapacity=1.0, usedResources=<memory:4096, vCores:2>, usedCapacity=0.5, absoluteUsedCapacity=0.5, numApps=1, numContainers=2
2019-06-07 07:57:54,340 INFO org.apache.hadoop.yarn.server.resourcemanager.scheduler.capacity.ParentQueue: Re-sorting assigned queue: root.default stats: default: capacity=1.0, absoluteCapacity=1.0, usedResources=<memory:4096, vCores:2>, usedCapacity=0.5, absoluteUsedCapacity=0.5, numApps=1, numContainers=2
2019-06-07 07:57:54,340 DEBUG org.apache.hadoop.yarn.server.resourcemanager.scheduler.capacity.ParentQueue: printChildQueues - queue: root child-queues: root.defaultusedCapacity=(0.5),  label=(*)
2019-06-07 07:57:54,340 DEBUG org.apache.hadoop.yarn.server.resourcemanager.scheduler.capacity.ParentQueue: printChildQueues - queue: root child-queues: root.defaultusedCapacity=(0.5),  label=(*)
2019-06-07 07:57:54,340 INFO org.apache.hadoop.yarn.server.resourcemanager.scheduler.capacity.ParentQueue: assignedContainer queue=root usedCapacity=0.5 absoluteUsedCapacity=0.5 used=<memory:4096, vCores:2> cluster=<memory:8192, vCores:2>
2019-06-07 07:57:54,340 INFO org.apache.hadoop.yarn.server.resourcemanager.scheduler.capacity.ParentQueue: assignedContainer queue=root usedCapacity=0.5 absoluteUsedCapacity=0.5 used=<memory:4096, vCores:2> cluster=<memory:8192, vCores:2>
2019-06-07 07:57:54,340 DEBUG org.apache.hadoop.yarn.server.resourcemanager.scheduler.capacity.ParentQueue: ParentQ=root assignedSoFarInThisIteration=<memory:3072, vCores:1> usedCapacity=0.5 absoluteUsedCapacity=0.5
2019-06-07 07:57:54,340 DEBUG org.apache.hadoop.yarn.server.resourcemanager.scheduler.capacity.ParentQueue: ParentQ=root assignedSoFarInThisIteration=<memory:3072, vCores:1> usedCapacity=0.5 absoluteUsedCapacity=0.5
2019-06-07 07:57:54,340 DEBUG org.apache.hadoop.yarn.server.resourcemanager.scheduler.capacity.ParentQueue: Assigned maximum number of off-switch containers: 1, assignments so far: resource:<memory:3072, vCores:1>; type:OFF_SWITCH; excessReservation:null; applicationid:null; skipped:NONE; fulfilled reservation:false; allocations(count/resource):1/<memory:3072, vCores:1>; reservations(count/resource):0/<memory:0, vCores:0>
2019-06-07 07:57:54,340 DEBUG org.apache.hadoop.yarn.server.resourcemanager.scheduler.capacity.ParentQueue: Assigned maximum number of off-switch containers: 1, assignments so far: resource:<memory:3072, vCores:1>; type:OFF_SWITCH; excessReservation:null; applicationid:null; skipped:NONE; fulfilled reservation:false; allocations(count/resource):1/<memory:3072, vCores:1>; reservations(count/resource):0/<memory:0, vCores:0>
2019-06-07 07:57:54,340 DEBUG org.apache.hadoop.yarn.server.resourcemanager.rmapp.attempt.RMAppAttemptImpl: Processing event for appattempt_1559894241434_0001_000001 of type CONTAINER_ALLOCATED
2019-06-07 07:57:54,340 DEBUG org.apache.hadoop.yarn.server.resourcemanager.rmapp.attempt.RMAppAttemptImpl: Processing event for appattempt_1559894241434_0001_000001 of type CONTAINER_ALLOCATED
2019-06-07 07:57:54,350 DEBUG org.apache.hadoop.yarn.server.resourcemanager.rmnode.RMNodeImpl: Processing slave2:42768 of type STATUS_UPDATE
2019-06-07 07:57:54,350 DEBUG org.apache.hadoop.yarn.server.resourcemanager.rmnode.RMNodeImpl: Processing slave2:42768 of type STATUS_UPDATE
2019-06-07 07:57:54,350 DEBUG org.apache.hadoop.yarn.server.resourcemanager.scheduler.capacity.CapacityScheduler: nodeUpdate: slave2:42768 clusterResources: <memory:8192, vCores:2>
2019-06-07 07:57:54,350 DEBUG org.apache.hadoop.yarn.server.resourcemanager.scheduler.capacity.CapacityScheduler: nodeUpdate: slave2:42768 clusterResources: <memory:8192, vCores:2>
2019-06-07 07:57:54,350 DEBUG org.apache.hadoop.yarn.server.resourcemanager.scheduler.capacity.CapacityScheduler: Node being looked for scheduling slave2:42768 availableResource: <memory:3072, vCores:0>
2019-06-07 07:57:54,350 DEBUG org.apache.hadoop.yarn.server.resourcemanager.scheduler.capacity.CapacityScheduler: Node being looked for scheduling slave2:42768 availableResource: <memory:3072, vCores:0>
2019-06-07 07:57:54,350 DEBUG org.apache.hadoop.yarn.server.resourcemanager.scheduler.capacity.CapacityScheduler: Trying to schedule on node: slave2, available: <memory:3072, vCores:0>
2019-06-07 07:57:54,350 DEBUG org.apache.hadoop.yarn.server.resourcemanager.scheduler.capacity.CapacityScheduler: Trying to schedule on node: slave2, available: <memory:3072, vCores:0>
2019-06-07 07:57:54,350 DEBUG org.apache.hadoop.yarn.server.resourcemanager.scheduler.capacity.ParentQueue: Trying to assign containers to child-queue of root
2019-06-07 07:57:54,350 DEBUG org.apache.hadoop.yarn.server.resourcemanager.scheduler.capacity.ParentQueue: Trying to assign containers to child-queue of root
2019-06-07 07:57:54,350 DEBUG org.apache.hadoop.yarn.server.resourcemanager.scheduler.capacity.ParentQueue: printChildQueues - queue: root child-queues: root.defaultusedCapacity=(0.5),  label=(*)
2019-06-07 07:57:54,350 DEBUG org.apache.hadoop.yarn.server.resourcemanager.scheduler.capacity.ParentQueue: printChildQueues - queue: root child-queues: root.defaultusedCapacity=(0.5),  label=(*)
2019-06-07 07:57:54,350 DEBUG org.apache.hadoop.yarn.server.resourcemanager.scheduler.capacity.ParentQueue: Trying to assign to queue: root.default stats: default: capacity=1.0, absoluteCapacity=1.0, usedResources=<memory:4096, vCores:2>, usedCapacity=0.5, absoluteUsedCapacity=0.5, numApps=1, numContainers=2
2019-06-07 07:57:54,350 DEBUG org.apache.hadoop.yarn.server.resourcemanager.scheduler.capacity.ParentQueue: Trying to assign to queue: root.default stats: default: capacity=1.0, absoluteCapacity=1.0, usedResources=<memory:4096, vCores:2>, usedCapacity=0.5, absoluteUsedCapacity=0.5, numApps=1, numContainers=2
2019-06-07 07:57:54,350 DEBUG org.apache.hadoop.yarn.server.resourcemanager.scheduler.capacity.LeafQueue: assignContainers: node=slave2 #applications=1
2019-06-07 07:57:54,350 DEBUG org.apache.hadoop.yarn.server.resourcemanager.scheduler.capacity.LeafQueue: assignContainers: node=slave2 #applications=1
2019-06-07 07:57:54,350 DEBUG org.apache.hadoop.yarn.server.resourcemanager.scheduler.capacity.LeafQueue: User limit computation for root in queue default userLimitPercent=100 userLimitFactor=1.0 required: <memory:1024, vCores:1> consumed: <memory:4096, vCores:1> user-limit-resource: <memory:8192, vCores:1> queueCapacity: <memory:8192, vCores:1> qconsumed: <memory:4096, vCores:2> consumedRatio: 0.0 currentCapacity: <memory:8192, vCores:1> activeUsers: 1.0 clusterCapacity: <memory:8192, vCores:2> resourceByLabel: <memory:8192, vCores:2> usageratio: 0.5 Partition:  maxUserLimit=<memory:8192, vCores:1> userWeight=1.0
2019-06-07 07:57:54,350 DEBUG org.apache.hadoop.yarn.server.resourcemanager.scheduler.capacity.LeafQueue: User limit computation for root in queue default userLimitPercent=100 userLimitFactor=1.0 required: <memory:1024, vCores:1> consumed: <memory:4096, vCores:1> user-limit-resource: <memory:8192, vCores:1> queueCapacity: <memory:8192, vCores:1> qconsumed: <memory:4096, vCores:2> consumedRatio: 0.0 currentCapacity: <memory:8192, vCores:1> activeUsers: 1.0 clusterCapacity: <memory:8192, vCores:2> resourceByLabel: <memory:8192, vCores:2> usageratio: 0.5 Partition:  maxUserLimit=<memory:8192, vCores:1> userWeight=1.0
2019-06-07 07:57:54,350 DEBUG org.apache.hadoop.yarn.server.resourcemanager.scheduler.capacity.LeafQueue: Headroom calculation for user root:  userLimit=<memory:8192, vCores:1> queueMaxAvailRes=<memory:8192, vCores:1> consumed=<memory:4096, vCores:2>
2019-06-07 07:57:54,350 DEBUG org.apache.hadoop.yarn.server.resourcemanager.scheduler.capacity.LeafQueue: Headroom calculation for user root:  userLimit=<memory:8192, vCores:1> queueMaxAvailRes=<memory:8192, vCores:1> consumed=<memory:4096, vCores:2>
2019-06-07 07:57:54,350 DEBUG org.apache.hadoop.yarn.server.resourcemanager.scheduler.common.fica.FiCaSchedulerApp: pre-assignContainers for application application_1559894241434_0001
2019-06-07 07:57:54,350 DEBUG org.apache.hadoop.yarn.server.resourcemanager.scheduler.common.fica.FiCaSchedulerApp: pre-assignContainers for application application_1559894241434_0001
2019-06-07 07:57:54,351 DEBUG org.apache.hadoop.yarn.server.resourcemanager.scheduler.capacity.LeafQueue: User limit computation for root in queue default userLimitPercent=100 userLimitFactor=1.0 required: <memory:1024, vCores:1> consumed: <memory:4096, vCores:1> user-limit-resource: <memory:8192, vCores:1> queueCapacity: <memory:8192, vCores:1> qconsumed: <memory:4096, vCores:2> consumedRatio: 0.0 currentCapacity: <memory:8192, vCores:1> activeUsers: 1.0 clusterCapacity: <memory:8192, vCores:2> resourceByLabel: <memory:8192, vCores:2> usageratio: 0.5 Partition:  maxUserLimit=<memory:8192, vCores:1> userWeight=1.0
2019-06-07 07:57:54,351 DEBUG org.apache.hadoop.yarn.server.resourcemanager.scheduler.capacity.LeafQueue: User limit computation for root in queue default userLimitPercent=100 userLimitFactor=1.0 required: <memory:1024, vCores:1> consumed: <memory:4096, vCores:1> user-limit-resource: <memory:8192, vCores:1> queueCapacity: <memory:8192, vCores:1> qconsumed: <memory:4096, vCores:2> consumedRatio: 0.0 currentCapacity: <memory:8192, vCores:1> activeUsers: 1.0 clusterCapacity: <memory:8192, vCores:2> resourceByLabel: <memory:8192, vCores:2> usageratio: 0.5 Partition:  maxUserLimit=<memory:8192, vCores:1> userWeight=1.0
2019-06-07 07:57:54,351 DEBUG org.apache.hadoop.yarn.server.resourcemanager.scheduler.SchedulerApplicationAttempt: showRequests: application=application_1559894241434_0001 headRoom=<memory:4096, vCores:0> currentConsumption=4096
2019-06-07 07:57:54,351 DEBUG org.apache.hadoop.yarn.server.resourcemanager.scheduler.SchedulerApplicationAttempt: showRequests: application=application_1559894241434_0001 headRoom=<memory:4096, vCores:0> currentConsumption=4096
2019-06-07 07:57:54,351 DEBUG org.apache.hadoop.yarn.server.resourcemanager.scheduler.SchedulerApplicationAttempt: showRequests: application=application_1559894241434_0001 request={Priority: 1, Capability: <memory:3072, vCores:1>, # Containers: 1, Location: *, Relax Locality: true, Node Label Expression: }
2019-06-07 07:57:54,351 DEBUG org.apache.hadoop.yarn.server.resourcemanager.scheduler.SchedulerApplicationAttempt: showRequests: application=application_1559894241434_0001 request={Priority: 1, Capability: <memory:3072, vCores:1>, # Containers: 1, Location: *, Relax Locality: true, Node Label Expression: }
2019-06-07 07:57:54,351 DEBUG org.apache.hadoop.yarn.server.resourcemanager.scheduler.capacity.allocator.IncreaseContainerAllocator: Skip allocating increase request since we don't have any increase request on this node=slave2:42768
2019-06-07 07:57:54,351 DEBUG org.apache.hadoop.yarn.server.resourcemanager.scheduler.capacity.allocator.IncreaseContainerAllocator: Skip allocating increase request since we don't have any increase request on this node=slave2:42768
2019-06-07 07:57:54,351 DEBUG org.apache.hadoop.yarn.server.resourcemanager.scheduler.capacity.allocator.RegularContainerAllocator: assignContainers: node=slave2 application=application_1559894241434_0001 priority=1 request={Priority: 1, Capability: <memory:3072, vCores:1>, # Containers: 1, Location: *, Relax Locality: true, Node Label Expression: } type=OFF_SWITCH
2019-06-07 07:57:54,351 DEBUG org.apache.hadoop.yarn.server.resourcemanager.scheduler.capacity.allocator.RegularContainerAllocator: assignContainers: node=slave2 application=application_1559894241434_0001 priority=1 request={Priority: 1, Capability: <memory:3072, vCores:1>, # Containers: 1, Location: *, Relax Locality: true, Node Label Expression: } type=OFF_SWITCH
2019-06-07 07:57:54,351 DEBUG org.apache.hadoop.yarn.server.resourcemanager.scheduler.ActiveUsersManager: User root removed from activeUsers, currently: 0
2019-06-07 07:57:54,351 DEBUG org.apache.hadoop.yarn.server.resourcemanager.scheduler.ActiveUsersManager: User root removed from activeUsers, currently: 0
2019-06-07 07:57:54,351 DEBUG org.apache.hadoop.yarn.server.resourcemanager.scheduler.AppSchedulingInfo: allocate: applicationId=application_1559894241434_0001 container=container_1559894241434_0001_01_000003 host=slave2:42768 user=root resource=<memory:3072, vCores:1> type=OFF_SWITCH
2019-06-07 07:57:54,351 DEBUG org.apache.hadoop.yarn.server.resourcemanager.scheduler.AppSchedulingInfo: allocate: applicationId=application_1559894241434_0001 container=container_1559894241434_0001_01_000003 host=slave2:42768 user=root resource=<memory:3072, vCores:1> type=OFF_SWITCH
2019-06-07 07:57:54,351 DEBUG org.apache.hadoop.yarn.server.resourcemanager.rmcontainer.RMContainerImpl: Processing container_1559894241434_0001_01_000003 of type START
2019-06-07 07:57:54,351 DEBUG org.apache.hadoop.yarn.server.resourcemanager.rmcontainer.RMContainerImpl: Processing container_1559894241434_0001_01_000003 of type START
2019-06-07 07:57:54,351 INFO org.apache.hadoop.yarn.server.resourcemanager.rmcontainer.RMContainerImpl: container_1559894241434_0001_01_000003 Container Transitioned from NEW to ALLOCATED
2019-06-07 07:57:54,351 INFO org.apache.hadoop.yarn.server.resourcemanager.rmcontainer.RMContainerImpl: container_1559894241434_0001_01_000003 Container Transitioned from NEW to ALLOCATED
2019-06-07 07:57:54,351 DEBUG org.apache.hadoop.yarn.server.resourcemanager.scheduler.common.fica.FiCaSchedulerApp: allocate: applicationAttemptId=appattempt_1559894241434_0001_000001 container=container_1559894241434_0001_01_000003 host=slave2 type=OFF_SWITCH
2019-06-07 07:57:54,351 DEBUG org.apache.hadoop.yarn.server.resourcemanager.scheduler.common.fica.FiCaSchedulerApp: allocate: applicationAttemptId=appattempt_1559894241434_0001_000001 container=container_1559894241434_0001_01_000003 host=slave2 type=OFF_SWITCH
2019-06-07 07:57:54,351 INFO org.apache.hadoop.yarn.server.resourcemanager.RMAuditLogger: USER=root	OPERATION=AM Allocated Container	TARGET=SchedulerApp	RESULT=SUCCESS	APPID=application_1559894241434_0001	CONTAINERID=container_1559894241434_0001_01_000003
2019-06-07 07:57:54,351 INFO org.apache.hadoop.yarn.server.resourcemanager.RMAuditLogger: USER=root	OPERATION=AM Allocated Container	TARGET=SchedulerApp	RESULT=SUCCESS	APPID=application_1559894241434_0001	CONTAINERID=container_1559894241434_0001_01_000003
2019-06-07 07:57:54,351 INFO org.apache.hadoop.yarn.server.resourcemanager.scheduler.SchedulerNode: Assigned container container_1559894241434_0001_01_000003 of capacity <memory:3072, vCores:1> on host slave2:42768, which has 2 containers, <memory:4096, vCores:2> used and <memory:0, vCores:-1> available after allocation
2019-06-07 07:57:54,351 INFO org.apache.hadoop.yarn.server.resourcemanager.scheduler.SchedulerNode: Assigned container container_1559894241434_0001_01_000003 of capacity <memory:3072, vCores:1> on host slave2:42768, which has 2 containers, <memory:4096, vCores:2> used and <memory:0, vCores:-1> available after allocation
2019-06-07 07:57:54,351 INFO org.apache.hadoop.yarn.server.resourcemanager.scheduler.capacity.allocator.AbstractContainerAllocator: assignedContainer application attempt=appattempt_1559894241434_0001_000001 container=container_1559894241434_0001_01_000003 queue=org.apache.hadoop.yarn.server.resourcemanager.scheduler.capacity.allocator.RegularContainerAllocator@3dce5bef clusterResource=<memory:8192, vCores:2> type=OFF_SWITCH requestedPartition=
2019-06-07 07:57:54,351 INFO org.apache.hadoop.yarn.server.resourcemanager.scheduler.capacity.allocator.AbstractContainerAllocator: assignedContainer application attempt=appattempt_1559894241434_0001_000001 container=container_1559894241434_0001_01_000003 queue=org.apache.hadoop.yarn.server.resourcemanager.scheduler.capacity.allocator.RegularContainerAllocator@3dce5bef clusterResource=<memory:8192, vCores:2> type=OFF_SWITCH requestedPartition=
2019-06-07 07:57:54,351 DEBUG org.apache.hadoop.yarn.server.resourcemanager.scheduler.capacity.LeafQueue: post-assignContainers for application application_1559894241434_0001
2019-06-07 07:57:54,351 DEBUG org.apache.hadoop.yarn.server.resourcemanager.scheduler.capacity.LeafQueue: post-assignContainers for application application_1559894241434_0001
2019-06-07 07:57:54,351 DEBUG org.apache.hadoop.yarn.server.resourcemanager.scheduler.capacity.LeafQueue: User limit computation for root in queue default userLimitPercent=100 userLimitFactor=1.0 required: <memory:1024, vCores:1> consumed: <memory:7168, vCores:1> user-limit-resource: <memory:8192, vCores:1> queueCapacity: <memory:8192, vCores:1> qconsumed: <memory:7168, vCores:3> consumedRatio: 0.0 currentCapacity: <memory:8192, vCores:1> activeUsers: 0.0 clusterCapacity: <memory:8192, vCores:2> resourceByLabel: <memory:8192, vCores:2> usageratio: 0.875 Partition:  maxUserLimit=<memory:8192, vCores:1> userWeight=1.0
2019-06-07 07:57:54,351 DEBUG org.apache.hadoop.yarn.server.resourcemanager.scheduler.capacity.LeafQueue: User limit computation for root in queue default userLimitPercent=100 userLimitFactor=1.0 required: <memory:1024, vCores:1> consumed: <memory:7168, vCores:1> user-limit-resource: <memory:8192, vCores:1> queueCapacity: <memory:8192, vCores:1> qconsumed: <memory:7168, vCores:3> consumedRatio: 0.0 currentCapacity: <memory:8192, vCores:1> activeUsers: 0.0 clusterCapacity: <memory:8192, vCores:2> resourceByLabel: <memory:8192, vCores:2> usageratio: 0.875 Partition:  maxUserLimit=<memory:8192, vCores:1> userWeight=1.0
2019-06-07 07:57:54,351 DEBUG org.apache.hadoop.yarn.server.resourcemanager.scheduler.capacity.LeafQueue: User limit computation for root in queue default userLimitPercent=100 userLimitFactor=1.0 required: <memory:1024, vCores:1> consumed: <memory:7168, vCores:1> user-limit-resource: <memory:8192, vCores:1> queueCapacity: <memory:8192, vCores:1> qconsumed: <memory:7168, vCores:3> consumedRatio: 0.0 currentCapacity: <memory:8192, vCores:1> activeUsers: 0.0 clusterCapacity: <memory:8192, vCores:2> resourceByLabel: <memory:8192, vCores:2> usageratio: 0.875 Partition:  maxUserLimit=<memory:8192, vCores:1> userWeight=1.0
2019-06-07 07:57:54,351 DEBUG org.apache.hadoop.yarn.server.resourcemanager.scheduler.capacity.LeafQueue: User limit computation for root in queue default userLimitPercent=100 userLimitFactor=1.0 required: <memory:1024, vCores:1> consumed: <memory:7168, vCores:1> user-limit-resource: <memory:8192, vCores:1> queueCapacity: <memory:8192, vCores:1> qconsumed: <memory:7168, vCores:3> consumedRatio: 0.0 currentCapacity: <memory:8192, vCores:1> activeUsers: 0.0 clusterCapacity: <memory:8192, vCores:2> resourceByLabel: <memory:8192, vCores:2> usageratio: 0.875 Partition:  maxUserLimit=<memory:8192, vCores:1> userWeight=1.0
2019-06-07 07:57:54,351 DEBUG org.apache.hadoop.yarn.server.resourcemanager.scheduler.capacity.LeafQueue: User limit computation for root in queue default userLimitPercent=100 userLimitFactor=1.0 required: <memory:1024, vCores:1> consumed: <memory:7168, vCores:1> user-limit-resource: <memory:8192, vCores:1> queueCapacity: <memory:8192, vCores:1> qconsumed: <memory:7168, vCores:3> consumedRatio: 0.0 currentCapacity: <memory:8192, vCores:1> activeUsers: 0.0 clusterCapacity: <memory:8192, vCores:2> resourceByLabel: <memory:8192, vCores:2> usageratio: 0.875 Partition:  maxUserLimit=<memory:8192, vCores:1> userWeight=1.0
2019-06-07 07:57:54,351 DEBUG org.apache.hadoop.yarn.server.resourcemanager.scheduler.capacity.LeafQueue: User limit computation for root in queue default userLimitPercent=100 userLimitFactor=1.0 required: <memory:1024, vCores:1> consumed: <memory:7168, vCores:1> user-limit-resource: <memory:8192, vCores:1> queueCapacity: <memory:8192, vCores:1> qconsumed: <memory:7168, vCores:3> consumedRatio: 0.0 currentCapacity: <memory:8192, vCores:1> activeUsers: 0.0 clusterCapacity: <memory:8192, vCores:2> resourceByLabel: <memory:8192, vCores:2> usageratio: 0.875 Partition:  maxUserLimit=<memory:8192, vCores:1> userWeight=1.0
2019-06-07 07:57:54,351 DEBUG org.apache.hadoop.yarn.server.resourcemanager.scheduler.capacity.LeafQueue: default user=root used=<memory:7168, vCores:3> numContainers=3 headroom = <memory:1024, vCores:1> user-resources=<memory:7168, vCores:3>
2019-06-07 07:57:54,351 DEBUG org.apache.hadoop.yarn.server.resourcemanager.scheduler.capacity.LeafQueue: default user=root used=<memory:7168, vCores:3> numContainers=3 headroom = <memory:1024, vCores:1> user-resources=<memory:7168, vCores:3>
2019-06-07 07:57:54,351 DEBUG org.apache.hadoop.yarn.server.resourcemanager.rmapp.attempt.RMAppAttemptImpl: Processing event for appattempt_1559894241434_0001_000001 of type CONTAINER_ALLOCATED
2019-06-07 07:57:54,351 DEBUG org.apache.hadoop.yarn.server.resourcemanager.rmapp.attempt.RMAppAttemptImpl: Processing event for appattempt_1559894241434_0001_000001 of type CONTAINER_ALLOCATED
2019-06-07 07:57:54,351 DEBUG org.apache.hadoop.yarn.server.resourcemanager.scheduler.capacity.ParentQueue: Assigned to queue: root.default stats: default: capacity=1.0, absoluteCapacity=1.0, usedResources=<memory:7168, vCores:3>, usedCapacity=0.875, absoluteUsedCapacity=0.875, numApps=1, numContainers=3 --> <memory:3072, vCores:1>, OFF_SWITCH
2019-06-07 07:57:54,351 DEBUG org.apache.hadoop.yarn.server.resourcemanager.scheduler.capacity.ParentQueue: Assigned to queue: root.default stats: default: capacity=1.0, absoluteCapacity=1.0, usedResources=<memory:7168, vCores:3>, usedCapacity=0.875, absoluteUsedCapacity=0.875, numApps=1, numContainers=3 --> <memory:3072, vCores:1>, OFF_SWITCH
2019-06-07 07:57:54,352 INFO org.apache.hadoop.yarn.server.resourcemanager.scheduler.capacity.ParentQueue: Re-sorting assigned queue: root.default stats: default: capacity=1.0, absoluteCapacity=1.0, usedResources=<memory:7168, vCores:3>, usedCapacity=0.875, absoluteUsedCapacity=0.875, numApps=1, numContainers=3
2019-06-07 07:57:54,352 INFO org.apache.hadoop.yarn.server.resourcemanager.scheduler.capacity.ParentQueue: Re-sorting assigned queue: root.default stats: default: capacity=1.0, absoluteCapacity=1.0, usedResources=<memory:7168, vCores:3>, usedCapacity=0.875, absoluteUsedCapacity=0.875, numApps=1, numContainers=3
2019-06-07 07:57:54,353 DEBUG org.apache.hadoop.yarn.server.resourcemanager.scheduler.capacity.ParentQueue: printChildQueues - queue: root child-queues: root.defaultusedCapacity=(0.875),  label=(*)
2019-06-07 07:57:54,353 DEBUG org.apache.hadoop.yarn.server.resourcemanager.scheduler.capacity.ParentQueue: printChildQueues - queue: root child-queues: root.defaultusedCapacity=(0.875),  label=(*)
2019-06-07 07:57:54,353 INFO org.apache.hadoop.yarn.server.resourcemanager.scheduler.capacity.ParentQueue: assignedContainer queue=root usedCapacity=0.875 absoluteUsedCapacity=0.875 used=<memory:7168, vCores:3> cluster=<memory:8192, vCores:2>
2019-06-07 07:57:54,353 INFO org.apache.hadoop.yarn.server.resourcemanager.scheduler.capacity.ParentQueue: assignedContainer queue=root usedCapacity=0.875 absoluteUsedCapacity=0.875 used=<memory:7168, vCores:3> cluster=<memory:8192, vCores:2>
2019-06-07 07:57:54,353 DEBUG org.apache.hadoop.yarn.server.resourcemanager.scheduler.capacity.ParentQueue: ParentQ=root assignedSoFarInThisIteration=<memory:3072, vCores:1> usedCapacity=0.875 absoluteUsedCapacity=0.875
2019-06-07 07:57:54,353 DEBUG org.apache.hadoop.yarn.server.resourcemanager.scheduler.capacity.ParentQueue: ParentQ=root assignedSoFarInThisIteration=<memory:3072, vCores:1> usedCapacity=0.875 absoluteUsedCapacity=0.875
2019-06-07 07:57:54,353 DEBUG org.apache.hadoop.yarn.server.resourcemanager.scheduler.capacity.ParentQueue: Assigned maximum number of off-switch containers: 1, assignments so far: resource:<memory:3072, vCores:1>; type:OFF_SWITCH; excessReservation:null; applicationid:null; skipped:NONE; fulfilled reservation:false; allocations(count/resource):1/<memory:3072, vCores:1>; reservations(count/resource):0/<memory:0, vCores:0>
2019-06-07 07:57:54,353 DEBUG org.apache.hadoop.yarn.server.resourcemanager.scheduler.capacity.ParentQueue: Assigned maximum number of off-switch containers: 1, assignments so far: resource:<memory:3072, vCores:1>; type:OFF_SWITCH; excessReservation:null; applicationid:null; skipped:NONE; fulfilled reservation:false; allocations(count/resource):1/<memory:3072, vCores:1>; reservations(count/resource):0/<memory:0, vCores:0>
2019-06-07 07:57:55,108 INFO org.apache.hadoop.yarn.server.resourcemanager.security.NMTokenSecretManagerInRM: Sending NMToken for nodeId : slave1:34830 for container : container_1559894241434_0001_01_000002
2019-06-07 07:57:55,108 INFO org.apache.hadoop.yarn.server.resourcemanager.security.NMTokenSecretManagerInRM: Sending NMToken for nodeId : slave1:34830 for container : container_1559894241434_0001_01_000002
2019-06-07 07:57:55,109 DEBUG org.apache.hadoop.yarn.server.resourcemanager.rmapp.attempt.RMAppAttemptImpl: Processing event for appattempt_1559894241434_0001_000001 of type STATUS_UPDATE
2019-06-07 07:57:55,109 DEBUG org.apache.hadoop.yarn.server.resourcemanager.rmapp.attempt.RMAppAttemptImpl: Processing event for appattempt_1559894241434_0001_000001 of type STATUS_UPDATE
2019-06-07 07:57:55,110 DEBUG org.apache.hadoop.yarn.server.resourcemanager.rmcontainer.RMContainerImpl: Processing container_1559894241434_0001_01_000002 of type ACQUIRED
2019-06-07 07:57:55,110 DEBUG org.apache.hadoop.yarn.server.resourcemanager.rmcontainer.RMContainerImpl: Processing container_1559894241434_0001_01_000002 of type ACQUIRED
2019-06-07 07:57:55,111 DEBUG org.apache.hadoop.yarn.server.resourcemanager.rmapp.RMAppImpl: Processing event for application_1559894241434_0001 of type APP_RUNNING_ON_NODE
2019-06-07 07:57:55,111 DEBUG org.apache.hadoop.yarn.server.resourcemanager.rmapp.RMAppImpl: Processing event for application_1559894241434_0001 of type APP_RUNNING_ON_NODE
2019-06-07 07:57:55,111 INFO org.apache.hadoop.yarn.server.resourcemanager.rmcontainer.RMContainerImpl: container_1559894241434_0001_01_000002 Container Transitioned from ALLOCATED to ACQUIRED
2019-06-07 07:57:55,111 INFO org.apache.hadoop.yarn.server.resourcemanager.rmcontainer.RMContainerImpl: container_1559894241434_0001_01_000002 Container Transitioned from ALLOCATED to ACQUIRED
2019-06-07 07:57:55,113 INFO org.apache.hadoop.yarn.server.resourcemanager.security.NMTokenSecretManagerInRM: Sending NMToken for nodeId : slave2:42768 for container : container_1559894241434_0001_01_000003
2019-06-07 07:57:55,113 INFO org.apache.hadoop.yarn.server.resourcemanager.security.NMTokenSecretManagerInRM: Sending NMToken for nodeId : slave2:42768 for container : container_1559894241434_0001_01_000003
2019-06-07 07:57:55,113 DEBUG org.apache.hadoop.yarn.server.resourcemanager.rmcontainer.RMContainerImpl: Processing container_1559894241434_0001_01_000003 of type ACQUIRED
2019-06-07 07:57:55,113 DEBUG org.apache.hadoop.yarn.server.resourcemanager.rmcontainer.RMContainerImpl: Processing container_1559894241434_0001_01_000003 of type ACQUIRED
2019-06-07 07:57:55,114 DEBUG org.apache.hadoop.yarn.server.resourcemanager.rmapp.RMAppImpl: Processing event for application_1559894241434_0001 of type APP_RUNNING_ON_NODE
2019-06-07 07:57:55,114 DEBUG org.apache.hadoop.yarn.server.resourcemanager.rmapp.RMAppImpl: Processing event for application_1559894241434_0001 of type APP_RUNNING_ON_NODE
2019-06-07 07:57:55,114 INFO org.apache.hadoop.yarn.server.resourcemanager.rmcontainer.RMContainerImpl: container_1559894241434_0001_01_000003 Container Transitioned from ALLOCATED to ACQUIRED
2019-06-07 07:57:55,114 INFO org.apache.hadoop.yarn.server.resourcemanager.rmcontainer.RMContainerImpl: container_1559894241434_0001_01_000003 Container Transitioned from ALLOCATED to ACQUIRED
2019-06-07 07:57:55,114 DEBUG org.apache.hadoop.yarn.server.resourcemanager.scheduler.capacity.LeafQueue: User limit computation for root in queue default userLimitPercent=100 userLimitFactor=1.0 required: <memory:1024, vCores:1> consumed: <memory:7168, vCores:1> user-limit-resource: <memory:8192, vCores:1> queueCapacity: <memory:8192, vCores:1> qconsumed: <memory:7168, vCores:3> consumedRatio: 0.0 currentCapacity: <memory:8192, vCores:1> activeUsers: 0.0 clusterCapacity: <memory:8192, vCores:2> resourceByLabel: <memory:8192, vCores:2> usageratio: 0.875 Partition:  maxUserLimit=<memory:8192, vCores:1> userWeight=1.0
2019-06-07 07:57:55,114 DEBUG org.apache.hadoop.yarn.server.resourcemanager.scheduler.capacity.LeafQueue: User limit computation for root in queue default userLimitPercent=100 userLimitFactor=1.0 required: <memory:1024, vCores:1> consumed: <memory:7168, vCores:1> user-limit-resource: <memory:8192, vCores:1> queueCapacity: <memory:8192, vCores:1> qconsumed: <memory:7168, vCores:3> consumedRatio: 0.0 currentCapacity: <memory:8192, vCores:1> activeUsers: 0.0 clusterCapacity: <memory:8192, vCores:2> resourceByLabel: <memory:8192, vCores:2> usageratio: 0.875 Partition:  maxUserLimit=<memory:8192, vCores:1> userWeight=1.0
2019-06-07 07:57:55,337 DEBUG org.apache.hadoop.yarn.server.resourcemanager.rmnode.RMNodeImpl: Processing slave1:34830 of type STATUS_UPDATE
2019-06-07 07:57:55,337 DEBUG org.apache.hadoop.yarn.server.resourcemanager.rmnode.RMNodeImpl: Processing slave1:34830 of type STATUS_UPDATE
2019-06-07 07:57:55,338 DEBUG org.apache.hadoop.yarn.server.resourcemanager.scheduler.capacity.CapacityScheduler: nodeUpdate: slave1:34830 clusterResources: <memory:8192, vCores:2>
2019-06-07 07:57:55,338 DEBUG org.apache.hadoop.yarn.server.resourcemanager.scheduler.capacity.CapacityScheduler: nodeUpdate: slave1:34830 clusterResources: <memory:8192, vCores:2>
2019-06-07 07:57:55,339 DEBUG org.apache.hadoop.yarn.server.resourcemanager.scheduler.capacity.CapacityScheduler: Node being looked for scheduling slave1:34830 availableResource: <memory:1024, vCores:0>
2019-06-07 07:57:55,339 DEBUG org.apache.hadoop.yarn.server.resourcemanager.scheduler.capacity.CapacityScheduler: Node being looked for scheduling slave1:34830 availableResource: <memory:1024, vCores:0>
2019-06-07 07:57:55,339 DEBUG org.apache.hadoop.yarn.server.resourcemanager.scheduler.capacity.CapacityScheduler: Trying to schedule on node: slave1, available: <memory:1024, vCores:0>
2019-06-07 07:57:55,339 DEBUG org.apache.hadoop.yarn.server.resourcemanager.scheduler.capacity.CapacityScheduler: Trying to schedule on node: slave1, available: <memory:1024, vCores:0>
2019-06-07 07:57:55,339 DEBUG org.apache.hadoop.yarn.server.resourcemanager.scheduler.capacity.ParentQueue: Skip this queue=root, because it doesn't need more resource, schedulingMode=RESPECT_PARTITION_EXCLUSIVITY node-partition=
2019-06-07 07:57:55,339 DEBUG org.apache.hadoop.yarn.server.resourcemanager.scheduler.capacity.ParentQueue: Skip this queue=root, because it doesn't need more resource, schedulingMode=RESPECT_PARTITION_EXCLUSIVITY node-partition=
2019-06-07 07:57:55,352 DEBUG org.apache.hadoop.yarn.server.resourcemanager.rmnode.RMNodeImpl: Processing slave2:42768 of type STATUS_UPDATE
2019-06-07 07:57:55,352 DEBUG org.apache.hadoop.yarn.server.resourcemanager.rmnode.RMNodeImpl: Processing slave2:42768 of type STATUS_UPDATE
2019-06-07 07:57:55,353 DEBUG org.apache.hadoop.yarn.server.resourcemanager.scheduler.capacity.CapacityScheduler: nodeUpdate: slave2:42768 clusterResources: <memory:8192, vCores:2>
2019-06-07 07:57:55,353 DEBUG org.apache.hadoop.yarn.server.resourcemanager.scheduler.capacity.CapacityScheduler: nodeUpdate: slave2:42768 clusterResources: <memory:8192, vCores:2>
2019-06-07 07:57:55,353 DEBUG org.apache.hadoop.yarn.server.resourcemanager.rmcontainer.RMContainerImpl: Processing container_1559894241434_0001_01_000003 of type LAUNCHED
2019-06-07 07:57:55,353 DEBUG org.apache.hadoop.yarn.server.resourcemanager.rmcontainer.RMContainerImpl: Processing container_1559894241434_0001_01_000003 of type LAUNCHED
2019-06-07 07:57:55,353 INFO org.apache.hadoop.yarn.server.resourcemanager.rmcontainer.RMContainerImpl: container_1559894241434_0001_01_000003 Container Transitioned from ACQUIRED to RUNNING
2019-06-07 07:57:55,353 INFO org.apache.hadoop.yarn.server.resourcemanager.rmcontainer.RMContainerImpl: container_1559894241434_0001_01_000003 Container Transitioned from ACQUIRED to RUNNING
2019-06-07 07:57:55,353 DEBUG org.apache.hadoop.yarn.server.resourcemanager.scheduler.capacity.CapacityScheduler: Node being looked for scheduling slave2:42768 availableResource: <memory:0, vCores:-1>
2019-06-07 07:57:55,353 DEBUG org.apache.hadoop.yarn.server.resourcemanager.scheduler.capacity.CapacityScheduler: Node being looked for scheduling slave2:42768 availableResource: <memory:0, vCores:-1>
2019-06-07 07:57:56,368 DEBUG org.apache.hadoop.yarn.server.resourcemanager.rmnode.RMNodeImpl: Processing slave2:42768 of type STATUS_UPDATE
2019-06-07 07:57:56,368 DEBUG org.apache.hadoop.yarn.server.resourcemanager.rmnode.RMNodeImpl: Processing slave2:42768 of type STATUS_UPDATE
2019-06-07 07:57:56,368 DEBUG org.apache.hadoop.yarn.server.resourcemanager.scheduler.capacity.CapacityScheduler: nodeUpdate: slave2:42768 clusterResources: <memory:8192, vCores:2>
2019-06-07 07:57:56,368 DEBUG org.apache.hadoop.yarn.server.resourcemanager.scheduler.capacity.CapacityScheduler: nodeUpdate: slave2:42768 clusterResources: <memory:8192, vCores:2>
2019-06-07 07:57:56,368 DEBUG org.apache.hadoop.yarn.server.resourcemanager.scheduler.capacity.CapacityScheduler: Node being looked for scheduling slave2:42768 availableResource: <memory:0, vCores:-1>
2019-06-07 07:57:56,368 DEBUG org.apache.hadoop.yarn.server.resourcemanager.scheduler.capacity.CapacityScheduler: Node being looked for scheduling slave2:42768 availableResource: <memory:0, vCores:-1>
2019-06-07 07:57:56,501 DEBUG org.apache.hadoop.yarn.server.resourcemanager.rmnode.RMNodeImpl: Processing slave1:34830 of type STATUS_UPDATE
2019-06-07 07:57:56,501 DEBUG org.apache.hadoop.yarn.server.resourcemanager.rmnode.RMNodeImpl: Processing slave1:34830 of type STATUS_UPDATE
2019-06-07 07:57:56,501 DEBUG org.apache.hadoop.yarn.server.resourcemanager.rmnode.RMNodeImpl: Container container_1559894241434_0001_01_000002 is the first container get launched for application application_1559894241434_0001
2019-06-07 07:57:56,501 DEBUG org.apache.hadoop.yarn.server.resourcemanager.rmnode.RMNodeImpl: Container container_1559894241434_0001_01_000002 is the first container get launched for application application_1559894241434_0001
2019-06-07 07:57:56,501 DEBUG org.apache.hadoop.yarn.server.resourcemanager.rmapp.RMAppImpl: Processing event for application_1559894241434_0001 of type APP_RUNNING_ON_NODE
2019-06-07 07:57:56,501 DEBUG org.apache.hadoop.yarn.server.resourcemanager.rmapp.RMAppImpl: Processing event for application_1559894241434_0001 of type APP_RUNNING_ON_NODE
2019-06-07 07:57:56,501 DEBUG org.apache.hadoop.yarn.server.resourcemanager.scheduler.capacity.CapacityScheduler: nodeUpdate: slave1:34830 clusterResources: <memory:8192, vCores:2>
2019-06-07 07:57:56,501 DEBUG org.apache.hadoop.yarn.server.resourcemanager.scheduler.capacity.CapacityScheduler: nodeUpdate: slave1:34830 clusterResources: <memory:8192, vCores:2>
2019-06-07 07:57:56,502 DEBUG org.apache.hadoop.yarn.server.resourcemanager.rmcontainer.RMContainerImpl: Processing container_1559894241434_0001_01_000002 of type LAUNCHED
2019-06-07 07:57:56,502 DEBUG org.apache.hadoop.yarn.server.resourcemanager.rmcontainer.RMContainerImpl: Processing container_1559894241434_0001_01_000002 of type LAUNCHED
2019-06-07 07:57:56,502 INFO org.apache.hadoop.yarn.server.resourcemanager.rmcontainer.RMContainerImpl: container_1559894241434_0001_01_000002 Container Transitioned from ACQUIRED to RUNNING
2019-06-07 07:57:56,502 INFO org.apache.hadoop.yarn.server.resourcemanager.rmcontainer.RMContainerImpl: container_1559894241434_0001_01_000002 Container Transitioned from ACQUIRED to RUNNING
2019-06-07 07:57:56,502 DEBUG org.apache.hadoop.yarn.server.resourcemanager.scheduler.capacity.CapacityScheduler: Node being looked for scheduling slave1:34830 availableResource: <memory:1024, vCores:0>
2019-06-07 07:57:56,502 DEBUG org.apache.hadoop.yarn.server.resourcemanager.scheduler.capacity.CapacityScheduler: Node being looked for scheduling slave1:34830 availableResource: <memory:1024, vCores:0>
2019-06-07 07:57:56,502 DEBUG org.apache.hadoop.yarn.server.resourcemanager.scheduler.capacity.CapacityScheduler: Trying to schedule on node: slave1, available: <memory:1024, vCores:0>
2019-06-07 07:57:56,502 DEBUG org.apache.hadoop.yarn.server.resourcemanager.scheduler.capacity.CapacityScheduler: Trying to schedule on node: slave1, available: <memory:1024, vCores:0>
2019-06-07 07:57:56,502 DEBUG org.apache.hadoop.yarn.server.resourcemanager.scheduler.capacity.ParentQueue: Skip this queue=root, because it doesn't need more resource, schedulingMode=RESPECT_PARTITION_EXCLUSIVITY node-partition=
2019-06-07 07:57:56,502 DEBUG org.apache.hadoop.yarn.server.resourcemanager.scheduler.capacity.ParentQueue: Skip this queue=root, because it doesn't need more resource, schedulingMode=RESPECT_PARTITION_EXCLUSIVITY node-partition=
2019-06-07 07:57:57,375 DEBUG org.apache.hadoop.yarn.server.resourcemanager.rmnode.RMNodeImpl: Processing slave2:42768 of type STATUS_UPDATE
2019-06-07 07:57:57,375 DEBUG org.apache.hadoop.yarn.server.resourcemanager.rmnode.RMNodeImpl: Processing slave2:42768 of type STATUS_UPDATE
2019-06-07 07:57:57,376 DEBUG org.apache.hadoop.yarn.server.resourcemanager.scheduler.capacity.CapacityScheduler: nodeUpdate: slave2:42768 clusterResources: <memory:8192, vCores:2>
2019-06-07 07:57:57,376 DEBUG org.apache.hadoop.yarn.server.resourcemanager.scheduler.capacity.CapacityScheduler: nodeUpdate: slave2:42768 clusterResources: <memory:8192, vCores:2>
2019-06-07 07:57:57,376 DEBUG org.apache.hadoop.yarn.server.resourcemanager.scheduler.capacity.CapacityScheduler: Node being looked for scheduling slave2:42768 availableResource: <memory:0, vCores:-1>
2019-06-07 07:57:57,376 DEBUG org.apache.hadoop.yarn.server.resourcemanager.scheduler.capacity.CapacityScheduler: Node being looked for scheduling slave2:42768 availableResource: <memory:0, vCores:-1>
2019-06-07 07:57:57,524 DEBUG org.apache.hadoop.yarn.server.resourcemanager.rmnode.RMNodeImpl: Processing slave1:34830 of type STATUS_UPDATE
2019-06-07 07:57:57,524 DEBUG org.apache.hadoop.yarn.server.resourcemanager.rmnode.RMNodeImpl: Processing slave1:34830 of type STATUS_UPDATE
2019-06-07 07:57:57,524 DEBUG org.apache.hadoop.yarn.server.resourcemanager.scheduler.capacity.CapacityScheduler: nodeUpdate: slave1:34830 clusterResources: <memory:8192, vCores:2>
2019-06-07 07:57:57,524 DEBUG org.apache.hadoop.yarn.server.resourcemanager.scheduler.capacity.CapacityScheduler: nodeUpdate: slave1:34830 clusterResources: <memory:8192, vCores:2>
2019-06-07 07:57:57,525 DEBUG org.apache.hadoop.yarn.server.resourcemanager.scheduler.capacity.CapacityScheduler: Node being looked for scheduling slave1:34830 availableResource: <memory:1024, vCores:0>
2019-06-07 07:57:57,525 DEBUG org.apache.hadoop.yarn.server.resourcemanager.scheduler.capacity.CapacityScheduler: Node being looked for scheduling slave1:34830 availableResource: <memory:1024, vCores:0>
2019-06-07 07:57:57,525 DEBUG org.apache.hadoop.yarn.server.resourcemanager.scheduler.capacity.CapacityScheduler: Trying to schedule on node: slave1, available: <memory:1024, vCores:0>
2019-06-07 07:57:57,525 DEBUG org.apache.hadoop.yarn.server.resourcemanager.scheduler.capacity.CapacityScheduler: Trying to schedule on node: slave1, available: <memory:1024, vCores:0>
2019-06-07 07:57:57,525 DEBUG org.apache.hadoop.yarn.server.resourcemanager.scheduler.capacity.ParentQueue: Skip this queue=root, because it doesn't need more resource, schedulingMode=RESPECT_PARTITION_EXCLUSIVITY node-partition=
2019-06-07 07:57:57,525 DEBUG org.apache.hadoop.yarn.server.resourcemanager.scheduler.capacity.ParentQueue: Skip this queue=root, because it doesn't need more resource, schedulingMode=RESPECT_PARTITION_EXCLUSIVITY node-partition=
2019-06-07 07:57:58,142 DEBUG org.apache.hadoop.yarn.server.resourcemanager.scheduler.capacity.CapacityScheduler: allocate: pre-update appattempt_1559894241434_0001_000001 ask size =1
2019-06-07 07:57:58,142 DEBUG org.apache.hadoop.yarn.server.resourcemanager.scheduler.capacity.CapacityScheduler: allocate: pre-update appattempt_1559894241434_0001_000001 ask size =1
2019-06-07 07:57:58,142 DEBUG org.apache.hadoop.yarn.server.resourcemanager.rmapp.attempt.RMAppAttemptImpl: Processing event for appattempt_1559894241434_0001_000001 of type STATUS_UPDATE
2019-06-07 07:57:58,142 DEBUG org.apache.hadoop.yarn.server.resourcemanager.rmapp.attempt.RMAppAttemptImpl: Processing event for appattempt_1559894241434_0001_000001 of type STATUS_UPDATE
2019-06-07 07:57:58,142 INFO org.apache.hadoop.yarn.server.resourcemanager.scheduler.AppSchedulingInfo: checking for deactivate of application :application_1559894241434_0001
2019-06-07 07:57:58,142 INFO org.apache.hadoop.yarn.server.resourcemanager.scheduler.AppSchedulingInfo: checking for deactivate of application :application_1559894241434_0001
2019-06-07 07:57:58,142 DEBUG org.apache.hadoop.yarn.server.resourcemanager.scheduler.capacity.CapacityScheduler: allocate: post-update
2019-06-07 07:57:58,142 DEBUG org.apache.hadoop.yarn.server.resourcemanager.scheduler.capacity.CapacityScheduler: allocate: post-update
2019-06-07 07:57:58,142 DEBUG org.apache.hadoop.yarn.server.resourcemanager.scheduler.capacity.LeafQueue: User limit computation for root in queue default userLimitPercent=100 userLimitFactor=1.0 required: <memory:1024, vCores:1> consumed: <memory:7168, vCores:1> user-limit-resource: <memory:8192, vCores:1> queueCapacity: <memory:8192, vCores:1> qconsumed: <memory:7168, vCores:3> consumedRatio: 0.0 currentCapacity: <memory:8192, vCores:1> activeUsers: 0.0 clusterCapacity: <memory:8192, vCores:2> resourceByLabel: <memory:8192, vCores:2> usageratio: 0.875 Partition:  maxUserLimit=<memory:8192, vCores:1> userWeight=1.0
2019-06-07 07:57:58,142 DEBUG org.apache.hadoop.yarn.server.resourcemanager.scheduler.capacity.LeafQueue: User limit computation for root in queue default userLimitPercent=100 userLimitFactor=1.0 required: <memory:1024, vCores:1> consumed: <memory:7168, vCores:1> user-limit-resource: <memory:8192, vCores:1> queueCapacity: <memory:8192, vCores:1> qconsumed: <memory:7168, vCores:3> consumedRatio: 0.0 currentCapacity: <memory:8192, vCores:1> activeUsers: 0.0 clusterCapacity: <memory:8192, vCores:2> resourceByLabel: <memory:8192, vCores:2> usageratio: 0.875 Partition:  maxUserLimit=<memory:8192, vCores:1> userWeight=1.0
2019-06-07 07:57:58,378 DEBUG org.apache.hadoop.yarn.server.resourcemanager.rmnode.RMNodeImpl: Processing slave2:42768 of type STATUS_UPDATE
2019-06-07 07:57:58,378 DEBUG org.apache.hadoop.yarn.server.resourcemanager.rmnode.RMNodeImpl: Processing slave2:42768 of type STATUS_UPDATE
2019-06-07 07:57:58,378 DEBUG org.apache.hadoop.yarn.server.resourcemanager.scheduler.capacity.CapacityScheduler: nodeUpdate: slave2:42768 clusterResources: <memory:8192, vCores:2>
2019-06-07 07:57:58,378 DEBUG org.apache.hadoop.yarn.server.resourcemanager.scheduler.capacity.CapacityScheduler: nodeUpdate: slave2:42768 clusterResources: <memory:8192, vCores:2>
2019-06-07 07:57:58,379 DEBUG org.apache.hadoop.yarn.server.resourcemanager.scheduler.capacity.CapacityScheduler: Node being looked for scheduling slave2:42768 availableResource: <memory:0, vCores:-1>
2019-06-07 07:57:58,379 DEBUG org.apache.hadoop.yarn.server.resourcemanager.scheduler.capacity.CapacityScheduler: Node being looked for scheduling slave2:42768 availableResource: <memory:0, vCores:-1>
2019-06-07 07:57:58,527 DEBUG org.apache.hadoop.yarn.server.resourcemanager.rmnode.RMNodeImpl: Processing slave1:34830 of type STATUS_UPDATE
2019-06-07 07:57:58,527 DEBUG org.apache.hadoop.yarn.server.resourcemanager.rmnode.RMNodeImpl: Processing slave1:34830 of type STATUS_UPDATE
2019-06-07 07:57:58,527 DEBUG org.apache.hadoop.yarn.server.resourcemanager.scheduler.capacity.CapacityScheduler: nodeUpdate: slave1:34830 clusterResources: <memory:8192, vCores:2>
2019-06-07 07:57:58,527 DEBUG org.apache.hadoop.yarn.server.resourcemanager.scheduler.capacity.CapacityScheduler: nodeUpdate: slave1:34830 clusterResources: <memory:8192, vCores:2>
2019-06-07 07:57:58,527 DEBUG org.apache.hadoop.yarn.server.resourcemanager.scheduler.capacity.CapacityScheduler: Node being looked for scheduling slave1:34830 availableResource: <memory:1024, vCores:0>
2019-06-07 07:57:58,527 DEBUG org.apache.hadoop.yarn.server.resourcemanager.scheduler.capacity.CapacityScheduler: Node being looked for scheduling slave1:34830 availableResource: <memory:1024, vCores:0>
2019-06-07 07:57:58,527 DEBUG org.apache.hadoop.yarn.server.resourcemanager.scheduler.capacity.CapacityScheduler: Trying to schedule on node: slave1, available: <memory:1024, vCores:0>
2019-06-07 07:57:58,527 DEBUG org.apache.hadoop.yarn.server.resourcemanager.scheduler.capacity.CapacityScheduler: Trying to schedule on node: slave1, available: <memory:1024, vCores:0>
2019-06-07 07:57:58,527 DEBUG org.apache.hadoop.yarn.server.resourcemanager.scheduler.capacity.ParentQueue: Skip this queue=root, because it doesn't need more resource, schedulingMode=RESPECT_PARTITION_EXCLUSIVITY node-partition=
2019-06-07 07:57:58,527 DEBUG org.apache.hadoop.yarn.server.resourcemanager.scheduler.capacity.ParentQueue: Skip this queue=root, because it doesn't need more resource, schedulingMode=RESPECT_PARTITION_EXCLUSIVITY node-partition=
2019-06-07 07:57:59,381 DEBUG org.apache.hadoop.yarn.server.resourcemanager.rmnode.RMNodeImpl: Processing slave2:42768 of type STATUS_UPDATE
2019-06-07 07:57:59,381 DEBUG org.apache.hadoop.yarn.server.resourcemanager.rmnode.RMNodeImpl: Processing slave2:42768 of type STATUS_UPDATE
2019-06-07 07:57:59,382 DEBUG org.apache.hadoop.yarn.server.resourcemanager.scheduler.capacity.CapacityScheduler: nodeUpdate: slave2:42768 clusterResources: <memory:8192, vCores:2>
2019-06-07 07:57:59,382 DEBUG org.apache.hadoop.yarn.server.resourcemanager.scheduler.capacity.CapacityScheduler: nodeUpdate: slave2:42768 clusterResources: <memory:8192, vCores:2>
2019-06-07 07:57:59,382 DEBUG org.apache.hadoop.yarn.server.resourcemanager.scheduler.capacity.CapacityScheduler: Node being looked for scheduling slave2:42768 availableResource: <memory:0, vCores:-1>
2019-06-07 07:57:59,382 DEBUG org.apache.hadoop.yarn.server.resourcemanager.scheduler.capacity.CapacityScheduler: Node being looked for scheduling slave2:42768 availableResource: <memory:0, vCores:-1>
2019-06-07 07:57:59,530 DEBUG org.apache.hadoop.yarn.server.resourcemanager.rmnode.RMNodeImpl: Processing slave1:34830 of type STATUS_UPDATE
2019-06-07 07:57:59,530 DEBUG org.apache.hadoop.yarn.server.resourcemanager.rmnode.RMNodeImpl: Processing slave1:34830 of type STATUS_UPDATE
2019-06-07 07:57:59,530 DEBUG org.apache.hadoop.yarn.server.resourcemanager.scheduler.capacity.CapacityScheduler: nodeUpdate: slave1:34830 clusterResources: <memory:8192, vCores:2>
2019-06-07 07:57:59,530 DEBUG org.apache.hadoop.yarn.server.resourcemanager.scheduler.capacity.CapacityScheduler: nodeUpdate: slave1:34830 clusterResources: <memory:8192, vCores:2>
2019-06-07 07:57:59,531 DEBUG org.apache.hadoop.yarn.server.resourcemanager.scheduler.capacity.CapacityScheduler: Node being looked for scheduling slave1:34830 availableResource: <memory:1024, vCores:0>
2019-06-07 07:57:59,531 DEBUG org.apache.hadoop.yarn.server.resourcemanager.scheduler.capacity.CapacityScheduler: Node being looked for scheduling slave1:34830 availableResource: <memory:1024, vCores:0>
2019-06-07 07:57:59,531 DEBUG org.apache.hadoop.yarn.server.resourcemanager.scheduler.capacity.CapacityScheduler: Trying to schedule on node: slave1, available: <memory:1024, vCores:0>
2019-06-07 07:57:59,531 DEBUG org.apache.hadoop.yarn.server.resourcemanager.scheduler.capacity.CapacityScheduler: Trying to schedule on node: slave1, available: <memory:1024, vCores:0>
2019-06-07 07:57:59,531 DEBUG org.apache.hadoop.yarn.server.resourcemanager.scheduler.capacity.ParentQueue: Skip this queue=root, because it doesn't need more resource, schedulingMode=RESPECT_PARTITION_EXCLUSIVITY node-partition=
2019-06-07 07:57:59,531 DEBUG org.apache.hadoop.yarn.server.resourcemanager.scheduler.capacity.ParentQueue: Skip this queue=root, because it doesn't need more resource, schedulingMode=RESPECT_PARTITION_EXCLUSIVITY node-partition=
2019-06-07 07:58:00,388 DEBUG org.apache.hadoop.yarn.server.resourcemanager.rmnode.RMNodeImpl: Processing slave2:42768 of type STATUS_UPDATE
2019-06-07 07:58:00,388 DEBUG org.apache.hadoop.yarn.server.resourcemanager.rmnode.RMNodeImpl: Processing slave2:42768 of type STATUS_UPDATE
2019-06-07 07:58:00,388 DEBUG org.apache.hadoop.yarn.server.resourcemanager.scheduler.capacity.CapacityScheduler: nodeUpdate: slave2:42768 clusterResources: <memory:8192, vCores:2>
2019-06-07 07:58:00,388 DEBUG org.apache.hadoop.yarn.server.resourcemanager.scheduler.capacity.CapacityScheduler: nodeUpdate: slave2:42768 clusterResources: <memory:8192, vCores:2>
2019-06-07 07:58:00,388 DEBUG org.apache.hadoop.yarn.server.resourcemanager.scheduler.capacity.CapacityScheduler: Node being looked for scheduling slave2:42768 availableResource: <memory:0, vCores:-1>
2019-06-07 07:58:00,388 DEBUG org.apache.hadoop.yarn.server.resourcemanager.scheduler.capacity.CapacityScheduler: Node being looked for scheduling slave2:42768 availableResource: <memory:0, vCores:-1>
2019-06-07 07:58:00,538 DEBUG org.apache.hadoop.yarn.server.resourcemanager.rmnode.RMNodeImpl: Processing slave1:34830 of type STATUS_UPDATE
2019-06-07 07:58:00,538 DEBUG org.apache.hadoop.yarn.server.resourcemanager.rmnode.RMNodeImpl: Processing slave1:34830 of type STATUS_UPDATE
2019-06-07 07:58:00,539 DEBUG org.apache.hadoop.yarn.server.resourcemanager.scheduler.capacity.CapacityScheduler: nodeUpdate: slave1:34830 clusterResources: <memory:8192, vCores:2>
2019-06-07 07:58:00,539 DEBUG org.apache.hadoop.yarn.server.resourcemanager.scheduler.capacity.CapacityScheduler: nodeUpdate: slave1:34830 clusterResources: <memory:8192, vCores:2>
2019-06-07 07:58:00,539 DEBUG org.apache.hadoop.yarn.server.resourcemanager.scheduler.capacity.CapacityScheduler: Node being looked for scheduling slave1:34830 availableResource: <memory:1024, vCores:0>
2019-06-07 07:58:00,539 DEBUG org.apache.hadoop.yarn.server.resourcemanager.scheduler.capacity.CapacityScheduler: Node being looked for scheduling slave1:34830 availableResource: <memory:1024, vCores:0>
2019-06-07 07:58:00,539 DEBUG org.apache.hadoop.yarn.server.resourcemanager.scheduler.capacity.CapacityScheduler: Trying to schedule on node: slave1, available: <memory:1024, vCores:0>
2019-06-07 07:58:00,539 DEBUG org.apache.hadoop.yarn.server.resourcemanager.scheduler.capacity.CapacityScheduler: Trying to schedule on node: slave1, available: <memory:1024, vCores:0>
2019-06-07 07:58:00,539 DEBUG org.apache.hadoop.yarn.server.resourcemanager.scheduler.capacity.ParentQueue: Skip this queue=root, because it doesn't need more resource, schedulingMode=RESPECT_PARTITION_EXCLUSIVITY node-partition=
2019-06-07 07:58:00,539 DEBUG org.apache.hadoop.yarn.server.resourcemanager.scheduler.capacity.ParentQueue: Skip this queue=root, because it doesn't need more resource, schedulingMode=RESPECT_PARTITION_EXCLUSIVITY node-partition=
2019-06-07 07:58:01,145 DEBUG org.apache.hadoop.yarn.server.resourcemanager.scheduler.capacity.LeafQueue: User limit computation for root in queue default userLimitPercent=100 userLimitFactor=1.0 required: <memory:1024, vCores:1> consumed: <memory:7168, vCores:1> user-limit-resource: <memory:8192, vCores:1> queueCapacity: <memory:8192, vCores:1> qconsumed: <memory:7168, vCores:3> consumedRatio: 0.0 currentCapacity: <memory:8192, vCores:1> activeUsers: 0.0 clusterCapacity: <memory:8192, vCores:2> resourceByLabel: <memory:8192, vCores:2> usageratio: 0.875 Partition:  maxUserLimit=<memory:8192, vCores:1> userWeight=1.0
2019-06-07 07:58:01,145 DEBUG org.apache.hadoop.yarn.server.resourcemanager.scheduler.capacity.LeafQueue: User limit computation for root in queue default userLimitPercent=100 userLimitFactor=1.0 required: <memory:1024, vCores:1> consumed: <memory:7168, vCores:1> user-limit-resource: <memory:8192, vCores:1> queueCapacity: <memory:8192, vCores:1> qconsumed: <memory:7168, vCores:3> consumedRatio: 0.0 currentCapacity: <memory:8192, vCores:1> activeUsers: 0.0 clusterCapacity: <memory:8192, vCores:2> resourceByLabel: <memory:8192, vCores:2> usageratio: 0.875 Partition:  maxUserLimit=<memory:8192, vCores:1> userWeight=1.0
2019-06-07 07:58:01,146 DEBUG org.apache.hadoop.yarn.server.resourcemanager.rmapp.attempt.RMAppAttemptImpl: Processing event for appattempt_1559894241434_0001_000001 of type STATUS_UPDATE
2019-06-07 07:58:01,146 DEBUG org.apache.hadoop.yarn.server.resourcemanager.rmapp.attempt.RMAppAttemptImpl: Processing event for appattempt_1559894241434_0001_000001 of type STATUS_UPDATE
2019-06-07 07:58:01,390 DEBUG org.apache.hadoop.yarn.server.resourcemanager.rmnode.RMNodeImpl: Processing slave2:42768 of type STATUS_UPDATE
2019-06-07 07:58:01,390 DEBUG org.apache.hadoop.yarn.server.resourcemanager.rmnode.RMNodeImpl: Processing slave2:42768 of type STATUS_UPDATE
2019-06-07 07:58:01,390 DEBUG org.apache.hadoop.yarn.server.resourcemanager.scheduler.capacity.CapacityScheduler: nodeUpdate: slave2:42768 clusterResources: <memory:8192, vCores:2>
2019-06-07 07:58:01,390 DEBUG org.apache.hadoop.yarn.server.resourcemanager.scheduler.capacity.CapacityScheduler: nodeUpdate: slave2:42768 clusterResources: <memory:8192, vCores:2>
2019-06-07 07:58:01,391 DEBUG org.apache.hadoop.yarn.server.resourcemanager.scheduler.capacity.CapacityScheduler: Node being looked for scheduling slave2:42768 availableResource: <memory:0, vCores:-1>
2019-06-07 07:58:01,391 DEBUG org.apache.hadoop.yarn.server.resourcemanager.scheduler.capacity.CapacityScheduler: Node being looked for scheduling slave2:42768 availableResource: <memory:0, vCores:-1>
2019-06-07 07:58:01,540 DEBUG org.apache.hadoop.yarn.server.resourcemanager.rmnode.RMNodeImpl: Processing slave1:34830 of type STATUS_UPDATE
2019-06-07 07:58:01,540 DEBUG org.apache.hadoop.yarn.server.resourcemanager.rmnode.RMNodeImpl: Processing slave1:34830 of type STATUS_UPDATE
2019-06-07 07:58:01,541 DEBUG org.apache.hadoop.yarn.server.resourcemanager.scheduler.capacity.CapacityScheduler: nodeUpdate: slave1:34830 clusterResources: <memory:8192, vCores:2>
2019-06-07 07:58:01,541 DEBUG org.apache.hadoop.yarn.server.resourcemanager.scheduler.capacity.CapacityScheduler: nodeUpdate: slave1:34830 clusterResources: <memory:8192, vCores:2>
2019-06-07 07:58:01,541 DEBUG org.apache.hadoop.yarn.server.resourcemanager.scheduler.capacity.CapacityScheduler: Node being looked for scheduling slave1:34830 availableResource: <memory:1024, vCores:0>
2019-06-07 07:58:01,541 DEBUG org.apache.hadoop.yarn.server.resourcemanager.scheduler.capacity.CapacityScheduler: Node being looked for scheduling slave1:34830 availableResource: <memory:1024, vCores:0>
2019-06-07 07:58:01,541 DEBUG org.apache.hadoop.yarn.server.resourcemanager.scheduler.capacity.CapacityScheduler: Trying to schedule on node: slave1, available: <memory:1024, vCores:0>
2019-06-07 07:58:01,541 DEBUG org.apache.hadoop.yarn.server.resourcemanager.scheduler.capacity.CapacityScheduler: Trying to schedule on node: slave1, available: <memory:1024, vCores:0>
2019-06-07 07:58:01,541 DEBUG org.apache.hadoop.yarn.server.resourcemanager.scheduler.capacity.ParentQueue: Skip this queue=root, because it doesn't need more resource, schedulingMode=RESPECT_PARTITION_EXCLUSIVITY node-partition=
2019-06-07 07:58:01,541 DEBUG org.apache.hadoop.yarn.server.resourcemanager.scheduler.capacity.ParentQueue: Skip this queue=root, because it doesn't need more resource, schedulingMode=RESPECT_PARTITION_EXCLUSIVITY node-partition=
2019-06-07 07:58:02,393 DEBUG org.apache.hadoop.yarn.server.resourcemanager.rmnode.RMNodeImpl: Processing slave2:42768 of type STATUS_UPDATE
2019-06-07 07:58:02,393 DEBUG org.apache.hadoop.yarn.server.resourcemanager.rmnode.RMNodeImpl: Processing slave2:42768 of type STATUS_UPDATE
2019-06-07 07:58:02,393 DEBUG org.apache.hadoop.yarn.server.resourcemanager.scheduler.capacity.CapacityScheduler: nodeUpdate: slave2:42768 clusterResources: <memory:8192, vCores:2>
2019-06-07 07:58:02,393 DEBUG org.apache.hadoop.yarn.server.resourcemanager.scheduler.capacity.CapacityScheduler: nodeUpdate: slave2:42768 clusterResources: <memory:8192, vCores:2>
2019-06-07 07:58:02,393 DEBUG org.apache.hadoop.yarn.server.resourcemanager.scheduler.capacity.CapacityScheduler: Node being looked for scheduling slave2:42768 availableResource: <memory:0, vCores:-1>
2019-06-07 07:58:02,393 DEBUG org.apache.hadoop.yarn.server.resourcemanager.scheduler.capacity.CapacityScheduler: Node being looked for scheduling slave2:42768 availableResource: <memory:0, vCores:-1>
2019-06-07 07:58:02,545 DEBUG org.apache.hadoop.yarn.server.resourcemanager.rmnode.RMNodeImpl: Processing slave1:34830 of type STATUS_UPDATE
2019-06-07 07:58:02,545 DEBUG org.apache.hadoop.yarn.server.resourcemanager.rmnode.RMNodeImpl: Processing slave1:34830 of type STATUS_UPDATE
2019-06-07 07:58:02,545 DEBUG org.apache.hadoop.yarn.server.resourcemanager.scheduler.capacity.CapacityScheduler: nodeUpdate: slave1:34830 clusterResources: <memory:8192, vCores:2>
2019-06-07 07:58:02,545 DEBUG org.apache.hadoop.yarn.server.resourcemanager.scheduler.capacity.CapacityScheduler: nodeUpdate: slave1:34830 clusterResources: <memory:8192, vCores:2>
2019-06-07 07:58:02,545 DEBUG org.apache.hadoop.yarn.server.resourcemanager.scheduler.capacity.CapacityScheduler: Node being looked for scheduling slave1:34830 availableResource: <memory:1024, vCores:0>
2019-06-07 07:58:02,545 DEBUG org.apache.hadoop.yarn.server.resourcemanager.scheduler.capacity.CapacityScheduler: Node being looked for scheduling slave1:34830 availableResource: <memory:1024, vCores:0>
2019-06-07 07:58:02,545 DEBUG org.apache.hadoop.yarn.server.resourcemanager.scheduler.capacity.CapacityScheduler: Trying to schedule on node: slave1, available: <memory:1024, vCores:0>
2019-06-07 07:58:02,545 DEBUG org.apache.hadoop.yarn.server.resourcemanager.scheduler.capacity.CapacityScheduler: Trying to schedule on node: slave1, available: <memory:1024, vCores:0>
2019-06-07 07:58:02,545 DEBUG org.apache.hadoop.yarn.server.resourcemanager.scheduler.capacity.ParentQueue: Skip this queue=root, because it doesn't need more resource, schedulingMode=RESPECT_PARTITION_EXCLUSIVITY node-partition=
2019-06-07 07:58:02,545 DEBUG org.apache.hadoop.yarn.server.resourcemanager.scheduler.capacity.ParentQueue: Skip this queue=root, because it doesn't need more resource, schedulingMode=RESPECT_PARTITION_EXCLUSIVITY node-partition=
2019-06-07 07:58:03,395 DEBUG org.apache.hadoop.yarn.server.resourcemanager.rmnode.RMNodeImpl: Processing slave2:42768 of type STATUS_UPDATE
2019-06-07 07:58:03,395 DEBUG org.apache.hadoop.yarn.server.resourcemanager.rmnode.RMNodeImpl: Processing slave2:42768 of type STATUS_UPDATE
2019-06-07 07:58:03,395 DEBUG org.apache.hadoop.yarn.server.resourcemanager.scheduler.capacity.CapacityScheduler: nodeUpdate: slave2:42768 clusterResources: <memory:8192, vCores:2>
2019-06-07 07:58:03,395 DEBUG org.apache.hadoop.yarn.server.resourcemanager.scheduler.capacity.CapacityScheduler: nodeUpdate: slave2:42768 clusterResources: <memory:8192, vCores:2>
2019-06-07 07:58:03,395 DEBUG org.apache.hadoop.yarn.server.resourcemanager.scheduler.capacity.CapacityScheduler: Node being looked for scheduling slave2:42768 availableResource: <memory:0, vCores:-1>
2019-06-07 07:58:03,395 DEBUG org.apache.hadoop.yarn.server.resourcemanager.scheduler.capacity.CapacityScheduler: Node being looked for scheduling slave2:42768 availableResource: <memory:0, vCores:-1>
2019-06-07 07:58:03,551 DEBUG org.apache.hadoop.yarn.server.resourcemanager.rmnode.RMNodeImpl: Processing slave1:34830 of type STATUS_UPDATE
2019-06-07 07:58:03,551 DEBUG org.apache.hadoop.yarn.server.resourcemanager.rmnode.RMNodeImpl: Processing slave1:34830 of type STATUS_UPDATE
2019-06-07 07:58:03,552 DEBUG org.apache.hadoop.yarn.server.resourcemanager.scheduler.capacity.CapacityScheduler: nodeUpdate: slave1:34830 clusterResources: <memory:8192, vCores:2>
2019-06-07 07:58:03,552 DEBUG org.apache.hadoop.yarn.server.resourcemanager.scheduler.capacity.CapacityScheduler: nodeUpdate: slave1:34830 clusterResources: <memory:8192, vCores:2>
2019-06-07 07:58:03,552 DEBUG org.apache.hadoop.yarn.server.resourcemanager.scheduler.capacity.CapacityScheduler: Node being looked for scheduling slave1:34830 availableResource: <memory:1024, vCores:0>
2019-06-07 07:58:03,552 DEBUG org.apache.hadoop.yarn.server.resourcemanager.scheduler.capacity.CapacityScheduler: Node being looked for scheduling slave1:34830 availableResource: <memory:1024, vCores:0>
2019-06-07 07:58:03,552 DEBUG org.apache.hadoop.yarn.server.resourcemanager.scheduler.capacity.CapacityScheduler: Trying to schedule on node: slave1, available: <memory:1024, vCores:0>
2019-06-07 07:58:03,552 DEBUG org.apache.hadoop.yarn.server.resourcemanager.scheduler.capacity.CapacityScheduler: Trying to schedule on node: slave1, available: <memory:1024, vCores:0>
2019-06-07 07:58:03,552 DEBUG org.apache.hadoop.yarn.server.resourcemanager.scheduler.capacity.ParentQueue: Skip this queue=root, because it doesn't need more resource, schedulingMode=RESPECT_PARTITION_EXCLUSIVITY node-partition=
2019-06-07 07:58:03,552 DEBUG org.apache.hadoop.yarn.server.resourcemanager.scheduler.capacity.ParentQueue: Skip this queue=root, because it doesn't need more resource, schedulingMode=RESPECT_PARTITION_EXCLUSIVITY node-partition=
2019-06-07 07:58:04,149 DEBUG org.apache.hadoop.yarn.server.resourcemanager.scheduler.capacity.LeafQueue: User limit computation for root in queue default userLimitPercent=100 userLimitFactor=1.0 required: <memory:1024, vCores:1> consumed: <memory:7168, vCores:1> user-limit-resource: <memory:8192, vCores:1> queueCapacity: <memory:8192, vCores:1> qconsumed: <memory:7168, vCores:3> consumedRatio: 0.0 currentCapacity: <memory:8192, vCores:1> activeUsers: 0.0 clusterCapacity: <memory:8192, vCores:2> resourceByLabel: <memory:8192, vCores:2> usageratio: 0.875 Partition:  maxUserLimit=<memory:8192, vCores:1> userWeight=1.0
2019-06-07 07:58:04,149 DEBUG org.apache.hadoop.yarn.server.resourcemanager.scheduler.capacity.LeafQueue: User limit computation for root in queue default userLimitPercent=100 userLimitFactor=1.0 required: <memory:1024, vCores:1> consumed: <memory:7168, vCores:1> user-limit-resource: <memory:8192, vCores:1> queueCapacity: <memory:8192, vCores:1> qconsumed: <memory:7168, vCores:3> consumedRatio: 0.0 currentCapacity: <memory:8192, vCores:1> activeUsers: 0.0 clusterCapacity: <memory:8192, vCores:2> resourceByLabel: <memory:8192, vCores:2> usageratio: 0.875 Partition:  maxUserLimit=<memory:8192, vCores:1> userWeight=1.0
2019-06-07 07:58:04,149 DEBUG org.apache.hadoop.yarn.server.resourcemanager.rmapp.attempt.RMAppAttemptImpl: Processing event for appattempt_1559894241434_0001_000001 of type STATUS_UPDATE
2019-06-07 07:58:04,149 DEBUG org.apache.hadoop.yarn.server.resourcemanager.rmapp.attempt.RMAppAttemptImpl: Processing event for appattempt_1559894241434_0001_000001 of type STATUS_UPDATE
2019-06-07 07:58:04,397 DEBUG org.apache.hadoop.yarn.server.resourcemanager.rmnode.RMNodeImpl: Processing slave2:42768 of type STATUS_UPDATE
2019-06-07 07:58:04,397 DEBUG org.apache.hadoop.yarn.server.resourcemanager.rmnode.RMNodeImpl: Processing slave2:42768 of type STATUS_UPDATE
2019-06-07 07:58:04,402 DEBUG org.apache.hadoop.yarn.server.resourcemanager.scheduler.capacity.CapacityScheduler: nodeUpdate: slave2:42768 clusterResources: <memory:8192, vCores:2>
2019-06-07 07:58:04,402 DEBUG org.apache.hadoop.yarn.server.resourcemanager.scheduler.capacity.CapacityScheduler: nodeUpdate: slave2:42768 clusterResources: <memory:8192, vCores:2>
2019-06-07 07:58:04,405 DEBUG org.apache.hadoop.yarn.server.resourcemanager.scheduler.capacity.CapacityScheduler: Node being looked for scheduling slave2:42768 availableResource: <memory:0, vCores:-1>
2019-06-07 07:58:04,405 DEBUG org.apache.hadoop.yarn.server.resourcemanager.scheduler.capacity.CapacityScheduler: Node being looked for scheduling slave2:42768 availableResource: <memory:0, vCores:-1>
2019-06-07 07:58:04,553 DEBUG org.apache.hadoop.yarn.server.resourcemanager.rmnode.RMNodeImpl: Processing slave1:34830 of type STATUS_UPDATE
2019-06-07 07:58:04,553 DEBUG org.apache.hadoop.yarn.server.resourcemanager.rmnode.RMNodeImpl: Processing slave1:34830 of type STATUS_UPDATE
2019-06-07 07:58:04,554 DEBUG org.apache.hadoop.yarn.server.resourcemanager.scheduler.capacity.CapacityScheduler: nodeUpdate: slave1:34830 clusterResources: <memory:8192, vCores:2>
2019-06-07 07:58:04,554 DEBUG org.apache.hadoop.yarn.server.resourcemanager.scheduler.capacity.CapacityScheduler: nodeUpdate: slave1:34830 clusterResources: <memory:8192, vCores:2>
2019-06-07 07:58:04,554 DEBUG org.apache.hadoop.yarn.server.resourcemanager.scheduler.capacity.CapacityScheduler: Node being looked for scheduling slave1:34830 availableResource: <memory:1024, vCores:0>
2019-06-07 07:58:04,554 DEBUG org.apache.hadoop.yarn.server.resourcemanager.scheduler.capacity.CapacityScheduler: Node being looked for scheduling slave1:34830 availableResource: <memory:1024, vCores:0>
2019-06-07 07:58:04,554 DEBUG org.apache.hadoop.yarn.server.resourcemanager.scheduler.capacity.CapacityScheduler: Trying to schedule on node: slave1, available: <memory:1024, vCores:0>
2019-06-07 07:58:04,554 DEBUG org.apache.hadoop.yarn.server.resourcemanager.scheduler.capacity.CapacityScheduler: Trying to schedule on node: slave1, available: <memory:1024, vCores:0>
2019-06-07 07:58:04,554 DEBUG org.apache.hadoop.yarn.server.resourcemanager.scheduler.capacity.ParentQueue: Skip this queue=root, because it doesn't need more resource, schedulingMode=RESPECT_PARTITION_EXCLUSIVITY node-partition=
2019-06-07 07:58:04,554 DEBUG org.apache.hadoop.yarn.server.resourcemanager.scheduler.capacity.ParentQueue: Skip this queue=root, because it doesn't need more resource, schedulingMode=RESPECT_PARTITION_EXCLUSIVITY node-partition=
2019-06-07 07:58:05,404 DEBUG org.apache.hadoop.yarn.server.resourcemanager.rmnode.RMNodeImpl: Processing slave2:42768 of type STATUS_UPDATE
2019-06-07 07:58:05,404 DEBUG org.apache.hadoop.yarn.server.resourcemanager.rmnode.RMNodeImpl: Processing slave2:42768 of type STATUS_UPDATE
2019-06-07 07:58:05,406 DEBUG org.apache.hadoop.yarn.server.resourcemanager.scheduler.capacity.CapacityScheduler: nodeUpdate: slave2:42768 clusterResources: <memory:8192, vCores:2>
2019-06-07 07:58:05,406 DEBUG org.apache.hadoop.yarn.server.resourcemanager.scheduler.capacity.CapacityScheduler: nodeUpdate: slave2:42768 clusterResources: <memory:8192, vCores:2>
2019-06-07 07:58:05,406 DEBUG org.apache.hadoop.yarn.server.resourcemanager.scheduler.capacity.CapacityScheduler: Node being looked for scheduling slave2:42768 availableResource: <memory:0, vCores:-1>
2019-06-07 07:58:05,406 DEBUG org.apache.hadoop.yarn.server.resourcemanager.scheduler.capacity.CapacityScheduler: Node being looked for scheduling slave2:42768 availableResource: <memory:0, vCores:-1>
2019-06-07 07:58:05,561 DEBUG org.apache.hadoop.yarn.server.resourcemanager.rmnode.RMNodeImpl: Processing slave1:34830 of type STATUS_UPDATE
2019-06-07 07:58:05,561 DEBUG org.apache.hadoop.yarn.server.resourcemanager.rmnode.RMNodeImpl: Processing slave1:34830 of type STATUS_UPDATE
2019-06-07 07:58:05,561 DEBUG org.apache.hadoop.yarn.server.resourcemanager.scheduler.capacity.CapacityScheduler: nodeUpdate: slave1:34830 clusterResources: <memory:8192, vCores:2>
2019-06-07 07:58:05,561 DEBUG org.apache.hadoop.yarn.server.resourcemanager.scheduler.capacity.CapacityScheduler: nodeUpdate: slave1:34830 clusterResources: <memory:8192, vCores:2>
2019-06-07 07:58:05,561 DEBUG org.apache.hadoop.yarn.server.resourcemanager.scheduler.capacity.CapacityScheduler: Node being looked for scheduling slave1:34830 availableResource: <memory:1024, vCores:0>
2019-06-07 07:58:05,561 DEBUG org.apache.hadoop.yarn.server.resourcemanager.scheduler.capacity.CapacityScheduler: Node being looked for scheduling slave1:34830 availableResource: <memory:1024, vCores:0>
2019-06-07 07:58:05,561 DEBUG org.apache.hadoop.yarn.server.resourcemanager.scheduler.capacity.CapacityScheduler: Trying to schedule on node: slave1, available: <memory:1024, vCores:0>
2019-06-07 07:58:05,561 DEBUG org.apache.hadoop.yarn.server.resourcemanager.scheduler.capacity.CapacityScheduler: Trying to schedule on node: slave1, available: <memory:1024, vCores:0>
2019-06-07 07:58:05,561 DEBUG org.apache.hadoop.yarn.server.resourcemanager.scheduler.capacity.ParentQueue: Skip this queue=root, because it doesn't need more resource, schedulingMode=RESPECT_PARTITION_EXCLUSIVITY node-partition=
2019-06-07 07:58:05,561 DEBUG org.apache.hadoop.yarn.server.resourcemanager.scheduler.capacity.ParentQueue: Skip this queue=root, because it doesn't need more resource, schedulingMode=RESPECT_PARTITION_EXCLUSIVITY node-partition=
2019-06-07 07:58:06,410 DEBUG org.apache.hadoop.yarn.server.resourcemanager.rmnode.RMNodeImpl: Processing slave2:42768 of type STATUS_UPDATE
2019-06-07 07:58:06,410 DEBUG org.apache.hadoop.yarn.server.resourcemanager.rmnode.RMNodeImpl: Processing slave2:42768 of type STATUS_UPDATE
2019-06-07 07:58:06,411 DEBUG org.apache.hadoop.yarn.server.resourcemanager.scheduler.capacity.CapacityScheduler: nodeUpdate: slave2:42768 clusterResources: <memory:8192, vCores:2>
2019-06-07 07:58:06,411 DEBUG org.apache.hadoop.yarn.server.resourcemanager.scheduler.capacity.CapacityScheduler: nodeUpdate: slave2:42768 clusterResources: <memory:8192, vCores:2>
2019-06-07 07:58:06,411 DEBUG org.apache.hadoop.yarn.server.resourcemanager.scheduler.capacity.CapacityScheduler: Node being looked for scheduling slave2:42768 availableResource: <memory:0, vCores:-1>
2019-06-07 07:58:06,411 DEBUG org.apache.hadoop.yarn.server.resourcemanager.scheduler.capacity.CapacityScheduler: Node being looked for scheduling slave2:42768 availableResource: <memory:0, vCores:-1>
2019-06-07 07:58:06,561 DEBUG org.apache.hadoop.yarn.server.resourcemanager.scheduler.capacity.LeafQueue: User limit computation for root in queue default userLimitPercent=100 userLimitFactor=1.0 required: <memory:1024, vCores:1> consumed: <memory:7168, vCores:1> user-limit-resource: <memory:8192, vCores:1> queueCapacity: <memory:8192, vCores:1> qconsumed: <memory:7168, vCores:3> consumedRatio: 0.0 currentCapacity: <memory:8192, vCores:1> activeUsers: 0.0 clusterCapacity: <memory:8192, vCores:2> resourceByLabel: <memory:8192, vCores:2> usageratio: 0.875 Partition:  maxUserLimit=<memory:8192, vCores:1> userWeight=1.0
2019-06-07 07:58:06,561 DEBUG org.apache.hadoop.yarn.server.resourcemanager.scheduler.capacity.LeafQueue: User limit computation for root in queue default userLimitPercent=100 userLimitFactor=1.0 required: <memory:1024, vCores:1> consumed: <memory:7168, vCores:1> user-limit-resource: <memory:8192, vCores:1> queueCapacity: <memory:8192, vCores:1> qconsumed: <memory:7168, vCores:3> consumedRatio: 0.0 currentCapacity: <memory:8192, vCores:1> activeUsers: 0.0 clusterCapacity: <memory:8192, vCores:2> resourceByLabel: <memory:8192, vCores:2> usageratio: 0.875 Partition:  maxUserLimit=<memory:8192, vCores:1> userWeight=1.0
2019-06-07 07:58:06,562 DEBUG org.apache.hadoop.yarn.server.resourcemanager.rmapp.attempt.RMAppAttemptImpl: Processing event for appattempt_1559894241434_0001_000001 of type STATUS_UPDATE
2019-06-07 07:58:06,562 DEBUG org.apache.hadoop.yarn.server.resourcemanager.rmapp.attempt.RMAppAttemptImpl: Processing event for appattempt_1559894241434_0001_000001 of type STATUS_UPDATE
2019-06-07 07:58:06,563 DEBUG org.apache.hadoop.yarn.server.resourcemanager.rmnode.RMNodeImpl: Processing slave1:34830 of type STATUS_UPDATE
2019-06-07 07:58:06,563 DEBUG org.apache.hadoop.yarn.server.resourcemanager.rmnode.RMNodeImpl: Processing slave1:34830 of type STATUS_UPDATE
2019-06-07 07:58:06,570 DEBUG org.apache.hadoop.yarn.server.resourcemanager.scheduler.capacity.CapacityScheduler: nodeUpdate: slave1:34830 clusterResources: <memory:8192, vCores:2>
2019-06-07 07:58:06,570 DEBUG org.apache.hadoop.yarn.server.resourcemanager.scheduler.capacity.CapacityScheduler: nodeUpdate: slave1:34830 clusterResources: <memory:8192, vCores:2>
2019-06-07 07:58:06,572 DEBUG org.apache.hadoop.yarn.server.resourcemanager.scheduler.capacity.CapacityScheduler: Node being looked for scheduling slave1:34830 availableResource: <memory:1024, vCores:0>
2019-06-07 07:58:06,572 DEBUG org.apache.hadoop.yarn.server.resourcemanager.scheduler.capacity.CapacityScheduler: Node being looked for scheduling slave1:34830 availableResource: <memory:1024, vCores:0>
2019-06-07 07:58:06,572 DEBUG org.apache.hadoop.yarn.server.resourcemanager.scheduler.capacity.CapacityScheduler: Trying to schedule on node: slave1, available: <memory:1024, vCores:0>
2019-06-07 07:58:06,572 DEBUG org.apache.hadoop.yarn.server.resourcemanager.scheduler.capacity.CapacityScheduler: Trying to schedule on node: slave1, available: <memory:1024, vCores:0>
2019-06-07 07:58:06,572 DEBUG org.apache.hadoop.yarn.server.resourcemanager.scheduler.capacity.ParentQueue: Skip this queue=root, because it doesn't need more resource, schedulingMode=RESPECT_PARTITION_EXCLUSIVITY node-partition=
2019-06-07 07:58:06,572 DEBUG org.apache.hadoop.yarn.server.resourcemanager.scheduler.capacity.ParentQueue: Skip this queue=root, because it doesn't need more resource, schedulingMode=RESPECT_PARTITION_EXCLUSIVITY node-partition=
2019-06-07 07:58:06,728 DEBUG org.apache.hadoop.yarn.server.resourcemanager.rmapp.attempt.RMAppAttemptImpl: Processing event for appattempt_1559894241434_0001_000001 of type UNREGISTERED
2019-06-07 07:58:06,728 DEBUG org.apache.hadoop.yarn.server.resourcemanager.rmapp.attempt.RMAppAttemptImpl: Processing event for appattempt_1559894241434_0001_000001 of type UNREGISTERED
2019-06-07 07:58:06,729 INFO org.apache.hadoop.yarn.server.resourcemanager.rmapp.attempt.RMAppAttemptImpl: Updating application attempt appattempt_1559894241434_0001_000001 with final state: FINISHING, and exit status: -1000
2019-06-07 07:58:06,729 INFO org.apache.hadoop.yarn.server.resourcemanager.rmapp.attempt.RMAppAttemptImpl: Updating application attempt appattempt_1559894241434_0001_000001 with final state: FINISHING, and exit status: -1000
2019-06-07 07:58:06,729 INFO org.apache.hadoop.yarn.server.resourcemanager.rmapp.attempt.RMAppAttemptImpl: appattempt_1559894241434_0001_000001 State change from RUNNING to FINAL_SAVING
2019-06-07 07:58:06,729 INFO org.apache.hadoop.yarn.server.resourcemanager.rmapp.attempt.RMAppAttemptImpl: appattempt_1559894241434_0001_000001 State change from RUNNING to FINAL_SAVING
2019-06-07 07:58:06,730 DEBUG org.apache.hadoop.yarn.server.resourcemanager.rmapp.RMAppImpl: Processing event for application_1559894241434_0001 of type ATTEMPT_UNREGISTERED
2019-06-07 07:58:06,730 DEBUG org.apache.hadoop.yarn.server.resourcemanager.rmapp.RMAppImpl: Processing event for application_1559894241434_0001 of type ATTEMPT_UNREGISTERED
2019-06-07 07:58:06,730 INFO org.apache.hadoop.yarn.server.resourcemanager.rmapp.RMAppImpl: Updating application application_1559894241434_0001 with final state: FINISHING
2019-06-07 07:58:06,730 INFO org.apache.hadoop.yarn.server.resourcemanager.rmapp.RMAppImpl: Updating application application_1559894241434_0001 with final state: FINISHING
2019-06-07 07:58:06,730 INFO org.apache.hadoop.yarn.server.resourcemanager.rmapp.RMAppImpl: application_1559894241434_0001 State change from RUNNING to FINAL_SAVING on event=ATTEMPT_UNREGISTERED
2019-06-07 07:58:06,730 INFO org.apache.hadoop.yarn.server.resourcemanager.rmapp.RMAppImpl: application_1559894241434_0001 State change from RUNNING to FINAL_SAVING on event=ATTEMPT_UNREGISTERED
2019-06-07 07:58:06,730 DEBUG org.apache.hadoop.yarn.server.resourcemanager.recovery.RMStateStore: Processing event of type UPDATE_APP_ATTEMPT
2019-06-07 07:58:06,730 DEBUG org.apache.hadoop.yarn.server.resourcemanager.recovery.RMStateStore: Processing event of type UPDATE_APP_ATTEMPT
2019-06-07 07:58:06,730 DEBUG org.apache.hadoop.yarn.server.resourcemanager.recovery.RMStateStore: Updating info for attempt: appattempt_1559894241434_0001_000001
2019-06-07 07:58:06,730 DEBUG org.apache.hadoop.yarn.server.resourcemanager.recovery.RMStateStore: Updating info for attempt: appattempt_1559894241434_0001_000001
2019-06-07 07:58:06,730 DEBUG org.apache.hadoop.yarn.server.resourcemanager.recovery.RMStateStore: Processing event of type UPDATE_APP
2019-06-07 07:58:06,730 DEBUG org.apache.hadoop.yarn.server.resourcemanager.recovery.RMStateStore: Processing event of type UPDATE_APP
2019-06-07 07:58:06,730 INFO org.apache.hadoop.yarn.server.resourcemanager.recovery.RMStateStore: Updating info for app: application_1559894241434_0001
2019-06-07 07:58:06,730 INFO org.apache.hadoop.yarn.server.resourcemanager.recovery.RMStateStore: Updating info for app: application_1559894241434_0001
2019-06-07 07:58:06,730 DEBUG org.apache.hadoop.yarn.server.resourcemanager.rmapp.attempt.RMAppAttemptImpl: Processing event for appattempt_1559894241434_0001_000001 of type ATTEMPT_UPDATE_SAVED
2019-06-07 07:58:06,730 DEBUG org.apache.hadoop.yarn.server.resourcemanager.rmapp.attempt.RMAppAttemptImpl: Processing event for appattempt_1559894241434_0001_000001 of type ATTEMPT_UPDATE_SAVED
2019-06-07 07:58:06,730 INFO org.apache.hadoop.yarn.server.resourcemanager.rmapp.attempt.RMAppAttemptImpl: appattempt_1559894241434_0001_000001 State change from FINAL_SAVING to FINISHING
2019-06-07 07:58:06,730 INFO org.apache.hadoop.yarn.server.resourcemanager.rmapp.attempt.RMAppAttemptImpl: appattempt_1559894241434_0001_000001 State change from FINAL_SAVING to FINISHING
2019-06-07 07:58:06,730 DEBUG org.apache.hadoop.yarn.server.resourcemanager.rmapp.RMAppImpl: Processing event for application_1559894241434_0001 of type APP_UPDATE_SAVED
2019-06-07 07:58:06,730 DEBUG org.apache.hadoop.yarn.server.resourcemanager.rmapp.RMAppImpl: Processing event for application_1559894241434_0001 of type APP_UPDATE_SAVED
2019-06-07 07:58:06,730 INFO org.apache.hadoop.yarn.server.resourcemanager.rmapp.RMAppImpl: application_1559894241434_0001 State change from FINAL_SAVING to FINISHING on event=APP_UPDATE_SAVED
2019-06-07 07:58:06,730 INFO org.apache.hadoop.yarn.server.resourcemanager.rmapp.RMAppImpl: application_1559894241434_0001 State change from FINAL_SAVING to FINISHING on event=APP_UPDATE_SAVED
2019-06-07 07:58:06,747 DEBUG org.apache.hadoop.yarn.server.resourcemanager.rmnode.RMNodeImpl: Processing slave1:34830 of type STATUS_UPDATE
2019-06-07 07:58:06,747 DEBUG org.apache.hadoop.yarn.server.resourcemanager.rmnode.RMNodeImpl: Processing slave1:34830 of type STATUS_UPDATE
2019-06-07 07:58:06,747 DEBUG org.apache.hadoop.yarn.server.resourcemanager.scheduler.capacity.CapacityScheduler: nodeUpdate: slave1:34830 clusterResources: <memory:8192, vCores:2>
2019-06-07 07:58:06,747 DEBUG org.apache.hadoop.yarn.server.resourcemanager.scheduler.capacity.CapacityScheduler: nodeUpdate: slave1:34830 clusterResources: <memory:8192, vCores:2>
2019-06-07 07:58:06,748 DEBUG org.apache.hadoop.yarn.server.resourcemanager.rmcontainer.RMContainerImpl: Processing container_1559894241434_0001_01_000002 of type FINISHED
2019-06-07 07:58:06,748 DEBUG org.apache.hadoop.yarn.server.resourcemanager.rmcontainer.RMContainerImpl: Processing container_1559894241434_0001_01_000002 of type FINISHED
2019-06-07 07:58:06,748 INFO org.apache.hadoop.yarn.server.resourcemanager.rmcontainer.RMContainerImpl: container_1559894241434_0001_01_000002 Container Transitioned from RUNNING to COMPLETED
2019-06-07 07:58:06,748 INFO org.apache.hadoop.yarn.server.resourcemanager.rmcontainer.RMContainerImpl: container_1559894241434_0001_01_000002 Container Transitioned from RUNNING to COMPLETED
2019-06-07 07:58:06,748 DEBUG org.apache.hadoop.yarn.server.resourcemanager.rmapp.attempt.RMAppAttemptImpl: Processing event for appattempt_1559894241434_0001_000001 of type CONTAINER_FINISHED
2019-06-07 07:58:06,748 DEBUG org.apache.hadoop.yarn.server.resourcemanager.rmapp.attempt.RMAppAttemptImpl: Processing event for appattempt_1559894241434_0001_000001 of type CONTAINER_FINISHED
2019-06-07 07:58:06,748 INFO org.apache.hadoop.yarn.server.resourcemanager.RMAuditLogger: USER=root	OPERATION=AM Released Container	TARGET=SchedulerApp	RESULT=SUCCESS	APPID=application_1559894241434_0001	CONTAINERID=container_1559894241434_0001_01_000002
2019-06-07 07:58:06,748 INFO org.apache.hadoop.yarn.server.resourcemanager.RMAuditLogger: USER=root	OPERATION=AM Released Container	TARGET=SchedulerApp	RESULT=SUCCESS	APPID=application_1559894241434_0001	CONTAINERID=container_1559894241434_0001_01_000002
2019-06-07 07:58:06,748 DEBUG org.apache.hadoop.yarn.server.resourcemanager.scheduler.capacity.LeafQueue: User limit computation for root in queue default userLimitPercent=100 userLimitFactor=1.0 required: <memory:1024, vCores:1> consumed: <memory:4096, vCores:1> user-limit-resource: <memory:8192, vCores:1> queueCapacity: <memory:8192, vCores:1> qconsumed: <memory:4096, vCores:2> consumedRatio: 0.0 currentCapacity: <memory:8192, vCores:1> activeUsers: 0.0 clusterCapacity: <memory:8192, vCores:2> resourceByLabel: <memory:8192, vCores:2> usageratio: 0.5 Partition:  maxUserLimit=<memory:8192, vCores:1> userWeight=1.0
2019-06-07 07:58:06,748 DEBUG org.apache.hadoop.yarn.server.resourcemanager.scheduler.capacity.LeafQueue: User limit computation for root in queue default userLimitPercent=100 userLimitFactor=1.0 required: <memory:1024, vCores:1> consumed: <memory:4096, vCores:1> user-limit-resource: <memory:8192, vCores:1> queueCapacity: <memory:8192, vCores:1> qconsumed: <memory:4096, vCores:2> consumedRatio: 0.0 currentCapacity: <memory:8192, vCores:1> activeUsers: 0.0 clusterCapacity: <memory:8192, vCores:2> resourceByLabel: <memory:8192, vCores:2> usageratio: 0.5 Partition:  maxUserLimit=<memory:8192, vCores:1> userWeight=1.0
2019-06-07 07:58:06,748 DEBUG org.apache.hadoop.yarn.server.resourcemanager.scheduler.capacity.LeafQueue: default used=<memory:4096, vCores:2> numContainers=2 user=root user-resources=<memory:4096, vCores:2>
2019-06-07 07:58:06,748 DEBUG org.apache.hadoop.yarn.server.resourcemanager.scheduler.capacity.LeafQueue: default used=<memory:4096, vCores:2> numContainers=2 user=root user-resources=<memory:4096, vCores:2>
2019-06-07 07:58:06,749 DEBUG org.apache.hadoop.yarn.server.resourcemanager.scheduler.capacity.ParentQueue: completedContainer root: numChildQueue= 1, capacity=1.0, absoluteCapacity=1.0, usedResources=<memory:4096, vCores:2>usedCapacity=0.5, numApps=1, numContainers=2, cluster=<memory:8192, vCores:2>
2019-06-07 07:58:06,749 DEBUG org.apache.hadoop.yarn.server.resourcemanager.scheduler.capacity.ParentQueue: completedContainer root: numChildQueue= 1, capacity=1.0, absoluteCapacity=1.0, usedResources=<memory:4096, vCores:2>usedCapacity=0.5, numApps=1, numContainers=2, cluster=<memory:8192, vCores:2>
2019-06-07 07:58:06,749 DEBUG org.apache.hadoop.yarn.server.resourcemanager.scheduler.capacity.ParentQueue: Re-sorting completed queue: default: capacity=1.0, absoluteCapacity=1.0, usedResources=<memory:4096, vCores:2>, usedCapacity=0.5, absoluteUsedCapacity=0.5, numApps=1, numContainers=2
2019-06-07 07:58:06,749 DEBUG org.apache.hadoop.yarn.server.resourcemanager.scheduler.capacity.ParentQueue: Re-sorting completed queue: default: capacity=1.0, absoluteCapacity=1.0, usedResources=<memory:4096, vCores:2>, usedCapacity=0.5, absoluteUsedCapacity=0.5, numApps=1, numContainers=2
2019-06-07 07:58:06,749 INFO org.apache.hadoop.yarn.server.resourcemanager.scheduler.SchedulerNode: Released container container_1559894241434_0001_01_000002 of capacity <memory:3072, vCores:1> on host slave1:34830, which currently has 0 containers, <memory:0, vCores:0> used and <memory:4096, vCores:1> available, release resources=true
2019-06-07 07:58:06,749 INFO org.apache.hadoop.yarn.server.resourcemanager.scheduler.SchedulerNode: Released container container_1559894241434_0001_01_000002 of capacity <memory:3072, vCores:1> on host slave1:34830, which currently has 0 containers, <memory:0, vCores:0> used and <memory:4096, vCores:1> available, release resources=true
2019-06-07 07:58:06,749 DEBUG org.apache.hadoop.yarn.server.resourcemanager.scheduler.capacity.CapacityScheduler: Node being looked for scheduling slave1:34830 availableResource: <memory:4096, vCores:1>
2019-06-07 07:58:06,749 DEBUG org.apache.hadoop.yarn.server.resourcemanager.scheduler.capacity.CapacityScheduler: Node being looked for scheduling slave1:34830 availableResource: <memory:4096, vCores:1>
2019-06-07 07:58:06,749 DEBUG org.apache.hadoop.yarn.server.resourcemanager.scheduler.capacity.CapacityScheduler: Trying to schedule on node: slave1, available: <memory:4096, vCores:1>
2019-06-07 07:58:06,749 DEBUG org.apache.hadoop.yarn.server.resourcemanager.scheduler.capacity.CapacityScheduler: Trying to schedule on node: slave1, available: <memory:4096, vCores:1>
2019-06-07 07:58:06,749 DEBUG org.apache.hadoop.yarn.server.resourcemanager.scheduler.capacity.ParentQueue: Skip this queue=root, because it doesn't need more resource, schedulingMode=RESPECT_PARTITION_EXCLUSIVITY node-partition=
2019-06-07 07:58:06,749 DEBUG org.apache.hadoop.yarn.server.resourcemanager.scheduler.capacity.ParentQueue: Skip this queue=root, because it doesn't need more resource, schedulingMode=RESPECT_PARTITION_EXCLUSIVITY node-partition=
2019-06-07 07:58:06,753 DEBUG org.apache.hadoop.yarn.server.resourcemanager.rmnode.RMNodeImpl: Processing slave2:42768 of type STATUS_UPDATE
2019-06-07 07:58:06,753 DEBUG org.apache.hadoop.yarn.server.resourcemanager.rmnode.RMNodeImpl: Processing slave2:42768 of type STATUS_UPDATE
2019-06-07 07:58:06,754 DEBUG org.apache.hadoop.yarn.server.resourcemanager.scheduler.capacity.CapacityScheduler: nodeUpdate: slave2:42768 clusterResources: <memory:8192, vCores:2>
2019-06-07 07:58:06,754 DEBUG org.apache.hadoop.yarn.server.resourcemanager.scheduler.capacity.CapacityScheduler: nodeUpdate: slave2:42768 clusterResources: <memory:8192, vCores:2>
2019-06-07 07:58:06,755 DEBUG org.apache.hadoop.yarn.server.resourcemanager.rmcontainer.RMContainerImpl: Processing container_1559894241434_0001_01_000003 of type FINISHED
2019-06-07 07:58:06,755 DEBUG org.apache.hadoop.yarn.server.resourcemanager.rmcontainer.RMContainerImpl: Processing container_1559894241434_0001_01_000003 of type FINISHED
2019-06-07 07:58:06,755 INFO org.apache.hadoop.yarn.server.resourcemanager.rmcontainer.RMContainerImpl: container_1559894241434_0001_01_000003 Container Transitioned from RUNNING to COMPLETED
2019-06-07 07:58:06,755 INFO org.apache.hadoop.yarn.server.resourcemanager.rmcontainer.RMContainerImpl: container_1559894241434_0001_01_000003 Container Transitioned from RUNNING to COMPLETED
2019-06-07 07:58:06,755 INFO org.apache.hadoop.yarn.server.resourcemanager.RMAuditLogger: USER=root	OPERATION=AM Released Container	TARGET=SchedulerApp	RESULT=SUCCESS	APPID=application_1559894241434_0001	CONTAINERID=container_1559894241434_0001_01_000003
2019-06-07 07:58:06,755 INFO org.apache.hadoop.yarn.server.resourcemanager.RMAuditLogger: USER=root	OPERATION=AM Released Container	TARGET=SchedulerApp	RESULT=SUCCESS	APPID=application_1559894241434_0001	CONTAINERID=container_1559894241434_0001_01_000003
2019-06-07 07:58:06,755 DEBUG org.apache.hadoop.yarn.server.resourcemanager.scheduler.capacity.LeafQueue: User limit computation for root in queue default userLimitPercent=100 userLimitFactor=1.0 required: <memory:1024, vCores:1> consumed: <memory:1024, vCores:1> user-limit-resource: <memory:8192, vCores:1> queueCapacity: <memory:8192, vCores:1> qconsumed: <memory:1024, vCores:1> consumedRatio: 0.0 currentCapacity: <memory:8192, vCores:1> activeUsers: 0.0 clusterCapacity: <memory:8192, vCores:2> resourceByLabel: <memory:8192, vCores:2> usageratio: 0.125 Partition:  maxUserLimit=<memory:8192, vCores:1> userWeight=1.0
2019-06-07 07:58:06,755 DEBUG org.apache.hadoop.yarn.server.resourcemanager.scheduler.capacity.LeafQueue: User limit computation for root in queue default userLimitPercent=100 userLimitFactor=1.0 required: <memory:1024, vCores:1> consumed: <memory:1024, vCores:1> user-limit-resource: <memory:8192, vCores:1> queueCapacity: <memory:8192, vCores:1> qconsumed: <memory:1024, vCores:1> consumedRatio: 0.0 currentCapacity: <memory:8192, vCores:1> activeUsers: 0.0 clusterCapacity: <memory:8192, vCores:2> resourceByLabel: <memory:8192, vCores:2> usageratio: 0.125 Partition:  maxUserLimit=<memory:8192, vCores:1> userWeight=1.0
2019-06-07 07:58:06,755 DEBUG org.apache.hadoop.yarn.server.resourcemanager.scheduler.capacity.LeafQueue: default used=<memory:1024, vCores:1> numContainers=1 user=root user-resources=<memory:1024, vCores:1>
2019-06-07 07:58:06,755 DEBUG org.apache.hadoop.yarn.server.resourcemanager.scheduler.capacity.LeafQueue: default used=<memory:1024, vCores:1> numContainers=1 user=root user-resources=<memory:1024, vCores:1>
2019-06-07 07:58:06,755 DEBUG org.apache.hadoop.yarn.server.resourcemanager.scheduler.capacity.ParentQueue: completedContainer root: numChildQueue= 1, capacity=1.0, absoluteCapacity=1.0, usedResources=<memory:1024, vCores:1>usedCapacity=0.125, numApps=1, numContainers=1, cluster=<memory:8192, vCores:2>
2019-06-07 07:58:06,755 DEBUG org.apache.hadoop.yarn.server.resourcemanager.scheduler.capacity.ParentQueue: completedContainer root: numChildQueue= 1, capacity=1.0, absoluteCapacity=1.0, usedResources=<memory:1024, vCores:1>usedCapacity=0.125, numApps=1, numContainers=1, cluster=<memory:8192, vCores:2>
2019-06-07 07:58:06,755 DEBUG org.apache.hadoop.yarn.server.resourcemanager.scheduler.capacity.ParentQueue: Re-sorting completed queue: default: capacity=1.0, absoluteCapacity=1.0, usedResources=<memory:1024, vCores:1>, usedCapacity=0.125, absoluteUsedCapacity=0.125, numApps=1, numContainers=1
2019-06-07 07:58:06,755 DEBUG org.apache.hadoop.yarn.server.resourcemanager.scheduler.capacity.ParentQueue: Re-sorting completed queue: default: capacity=1.0, absoluteCapacity=1.0, usedResources=<memory:1024, vCores:1>, usedCapacity=0.125, absoluteUsedCapacity=0.125, numApps=1, numContainers=1
2019-06-07 07:58:06,755 INFO org.apache.hadoop.yarn.server.resourcemanager.scheduler.SchedulerNode: Released container container_1559894241434_0001_01_000003 of capacity <memory:3072, vCores:1> on host slave2:42768, which currently has 1 containers, <memory:1024, vCores:1> used and <memory:3072, vCores:0> available, release resources=true
2019-06-07 07:58:06,755 INFO org.apache.hadoop.yarn.server.resourcemanager.scheduler.SchedulerNode: Released container container_1559894241434_0001_01_000003 of capacity <memory:3072, vCores:1> on host slave2:42768, which currently has 1 containers, <memory:1024, vCores:1> used and <memory:3072, vCores:0> available, release resources=true
2019-06-07 07:58:06,755 DEBUG org.apache.hadoop.yarn.server.resourcemanager.scheduler.capacity.CapacityScheduler: Node being looked for scheduling slave2:42768 availableResource: <memory:3072, vCores:0>
2019-06-07 07:58:06,755 DEBUG org.apache.hadoop.yarn.server.resourcemanager.scheduler.capacity.CapacityScheduler: Node being looked for scheduling slave2:42768 availableResource: <memory:3072, vCores:0>
2019-06-07 07:58:06,755 DEBUG org.apache.hadoop.yarn.server.resourcemanager.scheduler.capacity.CapacityScheduler: Trying to schedule on node: slave2, available: <memory:3072, vCores:0>
2019-06-07 07:58:06,755 DEBUG org.apache.hadoop.yarn.server.resourcemanager.scheduler.capacity.CapacityScheduler: Trying to schedule on node: slave2, available: <memory:3072, vCores:0>
2019-06-07 07:58:06,755 DEBUG org.apache.hadoop.yarn.server.resourcemanager.scheduler.capacity.ParentQueue: Skip this queue=root, because it doesn't need more resource, schedulingMode=RESPECT_PARTITION_EXCLUSIVITY node-partition=
2019-06-07 07:58:06,755 DEBUG org.apache.hadoop.yarn.server.resourcemanager.scheduler.capacity.ParentQueue: Skip this queue=root, because it doesn't need more resource, schedulingMode=RESPECT_PARTITION_EXCLUSIVITY node-partition=
2019-06-07 07:58:06,755 DEBUG org.apache.hadoop.yarn.server.resourcemanager.rmapp.attempt.RMAppAttemptImpl: Processing event for appattempt_1559894241434_0001_000001 of type CONTAINER_FINISHED
2019-06-07 07:58:06,755 DEBUG org.apache.hadoop.yarn.server.resourcemanager.rmapp.attempt.RMAppAttemptImpl: Processing event for appattempt_1559894241434_0001_000001 of type CONTAINER_FINISHED
2019-06-07 07:58:06,833 INFO org.apache.hadoop.yarn.server.resourcemanager.ApplicationMasterService: application_1559894241434_0001 unregistered successfully. 
2019-06-07 07:58:06,833 INFO org.apache.hadoop.yarn.server.resourcemanager.ApplicationMasterService: application_1559894241434_0001 unregistered successfully. 
2019-06-07 07:58:07,290 DEBUG org.apache.hadoop.yarn.server.resourcemanager.rmnode.RMNodeImpl: Processing slave2:42768 of type STATUS_UPDATE
2019-06-07 07:58:07,290 DEBUG org.apache.hadoop.yarn.server.resourcemanager.rmnode.RMNodeImpl: Processing slave2:42768 of type STATUS_UPDATE
2019-06-07 07:58:07,290 DEBUG org.apache.hadoop.yarn.server.resourcemanager.scheduler.capacity.CapacityScheduler: nodeUpdate: slave2:42768 clusterResources: <memory:8192, vCores:2>
2019-06-07 07:58:07,290 DEBUG org.apache.hadoop.yarn.server.resourcemanager.scheduler.capacity.CapacityScheduler: nodeUpdate: slave2:42768 clusterResources: <memory:8192, vCores:2>
2019-06-07 07:58:07,291 DEBUG org.apache.hadoop.yarn.server.resourcemanager.rmcontainer.RMContainerImpl: Processing container_1559894241434_0001_01_000001 of type FINISHED
2019-06-07 07:58:07,291 DEBUG org.apache.hadoop.yarn.server.resourcemanager.rmcontainer.RMContainerImpl: Processing container_1559894241434_0001_01_000001 of type FINISHED
2019-06-07 07:58:07,291 INFO org.apache.hadoop.yarn.server.resourcemanager.rmcontainer.RMContainerImpl: container_1559894241434_0001_01_000001 Container Transitioned from RUNNING to COMPLETED
2019-06-07 07:58:07,291 INFO org.apache.hadoop.yarn.server.resourcemanager.rmcontainer.RMContainerImpl: container_1559894241434_0001_01_000001 Container Transitioned from RUNNING to COMPLETED
2019-06-07 07:58:07,291 INFO org.apache.hadoop.yarn.server.resourcemanager.RMAuditLogger: USER=root	OPERATION=AM Released Container	TARGET=SchedulerApp	RESULT=SUCCESS	APPID=application_1559894241434_0001	CONTAINERID=container_1559894241434_0001_01_000001
2019-06-07 07:58:07,291 INFO org.apache.hadoop.yarn.server.resourcemanager.RMAuditLogger: USER=root	OPERATION=AM Released Container	TARGET=SchedulerApp	RESULT=SUCCESS	APPID=application_1559894241434_0001	CONTAINERID=container_1559894241434_0001_01_000001
2019-06-07 07:58:07,291 DEBUG org.apache.hadoop.yarn.server.resourcemanager.scheduler.capacity.LeafQueue: User limit computation for root in queue default userLimitPercent=100 userLimitFactor=1.0 required: <memory:1024, vCores:1> consumed: <memory:0, vCores:0> user-limit-resource: <memory:8192, vCores:1> queueCapacity: <memory:8192, vCores:1> qconsumed: <memory:0, vCores:0> consumedRatio: 0.0 currentCapacity: <memory:8192, vCores:1> activeUsers: 0.0 clusterCapacity: <memory:8192, vCores:2> resourceByLabel: <memory:8192, vCores:2> usageratio: 0.0 Partition:  maxUserLimit=<memory:8192, vCores:1> userWeight=1.0
2019-06-07 07:58:07,291 DEBUG org.apache.hadoop.yarn.server.resourcemanager.scheduler.capacity.LeafQueue: User limit computation for root in queue default userLimitPercent=100 userLimitFactor=1.0 required: <memory:1024, vCores:1> consumed: <memory:0, vCores:0> user-limit-resource: <memory:8192, vCores:1> queueCapacity: <memory:8192, vCores:1> qconsumed: <memory:0, vCores:0> consumedRatio: 0.0 currentCapacity: <memory:8192, vCores:1> activeUsers: 0.0 clusterCapacity: <memory:8192, vCores:2> resourceByLabel: <memory:8192, vCores:2> usageratio: 0.0 Partition:  maxUserLimit=<memory:8192, vCores:1> userWeight=1.0
2019-06-07 07:58:07,291 DEBUG org.apache.hadoop.yarn.server.resourcemanager.scheduler.capacity.LeafQueue: default used=<memory:0, vCores:0> numContainers=0 user=root user-resources=<memory:0, vCores:0>
2019-06-07 07:58:07,291 DEBUG org.apache.hadoop.yarn.server.resourcemanager.scheduler.capacity.LeafQueue: default used=<memory:0, vCores:0> numContainers=0 user=root user-resources=<memory:0, vCores:0>
2019-06-07 07:58:07,291 DEBUG org.apache.hadoop.yarn.server.resourcemanager.scheduler.capacity.ParentQueue: completedContainer root: numChildQueue= 1, capacity=1.0, absoluteCapacity=1.0, usedResources=<memory:0, vCores:0>usedCapacity=0.0, numApps=1, numContainers=0, cluster=<memory:8192, vCores:2>
2019-06-07 07:58:07,291 DEBUG org.apache.hadoop.yarn.server.resourcemanager.scheduler.capacity.ParentQueue: completedContainer root: numChildQueue= 1, capacity=1.0, absoluteCapacity=1.0, usedResources=<memory:0, vCores:0>usedCapacity=0.0, numApps=1, numContainers=0, cluster=<memory:8192, vCores:2>
2019-06-07 07:58:07,291 DEBUG org.apache.hadoop.yarn.server.resourcemanager.scheduler.capacity.ParentQueue: Re-sorting completed queue: default: capacity=1.0, absoluteCapacity=1.0, usedResources=<memory:0, vCores:0>, usedCapacity=0.0, absoluteUsedCapacity=0.0, numApps=1, numContainers=0
2019-06-07 07:58:07,291 DEBUG org.apache.hadoop.yarn.server.resourcemanager.scheduler.capacity.ParentQueue: Re-sorting completed queue: default: capacity=1.0, absoluteCapacity=1.0, usedResources=<memory:0, vCores:0>, usedCapacity=0.0, absoluteUsedCapacity=0.0, numApps=1, numContainers=0
2019-06-07 07:58:07,291 INFO org.apache.hadoop.yarn.server.resourcemanager.scheduler.SchedulerNode: Released container container_1559894241434_0001_01_000001 of capacity <memory:1024, vCores:1> on host slave2:42768, which currently has 0 containers, <memory:0, vCores:0> used and <memory:4096, vCores:1> available, release resources=true
2019-06-07 07:58:07,291 INFO org.apache.hadoop.yarn.server.resourcemanager.scheduler.SchedulerNode: Released container container_1559894241434_0001_01_000001 of capacity <memory:1024, vCores:1> on host slave2:42768, which currently has 0 containers, <memory:0, vCores:0> used and <memory:4096, vCores:1> available, release resources=true
2019-06-07 07:58:07,291 DEBUG org.apache.hadoop.yarn.server.resourcemanager.scheduler.capacity.CapacityScheduler: Node being looked for scheduling slave2:42768 availableResource: <memory:4096, vCores:1>
2019-06-07 07:58:07,291 DEBUG org.apache.hadoop.yarn.server.resourcemanager.scheduler.capacity.CapacityScheduler: Node being looked for scheduling slave2:42768 availableResource: <memory:4096, vCores:1>
2019-06-07 07:58:07,291 DEBUG org.apache.hadoop.yarn.server.resourcemanager.scheduler.capacity.CapacityScheduler: Trying to schedule on node: slave2, available: <memory:4096, vCores:1>
2019-06-07 07:58:07,291 DEBUG org.apache.hadoop.yarn.server.resourcemanager.scheduler.capacity.CapacityScheduler: Trying to schedule on node: slave2, available: <memory:4096, vCores:1>
2019-06-07 07:58:07,291 DEBUG org.apache.hadoop.yarn.server.resourcemanager.scheduler.capacity.ParentQueue: Skip this queue=root, because it doesn't need more resource, schedulingMode=RESPECT_PARTITION_EXCLUSIVITY node-partition=
2019-06-07 07:58:07,291 DEBUG org.apache.hadoop.yarn.server.resourcemanager.scheduler.capacity.ParentQueue: Skip this queue=root, because it doesn't need more resource, schedulingMode=RESPECT_PARTITION_EXCLUSIVITY node-partition=
2019-06-07 07:58:07,291 DEBUG org.apache.hadoop.yarn.server.resourcemanager.rmapp.attempt.RMAppAttemptImpl: Processing event for appattempt_1559894241434_0001_000001 of type CONTAINER_FINISHED
2019-06-07 07:58:07,291 DEBUG org.apache.hadoop.yarn.server.resourcemanager.rmapp.attempt.RMAppAttemptImpl: Processing event for appattempt_1559894241434_0001_000001 of type CONTAINER_FINISHED
2019-06-07 07:58:07,292 INFO org.apache.hadoop.yarn.server.resourcemanager.ApplicationMasterService: Unregistering app attempt : appattempt_1559894241434_0001_000001
2019-06-07 07:58:07,292 INFO org.apache.hadoop.yarn.server.resourcemanager.ApplicationMasterService: Unregistering app attempt : appattempt_1559894241434_0001_000001
2019-06-07 07:58:07,293 INFO org.apache.hadoop.yarn.server.resourcemanager.security.AMRMTokenSecretManager: Application finished, removing password for appattempt_1559894241434_0001_000001
2019-06-07 07:58:07,293 INFO org.apache.hadoop.yarn.server.resourcemanager.security.AMRMTokenSecretManager: Application finished, removing password for appattempt_1559894241434_0001_000001
2019-06-07 07:58:07,293 INFO org.apache.hadoop.yarn.server.resourcemanager.rmapp.attempt.RMAppAttemptImpl: appattempt_1559894241434_0001_000001 State change from FINISHING to FINISHED
2019-06-07 07:58:07,293 INFO org.apache.hadoop.yarn.server.resourcemanager.rmapp.attempt.RMAppAttemptImpl: appattempt_1559894241434_0001_000001 State change from FINISHING to FINISHED
2019-06-07 07:58:07,293 DEBUG org.apache.hadoop.yarn.server.resourcemanager.rmapp.RMAppImpl: Processing event for application_1559894241434_0001 of type ATTEMPT_FINISHED
2019-06-07 07:58:07,293 DEBUG org.apache.hadoop.yarn.server.resourcemanager.rmapp.RMAppImpl: Processing event for application_1559894241434_0001 of type ATTEMPT_FINISHED
2019-06-07 07:58:07,295 INFO org.apache.hadoop.yarn.server.resourcemanager.rmapp.RMAppImpl: application_1559894241434_0001 State change from FINISHING to FINISHED on event=ATTEMPT_FINISHED
2019-06-07 07:58:07,295 INFO org.apache.hadoop.yarn.server.resourcemanager.rmapp.RMAppImpl: application_1559894241434_0001 State change from FINISHING to FINISHED on event=ATTEMPT_FINISHED
2019-06-07 07:58:07,295 INFO org.apache.hadoop.yarn.server.resourcemanager.scheduler.capacity.CapacityScheduler: Application Attempt appattempt_1559894241434_0001_000001 is done. finalState=FINISHED
2019-06-07 07:58:07,295 INFO org.apache.hadoop.yarn.server.resourcemanager.scheduler.capacity.CapacityScheduler: Application Attempt appattempt_1559894241434_0001_000001 is done. finalState=FINISHED
2019-06-07 07:58:07,295 INFO org.apache.hadoop.yarn.server.resourcemanager.scheduler.AppSchedulingInfo: Application application_1559894241434_0001 requests cleared
2019-06-07 07:58:07,295 INFO org.apache.hadoop.yarn.server.resourcemanager.scheduler.AppSchedulingInfo: Application application_1559894241434_0001 requests cleared
2019-06-07 07:58:07,295 INFO org.apache.hadoop.yarn.server.resourcemanager.scheduler.capacity.LeafQueue: Application removed - appId: application_1559894241434_0001 user: root queue: default #user-pending-applications: 0 #user-active-applications: 0 #queue-pending-applications: 0 #queue-active-applications: 0
2019-06-07 07:58:07,295 INFO org.apache.hadoop.yarn.server.resourcemanager.scheduler.capacity.LeafQueue: Application removed - appId: application_1559894241434_0001 user: root queue: default #user-pending-applications: 0 #user-active-applications: 0 #queue-pending-applications: 0 #queue-active-applications: 0
2019-06-07 07:58:07,295 DEBUG org.apache.hadoop.yarn.server.resourcemanager.rmnode.RMNodeImpl: Processing slave2:42768 of type FINISHED_CONTAINERS_PULLED_BY_AM
2019-06-07 07:58:07,295 DEBUG org.apache.hadoop.yarn.server.resourcemanager.rmnode.RMNodeImpl: Processing slave2:42768 of type FINISHED_CONTAINERS_PULLED_BY_AM
2019-06-07 07:58:07,295 DEBUG org.apache.hadoop.yarn.server.resourcemanager.rmnode.RMNodeImpl: Processing slave1:34830 of type CLEANUP_APP
2019-06-07 07:58:07,295 DEBUG org.apache.hadoop.yarn.server.resourcemanager.rmnode.RMNodeImpl: Processing slave1:34830 of type CLEANUP_APP
2019-06-07 07:58:07,295 DEBUG org.apache.hadoop.yarn.server.resourcemanager.rmnode.RMNodeImpl: Processing slave2:42768 of type CLEANUP_APP
2019-06-07 07:58:07,295 DEBUG org.apache.hadoop.yarn.server.resourcemanager.rmnode.RMNodeImpl: Processing slave2:42768 of type CLEANUP_APP
2019-06-07 07:58:07,295 DEBUG org.apache.hadoop.yarn.server.resourcemanager.RMAppManager: RMAppManager processing event for application_1559894241434_0001 of type APP_COMPLETED
2019-06-07 07:58:07,295 DEBUG org.apache.hadoop.yarn.server.resourcemanager.RMAppManager: RMAppManager processing event for application_1559894241434_0001 of type APP_COMPLETED
2019-06-07 07:58:07,296 INFO org.apache.hadoop.yarn.server.resourcemanager.amlauncher.AMLauncher: Cleaning master appattempt_1559894241434_0001_000001
2019-06-07 07:58:07,296 INFO org.apache.hadoop.yarn.server.resourcemanager.amlauncher.AMLauncher: Cleaning master appattempt_1559894241434_0001_000001
2019-06-07 07:58:07,296 INFO org.apache.hadoop.yarn.server.resourcemanager.scheduler.capacity.ParentQueue: Application removed - appId: application_1559894241434_0001 user: root leaf-queue of parent: root #applications: 0
2019-06-07 07:58:07,296 INFO org.apache.hadoop.yarn.server.resourcemanager.scheduler.capacity.ParentQueue: Application removed - appId: application_1559894241434_0001 user: root leaf-queue of parent: root #applications: 0
2019-06-07 07:58:07,297 INFO org.apache.hadoop.yarn.server.resourcemanager.RMAuditLogger: USER=root	OPERATION=Application Finished - Succeeded	TARGET=RMAppManager	RESULT=SUCCESS	APPID=application_1559894241434_0001
2019-06-07 07:58:07,297 INFO org.apache.hadoop.yarn.server.resourcemanager.RMAuditLogger: USER=root	OPERATION=Application Finished - Succeeded	TARGET=RMAppManager	RESULT=SUCCESS	APPID=application_1559894241434_0001
2019-06-07 07:58:07,298 DEBUG org.apache.hadoop.yarn.server.resourcemanager.scheduler.AbstractYarnScheduler: Request for appInfo of unknown attempt appattempt_1559894241434_0001_000001
2019-06-07 07:58:07,298 DEBUG org.apache.hadoop.yarn.server.resourcemanager.scheduler.AbstractYarnScheduler: Request for appInfo of unknown attempt appattempt_1559894241434_0001_000001
2019-06-07 07:58:07,299 INFO org.apache.hadoop.yarn.server.resourcemanager.RMAppManager$ApplicationSummary: appId=application_1559894241434_0001,name=SparkALS,user=root,queue=default,state=FINISHED,trackingUrl=http://master:8088/proxy/application_1559894241434_0001/,appMasterHost=172.17.0.4,startTime=1559894266458,finishTime=1559894286730,finalStatus=SUCCEEDED,memorySeconds=96664,vcoreSeconds=43,preemptedMemorySeconds=0,preemptedVcoreSeconds=0,preemptedAMContainers=0,preemptedNonAMContainers=0,preemptedResources=<memory:0\, vCores:0>,applicationType=SPARK
2019-06-07 07:58:07,753 DEBUG org.apache.hadoop.yarn.server.resourcemanager.rmnode.RMNodeImpl: Processing slave1:34830 of type STATUS_UPDATE
2019-06-07 07:58:07,753 DEBUG org.apache.hadoop.yarn.server.resourcemanager.rmnode.RMNodeImpl: Processing slave1:34830 of type STATUS_UPDATE
2019-06-07 07:58:07,754 DEBUG org.apache.hadoop.yarn.server.resourcemanager.scheduler.capacity.CapacityScheduler: nodeUpdate: slave1:34830 clusterResources: <memory:8192, vCores:2>
2019-06-07 07:58:07,754 DEBUG org.apache.hadoop.yarn.server.resourcemanager.scheduler.capacity.CapacityScheduler: nodeUpdate: slave1:34830 clusterResources: <memory:8192, vCores:2>
2019-06-07 07:58:07,762 DEBUG org.apache.hadoop.yarn.server.resourcemanager.scheduler.capacity.CapacityScheduler: Node being looked for scheduling slave1:34830 availableResource: <memory:4096, vCores:1>
2019-06-07 07:58:07,762 DEBUG org.apache.hadoop.yarn.server.resourcemanager.scheduler.capacity.CapacityScheduler: Node being looked for scheduling slave1:34830 availableResource: <memory:4096, vCores:1>
2019-06-07 07:58:07,762 DEBUG org.apache.hadoop.yarn.server.resourcemanager.scheduler.capacity.CapacityScheduler: Trying to schedule on node: slave1, available: <memory:4096, vCores:1>
2019-06-07 07:58:07,762 DEBUG org.apache.hadoop.yarn.server.resourcemanager.scheduler.capacity.CapacityScheduler: Trying to schedule on node: slave1, available: <memory:4096, vCores:1>
2019-06-07 07:58:07,762 DEBUG org.apache.hadoop.yarn.server.resourcemanager.scheduler.capacity.ParentQueue: Skip this queue=root, because it doesn't need more resource, schedulingMode=RESPECT_PARTITION_EXCLUSIVITY node-partition=
2019-06-07 07:58:07,762 DEBUG org.apache.hadoop.yarn.server.resourcemanager.scheduler.capacity.ParentQueue: Skip this queue=root, because it doesn't need more resource, schedulingMode=RESPECT_PARTITION_EXCLUSIVITY node-partition=
2019-06-07 07:58:08,301 DEBUG org.apache.hadoop.yarn.server.resourcemanager.rmnode.RMNodeImpl: Processing slave2:42768 of type STATUS_UPDATE
2019-06-07 07:58:08,301 DEBUG org.apache.hadoop.yarn.server.resourcemanager.rmnode.RMNodeImpl: Processing slave2:42768 of type STATUS_UPDATE
2019-06-07 07:58:08,301 DEBUG org.apache.hadoop.yarn.server.resourcemanager.scheduler.capacity.CapacityScheduler: nodeUpdate: slave2:42768 clusterResources: <memory:8192, vCores:2>
2019-06-07 07:58:08,301 DEBUG org.apache.hadoop.yarn.server.resourcemanager.scheduler.capacity.CapacityScheduler: nodeUpdate: slave2:42768 clusterResources: <memory:8192, vCores:2>
2019-06-07 07:58:08,301 DEBUG org.apache.hadoop.yarn.server.resourcemanager.scheduler.capacity.CapacityScheduler: Node being looked for scheduling slave2:42768 availableResource: <memory:4096, vCores:1>
2019-06-07 07:58:08,301 DEBUG org.apache.hadoop.yarn.server.resourcemanager.scheduler.capacity.CapacityScheduler: Node being looked for scheduling slave2:42768 availableResource: <memory:4096, vCores:1>
2019-06-07 07:58:08,301 DEBUG org.apache.hadoop.yarn.server.resourcemanager.scheduler.capacity.CapacityScheduler: Trying to schedule on node: slave2, available: <memory:4096, vCores:1>
2019-06-07 07:58:08,301 DEBUG org.apache.hadoop.yarn.server.resourcemanager.scheduler.capacity.CapacityScheduler: Trying to schedule on node: slave2, available: <memory:4096, vCores:1>
2019-06-07 07:58:08,301 DEBUG org.apache.hadoop.yarn.server.resourcemanager.scheduler.capacity.ParentQueue: Skip this queue=root, because it doesn't need more resource, schedulingMode=RESPECT_PARTITION_EXCLUSIVITY node-partition=
2019-06-07 07:58:08,301 DEBUG org.apache.hadoop.yarn.server.resourcemanager.scheduler.capacity.ParentQueue: Skip this queue=root, because it doesn't need more resource, schedulingMode=RESPECT_PARTITION_EXCLUSIVITY node-partition=
2019-06-07 07:58:08,761 DEBUG org.apache.hadoop.yarn.server.resourcemanager.rmnode.RMNodeImpl: Processing slave1:34830 of type STATUS_UPDATE
2019-06-07 07:58:08,761 DEBUG org.apache.hadoop.yarn.server.resourcemanager.rmnode.RMNodeImpl: Processing slave1:34830 of type STATUS_UPDATE
2019-06-07 07:58:08,761 DEBUG org.apache.hadoop.yarn.server.resourcemanager.rmnode.RMNodeImpl: Container container_1559894241434_0001_01_000002 is the first container get launched for application application_1559894241434_0001
2019-06-07 07:58:08,761 DEBUG org.apache.hadoop.yarn.server.resourcemanager.rmnode.RMNodeImpl: Container container_1559894241434_0001_01_000002 is the first container get launched for application application_1559894241434_0001
2019-06-07 07:58:08,761 DEBUG org.apache.hadoop.yarn.server.resourcemanager.rmapp.RMAppImpl: Processing event for application_1559894241434_0001 of type APP_RUNNING_ON_NODE
2019-06-07 07:58:08,761 DEBUG org.apache.hadoop.yarn.server.resourcemanager.rmapp.RMAppImpl: Processing event for application_1559894241434_0001 of type APP_RUNNING_ON_NODE
2019-06-07 07:58:08,761 DEBUG org.apache.hadoop.yarn.server.resourcemanager.rmnode.RMNodeImpl: Processing slave1:34830 of type CLEANUP_APP
2019-06-07 07:58:08,761 DEBUG org.apache.hadoop.yarn.server.resourcemanager.rmnode.RMNodeImpl: Processing slave1:34830 of type CLEANUP_APP
2019-06-07 07:58:08,761 DEBUG org.apache.hadoop.yarn.server.resourcemanager.scheduler.capacity.CapacityScheduler: nodeUpdate: slave1:34830 clusterResources: <memory:8192, vCores:2>
2019-06-07 07:58:08,761 DEBUG org.apache.hadoop.yarn.server.resourcemanager.scheduler.capacity.CapacityScheduler: nodeUpdate: slave1:34830 clusterResources: <memory:8192, vCores:2>
2019-06-07 07:58:08,762 INFO org.apache.hadoop.yarn.server.resourcemanager.scheduler.AbstractYarnScheduler: Container container_1559894241434_0001_01_000002 completed with event FINISHED, but corresponding RMContainer doesn't exist.
2019-06-07 07:58:08,762 INFO org.apache.hadoop.yarn.server.resourcemanager.scheduler.AbstractYarnScheduler: Container container_1559894241434_0001_01_000002 completed with event FINISHED, but corresponding RMContainer doesn't exist.
2019-06-07 07:58:08,762 DEBUG org.apache.hadoop.yarn.server.resourcemanager.scheduler.capacity.CapacityScheduler: Node being looked for scheduling slave1:34830 availableResource: <memory:4096, vCores:1>
2019-06-07 07:58:08,762 DEBUG org.apache.hadoop.yarn.server.resourcemanager.scheduler.capacity.CapacityScheduler: Node being looked for scheduling slave1:34830 availableResource: <memory:4096, vCores:1>
2019-06-07 07:58:08,762 DEBUG org.apache.hadoop.yarn.server.resourcemanager.scheduler.capacity.CapacityScheduler: Trying to schedule on node: slave1, available: <memory:4096, vCores:1>
2019-06-07 07:58:08,762 DEBUG org.apache.hadoop.yarn.server.resourcemanager.scheduler.capacity.CapacityScheduler: Trying to schedule on node: slave1, available: <memory:4096, vCores:1>
2019-06-07 07:58:08,762 DEBUG org.apache.hadoop.yarn.server.resourcemanager.scheduler.capacity.ParentQueue: Skip this queue=root, because it doesn't need more resource, schedulingMode=RESPECT_PARTITION_EXCLUSIVITY node-partition=
2019-06-07 07:58:08,762 DEBUG org.apache.hadoop.yarn.server.resourcemanager.scheduler.capacity.ParentQueue: Skip this queue=root, because it doesn't need more resource, schedulingMode=RESPECT_PARTITION_EXCLUSIVITY node-partition=
2019-06-07 07:58:09,312 DEBUG org.apache.hadoop.yarn.server.resourcemanager.rmnode.RMNodeImpl: Processing slave2:42768 of type STATUS_UPDATE
2019-06-07 07:58:09,312 DEBUG org.apache.hadoop.yarn.server.resourcemanager.rmnode.RMNodeImpl: Processing slave2:42768 of type STATUS_UPDATE
2019-06-07 07:58:09,313 DEBUG org.apache.hadoop.yarn.server.resourcemanager.rmnode.RMNodeImpl: Container container_1559894241434_0001_01_000003 is the first container get launched for application application_1559894241434_0001
2019-06-07 07:58:09,313 DEBUG org.apache.hadoop.yarn.server.resourcemanager.rmnode.RMNodeImpl: Container container_1559894241434_0001_01_000003 is the first container get launched for application application_1559894241434_0001
2019-06-07 07:58:09,313 DEBUG org.apache.hadoop.yarn.server.resourcemanager.rmapp.RMAppImpl: Processing event for application_1559894241434_0001 of type APP_RUNNING_ON_NODE
2019-06-07 07:58:09,313 DEBUG org.apache.hadoop.yarn.server.resourcemanager.rmapp.RMAppImpl: Processing event for application_1559894241434_0001 of type APP_RUNNING_ON_NODE
2019-06-07 07:58:09,313 DEBUG org.apache.hadoop.yarn.server.resourcemanager.rmnode.RMNodeImpl: Processing slave2:42768 of type CLEANUP_APP
2019-06-07 07:58:09,313 DEBUG org.apache.hadoop.yarn.server.resourcemanager.rmnode.RMNodeImpl: Processing slave2:42768 of type CLEANUP_APP
2019-06-07 07:58:09,313 DEBUG org.apache.hadoop.yarn.server.resourcemanager.scheduler.capacity.CapacityScheduler: nodeUpdate: slave2:42768 clusterResources: <memory:8192, vCores:2>
2019-06-07 07:58:09,313 DEBUG org.apache.hadoop.yarn.server.resourcemanager.scheduler.capacity.CapacityScheduler: nodeUpdate: slave2:42768 clusterResources: <memory:8192, vCores:2>
2019-06-07 07:58:09,315 INFO org.apache.hadoop.yarn.server.resourcemanager.scheduler.AbstractYarnScheduler: Container container_1559894241434_0001_01_000003 completed with event FINISHED, but corresponding RMContainer doesn't exist.
2019-06-07 07:58:09,315 INFO org.apache.hadoop.yarn.server.resourcemanager.scheduler.AbstractYarnScheduler: Container container_1559894241434_0001_01_000003 completed with event FINISHED, but corresponding RMContainer doesn't exist.
2019-06-07 07:58:09,315 DEBUG org.apache.hadoop.yarn.server.resourcemanager.scheduler.capacity.CapacityScheduler: Node being looked for scheduling slave2:42768 availableResource: <memory:4096, vCores:1>
2019-06-07 07:58:09,315 DEBUG org.apache.hadoop.yarn.server.resourcemanager.scheduler.capacity.CapacityScheduler: Node being looked for scheduling slave2:42768 availableResource: <memory:4096, vCores:1>
2019-06-07 07:58:09,315 DEBUG org.apache.hadoop.yarn.server.resourcemanager.scheduler.capacity.CapacityScheduler: Trying to schedule on node: slave2, available: <memory:4096, vCores:1>
2019-06-07 07:58:09,315 DEBUG org.apache.hadoop.yarn.server.resourcemanager.scheduler.capacity.CapacityScheduler: Trying to schedule on node: slave2, available: <memory:4096, vCores:1>
2019-06-07 07:58:09,315 DEBUG org.apache.hadoop.yarn.server.resourcemanager.scheduler.capacity.ParentQueue: Skip this queue=root, because it doesn't need more resource, schedulingMode=RESPECT_PARTITION_EXCLUSIVITY node-partition=
2019-06-07 07:58:09,315 DEBUG org.apache.hadoop.yarn.server.resourcemanager.scheduler.capacity.ParentQueue: Skip this queue=root, because it doesn't need more resource, schedulingMode=RESPECT_PARTITION_EXCLUSIVITY node-partition=
2019-06-07 07:58:09,765 DEBUG org.apache.hadoop.yarn.server.resourcemanager.rmnode.RMNodeImpl: Processing slave1:34830 of type STATUS_UPDATE
2019-06-07 07:58:09,765 DEBUG org.apache.hadoop.yarn.server.resourcemanager.rmnode.RMNodeImpl: Processing slave1:34830 of type STATUS_UPDATE
2019-06-07 07:58:09,766 DEBUG org.apache.hadoop.yarn.server.resourcemanager.scheduler.capacity.CapacityScheduler: nodeUpdate: slave1:34830 clusterResources: <memory:8192, vCores:2>
2019-06-07 07:58:09,766 DEBUG org.apache.hadoop.yarn.server.resourcemanager.scheduler.capacity.CapacityScheduler: nodeUpdate: slave1:34830 clusterResources: <memory:8192, vCores:2>
2019-06-07 07:58:09,766 DEBUG org.apache.hadoop.yarn.server.resourcemanager.scheduler.capacity.CapacityScheduler: Node being looked for scheduling slave1:34830 availableResource: <memory:4096, vCores:1>
2019-06-07 07:58:09,766 DEBUG org.apache.hadoop.yarn.server.resourcemanager.scheduler.capacity.CapacityScheduler: Node being looked for scheduling slave1:34830 availableResource: <memory:4096, vCores:1>
2019-06-07 07:58:09,766 DEBUG org.apache.hadoop.yarn.server.resourcemanager.scheduler.capacity.CapacityScheduler: Trying to schedule on node: slave1, available: <memory:4096, vCores:1>
2019-06-07 07:58:09,766 DEBUG org.apache.hadoop.yarn.server.resourcemanager.scheduler.capacity.CapacityScheduler: Trying to schedule on node: slave1, available: <memory:4096, vCores:1>
2019-06-07 07:58:09,766 DEBUG org.apache.hadoop.yarn.server.resourcemanager.scheduler.capacity.ParentQueue: Skip this queue=root, because it doesn't need more resource, schedulingMode=RESPECT_PARTITION_EXCLUSIVITY node-partition=
2019-06-07 07:58:09,766 DEBUG org.apache.hadoop.yarn.server.resourcemanager.scheduler.capacity.ParentQueue: Skip this queue=root, because it doesn't need more resource, schedulingMode=RESPECT_PARTITION_EXCLUSIVITY node-partition=
2019-06-07 07:58:10,316 DEBUG org.apache.hadoop.yarn.server.resourcemanager.rmnode.RMNodeImpl: Processing slave2:42768 of type STATUS_UPDATE
2019-06-07 07:58:10,316 DEBUG org.apache.hadoop.yarn.server.resourcemanager.rmnode.RMNodeImpl: Processing slave2:42768 of type STATUS_UPDATE
2019-06-07 07:58:10,316 DEBUG org.apache.hadoop.yarn.server.resourcemanager.scheduler.capacity.CapacityScheduler: nodeUpdate: slave2:42768 clusterResources: <memory:8192, vCores:2>
2019-06-07 07:58:10,316 DEBUG org.apache.hadoop.yarn.server.resourcemanager.scheduler.capacity.CapacityScheduler: nodeUpdate: slave2:42768 clusterResources: <memory:8192, vCores:2>
2019-06-07 07:58:10,316 DEBUG org.apache.hadoop.yarn.server.resourcemanager.scheduler.capacity.CapacityScheduler: Node being looked for scheduling slave2:42768 availableResource: <memory:4096, vCores:1>
2019-06-07 07:58:10,316 DEBUG org.apache.hadoop.yarn.server.resourcemanager.scheduler.capacity.CapacityScheduler: Node being looked for scheduling slave2:42768 availableResource: <memory:4096, vCores:1>
2019-06-07 07:58:10,316 DEBUG org.apache.hadoop.yarn.server.resourcemanager.scheduler.capacity.CapacityScheduler: Trying to schedule on node: slave2, available: <memory:4096, vCores:1>
2019-06-07 07:58:10,316 DEBUG org.apache.hadoop.yarn.server.resourcemanager.scheduler.capacity.CapacityScheduler: Trying to schedule on node: slave2, available: <memory:4096, vCores:1>
2019-06-07 07:58:10,316 DEBUG org.apache.hadoop.yarn.server.resourcemanager.scheduler.capacity.ParentQueue: Skip this queue=root, because it doesn't need more resource, schedulingMode=RESPECT_PARTITION_EXCLUSIVITY node-partition=
2019-06-07 07:58:10,316 DEBUG org.apache.hadoop.yarn.server.resourcemanager.scheduler.capacity.ParentQueue: Skip this queue=root, because it doesn't need more resource, schedulingMode=RESPECT_PARTITION_EXCLUSIVITY node-partition=
2019-06-07 07:58:10,769 DEBUG org.apache.hadoop.yarn.server.resourcemanager.rmnode.RMNodeImpl: Processing slave1:34830 of type STATUS_UPDATE
2019-06-07 07:58:10,769 DEBUG org.apache.hadoop.yarn.server.resourcemanager.rmnode.RMNodeImpl: Processing slave1:34830 of type STATUS_UPDATE
2019-06-07 07:58:10,769 DEBUG org.apache.hadoop.yarn.server.resourcemanager.scheduler.capacity.CapacityScheduler: nodeUpdate: slave1:34830 clusterResources: <memory:8192, vCores:2>
2019-06-07 07:58:10,769 DEBUG org.apache.hadoop.yarn.server.resourcemanager.scheduler.capacity.CapacityScheduler: nodeUpdate: slave1:34830 clusterResources: <memory:8192, vCores:2>
2019-06-07 07:58:10,769 DEBUG org.apache.hadoop.yarn.server.resourcemanager.scheduler.capacity.CapacityScheduler: Node being looked for scheduling slave1:34830 availableResource: <memory:4096, vCores:1>
2019-06-07 07:58:10,769 DEBUG org.apache.hadoop.yarn.server.resourcemanager.scheduler.capacity.CapacityScheduler: Node being looked for scheduling slave1:34830 availableResource: <memory:4096, vCores:1>
2019-06-07 07:58:10,769 DEBUG org.apache.hadoop.yarn.server.resourcemanager.scheduler.capacity.CapacityScheduler: Trying to schedule on node: slave1, available: <memory:4096, vCores:1>
2019-06-07 07:58:10,769 DEBUG org.apache.hadoop.yarn.server.resourcemanager.scheduler.capacity.CapacityScheduler: Trying to schedule on node: slave1, available: <memory:4096, vCores:1>
2019-06-07 07:58:10,769 DEBUG org.apache.hadoop.yarn.server.resourcemanager.scheduler.capacity.ParentQueue: Skip this queue=root, because it doesn't need more resource, schedulingMode=RESPECT_PARTITION_EXCLUSIVITY node-partition=
2019-06-07 07:58:10,769 DEBUG org.apache.hadoop.yarn.server.resourcemanager.scheduler.capacity.ParentQueue: Skip this queue=root, because it doesn't need more resource, schedulingMode=RESPECT_PARTITION_EXCLUSIVITY node-partition=
2019-06-07 07:58:11,321 DEBUG org.apache.hadoop.yarn.server.resourcemanager.rmnode.RMNodeImpl: Processing slave2:42768 of type STATUS_UPDATE
2019-06-07 07:58:11,321 DEBUG org.apache.hadoop.yarn.server.resourcemanager.rmnode.RMNodeImpl: Processing slave2:42768 of type STATUS_UPDATE
2019-06-07 07:58:11,322 DEBUG org.apache.hadoop.yarn.server.resourcemanager.scheduler.capacity.CapacityScheduler: nodeUpdate: slave2:42768 clusterResources: <memory:8192, vCores:2>
2019-06-07 07:58:11,322 DEBUG org.apache.hadoop.yarn.server.resourcemanager.scheduler.capacity.CapacityScheduler: nodeUpdate: slave2:42768 clusterResources: <memory:8192, vCores:2>
2019-06-07 07:58:11,322 DEBUG org.apache.hadoop.yarn.server.resourcemanager.scheduler.capacity.CapacityScheduler: Node being looked for scheduling slave2:42768 availableResource: <memory:4096, vCores:1>
2019-06-07 07:58:11,322 DEBUG org.apache.hadoop.yarn.server.resourcemanager.scheduler.capacity.CapacityScheduler: Node being looked for scheduling slave2:42768 availableResource: <memory:4096, vCores:1>
2019-06-07 07:58:11,322 DEBUG org.apache.hadoop.yarn.server.resourcemanager.scheduler.capacity.CapacityScheduler: Trying to schedule on node: slave2, available: <memory:4096, vCores:1>
2019-06-07 07:58:11,322 DEBUG org.apache.hadoop.yarn.server.resourcemanager.scheduler.capacity.CapacityScheduler: Trying to schedule on node: slave2, available: <memory:4096, vCores:1>
2019-06-07 07:58:11,322 DEBUG org.apache.hadoop.yarn.server.resourcemanager.scheduler.capacity.ParentQueue: Skip this queue=root, because it doesn't need more resource, schedulingMode=RESPECT_PARTITION_EXCLUSIVITY node-partition=
2019-06-07 07:58:11,322 DEBUG org.apache.hadoop.yarn.server.resourcemanager.scheduler.capacity.ParentQueue: Skip this queue=root, because it doesn't need more resource, schedulingMode=RESPECT_PARTITION_EXCLUSIVITY node-partition=
2019-06-07 07:58:11,773 DEBUG org.apache.hadoop.yarn.server.resourcemanager.rmnode.RMNodeImpl: Processing slave1:34830 of type STATUS_UPDATE
2019-06-07 07:58:11,773 DEBUG org.apache.hadoop.yarn.server.resourcemanager.rmnode.RMNodeImpl: Processing slave1:34830 of type STATUS_UPDATE
2019-06-07 07:58:11,773 DEBUG org.apache.hadoop.yarn.server.resourcemanager.scheduler.capacity.CapacityScheduler: nodeUpdate: slave1:34830 clusterResources: <memory:8192, vCores:2>
2019-06-07 07:58:11,773 DEBUG org.apache.hadoop.yarn.server.resourcemanager.scheduler.capacity.CapacityScheduler: nodeUpdate: slave1:34830 clusterResources: <memory:8192, vCores:2>
2019-06-07 07:58:11,773 DEBUG org.apache.hadoop.yarn.server.resourcemanager.scheduler.capacity.CapacityScheduler: Node being looked for scheduling slave1:34830 availableResource: <memory:4096, vCores:1>
2019-06-07 07:58:11,773 DEBUG org.apache.hadoop.yarn.server.resourcemanager.scheduler.capacity.CapacityScheduler: Node being looked for scheduling slave1:34830 availableResource: <memory:4096, vCores:1>
2019-06-07 07:58:11,773 DEBUG org.apache.hadoop.yarn.server.resourcemanager.scheduler.capacity.CapacityScheduler: Trying to schedule on node: slave1, available: <memory:4096, vCores:1>
2019-06-07 07:58:11,773 DEBUG org.apache.hadoop.yarn.server.resourcemanager.scheduler.capacity.CapacityScheduler: Trying to schedule on node: slave1, available: <memory:4096, vCores:1>
2019-06-07 07:58:11,774 DEBUG org.apache.hadoop.yarn.server.resourcemanager.scheduler.capacity.ParentQueue: Skip this queue=root, because it doesn't need more resource, schedulingMode=RESPECT_PARTITION_EXCLUSIVITY node-partition=
2019-06-07 07:58:11,774 DEBUG org.apache.hadoop.yarn.server.resourcemanager.scheduler.capacity.ParentQueue: Skip this queue=root, because it doesn't need more resource, schedulingMode=RESPECT_PARTITION_EXCLUSIVITY node-partition=
2019-06-07 07:58:12,325 DEBUG org.apache.hadoop.yarn.server.resourcemanager.rmnode.RMNodeImpl: Processing slave2:42768 of type STATUS_UPDATE
2019-06-07 07:58:12,325 DEBUG org.apache.hadoop.yarn.server.resourcemanager.rmnode.RMNodeImpl: Processing slave2:42768 of type STATUS_UPDATE
2019-06-07 07:58:12,325 DEBUG org.apache.hadoop.yarn.server.resourcemanager.scheduler.capacity.CapacityScheduler: nodeUpdate: slave2:42768 clusterResources: <memory:8192, vCores:2>
2019-06-07 07:58:12,325 DEBUG org.apache.hadoop.yarn.server.resourcemanager.scheduler.capacity.CapacityScheduler: nodeUpdate: slave2:42768 clusterResources: <memory:8192, vCores:2>
2019-06-07 07:58:12,325 DEBUG org.apache.hadoop.yarn.server.resourcemanager.scheduler.capacity.CapacityScheduler: Node being looked for scheduling slave2:42768 availableResource: <memory:4096, vCores:1>
2019-06-07 07:58:12,325 DEBUG org.apache.hadoop.yarn.server.resourcemanager.scheduler.capacity.CapacityScheduler: Node being looked for scheduling slave2:42768 availableResource: <memory:4096, vCores:1>
2019-06-07 07:58:12,325 DEBUG org.apache.hadoop.yarn.server.resourcemanager.scheduler.capacity.CapacityScheduler: Trying to schedule on node: slave2, available: <memory:4096, vCores:1>
2019-06-07 07:58:12,325 DEBUG org.apache.hadoop.yarn.server.resourcemanager.scheduler.capacity.CapacityScheduler: Trying to schedule on node: slave2, available: <memory:4096, vCores:1>
2019-06-07 07:58:12,325 DEBUG org.apache.hadoop.yarn.server.resourcemanager.scheduler.capacity.ParentQueue: Skip this queue=root, because it doesn't need more resource, schedulingMode=RESPECT_PARTITION_EXCLUSIVITY node-partition=
2019-06-07 07:58:12,325 DEBUG org.apache.hadoop.yarn.server.resourcemanager.scheduler.capacity.ParentQueue: Skip this queue=root, because it doesn't need more resource, schedulingMode=RESPECT_PARTITION_EXCLUSIVITY node-partition=
2019-06-07 07:58:12,775 DEBUG org.apache.hadoop.yarn.server.resourcemanager.rmnode.RMNodeImpl: Processing slave1:34830 of type STATUS_UPDATE
2019-06-07 07:58:12,775 DEBUG org.apache.hadoop.yarn.server.resourcemanager.rmnode.RMNodeImpl: Processing slave1:34830 of type STATUS_UPDATE
2019-06-07 07:58:12,776 DEBUG org.apache.hadoop.yarn.server.resourcemanager.scheduler.capacity.CapacityScheduler: nodeUpdate: slave1:34830 clusterResources: <memory:8192, vCores:2>
2019-06-07 07:58:12,776 DEBUG org.apache.hadoop.yarn.server.resourcemanager.scheduler.capacity.CapacityScheduler: nodeUpdate: slave1:34830 clusterResources: <memory:8192, vCores:2>
2019-06-07 07:58:12,776 DEBUG org.apache.hadoop.yarn.server.resourcemanager.scheduler.capacity.CapacityScheduler: Node being looked for scheduling slave1:34830 availableResource: <memory:4096, vCores:1>
2019-06-07 07:58:12,776 DEBUG org.apache.hadoop.yarn.server.resourcemanager.scheduler.capacity.CapacityScheduler: Node being looked for scheduling slave1:34830 availableResource: <memory:4096, vCores:1>
2019-06-07 07:58:12,776 DEBUG org.apache.hadoop.yarn.server.resourcemanager.scheduler.capacity.CapacityScheduler: Trying to schedule on node: slave1, available: <memory:4096, vCores:1>
2019-06-07 07:58:12,776 DEBUG org.apache.hadoop.yarn.server.resourcemanager.scheduler.capacity.CapacityScheduler: Trying to schedule on node: slave1, available: <memory:4096, vCores:1>
2019-06-07 07:58:12,776 DEBUG org.apache.hadoop.yarn.server.resourcemanager.scheduler.capacity.ParentQueue: Skip this queue=root, because it doesn't need more resource, schedulingMode=RESPECT_PARTITION_EXCLUSIVITY node-partition=
2019-06-07 07:58:12,776 DEBUG org.apache.hadoop.yarn.server.resourcemanager.scheduler.capacity.ParentQueue: Skip this queue=root, because it doesn't need more resource, schedulingMode=RESPECT_PARTITION_EXCLUSIVITY node-partition=
2019-06-07 07:58:13,330 DEBUG org.apache.hadoop.yarn.server.resourcemanager.rmnode.RMNodeImpl: Processing slave2:42768 of type STATUS_UPDATE
2019-06-07 07:58:13,330 DEBUG org.apache.hadoop.yarn.server.resourcemanager.rmnode.RMNodeImpl: Processing slave2:42768 of type STATUS_UPDATE
2019-06-07 07:58:13,330 DEBUG org.apache.hadoop.yarn.server.resourcemanager.scheduler.capacity.CapacityScheduler: nodeUpdate: slave2:42768 clusterResources: <memory:8192, vCores:2>
2019-06-07 07:58:13,330 DEBUG org.apache.hadoop.yarn.server.resourcemanager.scheduler.capacity.CapacityScheduler: nodeUpdate: slave2:42768 clusterResources: <memory:8192, vCores:2>
2019-06-07 07:58:13,330 DEBUG org.apache.hadoop.yarn.server.resourcemanager.scheduler.capacity.CapacityScheduler: Node being looked for scheduling slave2:42768 availableResource: <memory:4096, vCores:1>
2019-06-07 07:58:13,330 DEBUG org.apache.hadoop.yarn.server.resourcemanager.scheduler.capacity.CapacityScheduler: Node being looked for scheduling slave2:42768 availableResource: <memory:4096, vCores:1>
2019-06-07 07:58:13,330 DEBUG org.apache.hadoop.yarn.server.resourcemanager.scheduler.capacity.CapacityScheduler: Trying to schedule on node: slave2, available: <memory:4096, vCores:1>
2019-06-07 07:58:13,330 DEBUG org.apache.hadoop.yarn.server.resourcemanager.scheduler.capacity.CapacityScheduler: Trying to schedule on node: slave2, available: <memory:4096, vCores:1>
2019-06-07 07:58:13,330 DEBUG org.apache.hadoop.yarn.server.resourcemanager.scheduler.capacity.ParentQueue: Skip this queue=root, because it doesn't need more resource, schedulingMode=RESPECT_PARTITION_EXCLUSIVITY node-partition=
2019-06-07 07:58:13,330 DEBUG org.apache.hadoop.yarn.server.resourcemanager.scheduler.capacity.ParentQueue: Skip this queue=root, because it doesn't need more resource, schedulingMode=RESPECT_PARTITION_EXCLUSIVITY node-partition=
2019-06-07 07:58:13,779 DEBUG org.apache.hadoop.yarn.server.resourcemanager.rmnode.RMNodeImpl: Processing slave1:34830 of type STATUS_UPDATE
2019-06-07 07:58:13,779 DEBUG org.apache.hadoop.yarn.server.resourcemanager.rmnode.RMNodeImpl: Processing slave1:34830 of type STATUS_UPDATE
2019-06-07 07:58:13,779 DEBUG org.apache.hadoop.yarn.server.resourcemanager.scheduler.capacity.CapacityScheduler: nodeUpdate: slave1:34830 clusterResources: <memory:8192, vCores:2>
2019-06-07 07:58:13,779 DEBUG org.apache.hadoop.yarn.server.resourcemanager.scheduler.capacity.CapacityScheduler: nodeUpdate: slave1:34830 clusterResources: <memory:8192, vCores:2>
2019-06-07 07:58:13,779 DEBUG org.apache.hadoop.yarn.server.resourcemanager.scheduler.capacity.CapacityScheduler: Node being looked for scheduling slave1:34830 availableResource: <memory:4096, vCores:1>
2019-06-07 07:58:13,779 DEBUG org.apache.hadoop.yarn.server.resourcemanager.scheduler.capacity.CapacityScheduler: Node being looked for scheduling slave1:34830 availableResource: <memory:4096, vCores:1>
2019-06-07 07:58:13,779 DEBUG org.apache.hadoop.yarn.server.resourcemanager.scheduler.capacity.CapacityScheduler: Trying to schedule on node: slave1, available: <memory:4096, vCores:1>
2019-06-07 07:58:13,779 DEBUG org.apache.hadoop.yarn.server.resourcemanager.scheduler.capacity.CapacityScheduler: Trying to schedule on node: slave1, available: <memory:4096, vCores:1>
2019-06-07 07:58:13,779 DEBUG org.apache.hadoop.yarn.server.resourcemanager.scheduler.capacity.ParentQueue: Skip this queue=root, because it doesn't need more resource, schedulingMode=RESPECT_PARTITION_EXCLUSIVITY node-partition=
2019-06-07 07:58:13,779 DEBUG org.apache.hadoop.yarn.server.resourcemanager.scheduler.capacity.ParentQueue: Skip this queue=root, because it doesn't need more resource, schedulingMode=RESPECT_PARTITION_EXCLUSIVITY node-partition=
2019-06-07 07:58:14,333 DEBUG org.apache.hadoop.yarn.server.resourcemanager.rmnode.RMNodeImpl: Processing slave2:42768 of type STATUS_UPDATE
2019-06-07 07:58:14,333 DEBUG org.apache.hadoop.yarn.server.resourcemanager.rmnode.RMNodeImpl: Processing slave2:42768 of type STATUS_UPDATE
2019-06-07 07:58:14,334 DEBUG org.apache.hadoop.yarn.server.resourcemanager.scheduler.capacity.CapacityScheduler: nodeUpdate: slave2:42768 clusterResources: <memory:8192, vCores:2>
2019-06-07 07:58:14,334 DEBUG org.apache.hadoop.yarn.server.resourcemanager.scheduler.capacity.CapacityScheduler: nodeUpdate: slave2:42768 clusterResources: <memory:8192, vCores:2>
2019-06-07 07:58:14,334 DEBUG org.apache.hadoop.yarn.server.resourcemanager.scheduler.capacity.CapacityScheduler: Node being looked for scheduling slave2:42768 availableResource: <memory:4096, vCores:1>
2019-06-07 07:58:14,334 DEBUG org.apache.hadoop.yarn.server.resourcemanager.scheduler.capacity.CapacityScheduler: Node being looked for scheduling slave2:42768 availableResource: <memory:4096, vCores:1>
2019-06-07 07:58:14,334 DEBUG org.apache.hadoop.yarn.server.resourcemanager.scheduler.capacity.CapacityScheduler: Trying to schedule on node: slave2, available: <memory:4096, vCores:1>
2019-06-07 07:58:14,334 DEBUG org.apache.hadoop.yarn.server.resourcemanager.scheduler.capacity.CapacityScheduler: Trying to schedule on node: slave2, available: <memory:4096, vCores:1>
2019-06-07 07:58:14,334 DEBUG org.apache.hadoop.yarn.server.resourcemanager.scheduler.capacity.ParentQueue: Skip this queue=root, because it doesn't need more resource, schedulingMode=RESPECT_PARTITION_EXCLUSIVITY node-partition=
2019-06-07 07:58:14,334 DEBUG org.apache.hadoop.yarn.server.resourcemanager.scheduler.capacity.ParentQueue: Skip this queue=root, because it doesn't need more resource, schedulingMode=RESPECT_PARTITION_EXCLUSIVITY node-partition=
2019-06-07 07:58:14,784 DEBUG org.apache.hadoop.yarn.server.resourcemanager.rmnode.RMNodeImpl: Processing slave1:34830 of type STATUS_UPDATE
2019-06-07 07:58:14,784 DEBUG org.apache.hadoop.yarn.server.resourcemanager.rmnode.RMNodeImpl: Processing slave1:34830 of type STATUS_UPDATE
2019-06-07 07:58:14,784 DEBUG org.apache.hadoop.yarn.server.resourcemanager.scheduler.capacity.CapacityScheduler: nodeUpdate: slave1:34830 clusterResources: <memory:8192, vCores:2>
2019-06-07 07:58:14,784 DEBUG org.apache.hadoop.yarn.server.resourcemanager.scheduler.capacity.CapacityScheduler: nodeUpdate: slave1:34830 clusterResources: <memory:8192, vCores:2>
2019-06-07 07:58:14,784 DEBUG org.apache.hadoop.yarn.server.resourcemanager.scheduler.capacity.CapacityScheduler: Node being looked for scheduling slave1:34830 availableResource: <memory:4096, vCores:1>
2019-06-07 07:58:14,784 DEBUG org.apache.hadoop.yarn.server.resourcemanager.scheduler.capacity.CapacityScheduler: Node being looked for scheduling slave1:34830 availableResource: <memory:4096, vCores:1>
2019-06-07 07:58:14,784 DEBUG org.apache.hadoop.yarn.server.resourcemanager.scheduler.capacity.CapacityScheduler: Trying to schedule on node: slave1, available: <memory:4096, vCores:1>
2019-06-07 07:58:14,784 DEBUG org.apache.hadoop.yarn.server.resourcemanager.scheduler.capacity.CapacityScheduler: Trying to schedule on node: slave1, available: <memory:4096, vCores:1>
2019-06-07 07:58:14,784 DEBUG org.apache.hadoop.yarn.server.resourcemanager.scheduler.capacity.ParentQueue: Skip this queue=root, because it doesn't need more resource, schedulingMode=RESPECT_PARTITION_EXCLUSIVITY node-partition=
2019-06-07 07:58:14,784 DEBUG org.apache.hadoop.yarn.server.resourcemanager.scheduler.capacity.ParentQueue: Skip this queue=root, because it doesn't need more resource, schedulingMode=RESPECT_PARTITION_EXCLUSIVITY node-partition=
2019-06-07 07:58:15,338 DEBUG org.apache.hadoop.yarn.server.resourcemanager.rmnode.RMNodeImpl: Processing slave2:42768 of type STATUS_UPDATE
2019-06-07 07:58:15,338 DEBUG org.apache.hadoop.yarn.server.resourcemanager.rmnode.RMNodeImpl: Processing slave2:42768 of type STATUS_UPDATE
2019-06-07 07:58:15,340 DEBUG org.apache.hadoop.yarn.server.resourcemanager.scheduler.capacity.CapacityScheduler: nodeUpdate: slave2:42768 clusterResources: <memory:8192, vCores:2>
2019-06-07 07:58:15,340 DEBUG org.apache.hadoop.yarn.server.resourcemanager.scheduler.capacity.CapacityScheduler: nodeUpdate: slave2:42768 clusterResources: <memory:8192, vCores:2>
2019-06-07 07:58:15,340 DEBUG org.apache.hadoop.yarn.server.resourcemanager.scheduler.capacity.CapacityScheduler: Node being looked for scheduling slave2:42768 availableResource: <memory:4096, vCores:1>
2019-06-07 07:58:15,340 DEBUG org.apache.hadoop.yarn.server.resourcemanager.scheduler.capacity.CapacityScheduler: Node being looked for scheduling slave2:42768 availableResource: <memory:4096, vCores:1>
2019-06-07 07:58:15,340 DEBUG org.apache.hadoop.yarn.server.resourcemanager.scheduler.capacity.CapacityScheduler: Trying to schedule on node: slave2, available: <memory:4096, vCores:1>
2019-06-07 07:58:15,340 DEBUG org.apache.hadoop.yarn.server.resourcemanager.scheduler.capacity.CapacityScheduler: Trying to schedule on node: slave2, available: <memory:4096, vCores:1>
2019-06-07 07:58:15,340 DEBUG org.apache.hadoop.yarn.server.resourcemanager.scheduler.capacity.ParentQueue: Skip this queue=root, because it doesn't need more resource, schedulingMode=RESPECT_PARTITION_EXCLUSIVITY node-partition=
2019-06-07 07:58:15,340 DEBUG org.apache.hadoop.yarn.server.resourcemanager.scheduler.capacity.ParentQueue: Skip this queue=root, because it doesn't need more resource, schedulingMode=RESPECT_PARTITION_EXCLUSIVITY node-partition=
2019-06-07 07:58:15,788 DEBUG org.apache.hadoop.yarn.server.resourcemanager.rmnode.RMNodeImpl: Processing slave1:34830 of type STATUS_UPDATE
2019-06-07 07:58:15,788 DEBUG org.apache.hadoop.yarn.server.resourcemanager.rmnode.RMNodeImpl: Processing slave1:34830 of type STATUS_UPDATE
2019-06-07 07:58:15,789 DEBUG org.apache.hadoop.yarn.server.resourcemanager.scheduler.capacity.CapacityScheduler: nodeUpdate: slave1:34830 clusterResources: <memory:8192, vCores:2>
2019-06-07 07:58:15,789 DEBUG org.apache.hadoop.yarn.server.resourcemanager.scheduler.capacity.CapacityScheduler: nodeUpdate: slave1:34830 clusterResources: <memory:8192, vCores:2>
2019-06-07 07:58:15,789 DEBUG org.apache.hadoop.yarn.server.resourcemanager.scheduler.capacity.CapacityScheduler: Node being looked for scheduling slave1:34830 availableResource: <memory:4096, vCores:1>
2019-06-07 07:58:15,789 DEBUG org.apache.hadoop.yarn.server.resourcemanager.scheduler.capacity.CapacityScheduler: Node being looked for scheduling slave1:34830 availableResource: <memory:4096, vCores:1>
2019-06-07 07:58:15,789 DEBUG org.apache.hadoop.yarn.server.resourcemanager.scheduler.capacity.CapacityScheduler: Trying to schedule on node: slave1, available: <memory:4096, vCores:1>
2019-06-07 07:58:15,789 DEBUG org.apache.hadoop.yarn.server.resourcemanager.scheduler.capacity.CapacityScheduler: Trying to schedule on node: slave1, available: <memory:4096, vCores:1>
2019-06-07 07:58:15,789 DEBUG org.apache.hadoop.yarn.server.resourcemanager.scheduler.capacity.ParentQueue: Skip this queue=root, because it doesn't need more resource, schedulingMode=RESPECT_PARTITION_EXCLUSIVITY node-partition=
2019-06-07 07:58:15,789 DEBUG org.apache.hadoop.yarn.server.resourcemanager.scheduler.capacity.ParentQueue: Skip this queue=root, because it doesn't need more resource, schedulingMode=RESPECT_PARTITION_EXCLUSIVITY node-partition=
2019-06-07 07:58:16,341 DEBUG org.apache.hadoop.yarn.server.resourcemanager.rmnode.RMNodeImpl: Processing slave2:42768 of type STATUS_UPDATE
2019-06-07 07:58:16,341 DEBUG org.apache.hadoop.yarn.server.resourcemanager.rmnode.RMNodeImpl: Processing slave2:42768 of type STATUS_UPDATE
2019-06-07 07:58:16,341 DEBUG org.apache.hadoop.yarn.server.resourcemanager.scheduler.capacity.CapacityScheduler: nodeUpdate: slave2:42768 clusterResources: <memory:8192, vCores:2>
2019-06-07 07:58:16,341 DEBUG org.apache.hadoop.yarn.server.resourcemanager.scheduler.capacity.CapacityScheduler: nodeUpdate: slave2:42768 clusterResources: <memory:8192, vCores:2>
2019-06-07 07:58:16,341 DEBUG org.apache.hadoop.yarn.server.resourcemanager.scheduler.capacity.CapacityScheduler: Node being looked for scheduling slave2:42768 availableResource: <memory:4096, vCores:1>
2019-06-07 07:58:16,341 DEBUG org.apache.hadoop.yarn.server.resourcemanager.scheduler.capacity.CapacityScheduler: Node being looked for scheduling slave2:42768 availableResource: <memory:4096, vCores:1>
2019-06-07 07:58:16,341 DEBUG org.apache.hadoop.yarn.server.resourcemanager.scheduler.capacity.CapacityScheduler: Trying to schedule on node: slave2, available: <memory:4096, vCores:1>
2019-06-07 07:58:16,341 DEBUG org.apache.hadoop.yarn.server.resourcemanager.scheduler.capacity.CapacityScheduler: Trying to schedule on node: slave2, available: <memory:4096, vCores:1>
2019-06-07 07:58:16,341 DEBUG org.apache.hadoop.yarn.server.resourcemanager.scheduler.capacity.ParentQueue: Skip this queue=root, because it doesn't need more resource, schedulingMode=RESPECT_PARTITION_EXCLUSIVITY node-partition=
2019-06-07 07:58:16,341 DEBUG org.apache.hadoop.yarn.server.resourcemanager.scheduler.capacity.ParentQueue: Skip this queue=root, because it doesn't need more resource, schedulingMode=RESPECT_PARTITION_EXCLUSIVITY node-partition=
2019-06-07 07:58:16,792 DEBUG org.apache.hadoop.yarn.server.resourcemanager.rmnode.RMNodeImpl: Processing slave1:34830 of type STATUS_UPDATE
2019-06-07 07:58:16,792 DEBUG org.apache.hadoop.yarn.server.resourcemanager.rmnode.RMNodeImpl: Processing slave1:34830 of type STATUS_UPDATE
2019-06-07 07:58:16,792 DEBUG org.apache.hadoop.yarn.server.resourcemanager.scheduler.capacity.CapacityScheduler: nodeUpdate: slave1:34830 clusterResources: <memory:8192, vCores:2>
2019-06-07 07:58:16,792 DEBUG org.apache.hadoop.yarn.server.resourcemanager.scheduler.capacity.CapacityScheduler: nodeUpdate: slave1:34830 clusterResources: <memory:8192, vCores:2>
2019-06-07 07:58:16,792 DEBUG org.apache.hadoop.yarn.server.resourcemanager.scheduler.capacity.CapacityScheduler: Node being looked for scheduling slave1:34830 availableResource: <memory:4096, vCores:1>
2019-06-07 07:58:16,792 DEBUG org.apache.hadoop.yarn.server.resourcemanager.scheduler.capacity.CapacityScheduler: Node being looked for scheduling slave1:34830 availableResource: <memory:4096, vCores:1>
2019-06-07 07:58:16,792 DEBUG org.apache.hadoop.yarn.server.resourcemanager.scheduler.capacity.CapacityScheduler: Trying to schedule on node: slave1, available: <memory:4096, vCores:1>
2019-06-07 07:58:16,792 DEBUG org.apache.hadoop.yarn.server.resourcemanager.scheduler.capacity.CapacityScheduler: Trying to schedule on node: slave1, available: <memory:4096, vCores:1>
2019-06-07 07:58:16,792 DEBUG org.apache.hadoop.yarn.server.resourcemanager.scheduler.capacity.ParentQueue: Skip this queue=root, because it doesn't need more resource, schedulingMode=RESPECT_PARTITION_EXCLUSIVITY node-partition=
2019-06-07 07:58:16,792 DEBUG org.apache.hadoop.yarn.server.resourcemanager.scheduler.capacity.ParentQueue: Skip this queue=root, because it doesn't need more resource, schedulingMode=RESPECT_PARTITION_EXCLUSIVITY node-partition=
2019-06-07 07:58:17,344 DEBUG org.apache.hadoop.yarn.server.resourcemanager.rmnode.RMNodeImpl: Processing slave2:42768 of type STATUS_UPDATE
2019-06-07 07:58:17,344 DEBUG org.apache.hadoop.yarn.server.resourcemanager.rmnode.RMNodeImpl: Processing slave2:42768 of type STATUS_UPDATE
2019-06-07 07:58:17,344 DEBUG org.apache.hadoop.yarn.server.resourcemanager.scheduler.capacity.CapacityScheduler: nodeUpdate: slave2:42768 clusterResources: <memory:8192, vCores:2>
2019-06-07 07:58:17,344 DEBUG org.apache.hadoop.yarn.server.resourcemanager.scheduler.capacity.CapacityScheduler: nodeUpdate: slave2:42768 clusterResources: <memory:8192, vCores:2>
2019-06-07 07:58:17,344 DEBUG org.apache.hadoop.yarn.server.resourcemanager.scheduler.capacity.CapacityScheduler: Node being looked for scheduling slave2:42768 availableResource: <memory:4096, vCores:1>
2019-06-07 07:58:17,344 DEBUG org.apache.hadoop.yarn.server.resourcemanager.scheduler.capacity.CapacityScheduler: Node being looked for scheduling slave2:42768 availableResource: <memory:4096, vCores:1>
2019-06-07 07:58:17,345 DEBUG org.apache.hadoop.yarn.server.resourcemanager.scheduler.capacity.CapacityScheduler: Trying to schedule on node: slave2, available: <memory:4096, vCores:1>
2019-06-07 07:58:17,345 DEBUG org.apache.hadoop.yarn.server.resourcemanager.scheduler.capacity.CapacityScheduler: Trying to schedule on node: slave2, available: <memory:4096, vCores:1>
2019-06-07 07:58:17,345 DEBUG org.apache.hadoop.yarn.server.resourcemanager.scheduler.capacity.ParentQueue: Skip this queue=root, because it doesn't need more resource, schedulingMode=RESPECT_PARTITION_EXCLUSIVITY node-partition=
2019-06-07 07:58:17,345 DEBUG org.apache.hadoop.yarn.server.resourcemanager.scheduler.capacity.ParentQueue: Skip this queue=root, because it doesn't need more resource, schedulingMode=RESPECT_PARTITION_EXCLUSIVITY node-partition=
2019-06-07 07:58:17,795 DEBUG org.apache.hadoop.yarn.server.resourcemanager.rmnode.RMNodeImpl: Processing slave1:34830 of type STATUS_UPDATE
2019-06-07 07:58:17,795 DEBUG org.apache.hadoop.yarn.server.resourcemanager.rmnode.RMNodeImpl: Processing slave1:34830 of type STATUS_UPDATE
2019-06-07 07:58:17,795 DEBUG org.apache.hadoop.yarn.server.resourcemanager.scheduler.capacity.CapacityScheduler: nodeUpdate: slave1:34830 clusterResources: <memory:8192, vCores:2>
2019-06-07 07:58:17,795 DEBUG org.apache.hadoop.yarn.server.resourcemanager.scheduler.capacity.CapacityScheduler: nodeUpdate: slave1:34830 clusterResources: <memory:8192, vCores:2>
2019-06-07 07:58:17,795 DEBUG org.apache.hadoop.yarn.server.resourcemanager.scheduler.capacity.CapacityScheduler: Node being looked for scheduling slave1:34830 availableResource: <memory:4096, vCores:1>
2019-06-07 07:58:17,795 DEBUG org.apache.hadoop.yarn.server.resourcemanager.scheduler.capacity.CapacityScheduler: Node being looked for scheduling slave1:34830 availableResource: <memory:4096, vCores:1>
2019-06-07 07:58:17,795 DEBUG org.apache.hadoop.yarn.server.resourcemanager.scheduler.capacity.CapacityScheduler: Trying to schedule on node: slave1, available: <memory:4096, vCores:1>
2019-06-07 07:58:17,795 DEBUG org.apache.hadoop.yarn.server.resourcemanager.scheduler.capacity.CapacityScheduler: Trying to schedule on node: slave1, available: <memory:4096, vCores:1>
2019-06-07 07:58:17,796 DEBUG org.apache.hadoop.yarn.server.resourcemanager.scheduler.capacity.ParentQueue: Skip this queue=root, because it doesn't need more resource, schedulingMode=RESPECT_PARTITION_EXCLUSIVITY node-partition=
2019-06-07 07:58:17,796 DEBUG org.apache.hadoop.yarn.server.resourcemanager.scheduler.capacity.ParentQueue: Skip this queue=root, because it doesn't need more resource, schedulingMode=RESPECT_PARTITION_EXCLUSIVITY node-partition=
2019-06-07 07:58:18,347 DEBUG org.apache.hadoop.yarn.server.resourcemanager.rmnode.RMNodeImpl: Processing slave2:42768 of type STATUS_UPDATE
2019-06-07 07:58:18,347 DEBUG org.apache.hadoop.yarn.server.resourcemanager.rmnode.RMNodeImpl: Processing slave2:42768 of type STATUS_UPDATE
2019-06-07 07:58:18,348 DEBUG org.apache.hadoop.yarn.server.resourcemanager.scheduler.capacity.CapacityScheduler: nodeUpdate: slave2:42768 clusterResources: <memory:8192, vCores:2>
2019-06-07 07:58:18,348 DEBUG org.apache.hadoop.yarn.server.resourcemanager.scheduler.capacity.CapacityScheduler: nodeUpdate: slave2:42768 clusterResources: <memory:8192, vCores:2>
2019-06-07 07:58:18,348 DEBUG org.apache.hadoop.yarn.server.resourcemanager.scheduler.capacity.CapacityScheduler: Node being looked for scheduling slave2:42768 availableResource: <memory:4096, vCores:1>
2019-06-07 07:58:18,348 DEBUG org.apache.hadoop.yarn.server.resourcemanager.scheduler.capacity.CapacityScheduler: Node being looked for scheduling slave2:42768 availableResource: <memory:4096, vCores:1>
2019-06-07 07:58:18,348 DEBUG org.apache.hadoop.yarn.server.resourcemanager.scheduler.capacity.CapacityScheduler: Trying to schedule on node: slave2, available: <memory:4096, vCores:1>
2019-06-07 07:58:18,348 DEBUG org.apache.hadoop.yarn.server.resourcemanager.scheduler.capacity.CapacityScheduler: Trying to schedule on node: slave2, available: <memory:4096, vCores:1>
2019-06-07 07:58:18,348 DEBUG org.apache.hadoop.yarn.server.resourcemanager.scheduler.capacity.ParentQueue: Skip this queue=root, because it doesn't need more resource, schedulingMode=RESPECT_PARTITION_EXCLUSIVITY node-partition=
2019-06-07 07:58:18,348 DEBUG org.apache.hadoop.yarn.server.resourcemanager.scheduler.capacity.ParentQueue: Skip this queue=root, because it doesn't need more resource, schedulingMode=RESPECT_PARTITION_EXCLUSIVITY node-partition=
2019-06-07 07:58:18,798 DEBUG org.apache.hadoop.yarn.server.resourcemanager.rmnode.RMNodeImpl: Processing slave1:34830 of type STATUS_UPDATE
2019-06-07 07:58:18,798 DEBUG org.apache.hadoop.yarn.server.resourcemanager.rmnode.RMNodeImpl: Processing slave1:34830 of type STATUS_UPDATE
2019-06-07 07:58:18,798 DEBUG org.apache.hadoop.yarn.server.resourcemanager.scheduler.capacity.CapacityScheduler: nodeUpdate: slave1:34830 clusterResources: <memory:8192, vCores:2>
2019-06-07 07:58:18,798 DEBUG org.apache.hadoop.yarn.server.resourcemanager.scheduler.capacity.CapacityScheduler: nodeUpdate: slave1:34830 clusterResources: <memory:8192, vCores:2>
2019-06-07 07:58:18,799 DEBUG org.apache.hadoop.yarn.server.resourcemanager.scheduler.capacity.CapacityScheduler: Node being looked for scheduling slave1:34830 availableResource: <memory:4096, vCores:1>
2019-06-07 07:58:18,799 DEBUG org.apache.hadoop.yarn.server.resourcemanager.scheduler.capacity.CapacityScheduler: Node being looked for scheduling slave1:34830 availableResource: <memory:4096, vCores:1>
2019-06-07 07:58:18,799 DEBUG org.apache.hadoop.yarn.server.resourcemanager.scheduler.capacity.CapacityScheduler: Trying to schedule on node: slave1, available: <memory:4096, vCores:1>
2019-06-07 07:58:18,799 DEBUG org.apache.hadoop.yarn.server.resourcemanager.scheduler.capacity.CapacityScheduler: Trying to schedule on node: slave1, available: <memory:4096, vCores:1>
2019-06-07 07:58:18,799 DEBUG org.apache.hadoop.yarn.server.resourcemanager.scheduler.capacity.ParentQueue: Skip this queue=root, because it doesn't need more resource, schedulingMode=RESPECT_PARTITION_EXCLUSIVITY node-partition=
2019-06-07 07:58:18,799 DEBUG org.apache.hadoop.yarn.server.resourcemanager.scheduler.capacity.ParentQueue: Skip this queue=root, because it doesn't need more resource, schedulingMode=RESPECT_PARTITION_EXCLUSIVITY node-partition=
2019-06-07 07:58:19,351 DEBUG org.apache.hadoop.yarn.server.resourcemanager.rmnode.RMNodeImpl: Processing slave2:42768 of type STATUS_UPDATE
2019-06-07 07:58:19,351 DEBUG org.apache.hadoop.yarn.server.resourcemanager.rmnode.RMNodeImpl: Processing slave2:42768 of type STATUS_UPDATE
2019-06-07 07:58:19,351 DEBUG org.apache.hadoop.yarn.server.resourcemanager.scheduler.capacity.CapacityScheduler: nodeUpdate: slave2:42768 clusterResources: <memory:8192, vCores:2>
2019-06-07 07:58:19,351 DEBUG org.apache.hadoop.yarn.server.resourcemanager.scheduler.capacity.CapacityScheduler: nodeUpdate: slave2:42768 clusterResources: <memory:8192, vCores:2>
2019-06-07 07:58:19,351 DEBUG org.apache.hadoop.yarn.server.resourcemanager.scheduler.capacity.CapacityScheduler: Node being looked for scheduling slave2:42768 availableResource: <memory:4096, vCores:1>
2019-06-07 07:58:19,351 DEBUG org.apache.hadoop.yarn.server.resourcemanager.scheduler.capacity.CapacityScheduler: Node being looked for scheduling slave2:42768 availableResource: <memory:4096, vCores:1>
2019-06-07 07:58:19,351 DEBUG org.apache.hadoop.yarn.server.resourcemanager.scheduler.capacity.CapacityScheduler: Trying to schedule on node: slave2, available: <memory:4096, vCores:1>
2019-06-07 07:58:19,351 DEBUG org.apache.hadoop.yarn.server.resourcemanager.scheduler.capacity.CapacityScheduler: Trying to schedule on node: slave2, available: <memory:4096, vCores:1>
2019-06-07 07:58:19,351 DEBUG org.apache.hadoop.yarn.server.resourcemanager.scheduler.capacity.ParentQueue: Skip this queue=root, because it doesn't need more resource, schedulingMode=RESPECT_PARTITION_EXCLUSIVITY node-partition=
2019-06-07 07:58:19,351 DEBUG org.apache.hadoop.yarn.server.resourcemanager.scheduler.capacity.ParentQueue: Skip this queue=root, because it doesn't need more resource, schedulingMode=RESPECT_PARTITION_EXCLUSIVITY node-partition=
2019-06-07 07:58:19,801 DEBUG org.apache.hadoop.yarn.server.resourcemanager.rmnode.RMNodeImpl: Processing slave1:34830 of type STATUS_UPDATE
2019-06-07 07:58:19,801 DEBUG org.apache.hadoop.yarn.server.resourcemanager.rmnode.RMNodeImpl: Processing slave1:34830 of type STATUS_UPDATE
2019-06-07 07:58:19,801 DEBUG org.apache.hadoop.yarn.server.resourcemanager.scheduler.capacity.CapacityScheduler: nodeUpdate: slave1:34830 clusterResources: <memory:8192, vCores:2>
2019-06-07 07:58:19,801 DEBUG org.apache.hadoop.yarn.server.resourcemanager.scheduler.capacity.CapacityScheduler: nodeUpdate: slave1:34830 clusterResources: <memory:8192, vCores:2>
2019-06-07 07:58:19,801 DEBUG org.apache.hadoop.yarn.server.resourcemanager.scheduler.capacity.CapacityScheduler: Node being looked for scheduling slave1:34830 availableResource: <memory:4096, vCores:1>
2019-06-07 07:58:19,801 DEBUG org.apache.hadoop.yarn.server.resourcemanager.scheduler.capacity.CapacityScheduler: Node being looked for scheduling slave1:34830 availableResource: <memory:4096, vCores:1>
2019-06-07 07:58:19,801 DEBUG org.apache.hadoop.yarn.server.resourcemanager.scheduler.capacity.CapacityScheduler: Trying to schedule on node: slave1, available: <memory:4096, vCores:1>
2019-06-07 07:58:19,801 DEBUG org.apache.hadoop.yarn.server.resourcemanager.scheduler.capacity.CapacityScheduler: Trying to schedule on node: slave1, available: <memory:4096, vCores:1>
2019-06-07 07:58:19,801 DEBUG org.apache.hadoop.yarn.server.resourcemanager.scheduler.capacity.ParentQueue: Skip this queue=root, because it doesn't need more resource, schedulingMode=RESPECT_PARTITION_EXCLUSIVITY node-partition=
2019-06-07 07:58:19,801 DEBUG org.apache.hadoop.yarn.server.resourcemanager.scheduler.capacity.ParentQueue: Skip this queue=root, because it doesn't need more resource, schedulingMode=RESPECT_PARTITION_EXCLUSIVITY node-partition=
2019-06-07 07:58:20,353 DEBUG org.apache.hadoop.yarn.server.resourcemanager.rmnode.RMNodeImpl: Processing slave2:42768 of type STATUS_UPDATE
2019-06-07 07:58:20,353 DEBUG org.apache.hadoop.yarn.server.resourcemanager.rmnode.RMNodeImpl: Processing slave2:42768 of type STATUS_UPDATE
2019-06-07 07:58:20,354 DEBUG org.apache.hadoop.yarn.server.resourcemanager.scheduler.capacity.CapacityScheduler: nodeUpdate: slave2:42768 clusterResources: <memory:8192, vCores:2>
2019-06-07 07:58:20,354 DEBUG org.apache.hadoop.yarn.server.resourcemanager.scheduler.capacity.CapacityScheduler: nodeUpdate: slave2:42768 clusterResources: <memory:8192, vCores:2>
2019-06-07 07:58:20,354 DEBUG org.apache.hadoop.yarn.server.resourcemanager.scheduler.capacity.CapacityScheduler: Node being looked for scheduling slave2:42768 availableResource: <memory:4096, vCores:1>
2019-06-07 07:58:20,354 DEBUG org.apache.hadoop.yarn.server.resourcemanager.scheduler.capacity.CapacityScheduler: Node being looked for scheduling slave2:42768 availableResource: <memory:4096, vCores:1>
2019-06-07 07:58:20,354 DEBUG org.apache.hadoop.yarn.server.resourcemanager.scheduler.capacity.CapacityScheduler: Trying to schedule on node: slave2, available: <memory:4096, vCores:1>
2019-06-07 07:58:20,354 DEBUG org.apache.hadoop.yarn.server.resourcemanager.scheduler.capacity.CapacityScheduler: Trying to schedule on node: slave2, available: <memory:4096, vCores:1>
2019-06-07 07:58:20,354 DEBUG org.apache.hadoop.yarn.server.resourcemanager.scheduler.capacity.ParentQueue: Skip this queue=root, because it doesn't need more resource, schedulingMode=RESPECT_PARTITION_EXCLUSIVITY node-partition=
2019-06-07 07:58:20,354 DEBUG org.apache.hadoop.yarn.server.resourcemanager.scheduler.capacity.ParentQueue: Skip this queue=root, because it doesn't need more resource, schedulingMode=RESPECT_PARTITION_EXCLUSIVITY node-partition=
2019-06-07 07:58:20,804 DEBUG org.apache.hadoop.yarn.server.resourcemanager.rmnode.RMNodeImpl: Processing slave1:34830 of type STATUS_UPDATE
2019-06-07 07:58:20,804 DEBUG org.apache.hadoop.yarn.server.resourcemanager.rmnode.RMNodeImpl: Processing slave1:34830 of type STATUS_UPDATE
2019-06-07 07:58:20,806 DEBUG org.apache.hadoop.yarn.server.resourcemanager.scheduler.capacity.CapacityScheduler: nodeUpdate: slave1:34830 clusterResources: <memory:8192, vCores:2>
2019-06-07 07:58:20,806 DEBUG org.apache.hadoop.yarn.server.resourcemanager.scheduler.capacity.CapacityScheduler: nodeUpdate: slave1:34830 clusterResources: <memory:8192, vCores:2>
2019-06-07 07:58:20,806 DEBUG org.apache.hadoop.yarn.server.resourcemanager.scheduler.capacity.CapacityScheduler: Node being looked for scheduling slave1:34830 availableResource: <memory:4096, vCores:1>
2019-06-07 07:58:20,806 DEBUG org.apache.hadoop.yarn.server.resourcemanager.scheduler.capacity.CapacityScheduler: Node being looked for scheduling slave1:34830 availableResource: <memory:4096, vCores:1>
2019-06-07 07:58:20,806 DEBUG org.apache.hadoop.yarn.server.resourcemanager.scheduler.capacity.CapacityScheduler: Trying to schedule on node: slave1, available: <memory:4096, vCores:1>
2019-06-07 07:58:20,806 DEBUG org.apache.hadoop.yarn.server.resourcemanager.scheduler.capacity.CapacityScheduler: Trying to schedule on node: slave1, available: <memory:4096, vCores:1>
2019-06-07 07:58:20,806 DEBUG org.apache.hadoop.yarn.server.resourcemanager.scheduler.capacity.ParentQueue: Skip this queue=root, because it doesn't need more resource, schedulingMode=RESPECT_PARTITION_EXCLUSIVITY node-partition=
2019-06-07 07:58:20,806 DEBUG org.apache.hadoop.yarn.server.resourcemanager.scheduler.capacity.ParentQueue: Skip this queue=root, because it doesn't need more resource, schedulingMode=RESPECT_PARTITION_EXCLUSIVITY node-partition=
2019-06-07 07:58:21,358 DEBUG org.apache.hadoop.yarn.server.resourcemanager.rmnode.RMNodeImpl: Processing slave2:42768 of type STATUS_UPDATE
2019-06-07 07:58:21,358 DEBUG org.apache.hadoop.yarn.server.resourcemanager.rmnode.RMNodeImpl: Processing slave2:42768 of type STATUS_UPDATE
2019-06-07 07:58:21,358 DEBUG org.apache.hadoop.yarn.server.resourcemanager.scheduler.capacity.CapacityScheduler: nodeUpdate: slave2:42768 clusterResources: <memory:8192, vCores:2>
2019-06-07 07:58:21,358 DEBUG org.apache.hadoop.yarn.server.resourcemanager.scheduler.capacity.CapacityScheduler: nodeUpdate: slave2:42768 clusterResources: <memory:8192, vCores:2>
2019-06-07 07:58:21,358 DEBUG org.apache.hadoop.yarn.server.resourcemanager.scheduler.capacity.CapacityScheduler: Node being looked for scheduling slave2:42768 availableResource: <memory:4096, vCores:1>
2019-06-07 07:58:21,358 DEBUG org.apache.hadoop.yarn.server.resourcemanager.scheduler.capacity.CapacityScheduler: Node being looked for scheduling slave2:42768 availableResource: <memory:4096, vCores:1>
2019-06-07 07:58:21,358 DEBUG org.apache.hadoop.yarn.server.resourcemanager.scheduler.capacity.CapacityScheduler: Trying to schedule on node: slave2, available: <memory:4096, vCores:1>
2019-06-07 07:58:21,358 DEBUG org.apache.hadoop.yarn.server.resourcemanager.scheduler.capacity.CapacityScheduler: Trying to schedule on node: slave2, available: <memory:4096, vCores:1>
2019-06-07 07:58:21,358 DEBUG org.apache.hadoop.yarn.server.resourcemanager.scheduler.capacity.ParentQueue: Skip this queue=root, because it doesn't need more resource, schedulingMode=RESPECT_PARTITION_EXCLUSIVITY node-partition=
2019-06-07 07:58:21,358 DEBUG org.apache.hadoop.yarn.server.resourcemanager.scheduler.capacity.ParentQueue: Skip this queue=root, because it doesn't need more resource, schedulingMode=RESPECT_PARTITION_EXCLUSIVITY node-partition=
2019-06-07 07:58:21,807 DEBUG org.apache.hadoop.yarn.server.resourcemanager.rmnode.RMNodeImpl: Processing slave1:34830 of type STATUS_UPDATE
2019-06-07 07:58:21,807 DEBUG org.apache.hadoop.yarn.server.resourcemanager.rmnode.RMNodeImpl: Processing slave1:34830 of type STATUS_UPDATE
2019-06-07 07:58:21,807 DEBUG org.apache.hadoop.yarn.server.resourcemanager.scheduler.capacity.CapacityScheduler: nodeUpdate: slave1:34830 clusterResources: <memory:8192, vCores:2>
2019-06-07 07:58:21,807 DEBUG org.apache.hadoop.yarn.server.resourcemanager.scheduler.capacity.CapacityScheduler: nodeUpdate: slave1:34830 clusterResources: <memory:8192, vCores:2>
2019-06-07 07:58:21,808 DEBUG org.apache.hadoop.yarn.server.resourcemanager.scheduler.capacity.CapacityScheduler: Node being looked for scheduling slave1:34830 availableResource: <memory:4096, vCores:1>
2019-06-07 07:58:21,808 DEBUG org.apache.hadoop.yarn.server.resourcemanager.scheduler.capacity.CapacityScheduler: Node being looked for scheduling slave1:34830 availableResource: <memory:4096, vCores:1>
2019-06-07 07:58:21,808 DEBUG org.apache.hadoop.yarn.server.resourcemanager.scheduler.capacity.CapacityScheduler: Trying to schedule on node: slave1, available: <memory:4096, vCores:1>
2019-06-07 07:58:21,808 DEBUG org.apache.hadoop.yarn.server.resourcemanager.scheduler.capacity.CapacityScheduler: Trying to schedule on node: slave1, available: <memory:4096, vCores:1>
2019-06-07 07:58:21,808 DEBUG org.apache.hadoop.yarn.server.resourcemanager.scheduler.capacity.ParentQueue: Skip this queue=root, because it doesn't need more resource, schedulingMode=RESPECT_PARTITION_EXCLUSIVITY node-partition=
2019-06-07 07:58:21,808 DEBUG org.apache.hadoop.yarn.server.resourcemanager.scheduler.capacity.ParentQueue: Skip this queue=root, because it doesn't need more resource, schedulingMode=RESPECT_PARTITION_EXCLUSIVITY node-partition=
2019-06-07 07:58:22,361 DEBUG org.apache.hadoop.yarn.server.resourcemanager.rmnode.RMNodeImpl: Processing slave2:42768 of type STATUS_UPDATE
2019-06-07 07:58:22,361 DEBUG org.apache.hadoop.yarn.server.resourcemanager.rmnode.RMNodeImpl: Processing slave2:42768 of type STATUS_UPDATE
2019-06-07 07:58:22,361 DEBUG org.apache.hadoop.yarn.server.resourcemanager.scheduler.capacity.CapacityScheduler: nodeUpdate: slave2:42768 clusterResources: <memory:8192, vCores:2>
2019-06-07 07:58:22,361 DEBUG org.apache.hadoop.yarn.server.resourcemanager.scheduler.capacity.CapacityScheduler: nodeUpdate: slave2:42768 clusterResources: <memory:8192, vCores:2>
2019-06-07 07:58:22,361 DEBUG org.apache.hadoop.yarn.server.resourcemanager.scheduler.capacity.CapacityScheduler: Node being looked for scheduling slave2:42768 availableResource: <memory:4096, vCores:1>
2019-06-07 07:58:22,361 DEBUG org.apache.hadoop.yarn.server.resourcemanager.scheduler.capacity.CapacityScheduler: Node being looked for scheduling slave2:42768 availableResource: <memory:4096, vCores:1>
2019-06-07 07:58:22,361 DEBUG org.apache.hadoop.yarn.server.resourcemanager.scheduler.capacity.CapacityScheduler: Trying to schedule on node: slave2, available: <memory:4096, vCores:1>
2019-06-07 07:58:22,361 DEBUG org.apache.hadoop.yarn.server.resourcemanager.scheduler.capacity.CapacityScheduler: Trying to schedule on node: slave2, available: <memory:4096, vCores:1>
2019-06-07 07:58:22,361 DEBUG org.apache.hadoop.yarn.server.resourcemanager.scheduler.capacity.ParentQueue: Skip this queue=root, because it doesn't need more resource, schedulingMode=RESPECT_PARTITION_EXCLUSIVITY node-partition=
2019-06-07 07:58:22,361 DEBUG org.apache.hadoop.yarn.server.resourcemanager.scheduler.capacity.ParentQueue: Skip this queue=root, because it doesn't need more resource, schedulingMode=RESPECT_PARTITION_EXCLUSIVITY node-partition=
2019-06-07 07:58:22,810 DEBUG org.apache.hadoop.yarn.server.resourcemanager.rmnode.RMNodeImpl: Processing slave1:34830 of type STATUS_UPDATE
2019-06-07 07:58:22,810 DEBUG org.apache.hadoop.yarn.server.resourcemanager.rmnode.RMNodeImpl: Processing slave1:34830 of type STATUS_UPDATE
2019-06-07 07:58:22,810 DEBUG org.apache.hadoop.yarn.server.resourcemanager.scheduler.capacity.CapacityScheduler: nodeUpdate: slave1:34830 clusterResources: <memory:8192, vCores:2>
2019-06-07 07:58:22,810 DEBUG org.apache.hadoop.yarn.server.resourcemanager.scheduler.capacity.CapacityScheduler: nodeUpdate: slave1:34830 clusterResources: <memory:8192, vCores:2>
2019-06-07 07:58:22,810 DEBUG org.apache.hadoop.yarn.server.resourcemanager.scheduler.capacity.CapacityScheduler: Node being looked for scheduling slave1:34830 availableResource: <memory:4096, vCores:1>
2019-06-07 07:58:22,810 DEBUG org.apache.hadoop.yarn.server.resourcemanager.scheduler.capacity.CapacityScheduler: Node being looked for scheduling slave1:34830 availableResource: <memory:4096, vCores:1>
2019-06-07 07:58:22,810 DEBUG org.apache.hadoop.yarn.server.resourcemanager.scheduler.capacity.CapacityScheduler: Trying to schedule on node: slave1, available: <memory:4096, vCores:1>
2019-06-07 07:58:22,810 DEBUG org.apache.hadoop.yarn.server.resourcemanager.scheduler.capacity.CapacityScheduler: Trying to schedule on node: slave1, available: <memory:4096, vCores:1>
2019-06-07 07:58:22,810 DEBUG org.apache.hadoop.yarn.server.resourcemanager.scheduler.capacity.ParentQueue: Skip this queue=root, because it doesn't need more resource, schedulingMode=RESPECT_PARTITION_EXCLUSIVITY node-partition=
2019-06-07 07:58:22,810 DEBUG org.apache.hadoop.yarn.server.resourcemanager.scheduler.capacity.ParentQueue: Skip this queue=root, because it doesn't need more resource, schedulingMode=RESPECT_PARTITION_EXCLUSIVITY node-partition=
2019-06-07 07:58:23,364 DEBUG org.apache.hadoop.yarn.server.resourcemanager.rmnode.RMNodeImpl: Processing slave2:42768 of type STATUS_UPDATE
2019-06-07 07:58:23,364 DEBUG org.apache.hadoop.yarn.server.resourcemanager.rmnode.RMNodeImpl: Processing slave2:42768 of type STATUS_UPDATE
2019-06-07 07:58:23,364 DEBUG org.apache.hadoop.yarn.server.resourcemanager.scheduler.capacity.CapacityScheduler: nodeUpdate: slave2:42768 clusterResources: <memory:8192, vCores:2>
2019-06-07 07:58:23,364 DEBUG org.apache.hadoop.yarn.server.resourcemanager.scheduler.capacity.CapacityScheduler: nodeUpdate: slave2:42768 clusterResources: <memory:8192, vCores:2>
2019-06-07 07:58:23,365 DEBUG org.apache.hadoop.yarn.server.resourcemanager.scheduler.capacity.CapacityScheduler: Node being looked for scheduling slave2:42768 availableResource: <memory:4096, vCores:1>
2019-06-07 07:58:23,365 DEBUG org.apache.hadoop.yarn.server.resourcemanager.scheduler.capacity.CapacityScheduler: Node being looked for scheduling slave2:42768 availableResource: <memory:4096, vCores:1>
2019-06-07 07:58:23,365 DEBUG org.apache.hadoop.yarn.server.resourcemanager.scheduler.capacity.CapacityScheduler: Trying to schedule on node: slave2, available: <memory:4096, vCores:1>
2019-06-07 07:58:23,365 DEBUG org.apache.hadoop.yarn.server.resourcemanager.scheduler.capacity.CapacityScheduler: Trying to schedule on node: slave2, available: <memory:4096, vCores:1>
2019-06-07 07:58:23,365 DEBUG org.apache.hadoop.yarn.server.resourcemanager.scheduler.capacity.ParentQueue: Skip this queue=root, because it doesn't need more resource, schedulingMode=RESPECT_PARTITION_EXCLUSIVITY node-partition=
2019-06-07 07:58:23,365 DEBUG org.apache.hadoop.yarn.server.resourcemanager.scheduler.capacity.ParentQueue: Skip this queue=root, because it doesn't need more resource, schedulingMode=RESPECT_PARTITION_EXCLUSIVITY node-partition=
2019-06-07 07:58:23,813 DEBUG org.apache.hadoop.yarn.server.resourcemanager.rmnode.RMNodeImpl: Processing slave1:34830 of type STATUS_UPDATE
2019-06-07 07:58:23,813 DEBUG org.apache.hadoop.yarn.server.resourcemanager.rmnode.RMNodeImpl: Processing slave1:34830 of type STATUS_UPDATE
2019-06-07 07:58:23,813 DEBUG org.apache.hadoop.yarn.server.resourcemanager.scheduler.capacity.CapacityScheduler: nodeUpdate: slave1:34830 clusterResources: <memory:8192, vCores:2>
2019-06-07 07:58:23,813 DEBUG org.apache.hadoop.yarn.server.resourcemanager.scheduler.capacity.CapacityScheduler: nodeUpdate: slave1:34830 clusterResources: <memory:8192, vCores:2>
2019-06-07 07:58:23,813 DEBUG org.apache.hadoop.yarn.server.resourcemanager.scheduler.capacity.CapacityScheduler: Node being looked for scheduling slave1:34830 availableResource: <memory:4096, vCores:1>
2019-06-07 07:58:23,813 DEBUG org.apache.hadoop.yarn.server.resourcemanager.scheduler.capacity.CapacityScheduler: Node being looked for scheduling slave1:34830 availableResource: <memory:4096, vCores:1>
2019-06-07 07:58:23,813 DEBUG org.apache.hadoop.yarn.server.resourcemanager.scheduler.capacity.CapacityScheduler: Trying to schedule on node: slave1, available: <memory:4096, vCores:1>
2019-06-07 07:58:23,813 DEBUG org.apache.hadoop.yarn.server.resourcemanager.scheduler.capacity.CapacityScheduler: Trying to schedule on node: slave1, available: <memory:4096, vCores:1>
2019-06-07 07:58:23,813 DEBUG org.apache.hadoop.yarn.server.resourcemanager.scheduler.capacity.ParentQueue: Skip this queue=root, because it doesn't need more resource, schedulingMode=RESPECT_PARTITION_EXCLUSIVITY node-partition=
2019-06-07 07:58:23,813 DEBUG org.apache.hadoop.yarn.server.resourcemanager.scheduler.capacity.ParentQueue: Skip this queue=root, because it doesn't need more resource, schedulingMode=RESPECT_PARTITION_EXCLUSIVITY node-partition=
2019-06-07 07:58:24,368 DEBUG org.apache.hadoop.yarn.server.resourcemanager.rmnode.RMNodeImpl: Processing slave2:42768 of type STATUS_UPDATE
2019-06-07 07:58:24,368 DEBUG org.apache.hadoop.yarn.server.resourcemanager.rmnode.RMNodeImpl: Processing slave2:42768 of type STATUS_UPDATE
2019-06-07 07:58:24,368 DEBUG org.apache.hadoop.yarn.server.resourcemanager.scheduler.capacity.CapacityScheduler: nodeUpdate: slave2:42768 clusterResources: <memory:8192, vCores:2>
2019-06-07 07:58:24,368 DEBUG org.apache.hadoop.yarn.server.resourcemanager.scheduler.capacity.CapacityScheduler: nodeUpdate: slave2:42768 clusterResources: <memory:8192, vCores:2>
2019-06-07 07:58:24,368 DEBUG org.apache.hadoop.yarn.server.resourcemanager.scheduler.capacity.CapacityScheduler: Node being looked for scheduling slave2:42768 availableResource: <memory:4096, vCores:1>
2019-06-07 07:58:24,368 DEBUG org.apache.hadoop.yarn.server.resourcemanager.scheduler.capacity.CapacityScheduler: Node being looked for scheduling slave2:42768 availableResource: <memory:4096, vCores:1>
2019-06-07 07:58:24,368 DEBUG org.apache.hadoop.yarn.server.resourcemanager.scheduler.capacity.CapacityScheduler: Trying to schedule on node: slave2, available: <memory:4096, vCores:1>
2019-06-07 07:58:24,368 DEBUG org.apache.hadoop.yarn.server.resourcemanager.scheduler.capacity.CapacityScheduler: Trying to schedule on node: slave2, available: <memory:4096, vCores:1>
2019-06-07 07:58:24,368 DEBUG org.apache.hadoop.yarn.server.resourcemanager.scheduler.capacity.ParentQueue: Skip this queue=root, because it doesn't need more resource, schedulingMode=RESPECT_PARTITION_EXCLUSIVITY node-partition=
2019-06-07 07:58:24,368 DEBUG org.apache.hadoop.yarn.server.resourcemanager.scheduler.capacity.ParentQueue: Skip this queue=root, because it doesn't need more resource, schedulingMode=RESPECT_PARTITION_EXCLUSIVITY node-partition=
2019-06-07 07:58:24,824 DEBUG org.apache.hadoop.yarn.server.resourcemanager.rmnode.RMNodeImpl: Processing slave1:34830 of type STATUS_UPDATE
2019-06-07 07:58:24,824 DEBUG org.apache.hadoop.yarn.server.resourcemanager.rmnode.RMNodeImpl: Processing slave1:34830 of type STATUS_UPDATE
2019-06-07 07:58:24,825 DEBUG org.apache.hadoop.yarn.server.resourcemanager.scheduler.capacity.CapacityScheduler: nodeUpdate: slave1:34830 clusterResources: <memory:8192, vCores:2>
2019-06-07 07:58:24,825 DEBUG org.apache.hadoop.yarn.server.resourcemanager.scheduler.capacity.CapacityScheduler: nodeUpdate: slave1:34830 clusterResources: <memory:8192, vCores:2>
2019-06-07 07:58:24,825 DEBUG org.apache.hadoop.yarn.server.resourcemanager.scheduler.capacity.CapacityScheduler: Node being looked for scheduling slave1:34830 availableResource: <memory:4096, vCores:1>
2019-06-07 07:58:24,825 DEBUG org.apache.hadoop.yarn.server.resourcemanager.scheduler.capacity.CapacityScheduler: Node being looked for scheduling slave1:34830 availableResource: <memory:4096, vCores:1>
2019-06-07 07:58:24,825 DEBUG org.apache.hadoop.yarn.server.resourcemanager.scheduler.capacity.CapacityScheduler: Trying to schedule on node: slave1, available: <memory:4096, vCores:1>
2019-06-07 07:58:24,825 DEBUG org.apache.hadoop.yarn.server.resourcemanager.scheduler.capacity.CapacityScheduler: Trying to schedule on node: slave1, available: <memory:4096, vCores:1>
2019-06-07 07:58:24,825 DEBUG org.apache.hadoop.yarn.server.resourcemanager.scheduler.capacity.ParentQueue: Skip this queue=root, because it doesn't need more resource, schedulingMode=RESPECT_PARTITION_EXCLUSIVITY node-partition=
2019-06-07 07:58:24,825 DEBUG org.apache.hadoop.yarn.server.resourcemanager.scheduler.capacity.ParentQueue: Skip this queue=root, because it doesn't need more resource, schedulingMode=RESPECT_PARTITION_EXCLUSIVITY node-partition=
2019-06-07 07:58:25,372 DEBUG org.apache.hadoop.yarn.server.resourcemanager.rmnode.RMNodeImpl: Processing slave2:42768 of type STATUS_UPDATE
2019-06-07 07:58:25,372 DEBUG org.apache.hadoop.yarn.server.resourcemanager.rmnode.RMNodeImpl: Processing slave2:42768 of type STATUS_UPDATE
2019-06-07 07:58:25,373 DEBUG org.apache.hadoop.yarn.server.resourcemanager.scheduler.capacity.CapacityScheduler: nodeUpdate: slave2:42768 clusterResources: <memory:8192, vCores:2>
2019-06-07 07:58:25,373 DEBUG org.apache.hadoop.yarn.server.resourcemanager.scheduler.capacity.CapacityScheduler: nodeUpdate: slave2:42768 clusterResources: <memory:8192, vCores:2>
2019-06-07 07:58:25,373 DEBUG org.apache.hadoop.yarn.server.resourcemanager.scheduler.capacity.CapacityScheduler: Node being looked for scheduling slave2:42768 availableResource: <memory:4096, vCores:1>
2019-06-07 07:58:25,373 DEBUG org.apache.hadoop.yarn.server.resourcemanager.scheduler.capacity.CapacityScheduler: Node being looked for scheduling slave2:42768 availableResource: <memory:4096, vCores:1>
2019-06-07 07:58:25,373 DEBUG org.apache.hadoop.yarn.server.resourcemanager.scheduler.capacity.CapacityScheduler: Trying to schedule on node: slave2, available: <memory:4096, vCores:1>
2019-06-07 07:58:25,373 DEBUG org.apache.hadoop.yarn.server.resourcemanager.scheduler.capacity.CapacityScheduler: Trying to schedule on node: slave2, available: <memory:4096, vCores:1>
2019-06-07 07:58:25,373 DEBUG org.apache.hadoop.yarn.server.resourcemanager.scheduler.capacity.ParentQueue: Skip this queue=root, because it doesn't need more resource, schedulingMode=RESPECT_PARTITION_EXCLUSIVITY node-partition=
2019-06-07 07:58:25,373 DEBUG org.apache.hadoop.yarn.server.resourcemanager.scheduler.capacity.ParentQueue: Skip this queue=root, because it doesn't need more resource, schedulingMode=RESPECT_PARTITION_EXCLUSIVITY node-partition=
2019-06-07 07:58:25,828 DEBUG org.apache.hadoop.yarn.server.resourcemanager.rmnode.RMNodeImpl: Processing slave1:34830 of type STATUS_UPDATE
2019-06-07 07:58:25,828 DEBUG org.apache.hadoop.yarn.server.resourcemanager.rmnode.RMNodeImpl: Processing slave1:34830 of type STATUS_UPDATE
2019-06-07 07:58:25,831 DEBUG org.apache.hadoop.yarn.server.resourcemanager.scheduler.capacity.CapacityScheduler: nodeUpdate: slave1:34830 clusterResources: <memory:8192, vCores:2>
2019-06-07 07:58:25,831 DEBUG org.apache.hadoop.yarn.server.resourcemanager.scheduler.capacity.CapacityScheduler: nodeUpdate: slave1:34830 clusterResources: <memory:8192, vCores:2>
2019-06-07 07:58:25,831 DEBUG org.apache.hadoop.yarn.server.resourcemanager.scheduler.capacity.CapacityScheduler: Node being looked for scheduling slave1:34830 availableResource: <memory:4096, vCores:1>
2019-06-07 07:58:25,831 DEBUG org.apache.hadoop.yarn.server.resourcemanager.scheduler.capacity.CapacityScheduler: Node being looked for scheduling slave1:34830 availableResource: <memory:4096, vCores:1>
2019-06-07 07:58:25,831 DEBUG org.apache.hadoop.yarn.server.resourcemanager.scheduler.capacity.CapacityScheduler: Trying to schedule on node: slave1, available: <memory:4096, vCores:1>
2019-06-07 07:58:25,831 DEBUG org.apache.hadoop.yarn.server.resourcemanager.scheduler.capacity.CapacityScheduler: Trying to schedule on node: slave1, available: <memory:4096, vCores:1>
2019-06-07 07:58:25,831 DEBUG org.apache.hadoop.yarn.server.resourcemanager.scheduler.capacity.ParentQueue: Skip this queue=root, because it doesn't need more resource, schedulingMode=RESPECT_PARTITION_EXCLUSIVITY node-partition=
2019-06-07 07:58:25,831 DEBUG org.apache.hadoop.yarn.server.resourcemanager.scheduler.capacity.ParentQueue: Skip this queue=root, because it doesn't need more resource, schedulingMode=RESPECT_PARTITION_EXCLUSIVITY node-partition=
2019-06-07 07:58:26,376 DEBUG org.apache.hadoop.yarn.server.resourcemanager.rmnode.RMNodeImpl: Processing slave2:42768 of type STATUS_UPDATE
2019-06-07 07:58:26,376 DEBUG org.apache.hadoop.yarn.server.resourcemanager.rmnode.RMNodeImpl: Processing slave2:42768 of type STATUS_UPDATE
2019-06-07 07:58:26,377 DEBUG org.apache.hadoop.yarn.server.resourcemanager.scheduler.capacity.CapacityScheduler: nodeUpdate: slave2:42768 clusterResources: <memory:8192, vCores:2>
2019-06-07 07:58:26,377 DEBUG org.apache.hadoop.yarn.server.resourcemanager.scheduler.capacity.CapacityScheduler: nodeUpdate: slave2:42768 clusterResources: <memory:8192, vCores:2>
2019-06-07 07:58:26,377 DEBUG org.apache.hadoop.yarn.server.resourcemanager.scheduler.capacity.CapacityScheduler: Node being looked for scheduling slave2:42768 availableResource: <memory:4096, vCores:1>
2019-06-07 07:58:26,377 DEBUG org.apache.hadoop.yarn.server.resourcemanager.scheduler.capacity.CapacityScheduler: Node being looked for scheduling slave2:42768 availableResource: <memory:4096, vCores:1>
2019-06-07 07:58:26,377 DEBUG org.apache.hadoop.yarn.server.resourcemanager.scheduler.capacity.CapacityScheduler: Trying to schedule on node: slave2, available: <memory:4096, vCores:1>
2019-06-07 07:58:26,377 DEBUG org.apache.hadoop.yarn.server.resourcemanager.scheduler.capacity.CapacityScheduler: Trying to schedule on node: slave2, available: <memory:4096, vCores:1>
2019-06-07 07:58:26,377 DEBUG org.apache.hadoop.yarn.server.resourcemanager.scheduler.capacity.ParentQueue: Skip this queue=root, because it doesn't need more resource, schedulingMode=RESPECT_PARTITION_EXCLUSIVITY node-partition=
2019-06-07 07:58:26,377 DEBUG org.apache.hadoop.yarn.server.resourcemanager.scheduler.capacity.ParentQueue: Skip this queue=root, because it doesn't need more resource, schedulingMode=RESPECT_PARTITION_EXCLUSIVITY node-partition=
2019-06-07 07:58:26,831 DEBUG org.apache.hadoop.yarn.server.resourcemanager.rmnode.RMNodeImpl: Processing slave1:34830 of type STATUS_UPDATE
2019-06-07 07:58:26,831 DEBUG org.apache.hadoop.yarn.server.resourcemanager.rmnode.RMNodeImpl: Processing slave1:34830 of type STATUS_UPDATE
2019-06-07 07:58:26,831 DEBUG org.apache.hadoop.yarn.server.resourcemanager.scheduler.capacity.CapacityScheduler: nodeUpdate: slave1:34830 clusterResources: <memory:8192, vCores:2>
2019-06-07 07:58:26,831 DEBUG org.apache.hadoop.yarn.server.resourcemanager.scheduler.capacity.CapacityScheduler: nodeUpdate: slave1:34830 clusterResources: <memory:8192, vCores:2>
2019-06-07 07:58:26,831 DEBUG org.apache.hadoop.yarn.server.resourcemanager.scheduler.capacity.CapacityScheduler: Node being looked for scheduling slave1:34830 availableResource: <memory:4096, vCores:1>
2019-06-07 07:58:26,831 DEBUG org.apache.hadoop.yarn.server.resourcemanager.scheduler.capacity.CapacityScheduler: Node being looked for scheduling slave1:34830 availableResource: <memory:4096, vCores:1>
2019-06-07 07:58:26,831 DEBUG org.apache.hadoop.yarn.server.resourcemanager.scheduler.capacity.CapacityScheduler: Trying to schedule on node: slave1, available: <memory:4096, vCores:1>
2019-06-07 07:58:26,831 DEBUG org.apache.hadoop.yarn.server.resourcemanager.scheduler.capacity.CapacityScheduler: Trying to schedule on node: slave1, available: <memory:4096, vCores:1>
2019-06-07 07:58:26,831 DEBUG org.apache.hadoop.yarn.server.resourcemanager.scheduler.capacity.ParentQueue: Skip this queue=root, because it doesn't need more resource, schedulingMode=RESPECT_PARTITION_EXCLUSIVITY node-partition=
2019-06-07 07:58:26,831 DEBUG org.apache.hadoop.yarn.server.resourcemanager.scheduler.capacity.ParentQueue: Skip this queue=root, because it doesn't need more resource, schedulingMode=RESPECT_PARTITION_EXCLUSIVITY node-partition=
2019-06-07 07:58:27,382 DEBUG org.apache.hadoop.yarn.server.resourcemanager.rmnode.RMNodeImpl: Processing slave2:42768 of type STATUS_UPDATE
2019-06-07 07:58:27,382 DEBUG org.apache.hadoop.yarn.server.resourcemanager.rmnode.RMNodeImpl: Processing slave2:42768 of type STATUS_UPDATE
2019-06-07 07:58:27,383 DEBUG org.apache.hadoop.yarn.server.resourcemanager.scheduler.capacity.CapacityScheduler: nodeUpdate: slave2:42768 clusterResources: <memory:8192, vCores:2>
2019-06-07 07:58:27,383 DEBUG org.apache.hadoop.yarn.server.resourcemanager.scheduler.capacity.CapacityScheduler: nodeUpdate: slave2:42768 clusterResources: <memory:8192, vCores:2>
2019-06-07 07:58:27,383 DEBUG org.apache.hadoop.yarn.server.resourcemanager.scheduler.capacity.CapacityScheduler: Node being looked for scheduling slave2:42768 availableResource: <memory:4096, vCores:1>
2019-06-07 07:58:27,383 DEBUG org.apache.hadoop.yarn.server.resourcemanager.scheduler.capacity.CapacityScheduler: Node being looked for scheduling slave2:42768 availableResource: <memory:4096, vCores:1>
2019-06-07 07:58:27,383 DEBUG org.apache.hadoop.yarn.server.resourcemanager.scheduler.capacity.CapacityScheduler: Trying to schedule on node: slave2, available: <memory:4096, vCores:1>
2019-06-07 07:58:27,383 DEBUG org.apache.hadoop.yarn.server.resourcemanager.scheduler.capacity.CapacityScheduler: Trying to schedule on node: slave2, available: <memory:4096, vCores:1>
2019-06-07 07:58:27,383 DEBUG org.apache.hadoop.yarn.server.resourcemanager.scheduler.capacity.ParentQueue: Skip this queue=root, because it doesn't need more resource, schedulingMode=RESPECT_PARTITION_EXCLUSIVITY node-partition=
2019-06-07 07:58:27,383 DEBUG org.apache.hadoop.yarn.server.resourcemanager.scheduler.capacity.ParentQueue: Skip this queue=root, because it doesn't need more resource, schedulingMode=RESPECT_PARTITION_EXCLUSIVITY node-partition=
2019-06-07 07:58:27,835 DEBUG org.apache.hadoop.yarn.server.resourcemanager.rmnode.RMNodeImpl: Processing slave1:34830 of type STATUS_UPDATE
2019-06-07 07:58:27,835 DEBUG org.apache.hadoop.yarn.server.resourcemanager.rmnode.RMNodeImpl: Processing slave1:34830 of type STATUS_UPDATE
2019-06-07 07:58:27,835 DEBUG org.apache.hadoop.yarn.server.resourcemanager.scheduler.capacity.CapacityScheduler: nodeUpdate: slave1:34830 clusterResources: <memory:8192, vCores:2>
2019-06-07 07:58:27,835 DEBUG org.apache.hadoop.yarn.server.resourcemanager.scheduler.capacity.CapacityScheduler: nodeUpdate: slave1:34830 clusterResources: <memory:8192, vCores:2>
2019-06-07 07:58:27,835 DEBUG org.apache.hadoop.yarn.server.resourcemanager.scheduler.capacity.CapacityScheduler: Node being looked for scheduling slave1:34830 availableResource: <memory:4096, vCores:1>
2019-06-07 07:58:27,835 DEBUG org.apache.hadoop.yarn.server.resourcemanager.scheduler.capacity.CapacityScheduler: Node being looked for scheduling slave1:34830 availableResource: <memory:4096, vCores:1>
2019-06-07 07:58:27,835 DEBUG org.apache.hadoop.yarn.server.resourcemanager.scheduler.capacity.CapacityScheduler: Trying to schedule on node: slave1, available: <memory:4096, vCores:1>
2019-06-07 07:58:27,835 DEBUG org.apache.hadoop.yarn.server.resourcemanager.scheduler.capacity.CapacityScheduler: Trying to schedule on node: slave1, available: <memory:4096, vCores:1>
2019-06-07 07:58:27,835 DEBUG org.apache.hadoop.yarn.server.resourcemanager.scheduler.capacity.ParentQueue: Skip this queue=root, because it doesn't need more resource, schedulingMode=RESPECT_PARTITION_EXCLUSIVITY node-partition=
2019-06-07 07:58:27,835 DEBUG org.apache.hadoop.yarn.server.resourcemanager.scheduler.capacity.ParentQueue: Skip this queue=root, because it doesn't need more resource, schedulingMode=RESPECT_PARTITION_EXCLUSIVITY node-partition=
2019-06-07 07:58:28,386 DEBUG org.apache.hadoop.yarn.server.resourcemanager.rmnode.RMNodeImpl: Processing slave2:42768 of type STATUS_UPDATE
2019-06-07 07:58:28,386 DEBUG org.apache.hadoop.yarn.server.resourcemanager.rmnode.RMNodeImpl: Processing slave2:42768 of type STATUS_UPDATE
2019-06-07 07:58:28,386 DEBUG org.apache.hadoop.yarn.server.resourcemanager.scheduler.capacity.CapacityScheduler: nodeUpdate: slave2:42768 clusterResources: <memory:8192, vCores:2>
2019-06-07 07:58:28,386 DEBUG org.apache.hadoop.yarn.server.resourcemanager.scheduler.capacity.CapacityScheduler: nodeUpdate: slave2:42768 clusterResources: <memory:8192, vCores:2>
2019-06-07 07:58:28,386 DEBUG org.apache.hadoop.yarn.server.resourcemanager.scheduler.capacity.CapacityScheduler: Node being looked for scheduling slave2:42768 availableResource: <memory:4096, vCores:1>
2019-06-07 07:58:28,386 DEBUG org.apache.hadoop.yarn.server.resourcemanager.scheduler.capacity.CapacityScheduler: Node being looked for scheduling slave2:42768 availableResource: <memory:4096, vCores:1>
2019-06-07 07:58:28,387 DEBUG org.apache.hadoop.yarn.server.resourcemanager.scheduler.capacity.CapacityScheduler: Trying to schedule on node: slave2, available: <memory:4096, vCores:1>
2019-06-07 07:58:28,387 DEBUG org.apache.hadoop.yarn.server.resourcemanager.scheduler.capacity.CapacityScheduler: Trying to schedule on node: slave2, available: <memory:4096, vCores:1>
2019-06-07 07:58:28,387 DEBUG org.apache.hadoop.yarn.server.resourcemanager.scheduler.capacity.ParentQueue: Skip this queue=root, because it doesn't need more resource, schedulingMode=RESPECT_PARTITION_EXCLUSIVITY node-partition=
2019-06-07 07:58:28,387 DEBUG org.apache.hadoop.yarn.server.resourcemanager.scheduler.capacity.ParentQueue: Skip this queue=root, because it doesn't need more resource, schedulingMode=RESPECT_PARTITION_EXCLUSIVITY node-partition=
2019-06-07 07:58:28,839 DEBUG org.apache.hadoop.yarn.server.resourcemanager.rmnode.RMNodeImpl: Processing slave1:34830 of type STATUS_UPDATE
2019-06-07 07:58:28,839 DEBUG org.apache.hadoop.yarn.server.resourcemanager.rmnode.RMNodeImpl: Processing slave1:34830 of type STATUS_UPDATE
2019-06-07 07:58:28,839 DEBUG org.apache.hadoop.yarn.server.resourcemanager.scheduler.capacity.CapacityScheduler: nodeUpdate: slave1:34830 clusterResources: <memory:8192, vCores:2>
2019-06-07 07:58:28,839 DEBUG org.apache.hadoop.yarn.server.resourcemanager.scheduler.capacity.CapacityScheduler: nodeUpdate: slave1:34830 clusterResources: <memory:8192, vCores:2>
2019-06-07 07:58:28,839 DEBUG org.apache.hadoop.yarn.server.resourcemanager.scheduler.capacity.CapacityScheduler: Node being looked for scheduling slave1:34830 availableResource: <memory:4096, vCores:1>
2019-06-07 07:58:28,839 DEBUG org.apache.hadoop.yarn.server.resourcemanager.scheduler.capacity.CapacityScheduler: Node being looked for scheduling slave1:34830 availableResource: <memory:4096, vCores:1>
2019-06-07 07:58:28,839 DEBUG org.apache.hadoop.yarn.server.resourcemanager.scheduler.capacity.CapacityScheduler: Trying to schedule on node: slave1, available: <memory:4096, vCores:1>
2019-06-07 07:58:28,839 DEBUG org.apache.hadoop.yarn.server.resourcemanager.scheduler.capacity.CapacityScheduler: Trying to schedule on node: slave1, available: <memory:4096, vCores:1>
2019-06-07 07:58:28,839 DEBUG org.apache.hadoop.yarn.server.resourcemanager.scheduler.capacity.ParentQueue: Skip this queue=root, because it doesn't need more resource, schedulingMode=RESPECT_PARTITION_EXCLUSIVITY node-partition=
2019-06-07 07:58:28,839 DEBUG org.apache.hadoop.yarn.server.resourcemanager.scheduler.capacity.ParentQueue: Skip this queue=root, because it doesn't need more resource, schedulingMode=RESPECT_PARTITION_EXCLUSIVITY node-partition=
2019-06-07 07:58:29,391 DEBUG org.apache.hadoop.yarn.server.resourcemanager.rmnode.RMNodeImpl: Processing slave2:42768 of type STATUS_UPDATE
2019-06-07 07:58:29,391 DEBUG org.apache.hadoop.yarn.server.resourcemanager.rmnode.RMNodeImpl: Processing slave2:42768 of type STATUS_UPDATE
2019-06-07 07:58:29,392 DEBUG org.apache.hadoop.yarn.server.resourcemanager.scheduler.capacity.CapacityScheduler: nodeUpdate: slave2:42768 clusterResources: <memory:8192, vCores:2>
2019-06-07 07:58:29,392 DEBUG org.apache.hadoop.yarn.server.resourcemanager.scheduler.capacity.CapacityScheduler: nodeUpdate: slave2:42768 clusterResources: <memory:8192, vCores:2>
2019-06-07 07:58:29,392 DEBUG org.apache.hadoop.yarn.server.resourcemanager.scheduler.capacity.CapacityScheduler: Node being looked for scheduling slave2:42768 availableResource: <memory:4096, vCores:1>
2019-06-07 07:58:29,392 DEBUG org.apache.hadoop.yarn.server.resourcemanager.scheduler.capacity.CapacityScheduler: Node being looked for scheduling slave2:42768 availableResource: <memory:4096, vCores:1>
2019-06-07 07:58:29,392 DEBUG org.apache.hadoop.yarn.server.resourcemanager.scheduler.capacity.CapacityScheduler: Trying to schedule on node: slave2, available: <memory:4096, vCores:1>
2019-06-07 07:58:29,392 DEBUG org.apache.hadoop.yarn.server.resourcemanager.scheduler.capacity.CapacityScheduler: Trying to schedule on node: slave2, available: <memory:4096, vCores:1>
2019-06-07 07:58:29,392 DEBUG org.apache.hadoop.yarn.server.resourcemanager.scheduler.capacity.ParentQueue: Skip this queue=root, because it doesn't need more resource, schedulingMode=RESPECT_PARTITION_EXCLUSIVITY node-partition=
2019-06-07 07:58:29,392 DEBUG org.apache.hadoop.yarn.server.resourcemanager.scheduler.capacity.ParentQueue: Skip this queue=root, because it doesn't need more resource, schedulingMode=RESPECT_PARTITION_EXCLUSIVITY node-partition=
2019-06-07 07:58:29,842 DEBUG org.apache.hadoop.yarn.server.resourcemanager.rmnode.RMNodeImpl: Processing slave1:34830 of type STATUS_UPDATE
2019-06-07 07:58:29,842 DEBUG org.apache.hadoop.yarn.server.resourcemanager.rmnode.RMNodeImpl: Processing slave1:34830 of type STATUS_UPDATE
2019-06-07 07:58:29,842 DEBUG org.apache.hadoop.yarn.server.resourcemanager.scheduler.capacity.CapacityScheduler: nodeUpdate: slave1:34830 clusterResources: <memory:8192, vCores:2>
2019-06-07 07:58:29,842 DEBUG org.apache.hadoop.yarn.server.resourcemanager.scheduler.capacity.CapacityScheduler: nodeUpdate: slave1:34830 clusterResources: <memory:8192, vCores:2>
2019-06-07 07:58:29,842 DEBUG org.apache.hadoop.yarn.server.resourcemanager.scheduler.capacity.CapacityScheduler: Node being looked for scheduling slave1:34830 availableResource: <memory:4096, vCores:1>
2019-06-07 07:58:29,842 DEBUG org.apache.hadoop.yarn.server.resourcemanager.scheduler.capacity.CapacityScheduler: Node being looked for scheduling slave1:34830 availableResource: <memory:4096, vCores:1>
2019-06-07 07:58:29,842 DEBUG org.apache.hadoop.yarn.server.resourcemanager.scheduler.capacity.CapacityScheduler: Trying to schedule on node: slave1, available: <memory:4096, vCores:1>
2019-06-07 07:58:29,842 DEBUG org.apache.hadoop.yarn.server.resourcemanager.scheduler.capacity.CapacityScheduler: Trying to schedule on node: slave1, available: <memory:4096, vCores:1>
2019-06-07 07:58:29,842 DEBUG org.apache.hadoop.yarn.server.resourcemanager.scheduler.capacity.ParentQueue: Skip this queue=root, because it doesn't need more resource, schedulingMode=RESPECT_PARTITION_EXCLUSIVITY node-partition=
2019-06-07 07:58:29,842 DEBUG org.apache.hadoop.yarn.server.resourcemanager.scheduler.capacity.ParentQueue: Skip this queue=root, because it doesn't need more resource, schedulingMode=RESPECT_PARTITION_EXCLUSIVITY node-partition=
2019-06-07 07:58:30,395 DEBUG org.apache.hadoop.yarn.server.resourcemanager.rmnode.RMNodeImpl: Processing slave2:42768 of type STATUS_UPDATE
2019-06-07 07:58:30,395 DEBUG org.apache.hadoop.yarn.server.resourcemanager.rmnode.RMNodeImpl: Processing slave2:42768 of type STATUS_UPDATE
2019-06-07 07:58:30,395 DEBUG org.apache.hadoop.yarn.server.resourcemanager.scheduler.capacity.CapacityScheduler: nodeUpdate: slave2:42768 clusterResources: <memory:8192, vCores:2>
2019-06-07 07:58:30,395 DEBUG org.apache.hadoop.yarn.server.resourcemanager.scheduler.capacity.CapacityScheduler: nodeUpdate: slave2:42768 clusterResources: <memory:8192, vCores:2>
2019-06-07 07:58:30,395 DEBUG org.apache.hadoop.yarn.server.resourcemanager.scheduler.capacity.CapacityScheduler: Node being looked for scheduling slave2:42768 availableResource: <memory:4096, vCores:1>
2019-06-07 07:58:30,395 DEBUG org.apache.hadoop.yarn.server.resourcemanager.scheduler.capacity.CapacityScheduler: Node being looked for scheduling slave2:42768 availableResource: <memory:4096, vCores:1>
2019-06-07 07:58:30,395 DEBUG org.apache.hadoop.yarn.server.resourcemanager.scheduler.capacity.CapacityScheduler: Trying to schedule on node: slave2, available: <memory:4096, vCores:1>
2019-06-07 07:58:30,395 DEBUG org.apache.hadoop.yarn.server.resourcemanager.scheduler.capacity.CapacityScheduler: Trying to schedule on node: slave2, available: <memory:4096, vCores:1>
2019-06-07 07:58:30,395 DEBUG org.apache.hadoop.yarn.server.resourcemanager.scheduler.capacity.ParentQueue: Skip this queue=root, because it doesn't need more resource, schedulingMode=RESPECT_PARTITION_EXCLUSIVITY node-partition=
2019-06-07 07:58:30,395 DEBUG org.apache.hadoop.yarn.server.resourcemanager.scheduler.capacity.ParentQueue: Skip this queue=root, because it doesn't need more resource, schedulingMode=RESPECT_PARTITION_EXCLUSIVITY node-partition=
2019-06-07 07:58:30,846 DEBUG org.apache.hadoop.yarn.server.resourcemanager.rmnode.RMNodeImpl: Processing slave1:34830 of type STATUS_UPDATE
2019-06-07 07:58:30,846 DEBUG org.apache.hadoop.yarn.server.resourcemanager.rmnode.RMNodeImpl: Processing slave1:34830 of type STATUS_UPDATE
2019-06-07 07:58:30,846 DEBUG org.apache.hadoop.yarn.server.resourcemanager.scheduler.capacity.CapacityScheduler: nodeUpdate: slave1:34830 clusterResources: <memory:8192, vCores:2>
2019-06-07 07:58:30,846 DEBUG org.apache.hadoop.yarn.server.resourcemanager.scheduler.capacity.CapacityScheduler: nodeUpdate: slave1:34830 clusterResources: <memory:8192, vCores:2>
2019-06-07 07:58:30,846 DEBUG org.apache.hadoop.yarn.server.resourcemanager.scheduler.capacity.CapacityScheduler: Node being looked for scheduling slave1:34830 availableResource: <memory:4096, vCores:1>
2019-06-07 07:58:30,846 DEBUG org.apache.hadoop.yarn.server.resourcemanager.scheduler.capacity.CapacityScheduler: Node being looked for scheduling slave1:34830 availableResource: <memory:4096, vCores:1>
2019-06-07 07:58:30,846 DEBUG org.apache.hadoop.yarn.server.resourcemanager.scheduler.capacity.CapacityScheduler: Trying to schedule on node: slave1, available: <memory:4096, vCores:1>
2019-06-07 07:58:30,846 DEBUG org.apache.hadoop.yarn.server.resourcemanager.scheduler.capacity.CapacityScheduler: Trying to schedule on node: slave1, available: <memory:4096, vCores:1>
2019-06-07 07:58:30,846 DEBUG org.apache.hadoop.yarn.server.resourcemanager.scheduler.capacity.ParentQueue: Skip this queue=root, because it doesn't need more resource, schedulingMode=RESPECT_PARTITION_EXCLUSIVITY node-partition=
2019-06-07 07:58:30,846 DEBUG org.apache.hadoop.yarn.server.resourcemanager.scheduler.capacity.ParentQueue: Skip this queue=root, because it doesn't need more resource, schedulingMode=RESPECT_PARTITION_EXCLUSIVITY node-partition=
2019-06-07 07:58:31,400 DEBUG org.apache.hadoop.yarn.server.resourcemanager.rmnode.RMNodeImpl: Processing slave2:42768 of type STATUS_UPDATE
2019-06-07 07:58:31,400 DEBUG org.apache.hadoop.yarn.server.resourcemanager.rmnode.RMNodeImpl: Processing slave2:42768 of type STATUS_UPDATE
2019-06-07 07:58:31,400 DEBUG org.apache.hadoop.yarn.server.resourcemanager.scheduler.capacity.CapacityScheduler: nodeUpdate: slave2:42768 clusterResources: <memory:8192, vCores:2>
2019-06-07 07:58:31,400 DEBUG org.apache.hadoop.yarn.server.resourcemanager.scheduler.capacity.CapacityScheduler: nodeUpdate: slave2:42768 clusterResources: <memory:8192, vCores:2>
2019-06-07 07:58:31,400 DEBUG org.apache.hadoop.yarn.server.resourcemanager.scheduler.capacity.CapacityScheduler: Node being looked for scheduling slave2:42768 availableResource: <memory:4096, vCores:1>
