2019-06-07 07:51:39,750 INFO org.apache.hadoop.yarn.server.resourcemanager.ResourceManager: STARTUP_MSG: 
/************************************************************
STARTUP_MSG: Starting ResourceManager
STARTUP_MSG:   user = root
STARTUP_MSG:   host = master/172.17.0.2
STARTUP_MSG:   args = []
STARTUP_MSG:   version = 2.8.5
STARTUP_MSG:   build = https://git-wip-us.apache.org/repos/asf/hadoop.git -r 0b8464d75227fcee2c6e7f2410377b3d53d3d5f8; compiled by 'jdu' on 2018-09-10T03:32Z
STARTUP_MSG:   java = 1.8.0_191
************************************************************/
2019-06-07 07:51:39,750 INFO org.apache.hadoop.yarn.server.resourcemanager.ResourceManager: STARTUP_MSG: 
/************************************************************
STARTUP_MSG: Starting ResourceManager
STARTUP_MSG:   user = root
STARTUP_MSG:   host = master/172.17.0.2
STARTUP_MSG:   args = []
STARTUP_MSG:   version = 2.8.5
STARTUP_MSG:   build = https://git-wip-us.apache.org/repos/asf/hadoop.git -r 0b8464d75227fcee2c6e7f2410377b3d53d3d5f8; compiled by 'jdu' on 2018-09-10T03:32Z
STARTUP_MSG:   java = 1.8.0_191
************************************************************/
2019-06-07 07:51:39,758 INFO org.apache.hadoop.yarn.server.resourcemanager.ResourceManager: registered UNIX signal handlers for [TERM, HUP, INT]
2019-06-07 07:51:39,758 INFO org.apache.hadoop.yarn.server.resourcemanager.ResourceManager: registered UNIX signal handlers for [TERM, HUP, INT]
2019-06-07 07:51:40,021 INFO org.apache.hadoop.conf.Configuration: found resource core-site.xml at file:/hadoop-2.8.5/etc/hadoop/core-site.xml
2019-06-07 07:51:40,141 WARN org.apache.hadoop.conf.Configuration: core-site.xml:an attempt to override final parameter: fs.defaultFS;  Ignoring.
2019-06-07 07:51:40,172 INFO org.apache.hadoop.security.Groups: clearing userToGroupsMap cache
2019-06-07 07:51:40,253 INFO org.apache.hadoop.conf.Configuration: found resource yarn-site.xml at file:/hadoop-2.8.5/etc/hadoop/yarn-site.xml
2019-06-07 07:51:40,478 INFO org.apache.hadoop.yarn.event.AsyncDispatcher: Registering class org.apache.hadoop.yarn.server.resourcemanager.RMFatalEventType for class org.apache.hadoop.yarn.server.resourcemanager.ResourceManager$RMFatalEventDispatcher
2019-06-07 07:51:40,534 INFO org.apache.hadoop.yarn.server.resourcemanager.security.NMTokenSecretManagerInRM: NMTokenKeyRollingInterval: 86400000ms and NMTokenKeyActivationDelay: 900000ms
2019-06-07 07:51:40,534 INFO org.apache.hadoop.yarn.server.resourcemanager.security.NMTokenSecretManagerInRM: NMTokenKeyRollingInterval: 86400000ms and NMTokenKeyActivationDelay: 900000ms
2019-06-07 07:51:40,543 INFO org.apache.hadoop.yarn.server.resourcemanager.security.RMContainerTokenSecretManager: ContainerTokenKeyRollingInterval: 86400000ms and ContainerTokenKeyActivationDelay: 900000ms
2019-06-07 07:51:40,543 INFO org.apache.hadoop.yarn.server.resourcemanager.security.RMContainerTokenSecretManager: ContainerTokenKeyRollingInterval: 86400000ms and ContainerTokenKeyActivationDelay: 900000ms
2019-06-07 07:51:40,555 INFO org.apache.hadoop.yarn.server.resourcemanager.security.AMRMTokenSecretManager: AMRMTokenKeyRollingInterval: 86400000ms and AMRMTokenKeyActivationDelay: 900000 ms
2019-06-07 07:51:40,555 INFO org.apache.hadoop.yarn.server.resourcemanager.security.AMRMTokenSecretManager: AMRMTokenKeyRollingInterval: 86400000ms and AMRMTokenKeyActivationDelay: 900000 ms
2019-06-07 07:51:40,595 INFO org.apache.hadoop.yarn.event.AsyncDispatcher: Registering class org.apache.hadoop.yarn.server.resourcemanager.recovery.RMStateStoreEventType for class org.apache.hadoop.yarn.server.resourcemanager.recovery.RMStateStore$ForwardingEventHandler
2019-06-07 07:51:40,598 INFO org.apache.hadoop.yarn.event.AsyncDispatcher: Registering class org.apache.hadoop.yarn.server.resourcemanager.NodesListManagerEventType for class org.apache.hadoop.yarn.server.resourcemanager.NodesListManager
2019-06-07 07:51:40,598 INFO org.apache.hadoop.yarn.server.resourcemanager.ResourceManager: Using Scheduler: org.apache.hadoop.yarn.server.resourcemanager.scheduler.capacity.CapacityScheduler
2019-06-07 07:51:40,598 INFO org.apache.hadoop.yarn.server.resourcemanager.ResourceManager: Using Scheduler: org.apache.hadoop.yarn.server.resourcemanager.scheduler.capacity.CapacityScheduler
2019-06-07 07:51:40,638 INFO org.apache.hadoop.yarn.event.AsyncDispatcher: Registering class org.apache.hadoop.yarn.server.resourcemanager.scheduler.event.SchedulerEventType for class org.apache.hadoop.yarn.server.resourcemanager.ResourceManager$SchedulerEventDispatcher
2019-06-07 07:51:40,639 INFO org.apache.hadoop.yarn.event.AsyncDispatcher: Registering class org.apache.hadoop.yarn.server.resourcemanager.rmapp.RMAppEventType for class org.apache.hadoop.yarn.server.resourcemanager.ResourceManager$ApplicationEventDispatcher
2019-06-07 07:51:40,641 INFO org.apache.hadoop.yarn.event.AsyncDispatcher: Registering class org.apache.hadoop.yarn.server.resourcemanager.rmapp.attempt.RMAppAttemptEventType for class org.apache.hadoop.yarn.server.resourcemanager.ResourceManager$ApplicationAttemptEventDispatcher
2019-06-07 07:51:40,643 INFO org.apache.hadoop.yarn.event.AsyncDispatcher: Registering class org.apache.hadoop.yarn.server.resourcemanager.rmnode.RMNodeEventType for class org.apache.hadoop.yarn.server.resourcemanager.ResourceManager$NodeEventDispatcher
2019-06-07 07:51:40,722 INFO org.apache.hadoop.metrics2.impl.MetricsConfig: loaded properties from hadoop-metrics2.properties
2019-06-07 07:51:40,877 INFO org.apache.hadoop.metrics2.impl.MetricsSystemImpl: Scheduled Metric snapshot period at 10 second(s).
2019-06-07 07:51:40,877 INFO org.apache.hadoop.metrics2.impl.MetricsSystemImpl: ResourceManager metrics system started
2019-06-07 07:51:40,905 INFO org.apache.hadoop.yarn.event.AsyncDispatcher: Registering class org.apache.hadoop.yarn.server.resourcemanager.RMAppManagerEventType for class org.apache.hadoop.yarn.server.resourcemanager.RMAppManager
2019-06-07 07:51:40,937 INFO org.apache.hadoop.yarn.event.AsyncDispatcher: Registering class org.apache.hadoop.yarn.server.resourcemanager.amlauncher.AMLauncherEventType for class org.apache.hadoop.yarn.server.resourcemanager.amlauncher.ApplicationMasterLauncher
2019-06-07 07:51:40,947 INFO org.apache.hadoop.yarn.server.resourcemanager.RMNMInfo: Registered RMNMInfo MBean
2019-06-07 07:51:40,947 INFO org.apache.hadoop.yarn.server.resourcemanager.RMNMInfo: Registered RMNMInfo MBean
2019-06-07 07:51:40,953 INFO org.apache.hadoop.yarn.security.YarnAuthorizationProvider: org.apache.hadoop.yarn.security.ConfiguredYarnAuthorizer is instiantiated.
2019-06-07 07:51:40,971 INFO org.apache.hadoop.util.HostsFileReader: Refreshing hosts (include/exclude) list
2019-06-07 07:51:40,971 DEBUG org.apache.hadoop.yarn.server.resourcemanager.NodesListManager: hostsReader: in= out=
2019-06-07 07:51:40,971 DEBUG org.apache.hadoop.yarn.server.resourcemanager.NodesListManager: hostsReader: in= out=
2019-06-07 07:51:40,987 INFO org.apache.hadoop.conf.Configuration: found resource capacity-scheduler.xml at file:/hadoop-2.8.5/etc/hadoop/capacity-scheduler.xml
2019-06-07 07:51:41,051 DEBUG org.apache.hadoop.yarn.server.resourcemanager.scheduler.capacity.CapacitySchedulerConfiguration: CSConf - getQueues called for: queuePrefix=yarn.scheduler.capacity.root.
2019-06-07 07:51:41,051 DEBUG org.apache.hadoop.yarn.server.resourcemanager.scheduler.capacity.CapacitySchedulerConfiguration: CSConf - getQueues called for: queuePrefix=yarn.scheduler.capacity.root.
2019-06-07 07:51:41,051 DEBUG org.apache.hadoop.yarn.server.resourcemanager.scheduler.capacity.CapacitySchedulerConfiguration: CSConf - getQueues: queuePrefix=yarn.scheduler.capacity.root., queues=default
2019-06-07 07:51:41,051 DEBUG org.apache.hadoop.yarn.server.resourcemanager.scheduler.capacity.CapacitySchedulerConfiguration: CSConf - getQueues: queuePrefix=yarn.scheduler.capacity.root., queues=default
2019-06-07 07:51:41,114 DEBUG org.apache.hadoop.yarn.server.resourcemanager.scheduler.capacity.CapacitySchedulerConfiguration: CSConf - getCapacity: queuePrefix=yarn.scheduler.capacity.root., capacity=100.0
2019-06-07 07:51:41,114 DEBUG org.apache.hadoop.yarn.server.resourcemanager.scheduler.capacity.CapacitySchedulerConfiguration: CSConf - getCapacity: queuePrefix=yarn.scheduler.capacity.root., capacity=100.0
2019-06-07 07:51:41,117 DEBUG org.apache.hadoop.yarn.server.resourcemanager.scheduler.capacity.CapacitySchedulerConfiguration: CSConf - getCapacity: queuePrefix=yarn.scheduler.capacity.root., capacity=100.0
2019-06-07 07:51:41,117 DEBUG org.apache.hadoop.yarn.server.resourcemanager.scheduler.capacity.CapacitySchedulerConfiguration: CSConf - getCapacity: queuePrefix=yarn.scheduler.capacity.root., capacity=100.0
2019-06-07 07:51:41,127 DEBUG org.apache.hadoop.yarn.server.resourcemanager.scheduler.capacity.CapacitySchedulerConfiguration: max alloc mb per queue for root is -1
2019-06-07 07:51:41,127 DEBUG org.apache.hadoop.yarn.server.resourcemanager.scheduler.capacity.CapacitySchedulerConfiguration: max alloc mb per queue for root is -1
2019-06-07 07:51:41,127 DEBUG org.apache.hadoop.yarn.server.resourcemanager.scheduler.capacity.CapacitySchedulerConfiguration: max alloc vcores per queue for root is -1
2019-06-07 07:51:41,127 DEBUG org.apache.hadoop.yarn.server.resourcemanager.scheduler.capacity.CapacitySchedulerConfiguration: max alloc vcores per queue for root is -1
2019-06-07 07:51:41,127 INFO org.apache.hadoop.yarn.server.resourcemanager.scheduler.capacity.CapacitySchedulerConfiguration: max alloc mb per queue for root is undefined
2019-06-07 07:51:41,127 INFO org.apache.hadoop.yarn.server.resourcemanager.scheduler.capacity.CapacitySchedulerConfiguration: max alloc mb per queue for root is undefined
2019-06-07 07:51:41,127 INFO org.apache.hadoop.yarn.server.resourcemanager.scheduler.capacity.CapacitySchedulerConfiguration: max alloc vcore per queue for root is undefined
2019-06-07 07:51:41,127 INFO org.apache.hadoop.yarn.server.resourcemanager.scheduler.capacity.CapacitySchedulerConfiguration: max alloc vcore per queue for root is undefined
2019-06-07 07:51:41,156 INFO org.apache.hadoop.yarn.server.resourcemanager.scheduler.capacity.ParentQueue: root, capacity=1.0, asboluteCapacity=1.0, maxCapacity=1.0, asboluteMaxCapacity=1.0, state=RUNNING, acls=ADMINISTER_QUEUE:*SUBMIT_APP:*, labels=*,, offswitchPerHeartbeatLimit = 1, reservationsContinueLooking=true
2019-06-07 07:51:41,156 INFO org.apache.hadoop.yarn.server.resourcemanager.scheduler.capacity.ParentQueue: root, capacity=1.0, asboluteCapacity=1.0, maxCapacity=1.0, asboluteMaxCapacity=1.0, state=RUNNING, acls=ADMINISTER_QUEUE:*SUBMIT_APP:*, labels=*,, offswitchPerHeartbeatLimit = 1, reservationsContinueLooking=true
2019-06-07 07:51:41,157 INFO org.apache.hadoop.yarn.server.resourcemanager.scheduler.capacity.ParentQueue: Initialized parent-queue root name=root, fullname=root
2019-06-07 07:51:41,157 INFO org.apache.hadoop.yarn.server.resourcemanager.scheduler.capacity.ParentQueue: Initialized parent-queue root name=root, fullname=root
2019-06-07 07:51:41,157 DEBUG org.apache.hadoop.yarn.server.resourcemanager.scheduler.capacity.CapacitySchedulerConfiguration: CSConf - getQueues called for: queuePrefix=yarn.scheduler.capacity.root.default.
2019-06-07 07:51:41,157 DEBUG org.apache.hadoop.yarn.server.resourcemanager.scheduler.capacity.CapacitySchedulerConfiguration: CSConf - getQueues called for: queuePrefix=yarn.scheduler.capacity.root.default.
2019-06-07 07:51:41,157 DEBUG org.apache.hadoop.yarn.server.resourcemanager.scheduler.capacity.CapacitySchedulerConfiguration: CSConf - getQueues: queuePrefix=yarn.scheduler.capacity.root.default., queues=
2019-06-07 07:51:41,157 DEBUG org.apache.hadoop.yarn.server.resourcemanager.scheduler.capacity.CapacitySchedulerConfiguration: CSConf - getQueues: queuePrefix=yarn.scheduler.capacity.root.default., queues=
2019-06-07 07:51:41,196 DEBUG org.apache.hadoop.yarn.server.resourcemanager.scheduler.capacity.LeafQueue: LeafQueue: name=default, fullname=root.default
2019-06-07 07:51:41,196 DEBUG org.apache.hadoop.yarn.server.resourcemanager.scheduler.capacity.LeafQueue: LeafQueue: name=default, fullname=root.default
2019-06-07 07:51:41,196 DEBUG org.apache.hadoop.yarn.server.resourcemanager.scheduler.capacity.CapacitySchedulerConfiguration: CSConf - getCapacity: queuePrefix=yarn.scheduler.capacity.root.default., capacity=100.0
2019-06-07 07:51:41,196 DEBUG org.apache.hadoop.yarn.server.resourcemanager.scheduler.capacity.CapacitySchedulerConfiguration: CSConf - getCapacity: queuePrefix=yarn.scheduler.capacity.root.default., capacity=100.0
2019-06-07 07:51:41,197 DEBUG org.apache.hadoop.yarn.server.resourcemanager.scheduler.capacity.CapacitySchedulerConfiguration: max alloc mb per queue for root.default is -1
2019-06-07 07:51:41,197 DEBUG org.apache.hadoop.yarn.server.resourcemanager.scheduler.capacity.CapacitySchedulerConfiguration: max alloc mb per queue for root.default is -1
2019-06-07 07:51:41,199 DEBUG org.apache.hadoop.yarn.server.resourcemanager.scheduler.capacity.CapacitySchedulerConfiguration: max alloc vcores per queue for root.default is -1
2019-06-07 07:51:41,199 DEBUG org.apache.hadoop.yarn.server.resourcemanager.scheduler.capacity.CapacitySchedulerConfiguration: max alloc vcores per queue for root.default is -1
2019-06-07 07:51:41,199 INFO org.apache.hadoop.yarn.server.resourcemanager.scheduler.capacity.CapacitySchedulerConfiguration: max alloc mb per queue for root.default is undefined
2019-06-07 07:51:41,199 INFO org.apache.hadoop.yarn.server.resourcemanager.scheduler.capacity.CapacitySchedulerConfiguration: max alloc mb per queue for root.default is undefined
2019-06-07 07:51:41,203 INFO org.apache.hadoop.yarn.server.resourcemanager.scheduler.capacity.CapacitySchedulerConfiguration: max alloc vcore per queue for root.default is undefined
2019-06-07 07:51:41,203 INFO org.apache.hadoop.yarn.server.resourcemanager.scheduler.capacity.CapacitySchedulerConfiguration: max alloc vcore per queue for root.default is undefined
2019-06-07 07:51:41,209 INFO org.apache.hadoop.yarn.server.resourcemanager.scheduler.capacity.LeafQueue: Initializing default
capacity = 1.0 [= (float) configuredCapacity / 100 ]
asboluteCapacity = 1.0 [= parentAbsoluteCapacity * capacity ]
maxCapacity = 1.0 [= configuredMaxCapacity ]
absoluteMaxCapacity = 1.0 [= 1.0 maximumCapacity undefined, (parentAbsoluteMaxCapacity * maximumCapacity) / 100 otherwise ]
userLimit = 100 [= configuredUserLimit ]
userLimitFactor = 1.0 [= configuredUserLimitFactor ]
maxApplications = 10000 [= configuredMaximumSystemApplicationsPerQueue or (int)(configuredMaximumSystemApplications * absoluteCapacity)]
maxApplicationsPerUser = 10000 [= (int)(maxApplications * (userLimit / 100.0f) * userLimitFactor) ]
usedCapacity = 0.0 [= usedResourcesMemory / (clusterResourceMemory * absoluteCapacity)]
absoluteUsedCapacity = 0.0 [= usedResourcesMemory / clusterResourceMemory]
maxAMResourcePerQueuePercent = 0.1 [= configuredMaximumAMResourcePercent ]
minimumAllocationFactor = 0.875 [= (float)(maximumAllocationMemory - minimumAllocationMemory) / maximumAllocationMemory ]
maximumAllocation = <memory:8192, vCores:4> [= configuredMaxAllocation ]
numContainers = 0 [= currentNumContainers ]
state = RUNNING [= configuredState ]
acls = ADMINISTER_QUEUE:*SUBMIT_APP:* [= configuredAcls ]
nodeLocalityDelay = 40
labels=*,
reservationsContinueLooking = true
preemptionDisabled = true
defaultAppPriorityPerQueue = 0
2019-06-07 07:51:41,209 INFO org.apache.hadoop.yarn.server.resourcemanager.scheduler.capacity.LeafQueue: Initializing default
capacity = 1.0 [= (float) configuredCapacity / 100 ]
asboluteCapacity = 1.0 [= parentAbsoluteCapacity * capacity ]
maxCapacity = 1.0 [= configuredMaxCapacity ]
absoluteMaxCapacity = 1.0 [= 1.0 maximumCapacity undefined, (parentAbsoluteMaxCapacity * maximumCapacity) / 100 otherwise ]
userLimit = 100 [= configuredUserLimit ]
userLimitFactor = 1.0 [= configuredUserLimitFactor ]
maxApplications = 10000 [= configuredMaximumSystemApplicationsPerQueue or (int)(configuredMaximumSystemApplications * absoluteCapacity)]
maxApplicationsPerUser = 10000 [= (int)(maxApplications * (userLimit / 100.0f) * userLimitFactor) ]
usedCapacity = 0.0 [= usedResourcesMemory / (clusterResourceMemory * absoluteCapacity)]
absoluteUsedCapacity = 0.0 [= usedResourcesMemory / clusterResourceMemory]
maxAMResourcePerQueuePercent = 0.1 [= configuredMaximumAMResourcePercent ]
minimumAllocationFactor = 0.875 [= (float)(maximumAllocationMemory - minimumAllocationMemory) / maximumAllocationMemory ]
maximumAllocation = <memory:8192, vCores:4> [= configuredMaxAllocation ]
numContainers = 0 [= currentNumContainers ]
state = RUNNING [= configuredState ]
acls = ADMINISTER_QUEUE:*SUBMIT_APP:* [= configuredAcls ]
nodeLocalityDelay = 40
labels=*,
reservationsContinueLooking = true
preemptionDisabled = true
defaultAppPriorityPerQueue = 0
2019-06-07 07:51:41,210 INFO org.apache.hadoop.yarn.server.resourcemanager.scheduler.capacity.CapacityScheduler: Initialized queue: default: capacity=1.0, absoluteCapacity=1.0, usedResources=<memory:0, vCores:0>, usedCapacity=0.0, absoluteUsedCapacity=0.0, numApps=0, numContainers=0
2019-06-07 07:51:41,210 INFO org.apache.hadoop.yarn.server.resourcemanager.scheduler.capacity.CapacityScheduler: Initialized queue: default: capacity=1.0, absoluteCapacity=1.0, usedResources=<memory:0, vCores:0>, usedCapacity=0.0, absoluteUsedCapacity=0.0, numApps=0, numContainers=0
2019-06-07 07:51:41,219 DEBUG org.apache.hadoop.yarn.server.resourcemanager.scheduler.capacity.ParentQueue: setChildQueues: root.defaultusedCapacity=(0.0),  label=(*)
2019-06-07 07:51:41,219 DEBUG org.apache.hadoop.yarn.server.resourcemanager.scheduler.capacity.ParentQueue: setChildQueues: root.defaultusedCapacity=(0.0),  label=(*)
2019-06-07 07:51:41,220 INFO org.apache.hadoop.yarn.server.resourcemanager.scheduler.capacity.CapacityScheduler: Initialized queue: root: numChildQueue= 1, capacity=1.0, absoluteCapacity=1.0, usedResources=<memory:0, vCores:0>usedCapacity=0.0, numApps=0, numContainers=0
2019-06-07 07:51:41,220 INFO org.apache.hadoop.yarn.server.resourcemanager.scheduler.capacity.CapacityScheduler: Initialized queue: root: numChildQueue= 1, capacity=1.0, absoluteCapacity=1.0, usedResources=<memory:0, vCores:0>usedCapacity=0.0, numApps=0, numContainers=0
2019-06-07 07:51:41,224 INFO org.apache.hadoop.yarn.server.resourcemanager.scheduler.capacity.CapacityScheduler: Initialized root queue root: numChildQueue= 1, capacity=1.0, absoluteCapacity=1.0, usedResources=<memory:0, vCores:0>usedCapacity=0.0, numApps=0, numContainers=0
2019-06-07 07:51:41,224 INFO org.apache.hadoop.yarn.server.resourcemanager.scheduler.capacity.CapacityScheduler: Initialized root queue root: numChildQueue= 1, capacity=1.0, absoluteCapacity=1.0, usedResources=<memory:0, vCores:0>usedCapacity=0.0, numApps=0, numContainers=0
2019-06-07 07:51:41,225 INFO org.apache.hadoop.yarn.server.resourcemanager.scheduler.capacity.CapacityScheduler: Initialized queue mappings, override: false
2019-06-07 07:51:41,225 INFO org.apache.hadoop.yarn.server.resourcemanager.scheduler.capacity.CapacityScheduler: Initialized queue mappings, override: false
2019-06-07 07:51:41,226 INFO org.apache.hadoop.yarn.server.resourcemanager.scheduler.capacity.CapacityScheduler: Initialized CapacityScheduler with calculator=class org.apache.hadoop.yarn.util.resource.DefaultResourceCalculator, minimumAllocation=<<memory:1024, vCores:1>>, maximumAllocation=<<memory:8192, vCores:4>>, asynchronousScheduling=false, asyncScheduleInterval=5ms
2019-06-07 07:51:41,226 INFO org.apache.hadoop.yarn.server.resourcemanager.scheduler.capacity.CapacityScheduler: Initialized CapacityScheduler with calculator=class org.apache.hadoop.yarn.util.resource.DefaultResourceCalculator, minimumAllocation=<<memory:1024, vCores:1>>, maximumAllocation=<<memory:8192, vCores:4>>, asynchronousScheduling=false, asyncScheduleInterval=5ms
2019-06-07 07:51:41,255 INFO org.apache.hadoop.conf.Configuration: dynamic-resources.xml not found
2019-06-07 07:51:41,298 INFO org.apache.hadoop.yarn.server.resourcemanager.metrics.SystemMetricsPublisher: YARN system metrics publishing service is not enabled
2019-06-07 07:51:41,298 INFO org.apache.hadoop.yarn.server.resourcemanager.metrics.SystemMetricsPublisher: YARN system metrics publishing service is not enabled
2019-06-07 07:51:41,298 INFO org.apache.hadoop.yarn.server.resourcemanager.ResourceManager: Transitioning to active state
2019-06-07 07:51:41,298 INFO org.apache.hadoop.yarn.server.resourcemanager.ResourceManager: Transitioning to active state
2019-06-07 07:51:41,367 INFO org.apache.hadoop.util.JvmPauseMonitor: Starting JVM pause monitor
2019-06-07 07:51:41,407 DEBUG org.apache.hadoop.yarn.server.resourcemanager.recovery.RMStateStore: Processing event of type UPDATE_AMRM_TOKEN
2019-06-07 07:51:41,407 DEBUG org.apache.hadoop.yarn.server.resourcemanager.recovery.RMStateStore: Processing event of type UPDATE_AMRM_TOKEN
2019-06-07 07:51:41,407 INFO org.apache.hadoop.yarn.server.resourcemanager.recovery.RMStateStore: Updating AMRMToken
2019-06-07 07:51:41,407 INFO org.apache.hadoop.yarn.server.resourcemanager.recovery.RMStateStore: Updating AMRMToken
2019-06-07 07:51:41,407 INFO org.apache.hadoop.yarn.server.resourcemanager.security.RMContainerTokenSecretManager: Rolling master-key for container-tokens
2019-06-07 07:51:41,407 INFO org.apache.hadoop.yarn.server.resourcemanager.security.RMContainerTokenSecretManager: Rolling master-key for container-tokens
2019-06-07 07:51:41,408 INFO org.apache.hadoop.yarn.server.resourcemanager.security.NMTokenSecretManagerInRM: Rolling master-key for nm-tokens
2019-06-07 07:51:41,408 INFO org.apache.hadoop.yarn.server.resourcemanager.security.NMTokenSecretManagerInRM: Rolling master-key for nm-tokens
2019-06-07 07:51:41,408 INFO org.apache.hadoop.security.token.delegation.AbstractDelegationTokenSecretManager: Updating the current master key for generating delegation tokens
2019-06-07 07:51:41,408 INFO org.apache.hadoop.yarn.server.resourcemanager.security.RMDelegationTokenSecretManager: storing master key with keyID 1
2019-06-07 07:51:41,408 INFO org.apache.hadoop.yarn.server.resourcemanager.security.RMDelegationTokenSecretManager: storing master key with keyID 1
2019-06-07 07:51:41,409 DEBUG org.apache.hadoop.yarn.server.resourcemanager.recovery.RMStateStore: Processing event of type STORE_MASTERKEY
2019-06-07 07:51:41,409 DEBUG org.apache.hadoop.yarn.server.resourcemanager.recovery.RMStateStore: Processing event of type STORE_MASTERKEY
2019-06-07 07:51:41,409 INFO org.apache.hadoop.yarn.server.resourcemanager.recovery.RMStateStore: Storing RMDTMasterKey.
2019-06-07 07:51:41,409 INFO org.apache.hadoop.yarn.server.resourcemanager.recovery.RMStateStore: Storing RMDTMasterKey.
2019-06-07 07:51:41,420 INFO org.apache.hadoop.security.token.delegation.AbstractDelegationTokenSecretManager: Starting expired delegation token remover thread, tokenRemoverScanInterval=60 min(s)
2019-06-07 07:51:41,420 INFO org.apache.hadoop.security.token.delegation.AbstractDelegationTokenSecretManager: Updating the current master key for generating delegation tokens
2019-06-07 07:51:41,420 INFO org.apache.hadoop.yarn.server.resourcemanager.security.RMDelegationTokenSecretManager: storing master key with keyID 2
2019-06-07 07:51:41,420 INFO org.apache.hadoop.yarn.server.resourcemanager.security.RMDelegationTokenSecretManager: storing master key with keyID 2
2019-06-07 07:51:41,420 DEBUG org.apache.hadoop.yarn.server.resourcemanager.recovery.RMStateStore: Processing event of type STORE_MASTERKEY
2019-06-07 07:51:41,420 DEBUG org.apache.hadoop.yarn.server.resourcemanager.recovery.RMStateStore: Processing event of type STORE_MASTERKEY
2019-06-07 07:51:41,420 INFO org.apache.hadoop.yarn.server.resourcemanager.recovery.RMStateStore: Storing RMDTMasterKey.
2019-06-07 07:51:41,420 INFO org.apache.hadoop.yarn.server.resourcemanager.recovery.RMStateStore: Storing RMDTMasterKey.
2019-06-07 07:51:41,439 INFO org.apache.hadoop.yarn.event.AsyncDispatcher: Registering class org.apache.hadoop.yarn.nodelabels.event.NodeLabelsStoreEventType for class org.apache.hadoop.yarn.nodelabels.CommonNodeLabelsManager$ForwardingEventHandler
2019-06-07 07:51:41,583 INFO org.apache.hadoop.ipc.CallQueueManager: Using callQueue: class java.util.concurrent.LinkedBlockingQueue queueCapacity: 5000 scheduler: class org.apache.hadoop.ipc.DefaultRpcScheduler
2019-06-07 07:51:41,644 INFO org.apache.hadoop.ipc.Server: Starting Socket Reader #1 for port 8031
2019-06-07 07:51:42,236 INFO org.apache.hadoop.yarn.factories.impl.pb.RpcServerFactoryPBImpl: Adding protocol org.apache.hadoop.yarn.server.api.ResourceTrackerPB to the server
2019-06-07 07:51:42,237 INFO org.apache.hadoop.ipc.Server: IPC Server Responder: starting
2019-06-07 07:51:42,238 INFO org.apache.hadoop.ipc.Server: IPC Server listener on 8031: starting
2019-06-07 07:51:42,486 INFO org.apache.hadoop.ipc.CallQueueManager: Using callQueue: class java.util.concurrent.LinkedBlockingQueue queueCapacity: 5000 scheduler: class org.apache.hadoop.ipc.DefaultRpcScheduler
2019-06-07 07:51:42,580 INFO org.apache.hadoop.ipc.Server: Starting Socket Reader #1 for port 8030
2019-06-07 07:51:42,683 INFO org.apache.hadoop.yarn.factories.impl.pb.RpcServerFactoryPBImpl: Adding protocol org.apache.hadoop.yarn.api.ApplicationMasterProtocolPB to the server
2019-06-07 07:51:42,687 INFO org.apache.hadoop.ipc.Server: IPC Server Responder: starting
2019-06-07 07:51:42,688 INFO org.apache.hadoop.ipc.Server: IPC Server listener on 8030: starting
2019-06-07 07:51:42,966 INFO org.apache.hadoop.ipc.CallQueueManager: Using callQueue: class java.util.concurrent.LinkedBlockingQueue queueCapacity: 5000 scheduler: class org.apache.hadoop.ipc.DefaultRpcScheduler
2019-06-07 07:51:42,988 INFO org.apache.hadoop.ipc.Server: Starting Socket Reader #1 for port 8032
2019-06-07 07:51:43,009 INFO org.apache.hadoop.yarn.factories.impl.pb.RpcServerFactoryPBImpl: Adding protocol org.apache.hadoop.yarn.api.ApplicationClientProtocolPB to the server
2019-06-07 07:51:43,028 INFO org.apache.hadoop.ipc.Server: IPC Server Responder: starting
2019-06-07 07:51:43,040 INFO org.apache.hadoop.ipc.Server: IPC Server listener on 8032: starting
2019-06-07 07:51:43,400 INFO org.apache.hadoop.yarn.server.resourcemanager.ResourceManager: Transitioned to active state
2019-06-07 07:51:43,400 INFO org.apache.hadoop.yarn.server.resourcemanager.ResourceManager: Transitioned to active state
2019-06-07 07:51:43,836 INFO org.mortbay.log: Logging to org.slf4j.impl.Log4jLoggerAdapter(org.mortbay.log) via org.mortbay.log.Slf4jLog
2019-06-07 07:51:43,884 INFO org.apache.hadoop.security.authentication.server.AuthenticationFilter: Unable to initialize FileSignerSecretProvider, falling back to use random secrets.
2019-06-07 07:51:43,912 INFO org.apache.hadoop.http.HttpRequestLog: Http request log for http.requests.resourcemanager is not defined
2019-06-07 07:51:43,952 INFO org.apache.hadoop.http.HttpServer2: Added global filter 'safety' (class=org.apache.hadoop.http.HttpServer2$QuotingInputFilter)
2019-06-07 07:51:43,983 INFO org.apache.hadoop.http.HttpServer2: Added filter RMAuthenticationFilter (class=org.apache.hadoop.yarn.server.security.http.RMAuthenticationFilter) to context cluster
2019-06-07 07:51:43,983 INFO org.apache.hadoop.http.HttpServer2: Added filter RMAuthenticationFilter (class=org.apache.hadoop.yarn.server.security.http.RMAuthenticationFilter) to context logs
2019-06-07 07:51:43,983 INFO org.apache.hadoop.http.HttpServer2: Added filter RMAuthenticationFilter (class=org.apache.hadoop.yarn.server.security.http.RMAuthenticationFilter) to context static
2019-06-07 07:51:43,984 INFO org.apache.hadoop.http.HttpServer2: Added filter static_user_filter (class=org.apache.hadoop.http.lib.StaticUserWebFilter$StaticUserFilter) to context cluster
2019-06-07 07:51:43,984 INFO org.apache.hadoop.http.HttpServer2: Added filter static_user_filter (class=org.apache.hadoop.http.lib.StaticUserWebFilter$StaticUserFilter) to context logs
2019-06-07 07:51:43,984 INFO org.apache.hadoop.http.HttpServer2: Added filter static_user_filter (class=org.apache.hadoop.http.lib.StaticUserWebFilter$StaticUserFilter) to context static
2019-06-07 07:51:44,003 INFO org.apache.hadoop.http.HttpServer2: adding path spec: /cluster/*
2019-06-07 07:51:44,004 INFO org.apache.hadoop.http.HttpServer2: adding path spec: /ws/*
2019-06-07 07:51:45,860 INFO org.apache.hadoop.yarn.webapp.WebApps: Registered webapp guice modules
2019-06-07 07:51:45,862 INFO org.apache.hadoop.http.HttpServer2: Jetty bound to port 8088
2019-06-07 07:51:45,862 INFO org.mortbay.log: jetty-6.1.26
2019-06-07 07:51:45,952 INFO org.mortbay.log: Extract jar:file:/hadoop-2.8.5/share/hadoop/yarn/hadoop-yarn-common-2.8.5.jar!/webapps/cluster to /tmp/Jetty_master_8088_cluster____i4ls4w/webapp
2019-06-07 07:51:46,657 INFO org.apache.hadoop.security.token.delegation.AbstractDelegationTokenSecretManager: Updating the current master key for generating delegation tokens
2019-06-07 07:51:46,671 INFO org.apache.hadoop.security.token.delegation.AbstractDelegationTokenSecretManager: Starting expired delegation token remover thread, tokenRemoverScanInterval=60 min(s)
2019-06-07 07:51:46,696 INFO org.apache.hadoop.security.token.delegation.AbstractDelegationTokenSecretManager: Updating the current master key for generating delegation tokens
2019-06-07 07:51:49,889 INFO org.apache.hadoop.yarn.server.resourcemanager.ResourceTrackerService: NodeManager from node slave1(cmPort: 39995 httpPort: 8042) registered with capability: <memory:4096, vCores:1>, assigned nodeId slave1:39995
2019-06-07 07:51:49,889 INFO org.apache.hadoop.yarn.server.resourcemanager.ResourceTrackerService: NodeManager from node slave1(cmPort: 39995 httpPort: 8042) registered with capability: <memory:4096, vCores:1>, assigned nodeId slave1:39995
2019-06-07 07:51:49,904 INFO org.apache.hadoop.yarn.server.resourcemanager.ResourceTrackerService: NodeManager from node slave2(cmPort: 38494 httpPort: 8042) registered with capability: <memory:4096, vCores:1>, assigned nodeId slave2:38494
2019-06-07 07:51:49,904 INFO org.apache.hadoop.yarn.server.resourcemanager.ResourceTrackerService: NodeManager from node slave2(cmPort: 38494 httpPort: 8042) registered with capability: <memory:4096, vCores:1>, assigned nodeId slave2:38494
2019-06-07 07:51:50,233 INFO org.mortbay.log: Started HttpServer2$SelectChannelConnectorWithSafeStartup@master:8088
2019-06-07 07:51:50,233 INFO org.apache.hadoop.yarn.webapp.WebApps: Web app cluster started at 8088
2019-06-07 07:51:50,247 DEBUG org.apache.hadoop.yarn.server.resourcemanager.rmnode.RMNodeImpl: Processing slave1:39995 of type STARTED
2019-06-07 07:51:50,247 DEBUG org.apache.hadoop.yarn.server.resourcemanager.rmnode.RMNodeImpl: Processing slave1:39995 of type STARTED
2019-06-07 07:51:50,256 INFO org.apache.hadoop.yarn.server.resourcemanager.rmnode.RMNodeImpl: slave1:39995 Node Transitioned from NEW to RUNNING
2019-06-07 07:51:50,256 INFO org.apache.hadoop.yarn.server.resourcemanager.rmnode.RMNodeImpl: slave1:39995 Node Transitioned from NEW to RUNNING
2019-06-07 07:51:50,256 DEBUG org.apache.hadoop.yarn.server.resourcemanager.rmnode.RMNodeImpl: Processing slave2:38494 of type STARTED
2019-06-07 07:51:50,256 DEBUG org.apache.hadoop.yarn.server.resourcemanager.rmnode.RMNodeImpl: Processing slave2:38494 of type STARTED
2019-06-07 07:51:50,256 INFO org.apache.hadoop.yarn.server.resourcemanager.rmnode.RMNodeImpl: slave2:38494 Node Transitioned from NEW to RUNNING
2019-06-07 07:51:50,256 INFO org.apache.hadoop.yarn.server.resourcemanager.rmnode.RMNodeImpl: slave2:38494 Node Transitioned from NEW to RUNNING
2019-06-07 07:51:50,256 DEBUG org.apache.hadoop.yarn.server.resourcemanager.rmnode.RMNodeImpl: Processing slave1:39995 of type STATUS_UPDATE
2019-06-07 07:51:50,256 DEBUG org.apache.hadoop.yarn.server.resourcemanager.rmnode.RMNodeImpl: Processing slave1:39995 of type STATUS_UPDATE
2019-06-07 07:51:50,269 DEBUG org.apache.hadoop.yarn.server.resourcemanager.rmnode.RMNodeImpl: Processing slave2:38494 of type STATUS_UPDATE
2019-06-07 07:51:50,269 DEBUG org.apache.hadoop.yarn.server.resourcemanager.rmnode.RMNodeImpl: Processing slave2:38494 of type STATUS_UPDATE
2019-06-07 07:51:50,275 DEBUG org.apache.hadoop.yarn.server.resourcemanager.NodesListManager: slave1:39995 reported usable
2019-06-07 07:51:50,275 DEBUG org.apache.hadoop.yarn.server.resourcemanager.NodesListManager: slave1:39995 reported usable
2019-06-07 07:51:50,276 DEBUG org.apache.hadoop.yarn.server.resourcemanager.NodesListManager: slave2:38494 reported usable
2019-06-07 07:51:50,276 DEBUG org.apache.hadoop.yarn.server.resourcemanager.NodesListManager: slave2:38494 reported usable
2019-06-07 07:51:50,280 INFO org.apache.hadoop.yarn.server.resourcemanager.scheduler.capacity.CapacityScheduler: Added node slave1:39995 clusterResource: <memory:4096, vCores:1>
2019-06-07 07:51:50,280 INFO org.apache.hadoop.yarn.server.resourcemanager.scheduler.capacity.CapacityScheduler: Added node slave1:39995 clusterResource: <memory:4096, vCores:1>
2019-06-07 07:51:50,281 INFO org.apache.hadoop.yarn.server.resourcemanager.scheduler.capacity.CapacityScheduler: Added node slave2:38494 clusterResource: <memory:8192, vCores:2>
2019-06-07 07:51:50,281 INFO org.apache.hadoop.yarn.server.resourcemanager.scheduler.capacity.CapacityScheduler: Added node slave2:38494 clusterResource: <memory:8192, vCores:2>
2019-06-07 07:51:50,281 DEBUG org.apache.hadoop.yarn.server.resourcemanager.scheduler.capacity.CapacityScheduler: nodeUpdate: slave1:39995 clusterResources: <memory:8192, vCores:2>
2019-06-07 07:51:50,281 DEBUG org.apache.hadoop.yarn.server.resourcemanager.scheduler.capacity.CapacityScheduler: nodeUpdate: slave1:39995 clusterResources: <memory:8192, vCores:2>
2019-06-07 07:51:50,282 DEBUG org.apache.hadoop.yarn.server.resourcemanager.scheduler.capacity.CapacityScheduler: Node being looked for scheduling slave1:39995 availableResource: <memory:4096, vCores:1>
2019-06-07 07:51:50,282 DEBUG org.apache.hadoop.yarn.server.resourcemanager.scheduler.capacity.CapacityScheduler: Node being looked for scheduling slave1:39995 availableResource: <memory:4096, vCores:1>
2019-06-07 07:51:50,291 DEBUG org.apache.hadoop.yarn.server.resourcemanager.scheduler.capacity.CapacityScheduler: Trying to schedule on node: slave1, available: <memory:4096, vCores:1>
2019-06-07 07:51:50,291 DEBUG org.apache.hadoop.yarn.server.resourcemanager.scheduler.capacity.CapacityScheduler: Trying to schedule on node: slave1, available: <memory:4096, vCores:1>
2019-06-07 07:51:50,292 DEBUG org.apache.hadoop.yarn.server.resourcemanager.scheduler.capacity.ParentQueue: Skip this queue=root, because it doesn't need more resource, schedulingMode=RESPECT_PARTITION_EXCLUSIVITY node-partition=
2019-06-07 07:51:50,292 DEBUG org.apache.hadoop.yarn.server.resourcemanager.scheduler.capacity.ParentQueue: Skip this queue=root, because it doesn't need more resource, schedulingMode=RESPECT_PARTITION_EXCLUSIVITY node-partition=
2019-06-07 07:51:50,292 DEBUG org.apache.hadoop.yarn.server.resourcemanager.scheduler.capacity.CapacityScheduler: nodeUpdate: slave2:38494 clusterResources: <memory:8192, vCores:2>
2019-06-07 07:51:50,292 DEBUG org.apache.hadoop.yarn.server.resourcemanager.scheduler.capacity.CapacityScheduler: nodeUpdate: slave2:38494 clusterResources: <memory:8192, vCores:2>
2019-06-07 07:51:50,300 DEBUG org.apache.hadoop.yarn.server.resourcemanager.scheduler.capacity.CapacityScheduler: Node being looked for scheduling slave2:38494 availableResource: <memory:4096, vCores:1>
2019-06-07 07:51:50,300 DEBUG org.apache.hadoop.yarn.server.resourcemanager.scheduler.capacity.CapacityScheduler: Node being looked for scheduling slave2:38494 availableResource: <memory:4096, vCores:1>
2019-06-07 07:51:50,300 DEBUG org.apache.hadoop.yarn.server.resourcemanager.scheduler.capacity.CapacityScheduler: Trying to schedule on node: slave2, available: <memory:4096, vCores:1>
2019-06-07 07:51:50,300 DEBUG org.apache.hadoop.yarn.server.resourcemanager.scheduler.capacity.CapacityScheduler: Trying to schedule on node: slave2, available: <memory:4096, vCores:1>
2019-06-07 07:51:50,300 DEBUG org.apache.hadoop.yarn.server.resourcemanager.scheduler.capacity.ParentQueue: Skip this queue=root, because it doesn't need more resource, schedulingMode=RESPECT_PARTITION_EXCLUSIVITY node-partition=
2019-06-07 07:51:50,300 DEBUG org.apache.hadoop.yarn.server.resourcemanager.scheduler.capacity.ParentQueue: Skip this queue=root, because it doesn't need more resource, schedulingMode=RESPECT_PARTITION_EXCLUSIVITY node-partition=
2019-06-07 07:51:50,306 INFO org.apache.hadoop.ipc.CallQueueManager: Using callQueue: class java.util.concurrent.LinkedBlockingQueue queueCapacity: 100 scheduler: class org.apache.hadoop.ipc.DefaultRpcScheduler
2019-06-07 07:51:50,309 INFO org.apache.hadoop.ipc.Server: Starting Socket Reader #1 for port 8033
2019-06-07 07:51:50,313 INFO org.apache.hadoop.yarn.factories.impl.pb.RpcServerFactoryPBImpl: Adding protocol org.apache.hadoop.yarn.server.api.ResourceManagerAdministrationProtocolPB to the server
2019-06-07 07:51:50,315 INFO org.apache.hadoop.ipc.Server: IPC Server Responder: starting
2019-06-07 07:51:50,322 INFO org.apache.hadoop.ipc.Server: IPC Server listener on 8033: starting
2019-06-07 07:51:51,006 DEBUG org.apache.hadoop.yarn.server.resourcemanager.rmnode.RMNodeImpl: Processing slave1:39995 of type STATUS_UPDATE
2019-06-07 07:51:51,006 DEBUG org.apache.hadoop.yarn.server.resourcemanager.rmnode.RMNodeImpl: Processing slave1:39995 of type STATUS_UPDATE
2019-06-07 07:51:51,007 DEBUG org.apache.hadoop.yarn.server.resourcemanager.scheduler.capacity.CapacityScheduler: nodeUpdate: slave1:39995 clusterResources: <memory:8192, vCores:2>
2019-06-07 07:51:51,007 DEBUG org.apache.hadoop.yarn.server.resourcemanager.scheduler.capacity.CapacityScheduler: nodeUpdate: slave1:39995 clusterResources: <memory:8192, vCores:2>
2019-06-07 07:51:51,007 DEBUG org.apache.hadoop.yarn.server.resourcemanager.scheduler.capacity.CapacityScheduler: Node being looked for scheduling slave1:39995 availableResource: <memory:4096, vCores:1>
2019-06-07 07:51:51,007 DEBUG org.apache.hadoop.yarn.server.resourcemanager.scheduler.capacity.CapacityScheduler: Node being looked for scheduling slave1:39995 availableResource: <memory:4096, vCores:1>
2019-06-07 07:51:51,007 DEBUG org.apache.hadoop.yarn.server.resourcemanager.scheduler.capacity.CapacityScheduler: Trying to schedule on node: slave1, available: <memory:4096, vCores:1>
2019-06-07 07:51:51,007 DEBUG org.apache.hadoop.yarn.server.resourcemanager.scheduler.capacity.CapacityScheduler: Trying to schedule on node: slave1, available: <memory:4096, vCores:1>
2019-06-07 07:51:51,008 DEBUG org.apache.hadoop.yarn.server.resourcemanager.scheduler.capacity.ParentQueue: Skip this queue=root, because it doesn't need more resource, schedulingMode=RESPECT_PARTITION_EXCLUSIVITY node-partition=
2019-06-07 07:51:51,008 DEBUG org.apache.hadoop.yarn.server.resourcemanager.scheduler.capacity.ParentQueue: Skip this queue=root, because it doesn't need more resource, schedulingMode=RESPECT_PARTITION_EXCLUSIVITY node-partition=
2019-06-07 07:51:51,012 DEBUG org.apache.hadoop.yarn.server.resourcemanager.rmnode.RMNodeImpl: Processing slave2:38494 of type STATUS_UPDATE
2019-06-07 07:51:51,012 DEBUG org.apache.hadoop.yarn.server.resourcemanager.rmnode.RMNodeImpl: Processing slave2:38494 of type STATUS_UPDATE
2019-06-07 07:51:51,013 DEBUG org.apache.hadoop.yarn.server.resourcemanager.scheduler.capacity.CapacityScheduler: nodeUpdate: slave2:38494 clusterResources: <memory:8192, vCores:2>
2019-06-07 07:51:51,013 DEBUG org.apache.hadoop.yarn.server.resourcemanager.scheduler.capacity.CapacityScheduler: nodeUpdate: slave2:38494 clusterResources: <memory:8192, vCores:2>
2019-06-07 07:51:51,013 DEBUG org.apache.hadoop.yarn.server.resourcemanager.scheduler.capacity.CapacityScheduler: Node being looked for scheduling slave2:38494 availableResource: <memory:4096, vCores:1>
2019-06-07 07:51:51,013 DEBUG org.apache.hadoop.yarn.server.resourcemanager.scheduler.capacity.CapacityScheduler: Node being looked for scheduling slave2:38494 availableResource: <memory:4096, vCores:1>
2019-06-07 07:51:51,013 DEBUG org.apache.hadoop.yarn.server.resourcemanager.scheduler.capacity.CapacityScheduler: Trying to schedule on node: slave2, available: <memory:4096, vCores:1>
2019-06-07 07:51:51,013 DEBUG org.apache.hadoop.yarn.server.resourcemanager.scheduler.capacity.CapacityScheduler: Trying to schedule on node: slave2, available: <memory:4096, vCores:1>
2019-06-07 07:51:51,013 DEBUG org.apache.hadoop.yarn.server.resourcemanager.scheduler.capacity.ParentQueue: Skip this queue=root, because it doesn't need more resource, schedulingMode=RESPECT_PARTITION_EXCLUSIVITY node-partition=
2019-06-07 07:51:51,013 DEBUG org.apache.hadoop.yarn.server.resourcemanager.scheduler.capacity.ParentQueue: Skip this queue=root, because it doesn't need more resource, schedulingMode=RESPECT_PARTITION_EXCLUSIVITY node-partition=
2019-06-07 07:51:52,009 DEBUG org.apache.hadoop.yarn.server.resourcemanager.rmnode.RMNodeImpl: Processing slave1:39995 of type STATUS_UPDATE
2019-06-07 07:51:52,009 DEBUG org.apache.hadoop.yarn.server.resourcemanager.rmnode.RMNodeImpl: Processing slave1:39995 of type STATUS_UPDATE
2019-06-07 07:51:52,010 DEBUG org.apache.hadoop.yarn.server.resourcemanager.scheduler.capacity.CapacityScheduler: nodeUpdate: slave1:39995 clusterResources: <memory:8192, vCores:2>
2019-06-07 07:51:52,010 DEBUG org.apache.hadoop.yarn.server.resourcemanager.scheduler.capacity.CapacityScheduler: nodeUpdate: slave1:39995 clusterResources: <memory:8192, vCores:2>
2019-06-07 07:51:52,010 DEBUG org.apache.hadoop.yarn.server.resourcemanager.scheduler.capacity.CapacityScheduler: Node being looked for scheduling slave1:39995 availableResource: <memory:4096, vCores:1>
2019-06-07 07:51:52,010 DEBUG org.apache.hadoop.yarn.server.resourcemanager.scheduler.capacity.CapacityScheduler: Node being looked for scheduling slave1:39995 availableResource: <memory:4096, vCores:1>
2019-06-07 07:51:52,010 DEBUG org.apache.hadoop.yarn.server.resourcemanager.scheduler.capacity.CapacityScheduler: Trying to schedule on node: slave1, available: <memory:4096, vCores:1>
2019-06-07 07:51:52,010 DEBUG org.apache.hadoop.yarn.server.resourcemanager.scheduler.capacity.CapacityScheduler: Trying to schedule on node: slave1, available: <memory:4096, vCores:1>
2019-06-07 07:51:52,010 DEBUG org.apache.hadoop.yarn.server.resourcemanager.scheduler.capacity.ParentQueue: Skip this queue=root, because it doesn't need more resource, schedulingMode=RESPECT_PARTITION_EXCLUSIVITY node-partition=
2019-06-07 07:51:52,010 DEBUG org.apache.hadoop.yarn.server.resourcemanager.scheduler.capacity.ParentQueue: Skip this queue=root, because it doesn't need more resource, schedulingMode=RESPECT_PARTITION_EXCLUSIVITY node-partition=
2019-06-07 07:51:52,016 DEBUG org.apache.hadoop.yarn.server.resourcemanager.rmnode.RMNodeImpl: Processing slave2:38494 of type STATUS_UPDATE
2019-06-07 07:51:52,016 DEBUG org.apache.hadoop.yarn.server.resourcemanager.rmnode.RMNodeImpl: Processing slave2:38494 of type STATUS_UPDATE
2019-06-07 07:51:52,016 DEBUG org.apache.hadoop.yarn.server.resourcemanager.scheduler.capacity.CapacityScheduler: nodeUpdate: slave2:38494 clusterResources: <memory:8192, vCores:2>
2019-06-07 07:51:52,016 DEBUG org.apache.hadoop.yarn.server.resourcemanager.scheduler.capacity.CapacityScheduler: nodeUpdate: slave2:38494 clusterResources: <memory:8192, vCores:2>
2019-06-07 07:51:52,016 DEBUG org.apache.hadoop.yarn.server.resourcemanager.scheduler.capacity.CapacityScheduler: Node being looked for scheduling slave2:38494 availableResource: <memory:4096, vCores:1>
2019-06-07 07:51:52,016 DEBUG org.apache.hadoop.yarn.server.resourcemanager.scheduler.capacity.CapacityScheduler: Node being looked for scheduling slave2:38494 availableResource: <memory:4096, vCores:1>
2019-06-07 07:51:52,017 DEBUG org.apache.hadoop.yarn.server.resourcemanager.scheduler.capacity.CapacityScheduler: Trying to schedule on node: slave2, available: <memory:4096, vCores:1>
2019-06-07 07:51:52,017 DEBUG org.apache.hadoop.yarn.server.resourcemanager.scheduler.capacity.CapacityScheduler: Trying to schedule on node: slave2, available: <memory:4096, vCores:1>
2019-06-07 07:51:52,017 DEBUG org.apache.hadoop.yarn.server.resourcemanager.scheduler.capacity.ParentQueue: Skip this queue=root, because it doesn't need more resource, schedulingMode=RESPECT_PARTITION_EXCLUSIVITY node-partition=
2019-06-07 07:51:52,017 DEBUG org.apache.hadoop.yarn.server.resourcemanager.scheduler.capacity.ParentQueue: Skip this queue=root, because it doesn't need more resource, schedulingMode=RESPECT_PARTITION_EXCLUSIVITY node-partition=
2019-06-07 07:51:53,012 DEBUG org.apache.hadoop.yarn.server.resourcemanager.rmnode.RMNodeImpl: Processing slave1:39995 of type STATUS_UPDATE
2019-06-07 07:51:53,012 DEBUG org.apache.hadoop.yarn.server.resourcemanager.rmnode.RMNodeImpl: Processing slave1:39995 of type STATUS_UPDATE
2019-06-07 07:51:53,013 DEBUG org.apache.hadoop.yarn.server.resourcemanager.scheduler.capacity.CapacityScheduler: nodeUpdate: slave1:39995 clusterResources: <memory:8192, vCores:2>
2019-06-07 07:51:53,013 DEBUG org.apache.hadoop.yarn.server.resourcemanager.scheduler.capacity.CapacityScheduler: nodeUpdate: slave1:39995 clusterResources: <memory:8192, vCores:2>
2019-06-07 07:51:53,013 DEBUG org.apache.hadoop.yarn.server.resourcemanager.scheduler.capacity.CapacityScheduler: Node being looked for scheduling slave1:39995 availableResource: <memory:4096, vCores:1>
2019-06-07 07:51:53,013 DEBUG org.apache.hadoop.yarn.server.resourcemanager.scheduler.capacity.CapacityScheduler: Node being looked for scheduling slave1:39995 availableResource: <memory:4096, vCores:1>
2019-06-07 07:51:53,014 DEBUG org.apache.hadoop.yarn.server.resourcemanager.scheduler.capacity.CapacityScheduler: Trying to schedule on node: slave1, available: <memory:4096, vCores:1>
2019-06-07 07:51:53,014 DEBUG org.apache.hadoop.yarn.server.resourcemanager.scheduler.capacity.CapacityScheduler: Trying to schedule on node: slave1, available: <memory:4096, vCores:1>
2019-06-07 07:51:53,014 DEBUG org.apache.hadoop.yarn.server.resourcemanager.scheduler.capacity.ParentQueue: Skip this queue=root, because it doesn't need more resource, schedulingMode=RESPECT_PARTITION_EXCLUSIVITY node-partition=
2019-06-07 07:51:53,014 DEBUG org.apache.hadoop.yarn.server.resourcemanager.scheduler.capacity.ParentQueue: Skip this queue=root, because it doesn't need more resource, schedulingMode=RESPECT_PARTITION_EXCLUSIVITY node-partition=
2019-06-07 07:51:53,018 DEBUG org.apache.hadoop.yarn.server.resourcemanager.rmnode.RMNodeImpl: Processing slave2:38494 of type STATUS_UPDATE
2019-06-07 07:51:53,018 DEBUG org.apache.hadoop.yarn.server.resourcemanager.rmnode.RMNodeImpl: Processing slave2:38494 of type STATUS_UPDATE
2019-06-07 07:51:53,020 DEBUG org.apache.hadoop.yarn.server.resourcemanager.scheduler.capacity.CapacityScheduler: nodeUpdate: slave2:38494 clusterResources: <memory:8192, vCores:2>
2019-06-07 07:51:53,020 DEBUG org.apache.hadoop.yarn.server.resourcemanager.scheduler.capacity.CapacityScheduler: nodeUpdate: slave2:38494 clusterResources: <memory:8192, vCores:2>
2019-06-07 07:51:53,020 DEBUG org.apache.hadoop.yarn.server.resourcemanager.scheduler.capacity.CapacityScheduler: Node being looked for scheduling slave2:38494 availableResource: <memory:4096, vCores:1>
2019-06-07 07:51:53,020 DEBUG org.apache.hadoop.yarn.server.resourcemanager.scheduler.capacity.CapacityScheduler: Node being looked for scheduling slave2:38494 availableResource: <memory:4096, vCores:1>
2019-06-07 07:51:53,020 DEBUG org.apache.hadoop.yarn.server.resourcemanager.scheduler.capacity.CapacityScheduler: Trying to schedule on node: slave2, available: <memory:4096, vCores:1>
2019-06-07 07:51:53,020 DEBUG org.apache.hadoop.yarn.server.resourcemanager.scheduler.capacity.CapacityScheduler: Trying to schedule on node: slave2, available: <memory:4096, vCores:1>
2019-06-07 07:51:53,020 DEBUG org.apache.hadoop.yarn.server.resourcemanager.scheduler.capacity.ParentQueue: Skip this queue=root, because it doesn't need more resource, schedulingMode=RESPECT_PARTITION_EXCLUSIVITY node-partition=
2019-06-07 07:51:53,020 DEBUG org.apache.hadoop.yarn.server.resourcemanager.scheduler.capacity.ParentQueue: Skip this queue=root, because it doesn't need more resource, schedulingMode=RESPECT_PARTITION_EXCLUSIVITY node-partition=
2019-06-07 07:51:53,590 INFO org.apache.hadoop.yarn.server.resourcemanager.ClientRMService: Allocated new applicationId: 1
2019-06-07 07:51:53,590 INFO org.apache.hadoop.yarn.server.resourcemanager.ClientRMService: Allocated new applicationId: 1
2019-06-07 07:51:54,016 DEBUG org.apache.hadoop.yarn.server.resourcemanager.rmnode.RMNodeImpl: Processing slave1:39995 of type STATUS_UPDATE
2019-06-07 07:51:54,016 DEBUG org.apache.hadoop.yarn.server.resourcemanager.rmnode.RMNodeImpl: Processing slave1:39995 of type STATUS_UPDATE
2019-06-07 07:51:54,017 DEBUG org.apache.hadoop.yarn.server.resourcemanager.scheduler.capacity.CapacityScheduler: nodeUpdate: slave1:39995 clusterResources: <memory:8192, vCores:2>
2019-06-07 07:51:54,017 DEBUG org.apache.hadoop.yarn.server.resourcemanager.scheduler.capacity.CapacityScheduler: nodeUpdate: slave1:39995 clusterResources: <memory:8192, vCores:2>
2019-06-07 07:51:54,017 DEBUG org.apache.hadoop.yarn.server.resourcemanager.scheduler.capacity.CapacityScheduler: Node being looked for scheduling slave1:39995 availableResource: <memory:4096, vCores:1>
2019-06-07 07:51:54,017 DEBUG org.apache.hadoop.yarn.server.resourcemanager.scheduler.capacity.CapacityScheduler: Node being looked for scheduling slave1:39995 availableResource: <memory:4096, vCores:1>
2019-06-07 07:51:54,017 DEBUG org.apache.hadoop.yarn.server.resourcemanager.scheduler.capacity.CapacityScheduler: Trying to schedule on node: slave1, available: <memory:4096, vCores:1>
2019-06-07 07:51:54,017 DEBUG org.apache.hadoop.yarn.server.resourcemanager.scheduler.capacity.CapacityScheduler: Trying to schedule on node: slave1, available: <memory:4096, vCores:1>
2019-06-07 07:51:54,017 DEBUG org.apache.hadoop.yarn.server.resourcemanager.scheduler.capacity.ParentQueue: Skip this queue=root, because it doesn't need more resource, schedulingMode=RESPECT_PARTITION_EXCLUSIVITY node-partition=
2019-06-07 07:51:54,017 DEBUG org.apache.hadoop.yarn.server.resourcemanager.scheduler.capacity.ParentQueue: Skip this queue=root, because it doesn't need more resource, schedulingMode=RESPECT_PARTITION_EXCLUSIVITY node-partition=
2019-06-07 07:51:54,020 DEBUG org.apache.hadoop.yarn.server.resourcemanager.rmnode.RMNodeImpl: Processing slave2:38494 of type STATUS_UPDATE
2019-06-07 07:51:54,020 DEBUG org.apache.hadoop.yarn.server.resourcemanager.rmnode.RMNodeImpl: Processing slave2:38494 of type STATUS_UPDATE
2019-06-07 07:51:54,021 DEBUG org.apache.hadoop.yarn.server.resourcemanager.scheduler.capacity.CapacityScheduler: nodeUpdate: slave2:38494 clusterResources: <memory:8192, vCores:2>
2019-06-07 07:51:54,021 DEBUG org.apache.hadoop.yarn.server.resourcemanager.scheduler.capacity.CapacityScheduler: nodeUpdate: slave2:38494 clusterResources: <memory:8192, vCores:2>
2019-06-07 07:51:54,021 DEBUG org.apache.hadoop.yarn.server.resourcemanager.scheduler.capacity.CapacityScheduler: Node being looked for scheduling slave2:38494 availableResource: <memory:4096, vCores:1>
2019-06-07 07:51:54,021 DEBUG org.apache.hadoop.yarn.server.resourcemanager.scheduler.capacity.CapacityScheduler: Node being looked for scheduling slave2:38494 availableResource: <memory:4096, vCores:1>
2019-06-07 07:51:54,021 DEBUG org.apache.hadoop.yarn.server.resourcemanager.scheduler.capacity.CapacityScheduler: Trying to schedule on node: slave2, available: <memory:4096, vCores:1>
2019-06-07 07:51:54,021 DEBUG org.apache.hadoop.yarn.server.resourcemanager.scheduler.capacity.CapacityScheduler: Trying to schedule on node: slave2, available: <memory:4096, vCores:1>
2019-06-07 07:51:54,021 DEBUG org.apache.hadoop.yarn.server.resourcemanager.scheduler.capacity.ParentQueue: Skip this queue=root, because it doesn't need more resource, schedulingMode=RESPECT_PARTITION_EXCLUSIVITY node-partition=
2019-06-07 07:51:54,021 DEBUG org.apache.hadoop.yarn.server.resourcemanager.scheduler.capacity.ParentQueue: Skip this queue=root, because it doesn't need more resource, schedulingMode=RESPECT_PARTITION_EXCLUSIVITY node-partition=
2019-06-07 07:51:55,023 DEBUG org.apache.hadoop.yarn.server.resourcemanager.rmnode.RMNodeImpl: Processing slave1:39995 of type STATUS_UPDATE
2019-06-07 07:51:55,023 DEBUG org.apache.hadoop.yarn.server.resourcemanager.rmnode.RMNodeImpl: Processing slave1:39995 of type STATUS_UPDATE
2019-06-07 07:51:55,025 DEBUG org.apache.hadoop.yarn.server.resourcemanager.rmnode.RMNodeImpl: Processing slave2:38494 of type STATUS_UPDATE
2019-06-07 07:51:55,025 DEBUG org.apache.hadoop.yarn.server.resourcemanager.rmnode.RMNodeImpl: Processing slave2:38494 of type STATUS_UPDATE
2019-06-07 07:51:55,025 DEBUG org.apache.hadoop.yarn.server.resourcemanager.scheduler.capacity.CapacityScheduler: nodeUpdate: slave1:39995 clusterResources: <memory:8192, vCores:2>
2019-06-07 07:51:55,025 DEBUG org.apache.hadoop.yarn.server.resourcemanager.scheduler.capacity.CapacityScheduler: nodeUpdate: slave1:39995 clusterResources: <memory:8192, vCores:2>
2019-06-07 07:51:55,025 DEBUG org.apache.hadoop.yarn.server.resourcemanager.scheduler.capacity.CapacityScheduler: Node being looked for scheduling slave1:39995 availableResource: <memory:4096, vCores:1>
2019-06-07 07:51:55,025 DEBUG org.apache.hadoop.yarn.server.resourcemanager.scheduler.capacity.CapacityScheduler: Node being looked for scheduling slave1:39995 availableResource: <memory:4096, vCores:1>
2019-06-07 07:51:55,026 DEBUG org.apache.hadoop.yarn.server.resourcemanager.scheduler.capacity.CapacityScheduler: Trying to schedule on node: slave1, available: <memory:4096, vCores:1>
2019-06-07 07:51:55,026 DEBUG org.apache.hadoop.yarn.server.resourcemanager.scheduler.capacity.CapacityScheduler: Trying to schedule on node: slave1, available: <memory:4096, vCores:1>
2019-06-07 07:51:55,026 DEBUG org.apache.hadoop.yarn.server.resourcemanager.scheduler.capacity.ParentQueue: Skip this queue=root, because it doesn't need more resource, schedulingMode=RESPECT_PARTITION_EXCLUSIVITY node-partition=
2019-06-07 07:51:55,026 DEBUG org.apache.hadoop.yarn.server.resourcemanager.scheduler.capacity.ParentQueue: Skip this queue=root, because it doesn't need more resource, schedulingMode=RESPECT_PARTITION_EXCLUSIVITY node-partition=
2019-06-07 07:51:55,026 DEBUG org.apache.hadoop.yarn.server.resourcemanager.scheduler.capacity.CapacityScheduler: nodeUpdate: slave2:38494 clusterResources: <memory:8192, vCores:2>
2019-06-07 07:51:55,026 DEBUG org.apache.hadoop.yarn.server.resourcemanager.scheduler.capacity.CapacityScheduler: nodeUpdate: slave2:38494 clusterResources: <memory:8192, vCores:2>
2019-06-07 07:51:55,026 DEBUG org.apache.hadoop.yarn.server.resourcemanager.scheduler.capacity.CapacityScheduler: Node being looked for scheduling slave2:38494 availableResource: <memory:4096, vCores:1>
2019-06-07 07:51:55,026 DEBUG org.apache.hadoop.yarn.server.resourcemanager.scheduler.capacity.CapacityScheduler: Node being looked for scheduling slave2:38494 availableResource: <memory:4096, vCores:1>
2019-06-07 07:51:55,026 DEBUG org.apache.hadoop.yarn.server.resourcemanager.scheduler.capacity.CapacityScheduler: Trying to schedule on node: slave2, available: <memory:4096, vCores:1>
2019-06-07 07:51:55,026 DEBUG org.apache.hadoop.yarn.server.resourcemanager.scheduler.capacity.CapacityScheduler: Trying to schedule on node: slave2, available: <memory:4096, vCores:1>
2019-06-07 07:51:55,026 DEBUG org.apache.hadoop.yarn.server.resourcemanager.scheduler.capacity.ParentQueue: Skip this queue=root, because it doesn't need more resource, schedulingMode=RESPECT_PARTITION_EXCLUSIVITY node-partition=
2019-06-07 07:51:55,026 DEBUG org.apache.hadoop.yarn.server.resourcemanager.scheduler.capacity.ParentQueue: Skip this queue=root, because it doesn't need more resource, schedulingMode=RESPECT_PARTITION_EXCLUSIVITY node-partition=
2019-06-07 07:51:56,028 DEBUG org.apache.hadoop.yarn.server.resourcemanager.rmnode.RMNodeImpl: Processing slave1:39995 of type STATUS_UPDATE
2019-06-07 07:51:56,028 DEBUG org.apache.hadoop.yarn.server.resourcemanager.rmnode.RMNodeImpl: Processing slave1:39995 of type STATUS_UPDATE
2019-06-07 07:51:56,028 DEBUG org.apache.hadoop.yarn.server.resourcemanager.scheduler.capacity.CapacityScheduler: nodeUpdate: slave1:39995 clusterResources: <memory:8192, vCores:2>
2019-06-07 07:51:56,028 DEBUG org.apache.hadoop.yarn.server.resourcemanager.scheduler.capacity.CapacityScheduler: nodeUpdate: slave1:39995 clusterResources: <memory:8192, vCores:2>
2019-06-07 07:51:56,029 DEBUG org.apache.hadoop.yarn.server.resourcemanager.scheduler.capacity.CapacityScheduler: Node being looked for scheduling slave1:39995 availableResource: <memory:4096, vCores:1>
2019-06-07 07:51:56,029 DEBUG org.apache.hadoop.yarn.server.resourcemanager.scheduler.capacity.CapacityScheduler: Node being looked for scheduling slave1:39995 availableResource: <memory:4096, vCores:1>
2019-06-07 07:51:56,029 DEBUG org.apache.hadoop.yarn.server.resourcemanager.scheduler.capacity.CapacityScheduler: Trying to schedule on node: slave1, available: <memory:4096, vCores:1>
2019-06-07 07:51:56,029 DEBUG org.apache.hadoop.yarn.server.resourcemanager.scheduler.capacity.CapacityScheduler: Trying to schedule on node: slave1, available: <memory:4096, vCores:1>
2019-06-07 07:51:56,029 DEBUG org.apache.hadoop.yarn.server.resourcemanager.scheduler.capacity.ParentQueue: Skip this queue=root, because it doesn't need more resource, schedulingMode=RESPECT_PARTITION_EXCLUSIVITY node-partition=
2019-06-07 07:51:56,029 DEBUG org.apache.hadoop.yarn.server.resourcemanager.scheduler.capacity.ParentQueue: Skip this queue=root, because it doesn't need more resource, schedulingMode=RESPECT_PARTITION_EXCLUSIVITY node-partition=
2019-06-07 07:51:56,030 DEBUG org.apache.hadoop.yarn.server.resourcemanager.rmnode.RMNodeImpl: Processing slave2:38494 of type STATUS_UPDATE
2019-06-07 07:51:56,030 DEBUG org.apache.hadoop.yarn.server.resourcemanager.rmnode.RMNodeImpl: Processing slave2:38494 of type STATUS_UPDATE
2019-06-07 07:51:56,031 DEBUG org.apache.hadoop.yarn.server.resourcemanager.scheduler.capacity.CapacityScheduler: nodeUpdate: slave2:38494 clusterResources: <memory:8192, vCores:2>
2019-06-07 07:51:56,031 DEBUG org.apache.hadoop.yarn.server.resourcemanager.scheduler.capacity.CapacityScheduler: nodeUpdate: slave2:38494 clusterResources: <memory:8192, vCores:2>
2019-06-07 07:51:56,031 DEBUG org.apache.hadoop.yarn.server.resourcemanager.scheduler.capacity.CapacityScheduler: Node being looked for scheduling slave2:38494 availableResource: <memory:4096, vCores:1>
2019-06-07 07:51:56,031 DEBUG org.apache.hadoop.yarn.server.resourcemanager.scheduler.capacity.CapacityScheduler: Node being looked for scheduling slave2:38494 availableResource: <memory:4096, vCores:1>
2019-06-07 07:51:56,032 DEBUG org.apache.hadoop.yarn.server.resourcemanager.scheduler.capacity.CapacityScheduler: Trying to schedule on node: slave2, available: <memory:4096, vCores:1>
2019-06-07 07:51:56,032 DEBUG org.apache.hadoop.yarn.server.resourcemanager.scheduler.capacity.CapacityScheduler: Trying to schedule on node: slave2, available: <memory:4096, vCores:1>
2019-06-07 07:51:56,032 DEBUG org.apache.hadoop.yarn.server.resourcemanager.scheduler.capacity.ParentQueue: Skip this queue=root, because it doesn't need more resource, schedulingMode=RESPECT_PARTITION_EXCLUSIVITY node-partition=
2019-06-07 07:51:56,032 DEBUG org.apache.hadoop.yarn.server.resourcemanager.scheduler.capacity.ParentQueue: Skip this queue=root, because it doesn't need more resource, schedulingMode=RESPECT_PARTITION_EXCLUSIVITY node-partition=
2019-06-07 07:51:57,032 DEBUG org.apache.hadoop.yarn.server.resourcemanager.rmnode.RMNodeImpl: Processing slave1:39995 of type STATUS_UPDATE
2019-06-07 07:51:57,032 DEBUG org.apache.hadoop.yarn.server.resourcemanager.rmnode.RMNodeImpl: Processing slave1:39995 of type STATUS_UPDATE
2019-06-07 07:51:57,033 DEBUG org.apache.hadoop.yarn.server.resourcemanager.scheduler.capacity.CapacityScheduler: nodeUpdate: slave1:39995 clusterResources: <memory:8192, vCores:2>
2019-06-07 07:51:57,033 DEBUG org.apache.hadoop.yarn.server.resourcemanager.scheduler.capacity.CapacityScheduler: nodeUpdate: slave1:39995 clusterResources: <memory:8192, vCores:2>
2019-06-07 07:51:57,033 DEBUG org.apache.hadoop.yarn.server.resourcemanager.scheduler.capacity.CapacityScheduler: Node being looked for scheduling slave1:39995 availableResource: <memory:4096, vCores:1>
2019-06-07 07:51:57,033 DEBUG org.apache.hadoop.yarn.server.resourcemanager.scheduler.capacity.CapacityScheduler: Node being looked for scheduling slave1:39995 availableResource: <memory:4096, vCores:1>
2019-06-07 07:51:57,033 DEBUG org.apache.hadoop.yarn.server.resourcemanager.scheduler.capacity.CapacityScheduler: Trying to schedule on node: slave1, available: <memory:4096, vCores:1>
2019-06-07 07:51:57,033 DEBUG org.apache.hadoop.yarn.server.resourcemanager.scheduler.capacity.CapacityScheduler: Trying to schedule on node: slave1, available: <memory:4096, vCores:1>
2019-06-07 07:51:57,033 DEBUG org.apache.hadoop.yarn.server.resourcemanager.scheduler.capacity.ParentQueue: Skip this queue=root, because it doesn't need more resource, schedulingMode=RESPECT_PARTITION_EXCLUSIVITY node-partition=
2019-06-07 07:51:57,033 DEBUG org.apache.hadoop.yarn.server.resourcemanager.scheduler.capacity.ParentQueue: Skip this queue=root, because it doesn't need more resource, schedulingMode=RESPECT_PARTITION_EXCLUSIVITY node-partition=
2019-06-07 07:51:57,036 DEBUG org.apache.hadoop.yarn.server.resourcemanager.rmnode.RMNodeImpl: Processing slave2:38494 of type STATUS_UPDATE
2019-06-07 07:51:57,036 DEBUG org.apache.hadoop.yarn.server.resourcemanager.rmnode.RMNodeImpl: Processing slave2:38494 of type STATUS_UPDATE
2019-06-07 07:51:57,036 DEBUG org.apache.hadoop.yarn.server.resourcemanager.scheduler.capacity.CapacityScheduler: nodeUpdate: slave2:38494 clusterResources: <memory:8192, vCores:2>
2019-06-07 07:51:57,036 DEBUG org.apache.hadoop.yarn.server.resourcemanager.scheduler.capacity.CapacityScheduler: nodeUpdate: slave2:38494 clusterResources: <memory:8192, vCores:2>
2019-06-07 07:51:57,037 DEBUG org.apache.hadoop.yarn.server.resourcemanager.scheduler.capacity.CapacityScheduler: Node being looked for scheduling slave2:38494 availableResource: <memory:4096, vCores:1>
2019-06-07 07:51:57,037 DEBUG org.apache.hadoop.yarn.server.resourcemanager.scheduler.capacity.CapacityScheduler: Node being looked for scheduling slave2:38494 availableResource: <memory:4096, vCores:1>
2019-06-07 07:51:57,037 DEBUG org.apache.hadoop.yarn.server.resourcemanager.scheduler.capacity.CapacityScheduler: Trying to schedule on node: slave2, available: <memory:4096, vCores:1>
2019-06-07 07:51:57,037 DEBUG org.apache.hadoop.yarn.server.resourcemanager.scheduler.capacity.CapacityScheduler: Trying to schedule on node: slave2, available: <memory:4096, vCores:1>
2019-06-07 07:51:57,037 DEBUG org.apache.hadoop.yarn.server.resourcemanager.scheduler.capacity.ParentQueue: Skip this queue=root, because it doesn't need more resource, schedulingMode=RESPECT_PARTITION_EXCLUSIVITY node-partition=
2019-06-07 07:51:57,037 DEBUG org.apache.hadoop.yarn.server.resourcemanager.scheduler.capacity.ParentQueue: Skip this queue=root, because it doesn't need more resource, schedulingMode=RESPECT_PARTITION_EXCLUSIVITY node-partition=
2019-06-07 07:51:58,039 DEBUG org.apache.hadoop.yarn.server.resourcemanager.rmnode.RMNodeImpl: Processing slave1:39995 of type STATUS_UPDATE
2019-06-07 07:51:58,039 DEBUG org.apache.hadoop.yarn.server.resourcemanager.rmnode.RMNodeImpl: Processing slave1:39995 of type STATUS_UPDATE
2019-06-07 07:51:58,040 DEBUG org.apache.hadoop.yarn.server.resourcemanager.scheduler.capacity.CapacityScheduler: nodeUpdate: slave1:39995 clusterResources: <memory:8192, vCores:2>
2019-06-07 07:51:58,040 DEBUG org.apache.hadoop.yarn.server.resourcemanager.scheduler.capacity.CapacityScheduler: nodeUpdate: slave1:39995 clusterResources: <memory:8192, vCores:2>
2019-06-07 07:51:58,040 DEBUG org.apache.hadoop.yarn.server.resourcemanager.scheduler.capacity.CapacityScheduler: Node being looked for scheduling slave1:39995 availableResource: <memory:4096, vCores:1>
2019-06-07 07:51:58,040 DEBUG org.apache.hadoop.yarn.server.resourcemanager.scheduler.capacity.CapacityScheduler: Node being looked for scheduling slave1:39995 availableResource: <memory:4096, vCores:1>
2019-06-07 07:51:58,041 DEBUG org.apache.hadoop.yarn.server.resourcemanager.scheduler.capacity.CapacityScheduler: Trying to schedule on node: slave1, available: <memory:4096, vCores:1>
2019-06-07 07:51:58,041 DEBUG org.apache.hadoop.yarn.server.resourcemanager.scheduler.capacity.CapacityScheduler: Trying to schedule on node: slave1, available: <memory:4096, vCores:1>
2019-06-07 07:51:58,041 DEBUG org.apache.hadoop.yarn.server.resourcemanager.scheduler.capacity.ParentQueue: Skip this queue=root, because it doesn't need more resource, schedulingMode=RESPECT_PARTITION_EXCLUSIVITY node-partition=
2019-06-07 07:51:58,041 DEBUG org.apache.hadoop.yarn.server.resourcemanager.scheduler.capacity.ParentQueue: Skip this queue=root, because it doesn't need more resource, schedulingMode=RESPECT_PARTITION_EXCLUSIVITY node-partition=
2019-06-07 07:51:58,047 DEBUG org.apache.hadoop.yarn.server.resourcemanager.rmnode.RMNodeImpl: Processing slave2:38494 of type STATUS_UPDATE
2019-06-07 07:51:58,047 DEBUG org.apache.hadoop.yarn.server.resourcemanager.rmnode.RMNodeImpl: Processing slave2:38494 of type STATUS_UPDATE
2019-06-07 07:51:58,056 DEBUG org.apache.hadoop.yarn.server.resourcemanager.scheduler.capacity.CapacityScheduler: nodeUpdate: slave2:38494 clusterResources: <memory:8192, vCores:2>
2019-06-07 07:51:58,056 DEBUG org.apache.hadoop.yarn.server.resourcemanager.scheduler.capacity.CapacityScheduler: nodeUpdate: slave2:38494 clusterResources: <memory:8192, vCores:2>
2019-06-07 07:51:58,056 DEBUG org.apache.hadoop.yarn.server.resourcemanager.scheduler.capacity.CapacityScheduler: Node being looked for scheduling slave2:38494 availableResource: <memory:4096, vCores:1>
2019-06-07 07:51:58,056 DEBUG org.apache.hadoop.yarn.server.resourcemanager.scheduler.capacity.CapacityScheduler: Node being looked for scheduling slave2:38494 availableResource: <memory:4096, vCores:1>
2019-06-07 07:51:58,056 DEBUG org.apache.hadoop.yarn.server.resourcemanager.scheduler.capacity.CapacityScheduler: Trying to schedule on node: slave2, available: <memory:4096, vCores:1>
2019-06-07 07:51:58,056 DEBUG org.apache.hadoop.yarn.server.resourcemanager.scheduler.capacity.CapacityScheduler: Trying to schedule on node: slave2, available: <memory:4096, vCores:1>
2019-06-07 07:51:58,056 DEBUG org.apache.hadoop.yarn.server.resourcemanager.scheduler.capacity.ParentQueue: Skip this queue=root, because it doesn't need more resource, schedulingMode=RESPECT_PARTITION_EXCLUSIVITY node-partition=
2019-06-07 07:51:58,056 DEBUG org.apache.hadoop.yarn.server.resourcemanager.scheduler.capacity.ParentQueue: Skip this queue=root, because it doesn't need more resource, schedulingMode=RESPECT_PARTITION_EXCLUSIVITY node-partition=
2019-06-07 07:51:59,043 DEBUG org.apache.hadoop.yarn.server.resourcemanager.rmnode.RMNodeImpl: Processing slave1:39995 of type STATUS_UPDATE
2019-06-07 07:51:59,043 DEBUG org.apache.hadoop.yarn.server.resourcemanager.rmnode.RMNodeImpl: Processing slave1:39995 of type STATUS_UPDATE
2019-06-07 07:51:59,047 DEBUG org.apache.hadoop.yarn.server.resourcemanager.scheduler.capacity.CapacityScheduler: nodeUpdate: slave1:39995 clusterResources: <memory:8192, vCores:2>
2019-06-07 07:51:59,047 DEBUG org.apache.hadoop.yarn.server.resourcemanager.scheduler.capacity.CapacityScheduler: nodeUpdate: slave1:39995 clusterResources: <memory:8192, vCores:2>
2019-06-07 07:51:59,047 DEBUG org.apache.hadoop.yarn.server.resourcemanager.scheduler.capacity.CapacityScheduler: Node being looked for scheduling slave1:39995 availableResource: <memory:4096, vCores:1>
2019-06-07 07:51:59,047 DEBUG org.apache.hadoop.yarn.server.resourcemanager.scheduler.capacity.CapacityScheduler: Node being looked for scheduling slave1:39995 availableResource: <memory:4096, vCores:1>
2019-06-07 07:51:59,047 DEBUG org.apache.hadoop.yarn.server.resourcemanager.scheduler.capacity.CapacityScheduler: Trying to schedule on node: slave1, available: <memory:4096, vCores:1>
2019-06-07 07:51:59,047 DEBUG org.apache.hadoop.yarn.server.resourcemanager.scheduler.capacity.CapacityScheduler: Trying to schedule on node: slave1, available: <memory:4096, vCores:1>
2019-06-07 07:51:59,047 DEBUG org.apache.hadoop.yarn.server.resourcemanager.scheduler.capacity.ParentQueue: Skip this queue=root, because it doesn't need more resource, schedulingMode=RESPECT_PARTITION_EXCLUSIVITY node-partition=
2019-06-07 07:51:59,047 DEBUG org.apache.hadoop.yarn.server.resourcemanager.scheduler.capacity.ParentQueue: Skip this queue=root, because it doesn't need more resource, schedulingMode=RESPECT_PARTITION_EXCLUSIVITY node-partition=
2019-06-07 07:51:59,067 DEBUG org.apache.hadoop.yarn.server.resourcemanager.rmnode.RMNodeImpl: Processing slave2:38494 of type STATUS_UPDATE
2019-06-07 07:51:59,067 DEBUG org.apache.hadoop.yarn.server.resourcemanager.rmnode.RMNodeImpl: Processing slave2:38494 of type STATUS_UPDATE
2019-06-07 07:51:59,068 DEBUG org.apache.hadoop.yarn.server.resourcemanager.scheduler.capacity.CapacityScheduler: nodeUpdate: slave2:38494 clusterResources: <memory:8192, vCores:2>
2019-06-07 07:51:59,068 DEBUG org.apache.hadoop.yarn.server.resourcemanager.scheduler.capacity.CapacityScheduler: nodeUpdate: slave2:38494 clusterResources: <memory:8192, vCores:2>
2019-06-07 07:51:59,069 DEBUG org.apache.hadoop.yarn.server.resourcemanager.scheduler.capacity.CapacityScheduler: Node being looked for scheduling slave2:38494 availableResource: <memory:4096, vCores:1>
2019-06-07 07:51:59,069 DEBUG org.apache.hadoop.yarn.server.resourcemanager.scheduler.capacity.CapacityScheduler: Node being looked for scheduling slave2:38494 availableResource: <memory:4096, vCores:1>
2019-06-07 07:51:59,069 DEBUG org.apache.hadoop.yarn.server.resourcemanager.scheduler.capacity.CapacityScheduler: Trying to schedule on node: slave2, available: <memory:4096, vCores:1>
2019-06-07 07:51:59,069 DEBUG org.apache.hadoop.yarn.server.resourcemanager.scheduler.capacity.CapacityScheduler: Trying to schedule on node: slave2, available: <memory:4096, vCores:1>
2019-06-07 07:51:59,069 DEBUG org.apache.hadoop.yarn.server.resourcemanager.scheduler.capacity.ParentQueue: Skip this queue=root, because it doesn't need more resource, schedulingMode=RESPECT_PARTITION_EXCLUSIVITY node-partition=
2019-06-07 07:51:59,069 DEBUG org.apache.hadoop.yarn.server.resourcemanager.scheduler.capacity.ParentQueue: Skip this queue=root, because it doesn't need more resource, schedulingMode=RESPECT_PARTITION_EXCLUSIVITY node-partition=
2019-06-07 07:52:00,048 DEBUG org.apache.hadoop.yarn.server.resourcemanager.rmnode.RMNodeImpl: Processing slave1:39995 of type STATUS_UPDATE
2019-06-07 07:52:00,048 DEBUG org.apache.hadoop.yarn.server.resourcemanager.rmnode.RMNodeImpl: Processing slave1:39995 of type STATUS_UPDATE
2019-06-07 07:52:00,049 DEBUG org.apache.hadoop.yarn.server.resourcemanager.scheduler.capacity.CapacityScheduler: nodeUpdate: slave1:39995 clusterResources: <memory:8192, vCores:2>
2019-06-07 07:52:00,049 DEBUG org.apache.hadoop.yarn.server.resourcemanager.scheduler.capacity.CapacityScheduler: nodeUpdate: slave1:39995 clusterResources: <memory:8192, vCores:2>
2019-06-07 07:52:00,049 DEBUG org.apache.hadoop.yarn.server.resourcemanager.scheduler.capacity.CapacityScheduler: Node being looked for scheduling slave1:39995 availableResource: <memory:4096, vCores:1>
2019-06-07 07:52:00,049 DEBUG org.apache.hadoop.yarn.server.resourcemanager.scheduler.capacity.CapacityScheduler: Node being looked for scheduling slave1:39995 availableResource: <memory:4096, vCores:1>
2019-06-07 07:52:00,049 DEBUG org.apache.hadoop.yarn.server.resourcemanager.scheduler.capacity.CapacityScheduler: Trying to schedule on node: slave1, available: <memory:4096, vCores:1>
2019-06-07 07:52:00,049 DEBUG org.apache.hadoop.yarn.server.resourcemanager.scheduler.capacity.CapacityScheduler: Trying to schedule on node: slave1, available: <memory:4096, vCores:1>
2019-06-07 07:52:00,049 DEBUG org.apache.hadoop.yarn.server.resourcemanager.scheduler.capacity.ParentQueue: Skip this queue=root, because it doesn't need more resource, schedulingMode=RESPECT_PARTITION_EXCLUSIVITY node-partition=
2019-06-07 07:52:00,049 DEBUG org.apache.hadoop.yarn.server.resourcemanager.scheduler.capacity.ParentQueue: Skip this queue=root, because it doesn't need more resource, schedulingMode=RESPECT_PARTITION_EXCLUSIVITY node-partition=
2019-06-07 07:52:00,074 DEBUG org.apache.hadoop.yarn.server.resourcemanager.rmnode.RMNodeImpl: Processing slave2:38494 of type STATUS_UPDATE
2019-06-07 07:52:00,074 DEBUG org.apache.hadoop.yarn.server.resourcemanager.rmnode.RMNodeImpl: Processing slave2:38494 of type STATUS_UPDATE
2019-06-07 07:52:00,075 DEBUG org.apache.hadoop.yarn.server.resourcemanager.scheduler.capacity.CapacityScheduler: nodeUpdate: slave2:38494 clusterResources: <memory:8192, vCores:2>
2019-06-07 07:52:00,075 DEBUG org.apache.hadoop.yarn.server.resourcemanager.scheduler.capacity.CapacityScheduler: nodeUpdate: slave2:38494 clusterResources: <memory:8192, vCores:2>
2019-06-07 07:52:00,075 DEBUG org.apache.hadoop.yarn.server.resourcemanager.scheduler.capacity.CapacityScheduler: Node being looked for scheduling slave2:38494 availableResource: <memory:4096, vCores:1>
2019-06-07 07:52:00,075 DEBUG org.apache.hadoop.yarn.server.resourcemanager.scheduler.capacity.CapacityScheduler: Node being looked for scheduling slave2:38494 availableResource: <memory:4096, vCores:1>
2019-06-07 07:52:00,075 DEBUG org.apache.hadoop.yarn.server.resourcemanager.scheduler.capacity.CapacityScheduler: Trying to schedule on node: slave2, available: <memory:4096, vCores:1>
2019-06-07 07:52:00,075 DEBUG org.apache.hadoop.yarn.server.resourcemanager.scheduler.capacity.CapacityScheduler: Trying to schedule on node: slave2, available: <memory:4096, vCores:1>
2019-06-07 07:52:00,075 DEBUG org.apache.hadoop.yarn.server.resourcemanager.scheduler.capacity.ParentQueue: Skip this queue=root, because it doesn't need more resource, schedulingMode=RESPECT_PARTITION_EXCLUSIVITY node-partition=
2019-06-07 07:52:00,075 DEBUG org.apache.hadoop.yarn.server.resourcemanager.scheduler.capacity.ParentQueue: Skip this queue=root, because it doesn't need more resource, schedulingMode=RESPECT_PARTITION_EXCLUSIVITY node-partition=
2019-06-07 07:52:01,054 DEBUG org.apache.hadoop.yarn.server.resourcemanager.rmnode.RMNodeImpl: Processing slave1:39995 of type STATUS_UPDATE
2019-06-07 07:52:01,054 DEBUG org.apache.hadoop.yarn.server.resourcemanager.rmnode.RMNodeImpl: Processing slave1:39995 of type STATUS_UPDATE
2019-06-07 07:52:01,055 DEBUG org.apache.hadoop.yarn.server.resourcemanager.scheduler.capacity.CapacityScheduler: nodeUpdate: slave1:39995 clusterResources: <memory:8192, vCores:2>
2019-06-07 07:52:01,055 DEBUG org.apache.hadoop.yarn.server.resourcemanager.scheduler.capacity.CapacityScheduler: nodeUpdate: slave1:39995 clusterResources: <memory:8192, vCores:2>
2019-06-07 07:52:01,056 DEBUG org.apache.hadoop.yarn.server.resourcemanager.scheduler.capacity.CapacityScheduler: Node being looked for scheduling slave1:39995 availableResource: <memory:4096, vCores:1>
2019-06-07 07:52:01,056 DEBUG org.apache.hadoop.yarn.server.resourcemanager.scheduler.capacity.CapacityScheduler: Node being looked for scheduling slave1:39995 availableResource: <memory:4096, vCores:1>
2019-06-07 07:52:01,056 DEBUG org.apache.hadoop.yarn.server.resourcemanager.scheduler.capacity.CapacityScheduler: Trying to schedule on node: slave1, available: <memory:4096, vCores:1>
2019-06-07 07:52:01,056 DEBUG org.apache.hadoop.yarn.server.resourcemanager.scheduler.capacity.CapacityScheduler: Trying to schedule on node: slave1, available: <memory:4096, vCores:1>
2019-06-07 07:52:01,056 DEBUG org.apache.hadoop.yarn.server.resourcemanager.scheduler.capacity.ParentQueue: Skip this queue=root, because it doesn't need more resource, schedulingMode=RESPECT_PARTITION_EXCLUSIVITY node-partition=
2019-06-07 07:52:01,056 DEBUG org.apache.hadoop.yarn.server.resourcemanager.scheduler.capacity.ParentQueue: Skip this queue=root, because it doesn't need more resource, schedulingMode=RESPECT_PARTITION_EXCLUSIVITY node-partition=
2019-06-07 07:52:01,079 DEBUG org.apache.hadoop.yarn.server.resourcemanager.rmnode.RMNodeImpl: Processing slave2:38494 of type STATUS_UPDATE
2019-06-07 07:52:01,079 DEBUG org.apache.hadoop.yarn.server.resourcemanager.rmnode.RMNodeImpl: Processing slave2:38494 of type STATUS_UPDATE
2019-06-07 07:52:01,079 DEBUG org.apache.hadoop.yarn.server.resourcemanager.scheduler.capacity.CapacityScheduler: nodeUpdate: slave2:38494 clusterResources: <memory:8192, vCores:2>
2019-06-07 07:52:01,079 DEBUG org.apache.hadoop.yarn.server.resourcemanager.scheduler.capacity.CapacityScheduler: nodeUpdate: slave2:38494 clusterResources: <memory:8192, vCores:2>
2019-06-07 07:52:01,080 DEBUG org.apache.hadoop.yarn.server.resourcemanager.scheduler.capacity.CapacityScheduler: Node being looked for scheduling slave2:38494 availableResource: <memory:4096, vCores:1>
2019-06-07 07:52:01,080 DEBUG org.apache.hadoop.yarn.server.resourcemanager.scheduler.capacity.CapacityScheduler: Node being looked for scheduling slave2:38494 availableResource: <memory:4096, vCores:1>
2019-06-07 07:52:01,080 DEBUG org.apache.hadoop.yarn.server.resourcemanager.scheduler.capacity.CapacityScheduler: Trying to schedule on node: slave2, available: <memory:4096, vCores:1>
2019-06-07 07:52:01,080 DEBUG org.apache.hadoop.yarn.server.resourcemanager.scheduler.capacity.CapacityScheduler: Trying to schedule on node: slave2, available: <memory:4096, vCores:1>
2019-06-07 07:52:01,080 DEBUG org.apache.hadoop.yarn.server.resourcemanager.scheduler.capacity.ParentQueue: Skip this queue=root, because it doesn't need more resource, schedulingMode=RESPECT_PARTITION_EXCLUSIVITY node-partition=
2019-06-07 07:52:01,080 DEBUG org.apache.hadoop.yarn.server.resourcemanager.scheduler.capacity.ParentQueue: Skip this queue=root, because it doesn't need more resource, schedulingMode=RESPECT_PARTITION_EXCLUSIVITY node-partition=
2019-06-07 07:52:02,069 DEBUG org.apache.hadoop.yarn.server.resourcemanager.rmnode.RMNodeImpl: Processing slave1:39995 of type STATUS_UPDATE
2019-06-07 07:52:02,069 DEBUG org.apache.hadoop.yarn.server.resourcemanager.rmnode.RMNodeImpl: Processing slave1:39995 of type STATUS_UPDATE
2019-06-07 07:52:02,071 DEBUG org.apache.hadoop.yarn.server.resourcemanager.scheduler.capacity.CapacityScheduler: nodeUpdate: slave1:39995 clusterResources: <memory:8192, vCores:2>
2019-06-07 07:52:02,071 DEBUG org.apache.hadoop.yarn.server.resourcemanager.scheduler.capacity.CapacityScheduler: nodeUpdate: slave1:39995 clusterResources: <memory:8192, vCores:2>
2019-06-07 07:52:02,071 DEBUG org.apache.hadoop.yarn.server.resourcemanager.scheduler.capacity.CapacityScheduler: Node being looked for scheduling slave1:39995 availableResource: <memory:4096, vCores:1>
2019-06-07 07:52:02,071 DEBUG org.apache.hadoop.yarn.server.resourcemanager.scheduler.capacity.CapacityScheduler: Node being looked for scheduling slave1:39995 availableResource: <memory:4096, vCores:1>
2019-06-07 07:52:02,071 DEBUG org.apache.hadoop.yarn.server.resourcemanager.scheduler.capacity.CapacityScheduler: Trying to schedule on node: slave1, available: <memory:4096, vCores:1>
2019-06-07 07:52:02,071 DEBUG org.apache.hadoop.yarn.server.resourcemanager.scheduler.capacity.CapacityScheduler: Trying to schedule on node: slave1, available: <memory:4096, vCores:1>
2019-06-07 07:52:02,071 DEBUG org.apache.hadoop.yarn.server.resourcemanager.scheduler.capacity.ParentQueue: Skip this queue=root, because it doesn't need more resource, schedulingMode=RESPECT_PARTITION_EXCLUSIVITY node-partition=
2019-06-07 07:52:02,071 DEBUG org.apache.hadoop.yarn.server.resourcemanager.scheduler.capacity.ParentQueue: Skip this queue=root, because it doesn't need more resource, schedulingMode=RESPECT_PARTITION_EXCLUSIVITY node-partition=
2019-06-07 07:52:02,081 DEBUG org.apache.hadoop.yarn.server.resourcemanager.rmnode.RMNodeImpl: Processing slave2:38494 of type STATUS_UPDATE
2019-06-07 07:52:02,081 DEBUG org.apache.hadoop.yarn.server.resourcemanager.rmnode.RMNodeImpl: Processing slave2:38494 of type STATUS_UPDATE
2019-06-07 07:52:02,081 DEBUG org.apache.hadoop.yarn.server.resourcemanager.scheduler.capacity.CapacityScheduler: nodeUpdate: slave2:38494 clusterResources: <memory:8192, vCores:2>
2019-06-07 07:52:02,081 DEBUG org.apache.hadoop.yarn.server.resourcemanager.scheduler.capacity.CapacityScheduler: nodeUpdate: slave2:38494 clusterResources: <memory:8192, vCores:2>
2019-06-07 07:52:02,081 DEBUG org.apache.hadoop.yarn.server.resourcemanager.scheduler.capacity.CapacityScheduler: Node being looked for scheduling slave2:38494 availableResource: <memory:4096, vCores:1>
2019-06-07 07:52:02,081 DEBUG org.apache.hadoop.yarn.server.resourcemanager.scheduler.capacity.CapacityScheduler: Node being looked for scheduling slave2:38494 availableResource: <memory:4096, vCores:1>
2019-06-07 07:52:02,081 DEBUG org.apache.hadoop.yarn.server.resourcemanager.scheduler.capacity.CapacityScheduler: Trying to schedule on node: slave2, available: <memory:4096, vCores:1>
2019-06-07 07:52:02,081 DEBUG org.apache.hadoop.yarn.server.resourcemanager.scheduler.capacity.CapacityScheduler: Trying to schedule on node: slave2, available: <memory:4096, vCores:1>
2019-06-07 07:52:02,081 DEBUG org.apache.hadoop.yarn.server.resourcemanager.scheduler.capacity.ParentQueue: Skip this queue=root, because it doesn't need more resource, schedulingMode=RESPECT_PARTITION_EXCLUSIVITY node-partition=
2019-06-07 07:52:02,081 DEBUG org.apache.hadoop.yarn.server.resourcemanager.scheduler.capacity.ParentQueue: Skip this queue=root, because it doesn't need more resource, schedulingMode=RESPECT_PARTITION_EXCLUSIVITY node-partition=
2019-06-07 07:52:03,075 DEBUG org.apache.hadoop.yarn.server.resourcemanager.rmnode.RMNodeImpl: Processing slave1:39995 of type STATUS_UPDATE
2019-06-07 07:52:03,075 DEBUG org.apache.hadoop.yarn.server.resourcemanager.rmnode.RMNodeImpl: Processing slave1:39995 of type STATUS_UPDATE
2019-06-07 07:52:03,076 DEBUG org.apache.hadoop.yarn.server.resourcemanager.scheduler.capacity.CapacityScheduler: nodeUpdate: slave1:39995 clusterResources: <memory:8192, vCores:2>
2019-06-07 07:52:03,076 DEBUG org.apache.hadoop.yarn.server.resourcemanager.scheduler.capacity.CapacityScheduler: nodeUpdate: slave1:39995 clusterResources: <memory:8192, vCores:2>
2019-06-07 07:52:03,076 DEBUG org.apache.hadoop.yarn.server.resourcemanager.scheduler.capacity.CapacityScheduler: Node being looked for scheduling slave1:39995 availableResource: <memory:4096, vCores:1>
2019-06-07 07:52:03,076 DEBUG org.apache.hadoop.yarn.server.resourcemanager.scheduler.capacity.CapacityScheduler: Node being looked for scheduling slave1:39995 availableResource: <memory:4096, vCores:1>
2019-06-07 07:52:03,077 DEBUG org.apache.hadoop.yarn.server.resourcemanager.scheduler.capacity.CapacityScheduler: Trying to schedule on node: slave1, available: <memory:4096, vCores:1>
2019-06-07 07:52:03,077 DEBUG org.apache.hadoop.yarn.server.resourcemanager.scheduler.capacity.CapacityScheduler: Trying to schedule on node: slave1, available: <memory:4096, vCores:1>
2019-06-07 07:52:03,077 DEBUG org.apache.hadoop.yarn.server.resourcemanager.scheduler.capacity.ParentQueue: Skip this queue=root, because it doesn't need more resource, schedulingMode=RESPECT_PARTITION_EXCLUSIVITY node-partition=
2019-06-07 07:52:03,077 DEBUG org.apache.hadoop.yarn.server.resourcemanager.scheduler.capacity.ParentQueue: Skip this queue=root, because it doesn't need more resource, schedulingMode=RESPECT_PARTITION_EXCLUSIVITY node-partition=
2019-06-07 07:52:03,090 DEBUG org.apache.hadoop.yarn.server.resourcemanager.rmnode.RMNodeImpl: Processing slave2:38494 of type STATUS_UPDATE
2019-06-07 07:52:03,090 DEBUG org.apache.hadoop.yarn.server.resourcemanager.rmnode.RMNodeImpl: Processing slave2:38494 of type STATUS_UPDATE
2019-06-07 07:52:03,090 DEBUG org.apache.hadoop.yarn.server.resourcemanager.scheduler.capacity.CapacityScheduler: nodeUpdate: slave2:38494 clusterResources: <memory:8192, vCores:2>
2019-06-07 07:52:03,090 DEBUG org.apache.hadoop.yarn.server.resourcemanager.scheduler.capacity.CapacityScheduler: nodeUpdate: slave2:38494 clusterResources: <memory:8192, vCores:2>
2019-06-07 07:52:03,090 DEBUG org.apache.hadoop.yarn.server.resourcemanager.scheduler.capacity.CapacityScheduler: Node being looked for scheduling slave2:38494 availableResource: <memory:4096, vCores:1>
2019-06-07 07:52:03,090 DEBUG org.apache.hadoop.yarn.server.resourcemanager.scheduler.capacity.CapacityScheduler: Node being looked for scheduling slave2:38494 availableResource: <memory:4096, vCores:1>
2019-06-07 07:52:03,091 DEBUG org.apache.hadoop.yarn.server.resourcemanager.scheduler.capacity.CapacityScheduler: Trying to schedule on node: slave2, available: <memory:4096, vCores:1>
2019-06-07 07:52:03,091 DEBUG org.apache.hadoop.yarn.server.resourcemanager.scheduler.capacity.CapacityScheduler: Trying to schedule on node: slave2, available: <memory:4096, vCores:1>
2019-06-07 07:52:03,091 DEBUG org.apache.hadoop.yarn.server.resourcemanager.scheduler.capacity.ParentQueue: Skip this queue=root, because it doesn't need more resource, schedulingMode=RESPECT_PARTITION_EXCLUSIVITY node-partition=
2019-06-07 07:52:03,091 DEBUG org.apache.hadoop.yarn.server.resourcemanager.scheduler.capacity.ParentQueue: Skip this queue=root, because it doesn't need more resource, schedulingMode=RESPECT_PARTITION_EXCLUSIVITY node-partition=
2019-06-07 07:52:04,087 DEBUG org.apache.hadoop.yarn.server.resourcemanager.rmnode.RMNodeImpl: Processing slave1:39995 of type STATUS_UPDATE
2019-06-07 07:52:04,087 DEBUG org.apache.hadoop.yarn.server.resourcemanager.rmnode.RMNodeImpl: Processing slave1:39995 of type STATUS_UPDATE
2019-06-07 07:52:04,089 DEBUG org.apache.hadoop.yarn.server.resourcemanager.scheduler.capacity.CapacityScheduler: nodeUpdate: slave1:39995 clusterResources: <memory:8192, vCores:2>
2019-06-07 07:52:04,089 DEBUG org.apache.hadoop.yarn.server.resourcemanager.scheduler.capacity.CapacityScheduler: nodeUpdate: slave1:39995 clusterResources: <memory:8192, vCores:2>
2019-06-07 07:52:04,089 DEBUG org.apache.hadoop.yarn.server.resourcemanager.scheduler.capacity.CapacityScheduler: Node being looked for scheduling slave1:39995 availableResource: <memory:4096, vCores:1>
2019-06-07 07:52:04,089 DEBUG org.apache.hadoop.yarn.server.resourcemanager.scheduler.capacity.CapacityScheduler: Node being looked for scheduling slave1:39995 availableResource: <memory:4096, vCores:1>
2019-06-07 07:52:04,089 DEBUG org.apache.hadoop.yarn.server.resourcemanager.scheduler.capacity.CapacityScheduler: Trying to schedule on node: slave1, available: <memory:4096, vCores:1>
2019-06-07 07:52:04,089 DEBUG org.apache.hadoop.yarn.server.resourcemanager.scheduler.capacity.CapacityScheduler: Trying to schedule on node: slave1, available: <memory:4096, vCores:1>
2019-06-07 07:52:04,089 DEBUG org.apache.hadoop.yarn.server.resourcemanager.scheduler.capacity.ParentQueue: Skip this queue=root, because it doesn't need more resource, schedulingMode=RESPECT_PARTITION_EXCLUSIVITY node-partition=
2019-06-07 07:52:04,089 DEBUG org.apache.hadoop.yarn.server.resourcemanager.scheduler.capacity.ParentQueue: Skip this queue=root, because it doesn't need more resource, schedulingMode=RESPECT_PARTITION_EXCLUSIVITY node-partition=
2019-06-07 07:52:04,092 DEBUG org.apache.hadoop.yarn.server.resourcemanager.rmnode.RMNodeImpl: Processing slave2:38494 of type STATUS_UPDATE
2019-06-07 07:52:04,092 DEBUG org.apache.hadoop.yarn.server.resourcemanager.rmnode.RMNodeImpl: Processing slave2:38494 of type STATUS_UPDATE
2019-06-07 07:52:04,093 DEBUG org.apache.hadoop.yarn.server.resourcemanager.scheduler.capacity.CapacityScheduler: nodeUpdate: slave2:38494 clusterResources: <memory:8192, vCores:2>
2019-06-07 07:52:04,093 DEBUG org.apache.hadoop.yarn.server.resourcemanager.scheduler.capacity.CapacityScheduler: nodeUpdate: slave2:38494 clusterResources: <memory:8192, vCores:2>
2019-06-07 07:52:04,093 DEBUG org.apache.hadoop.yarn.server.resourcemanager.scheduler.capacity.CapacityScheduler: Node being looked for scheduling slave2:38494 availableResource: <memory:4096, vCores:1>
2019-06-07 07:52:04,093 DEBUG org.apache.hadoop.yarn.server.resourcemanager.scheduler.capacity.CapacityScheduler: Node being looked for scheduling slave2:38494 availableResource: <memory:4096, vCores:1>
2019-06-07 07:52:04,093 DEBUG org.apache.hadoop.yarn.server.resourcemanager.scheduler.capacity.CapacityScheduler: Trying to schedule on node: slave2, available: <memory:4096, vCores:1>
2019-06-07 07:52:04,093 DEBUG org.apache.hadoop.yarn.server.resourcemanager.scheduler.capacity.CapacityScheduler: Trying to schedule on node: slave2, available: <memory:4096, vCores:1>
2019-06-07 07:52:04,093 DEBUG org.apache.hadoop.yarn.server.resourcemanager.scheduler.capacity.ParentQueue: Skip this queue=root, because it doesn't need more resource, schedulingMode=RESPECT_PARTITION_EXCLUSIVITY node-partition=
2019-06-07 07:52:04,093 DEBUG org.apache.hadoop.yarn.server.resourcemanager.scheduler.capacity.ParentQueue: Skip this queue=root, because it doesn't need more resource, schedulingMode=RESPECT_PARTITION_EXCLUSIVITY node-partition=
2019-06-07 07:52:04,476 INFO org.apache.hadoop.yarn.server.resourcemanager.scheduler.capacity.CapacityScheduler: Application 'application_1559893901343_0001' is submitted without priority hence considering default queue/cluster priority: 0
2019-06-07 07:52:04,476 INFO org.apache.hadoop.yarn.server.resourcemanager.scheduler.capacity.CapacityScheduler: Application 'application_1559893901343_0001' is submitted without priority hence considering default queue/cluster priority: 0
2019-06-07 07:52:04,476 INFO org.apache.hadoop.yarn.server.resourcemanager.scheduler.capacity.CapacityScheduler: Priority '0' is acceptable in queue : default for application: application_1559893901343_0001 for the user: root
2019-06-07 07:52:04,476 INFO org.apache.hadoop.yarn.server.resourcemanager.scheduler.capacity.CapacityScheduler: Priority '0' is acceptable in queue : default for application: application_1559893901343_0001 for the user: root
2019-06-07 07:52:04,491 WARN org.apache.hadoop.yarn.server.resourcemanager.rmapp.RMAppImpl: The specific max attempts: 0 for application: 1 is invalid, because it is out of the range [1, 2]. Use the global max attempts instead.
2019-06-07 07:52:04,491 WARN org.apache.hadoop.yarn.server.resourcemanager.rmapp.RMAppImpl: The specific max attempts: 0 for application: 1 is invalid, because it is out of the range [1, 2]. Use the global max attempts instead.
2019-06-07 07:52:04,501 INFO org.apache.hadoop.yarn.server.resourcemanager.ClientRMService: Application with id 1 submitted by user root
2019-06-07 07:52:04,501 INFO org.apache.hadoop.yarn.server.resourcemanager.ClientRMService: Application with id 1 submitted by user root
2019-06-07 07:52:04,501 DEBUG org.apache.hadoop.yarn.server.resourcemanager.rmapp.RMAppImpl: Processing event for application_1559893901343_0001 of type START
2019-06-07 07:52:04,501 DEBUG org.apache.hadoop.yarn.server.resourcemanager.rmapp.RMAppImpl: Processing event for application_1559893901343_0001 of type START
2019-06-07 07:52:04,502 INFO org.apache.hadoop.yarn.server.resourcemanager.rmapp.RMAppImpl: Storing application with id application_1559893901343_0001
2019-06-07 07:52:04,502 INFO org.apache.hadoop.yarn.server.resourcemanager.rmapp.RMAppImpl: Storing application with id application_1559893901343_0001
2019-06-07 07:52:04,506 INFO org.apache.hadoop.yarn.server.resourcemanager.RMAuditLogger: USER=root	IP=172.17.0.2	OPERATION=Submit Application Request	TARGET=ClientRMService	RESULT=SUCCESS	APPID=application_1559893901343_0001
2019-06-07 07:52:04,506 INFO org.apache.hadoop.yarn.server.resourcemanager.RMAuditLogger: USER=root	IP=172.17.0.2	OPERATION=Submit Application Request	TARGET=ClientRMService	RESULT=SUCCESS	APPID=application_1559893901343_0001
2019-06-07 07:52:04,520 DEBUG org.apache.hadoop.yarn.server.resourcemanager.recovery.RMStateStore: Processing event of type STORE_APP
2019-06-07 07:52:04,520 DEBUG org.apache.hadoop.yarn.server.resourcemanager.recovery.RMStateStore: Processing event of type STORE_APP
2019-06-07 07:52:04,520 INFO org.apache.hadoop.yarn.server.resourcemanager.recovery.RMStateStore: Storing info for app: application_1559893901343_0001
2019-06-07 07:52:04,520 INFO org.apache.hadoop.yarn.server.resourcemanager.recovery.RMStateStore: Storing info for app: application_1559893901343_0001
2019-06-07 07:52:04,521 INFO org.apache.hadoop.yarn.server.resourcemanager.rmapp.RMAppImpl: application_1559893901343_0001 State change from NEW to NEW_SAVING on event=START
2019-06-07 07:52:04,521 INFO org.apache.hadoop.yarn.server.resourcemanager.rmapp.RMAppImpl: application_1559893901343_0001 State change from NEW to NEW_SAVING on event=START
2019-06-07 07:52:04,521 DEBUG org.apache.hadoop.yarn.server.resourcemanager.rmapp.RMAppImpl: Processing event for application_1559893901343_0001 of type APP_NEW_SAVED
2019-06-07 07:52:04,521 DEBUG org.apache.hadoop.yarn.server.resourcemanager.rmapp.RMAppImpl: Processing event for application_1559893901343_0001 of type APP_NEW_SAVED
2019-06-07 07:52:04,521 INFO org.apache.hadoop.yarn.server.resourcemanager.rmapp.RMAppImpl: application_1559893901343_0001 State change from NEW_SAVING to SUBMITTED on event=APP_NEW_SAVED
2019-06-07 07:52:04,521 INFO org.apache.hadoop.yarn.server.resourcemanager.rmapp.RMAppImpl: application_1559893901343_0001 State change from NEW_SAVING to SUBMITTED on event=APP_NEW_SAVED
2019-06-07 07:52:04,527 INFO org.apache.hadoop.yarn.server.resourcemanager.scheduler.capacity.ParentQueue: Application added - appId: application_1559893901343_0001 user: root leaf-queue of parent: root #applications: 1
2019-06-07 07:52:04,527 INFO org.apache.hadoop.yarn.server.resourcemanager.scheduler.capacity.ParentQueue: Application added - appId: application_1559893901343_0001 user: root leaf-queue of parent: root #applications: 1
2019-06-07 07:52:04,528 INFO org.apache.hadoop.yarn.server.resourcemanager.scheduler.capacity.CapacityScheduler: Accepted application application_1559893901343_0001 from user: root, in queue: default
2019-06-07 07:52:04,528 INFO org.apache.hadoop.yarn.server.resourcemanager.scheduler.capacity.CapacityScheduler: Accepted application application_1559893901343_0001 from user: root, in queue: default
2019-06-07 07:52:04,555 DEBUG org.apache.hadoop.yarn.server.resourcemanager.rmapp.RMAppImpl: Processing event for application_1559893901343_0001 of type APP_ACCEPTED
2019-06-07 07:52:04,555 DEBUG org.apache.hadoop.yarn.server.resourcemanager.rmapp.RMAppImpl: Processing event for application_1559893901343_0001 of type APP_ACCEPTED
2019-06-07 07:52:04,569 INFO org.apache.hadoop.yarn.server.resourcemanager.rmapp.RMAppImpl: application_1559893901343_0001 State change from SUBMITTED to ACCEPTED on event=APP_ACCEPTED
2019-06-07 07:52:04,569 INFO org.apache.hadoop.yarn.server.resourcemanager.rmapp.RMAppImpl: application_1559893901343_0001 State change from SUBMITTED to ACCEPTED on event=APP_ACCEPTED
2019-06-07 07:52:04,574 DEBUG org.apache.hadoop.yarn.server.resourcemanager.rmapp.attempt.RMAppAttemptImpl: Processing event for appattempt_1559893901343_0001_000001 of type START
2019-06-07 07:52:04,574 DEBUG org.apache.hadoop.yarn.server.resourcemanager.rmapp.attempt.RMAppAttemptImpl: Processing event for appattempt_1559893901343_0001_000001 of type START
2019-06-07 07:52:04,615 INFO org.apache.hadoop.yarn.server.resourcemanager.ApplicationMasterService: Registering app attempt : appattempt_1559893901343_0001_000001
2019-06-07 07:52:04,615 INFO org.apache.hadoop.yarn.server.resourcemanager.ApplicationMasterService: Registering app attempt : appattempt_1559893901343_0001_000001
2019-06-07 07:52:04,615 INFO org.apache.hadoop.yarn.server.resourcemanager.rmapp.attempt.RMAppAttemptImpl: appattempt_1559893901343_0001_000001 State change from NEW to SUBMITTED
2019-06-07 07:52:04,615 INFO org.apache.hadoop.yarn.server.resourcemanager.rmapp.attempt.RMAppAttemptImpl: appattempt_1559893901343_0001_000001 State change from NEW to SUBMITTED
2019-06-07 07:52:04,636 DEBUG org.apache.hadoop.yarn.server.resourcemanager.scheduler.capacity.LeafQueue: application application_1559893901343_0001 AMResource <memory:1024, vCores:1> maxAMResourcePerQueuePercent 0.1 amLimit <memory:1024, vCores:1> lastClusterResource <memory:8192, vCores:2> amIfStarted <memory:1024, vCores:1> AM node-partition name 
2019-06-07 07:52:04,636 DEBUG org.apache.hadoop.yarn.server.resourcemanager.scheduler.capacity.LeafQueue: application application_1559893901343_0001 AMResource <memory:1024, vCores:1> maxAMResourcePerQueuePercent 0.1 amLimit <memory:1024, vCores:1> lastClusterResource <memory:8192, vCores:2> amIfStarted <memory:1024, vCores:1> AM node-partition name 
2019-06-07 07:52:04,636 DEBUG org.apache.hadoop.yarn.server.resourcemanager.scheduler.capacity.LeafQueue: Effective user AM limit for "root":<memory:1024, vCores:1>. Effective weighted user AM limit: <memory:1024, vCores:1>. User weight: 1.0
2019-06-07 07:52:04,636 DEBUG org.apache.hadoop.yarn.server.resourcemanager.scheduler.capacity.LeafQueue: Effective user AM limit for "root":<memory:1024, vCores:1>. Effective weighted user AM limit: <memory:1024, vCores:1>. User weight: 1.0
2019-06-07 07:52:04,638 INFO org.apache.hadoop.yarn.server.resourcemanager.scheduler.capacity.LeafQueue: Application application_1559893901343_0001 from user: root activated in queue: default
2019-06-07 07:52:04,638 INFO org.apache.hadoop.yarn.server.resourcemanager.scheduler.capacity.LeafQueue: Application application_1559893901343_0001 from user: root activated in queue: default
2019-06-07 07:52:04,638 INFO org.apache.hadoop.yarn.server.resourcemanager.scheduler.capacity.LeafQueue: Application added - appId: application_1559893901343_0001 user: root, leaf-queue: default #user-pending-applications: 0 #user-active-applications: 1 #queue-pending-applications: 0 #queue-active-applications: 1
2019-06-07 07:52:04,638 INFO org.apache.hadoop.yarn.server.resourcemanager.scheduler.capacity.LeafQueue: Application added - appId: application_1559893901343_0001 user: root, leaf-queue: default #user-pending-applications: 0 #user-active-applications: 1 #queue-pending-applications: 0 #queue-active-applications: 1
2019-06-07 07:52:04,638 INFO org.apache.hadoop.yarn.server.resourcemanager.scheduler.capacity.CapacityScheduler: Added Application Attempt appattempt_1559893901343_0001_000001 to scheduler from user root in queue default
2019-06-07 07:52:04,638 INFO org.apache.hadoop.yarn.server.resourcemanager.scheduler.capacity.CapacityScheduler: Added Application Attempt appattempt_1559893901343_0001_000001 to scheduler from user root in queue default
2019-06-07 07:52:04,638 DEBUG org.apache.hadoop.yarn.server.resourcemanager.rmapp.attempt.RMAppAttemptImpl: Processing event for appattempt_1559893901343_0001_000001 of type ATTEMPT_ADDED
2019-06-07 07:52:04,638 DEBUG org.apache.hadoop.yarn.server.resourcemanager.rmapp.attempt.RMAppAttemptImpl: Processing event for appattempt_1559893901343_0001_000001 of type ATTEMPT_ADDED
2019-06-07 07:52:04,639 DEBUG org.apache.hadoop.yarn.server.resourcemanager.rmapp.attempt.RMAppAttemptImpl: Using blacklist for AM: additions([]) and removals([])
2019-06-07 07:52:04,639 DEBUG org.apache.hadoop.yarn.server.resourcemanager.rmapp.attempt.RMAppAttemptImpl: Using blacklist for AM: additions([]) and removals([])
2019-06-07 07:52:04,639 DEBUG org.apache.hadoop.yarn.server.resourcemanager.scheduler.capacity.CapacityScheduler: allocate: pre-update appattempt_1559893901343_0001_000001 ask size =1
2019-06-07 07:52:04,639 DEBUG org.apache.hadoop.yarn.server.resourcemanager.scheduler.capacity.CapacityScheduler: allocate: pre-update appattempt_1559893901343_0001_000001 ask size =1
2019-06-07 07:52:04,641 DEBUG org.apache.hadoop.yarn.server.resourcemanager.scheduler.ActiveUsersManager: User root added to activeUsers, currently: 1
2019-06-07 07:52:04,641 DEBUG org.apache.hadoop.yarn.server.resourcemanager.scheduler.ActiveUsersManager: User root added to activeUsers, currently: 1
2019-06-07 07:52:04,641 DEBUG org.apache.hadoop.yarn.server.resourcemanager.scheduler.capacity.CapacityScheduler: allocate: post-update
2019-06-07 07:52:04,641 DEBUG org.apache.hadoop.yarn.server.resourcemanager.scheduler.capacity.CapacityScheduler: allocate: post-update
2019-06-07 07:52:04,641 DEBUG org.apache.hadoop.yarn.server.resourcemanager.scheduler.SchedulerApplicationAttempt: showRequests: application=application_1559893901343_0001 headRoom=<memory:0, vCores:0> currentConsumption=0
2019-06-07 07:52:04,641 DEBUG org.apache.hadoop.yarn.server.resourcemanager.scheduler.SchedulerApplicationAttempt: showRequests: application=application_1559893901343_0001 headRoom=<memory:0, vCores:0> currentConsumption=0
2019-06-07 07:52:04,641 DEBUG org.apache.hadoop.yarn.server.resourcemanager.scheduler.SchedulerApplicationAttempt: showRequests: application=application_1559893901343_0001 request={Priority: 0, Capability: <memory:1024, vCores:1>, # Containers: 1, Location: *, Relax Locality: true, Node Label Expression: }
2019-06-07 07:52:04,641 DEBUG org.apache.hadoop.yarn.server.resourcemanager.scheduler.SchedulerApplicationAttempt: showRequests: application=application_1559893901343_0001 request={Priority: 0, Capability: <memory:1024, vCores:1>, # Containers: 1, Location: *, Relax Locality: true, Node Label Expression: }
2019-06-07 07:52:04,642 INFO org.apache.hadoop.yarn.server.resourcemanager.rmapp.attempt.RMAppAttemptImpl: appattempt_1559893901343_0001_000001 State change from SUBMITTED to SCHEDULED
2019-06-07 07:52:04,642 INFO org.apache.hadoop.yarn.server.resourcemanager.rmapp.attempt.RMAppAttemptImpl: appattempt_1559893901343_0001_000001 State change from SUBMITTED to SCHEDULED
2019-06-07 07:52:05,093 DEBUG org.apache.hadoop.yarn.server.resourcemanager.rmnode.RMNodeImpl: Processing slave1:39995 of type STATUS_UPDATE
2019-06-07 07:52:05,093 DEBUG org.apache.hadoop.yarn.server.resourcemanager.rmnode.RMNodeImpl: Processing slave1:39995 of type STATUS_UPDATE
2019-06-07 07:52:05,094 DEBUG org.apache.hadoop.yarn.server.resourcemanager.scheduler.capacity.CapacityScheduler: nodeUpdate: slave1:39995 clusterResources: <memory:8192, vCores:2>
2019-06-07 07:52:05,094 DEBUG org.apache.hadoop.yarn.server.resourcemanager.scheduler.capacity.CapacityScheduler: nodeUpdate: slave1:39995 clusterResources: <memory:8192, vCores:2>
2019-06-07 07:52:05,094 DEBUG org.apache.hadoop.yarn.server.resourcemanager.scheduler.capacity.CapacityScheduler: Node being looked for scheduling slave1:39995 availableResource: <memory:4096, vCores:1>
2019-06-07 07:52:05,094 DEBUG org.apache.hadoop.yarn.server.resourcemanager.scheduler.capacity.CapacityScheduler: Node being looked for scheduling slave1:39995 availableResource: <memory:4096, vCores:1>
2019-06-07 07:52:05,094 DEBUG org.apache.hadoop.yarn.server.resourcemanager.scheduler.capacity.CapacityScheduler: Trying to schedule on node: slave1, available: <memory:4096, vCores:1>
2019-06-07 07:52:05,094 DEBUG org.apache.hadoop.yarn.server.resourcemanager.scheduler.capacity.CapacityScheduler: Trying to schedule on node: slave1, available: <memory:4096, vCores:1>
2019-06-07 07:52:05,094 DEBUG org.apache.hadoop.yarn.server.resourcemanager.scheduler.capacity.ParentQueue: Trying to assign containers to child-queue of root
2019-06-07 07:52:05,094 DEBUG org.apache.hadoop.yarn.server.resourcemanager.scheduler.capacity.ParentQueue: Trying to assign containers to child-queue of root
2019-06-07 07:52:05,095 DEBUG org.apache.hadoop.yarn.server.resourcemanager.scheduler.capacity.ParentQueue: printChildQueues - queue: root child-queues: root.defaultusedCapacity=(0.0),  label=(*)
2019-06-07 07:52:05,095 DEBUG org.apache.hadoop.yarn.server.resourcemanager.scheduler.capacity.ParentQueue: printChildQueues - queue: root child-queues: root.defaultusedCapacity=(0.0),  label=(*)
2019-06-07 07:52:05,095 DEBUG org.apache.hadoop.yarn.server.resourcemanager.scheduler.capacity.ParentQueue: Trying to assign to queue: root.default stats: default: capacity=1.0, absoluteCapacity=1.0, usedResources=<memory:0, vCores:0>, usedCapacity=0.0, absoluteUsedCapacity=0.0, numApps=1, numContainers=0
2019-06-07 07:52:05,095 DEBUG org.apache.hadoop.yarn.server.resourcemanager.scheduler.capacity.ParentQueue: Trying to assign to queue: root.default stats: default: capacity=1.0, absoluteCapacity=1.0, usedResources=<memory:0, vCores:0>, usedCapacity=0.0, absoluteUsedCapacity=0.0, numApps=1, numContainers=0
2019-06-07 07:52:05,095 DEBUG org.apache.hadoop.yarn.server.resourcemanager.scheduler.capacity.LeafQueue: assignContainers: node=slave1 #applications=1
2019-06-07 07:52:05,095 DEBUG org.apache.hadoop.yarn.server.resourcemanager.scheduler.capacity.LeafQueue: assignContainers: node=slave1 #applications=1
2019-06-07 07:52:05,095 DEBUG org.apache.hadoop.yarn.server.resourcemanager.scheduler.capacity.LeafQueue: User limit computation for root in queue default userLimitPercent=100 userLimitFactor=1.0 required: <memory:1024, vCores:1> consumed: <memory:0, vCores:0> user-limit-resource: <memory:8192, vCores:1> queueCapacity: <memory:8192, vCores:1> qconsumed: <memory:0, vCores:0> consumedRatio: 0.0 currentCapacity: <memory:8192, vCores:1> activeUsers: 1.0 clusterCapacity: <memory:8192, vCores:2> resourceByLabel: <memory:8192, vCores:2> usageratio: 0.0 Partition:  maxUserLimit=<memory:8192, vCores:1> userWeight=1.0
2019-06-07 07:52:05,095 DEBUG org.apache.hadoop.yarn.server.resourcemanager.scheduler.capacity.LeafQueue: User limit computation for root in queue default userLimitPercent=100 userLimitFactor=1.0 required: <memory:1024, vCores:1> consumed: <memory:0, vCores:0> user-limit-resource: <memory:8192, vCores:1> queueCapacity: <memory:8192, vCores:1> qconsumed: <memory:0, vCores:0> consumedRatio: 0.0 currentCapacity: <memory:8192, vCores:1> activeUsers: 1.0 clusterCapacity: <memory:8192, vCores:2> resourceByLabel: <memory:8192, vCores:2> usageratio: 0.0 Partition:  maxUserLimit=<memory:8192, vCores:1> userWeight=1.0
2019-06-07 07:52:05,095 DEBUG org.apache.hadoop.yarn.server.resourcemanager.scheduler.capacity.LeafQueue: Headroom calculation for user root:  userLimit=<memory:8192, vCores:1> queueMaxAvailRes=<memory:8192, vCores:1> consumed=<memory:0, vCores:0>
2019-06-07 07:52:05,095 DEBUG org.apache.hadoop.yarn.server.resourcemanager.scheduler.capacity.LeafQueue: Headroom calculation for user root:  userLimit=<memory:8192, vCores:1> queueMaxAvailRes=<memory:8192, vCores:1> consumed=<memory:0, vCores:0>
2019-06-07 07:52:05,097 DEBUG org.apache.hadoop.yarn.server.resourcemanager.scheduler.common.fica.FiCaSchedulerApp: pre-assignContainers for application application_1559893901343_0001
2019-06-07 07:52:05,097 DEBUG org.apache.hadoop.yarn.server.resourcemanager.scheduler.common.fica.FiCaSchedulerApp: pre-assignContainers for application application_1559893901343_0001
2019-06-07 07:52:05,098 DEBUG org.apache.hadoop.yarn.server.resourcemanager.scheduler.capacity.LeafQueue: User limit computation for root in queue default userLimitPercent=100 userLimitFactor=1.0 required: <memory:1024, vCores:1> consumed: <memory:0, vCores:0> user-limit-resource: <memory:8192, vCores:1> queueCapacity: <memory:8192, vCores:1> qconsumed: <memory:0, vCores:0> consumedRatio: 0.0 currentCapacity: <memory:8192, vCores:1> activeUsers: 1.0 clusterCapacity: <memory:8192, vCores:2> resourceByLabel: <memory:8192, vCores:2> usageratio: 0.0 Partition:  maxUserLimit=<memory:8192, vCores:1> userWeight=1.0
2019-06-07 07:52:05,098 DEBUG org.apache.hadoop.yarn.server.resourcemanager.scheduler.capacity.LeafQueue: User limit computation for root in queue default userLimitPercent=100 userLimitFactor=1.0 required: <memory:1024, vCores:1> consumed: <memory:0, vCores:0> user-limit-resource: <memory:8192, vCores:1> queueCapacity: <memory:8192, vCores:1> qconsumed: <memory:0, vCores:0> consumedRatio: 0.0 currentCapacity: <memory:8192, vCores:1> activeUsers: 1.0 clusterCapacity: <memory:8192, vCores:2> resourceByLabel: <memory:8192, vCores:2> usageratio: 0.0 Partition:  maxUserLimit=<memory:8192, vCores:1> userWeight=1.0
2019-06-07 07:52:05,099 DEBUG org.apache.hadoop.yarn.server.resourcemanager.rmnode.RMNodeImpl: Processing slave2:38494 of type STATUS_UPDATE
2019-06-07 07:52:05,099 DEBUG org.apache.hadoop.yarn.server.resourcemanager.rmnode.RMNodeImpl: Processing slave2:38494 of type STATUS_UPDATE
2019-06-07 07:52:05,098 DEBUG org.apache.hadoop.yarn.server.resourcemanager.scheduler.SchedulerApplicationAttempt: showRequests: application=application_1559893901343_0001 headRoom=<memory:8192, vCores:2> currentConsumption=0
2019-06-07 07:52:05,098 DEBUG org.apache.hadoop.yarn.server.resourcemanager.scheduler.SchedulerApplicationAttempt: showRequests: application=application_1559893901343_0001 headRoom=<memory:8192, vCores:2> currentConsumption=0
2019-06-07 07:52:05,102 DEBUG org.apache.hadoop.yarn.server.resourcemanager.scheduler.SchedulerApplicationAttempt: showRequests: application=application_1559893901343_0001 request={Priority: 0, Capability: <memory:1024, vCores:1>, # Containers: 1, Location: *, Relax Locality: true, Node Label Expression: }
2019-06-07 07:52:05,102 DEBUG org.apache.hadoop.yarn.server.resourcemanager.scheduler.SchedulerApplicationAttempt: showRequests: application=application_1559893901343_0001 request={Priority: 0, Capability: <memory:1024, vCores:1>, # Containers: 1, Location: *, Relax Locality: true, Node Label Expression: }
2019-06-07 07:52:05,102 DEBUG org.apache.hadoop.yarn.server.resourcemanager.scheduler.capacity.allocator.IncreaseContainerAllocator: Skip allocating increase request since we don't have any increase request on this node=slave1:39995
2019-06-07 07:52:05,102 DEBUG org.apache.hadoop.yarn.server.resourcemanager.scheduler.capacity.allocator.IncreaseContainerAllocator: Skip allocating increase request since we don't have any increase request on this node=slave1:39995
2019-06-07 07:52:05,104 DEBUG org.apache.hadoop.yarn.server.resourcemanager.scheduler.capacity.allocator.RegularContainerAllocator: assignContainers: node=slave1 application=application_1559893901343_0001 priority=0 request={Priority: 0, Capability: <memory:1024, vCores:1>, # Containers: 1, Location: *, Relax Locality: true, Node Label Expression: } type=OFF_SWITCH
2019-06-07 07:52:05,104 DEBUG org.apache.hadoop.yarn.server.resourcemanager.scheduler.capacity.allocator.RegularContainerAllocator: assignContainers: node=slave1 application=application_1559893901343_0001 priority=0 request={Priority: 0, Capability: <memory:1024, vCores:1>, # Containers: 1, Location: *, Relax Locality: true, Node Label Expression: } type=OFF_SWITCH
2019-06-07 07:52:05,238 DEBUG org.apache.hadoop.yarn.server.resourcemanager.scheduler.ActiveUsersManager: User root removed from activeUsers, currently: 0
2019-06-07 07:52:05,238 DEBUG org.apache.hadoop.yarn.server.resourcemanager.scheduler.ActiveUsersManager: User root removed from activeUsers, currently: 0
2019-06-07 07:52:05,244 DEBUG org.apache.hadoop.yarn.server.resourcemanager.scheduler.AppSchedulingInfo: allocate: applicationId=application_1559893901343_0001 container=container_1559893901343_0001_01_000001 host=slave1:39995 user=root resource=<memory:1024, vCores:1> type=OFF_SWITCH
2019-06-07 07:52:05,244 DEBUG org.apache.hadoop.yarn.server.resourcemanager.scheduler.AppSchedulingInfo: allocate: applicationId=application_1559893901343_0001 container=container_1559893901343_0001_01_000001 host=slave1:39995 user=root resource=<memory:1024, vCores:1> type=OFF_SWITCH
2019-06-07 07:52:05,244 DEBUG org.apache.hadoop.yarn.server.resourcemanager.rmcontainer.RMContainerImpl: Processing container_1559893901343_0001_01_000001 of type START
2019-06-07 07:52:05,244 DEBUG org.apache.hadoop.yarn.server.resourcemanager.rmcontainer.RMContainerImpl: Processing container_1559893901343_0001_01_000001 of type START
2019-06-07 07:52:05,245 DEBUG org.apache.hadoop.yarn.server.resourcemanager.rmapp.attempt.RMAppAttemptImpl: Processing event for appattempt_1559893901343_0001_000001 of type CONTAINER_ALLOCATED
2019-06-07 07:52:05,245 DEBUG org.apache.hadoop.yarn.server.resourcemanager.rmapp.attempt.RMAppAttemptImpl: Processing event for appattempt_1559893901343_0001_000001 of type CONTAINER_ALLOCATED
2019-06-07 07:52:05,245 INFO org.apache.hadoop.yarn.server.resourcemanager.rmcontainer.RMContainerImpl: container_1559893901343_0001_01_000001 Container Transitioned from NEW to ALLOCATED
2019-06-07 07:52:05,245 INFO org.apache.hadoop.yarn.server.resourcemanager.rmcontainer.RMContainerImpl: container_1559893901343_0001_01_000001 Container Transitioned from NEW to ALLOCATED
2019-06-07 07:52:05,245 DEBUG org.apache.hadoop.yarn.server.resourcemanager.scheduler.common.fica.FiCaSchedulerApp: allocate: applicationAttemptId=appattempt_1559893901343_0001_000001 container=container_1559893901343_0001_01_000001 host=slave1 type=OFF_SWITCH
2019-06-07 07:52:05,245 DEBUG org.apache.hadoop.yarn.server.resourcemanager.scheduler.common.fica.FiCaSchedulerApp: allocate: applicationAttemptId=appattempt_1559893901343_0001_000001 container=container_1559893901343_0001_01_000001 host=slave1 type=OFF_SWITCH
2019-06-07 07:52:05,245 INFO org.apache.hadoop.yarn.server.resourcemanager.RMAuditLogger: USER=root	OPERATION=AM Allocated Container	TARGET=SchedulerApp	RESULT=SUCCESS	APPID=application_1559893901343_0001	CONTAINERID=container_1559893901343_0001_01_000001
2019-06-07 07:52:05,245 INFO org.apache.hadoop.yarn.server.resourcemanager.RMAuditLogger: USER=root	OPERATION=AM Allocated Container	TARGET=SchedulerApp	RESULT=SUCCESS	APPID=application_1559893901343_0001	CONTAINERID=container_1559893901343_0001_01_000001
2019-06-07 07:52:05,246 INFO org.apache.hadoop.yarn.server.resourcemanager.scheduler.SchedulerNode: Assigned container container_1559893901343_0001_01_000001 of capacity <memory:1024, vCores:1> on host slave1:39995, which has 1 containers, <memory:1024, vCores:1> used and <memory:3072, vCores:0> available after allocation
2019-06-07 07:52:05,246 INFO org.apache.hadoop.yarn.server.resourcemanager.scheduler.SchedulerNode: Assigned container container_1559893901343_0001_01_000001 of capacity <memory:1024, vCores:1> on host slave1:39995, which has 1 containers, <memory:1024, vCores:1> used and <memory:3072, vCores:0> available after allocation
2019-06-07 07:52:05,247 INFO org.apache.hadoop.yarn.server.resourcemanager.scheduler.capacity.allocator.AbstractContainerAllocator: assignedContainer application attempt=appattempt_1559893901343_0001_000001 container=container_1559893901343_0001_01_000001 queue=org.apache.hadoop.yarn.server.resourcemanager.scheduler.capacity.allocator.RegularContainerAllocator@17efde5 clusterResource=<memory:8192, vCores:2> type=OFF_SWITCH requestedPartition=
2019-06-07 07:52:05,247 INFO org.apache.hadoop.yarn.server.resourcemanager.scheduler.capacity.allocator.AbstractContainerAllocator: assignedContainer application attempt=appattempt_1559893901343_0001_000001 container=container_1559893901343_0001_01_000001 queue=org.apache.hadoop.yarn.server.resourcemanager.scheduler.capacity.allocator.RegularContainerAllocator@17efde5 clusterResource=<memory:8192, vCores:2> type=OFF_SWITCH requestedPartition=
2019-06-07 07:52:05,255 DEBUG org.apache.hadoop.yarn.server.resourcemanager.scheduler.capacity.LeafQueue: post-assignContainers for application application_1559893901343_0001
2019-06-07 07:52:05,255 DEBUG org.apache.hadoop.yarn.server.resourcemanager.scheduler.capacity.LeafQueue: post-assignContainers for application application_1559893901343_0001
2019-06-07 07:52:05,264 INFO org.apache.hadoop.yarn.server.resourcemanager.security.NMTokenSecretManagerInRM: Sending NMToken for nodeId : slave1:39995 for container : container_1559893901343_0001_01_000001
2019-06-07 07:52:05,264 INFO org.apache.hadoop.yarn.server.resourcemanager.security.NMTokenSecretManagerInRM: Sending NMToken for nodeId : slave1:39995 for container : container_1559893901343_0001_01_000001
2019-06-07 07:52:05,271 DEBUG org.apache.hadoop.yarn.server.resourcemanager.rmcontainer.RMContainerImpl: Processing container_1559893901343_0001_01_000001 of type ACQUIRED
2019-06-07 07:52:05,271 DEBUG org.apache.hadoop.yarn.server.resourcemanager.rmcontainer.RMContainerImpl: Processing container_1559893901343_0001_01_000001 of type ACQUIRED
2019-06-07 07:52:05,273 INFO org.apache.hadoop.yarn.server.resourcemanager.rmcontainer.RMContainerImpl: container_1559893901343_0001_01_000001 Container Transitioned from ALLOCATED to ACQUIRED
2019-06-07 07:52:05,273 INFO org.apache.hadoop.yarn.server.resourcemanager.rmcontainer.RMContainerImpl: container_1559893901343_0001_01_000001 Container Transitioned from ALLOCATED to ACQUIRED
2019-06-07 07:52:05,273 DEBUG org.apache.hadoop.yarn.server.resourcemanager.scheduler.capacity.LeafQueue: User limit computation for root in queue default userLimitPercent=100 userLimitFactor=1.0 required: <memory:1024, vCores:1> consumed: <memory:0, vCores:0> user-limit-resource: <memory:8192, vCores:1> queueCapacity: <memory:8192, vCores:1> qconsumed: <memory:0, vCores:0> consumedRatio: 0.0 currentCapacity: <memory:8192, vCores:1> activeUsers: 0.0 clusterCapacity: <memory:8192, vCores:2> resourceByLabel: <memory:8192, vCores:2> usageratio: 0.0 Partition:  maxUserLimit=<memory:8192, vCores:1> userWeight=1.0
2019-06-07 07:52:05,273 DEBUG org.apache.hadoop.yarn.server.resourcemanager.scheduler.capacity.LeafQueue: User limit computation for root in queue default userLimitPercent=100 userLimitFactor=1.0 required: <memory:1024, vCores:1> consumed: <memory:0, vCores:0> user-limit-resource: <memory:8192, vCores:1> queueCapacity: <memory:8192, vCores:1> qconsumed: <memory:0, vCores:0> consumedRatio: 0.0 currentCapacity: <memory:8192, vCores:1> activeUsers: 0.0 clusterCapacity: <memory:8192, vCores:2> resourceByLabel: <memory:8192, vCores:2> usageratio: 0.0 Partition:  maxUserLimit=<memory:8192, vCores:1> userWeight=1.0
2019-06-07 07:52:05,273 DEBUG org.apache.hadoop.yarn.server.resourcemanager.scheduler.capacity.LeafQueue: User limit computation for root in queue default userLimitPercent=100 userLimitFactor=1.0 required: <memory:1024, vCores:1> consumed: <memory:1024, vCores:1> user-limit-resource: <memory:8192, vCores:1> queueCapacity: <memory:8192, vCores:1> qconsumed: <memory:1024, vCores:1> consumedRatio: 0.0 currentCapacity: <memory:8192, vCores:1> activeUsers: 0.0 clusterCapacity: <memory:8192, vCores:2> resourceByLabel: <memory:8192, vCores:2> usageratio: 0.125 Partition:  maxUserLimit=<memory:8192, vCores:1> userWeight=1.0
2019-06-07 07:52:05,273 DEBUG org.apache.hadoop.yarn.server.resourcemanager.scheduler.capacity.LeafQueue: User limit computation for root in queue default userLimitPercent=100 userLimitFactor=1.0 required: <memory:1024, vCores:1> consumed: <memory:1024, vCores:1> user-limit-resource: <memory:8192, vCores:1> queueCapacity: <memory:8192, vCores:1> qconsumed: <memory:1024, vCores:1> consumedRatio: 0.0 currentCapacity: <memory:8192, vCores:1> activeUsers: 0.0 clusterCapacity: <memory:8192, vCores:2> resourceByLabel: <memory:8192, vCores:2> usageratio: 0.125 Partition:  maxUserLimit=<memory:8192, vCores:1> userWeight=1.0
2019-06-07 07:52:05,273 DEBUG org.apache.hadoop.yarn.server.resourcemanager.scheduler.capacity.LeafQueue: User limit computation for root in queue default userLimitPercent=100 userLimitFactor=1.0 required: <memory:1024, vCores:1> consumed: <memory:1024, vCores:1> user-limit-resource: <memory:8192, vCores:1> queueCapacity: <memory:8192, vCores:1> qconsumed: <memory:1024, vCores:1> consumedRatio: 0.0 currentCapacity: <memory:8192, vCores:1> activeUsers: 0.0 clusterCapacity: <memory:8192, vCores:2> resourceByLabel: <memory:8192, vCores:2> usageratio: 0.125 Partition:  maxUserLimit=<memory:8192, vCores:1> userWeight=1.0
2019-06-07 07:52:05,273 DEBUG org.apache.hadoop.yarn.server.resourcemanager.scheduler.capacity.LeafQueue: User limit computation for root in queue default userLimitPercent=100 userLimitFactor=1.0 required: <memory:1024, vCores:1> consumed: <memory:1024, vCores:1> user-limit-resource: <memory:8192, vCores:1> queueCapacity: <memory:8192, vCores:1> qconsumed: <memory:1024, vCores:1> consumedRatio: 0.0 currentCapacity: <memory:8192, vCores:1> activeUsers: 0.0 clusterCapacity: <memory:8192, vCores:2> resourceByLabel: <memory:8192, vCores:2> usageratio: 0.125 Partition:  maxUserLimit=<memory:8192, vCores:1> userWeight=1.0
2019-06-07 07:52:05,273 DEBUG org.apache.hadoop.yarn.server.resourcemanager.scheduler.capacity.LeafQueue: User limit computation for root in queue default userLimitPercent=100 userLimitFactor=1.0 required: <memory:1024, vCores:1> consumed: <memory:1024, vCores:1> user-limit-resource: <memory:8192, vCores:1> queueCapacity: <memory:8192, vCores:1> qconsumed: <memory:1024, vCores:1> consumedRatio: 0.0 currentCapacity: <memory:8192, vCores:1> activeUsers: 0.0 clusterCapacity: <memory:8192, vCores:2> resourceByLabel: <memory:8192, vCores:2> usageratio: 0.125 Partition:  maxUserLimit=<memory:8192, vCores:1> userWeight=1.0
2019-06-07 07:52:05,273 DEBUG org.apache.hadoop.yarn.server.resourcemanager.scheduler.capacity.LeafQueue: User limit computation for root in queue default userLimitPercent=100 userLimitFactor=1.0 required: <memory:1024, vCores:1> consumed: <memory:1024, vCores:1> user-limit-resource: <memory:8192, vCores:1> queueCapacity: <memory:8192, vCores:1> qconsumed: <memory:1024, vCores:1> consumedRatio: 0.0 currentCapacity: <memory:8192, vCores:1> activeUsers: 0.0 clusterCapacity: <memory:8192, vCores:2> resourceByLabel: <memory:8192, vCores:2> usageratio: 0.125 Partition:  maxUserLimit=<memory:8192, vCores:1> userWeight=1.0
2019-06-07 07:52:05,273 DEBUG org.apache.hadoop.yarn.server.resourcemanager.scheduler.capacity.LeafQueue: default user=root used=<memory:1024, vCores:1> numContainers=1 headroom = <memory:7168, vCores:1> user-resources=<memory:1024, vCores:1>
2019-06-07 07:52:05,273 DEBUG org.apache.hadoop.yarn.server.resourcemanager.scheduler.capacity.LeafQueue: default user=root used=<memory:1024, vCores:1> numContainers=1 headroom = <memory:7168, vCores:1> user-resources=<memory:1024, vCores:1>
2019-06-07 07:52:05,273 DEBUG org.apache.hadoop.yarn.server.resourcemanager.scheduler.capacity.ParentQueue: Assigned to queue: root.default stats: default: capacity=1.0, absoluteCapacity=1.0, usedResources=<memory:1024, vCores:1>, usedCapacity=0.125, absoluteUsedCapacity=0.125, numApps=1, numContainers=1 --> <memory:1024, vCores:1>, OFF_SWITCH
2019-06-07 07:52:05,273 DEBUG org.apache.hadoop.yarn.server.resourcemanager.scheduler.capacity.ParentQueue: Assigned to queue: root.default stats: default: capacity=1.0, absoluteCapacity=1.0, usedResources=<memory:1024, vCores:1>, usedCapacity=0.125, absoluteUsedCapacity=0.125, numApps=1, numContainers=1 --> <memory:1024, vCores:1>, OFF_SWITCH
2019-06-07 07:52:05,273 INFO org.apache.hadoop.yarn.server.resourcemanager.scheduler.capacity.ParentQueue: Re-sorting assigned queue: root.default stats: default: capacity=1.0, absoluteCapacity=1.0, usedResources=<memory:1024, vCores:1>, usedCapacity=0.125, absoluteUsedCapacity=0.125, numApps=1, numContainers=1
2019-06-07 07:52:05,273 INFO org.apache.hadoop.yarn.server.resourcemanager.scheduler.capacity.ParentQueue: Re-sorting assigned queue: root.default stats: default: capacity=1.0, absoluteCapacity=1.0, usedResources=<memory:1024, vCores:1>, usedCapacity=0.125, absoluteUsedCapacity=0.125, numApps=1, numContainers=1
2019-06-07 07:52:05,273 DEBUG org.apache.hadoop.yarn.server.resourcemanager.scheduler.capacity.ParentQueue: printChildQueues - queue: root child-queues: root.defaultusedCapacity=(0.125),  label=(*)
2019-06-07 07:52:05,273 DEBUG org.apache.hadoop.yarn.server.resourcemanager.scheduler.capacity.ParentQueue: printChildQueues - queue: root child-queues: root.defaultusedCapacity=(0.125),  label=(*)
2019-06-07 07:52:05,274 INFO org.apache.hadoop.yarn.server.resourcemanager.scheduler.capacity.ParentQueue: assignedContainer queue=root usedCapacity=0.125 absoluteUsedCapacity=0.125 used=<memory:1024, vCores:1> cluster=<memory:8192, vCores:2>
2019-06-07 07:52:05,274 INFO org.apache.hadoop.yarn.server.resourcemanager.scheduler.capacity.ParentQueue: assignedContainer queue=root usedCapacity=0.125 absoluteUsedCapacity=0.125 used=<memory:1024, vCores:1> cluster=<memory:8192, vCores:2>
2019-06-07 07:52:05,274 DEBUG org.apache.hadoop.yarn.server.resourcemanager.scheduler.capacity.ParentQueue: ParentQ=root assignedSoFarInThisIteration=<memory:1024, vCores:1> usedCapacity=0.125 absoluteUsedCapacity=0.125
2019-06-07 07:52:05,274 DEBUG org.apache.hadoop.yarn.server.resourcemanager.scheduler.capacity.ParentQueue: ParentQ=root assignedSoFarInThisIteration=<memory:1024, vCores:1> usedCapacity=0.125 absoluteUsedCapacity=0.125
2019-06-07 07:52:05,274 DEBUG org.apache.hadoop.yarn.server.resourcemanager.scheduler.capacity.ParentQueue: Assigned maximum number of off-switch containers: 1, assignments so far: resource:<memory:1024, vCores:1>; type:OFF_SWITCH; excessReservation:null; applicationid:null; skipped:NONE; fulfilled reservation:false; allocations(count/resource):1/<memory:1024, vCores:1>; reservations(count/resource):0/<memory:0, vCores:0>
2019-06-07 07:52:05,274 DEBUG org.apache.hadoop.yarn.server.resourcemanager.scheduler.capacity.ParentQueue: Assigned maximum number of off-switch containers: 1, assignments so far: resource:<memory:1024, vCores:1>; type:OFF_SWITCH; excessReservation:null; applicationid:null; skipped:NONE; fulfilled reservation:false; allocations(count/resource):1/<memory:1024, vCores:1>; reservations(count/resource):0/<memory:0, vCores:0>
2019-06-07 07:52:05,274 DEBUG org.apache.hadoop.yarn.server.resourcemanager.scheduler.capacity.CapacityScheduler: nodeUpdate: slave2:38494 clusterResources: <memory:8192, vCores:2>
2019-06-07 07:52:05,274 DEBUG org.apache.hadoop.yarn.server.resourcemanager.scheduler.capacity.CapacityScheduler: nodeUpdate: slave2:38494 clusterResources: <memory:8192, vCores:2>
2019-06-07 07:52:05,274 DEBUG org.apache.hadoop.yarn.server.resourcemanager.scheduler.capacity.CapacityScheduler: Node being looked for scheduling slave2:38494 availableResource: <memory:4096, vCores:1>
2019-06-07 07:52:05,274 DEBUG org.apache.hadoop.yarn.server.resourcemanager.scheduler.capacity.CapacityScheduler: Node being looked for scheduling slave2:38494 availableResource: <memory:4096, vCores:1>
2019-06-07 07:52:05,274 DEBUG org.apache.hadoop.yarn.server.resourcemanager.scheduler.capacity.CapacityScheduler: Trying to schedule on node: slave2, available: <memory:4096, vCores:1>
2019-06-07 07:52:05,274 DEBUG org.apache.hadoop.yarn.server.resourcemanager.scheduler.capacity.CapacityScheduler: Trying to schedule on node: slave2, available: <memory:4096, vCores:1>
2019-06-07 07:52:05,274 DEBUG org.apache.hadoop.yarn.server.resourcemanager.scheduler.capacity.ParentQueue: Skip this queue=root, because it doesn't need more resource, schedulingMode=RESPECT_PARTITION_EXCLUSIVITY node-partition=
2019-06-07 07:52:05,274 DEBUG org.apache.hadoop.yarn.server.resourcemanager.scheduler.capacity.ParentQueue: Skip this queue=root, because it doesn't need more resource, schedulingMode=RESPECT_PARTITION_EXCLUSIVITY node-partition=
2019-06-07 07:52:05,274 INFO org.apache.hadoop.yarn.server.resourcemanager.security.NMTokenSecretManagerInRM: Clear node set for appattempt_1559893901343_0001_000001
2019-06-07 07:52:05,274 INFO org.apache.hadoop.yarn.server.resourcemanager.security.NMTokenSecretManagerInRM: Clear node set for appattempt_1559893901343_0001_000001
2019-06-07 07:52:05,275 INFO org.apache.hadoop.yarn.server.resourcemanager.rmapp.attempt.RMAppAttemptImpl: Storing attempt: AppId: application_1559893901343_0001 AttemptId: appattempt_1559893901343_0001_000001 MasterContainer: Container: [ContainerId: container_1559893901343_0001_01_000001, Version: 0, NodeId: slave1:39995, NodeHttpAddress: slave1:8042, Resource: <memory:1024, vCores:1>, Priority: 0, Token: Token { kind: ContainerToken, service: 172.17.0.3:39995 }, ]
2019-06-07 07:52:05,275 INFO org.apache.hadoop.yarn.server.resourcemanager.rmapp.attempt.RMAppAttemptImpl: Storing attempt: AppId: application_1559893901343_0001 AttemptId: appattempt_1559893901343_0001_000001 MasterContainer: Container: [ContainerId: container_1559893901343_0001_01_000001, Version: 0, NodeId: slave1:39995, NodeHttpAddress: slave1:8042, Resource: <memory:1024, vCores:1>, Priority: 0, Token: Token { kind: ContainerToken, service: 172.17.0.3:39995 }, ]
2019-06-07 07:52:05,283 DEBUG org.apache.hadoop.yarn.server.resourcemanager.recovery.RMStateStore: Processing event of type STORE_APP_ATTEMPT
2019-06-07 07:52:05,283 DEBUG org.apache.hadoop.yarn.server.resourcemanager.recovery.RMStateStore: Processing event of type STORE_APP_ATTEMPT
2019-06-07 07:52:05,283 DEBUG org.apache.hadoop.yarn.server.resourcemanager.recovery.RMStateStore: Storing info for attempt: appattempt_1559893901343_0001_000001
2019-06-07 07:52:05,283 DEBUG org.apache.hadoop.yarn.server.resourcemanager.recovery.RMStateStore: Storing info for attempt: appattempt_1559893901343_0001_000001
2019-06-07 07:52:05,283 INFO org.apache.hadoop.yarn.server.resourcemanager.rmapp.attempt.RMAppAttemptImpl: appattempt_1559893901343_0001_000001 State change from SCHEDULED to ALLOCATED_SAVING
2019-06-07 07:52:05,283 INFO org.apache.hadoop.yarn.server.resourcemanager.rmapp.attempt.RMAppAttemptImpl: appattempt_1559893901343_0001_000001 State change from SCHEDULED to ALLOCATED_SAVING
2019-06-07 07:52:05,283 DEBUG org.apache.hadoop.yarn.server.resourcemanager.rmapp.RMAppImpl: Processing event for application_1559893901343_0001 of type APP_RUNNING_ON_NODE
2019-06-07 07:52:05,283 DEBUG org.apache.hadoop.yarn.server.resourcemanager.rmapp.RMAppImpl: Processing event for application_1559893901343_0001 of type APP_RUNNING_ON_NODE
2019-06-07 07:52:05,288 DEBUG org.apache.hadoop.yarn.server.resourcemanager.rmapp.attempt.RMAppAttemptImpl: Processing event for appattempt_1559893901343_0001_000001 of type ATTEMPT_NEW_SAVED
2019-06-07 07:52:05,288 DEBUG org.apache.hadoop.yarn.server.resourcemanager.rmapp.attempt.RMAppAttemptImpl: Processing event for appattempt_1559893901343_0001_000001 of type ATTEMPT_NEW_SAVED
2019-06-07 07:52:05,289 INFO org.apache.hadoop.yarn.server.resourcemanager.rmapp.attempt.RMAppAttemptImpl: appattempt_1559893901343_0001_000001 State change from ALLOCATED_SAVING to ALLOCATED
2019-06-07 07:52:05,289 INFO org.apache.hadoop.yarn.server.resourcemanager.rmapp.attempt.RMAppAttemptImpl: appattempt_1559893901343_0001_000001 State change from ALLOCATED_SAVING to ALLOCATED
2019-06-07 07:52:05,292 INFO org.apache.hadoop.yarn.server.resourcemanager.amlauncher.AMLauncher: Launching masterappattempt_1559893901343_0001_000001
2019-06-07 07:52:05,292 INFO org.apache.hadoop.yarn.server.resourcemanager.amlauncher.AMLauncher: Launching masterappattempt_1559893901343_0001_000001
2019-06-07 07:52:05,341 INFO org.apache.hadoop.yarn.server.resourcemanager.amlauncher.AMLauncher: Setting up container Container: [ContainerId: container_1559893901343_0001_01_000001, Version: 0, NodeId: slave1:39995, NodeHttpAddress: slave1:8042, Resource: <memory:1024, vCores:1>, Priority: 0, Token: Token { kind: ContainerToken, service: 172.17.0.3:39995 }, ] for AM appattempt_1559893901343_0001_000001
2019-06-07 07:52:05,341 INFO org.apache.hadoop.yarn.server.resourcemanager.amlauncher.AMLauncher: Setting up container Container: [ContainerId: container_1559893901343_0001_01_000001, Version: 0, NodeId: slave1:39995, NodeHttpAddress: slave1:8042, Resource: <memory:1024, vCores:1>, Priority: 0, Token: Token { kind: ContainerToken, service: 172.17.0.3:39995 }, ] for AM appattempt_1559893901343_0001_000001
2019-06-07 07:52:05,341 INFO org.apache.hadoop.yarn.server.resourcemanager.security.AMRMTokenSecretManager: Create AMRMToken for ApplicationAttempt: appattempt_1559893901343_0001_000001
2019-06-07 07:52:05,341 INFO org.apache.hadoop.yarn.server.resourcemanager.security.AMRMTokenSecretManager: Create AMRMToken for ApplicationAttempt: appattempt_1559893901343_0001_000001
2019-06-07 07:52:05,345 INFO org.apache.hadoop.yarn.server.resourcemanager.security.AMRMTokenSecretManager: Creating password for appattempt_1559893901343_0001_000001
2019-06-07 07:52:05,345 INFO org.apache.hadoop.yarn.server.resourcemanager.security.AMRMTokenSecretManager: Creating password for appattempt_1559893901343_0001_000001
2019-06-07 07:52:05,791 INFO org.apache.hadoop.yarn.server.resourcemanager.amlauncher.AMLauncher: Done launching container Container: [ContainerId: container_1559893901343_0001_01_000001, Version: 0, NodeId: slave1:39995, NodeHttpAddress: slave1:8042, Resource: <memory:1024, vCores:1>, Priority: 0, Token: Token { kind: ContainerToken, service: 172.17.0.3:39995 }, ] for AM appattempt_1559893901343_0001_000001
2019-06-07 07:52:05,791 INFO org.apache.hadoop.yarn.server.resourcemanager.amlauncher.AMLauncher: Done launching container Container: [ContainerId: container_1559893901343_0001_01_000001, Version: 0, NodeId: slave1:39995, NodeHttpAddress: slave1:8042, Resource: <memory:1024, vCores:1>, Priority: 0, Token: Token { kind: ContainerToken, service: 172.17.0.3:39995 }, ] for AM appattempt_1559893901343_0001_000001
2019-06-07 07:52:05,791 DEBUG org.apache.hadoop.yarn.server.resourcemanager.rmapp.attempt.RMAppAttemptImpl: Processing event for appattempt_1559893901343_0001_000001 of type LAUNCHED
2019-06-07 07:52:05,791 DEBUG org.apache.hadoop.yarn.server.resourcemanager.rmapp.attempt.RMAppAttemptImpl: Processing event for appattempt_1559893901343_0001_000001 of type LAUNCHED
2019-06-07 07:52:05,791 INFO org.apache.hadoop.yarn.server.resourcemanager.rmapp.attempt.RMAppAttemptImpl: appattempt_1559893901343_0001_000001 State change from ALLOCATED to LAUNCHED
2019-06-07 07:52:05,791 INFO org.apache.hadoop.yarn.server.resourcemanager.rmapp.attempt.RMAppAttemptImpl: appattempt_1559893901343_0001_000001 State change from ALLOCATED to LAUNCHED
2019-06-07 07:52:06,102 DEBUG org.apache.hadoop.yarn.server.resourcemanager.rmnode.RMNodeImpl: Processing slave2:38494 of type STATUS_UPDATE
2019-06-07 07:52:06,102 DEBUG org.apache.hadoop.yarn.server.resourcemanager.rmnode.RMNodeImpl: Processing slave2:38494 of type STATUS_UPDATE
2019-06-07 07:52:06,103 DEBUG org.apache.hadoop.yarn.server.resourcemanager.scheduler.capacity.CapacityScheduler: nodeUpdate: slave2:38494 clusterResources: <memory:8192, vCores:2>
2019-06-07 07:52:06,103 DEBUG org.apache.hadoop.yarn.server.resourcemanager.scheduler.capacity.CapacityScheduler: nodeUpdate: slave2:38494 clusterResources: <memory:8192, vCores:2>
2019-06-07 07:52:06,103 DEBUG org.apache.hadoop.yarn.server.resourcemanager.scheduler.capacity.CapacityScheduler: Node being looked for scheduling slave2:38494 availableResource: <memory:4096, vCores:1>
2019-06-07 07:52:06,103 DEBUG org.apache.hadoop.yarn.server.resourcemanager.scheduler.capacity.CapacityScheduler: Node being looked for scheduling slave2:38494 availableResource: <memory:4096, vCores:1>
2019-06-07 07:52:06,103 DEBUG org.apache.hadoop.yarn.server.resourcemanager.scheduler.capacity.CapacityScheduler: Trying to schedule on node: slave2, available: <memory:4096, vCores:1>
2019-06-07 07:52:06,103 DEBUG org.apache.hadoop.yarn.server.resourcemanager.scheduler.capacity.CapacityScheduler: Trying to schedule on node: slave2, available: <memory:4096, vCores:1>
2019-06-07 07:52:06,104 DEBUG org.apache.hadoop.yarn.server.resourcemanager.scheduler.capacity.ParentQueue: Skip this queue=root, because it doesn't need more resource, schedulingMode=RESPECT_PARTITION_EXCLUSIVITY node-partition=
2019-06-07 07:52:06,104 DEBUG org.apache.hadoop.yarn.server.resourcemanager.scheduler.capacity.ParentQueue: Skip this queue=root, because it doesn't need more resource, schedulingMode=RESPECT_PARTITION_EXCLUSIVITY node-partition=
2019-06-07 07:52:06,130 DEBUG org.apache.hadoop.yarn.server.resourcemanager.rmnode.RMNodeImpl: Processing slave1:39995 of type STATUS_UPDATE
2019-06-07 07:52:06,130 DEBUG org.apache.hadoop.yarn.server.resourcemanager.rmnode.RMNodeImpl: Processing slave1:39995 of type STATUS_UPDATE
2019-06-07 07:52:06,142 DEBUG org.apache.hadoop.yarn.server.resourcemanager.rmnode.RMNodeImpl: Container container_1559893901343_0001_01_000001 is the first container get launched for application application_1559893901343_0001
2019-06-07 07:52:06,142 DEBUG org.apache.hadoop.yarn.server.resourcemanager.rmnode.RMNodeImpl: Container container_1559893901343_0001_01_000001 is the first container get launched for application application_1559893901343_0001
2019-06-07 07:52:06,144 DEBUG org.apache.hadoop.yarn.server.resourcemanager.rmapp.RMAppImpl: Processing event for application_1559893901343_0001 of type APP_RUNNING_ON_NODE
2019-06-07 07:52:06,144 DEBUG org.apache.hadoop.yarn.server.resourcemanager.rmapp.RMAppImpl: Processing event for application_1559893901343_0001 of type APP_RUNNING_ON_NODE
2019-06-07 07:52:06,144 DEBUG org.apache.hadoop.yarn.server.resourcemanager.scheduler.capacity.CapacityScheduler: nodeUpdate: slave1:39995 clusterResources: <memory:8192, vCores:2>
2019-06-07 07:52:06,144 DEBUG org.apache.hadoop.yarn.server.resourcemanager.scheduler.capacity.CapacityScheduler: nodeUpdate: slave1:39995 clusterResources: <memory:8192, vCores:2>
2019-06-07 07:52:06,147 DEBUG org.apache.hadoop.yarn.server.resourcemanager.rmcontainer.RMContainerImpl: Processing container_1559893901343_0001_01_000001 of type LAUNCHED
2019-06-07 07:52:06,147 DEBUG org.apache.hadoop.yarn.server.resourcemanager.rmcontainer.RMContainerImpl: Processing container_1559893901343_0001_01_000001 of type LAUNCHED
2019-06-07 07:52:06,147 INFO org.apache.hadoop.yarn.server.resourcemanager.rmcontainer.RMContainerImpl: container_1559893901343_0001_01_000001 Container Transitioned from ACQUIRED to RUNNING
2019-06-07 07:52:06,147 INFO org.apache.hadoop.yarn.server.resourcemanager.rmcontainer.RMContainerImpl: container_1559893901343_0001_01_000001 Container Transitioned from ACQUIRED to RUNNING
2019-06-07 07:52:06,147 DEBUG org.apache.hadoop.yarn.server.resourcemanager.scheduler.capacity.CapacityScheduler: Node being looked for scheduling slave1:39995 availableResource: <memory:3072, vCores:0>
2019-06-07 07:52:06,147 DEBUG org.apache.hadoop.yarn.server.resourcemanager.scheduler.capacity.CapacityScheduler: Node being looked for scheduling slave1:39995 availableResource: <memory:3072, vCores:0>
2019-06-07 07:52:06,147 DEBUG org.apache.hadoop.yarn.server.resourcemanager.scheduler.capacity.CapacityScheduler: Trying to schedule on node: slave1, available: <memory:3072, vCores:0>
2019-06-07 07:52:06,147 DEBUG org.apache.hadoop.yarn.server.resourcemanager.scheduler.capacity.CapacityScheduler: Trying to schedule on node: slave1, available: <memory:3072, vCores:0>
2019-06-07 07:52:06,147 DEBUG org.apache.hadoop.yarn.server.resourcemanager.scheduler.capacity.ParentQueue: Skip this queue=root, because it doesn't need more resource, schedulingMode=RESPECT_PARTITION_EXCLUSIVITY node-partition=
2019-06-07 07:52:06,147 DEBUG org.apache.hadoop.yarn.server.resourcemanager.scheduler.capacity.ParentQueue: Skip this queue=root, because it doesn't need more resource, schedulingMode=RESPECT_PARTITION_EXCLUSIVITY node-partition=
2019-06-07 07:52:07,106 DEBUG org.apache.hadoop.yarn.server.resourcemanager.rmnode.RMNodeImpl: Processing slave2:38494 of type STATUS_UPDATE
2019-06-07 07:52:07,106 DEBUG org.apache.hadoop.yarn.server.resourcemanager.rmnode.RMNodeImpl: Processing slave2:38494 of type STATUS_UPDATE
2019-06-07 07:52:07,107 DEBUG org.apache.hadoop.yarn.server.resourcemanager.scheduler.capacity.CapacityScheduler: nodeUpdate: slave2:38494 clusterResources: <memory:8192, vCores:2>
2019-06-07 07:52:07,107 DEBUG org.apache.hadoop.yarn.server.resourcemanager.scheduler.capacity.CapacityScheduler: nodeUpdate: slave2:38494 clusterResources: <memory:8192, vCores:2>
2019-06-07 07:52:07,107 DEBUG org.apache.hadoop.yarn.server.resourcemanager.scheduler.capacity.CapacityScheduler: Node being looked for scheduling slave2:38494 availableResource: <memory:4096, vCores:1>
2019-06-07 07:52:07,107 DEBUG org.apache.hadoop.yarn.server.resourcemanager.scheduler.capacity.CapacityScheduler: Node being looked for scheduling slave2:38494 availableResource: <memory:4096, vCores:1>
2019-06-07 07:52:07,107 DEBUG org.apache.hadoop.yarn.server.resourcemanager.scheduler.capacity.CapacityScheduler: Trying to schedule on node: slave2, available: <memory:4096, vCores:1>
2019-06-07 07:52:07,107 DEBUG org.apache.hadoop.yarn.server.resourcemanager.scheduler.capacity.CapacityScheduler: Trying to schedule on node: slave2, available: <memory:4096, vCores:1>
2019-06-07 07:52:07,107 DEBUG org.apache.hadoop.yarn.server.resourcemanager.scheduler.capacity.ParentQueue: Skip this queue=root, because it doesn't need more resource, schedulingMode=RESPECT_PARTITION_EXCLUSIVITY node-partition=
2019-06-07 07:52:07,107 DEBUG org.apache.hadoop.yarn.server.resourcemanager.scheduler.capacity.ParentQueue: Skip this queue=root, because it doesn't need more resource, schedulingMode=RESPECT_PARTITION_EXCLUSIVITY node-partition=
2019-06-07 07:52:07,148 DEBUG org.apache.hadoop.yarn.server.resourcemanager.rmnode.RMNodeImpl: Processing slave1:39995 of type STATUS_UPDATE
2019-06-07 07:52:07,148 DEBUG org.apache.hadoop.yarn.server.resourcemanager.rmnode.RMNodeImpl: Processing slave1:39995 of type STATUS_UPDATE
2019-06-07 07:52:07,149 DEBUG org.apache.hadoop.yarn.server.resourcemanager.scheduler.capacity.CapacityScheduler: nodeUpdate: slave1:39995 clusterResources: <memory:8192, vCores:2>
2019-06-07 07:52:07,149 DEBUG org.apache.hadoop.yarn.server.resourcemanager.scheduler.capacity.CapacityScheduler: nodeUpdate: slave1:39995 clusterResources: <memory:8192, vCores:2>
2019-06-07 07:52:07,149 DEBUG org.apache.hadoop.yarn.server.resourcemanager.scheduler.capacity.CapacityScheduler: Node being looked for scheduling slave1:39995 availableResource: <memory:3072, vCores:0>
2019-06-07 07:52:07,149 DEBUG org.apache.hadoop.yarn.server.resourcemanager.scheduler.capacity.CapacityScheduler: Node being looked for scheduling slave1:39995 availableResource: <memory:3072, vCores:0>
2019-06-07 07:52:07,149 DEBUG org.apache.hadoop.yarn.server.resourcemanager.scheduler.capacity.CapacityScheduler: Trying to schedule on node: slave1, available: <memory:3072, vCores:0>
2019-06-07 07:52:07,149 DEBUG org.apache.hadoop.yarn.server.resourcemanager.scheduler.capacity.CapacityScheduler: Trying to schedule on node: slave1, available: <memory:3072, vCores:0>
2019-06-07 07:52:07,149 DEBUG org.apache.hadoop.yarn.server.resourcemanager.scheduler.capacity.ParentQueue: Skip this queue=root, because it doesn't need more resource, schedulingMode=RESPECT_PARTITION_EXCLUSIVITY node-partition=
2019-06-07 07:52:07,149 DEBUG org.apache.hadoop.yarn.server.resourcemanager.scheduler.capacity.ParentQueue: Skip this queue=root, because it doesn't need more resource, schedulingMode=RESPECT_PARTITION_EXCLUSIVITY node-partition=
2019-06-07 07:52:08,111 DEBUG org.apache.hadoop.yarn.server.resourcemanager.rmnode.RMNodeImpl: Processing slave2:38494 of type STATUS_UPDATE
2019-06-07 07:52:08,111 DEBUG org.apache.hadoop.yarn.server.resourcemanager.rmnode.RMNodeImpl: Processing slave2:38494 of type STATUS_UPDATE
2019-06-07 07:52:08,111 DEBUG org.apache.hadoop.yarn.server.resourcemanager.scheduler.capacity.CapacityScheduler: nodeUpdate: slave2:38494 clusterResources: <memory:8192, vCores:2>
2019-06-07 07:52:08,111 DEBUG org.apache.hadoop.yarn.server.resourcemanager.scheduler.capacity.CapacityScheduler: nodeUpdate: slave2:38494 clusterResources: <memory:8192, vCores:2>
2019-06-07 07:52:08,112 DEBUG org.apache.hadoop.yarn.server.resourcemanager.scheduler.capacity.CapacityScheduler: Node being looked for scheduling slave2:38494 availableResource: <memory:4096, vCores:1>
2019-06-07 07:52:08,112 DEBUG org.apache.hadoop.yarn.server.resourcemanager.scheduler.capacity.CapacityScheduler: Node being looked for scheduling slave2:38494 availableResource: <memory:4096, vCores:1>
2019-06-07 07:52:08,112 DEBUG org.apache.hadoop.yarn.server.resourcemanager.scheduler.capacity.CapacityScheduler: Trying to schedule on node: slave2, available: <memory:4096, vCores:1>
2019-06-07 07:52:08,112 DEBUG org.apache.hadoop.yarn.server.resourcemanager.scheduler.capacity.CapacityScheduler: Trying to schedule on node: slave2, available: <memory:4096, vCores:1>
2019-06-07 07:52:08,112 DEBUG org.apache.hadoop.yarn.server.resourcemanager.scheduler.capacity.ParentQueue: Skip this queue=root, because it doesn't need more resource, schedulingMode=RESPECT_PARTITION_EXCLUSIVITY node-partition=
2019-06-07 07:52:08,112 DEBUG org.apache.hadoop.yarn.server.resourcemanager.scheduler.capacity.ParentQueue: Skip this queue=root, because it doesn't need more resource, schedulingMode=RESPECT_PARTITION_EXCLUSIVITY node-partition=
2019-06-07 07:52:08,153 DEBUG org.apache.hadoop.yarn.server.resourcemanager.rmnode.RMNodeImpl: Processing slave1:39995 of type STATUS_UPDATE
2019-06-07 07:52:08,153 DEBUG org.apache.hadoop.yarn.server.resourcemanager.rmnode.RMNodeImpl: Processing slave1:39995 of type STATUS_UPDATE
2019-06-07 07:52:08,156 DEBUG org.apache.hadoop.yarn.server.resourcemanager.scheduler.capacity.CapacityScheduler: nodeUpdate: slave1:39995 clusterResources: <memory:8192, vCores:2>
2019-06-07 07:52:08,156 DEBUG org.apache.hadoop.yarn.server.resourcemanager.scheduler.capacity.CapacityScheduler: nodeUpdate: slave1:39995 clusterResources: <memory:8192, vCores:2>
2019-06-07 07:52:08,156 DEBUG org.apache.hadoop.yarn.server.resourcemanager.scheduler.capacity.CapacityScheduler: Node being looked for scheduling slave1:39995 availableResource: <memory:3072, vCores:0>
2019-06-07 07:52:08,156 DEBUG org.apache.hadoop.yarn.server.resourcemanager.scheduler.capacity.CapacityScheduler: Node being looked for scheduling slave1:39995 availableResource: <memory:3072, vCores:0>
2019-06-07 07:52:08,157 DEBUG org.apache.hadoop.yarn.server.resourcemanager.scheduler.capacity.CapacityScheduler: Trying to schedule on node: slave1, available: <memory:3072, vCores:0>
2019-06-07 07:52:08,157 DEBUG org.apache.hadoop.yarn.server.resourcemanager.scheduler.capacity.CapacityScheduler: Trying to schedule on node: slave1, available: <memory:3072, vCores:0>
2019-06-07 07:52:08,157 DEBUG org.apache.hadoop.yarn.server.resourcemanager.scheduler.capacity.ParentQueue: Skip this queue=root, because it doesn't need more resource, schedulingMode=RESPECT_PARTITION_EXCLUSIVITY node-partition=
2019-06-07 07:52:08,157 DEBUG org.apache.hadoop.yarn.server.resourcemanager.scheduler.capacity.ParentQueue: Skip this queue=root, because it doesn't need more resource, schedulingMode=RESPECT_PARTITION_EXCLUSIVITY node-partition=
2019-06-07 07:52:09,115 DEBUG org.apache.hadoop.yarn.server.resourcemanager.rmnode.RMNodeImpl: Processing slave2:38494 of type STATUS_UPDATE
2019-06-07 07:52:09,115 DEBUG org.apache.hadoop.yarn.server.resourcemanager.rmnode.RMNodeImpl: Processing slave2:38494 of type STATUS_UPDATE
2019-06-07 07:52:09,116 DEBUG org.apache.hadoop.yarn.server.resourcemanager.scheduler.capacity.CapacityScheduler: nodeUpdate: slave2:38494 clusterResources: <memory:8192, vCores:2>
2019-06-07 07:52:09,116 DEBUG org.apache.hadoop.yarn.server.resourcemanager.scheduler.capacity.CapacityScheduler: nodeUpdate: slave2:38494 clusterResources: <memory:8192, vCores:2>
2019-06-07 07:52:09,116 DEBUG org.apache.hadoop.yarn.server.resourcemanager.scheduler.capacity.CapacityScheduler: Node being looked for scheduling slave2:38494 availableResource: <memory:4096, vCores:1>
2019-06-07 07:52:09,116 DEBUG org.apache.hadoop.yarn.server.resourcemanager.scheduler.capacity.CapacityScheduler: Node being looked for scheduling slave2:38494 availableResource: <memory:4096, vCores:1>
2019-06-07 07:52:09,116 DEBUG org.apache.hadoop.yarn.server.resourcemanager.scheduler.capacity.CapacityScheduler: Trying to schedule on node: slave2, available: <memory:4096, vCores:1>
2019-06-07 07:52:09,116 DEBUG org.apache.hadoop.yarn.server.resourcemanager.scheduler.capacity.CapacityScheduler: Trying to schedule on node: slave2, available: <memory:4096, vCores:1>
2019-06-07 07:52:09,116 DEBUG org.apache.hadoop.yarn.server.resourcemanager.scheduler.capacity.ParentQueue: Skip this queue=root, because it doesn't need more resource, schedulingMode=RESPECT_PARTITION_EXCLUSIVITY node-partition=
2019-06-07 07:52:09,116 DEBUG org.apache.hadoop.yarn.server.resourcemanager.scheduler.capacity.ParentQueue: Skip this queue=root, because it doesn't need more resource, schedulingMode=RESPECT_PARTITION_EXCLUSIVITY node-partition=
2019-06-07 07:52:09,161 DEBUG org.apache.hadoop.yarn.server.resourcemanager.rmnode.RMNodeImpl: Processing slave1:39995 of type STATUS_UPDATE
2019-06-07 07:52:09,161 DEBUG org.apache.hadoop.yarn.server.resourcemanager.rmnode.RMNodeImpl: Processing slave1:39995 of type STATUS_UPDATE
2019-06-07 07:52:09,163 DEBUG org.apache.hadoop.yarn.server.resourcemanager.scheduler.capacity.CapacityScheduler: nodeUpdate: slave1:39995 clusterResources: <memory:8192, vCores:2>
2019-06-07 07:52:09,163 DEBUG org.apache.hadoop.yarn.server.resourcemanager.scheduler.capacity.CapacityScheduler: nodeUpdate: slave1:39995 clusterResources: <memory:8192, vCores:2>
2019-06-07 07:52:09,163 DEBUG org.apache.hadoop.yarn.server.resourcemanager.scheduler.capacity.CapacityScheduler: Node being looked for scheduling slave1:39995 availableResource: <memory:3072, vCores:0>
2019-06-07 07:52:09,163 DEBUG org.apache.hadoop.yarn.server.resourcemanager.scheduler.capacity.CapacityScheduler: Node being looked for scheduling slave1:39995 availableResource: <memory:3072, vCores:0>
2019-06-07 07:52:09,163 DEBUG org.apache.hadoop.yarn.server.resourcemanager.scheduler.capacity.CapacityScheduler: Trying to schedule on node: slave1, available: <memory:3072, vCores:0>
2019-06-07 07:52:09,163 DEBUG org.apache.hadoop.yarn.server.resourcemanager.scheduler.capacity.CapacityScheduler: Trying to schedule on node: slave1, available: <memory:3072, vCores:0>
2019-06-07 07:52:09,163 DEBUG org.apache.hadoop.yarn.server.resourcemanager.scheduler.capacity.ParentQueue: Skip this queue=root, because it doesn't need more resource, schedulingMode=RESPECT_PARTITION_EXCLUSIVITY node-partition=
2019-06-07 07:52:09,163 DEBUG org.apache.hadoop.yarn.server.resourcemanager.scheduler.capacity.ParentQueue: Skip this queue=root, because it doesn't need more resource, schedulingMode=RESPECT_PARTITION_EXCLUSIVITY node-partition=
2019-06-07 07:52:10,118 DEBUG org.apache.hadoop.yarn.server.resourcemanager.rmnode.RMNodeImpl: Processing slave2:38494 of type STATUS_UPDATE
2019-06-07 07:52:10,118 DEBUG org.apache.hadoop.yarn.server.resourcemanager.rmnode.RMNodeImpl: Processing slave2:38494 of type STATUS_UPDATE
2019-06-07 07:52:10,118 DEBUG org.apache.hadoop.yarn.server.resourcemanager.scheduler.capacity.CapacityScheduler: nodeUpdate: slave2:38494 clusterResources: <memory:8192, vCores:2>
2019-06-07 07:52:10,118 DEBUG org.apache.hadoop.yarn.server.resourcemanager.scheduler.capacity.CapacityScheduler: nodeUpdate: slave2:38494 clusterResources: <memory:8192, vCores:2>
2019-06-07 07:52:10,118 DEBUG org.apache.hadoop.yarn.server.resourcemanager.scheduler.capacity.CapacityScheduler: Node being looked for scheduling slave2:38494 availableResource: <memory:4096, vCores:1>
2019-06-07 07:52:10,118 DEBUG org.apache.hadoop.yarn.server.resourcemanager.scheduler.capacity.CapacityScheduler: Node being looked for scheduling slave2:38494 availableResource: <memory:4096, vCores:1>
2019-06-07 07:52:10,118 DEBUG org.apache.hadoop.yarn.server.resourcemanager.scheduler.capacity.CapacityScheduler: Trying to schedule on node: slave2, available: <memory:4096, vCores:1>
2019-06-07 07:52:10,118 DEBUG org.apache.hadoop.yarn.server.resourcemanager.scheduler.capacity.CapacityScheduler: Trying to schedule on node: slave2, available: <memory:4096, vCores:1>
2019-06-07 07:52:10,118 DEBUG org.apache.hadoop.yarn.server.resourcemanager.scheduler.capacity.ParentQueue: Skip this queue=root, because it doesn't need more resource, schedulingMode=RESPECT_PARTITION_EXCLUSIVITY node-partition=
2019-06-07 07:52:10,118 DEBUG org.apache.hadoop.yarn.server.resourcemanager.scheduler.capacity.ParentQueue: Skip this queue=root, because it doesn't need more resource, schedulingMode=RESPECT_PARTITION_EXCLUSIVITY node-partition=
2019-06-07 07:52:10,165 DEBUG org.apache.hadoop.yarn.server.resourcemanager.rmnode.RMNodeImpl: Processing slave1:39995 of type STATUS_UPDATE
2019-06-07 07:52:10,165 DEBUG org.apache.hadoop.yarn.server.resourcemanager.rmnode.RMNodeImpl: Processing slave1:39995 of type STATUS_UPDATE
2019-06-07 07:52:10,165 DEBUG org.apache.hadoop.yarn.server.resourcemanager.scheduler.capacity.CapacityScheduler: nodeUpdate: slave1:39995 clusterResources: <memory:8192, vCores:2>
2019-06-07 07:52:10,165 DEBUG org.apache.hadoop.yarn.server.resourcemanager.scheduler.capacity.CapacityScheduler: nodeUpdate: slave1:39995 clusterResources: <memory:8192, vCores:2>
2019-06-07 07:52:10,165 DEBUG org.apache.hadoop.yarn.server.resourcemanager.scheduler.capacity.CapacityScheduler: Node being looked for scheduling slave1:39995 availableResource: <memory:3072, vCores:0>
2019-06-07 07:52:10,165 DEBUG org.apache.hadoop.yarn.server.resourcemanager.scheduler.capacity.CapacityScheduler: Node being looked for scheduling slave1:39995 availableResource: <memory:3072, vCores:0>
2019-06-07 07:52:10,165 DEBUG org.apache.hadoop.yarn.server.resourcemanager.scheduler.capacity.CapacityScheduler: Trying to schedule on node: slave1, available: <memory:3072, vCores:0>
2019-06-07 07:52:10,165 DEBUG org.apache.hadoop.yarn.server.resourcemanager.scheduler.capacity.CapacityScheduler: Trying to schedule on node: slave1, available: <memory:3072, vCores:0>
2019-06-07 07:52:10,165 DEBUG org.apache.hadoop.yarn.server.resourcemanager.scheduler.capacity.ParentQueue: Skip this queue=root, because it doesn't need more resource, schedulingMode=RESPECT_PARTITION_EXCLUSIVITY node-partition=
2019-06-07 07:52:10,165 DEBUG org.apache.hadoop.yarn.server.resourcemanager.scheduler.capacity.ParentQueue: Skip this queue=root, because it doesn't need more resource, schedulingMode=RESPECT_PARTITION_EXCLUSIVITY node-partition=
2019-06-07 07:52:11,121 DEBUG org.apache.hadoop.yarn.server.resourcemanager.rmnode.RMNodeImpl: Processing slave2:38494 of type STATUS_UPDATE
2019-06-07 07:52:11,121 DEBUG org.apache.hadoop.yarn.server.resourcemanager.rmnode.RMNodeImpl: Processing slave2:38494 of type STATUS_UPDATE
2019-06-07 07:52:11,121 DEBUG org.apache.hadoop.yarn.server.resourcemanager.scheduler.capacity.CapacityScheduler: nodeUpdate: slave2:38494 clusterResources: <memory:8192, vCores:2>
2019-06-07 07:52:11,121 DEBUG org.apache.hadoop.yarn.server.resourcemanager.scheduler.capacity.CapacityScheduler: nodeUpdate: slave2:38494 clusterResources: <memory:8192, vCores:2>
2019-06-07 07:52:11,121 DEBUG org.apache.hadoop.yarn.server.resourcemanager.scheduler.capacity.CapacityScheduler: Node being looked for scheduling slave2:38494 availableResource: <memory:4096, vCores:1>
2019-06-07 07:52:11,121 DEBUG org.apache.hadoop.yarn.server.resourcemanager.scheduler.capacity.CapacityScheduler: Node being looked for scheduling slave2:38494 availableResource: <memory:4096, vCores:1>
2019-06-07 07:52:11,122 DEBUG org.apache.hadoop.yarn.server.resourcemanager.scheduler.capacity.CapacityScheduler: Trying to schedule on node: slave2, available: <memory:4096, vCores:1>
2019-06-07 07:52:11,122 DEBUG org.apache.hadoop.yarn.server.resourcemanager.scheduler.capacity.CapacityScheduler: Trying to schedule on node: slave2, available: <memory:4096, vCores:1>
2019-06-07 07:52:11,122 DEBUG org.apache.hadoop.yarn.server.resourcemanager.scheduler.capacity.ParentQueue: Skip this queue=root, because it doesn't need more resource, schedulingMode=RESPECT_PARTITION_EXCLUSIVITY node-partition=
2019-06-07 07:52:11,122 DEBUG org.apache.hadoop.yarn.server.resourcemanager.scheduler.capacity.ParentQueue: Skip this queue=root, because it doesn't need more resource, schedulingMode=RESPECT_PARTITION_EXCLUSIVITY node-partition=
2019-06-07 07:52:11,171 DEBUG org.apache.hadoop.yarn.server.resourcemanager.rmnode.RMNodeImpl: Processing slave1:39995 of type STATUS_UPDATE
2019-06-07 07:52:11,171 DEBUG org.apache.hadoop.yarn.server.resourcemanager.rmnode.RMNodeImpl: Processing slave1:39995 of type STATUS_UPDATE
2019-06-07 07:52:11,171 DEBUG org.apache.hadoop.yarn.server.resourcemanager.scheduler.capacity.CapacityScheduler: nodeUpdate: slave1:39995 clusterResources: <memory:8192, vCores:2>
2019-06-07 07:52:11,171 DEBUG org.apache.hadoop.yarn.server.resourcemanager.scheduler.capacity.CapacityScheduler: nodeUpdate: slave1:39995 clusterResources: <memory:8192, vCores:2>
2019-06-07 07:52:11,171 DEBUG org.apache.hadoop.yarn.server.resourcemanager.scheduler.capacity.CapacityScheduler: Node being looked for scheduling slave1:39995 availableResource: <memory:3072, vCores:0>
2019-06-07 07:52:11,171 DEBUG org.apache.hadoop.yarn.server.resourcemanager.scheduler.capacity.CapacityScheduler: Node being looked for scheduling slave1:39995 availableResource: <memory:3072, vCores:0>
2019-06-07 07:52:11,171 DEBUG org.apache.hadoop.yarn.server.resourcemanager.scheduler.capacity.CapacityScheduler: Trying to schedule on node: slave1, available: <memory:3072, vCores:0>
2019-06-07 07:52:11,171 DEBUG org.apache.hadoop.yarn.server.resourcemanager.scheduler.capacity.CapacityScheduler: Trying to schedule on node: slave1, available: <memory:3072, vCores:0>
2019-06-07 07:52:11,171 DEBUG org.apache.hadoop.yarn.server.resourcemanager.scheduler.capacity.ParentQueue: Skip this queue=root, because it doesn't need more resource, schedulingMode=RESPECT_PARTITION_EXCLUSIVITY node-partition=
2019-06-07 07:52:11,171 DEBUG org.apache.hadoop.yarn.server.resourcemanager.scheduler.capacity.ParentQueue: Skip this queue=root, because it doesn't need more resource, schedulingMode=RESPECT_PARTITION_EXCLUSIVITY node-partition=
2019-06-07 07:52:11,897 DEBUG org.apache.hadoop.yarn.server.resourcemanager.security.AMRMTokenSecretManager: Trying to retrieve password for appattempt_1559893901343_0001_000001
2019-06-07 07:52:11,897 DEBUG org.apache.hadoop.yarn.server.resourcemanager.security.AMRMTokenSecretManager: Trying to retrieve password for appattempt_1559893901343_0001_000001
2019-06-07 07:52:11,900 INFO SecurityLogger.org.apache.hadoop.ipc.Server: Auth successful for appattempt_1559893901343_0001_000001 (auth:SIMPLE)
2019-06-07 07:52:11,909 INFO org.apache.hadoop.yarn.server.resourcemanager.ApplicationMasterService: AM registration appattempt_1559893901343_0001_000001
2019-06-07 07:52:11,909 INFO org.apache.hadoop.yarn.server.resourcemanager.ApplicationMasterService: AM registration appattempt_1559893901343_0001_000001
2019-06-07 07:52:11,909 DEBUG org.apache.hadoop.yarn.server.resourcemanager.rmapp.attempt.RMAppAttemptImpl: Processing event for appattempt_1559893901343_0001_000001 of type REGISTERED
2019-06-07 07:52:11,909 DEBUG org.apache.hadoop.yarn.server.resourcemanager.rmapp.attempt.RMAppAttemptImpl: Processing event for appattempt_1559893901343_0001_000001 of type REGISTERED
2019-06-07 07:52:11,910 INFO org.apache.hadoop.yarn.server.resourcemanager.rmapp.attempt.RMAppAttemptImpl: appattempt_1559893901343_0001_000001 State change from LAUNCHED to RUNNING
2019-06-07 07:52:11,910 INFO org.apache.hadoop.yarn.server.resourcemanager.rmapp.attempt.RMAppAttemptImpl: appattempt_1559893901343_0001_000001 State change from LAUNCHED to RUNNING
2019-06-07 07:52:11,910 DEBUG org.apache.hadoop.yarn.server.resourcemanager.rmapp.RMAppImpl: Processing event for application_1559893901343_0001 of type ATTEMPT_REGISTERED
2019-06-07 07:52:11,910 DEBUG org.apache.hadoop.yarn.server.resourcemanager.rmapp.RMAppImpl: Processing event for application_1559893901343_0001 of type ATTEMPT_REGISTERED
2019-06-07 07:52:11,910 INFO org.apache.hadoop.yarn.server.resourcemanager.rmapp.RMAppImpl: application_1559893901343_0001 State change from ACCEPTED to RUNNING on event=ATTEMPT_REGISTERED
2019-06-07 07:52:11,910 INFO org.apache.hadoop.yarn.server.resourcemanager.rmapp.RMAppImpl: application_1559893901343_0001 State change from ACCEPTED to RUNNING on event=ATTEMPT_REGISTERED
2019-06-07 07:52:11,910 INFO org.apache.hadoop.yarn.server.resourcemanager.RMAuditLogger: USER=root	IP=172.17.0.3	OPERATION=Register App Master	TARGET=ApplicationMasterService	RESULT=SUCCESS	APPID=application_1559893901343_0001	APPATTEMPTID=appattempt_1559893901343_0001_000001
2019-06-07 07:52:11,910 INFO org.apache.hadoop.yarn.server.resourcemanager.RMAuditLogger: USER=root	IP=172.17.0.3	OPERATION=Register App Master	TARGET=ApplicationMasterService	RESULT=SUCCESS	APPID=application_1559893901343_0001	APPATTEMPTID=appattempt_1559893901343_0001_000001
2019-06-07 07:52:12,042 DEBUG org.apache.hadoop.yarn.server.resourcemanager.rmapp.attempt.RMAppAttemptImpl: Processing event for appattempt_1559893901343_0001_000001 of type STATUS_UPDATE
2019-06-07 07:52:12,042 DEBUG org.apache.hadoop.yarn.server.resourcemanager.rmapp.attempt.RMAppAttemptImpl: Processing event for appattempt_1559893901343_0001_000001 of type STATUS_UPDATE
2019-06-07 07:52:12,043 DEBUG org.apache.hadoop.yarn.server.resourcemanager.scheduler.capacity.CapacityScheduler: allocate: pre-update appattempt_1559893901343_0001_000001 ask size =1
2019-06-07 07:52:12,043 DEBUG org.apache.hadoop.yarn.server.resourcemanager.scheduler.capacity.CapacityScheduler: allocate: pre-update appattempt_1559893901343_0001_000001 ask size =1
2019-06-07 07:52:12,043 DEBUG org.apache.hadoop.yarn.server.resourcemanager.scheduler.ActiveUsersManager: User root added to activeUsers, currently: 1
2019-06-07 07:52:12,043 DEBUG org.apache.hadoop.yarn.server.resourcemanager.scheduler.ActiveUsersManager: User root added to activeUsers, currently: 1
2019-06-07 07:52:12,043 DEBUG org.apache.hadoop.yarn.server.resourcemanager.scheduler.capacity.CapacityScheduler: allocate: post-update
2019-06-07 07:52:12,043 DEBUG org.apache.hadoop.yarn.server.resourcemanager.scheduler.capacity.CapacityScheduler: allocate: post-update
2019-06-07 07:52:12,043 DEBUG org.apache.hadoop.yarn.server.resourcemanager.scheduler.capacity.LeafQueue: User limit computation for root in queue default userLimitPercent=100 userLimitFactor=1.0 required: <memory:1024, vCores:1> consumed: <memory:1024, vCores:1> user-limit-resource: <memory:8192, vCores:1> queueCapacity: <memory:8192, vCores:1> qconsumed: <memory:1024, vCores:1> consumedRatio: 0.0 currentCapacity: <memory:8192, vCores:1> activeUsers: 1.0 clusterCapacity: <memory:8192, vCores:2> resourceByLabel: <memory:8192, vCores:2> usageratio: 0.125 Partition:  maxUserLimit=<memory:8192, vCores:1> userWeight=1.0
2019-06-07 07:52:12,043 DEBUG org.apache.hadoop.yarn.server.resourcemanager.scheduler.capacity.LeafQueue: User limit computation for root in queue default userLimitPercent=100 userLimitFactor=1.0 required: <memory:1024, vCores:1> consumed: <memory:1024, vCores:1> user-limit-resource: <memory:8192, vCores:1> queueCapacity: <memory:8192, vCores:1> qconsumed: <memory:1024, vCores:1> consumedRatio: 0.0 currentCapacity: <memory:8192, vCores:1> activeUsers: 1.0 clusterCapacity: <memory:8192, vCores:2> resourceByLabel: <memory:8192, vCores:2> usageratio: 0.125 Partition:  maxUserLimit=<memory:8192, vCores:1> userWeight=1.0
2019-06-07 07:52:12,043 DEBUG org.apache.hadoop.yarn.server.resourcemanager.scheduler.SchedulerApplicationAttempt: showRequests: application=application_1559893901343_0001 headRoom=<memory:7168, vCores:1> currentConsumption=1024
2019-06-07 07:52:12,043 DEBUG org.apache.hadoop.yarn.server.resourcemanager.scheduler.SchedulerApplicationAttempt: showRequests: application=application_1559893901343_0001 headRoom=<memory:7168, vCores:1> currentConsumption=1024
2019-06-07 07:52:12,044 DEBUG org.apache.hadoop.yarn.server.resourcemanager.scheduler.SchedulerApplicationAttempt: showRequests: application=application_1559893901343_0001 request={Priority: 1, Capability: <memory:3072, vCores:1>, # Containers: 2, Location: *, Relax Locality: true, Node Label Expression: }
2019-06-07 07:52:12,044 DEBUG org.apache.hadoop.yarn.server.resourcemanager.scheduler.SchedulerApplicationAttempt: showRequests: application=application_1559893901343_0001 request={Priority: 1, Capability: <memory:3072, vCores:1>, # Containers: 2, Location: *, Relax Locality: true, Node Label Expression: }
2019-06-07 07:52:12,044 DEBUG org.apache.hadoop.yarn.server.resourcemanager.scheduler.capacity.LeafQueue: User limit computation for root in queue default userLimitPercent=100 userLimitFactor=1.0 required: <memory:1024, vCores:1> consumed: <memory:1024, vCores:1> user-limit-resource: <memory:8192, vCores:1> queueCapacity: <memory:8192, vCores:1> qconsumed: <memory:1024, vCores:1> consumedRatio: 0.0 currentCapacity: <memory:8192, vCores:1> activeUsers: 1.0 clusterCapacity: <memory:8192, vCores:2> resourceByLabel: <memory:8192, vCores:2> usageratio: 0.125 Partition:  maxUserLimit=<memory:8192, vCores:1> userWeight=1.0
2019-06-07 07:52:12,044 DEBUG org.apache.hadoop.yarn.server.resourcemanager.scheduler.capacity.LeafQueue: User limit computation for root in queue default userLimitPercent=100 userLimitFactor=1.0 required: <memory:1024, vCores:1> consumed: <memory:1024, vCores:1> user-limit-resource: <memory:8192, vCores:1> queueCapacity: <memory:8192, vCores:1> qconsumed: <memory:1024, vCores:1> consumedRatio: 0.0 currentCapacity: <memory:8192, vCores:1> activeUsers: 1.0 clusterCapacity: <memory:8192, vCores:2> resourceByLabel: <memory:8192, vCores:2> usageratio: 0.125 Partition:  maxUserLimit=<memory:8192, vCores:1> userWeight=1.0
2019-06-07 07:52:12,081 DEBUG org.apache.hadoop.yarn.server.resourcemanager.rmapp.attempt.RMAppAttemptImpl: Processing event for appattempt_1559893901343_0001_000001 of type STATUS_UPDATE
2019-06-07 07:52:12,081 DEBUG org.apache.hadoop.yarn.server.resourcemanager.rmapp.attempt.RMAppAttemptImpl: Processing event for appattempt_1559893901343_0001_000001 of type STATUS_UPDATE
2019-06-07 07:52:12,082 DEBUG org.apache.hadoop.yarn.server.resourcemanager.scheduler.capacity.LeafQueue: User limit computation for root in queue default userLimitPercent=100 userLimitFactor=1.0 required: <memory:1024, vCores:1> consumed: <memory:1024, vCores:1> user-limit-resource: <memory:8192, vCores:1> queueCapacity: <memory:8192, vCores:1> qconsumed: <memory:1024, vCores:1> consumedRatio: 0.0 currentCapacity: <memory:8192, vCores:1> activeUsers: 1.0 clusterCapacity: <memory:8192, vCores:2> resourceByLabel: <memory:8192, vCores:2> usageratio: 0.125 Partition:  maxUserLimit=<memory:8192, vCores:1> userWeight=1.0
2019-06-07 07:52:12,082 DEBUG org.apache.hadoop.yarn.server.resourcemanager.scheduler.capacity.LeafQueue: User limit computation for root in queue default userLimitPercent=100 userLimitFactor=1.0 required: <memory:1024, vCores:1> consumed: <memory:1024, vCores:1> user-limit-resource: <memory:8192, vCores:1> queueCapacity: <memory:8192, vCores:1> qconsumed: <memory:1024, vCores:1> consumedRatio: 0.0 currentCapacity: <memory:8192, vCores:1> activeUsers: 1.0 clusterCapacity: <memory:8192, vCores:2> resourceByLabel: <memory:8192, vCores:2> usageratio: 0.125 Partition:  maxUserLimit=<memory:8192, vCores:1> userWeight=1.0
2019-06-07 07:52:12,126 DEBUG org.apache.hadoop.yarn.server.resourcemanager.rmnode.RMNodeImpl: Processing slave2:38494 of type STATUS_UPDATE
2019-06-07 07:52:12,126 DEBUG org.apache.hadoop.yarn.server.resourcemanager.rmnode.RMNodeImpl: Processing slave2:38494 of type STATUS_UPDATE
2019-06-07 07:52:12,127 DEBUG org.apache.hadoop.yarn.server.resourcemanager.scheduler.capacity.CapacityScheduler: nodeUpdate: slave2:38494 clusterResources: <memory:8192, vCores:2>
2019-06-07 07:52:12,127 DEBUG org.apache.hadoop.yarn.server.resourcemanager.scheduler.capacity.CapacityScheduler: nodeUpdate: slave2:38494 clusterResources: <memory:8192, vCores:2>
2019-06-07 07:52:12,128 DEBUG org.apache.hadoop.yarn.server.resourcemanager.scheduler.capacity.CapacityScheduler: Node being looked for scheduling slave2:38494 availableResource: <memory:4096, vCores:1>
2019-06-07 07:52:12,128 DEBUG org.apache.hadoop.yarn.server.resourcemanager.scheduler.capacity.CapacityScheduler: Node being looked for scheduling slave2:38494 availableResource: <memory:4096, vCores:1>
2019-06-07 07:52:12,128 DEBUG org.apache.hadoop.yarn.server.resourcemanager.scheduler.capacity.CapacityScheduler: Trying to schedule on node: slave2, available: <memory:4096, vCores:1>
2019-06-07 07:52:12,128 DEBUG org.apache.hadoop.yarn.server.resourcemanager.scheduler.capacity.CapacityScheduler: Trying to schedule on node: slave2, available: <memory:4096, vCores:1>
2019-06-07 07:52:12,128 DEBUG org.apache.hadoop.yarn.server.resourcemanager.scheduler.capacity.ParentQueue: Trying to assign containers to child-queue of root
2019-06-07 07:52:12,128 DEBUG org.apache.hadoop.yarn.server.resourcemanager.scheduler.capacity.ParentQueue: Trying to assign containers to child-queue of root
2019-06-07 07:52:12,128 DEBUG org.apache.hadoop.yarn.server.resourcemanager.scheduler.capacity.ParentQueue: printChildQueues - queue: root child-queues: root.defaultusedCapacity=(0.125),  label=(*)
2019-06-07 07:52:12,128 DEBUG org.apache.hadoop.yarn.server.resourcemanager.scheduler.capacity.ParentQueue: printChildQueues - queue: root child-queues: root.defaultusedCapacity=(0.125),  label=(*)
2019-06-07 07:52:12,128 DEBUG org.apache.hadoop.yarn.server.resourcemanager.scheduler.capacity.ParentQueue: Trying to assign to queue: root.default stats: default: capacity=1.0, absoluteCapacity=1.0, usedResources=<memory:1024, vCores:1>, usedCapacity=0.125, absoluteUsedCapacity=0.125, numApps=1, numContainers=1
2019-06-07 07:52:12,128 DEBUG org.apache.hadoop.yarn.server.resourcemanager.scheduler.capacity.ParentQueue: Trying to assign to queue: root.default stats: default: capacity=1.0, absoluteCapacity=1.0, usedResources=<memory:1024, vCores:1>, usedCapacity=0.125, absoluteUsedCapacity=0.125, numApps=1, numContainers=1
2019-06-07 07:52:12,128 DEBUG org.apache.hadoop.yarn.server.resourcemanager.scheduler.capacity.LeafQueue: assignContainers: node=slave2 #applications=1
2019-06-07 07:52:12,128 DEBUG org.apache.hadoop.yarn.server.resourcemanager.scheduler.capacity.LeafQueue: assignContainers: node=slave2 #applications=1
2019-06-07 07:52:12,128 DEBUG org.apache.hadoop.yarn.server.resourcemanager.scheduler.capacity.LeafQueue: User limit computation for root in queue default userLimitPercent=100 userLimitFactor=1.0 required: <memory:1024, vCores:1> consumed: <memory:1024, vCores:1> user-limit-resource: <memory:8192, vCores:1> queueCapacity: <memory:8192, vCores:1> qconsumed: <memory:1024, vCores:1> consumedRatio: 0.0 currentCapacity: <memory:8192, vCores:1> activeUsers: 1.0 clusterCapacity: <memory:8192, vCores:2> resourceByLabel: <memory:8192, vCores:2> usageratio: 0.125 Partition:  maxUserLimit=<memory:8192, vCores:1> userWeight=1.0
2019-06-07 07:52:12,128 DEBUG org.apache.hadoop.yarn.server.resourcemanager.scheduler.capacity.LeafQueue: User limit computation for root in queue default userLimitPercent=100 userLimitFactor=1.0 required: <memory:1024, vCores:1> consumed: <memory:1024, vCores:1> user-limit-resource: <memory:8192, vCores:1> queueCapacity: <memory:8192, vCores:1> qconsumed: <memory:1024, vCores:1> consumedRatio: 0.0 currentCapacity: <memory:8192, vCores:1> activeUsers: 1.0 clusterCapacity: <memory:8192, vCores:2> resourceByLabel: <memory:8192, vCores:2> usageratio: 0.125 Partition:  maxUserLimit=<memory:8192, vCores:1> userWeight=1.0
2019-06-07 07:52:12,128 DEBUG org.apache.hadoop.yarn.server.resourcemanager.scheduler.capacity.LeafQueue: Headroom calculation for user root:  userLimit=<memory:8192, vCores:1> queueMaxAvailRes=<memory:8192, vCores:1> consumed=<memory:1024, vCores:1>
2019-06-07 07:52:12,128 DEBUG org.apache.hadoop.yarn.server.resourcemanager.scheduler.capacity.LeafQueue: Headroom calculation for user root:  userLimit=<memory:8192, vCores:1> queueMaxAvailRes=<memory:8192, vCores:1> consumed=<memory:1024, vCores:1>
2019-06-07 07:52:12,128 DEBUG org.apache.hadoop.yarn.server.resourcemanager.scheduler.common.fica.FiCaSchedulerApp: pre-assignContainers for application application_1559893901343_0001
2019-06-07 07:52:12,128 DEBUG org.apache.hadoop.yarn.server.resourcemanager.scheduler.common.fica.FiCaSchedulerApp: pre-assignContainers for application application_1559893901343_0001
2019-06-07 07:52:12,128 DEBUG org.apache.hadoop.yarn.server.resourcemanager.scheduler.capacity.LeafQueue: User limit computation for root in queue default userLimitPercent=100 userLimitFactor=1.0 required: <memory:1024, vCores:1> consumed: <memory:1024, vCores:1> user-limit-resource: <memory:8192, vCores:1> queueCapacity: <memory:8192, vCores:1> qconsumed: <memory:1024, vCores:1> consumedRatio: 0.0 currentCapacity: <memory:8192, vCores:1> activeUsers: 1.0 clusterCapacity: <memory:8192, vCores:2> resourceByLabel: <memory:8192, vCores:2> usageratio: 0.125 Partition:  maxUserLimit=<memory:8192, vCores:1> userWeight=1.0
2019-06-07 07:52:12,128 DEBUG org.apache.hadoop.yarn.server.resourcemanager.scheduler.capacity.LeafQueue: User limit computation for root in queue default userLimitPercent=100 userLimitFactor=1.0 required: <memory:1024, vCores:1> consumed: <memory:1024, vCores:1> user-limit-resource: <memory:8192, vCores:1> queueCapacity: <memory:8192, vCores:1> qconsumed: <memory:1024, vCores:1> consumedRatio: 0.0 currentCapacity: <memory:8192, vCores:1> activeUsers: 1.0 clusterCapacity: <memory:8192, vCores:2> resourceByLabel: <memory:8192, vCores:2> usageratio: 0.125 Partition:  maxUserLimit=<memory:8192, vCores:1> userWeight=1.0
2019-06-07 07:52:12,128 DEBUG org.apache.hadoop.yarn.server.resourcemanager.scheduler.SchedulerApplicationAttempt: showRequests: application=application_1559893901343_0001 headRoom=<memory:7168, vCores:1> currentConsumption=1024
2019-06-07 07:52:12,128 DEBUG org.apache.hadoop.yarn.server.resourcemanager.scheduler.SchedulerApplicationAttempt: showRequests: application=application_1559893901343_0001 headRoom=<memory:7168, vCores:1> currentConsumption=1024
2019-06-07 07:52:12,135 DEBUG org.apache.hadoop.yarn.server.resourcemanager.scheduler.SchedulerApplicationAttempt: showRequests: application=application_1559893901343_0001 request={Priority: 1, Capability: <memory:3072, vCores:1>, # Containers: 2, Location: *, Relax Locality: true, Node Label Expression: }
2019-06-07 07:52:12,135 DEBUG org.apache.hadoop.yarn.server.resourcemanager.scheduler.SchedulerApplicationAttempt: showRequests: application=application_1559893901343_0001 request={Priority: 1, Capability: <memory:3072, vCores:1>, # Containers: 2, Location: *, Relax Locality: true, Node Label Expression: }
2019-06-07 07:52:12,135 DEBUG org.apache.hadoop.yarn.server.resourcemanager.scheduler.capacity.allocator.IncreaseContainerAllocator: Skip allocating increase request since we don't have any increase request on this node=slave2:38494
2019-06-07 07:52:12,135 DEBUG org.apache.hadoop.yarn.server.resourcemanager.scheduler.capacity.allocator.IncreaseContainerAllocator: Skip allocating increase request since we don't have any increase request on this node=slave2:38494
2019-06-07 07:52:12,135 DEBUG org.apache.hadoop.yarn.server.resourcemanager.scheduler.capacity.allocator.RegularContainerAllocator: assignContainers: node=slave2 application=application_1559893901343_0001 priority=1 request={Priority: 1, Capability: <memory:3072, vCores:1>, # Containers: 2, Location: *, Relax Locality: true, Node Label Expression: } type=OFF_SWITCH
2019-06-07 07:52:12,135 DEBUG org.apache.hadoop.yarn.server.resourcemanager.scheduler.capacity.allocator.RegularContainerAllocator: assignContainers: node=slave2 application=application_1559893901343_0001 priority=1 request={Priority: 1, Capability: <memory:3072, vCores:1>, # Containers: 2, Location: *, Relax Locality: true, Node Label Expression: } type=OFF_SWITCH
2019-06-07 07:52:12,135 DEBUG org.apache.hadoop.yarn.server.resourcemanager.scheduler.AppSchedulingInfo: allocate: applicationId=application_1559893901343_0001 container=container_1559893901343_0001_01_000002 host=slave2:38494 user=root resource=<memory:3072, vCores:1> type=OFF_SWITCH
2019-06-07 07:52:12,135 DEBUG org.apache.hadoop.yarn.server.resourcemanager.scheduler.AppSchedulingInfo: allocate: applicationId=application_1559893901343_0001 container=container_1559893901343_0001_01_000002 host=slave2:38494 user=root resource=<memory:3072, vCores:1> type=OFF_SWITCH
2019-06-07 07:52:12,136 DEBUG org.apache.hadoop.yarn.server.resourcemanager.rmcontainer.RMContainerImpl: Processing container_1559893901343_0001_01_000002 of type START
2019-06-07 07:52:12,136 DEBUG org.apache.hadoop.yarn.server.resourcemanager.rmcontainer.RMContainerImpl: Processing container_1559893901343_0001_01_000002 of type START
2019-06-07 07:52:12,136 INFO org.apache.hadoop.yarn.server.resourcemanager.rmcontainer.RMContainerImpl: container_1559893901343_0001_01_000002 Container Transitioned from NEW to ALLOCATED
2019-06-07 07:52:12,136 INFO org.apache.hadoop.yarn.server.resourcemanager.rmcontainer.RMContainerImpl: container_1559893901343_0001_01_000002 Container Transitioned from NEW to ALLOCATED
2019-06-07 07:52:12,136 DEBUG org.apache.hadoop.yarn.server.resourcemanager.scheduler.common.fica.FiCaSchedulerApp: allocate: applicationAttemptId=appattempt_1559893901343_0001_000001 container=container_1559893901343_0001_01_000002 host=slave2 type=OFF_SWITCH
2019-06-07 07:52:12,136 DEBUG org.apache.hadoop.yarn.server.resourcemanager.scheduler.common.fica.FiCaSchedulerApp: allocate: applicationAttemptId=appattempt_1559893901343_0001_000001 container=container_1559893901343_0001_01_000002 host=slave2 type=OFF_SWITCH
2019-06-07 07:52:12,136 INFO org.apache.hadoop.yarn.server.resourcemanager.RMAuditLogger: USER=root	OPERATION=AM Allocated Container	TARGET=SchedulerApp	RESULT=SUCCESS	APPID=application_1559893901343_0001	CONTAINERID=container_1559893901343_0001_01_000002
2019-06-07 07:52:12,136 INFO org.apache.hadoop.yarn.server.resourcemanager.RMAuditLogger: USER=root	OPERATION=AM Allocated Container	TARGET=SchedulerApp	RESULT=SUCCESS	APPID=application_1559893901343_0001	CONTAINERID=container_1559893901343_0001_01_000002
2019-06-07 07:52:12,136 INFO org.apache.hadoop.yarn.server.resourcemanager.scheduler.SchedulerNode: Assigned container container_1559893901343_0001_01_000002 of capacity <memory:3072, vCores:1> on host slave2:38494, which has 1 containers, <memory:3072, vCores:1> used and <memory:1024, vCores:0> available after allocation
2019-06-07 07:52:12,136 INFO org.apache.hadoop.yarn.server.resourcemanager.scheduler.SchedulerNode: Assigned container container_1559893901343_0001_01_000002 of capacity <memory:3072, vCores:1> on host slave2:38494, which has 1 containers, <memory:3072, vCores:1> used and <memory:1024, vCores:0> available after allocation
2019-06-07 07:52:12,136 DEBUG org.apache.hadoop.yarn.server.resourcemanager.rmapp.attempt.RMAppAttemptImpl: Processing event for appattempt_1559893901343_0001_000001 of type CONTAINER_ALLOCATED
2019-06-07 07:52:12,136 INFO org.apache.hadoop.yarn.server.resourcemanager.scheduler.capacity.allocator.AbstractContainerAllocator: assignedContainer application attempt=appattempt_1559893901343_0001_000001 container=container_1559893901343_0001_01_000002 queue=org.apache.hadoop.yarn.server.resourcemanager.scheduler.capacity.allocator.RegularContainerAllocator@17efde5 clusterResource=<memory:8192, vCores:2> type=OFF_SWITCH requestedPartition=
2019-06-07 07:52:12,136 DEBUG org.apache.hadoop.yarn.server.resourcemanager.rmapp.attempt.RMAppAttemptImpl: Processing event for appattempt_1559893901343_0001_000001 of type CONTAINER_ALLOCATED
2019-06-07 07:52:12,136 INFO org.apache.hadoop.yarn.server.resourcemanager.scheduler.capacity.allocator.AbstractContainerAllocator: assignedContainer application attempt=appattempt_1559893901343_0001_000001 container=container_1559893901343_0001_01_000002 queue=org.apache.hadoop.yarn.server.resourcemanager.scheduler.capacity.allocator.RegularContainerAllocator@17efde5 clusterResource=<memory:8192, vCores:2> type=OFF_SWITCH requestedPartition=
2019-06-07 07:52:12,143 DEBUG org.apache.hadoop.yarn.server.resourcemanager.scheduler.capacity.LeafQueue: post-assignContainers for application application_1559893901343_0001
2019-06-07 07:52:12,143 DEBUG org.apache.hadoop.yarn.server.resourcemanager.scheduler.capacity.LeafQueue: post-assignContainers for application application_1559893901343_0001
2019-06-07 07:52:12,143 DEBUG org.apache.hadoop.yarn.server.resourcemanager.scheduler.capacity.LeafQueue: User limit computation for root in queue default userLimitPercent=100 userLimitFactor=1.0 required: <memory:1024, vCores:1> consumed: <memory:1024, vCores:1> user-limit-resource: <memory:8192, vCores:1> queueCapacity: <memory:8192, vCores:1> qconsumed: <memory:1024, vCores:1> consumedRatio: 0.0 currentCapacity: <memory:8192, vCores:1> activeUsers: 1.0 clusterCapacity: <memory:8192, vCores:2> resourceByLabel: <memory:8192, vCores:2> usageratio: 0.125 Partition:  maxUserLimit=<memory:8192, vCores:1> userWeight=1.0
2019-06-07 07:52:12,143 DEBUG org.apache.hadoop.yarn.server.resourcemanager.scheduler.capacity.LeafQueue: User limit computation for root in queue default userLimitPercent=100 userLimitFactor=1.0 required: <memory:1024, vCores:1> consumed: <memory:1024, vCores:1> user-limit-resource: <memory:8192, vCores:1> queueCapacity: <memory:8192, vCores:1> qconsumed: <memory:1024, vCores:1> consumedRatio: 0.0 currentCapacity: <memory:8192, vCores:1> activeUsers: 1.0 clusterCapacity: <memory:8192, vCores:2> resourceByLabel: <memory:8192, vCores:2> usageratio: 0.125 Partition:  maxUserLimit=<memory:8192, vCores:1> userWeight=1.0
2019-06-07 07:52:12,143 DEBUG org.apache.hadoop.yarn.server.resourcemanager.scheduler.SchedulerApplicationAttempt: showRequests: application=application_1559893901343_0001 headRoom=<memory:7168, vCores:1> currentConsumption=4096
2019-06-07 07:52:12,143 DEBUG org.apache.hadoop.yarn.server.resourcemanager.scheduler.SchedulerApplicationAttempt: showRequests: application=application_1559893901343_0001 headRoom=<memory:7168, vCores:1> currentConsumption=4096
2019-06-07 07:52:12,143 DEBUG org.apache.hadoop.yarn.server.resourcemanager.scheduler.SchedulerApplicationAttempt: showRequests: application=application_1559893901343_0001 request={Priority: 1, Capability: <memory:3072, vCores:1>, # Containers: 1, Location: *, Relax Locality: true, Node Label Expression: }
2019-06-07 07:52:12,143 DEBUG org.apache.hadoop.yarn.server.resourcemanager.scheduler.SchedulerApplicationAttempt: showRequests: application=application_1559893901343_0001 request={Priority: 1, Capability: <memory:3072, vCores:1>, # Containers: 1, Location: *, Relax Locality: true, Node Label Expression: }
2019-06-07 07:52:12,144 DEBUG org.apache.hadoop.yarn.server.resourcemanager.scheduler.capacity.LeafQueue: User limit computation for root in queue default userLimitPercent=100 userLimitFactor=1.0 required: <memory:1024, vCores:1> consumed: <memory:4096, vCores:1> user-limit-resource: <memory:8192, vCores:1> queueCapacity: <memory:8192, vCores:1> qconsumed: <memory:4096, vCores:2> consumedRatio: 0.0 currentCapacity: <memory:8192, vCores:1> activeUsers: 1.0 clusterCapacity: <memory:8192, vCores:2> resourceByLabel: <memory:8192, vCores:2> usageratio: 0.5 Partition:  maxUserLimit=<memory:8192, vCores:1> userWeight=1.0
2019-06-07 07:52:12,144 DEBUG org.apache.hadoop.yarn.server.resourcemanager.scheduler.capacity.LeafQueue: User limit computation for root in queue default userLimitPercent=100 userLimitFactor=1.0 required: <memory:1024, vCores:1> consumed: <memory:4096, vCores:1> user-limit-resource: <memory:8192, vCores:1> queueCapacity: <memory:8192, vCores:1> qconsumed: <memory:4096, vCores:2> consumedRatio: 0.0 currentCapacity: <memory:8192, vCores:1> activeUsers: 1.0 clusterCapacity: <memory:8192, vCores:2> resourceByLabel: <memory:8192, vCores:2> usageratio: 0.5 Partition:  maxUserLimit=<memory:8192, vCores:1> userWeight=1.0
2019-06-07 07:52:12,144 DEBUG org.apache.hadoop.yarn.server.resourcemanager.scheduler.capacity.LeafQueue: User limit computation for root in queue default userLimitPercent=100 userLimitFactor=1.0 required: <memory:1024, vCores:1> consumed: <memory:4096, vCores:1> user-limit-resource: <memory:8192, vCores:1> queueCapacity: <memory:8192, vCores:1> qconsumed: <memory:4096, vCores:2> consumedRatio: 0.0 currentCapacity: <memory:8192, vCores:1> activeUsers: 1.0 clusterCapacity: <memory:8192, vCores:2> resourceByLabel: <memory:8192, vCores:2> usageratio: 0.5 Partition:  maxUserLimit=<memory:8192, vCores:1> userWeight=1.0
2019-06-07 07:52:12,144 DEBUG org.apache.hadoop.yarn.server.resourcemanager.scheduler.capacity.LeafQueue: User limit computation for root in queue default userLimitPercent=100 userLimitFactor=1.0 required: <memory:1024, vCores:1> consumed: <memory:4096, vCores:1> user-limit-resource: <memory:8192, vCores:1> queueCapacity: <memory:8192, vCores:1> qconsumed: <memory:4096, vCores:2> consumedRatio: 0.0 currentCapacity: <memory:8192, vCores:1> activeUsers: 1.0 clusterCapacity: <memory:8192, vCores:2> resourceByLabel: <memory:8192, vCores:2> usageratio: 0.5 Partition:  maxUserLimit=<memory:8192, vCores:1> userWeight=1.0
2019-06-07 07:52:12,144 DEBUG org.apache.hadoop.yarn.server.resourcemanager.scheduler.capacity.LeafQueue: User limit computation for root in queue default userLimitPercent=100 userLimitFactor=1.0 required: <memory:1024, vCores:1> consumed: <memory:4096, vCores:1> user-limit-resource: <memory:8192, vCores:1> queueCapacity: <memory:8192, vCores:1> qconsumed: <memory:4096, vCores:2> consumedRatio: 0.0 currentCapacity: <memory:8192, vCores:1> activeUsers: 1.0 clusterCapacity: <memory:8192, vCores:2> resourceByLabel: <memory:8192, vCores:2> usageratio: 0.5 Partition:  maxUserLimit=<memory:8192, vCores:1> userWeight=1.0
2019-06-07 07:52:12,144 DEBUG org.apache.hadoop.yarn.server.resourcemanager.scheduler.capacity.LeafQueue: User limit computation for root in queue default userLimitPercent=100 userLimitFactor=1.0 required: <memory:1024, vCores:1> consumed: <memory:4096, vCores:1> user-limit-resource: <memory:8192, vCores:1> queueCapacity: <memory:8192, vCores:1> qconsumed: <memory:4096, vCores:2> consumedRatio: 0.0 currentCapacity: <memory:8192, vCores:1> activeUsers: 1.0 clusterCapacity: <memory:8192, vCores:2> resourceByLabel: <memory:8192, vCores:2> usageratio: 0.5 Partition:  maxUserLimit=<memory:8192, vCores:1> userWeight=1.0
2019-06-07 07:52:12,144 DEBUG org.apache.hadoop.yarn.server.resourcemanager.scheduler.capacity.LeafQueue: default user=root used=<memory:4096, vCores:2> numContainers=2 headroom = <memory:4096, vCores:1> user-resources=<memory:4096, vCores:2>
2019-06-07 07:52:12,144 DEBUG org.apache.hadoop.yarn.server.resourcemanager.scheduler.capacity.LeafQueue: default user=root used=<memory:4096, vCores:2> numContainers=2 headroom = <memory:4096, vCores:1> user-resources=<memory:4096, vCores:2>
2019-06-07 07:52:12,144 DEBUG org.apache.hadoop.yarn.server.resourcemanager.scheduler.capacity.ParentQueue: Assigned to queue: root.default stats: default: capacity=1.0, absoluteCapacity=1.0, usedResources=<memory:4096, vCores:2>, usedCapacity=0.5, absoluteUsedCapacity=0.5, numApps=1, numContainers=2 --> <memory:3072, vCores:1>, OFF_SWITCH
2019-06-07 07:52:12,144 DEBUG org.apache.hadoop.yarn.server.resourcemanager.scheduler.capacity.ParentQueue: Assigned to queue: root.default stats: default: capacity=1.0, absoluteCapacity=1.0, usedResources=<memory:4096, vCores:2>, usedCapacity=0.5, absoluteUsedCapacity=0.5, numApps=1, numContainers=2 --> <memory:3072, vCores:1>, OFF_SWITCH
2019-06-07 07:52:12,144 INFO org.apache.hadoop.yarn.server.resourcemanager.scheduler.capacity.ParentQueue: Re-sorting assigned queue: root.default stats: default: capacity=1.0, absoluteCapacity=1.0, usedResources=<memory:4096, vCores:2>, usedCapacity=0.5, absoluteUsedCapacity=0.5, numApps=1, numContainers=2
2019-06-07 07:52:12,144 INFO org.apache.hadoop.yarn.server.resourcemanager.scheduler.capacity.ParentQueue: Re-sorting assigned queue: root.default stats: default: capacity=1.0, absoluteCapacity=1.0, usedResources=<memory:4096, vCores:2>, usedCapacity=0.5, absoluteUsedCapacity=0.5, numApps=1, numContainers=2
2019-06-07 07:52:12,144 DEBUG org.apache.hadoop.yarn.server.resourcemanager.scheduler.capacity.ParentQueue: printChildQueues - queue: root child-queues: root.defaultusedCapacity=(0.5),  label=(*)
2019-06-07 07:52:12,144 DEBUG org.apache.hadoop.yarn.server.resourcemanager.scheduler.capacity.ParentQueue: printChildQueues - queue: root child-queues: root.defaultusedCapacity=(0.5),  label=(*)
2019-06-07 07:52:12,144 INFO org.apache.hadoop.yarn.server.resourcemanager.scheduler.capacity.ParentQueue: assignedContainer queue=root usedCapacity=0.5 absoluteUsedCapacity=0.5 used=<memory:4096, vCores:2> cluster=<memory:8192, vCores:2>
2019-06-07 07:52:12,144 INFO org.apache.hadoop.yarn.server.resourcemanager.scheduler.capacity.ParentQueue: assignedContainer queue=root usedCapacity=0.5 absoluteUsedCapacity=0.5 used=<memory:4096, vCores:2> cluster=<memory:8192, vCores:2>
2019-06-07 07:52:12,144 DEBUG org.apache.hadoop.yarn.server.resourcemanager.scheduler.capacity.ParentQueue: ParentQ=root assignedSoFarInThisIteration=<memory:3072, vCores:1> usedCapacity=0.5 absoluteUsedCapacity=0.5
2019-06-07 07:52:12,144 DEBUG org.apache.hadoop.yarn.server.resourcemanager.scheduler.capacity.ParentQueue: ParentQ=root assignedSoFarInThisIteration=<memory:3072, vCores:1> usedCapacity=0.5 absoluteUsedCapacity=0.5
2019-06-07 07:52:12,144 DEBUG org.apache.hadoop.yarn.server.resourcemanager.scheduler.capacity.ParentQueue: Assigned maximum number of off-switch containers: 1, assignments so far: resource:<memory:3072, vCores:1>; type:OFF_SWITCH; excessReservation:null; applicationid:null; skipped:NONE; fulfilled reservation:false; allocations(count/resource):1/<memory:3072, vCores:1>; reservations(count/resource):0/<memory:0, vCores:0>
2019-06-07 07:52:12,144 DEBUG org.apache.hadoop.yarn.server.resourcemanager.scheduler.capacity.ParentQueue: Assigned maximum number of off-switch containers: 1, assignments so far: resource:<memory:3072, vCores:1>; type:OFF_SWITCH; excessReservation:null; applicationid:null; skipped:NONE; fulfilled reservation:false; allocations(count/resource):1/<memory:3072, vCores:1>; reservations(count/resource):0/<memory:0, vCores:0>
2019-06-07 07:52:12,176 DEBUG org.apache.hadoop.yarn.server.resourcemanager.rmnode.RMNodeImpl: Processing slave1:39995 of type STATUS_UPDATE
2019-06-07 07:52:12,176 DEBUG org.apache.hadoop.yarn.server.resourcemanager.rmnode.RMNodeImpl: Processing slave1:39995 of type STATUS_UPDATE
2019-06-07 07:52:12,178 DEBUG org.apache.hadoop.yarn.server.resourcemanager.scheduler.capacity.CapacityScheduler: nodeUpdate: slave1:39995 clusterResources: <memory:8192, vCores:2>
2019-06-07 07:52:12,178 DEBUG org.apache.hadoop.yarn.server.resourcemanager.scheduler.capacity.CapacityScheduler: nodeUpdate: slave1:39995 clusterResources: <memory:8192, vCores:2>
2019-06-07 07:52:12,178 DEBUG org.apache.hadoop.yarn.server.resourcemanager.scheduler.capacity.CapacityScheduler: Node being looked for scheduling slave1:39995 availableResource: <memory:3072, vCores:0>
2019-06-07 07:52:12,178 DEBUG org.apache.hadoop.yarn.server.resourcemanager.scheduler.capacity.CapacityScheduler: Node being looked for scheduling slave1:39995 availableResource: <memory:3072, vCores:0>
2019-06-07 07:52:12,178 DEBUG org.apache.hadoop.yarn.server.resourcemanager.scheduler.capacity.CapacityScheduler: Trying to schedule on node: slave1, available: <memory:3072, vCores:0>
2019-06-07 07:52:12,178 DEBUG org.apache.hadoop.yarn.server.resourcemanager.scheduler.capacity.CapacityScheduler: Trying to schedule on node: slave1, available: <memory:3072, vCores:0>
2019-06-07 07:52:12,178 DEBUG org.apache.hadoop.yarn.server.resourcemanager.scheduler.capacity.ParentQueue: Trying to assign containers to child-queue of root
2019-06-07 07:52:12,178 DEBUG org.apache.hadoop.yarn.server.resourcemanager.scheduler.capacity.ParentQueue: Trying to assign containers to child-queue of root
2019-06-07 07:52:12,178 DEBUG org.apache.hadoop.yarn.server.resourcemanager.scheduler.capacity.ParentQueue: printChildQueues - queue: root child-queues: root.defaultusedCapacity=(0.5),  label=(*)
2019-06-07 07:52:12,178 DEBUG org.apache.hadoop.yarn.server.resourcemanager.scheduler.capacity.ParentQueue: printChildQueues - queue: root child-queues: root.defaultusedCapacity=(0.5),  label=(*)
2019-06-07 07:52:12,178 DEBUG org.apache.hadoop.yarn.server.resourcemanager.scheduler.capacity.ParentQueue: Trying to assign to queue: root.default stats: default: capacity=1.0, absoluteCapacity=1.0, usedResources=<memory:4096, vCores:2>, usedCapacity=0.5, absoluteUsedCapacity=0.5, numApps=1, numContainers=2
2019-06-07 07:52:12,178 DEBUG org.apache.hadoop.yarn.server.resourcemanager.scheduler.capacity.ParentQueue: Trying to assign to queue: root.default stats: default: capacity=1.0, absoluteCapacity=1.0, usedResources=<memory:4096, vCores:2>, usedCapacity=0.5, absoluteUsedCapacity=0.5, numApps=1, numContainers=2
2019-06-07 07:52:12,178 DEBUG org.apache.hadoop.yarn.server.resourcemanager.scheduler.capacity.LeafQueue: assignContainers: node=slave1 #applications=1
2019-06-07 07:52:12,178 DEBUG org.apache.hadoop.yarn.server.resourcemanager.scheduler.capacity.LeafQueue: assignContainers: node=slave1 #applications=1
2019-06-07 07:52:12,179 DEBUG org.apache.hadoop.yarn.server.resourcemanager.scheduler.capacity.LeafQueue: User limit computation for root in queue default userLimitPercent=100 userLimitFactor=1.0 required: <memory:1024, vCores:1> consumed: <memory:4096, vCores:1> user-limit-resource: <memory:8192, vCores:1> queueCapacity: <memory:8192, vCores:1> qconsumed: <memory:4096, vCores:2> consumedRatio: 0.0 currentCapacity: <memory:8192, vCores:1> activeUsers: 1.0 clusterCapacity: <memory:8192, vCores:2> resourceByLabel: <memory:8192, vCores:2> usageratio: 0.5 Partition:  maxUserLimit=<memory:8192, vCores:1> userWeight=1.0
2019-06-07 07:52:12,179 DEBUG org.apache.hadoop.yarn.server.resourcemanager.scheduler.capacity.LeafQueue: User limit computation for root in queue default userLimitPercent=100 userLimitFactor=1.0 required: <memory:1024, vCores:1> consumed: <memory:4096, vCores:1> user-limit-resource: <memory:8192, vCores:1> queueCapacity: <memory:8192, vCores:1> qconsumed: <memory:4096, vCores:2> consumedRatio: 0.0 currentCapacity: <memory:8192, vCores:1> activeUsers: 1.0 clusterCapacity: <memory:8192, vCores:2> resourceByLabel: <memory:8192, vCores:2> usageratio: 0.5 Partition:  maxUserLimit=<memory:8192, vCores:1> userWeight=1.0
2019-06-07 07:52:12,179 DEBUG org.apache.hadoop.yarn.server.resourcemanager.scheduler.capacity.LeafQueue: Headroom calculation for user root:  userLimit=<memory:8192, vCores:1> queueMaxAvailRes=<memory:8192, vCores:1> consumed=<memory:4096, vCores:2>
2019-06-07 07:52:12,179 DEBUG org.apache.hadoop.yarn.server.resourcemanager.scheduler.capacity.LeafQueue: Headroom calculation for user root:  userLimit=<memory:8192, vCores:1> queueMaxAvailRes=<memory:8192, vCores:1> consumed=<memory:4096, vCores:2>
2019-06-07 07:52:12,179 DEBUG org.apache.hadoop.yarn.server.resourcemanager.scheduler.common.fica.FiCaSchedulerApp: pre-assignContainers for application application_1559893901343_0001
2019-06-07 07:52:12,179 DEBUG org.apache.hadoop.yarn.server.resourcemanager.scheduler.common.fica.FiCaSchedulerApp: pre-assignContainers for application application_1559893901343_0001
2019-06-07 07:52:12,179 DEBUG org.apache.hadoop.yarn.server.resourcemanager.scheduler.capacity.LeafQueue: User limit computation for root in queue default userLimitPercent=100 userLimitFactor=1.0 required: <memory:1024, vCores:1> consumed: <memory:4096, vCores:1> user-limit-resource: <memory:8192, vCores:1> queueCapacity: <memory:8192, vCores:1> qconsumed: <memory:4096, vCores:2> consumedRatio: 0.0 currentCapacity: <memory:8192, vCores:1> activeUsers: 1.0 clusterCapacity: <memory:8192, vCores:2> resourceByLabel: <memory:8192, vCores:2> usageratio: 0.5 Partition:  maxUserLimit=<memory:8192, vCores:1> userWeight=1.0
2019-06-07 07:52:12,179 DEBUG org.apache.hadoop.yarn.server.resourcemanager.scheduler.capacity.LeafQueue: User limit computation for root in queue default userLimitPercent=100 userLimitFactor=1.0 required: <memory:1024, vCores:1> consumed: <memory:4096, vCores:1> user-limit-resource: <memory:8192, vCores:1> queueCapacity: <memory:8192, vCores:1> qconsumed: <memory:4096, vCores:2> consumedRatio: 0.0 currentCapacity: <memory:8192, vCores:1> activeUsers: 1.0 clusterCapacity: <memory:8192, vCores:2> resourceByLabel: <memory:8192, vCores:2> usageratio: 0.5 Partition:  maxUserLimit=<memory:8192, vCores:1> userWeight=1.0
2019-06-07 07:52:12,179 DEBUG org.apache.hadoop.yarn.server.resourcemanager.scheduler.SchedulerApplicationAttempt: showRequests: application=application_1559893901343_0001 headRoom=<memory:4096, vCores:0> currentConsumption=4096
2019-06-07 07:52:12,179 DEBUG org.apache.hadoop.yarn.server.resourcemanager.scheduler.SchedulerApplicationAttempt: showRequests: application=application_1559893901343_0001 headRoom=<memory:4096, vCores:0> currentConsumption=4096
2019-06-07 07:52:12,179 DEBUG org.apache.hadoop.yarn.server.resourcemanager.scheduler.SchedulerApplicationAttempt: showRequests: application=application_1559893901343_0001 request={Priority: 1, Capability: <memory:3072, vCores:1>, # Containers: 1, Location: *, Relax Locality: true, Node Label Expression: }
2019-06-07 07:52:12,179 DEBUG org.apache.hadoop.yarn.server.resourcemanager.scheduler.SchedulerApplicationAttempt: showRequests: application=application_1559893901343_0001 request={Priority: 1, Capability: <memory:3072, vCores:1>, # Containers: 1, Location: *, Relax Locality: true, Node Label Expression: }
2019-06-07 07:52:12,179 DEBUG org.apache.hadoop.yarn.server.resourcemanager.scheduler.capacity.allocator.IncreaseContainerAllocator: Skip allocating increase request since we don't have any increase request on this node=slave1:39995
2019-06-07 07:52:12,179 DEBUG org.apache.hadoop.yarn.server.resourcemanager.scheduler.capacity.allocator.IncreaseContainerAllocator: Skip allocating increase request since we don't have any increase request on this node=slave1:39995
2019-06-07 07:52:12,179 DEBUG org.apache.hadoop.yarn.server.resourcemanager.scheduler.capacity.allocator.RegularContainerAllocator: assignContainers: node=slave1 application=application_1559893901343_0001 priority=1 request={Priority: 1, Capability: <memory:3072, vCores:1>, # Containers: 1, Location: *, Relax Locality: true, Node Label Expression: } type=OFF_SWITCH
2019-06-07 07:52:12,179 DEBUG org.apache.hadoop.yarn.server.resourcemanager.scheduler.capacity.allocator.RegularContainerAllocator: assignContainers: node=slave1 application=application_1559893901343_0001 priority=1 request={Priority: 1, Capability: <memory:3072, vCores:1>, # Containers: 1, Location: *, Relax Locality: true, Node Label Expression: } type=OFF_SWITCH
2019-06-07 07:52:12,179 DEBUG org.apache.hadoop.yarn.server.resourcemanager.scheduler.ActiveUsersManager: User root removed from activeUsers, currently: 0
2019-06-07 07:52:12,179 DEBUG org.apache.hadoop.yarn.server.resourcemanager.scheduler.ActiveUsersManager: User root removed from activeUsers, currently: 0
2019-06-07 07:52:12,179 DEBUG org.apache.hadoop.yarn.server.resourcemanager.scheduler.AppSchedulingInfo: allocate: applicationId=application_1559893901343_0001 container=container_1559893901343_0001_01_000003 host=slave1:39995 user=root resource=<memory:3072, vCores:1> type=OFF_SWITCH
2019-06-07 07:52:12,179 DEBUG org.apache.hadoop.yarn.server.resourcemanager.scheduler.AppSchedulingInfo: allocate: applicationId=application_1559893901343_0001 container=container_1559893901343_0001_01_000003 host=slave1:39995 user=root resource=<memory:3072, vCores:1> type=OFF_SWITCH
2019-06-07 07:52:12,179 DEBUG org.apache.hadoop.yarn.server.resourcemanager.rmcontainer.RMContainerImpl: Processing container_1559893901343_0001_01_000003 of type START
2019-06-07 07:52:12,179 DEBUG org.apache.hadoop.yarn.server.resourcemanager.rmcontainer.RMContainerImpl: Processing container_1559893901343_0001_01_000003 of type START
2019-06-07 07:52:12,179 DEBUG org.apache.hadoop.yarn.server.resourcemanager.rmapp.attempt.RMAppAttemptImpl: Processing event for appattempt_1559893901343_0001_000001 of type CONTAINER_ALLOCATED
2019-06-07 07:52:12,179 INFO org.apache.hadoop.yarn.server.resourcemanager.rmcontainer.RMContainerImpl: container_1559893901343_0001_01_000003 Container Transitioned from NEW to ALLOCATED
2019-06-07 07:52:12,179 DEBUG org.apache.hadoop.yarn.server.resourcemanager.rmapp.attempt.RMAppAttemptImpl: Processing event for appattempt_1559893901343_0001_000001 of type CONTAINER_ALLOCATED
2019-06-07 07:52:12,179 INFO org.apache.hadoop.yarn.server.resourcemanager.rmcontainer.RMContainerImpl: container_1559893901343_0001_01_000003 Container Transitioned from NEW to ALLOCATED
2019-06-07 07:52:12,181 DEBUG org.apache.hadoop.yarn.server.resourcemanager.scheduler.common.fica.FiCaSchedulerApp: allocate: applicationAttemptId=appattempt_1559893901343_0001_000001 container=container_1559893901343_0001_01_000003 host=slave1 type=OFF_SWITCH
2019-06-07 07:52:12,181 DEBUG org.apache.hadoop.yarn.server.resourcemanager.scheduler.common.fica.FiCaSchedulerApp: allocate: applicationAttemptId=appattempt_1559893901343_0001_000001 container=container_1559893901343_0001_01_000003 host=slave1 type=OFF_SWITCH
2019-06-07 07:52:12,181 INFO org.apache.hadoop.yarn.server.resourcemanager.RMAuditLogger: USER=root	OPERATION=AM Allocated Container	TARGET=SchedulerApp	RESULT=SUCCESS	APPID=application_1559893901343_0001	CONTAINERID=container_1559893901343_0001_01_000003
2019-06-07 07:52:12,181 INFO org.apache.hadoop.yarn.server.resourcemanager.RMAuditLogger: USER=root	OPERATION=AM Allocated Container	TARGET=SchedulerApp	RESULT=SUCCESS	APPID=application_1559893901343_0001	CONTAINERID=container_1559893901343_0001_01_000003
2019-06-07 07:52:12,181 INFO org.apache.hadoop.yarn.server.resourcemanager.scheduler.SchedulerNode: Assigned container container_1559893901343_0001_01_000003 of capacity <memory:3072, vCores:1> on host slave1:39995, which has 2 containers, <memory:4096, vCores:2> used and <memory:0, vCores:-1> available after allocation
2019-06-07 07:52:12,181 INFO org.apache.hadoop.yarn.server.resourcemanager.scheduler.SchedulerNode: Assigned container container_1559893901343_0001_01_000003 of capacity <memory:3072, vCores:1> on host slave1:39995, which has 2 containers, <memory:4096, vCores:2> used and <memory:0, vCores:-1> available after allocation
2019-06-07 07:52:12,181 INFO org.apache.hadoop.yarn.server.resourcemanager.scheduler.capacity.allocator.AbstractContainerAllocator: assignedContainer application attempt=appattempt_1559893901343_0001_000001 container=container_1559893901343_0001_01_000003 queue=org.apache.hadoop.yarn.server.resourcemanager.scheduler.capacity.allocator.RegularContainerAllocator@17efde5 clusterResource=<memory:8192, vCores:2> type=OFF_SWITCH requestedPartition=
2019-06-07 07:52:12,181 INFO org.apache.hadoop.yarn.server.resourcemanager.scheduler.capacity.allocator.AbstractContainerAllocator: assignedContainer application attempt=appattempt_1559893901343_0001_000001 container=container_1559893901343_0001_01_000003 queue=org.apache.hadoop.yarn.server.resourcemanager.scheduler.capacity.allocator.RegularContainerAllocator@17efde5 clusterResource=<memory:8192, vCores:2> type=OFF_SWITCH requestedPartition=
2019-06-07 07:52:12,181 DEBUG org.apache.hadoop.yarn.server.resourcemanager.scheduler.capacity.LeafQueue: post-assignContainers for application application_1559893901343_0001
2019-06-07 07:52:12,181 DEBUG org.apache.hadoop.yarn.server.resourcemanager.scheduler.capacity.LeafQueue: post-assignContainers for application application_1559893901343_0001
2019-06-07 07:52:12,182 DEBUG org.apache.hadoop.yarn.server.resourcemanager.scheduler.capacity.LeafQueue: User limit computation for root in queue default userLimitPercent=100 userLimitFactor=1.0 required: <memory:1024, vCores:1> consumed: <memory:7168, vCores:1> user-limit-resource: <memory:8192, vCores:1> queueCapacity: <memory:8192, vCores:1> qconsumed: <memory:7168, vCores:3> consumedRatio: 0.0 currentCapacity: <memory:8192, vCores:1> activeUsers: 0.0 clusterCapacity: <memory:8192, vCores:2> resourceByLabel: <memory:8192, vCores:2> usageratio: 0.875 Partition:  maxUserLimit=<memory:8192, vCores:1> userWeight=1.0
2019-06-07 07:52:12,182 DEBUG org.apache.hadoop.yarn.server.resourcemanager.scheduler.capacity.LeafQueue: User limit computation for root in queue default userLimitPercent=100 userLimitFactor=1.0 required: <memory:1024, vCores:1> consumed: <memory:7168, vCores:1> user-limit-resource: <memory:8192, vCores:1> queueCapacity: <memory:8192, vCores:1> qconsumed: <memory:7168, vCores:3> consumedRatio: 0.0 currentCapacity: <memory:8192, vCores:1> activeUsers: 0.0 clusterCapacity: <memory:8192, vCores:2> resourceByLabel: <memory:8192, vCores:2> usageratio: 0.875 Partition:  maxUserLimit=<memory:8192, vCores:1> userWeight=1.0
2019-06-07 07:52:12,182 DEBUG org.apache.hadoop.yarn.server.resourcemanager.scheduler.capacity.LeafQueue: User limit computation for root in queue default userLimitPercent=100 userLimitFactor=1.0 required: <memory:1024, vCores:1> consumed: <memory:7168, vCores:1> user-limit-resource: <memory:8192, vCores:1> queueCapacity: <memory:8192, vCores:1> qconsumed: <memory:7168, vCores:3> consumedRatio: 0.0 currentCapacity: <memory:8192, vCores:1> activeUsers: 0.0 clusterCapacity: <memory:8192, vCores:2> resourceByLabel: <memory:8192, vCores:2> usageratio: 0.875 Partition:  maxUserLimit=<memory:8192, vCores:1> userWeight=1.0
2019-06-07 07:52:12,182 DEBUG org.apache.hadoop.yarn.server.resourcemanager.scheduler.capacity.LeafQueue: User limit computation for root in queue default userLimitPercent=100 userLimitFactor=1.0 required: <memory:1024, vCores:1> consumed: <memory:7168, vCores:1> user-limit-resource: <memory:8192, vCores:1> queueCapacity: <memory:8192, vCores:1> qconsumed: <memory:7168, vCores:3> consumedRatio: 0.0 currentCapacity: <memory:8192, vCores:1> activeUsers: 0.0 clusterCapacity: <memory:8192, vCores:2> resourceByLabel: <memory:8192, vCores:2> usageratio: 0.875 Partition:  maxUserLimit=<memory:8192, vCores:1> userWeight=1.0
2019-06-07 07:52:12,182 DEBUG org.apache.hadoop.yarn.server.resourcemanager.scheduler.capacity.LeafQueue: User limit computation for root in queue default userLimitPercent=100 userLimitFactor=1.0 required: <memory:1024, vCores:1> consumed: <memory:7168, vCores:1> user-limit-resource: <memory:8192, vCores:1> queueCapacity: <memory:8192, vCores:1> qconsumed: <memory:7168, vCores:3> consumedRatio: 0.0 currentCapacity: <memory:8192, vCores:1> activeUsers: 0.0 clusterCapacity: <memory:8192, vCores:2> resourceByLabel: <memory:8192, vCores:2> usageratio: 0.875 Partition:  maxUserLimit=<memory:8192, vCores:1> userWeight=1.0
2019-06-07 07:52:12,182 DEBUG org.apache.hadoop.yarn.server.resourcemanager.scheduler.capacity.LeafQueue: User limit computation for root in queue default userLimitPercent=100 userLimitFactor=1.0 required: <memory:1024, vCores:1> consumed: <memory:7168, vCores:1> user-limit-resource: <memory:8192, vCores:1> queueCapacity: <memory:8192, vCores:1> qconsumed: <memory:7168, vCores:3> consumedRatio: 0.0 currentCapacity: <memory:8192, vCores:1> activeUsers: 0.0 clusterCapacity: <memory:8192, vCores:2> resourceByLabel: <memory:8192, vCores:2> usageratio: 0.875 Partition:  maxUserLimit=<memory:8192, vCores:1> userWeight=1.0
2019-06-07 07:52:12,182 DEBUG org.apache.hadoop.yarn.server.resourcemanager.scheduler.capacity.LeafQueue: default user=root used=<memory:7168, vCores:3> numContainers=3 headroom = <memory:1024, vCores:1> user-resources=<memory:7168, vCores:3>
2019-06-07 07:52:12,182 DEBUG org.apache.hadoop.yarn.server.resourcemanager.scheduler.capacity.LeafQueue: default user=root used=<memory:7168, vCores:3> numContainers=3 headroom = <memory:1024, vCores:1> user-resources=<memory:7168, vCores:3>
2019-06-07 07:52:12,182 DEBUG org.apache.hadoop.yarn.server.resourcemanager.scheduler.capacity.ParentQueue: Assigned to queue: root.default stats: default: capacity=1.0, absoluteCapacity=1.0, usedResources=<memory:7168, vCores:3>, usedCapacity=0.875, absoluteUsedCapacity=0.875, numApps=1, numContainers=3 --> <memory:3072, vCores:1>, OFF_SWITCH
2019-06-07 07:52:12,182 DEBUG org.apache.hadoop.yarn.server.resourcemanager.scheduler.capacity.ParentQueue: Assigned to queue: root.default stats: default: capacity=1.0, absoluteCapacity=1.0, usedResources=<memory:7168, vCores:3>, usedCapacity=0.875, absoluteUsedCapacity=0.875, numApps=1, numContainers=3 --> <memory:3072, vCores:1>, OFF_SWITCH
2019-06-07 07:52:12,182 INFO org.apache.hadoop.yarn.server.resourcemanager.scheduler.capacity.ParentQueue: Re-sorting assigned queue: root.default stats: default: capacity=1.0, absoluteCapacity=1.0, usedResources=<memory:7168, vCores:3>, usedCapacity=0.875, absoluteUsedCapacity=0.875, numApps=1, numContainers=3
2019-06-07 07:52:12,182 INFO org.apache.hadoop.yarn.server.resourcemanager.scheduler.capacity.ParentQueue: Re-sorting assigned queue: root.default stats: default: capacity=1.0, absoluteCapacity=1.0, usedResources=<memory:7168, vCores:3>, usedCapacity=0.875, absoluteUsedCapacity=0.875, numApps=1, numContainers=3
2019-06-07 07:52:12,182 DEBUG org.apache.hadoop.yarn.server.resourcemanager.scheduler.capacity.ParentQueue: printChildQueues - queue: root child-queues: root.defaultusedCapacity=(0.875),  label=(*)
2019-06-07 07:52:12,182 DEBUG org.apache.hadoop.yarn.server.resourcemanager.scheduler.capacity.ParentQueue: printChildQueues - queue: root child-queues: root.defaultusedCapacity=(0.875),  label=(*)
2019-06-07 07:52:12,182 INFO org.apache.hadoop.yarn.server.resourcemanager.scheduler.capacity.ParentQueue: assignedContainer queue=root usedCapacity=0.875 absoluteUsedCapacity=0.875 used=<memory:7168, vCores:3> cluster=<memory:8192, vCores:2>
2019-06-07 07:52:12,182 INFO org.apache.hadoop.yarn.server.resourcemanager.scheduler.capacity.ParentQueue: assignedContainer queue=root usedCapacity=0.875 absoluteUsedCapacity=0.875 used=<memory:7168, vCores:3> cluster=<memory:8192, vCores:2>
2019-06-07 07:52:12,182 DEBUG org.apache.hadoop.yarn.server.resourcemanager.scheduler.capacity.ParentQueue: ParentQ=root assignedSoFarInThisIteration=<memory:3072, vCores:1> usedCapacity=0.875 absoluteUsedCapacity=0.875
2019-06-07 07:52:12,182 DEBUG org.apache.hadoop.yarn.server.resourcemanager.scheduler.capacity.ParentQueue: ParentQ=root assignedSoFarInThisIteration=<memory:3072, vCores:1> usedCapacity=0.875 absoluteUsedCapacity=0.875
2019-06-07 07:52:12,182 DEBUG org.apache.hadoop.yarn.server.resourcemanager.scheduler.capacity.ParentQueue: Assigned maximum number of off-switch containers: 1, assignments so far: resource:<memory:3072, vCores:1>; type:OFF_SWITCH; excessReservation:null; applicationid:null; skipped:NONE; fulfilled reservation:false; allocations(count/resource):1/<memory:3072, vCores:1>; reservations(count/resource):0/<memory:0, vCores:0>
2019-06-07 07:52:12,182 DEBUG org.apache.hadoop.yarn.server.resourcemanager.scheduler.capacity.ParentQueue: Assigned maximum number of off-switch containers: 1, assignments so far: resource:<memory:3072, vCores:1>; type:OFF_SWITCH; excessReservation:null; applicationid:null; skipped:NONE; fulfilled reservation:false; allocations(count/resource):1/<memory:3072, vCores:1>; reservations(count/resource):0/<memory:0, vCores:0>
2019-06-07 07:52:12,293 DEBUG org.apache.hadoop.yarn.server.resourcemanager.rmapp.attempt.RMAppAttemptImpl: Processing event for appattempt_1559893901343_0001_000001 of type STATUS_UPDATE
2019-06-07 07:52:12,293 DEBUG org.apache.hadoop.yarn.server.resourcemanager.rmapp.attempt.RMAppAttemptImpl: Processing event for appattempt_1559893901343_0001_000001 of type STATUS_UPDATE
2019-06-07 07:52:12,296 INFO org.apache.hadoop.yarn.server.resourcemanager.security.NMTokenSecretManagerInRM: Sending NMToken for nodeId : slave2:38494 for container : container_1559893901343_0001_01_000002
2019-06-07 07:52:12,296 INFO org.apache.hadoop.yarn.server.resourcemanager.security.NMTokenSecretManagerInRM: Sending NMToken for nodeId : slave2:38494 for container : container_1559893901343_0001_01_000002
2019-06-07 07:52:12,301 DEBUG org.apache.hadoop.yarn.server.resourcemanager.rmcontainer.RMContainerImpl: Processing container_1559893901343_0001_01_000002 of type ACQUIRED
2019-06-07 07:52:12,301 DEBUG org.apache.hadoop.yarn.server.resourcemanager.rmcontainer.RMContainerImpl: Processing container_1559893901343_0001_01_000002 of type ACQUIRED
2019-06-07 07:52:12,301 INFO org.apache.hadoop.yarn.server.resourcemanager.rmcontainer.RMContainerImpl: container_1559893901343_0001_01_000002 Container Transitioned from ALLOCATED to ACQUIRED
2019-06-07 07:52:12,301 INFO org.apache.hadoop.yarn.server.resourcemanager.rmcontainer.RMContainerImpl: container_1559893901343_0001_01_000002 Container Transitioned from ALLOCATED to ACQUIRED
2019-06-07 07:52:12,301 DEBUG org.apache.hadoop.yarn.server.resourcemanager.rmapp.RMAppImpl: Processing event for application_1559893901343_0001 of type APP_RUNNING_ON_NODE
2019-06-07 07:52:12,301 DEBUG org.apache.hadoop.yarn.server.resourcemanager.rmapp.RMAppImpl: Processing event for application_1559893901343_0001 of type APP_RUNNING_ON_NODE
2019-06-07 07:52:12,302 INFO org.apache.hadoop.yarn.server.resourcemanager.security.NMTokenSecretManagerInRM: Sending NMToken for nodeId : slave1:39995 for container : container_1559893901343_0001_01_000003
2019-06-07 07:52:12,302 INFO org.apache.hadoop.yarn.server.resourcemanager.security.NMTokenSecretManagerInRM: Sending NMToken for nodeId : slave1:39995 for container : container_1559893901343_0001_01_000003
2019-06-07 07:52:12,303 DEBUG org.apache.hadoop.yarn.server.resourcemanager.rmcontainer.RMContainerImpl: Processing container_1559893901343_0001_01_000003 of type ACQUIRED
2019-06-07 07:52:12,303 DEBUG org.apache.hadoop.yarn.server.resourcemanager.rmcontainer.RMContainerImpl: Processing container_1559893901343_0001_01_000003 of type ACQUIRED
2019-06-07 07:52:12,303 INFO org.apache.hadoop.yarn.server.resourcemanager.rmcontainer.RMContainerImpl: container_1559893901343_0001_01_000003 Container Transitioned from ALLOCATED to ACQUIRED
2019-06-07 07:52:12,303 INFO org.apache.hadoop.yarn.server.resourcemanager.rmcontainer.RMContainerImpl: container_1559893901343_0001_01_000003 Container Transitioned from ALLOCATED to ACQUIRED
2019-06-07 07:52:12,303 DEBUG org.apache.hadoop.yarn.server.resourcemanager.rmapp.RMAppImpl: Processing event for application_1559893901343_0001 of type APP_RUNNING_ON_NODE
2019-06-07 07:52:12,303 DEBUG org.apache.hadoop.yarn.server.resourcemanager.rmapp.RMAppImpl: Processing event for application_1559893901343_0001 of type APP_RUNNING_ON_NODE
2019-06-07 07:52:12,303 DEBUG org.apache.hadoop.yarn.server.resourcemanager.scheduler.capacity.LeafQueue: User limit computation for root in queue default userLimitPercent=100 userLimitFactor=1.0 required: <memory:1024, vCores:1> consumed: <memory:7168, vCores:1> user-limit-resource: <memory:8192, vCores:1> queueCapacity: <memory:8192, vCores:1> qconsumed: <memory:7168, vCores:3> consumedRatio: 0.0 currentCapacity: <memory:8192, vCores:1> activeUsers: 0.0 clusterCapacity: <memory:8192, vCores:2> resourceByLabel: <memory:8192, vCores:2> usageratio: 0.875 Partition:  maxUserLimit=<memory:8192, vCores:1> userWeight=1.0
2019-06-07 07:52:12,303 DEBUG org.apache.hadoop.yarn.server.resourcemanager.scheduler.capacity.LeafQueue: User limit computation for root in queue default userLimitPercent=100 userLimitFactor=1.0 required: <memory:1024, vCores:1> consumed: <memory:7168, vCores:1> user-limit-resource: <memory:8192, vCores:1> queueCapacity: <memory:8192, vCores:1> qconsumed: <memory:7168, vCores:3> consumedRatio: 0.0 currentCapacity: <memory:8192, vCores:1> activeUsers: 0.0 clusterCapacity: <memory:8192, vCores:2> resourceByLabel: <memory:8192, vCores:2> usageratio: 0.875 Partition:  maxUserLimit=<memory:8192, vCores:1> userWeight=1.0
2019-06-07 07:52:13,168 DEBUG org.apache.hadoop.yarn.server.resourcemanager.rmnode.RMNodeImpl: Processing slave2:38494 of type STATUS_UPDATE
2019-06-07 07:52:13,168 DEBUG org.apache.hadoop.yarn.server.resourcemanager.rmnode.RMNodeImpl: Processing slave2:38494 of type STATUS_UPDATE
2019-06-07 07:52:13,168 DEBUG org.apache.hadoop.yarn.server.resourcemanager.rmnode.RMNodeImpl: Container container_1559893901343_0001_01_000002 is the first container get launched for application application_1559893901343_0001
2019-06-07 07:52:13,168 DEBUG org.apache.hadoop.yarn.server.resourcemanager.rmnode.RMNodeImpl: Container container_1559893901343_0001_01_000002 is the first container get launched for application application_1559893901343_0001
2019-06-07 07:52:13,168 DEBUG org.apache.hadoop.yarn.server.resourcemanager.rmapp.RMAppImpl: Processing event for application_1559893901343_0001 of type APP_RUNNING_ON_NODE
2019-06-07 07:52:13,168 DEBUG org.apache.hadoop.yarn.server.resourcemanager.rmapp.RMAppImpl: Processing event for application_1559893901343_0001 of type APP_RUNNING_ON_NODE
2019-06-07 07:52:13,170 DEBUG org.apache.hadoop.yarn.server.resourcemanager.scheduler.capacity.CapacityScheduler: nodeUpdate: slave2:38494 clusterResources: <memory:8192, vCores:2>
2019-06-07 07:52:13,170 DEBUG org.apache.hadoop.yarn.server.resourcemanager.scheduler.capacity.CapacityScheduler: nodeUpdate: slave2:38494 clusterResources: <memory:8192, vCores:2>
2019-06-07 07:52:13,176 DEBUG org.apache.hadoop.yarn.server.resourcemanager.rmcontainer.RMContainerImpl: Processing container_1559893901343_0001_01_000002 of type LAUNCHED
2019-06-07 07:52:13,176 DEBUG org.apache.hadoop.yarn.server.resourcemanager.rmcontainer.RMContainerImpl: Processing container_1559893901343_0001_01_000002 of type LAUNCHED
2019-06-07 07:52:13,176 INFO org.apache.hadoop.yarn.server.resourcemanager.rmcontainer.RMContainerImpl: container_1559893901343_0001_01_000002 Container Transitioned from ACQUIRED to RUNNING
2019-06-07 07:52:13,176 INFO org.apache.hadoop.yarn.server.resourcemanager.rmcontainer.RMContainerImpl: container_1559893901343_0001_01_000002 Container Transitioned from ACQUIRED to RUNNING
2019-06-07 07:52:13,176 DEBUG org.apache.hadoop.yarn.server.resourcemanager.scheduler.capacity.CapacityScheduler: Node being looked for scheduling slave2:38494 availableResource: <memory:1024, vCores:0>
2019-06-07 07:52:13,176 DEBUG org.apache.hadoop.yarn.server.resourcemanager.scheduler.capacity.CapacityScheduler: Node being looked for scheduling slave2:38494 availableResource: <memory:1024, vCores:0>
2019-06-07 07:52:13,176 DEBUG org.apache.hadoop.yarn.server.resourcemanager.scheduler.capacity.CapacityScheduler: Trying to schedule on node: slave2, available: <memory:1024, vCores:0>
2019-06-07 07:52:13,176 DEBUG org.apache.hadoop.yarn.server.resourcemanager.scheduler.capacity.CapacityScheduler: Trying to schedule on node: slave2, available: <memory:1024, vCores:0>
2019-06-07 07:52:13,176 DEBUG org.apache.hadoop.yarn.server.resourcemanager.scheduler.capacity.ParentQueue: Skip this queue=root, because it doesn't need more resource, schedulingMode=RESPECT_PARTITION_EXCLUSIVITY node-partition=
2019-06-07 07:52:13,176 DEBUG org.apache.hadoop.yarn.server.resourcemanager.scheduler.capacity.ParentQueue: Skip this queue=root, because it doesn't need more resource, schedulingMode=RESPECT_PARTITION_EXCLUSIVITY node-partition=
2019-06-07 07:52:13,184 DEBUG org.apache.hadoop.yarn.server.resourcemanager.rmnode.RMNodeImpl: Processing slave1:39995 of type STATUS_UPDATE
2019-06-07 07:52:13,184 DEBUG org.apache.hadoop.yarn.server.resourcemanager.rmnode.RMNodeImpl: Processing slave1:39995 of type STATUS_UPDATE
2019-06-07 07:52:13,184 DEBUG org.apache.hadoop.yarn.server.resourcemanager.scheduler.capacity.CapacityScheduler: nodeUpdate: slave1:39995 clusterResources: <memory:8192, vCores:2>
2019-06-07 07:52:13,184 DEBUG org.apache.hadoop.yarn.server.resourcemanager.scheduler.capacity.CapacityScheduler: nodeUpdate: slave1:39995 clusterResources: <memory:8192, vCores:2>
2019-06-07 07:52:13,185 DEBUG org.apache.hadoop.yarn.server.resourcemanager.rmcontainer.RMContainerImpl: Processing container_1559893901343_0001_01_000003 of type LAUNCHED
2019-06-07 07:52:13,185 DEBUG org.apache.hadoop.yarn.server.resourcemanager.rmcontainer.RMContainerImpl: Processing container_1559893901343_0001_01_000003 of type LAUNCHED
2019-06-07 07:52:13,185 INFO org.apache.hadoop.yarn.server.resourcemanager.rmcontainer.RMContainerImpl: container_1559893901343_0001_01_000003 Container Transitioned from ACQUIRED to RUNNING
2019-06-07 07:52:13,185 INFO org.apache.hadoop.yarn.server.resourcemanager.rmcontainer.RMContainerImpl: container_1559893901343_0001_01_000003 Container Transitioned from ACQUIRED to RUNNING
2019-06-07 07:52:13,185 DEBUG org.apache.hadoop.yarn.server.resourcemanager.scheduler.capacity.CapacityScheduler: Node being looked for scheduling slave1:39995 availableResource: <memory:0, vCores:-1>
2019-06-07 07:52:13,185 DEBUG org.apache.hadoop.yarn.server.resourcemanager.scheduler.capacity.CapacityScheduler: Node being looked for scheduling slave1:39995 availableResource: <memory:0, vCores:-1>
2019-06-07 07:52:14,183 DEBUG org.apache.hadoop.yarn.server.resourcemanager.rmnode.RMNodeImpl: Processing slave2:38494 of type STATUS_UPDATE
2019-06-07 07:52:14,183 DEBUG org.apache.hadoop.yarn.server.resourcemanager.rmnode.RMNodeImpl: Processing slave2:38494 of type STATUS_UPDATE
2019-06-07 07:52:14,184 DEBUG org.apache.hadoop.yarn.server.resourcemanager.scheduler.capacity.CapacityScheduler: nodeUpdate: slave2:38494 clusterResources: <memory:8192, vCores:2>
2019-06-07 07:52:14,184 DEBUG org.apache.hadoop.yarn.server.resourcemanager.scheduler.capacity.CapacityScheduler: nodeUpdate: slave2:38494 clusterResources: <memory:8192, vCores:2>
2019-06-07 07:52:14,184 DEBUG org.apache.hadoop.yarn.server.resourcemanager.scheduler.capacity.CapacityScheduler: Node being looked for scheduling slave2:38494 availableResource: <memory:1024, vCores:0>
2019-06-07 07:52:14,184 DEBUG org.apache.hadoop.yarn.server.resourcemanager.scheduler.capacity.CapacityScheduler: Node being looked for scheduling slave2:38494 availableResource: <memory:1024, vCores:0>
2019-06-07 07:52:14,184 DEBUG org.apache.hadoop.yarn.server.resourcemanager.scheduler.capacity.CapacityScheduler: Trying to schedule on node: slave2, available: <memory:1024, vCores:0>
2019-06-07 07:52:14,184 DEBUG org.apache.hadoop.yarn.server.resourcemanager.scheduler.capacity.CapacityScheduler: Trying to schedule on node: slave2, available: <memory:1024, vCores:0>
2019-06-07 07:52:14,184 DEBUG org.apache.hadoop.yarn.server.resourcemanager.scheduler.capacity.ParentQueue: Skip this queue=root, because it doesn't need more resource, schedulingMode=RESPECT_PARTITION_EXCLUSIVITY node-partition=
2019-06-07 07:52:14,184 DEBUG org.apache.hadoop.yarn.server.resourcemanager.scheduler.capacity.ParentQueue: Skip this queue=root, because it doesn't need more resource, schedulingMode=RESPECT_PARTITION_EXCLUSIVITY node-partition=
2019-06-07 07:52:14,204 DEBUG org.apache.hadoop.yarn.server.resourcemanager.rmnode.RMNodeImpl: Processing slave1:39995 of type STATUS_UPDATE
2019-06-07 07:52:14,204 DEBUG org.apache.hadoop.yarn.server.resourcemanager.rmnode.RMNodeImpl: Processing slave1:39995 of type STATUS_UPDATE
2019-06-07 07:52:14,204 DEBUG org.apache.hadoop.yarn.server.resourcemanager.scheduler.capacity.CapacityScheduler: nodeUpdate: slave1:39995 clusterResources: <memory:8192, vCores:2>
2019-06-07 07:52:14,204 DEBUG org.apache.hadoop.yarn.server.resourcemanager.scheduler.capacity.CapacityScheduler: nodeUpdate: slave1:39995 clusterResources: <memory:8192, vCores:2>
2019-06-07 07:52:14,204 DEBUG org.apache.hadoop.yarn.server.resourcemanager.scheduler.capacity.CapacityScheduler: Node being looked for scheduling slave1:39995 availableResource: <memory:0, vCores:-1>
2019-06-07 07:52:14,204 DEBUG org.apache.hadoop.yarn.server.resourcemanager.scheduler.capacity.CapacityScheduler: Node being looked for scheduling slave1:39995 availableResource: <memory:0, vCores:-1>
2019-06-07 07:52:15,194 DEBUG org.apache.hadoop.yarn.server.resourcemanager.rmnode.RMNodeImpl: Processing slave2:38494 of type STATUS_UPDATE
2019-06-07 07:52:15,194 DEBUG org.apache.hadoop.yarn.server.resourcemanager.rmnode.RMNodeImpl: Processing slave2:38494 of type STATUS_UPDATE
2019-06-07 07:52:15,194 DEBUG org.apache.hadoop.yarn.server.resourcemanager.scheduler.capacity.CapacityScheduler: nodeUpdate: slave2:38494 clusterResources: <memory:8192, vCores:2>
2019-06-07 07:52:15,194 DEBUG org.apache.hadoop.yarn.server.resourcemanager.scheduler.capacity.CapacityScheduler: nodeUpdate: slave2:38494 clusterResources: <memory:8192, vCores:2>
2019-06-07 07:52:15,194 DEBUG org.apache.hadoop.yarn.server.resourcemanager.scheduler.capacity.CapacityScheduler: Node being looked for scheduling slave2:38494 availableResource: <memory:1024, vCores:0>
2019-06-07 07:52:15,194 DEBUG org.apache.hadoop.yarn.server.resourcemanager.scheduler.capacity.CapacityScheduler: Node being looked for scheduling slave2:38494 availableResource: <memory:1024, vCores:0>
2019-06-07 07:52:15,194 DEBUG org.apache.hadoop.yarn.server.resourcemanager.scheduler.capacity.CapacityScheduler: Trying to schedule on node: slave2, available: <memory:1024, vCores:0>
2019-06-07 07:52:15,194 DEBUG org.apache.hadoop.yarn.server.resourcemanager.scheduler.capacity.CapacityScheduler: Trying to schedule on node: slave2, available: <memory:1024, vCores:0>
2019-06-07 07:52:15,195 DEBUG org.apache.hadoop.yarn.server.resourcemanager.scheduler.capacity.ParentQueue: Skip this queue=root, because it doesn't need more resource, schedulingMode=RESPECT_PARTITION_EXCLUSIVITY node-partition=
2019-06-07 07:52:15,195 DEBUG org.apache.hadoop.yarn.server.resourcemanager.scheduler.capacity.ParentQueue: Skip this queue=root, because it doesn't need more resource, schedulingMode=RESPECT_PARTITION_EXCLUSIVITY node-partition=
2019-06-07 07:52:15,214 DEBUG org.apache.hadoop.yarn.server.resourcemanager.rmnode.RMNodeImpl: Processing slave1:39995 of type STATUS_UPDATE
2019-06-07 07:52:15,214 DEBUG org.apache.hadoop.yarn.server.resourcemanager.rmnode.RMNodeImpl: Processing slave1:39995 of type STATUS_UPDATE
2019-06-07 07:52:15,214 DEBUG org.apache.hadoop.yarn.server.resourcemanager.scheduler.capacity.CapacityScheduler: nodeUpdate: slave1:39995 clusterResources: <memory:8192, vCores:2>
2019-06-07 07:52:15,214 DEBUG org.apache.hadoop.yarn.server.resourcemanager.scheduler.capacity.CapacityScheduler: nodeUpdate: slave1:39995 clusterResources: <memory:8192, vCores:2>
2019-06-07 07:52:15,214 DEBUG org.apache.hadoop.yarn.server.resourcemanager.scheduler.capacity.CapacityScheduler: Node being looked for scheduling slave1:39995 availableResource: <memory:0, vCores:-1>
2019-06-07 07:52:15,214 DEBUG org.apache.hadoop.yarn.server.resourcemanager.scheduler.capacity.CapacityScheduler: Node being looked for scheduling slave1:39995 availableResource: <memory:0, vCores:-1>
2019-06-07 07:52:15,342 DEBUG org.apache.hadoop.yarn.server.resourcemanager.rmapp.attempt.RMAppAttemptImpl: Processing event for appattempt_1559893901343_0001_000001 of type STATUS_UPDATE
2019-06-07 07:52:15,342 DEBUG org.apache.hadoop.yarn.server.resourcemanager.rmapp.attempt.RMAppAttemptImpl: Processing event for appattempt_1559893901343_0001_000001 of type STATUS_UPDATE
2019-06-07 07:52:15,342 DEBUG org.apache.hadoop.yarn.server.resourcemanager.scheduler.capacity.CapacityScheduler: allocate: pre-update appattempt_1559893901343_0001_000001 ask size =1
2019-06-07 07:52:15,342 DEBUG org.apache.hadoop.yarn.server.resourcemanager.scheduler.capacity.CapacityScheduler: allocate: pre-update appattempt_1559893901343_0001_000001 ask size =1
2019-06-07 07:52:15,342 INFO org.apache.hadoop.yarn.server.resourcemanager.scheduler.AppSchedulingInfo: checking for deactivate of application :application_1559893901343_0001
2019-06-07 07:52:15,342 INFO org.apache.hadoop.yarn.server.resourcemanager.scheduler.AppSchedulingInfo: checking for deactivate of application :application_1559893901343_0001
2019-06-07 07:52:15,342 DEBUG org.apache.hadoop.yarn.server.resourcemanager.scheduler.capacity.CapacityScheduler: allocate: post-update
2019-06-07 07:52:15,342 DEBUG org.apache.hadoop.yarn.server.resourcemanager.scheduler.capacity.CapacityScheduler: allocate: post-update
2019-06-07 07:52:15,343 DEBUG org.apache.hadoop.yarn.server.resourcemanager.scheduler.capacity.LeafQueue: User limit computation for root in queue default userLimitPercent=100 userLimitFactor=1.0 required: <memory:1024, vCores:1> consumed: <memory:7168, vCores:1> user-limit-resource: <memory:8192, vCores:1> queueCapacity: <memory:8192, vCores:1> qconsumed: <memory:7168, vCores:3> consumedRatio: 0.0 currentCapacity: <memory:8192, vCores:1> activeUsers: 0.0 clusterCapacity: <memory:8192, vCores:2> resourceByLabel: <memory:8192, vCores:2> usageratio: 0.875 Partition:  maxUserLimit=<memory:8192, vCores:1> userWeight=1.0
2019-06-07 07:52:15,343 DEBUG org.apache.hadoop.yarn.server.resourcemanager.scheduler.capacity.LeafQueue: User limit computation for root in queue default userLimitPercent=100 userLimitFactor=1.0 required: <memory:1024, vCores:1> consumed: <memory:7168, vCores:1> user-limit-resource: <memory:8192, vCores:1> queueCapacity: <memory:8192, vCores:1> qconsumed: <memory:7168, vCores:3> consumedRatio: 0.0 currentCapacity: <memory:8192, vCores:1> activeUsers: 0.0 clusterCapacity: <memory:8192, vCores:2> resourceByLabel: <memory:8192, vCores:2> usageratio: 0.875 Partition:  maxUserLimit=<memory:8192, vCores:1> userWeight=1.0
2019-06-07 07:52:16,198 DEBUG org.apache.hadoop.yarn.server.resourcemanager.rmnode.RMNodeImpl: Processing slave2:38494 of type STATUS_UPDATE
2019-06-07 07:52:16,198 DEBUG org.apache.hadoop.yarn.server.resourcemanager.rmnode.RMNodeImpl: Processing slave2:38494 of type STATUS_UPDATE
2019-06-07 07:52:16,199 DEBUG org.apache.hadoop.yarn.server.resourcemanager.scheduler.capacity.CapacityScheduler: nodeUpdate: slave2:38494 clusterResources: <memory:8192, vCores:2>
2019-06-07 07:52:16,199 DEBUG org.apache.hadoop.yarn.server.resourcemanager.scheduler.capacity.CapacityScheduler: nodeUpdate: slave2:38494 clusterResources: <memory:8192, vCores:2>
2019-06-07 07:52:16,199 DEBUG org.apache.hadoop.yarn.server.resourcemanager.scheduler.capacity.CapacityScheduler: Node being looked for scheduling slave2:38494 availableResource: <memory:1024, vCores:0>
2019-06-07 07:52:16,199 DEBUG org.apache.hadoop.yarn.server.resourcemanager.scheduler.capacity.CapacityScheduler: Node being looked for scheduling slave2:38494 availableResource: <memory:1024, vCores:0>
2019-06-07 07:52:16,199 DEBUG org.apache.hadoop.yarn.server.resourcemanager.scheduler.capacity.CapacityScheduler: Trying to schedule on node: slave2, available: <memory:1024, vCores:0>
2019-06-07 07:52:16,199 DEBUG org.apache.hadoop.yarn.server.resourcemanager.scheduler.capacity.CapacityScheduler: Trying to schedule on node: slave2, available: <memory:1024, vCores:0>
2019-06-07 07:52:16,199 DEBUG org.apache.hadoop.yarn.server.resourcemanager.scheduler.capacity.ParentQueue: Skip this queue=root, because it doesn't need more resource, schedulingMode=RESPECT_PARTITION_EXCLUSIVITY node-partition=
2019-06-07 07:52:16,199 DEBUG org.apache.hadoop.yarn.server.resourcemanager.scheduler.capacity.ParentQueue: Skip this queue=root, because it doesn't need more resource, schedulingMode=RESPECT_PARTITION_EXCLUSIVITY node-partition=
2019-06-07 07:52:16,227 DEBUG org.apache.hadoop.yarn.server.resourcemanager.rmnode.RMNodeImpl: Processing slave1:39995 of type STATUS_UPDATE
2019-06-07 07:52:16,227 DEBUG org.apache.hadoop.yarn.server.resourcemanager.rmnode.RMNodeImpl: Processing slave1:39995 of type STATUS_UPDATE
2019-06-07 07:52:16,227 DEBUG org.apache.hadoop.yarn.server.resourcemanager.scheduler.capacity.CapacityScheduler: nodeUpdate: slave1:39995 clusterResources: <memory:8192, vCores:2>
2019-06-07 07:52:16,227 DEBUG org.apache.hadoop.yarn.server.resourcemanager.scheduler.capacity.CapacityScheduler: nodeUpdate: slave1:39995 clusterResources: <memory:8192, vCores:2>
2019-06-07 07:52:16,227 DEBUG org.apache.hadoop.yarn.server.resourcemanager.scheduler.capacity.CapacityScheduler: Node being looked for scheduling slave1:39995 availableResource: <memory:0, vCores:-1>
2019-06-07 07:52:16,227 DEBUG org.apache.hadoop.yarn.server.resourcemanager.scheduler.capacity.CapacityScheduler: Node being looked for scheduling slave1:39995 availableResource: <memory:0, vCores:-1>
2019-06-07 07:52:17,210 DEBUG org.apache.hadoop.yarn.server.resourcemanager.rmnode.RMNodeImpl: Processing slave2:38494 of type STATUS_UPDATE
2019-06-07 07:52:17,210 DEBUG org.apache.hadoop.yarn.server.resourcemanager.rmnode.RMNodeImpl: Processing slave2:38494 of type STATUS_UPDATE
2019-06-07 07:52:17,210 DEBUG org.apache.hadoop.yarn.server.resourcemanager.scheduler.capacity.CapacityScheduler: nodeUpdate: slave2:38494 clusterResources: <memory:8192, vCores:2>
2019-06-07 07:52:17,210 DEBUG org.apache.hadoop.yarn.server.resourcemanager.scheduler.capacity.CapacityScheduler: nodeUpdate: slave2:38494 clusterResources: <memory:8192, vCores:2>
2019-06-07 07:52:17,210 DEBUG org.apache.hadoop.yarn.server.resourcemanager.scheduler.capacity.CapacityScheduler: Node being looked for scheduling slave2:38494 availableResource: <memory:1024, vCores:0>
2019-06-07 07:52:17,210 DEBUG org.apache.hadoop.yarn.server.resourcemanager.scheduler.capacity.CapacityScheduler: Node being looked for scheduling slave2:38494 availableResource: <memory:1024, vCores:0>
2019-06-07 07:52:17,210 DEBUG org.apache.hadoop.yarn.server.resourcemanager.scheduler.capacity.CapacityScheduler: Trying to schedule on node: slave2, available: <memory:1024, vCores:0>
2019-06-07 07:52:17,210 DEBUG org.apache.hadoop.yarn.server.resourcemanager.scheduler.capacity.CapacityScheduler: Trying to schedule on node: slave2, available: <memory:1024, vCores:0>
2019-06-07 07:52:17,210 DEBUG org.apache.hadoop.yarn.server.resourcemanager.scheduler.capacity.ParentQueue: Skip this queue=root, because it doesn't need more resource, schedulingMode=RESPECT_PARTITION_EXCLUSIVITY node-partition=
2019-06-07 07:52:17,210 DEBUG org.apache.hadoop.yarn.server.resourcemanager.scheduler.capacity.ParentQueue: Skip this queue=root, because it doesn't need more resource, schedulingMode=RESPECT_PARTITION_EXCLUSIVITY node-partition=
2019-06-07 07:52:17,253 DEBUG org.apache.hadoop.yarn.server.resourcemanager.rmnode.RMNodeImpl: Processing slave1:39995 of type STATUS_UPDATE
2019-06-07 07:52:17,253 DEBUG org.apache.hadoop.yarn.server.resourcemanager.rmnode.RMNodeImpl: Processing slave1:39995 of type STATUS_UPDATE
2019-06-07 07:52:17,253 DEBUG org.apache.hadoop.yarn.server.resourcemanager.scheduler.capacity.CapacityScheduler: nodeUpdate: slave1:39995 clusterResources: <memory:8192, vCores:2>
2019-06-07 07:52:17,253 DEBUG org.apache.hadoop.yarn.server.resourcemanager.scheduler.capacity.CapacityScheduler: nodeUpdate: slave1:39995 clusterResources: <memory:8192, vCores:2>
2019-06-07 07:52:17,253 DEBUG org.apache.hadoop.yarn.server.resourcemanager.scheduler.capacity.CapacityScheduler: Node being looked for scheduling slave1:39995 availableResource: <memory:0, vCores:-1>
2019-06-07 07:52:17,253 DEBUG org.apache.hadoop.yarn.server.resourcemanager.scheduler.capacity.CapacityScheduler: Node being looked for scheduling slave1:39995 availableResource: <memory:0, vCores:-1>
2019-06-07 07:52:18,213 DEBUG org.apache.hadoop.yarn.server.resourcemanager.rmnode.RMNodeImpl: Processing slave2:38494 of type STATUS_UPDATE
2019-06-07 07:52:18,213 DEBUG org.apache.hadoop.yarn.server.resourcemanager.rmnode.RMNodeImpl: Processing slave2:38494 of type STATUS_UPDATE
2019-06-07 07:52:18,213 DEBUG org.apache.hadoop.yarn.server.resourcemanager.scheduler.capacity.CapacityScheduler: nodeUpdate: slave2:38494 clusterResources: <memory:8192, vCores:2>
2019-06-07 07:52:18,213 DEBUG org.apache.hadoop.yarn.server.resourcemanager.scheduler.capacity.CapacityScheduler: nodeUpdate: slave2:38494 clusterResources: <memory:8192, vCores:2>
2019-06-07 07:52:18,213 DEBUG org.apache.hadoop.yarn.server.resourcemanager.scheduler.capacity.CapacityScheduler: Node being looked for scheduling slave2:38494 availableResource: <memory:1024, vCores:0>
2019-06-07 07:52:18,213 DEBUG org.apache.hadoop.yarn.server.resourcemanager.scheduler.capacity.CapacityScheduler: Node being looked for scheduling slave2:38494 availableResource: <memory:1024, vCores:0>
2019-06-07 07:52:18,213 DEBUG org.apache.hadoop.yarn.server.resourcemanager.scheduler.capacity.CapacityScheduler: Trying to schedule on node: slave2, available: <memory:1024, vCores:0>
2019-06-07 07:52:18,213 DEBUG org.apache.hadoop.yarn.server.resourcemanager.scheduler.capacity.CapacityScheduler: Trying to schedule on node: slave2, available: <memory:1024, vCores:0>
2019-06-07 07:52:18,213 DEBUG org.apache.hadoop.yarn.server.resourcemanager.scheduler.capacity.ParentQueue: Skip this queue=root, because it doesn't need more resource, schedulingMode=RESPECT_PARTITION_EXCLUSIVITY node-partition=
2019-06-07 07:52:18,213 DEBUG org.apache.hadoop.yarn.server.resourcemanager.scheduler.capacity.ParentQueue: Skip this queue=root, because it doesn't need more resource, schedulingMode=RESPECT_PARTITION_EXCLUSIVITY node-partition=
2019-06-07 07:52:18,255 DEBUG org.apache.hadoop.yarn.server.resourcemanager.rmnode.RMNodeImpl: Processing slave1:39995 of type STATUS_UPDATE
2019-06-07 07:52:18,255 DEBUG org.apache.hadoop.yarn.server.resourcemanager.rmnode.RMNodeImpl: Processing slave1:39995 of type STATUS_UPDATE
2019-06-07 07:52:18,256 DEBUG org.apache.hadoop.yarn.server.resourcemanager.scheduler.capacity.CapacityScheduler: nodeUpdate: slave1:39995 clusterResources: <memory:8192, vCores:2>
2019-06-07 07:52:18,256 DEBUG org.apache.hadoop.yarn.server.resourcemanager.scheduler.capacity.CapacityScheduler: nodeUpdate: slave1:39995 clusterResources: <memory:8192, vCores:2>
2019-06-07 07:52:18,256 DEBUG org.apache.hadoop.yarn.server.resourcemanager.scheduler.capacity.CapacityScheduler: Node being looked for scheduling slave1:39995 availableResource: <memory:0, vCores:-1>
2019-06-07 07:52:18,256 DEBUG org.apache.hadoop.yarn.server.resourcemanager.scheduler.capacity.CapacityScheduler: Node being looked for scheduling slave1:39995 availableResource: <memory:0, vCores:-1>
2019-06-07 07:52:18,346 DEBUG org.apache.hadoop.yarn.server.resourcemanager.rmapp.attempt.RMAppAttemptImpl: Processing event for appattempt_1559893901343_0001_000001 of type STATUS_UPDATE
2019-06-07 07:52:18,346 DEBUG org.apache.hadoop.yarn.server.resourcemanager.rmapp.attempt.RMAppAttemptImpl: Processing event for appattempt_1559893901343_0001_000001 of type STATUS_UPDATE
2019-06-07 07:52:18,346 DEBUG org.apache.hadoop.yarn.server.resourcemanager.scheduler.capacity.LeafQueue: User limit computation for root in queue default userLimitPercent=100 userLimitFactor=1.0 required: <memory:1024, vCores:1> consumed: <memory:7168, vCores:1> user-limit-resource: <memory:8192, vCores:1> queueCapacity: <memory:8192, vCores:1> qconsumed: <memory:7168, vCores:3> consumedRatio: 0.0 currentCapacity: <memory:8192, vCores:1> activeUsers: 0.0 clusterCapacity: <memory:8192, vCores:2> resourceByLabel: <memory:8192, vCores:2> usageratio: 0.875 Partition:  maxUserLimit=<memory:8192, vCores:1> userWeight=1.0
2019-06-07 07:52:18,346 DEBUG org.apache.hadoop.yarn.server.resourcemanager.scheduler.capacity.LeafQueue: User limit computation for root in queue default userLimitPercent=100 userLimitFactor=1.0 required: <memory:1024, vCores:1> consumed: <memory:7168, vCores:1> user-limit-resource: <memory:8192, vCores:1> queueCapacity: <memory:8192, vCores:1> qconsumed: <memory:7168, vCores:3> consumedRatio: 0.0 currentCapacity: <memory:8192, vCores:1> activeUsers: 0.0 clusterCapacity: <memory:8192, vCores:2> resourceByLabel: <memory:8192, vCores:2> usageratio: 0.875 Partition:  maxUserLimit=<memory:8192, vCores:1> userWeight=1.0
2019-06-07 07:52:19,225 DEBUG org.apache.hadoop.yarn.server.resourcemanager.rmnode.RMNodeImpl: Processing slave2:38494 of type STATUS_UPDATE
2019-06-07 07:52:19,225 DEBUG org.apache.hadoop.yarn.server.resourcemanager.rmnode.RMNodeImpl: Processing slave2:38494 of type STATUS_UPDATE
2019-06-07 07:52:19,226 DEBUG org.apache.hadoop.yarn.server.resourcemanager.scheduler.capacity.CapacityScheduler: nodeUpdate: slave2:38494 clusterResources: <memory:8192, vCores:2>
2019-06-07 07:52:19,226 DEBUG org.apache.hadoop.yarn.server.resourcemanager.scheduler.capacity.CapacityScheduler: nodeUpdate: slave2:38494 clusterResources: <memory:8192, vCores:2>
2019-06-07 07:52:19,226 DEBUG org.apache.hadoop.yarn.server.resourcemanager.scheduler.capacity.CapacityScheduler: Node being looked for scheduling slave2:38494 availableResource: <memory:1024, vCores:0>
2019-06-07 07:52:19,226 DEBUG org.apache.hadoop.yarn.server.resourcemanager.scheduler.capacity.CapacityScheduler: Node being looked for scheduling slave2:38494 availableResource: <memory:1024, vCores:0>
2019-06-07 07:52:19,226 DEBUG org.apache.hadoop.yarn.server.resourcemanager.scheduler.capacity.CapacityScheduler: Trying to schedule on node: slave2, available: <memory:1024, vCores:0>
2019-06-07 07:52:19,226 DEBUG org.apache.hadoop.yarn.server.resourcemanager.scheduler.capacity.CapacityScheduler: Trying to schedule on node: slave2, available: <memory:1024, vCores:0>
2019-06-07 07:52:19,226 DEBUG org.apache.hadoop.yarn.server.resourcemanager.scheduler.capacity.ParentQueue: Skip this queue=root, because it doesn't need more resource, schedulingMode=RESPECT_PARTITION_EXCLUSIVITY node-partition=
2019-06-07 07:52:19,226 DEBUG org.apache.hadoop.yarn.server.resourcemanager.scheduler.capacity.ParentQueue: Skip this queue=root, because it doesn't need more resource, schedulingMode=RESPECT_PARTITION_EXCLUSIVITY node-partition=
2019-06-07 07:52:19,264 DEBUG org.apache.hadoop.yarn.server.resourcemanager.rmnode.RMNodeImpl: Processing slave1:39995 of type STATUS_UPDATE
2019-06-07 07:52:19,264 DEBUG org.apache.hadoop.yarn.server.resourcemanager.rmnode.RMNodeImpl: Processing slave1:39995 of type STATUS_UPDATE
2019-06-07 07:52:19,264 DEBUG org.apache.hadoop.yarn.server.resourcemanager.scheduler.capacity.CapacityScheduler: nodeUpdate: slave1:39995 clusterResources: <memory:8192, vCores:2>
2019-06-07 07:52:19,264 DEBUG org.apache.hadoop.yarn.server.resourcemanager.scheduler.capacity.CapacityScheduler: nodeUpdate: slave1:39995 clusterResources: <memory:8192, vCores:2>
2019-06-07 07:52:19,264 DEBUG org.apache.hadoop.yarn.server.resourcemanager.scheduler.capacity.CapacityScheduler: Node being looked for scheduling slave1:39995 availableResource: <memory:0, vCores:-1>
2019-06-07 07:52:19,264 DEBUG org.apache.hadoop.yarn.server.resourcemanager.scheduler.capacity.CapacityScheduler: Node being looked for scheduling slave1:39995 availableResource: <memory:0, vCores:-1>
2019-06-07 07:52:20,230 DEBUG org.apache.hadoop.yarn.server.resourcemanager.rmnode.RMNodeImpl: Processing slave2:38494 of type STATUS_UPDATE
2019-06-07 07:52:20,230 DEBUG org.apache.hadoop.yarn.server.resourcemanager.rmnode.RMNodeImpl: Processing slave2:38494 of type STATUS_UPDATE
2019-06-07 07:52:20,230 DEBUG org.apache.hadoop.yarn.server.resourcemanager.scheduler.capacity.CapacityScheduler: nodeUpdate: slave2:38494 clusterResources: <memory:8192, vCores:2>
2019-06-07 07:52:20,230 DEBUG org.apache.hadoop.yarn.server.resourcemanager.scheduler.capacity.CapacityScheduler: nodeUpdate: slave2:38494 clusterResources: <memory:8192, vCores:2>
2019-06-07 07:52:20,230 DEBUG org.apache.hadoop.yarn.server.resourcemanager.scheduler.capacity.CapacityScheduler: Node being looked for scheduling slave2:38494 availableResource: <memory:1024, vCores:0>
2019-06-07 07:52:20,230 DEBUG org.apache.hadoop.yarn.server.resourcemanager.scheduler.capacity.CapacityScheduler: Node being looked for scheduling slave2:38494 availableResource: <memory:1024, vCores:0>
2019-06-07 07:52:20,230 DEBUG org.apache.hadoop.yarn.server.resourcemanager.scheduler.capacity.CapacityScheduler: Trying to schedule on node: slave2, available: <memory:1024, vCores:0>
2019-06-07 07:52:20,230 DEBUG org.apache.hadoop.yarn.server.resourcemanager.scheduler.capacity.CapacityScheduler: Trying to schedule on node: slave2, available: <memory:1024, vCores:0>
2019-06-07 07:52:20,231 DEBUG org.apache.hadoop.yarn.server.resourcemanager.scheduler.capacity.ParentQueue: Skip this queue=root, because it doesn't need more resource, schedulingMode=RESPECT_PARTITION_EXCLUSIVITY node-partition=
2019-06-07 07:52:20,231 DEBUG org.apache.hadoop.yarn.server.resourcemanager.scheduler.capacity.ParentQueue: Skip this queue=root, because it doesn't need more resource, schedulingMode=RESPECT_PARTITION_EXCLUSIVITY node-partition=
2019-06-07 07:52:20,270 DEBUG org.apache.hadoop.yarn.server.resourcemanager.rmnode.RMNodeImpl: Processing slave1:39995 of type STATUS_UPDATE
2019-06-07 07:52:20,270 DEBUG org.apache.hadoop.yarn.server.resourcemanager.rmnode.RMNodeImpl: Processing slave1:39995 of type STATUS_UPDATE
2019-06-07 07:52:20,271 DEBUG org.apache.hadoop.yarn.server.resourcemanager.scheduler.capacity.CapacityScheduler: nodeUpdate: slave1:39995 clusterResources: <memory:8192, vCores:2>
2019-06-07 07:52:20,271 DEBUG org.apache.hadoop.yarn.server.resourcemanager.scheduler.capacity.CapacityScheduler: nodeUpdate: slave1:39995 clusterResources: <memory:8192, vCores:2>
2019-06-07 07:52:20,271 DEBUG org.apache.hadoop.yarn.server.resourcemanager.scheduler.capacity.CapacityScheduler: Node being looked for scheduling slave1:39995 availableResource: <memory:0, vCores:-1>
2019-06-07 07:52:20,271 DEBUG org.apache.hadoop.yarn.server.resourcemanager.scheduler.capacity.CapacityScheduler: Node being looked for scheduling slave1:39995 availableResource: <memory:0, vCores:-1>
2019-06-07 07:52:21,236 DEBUG org.apache.hadoop.yarn.server.resourcemanager.rmnode.RMNodeImpl: Processing slave2:38494 of type STATUS_UPDATE
2019-06-07 07:52:21,236 DEBUG org.apache.hadoop.yarn.server.resourcemanager.rmnode.RMNodeImpl: Processing slave2:38494 of type STATUS_UPDATE
2019-06-07 07:52:21,236 DEBUG org.apache.hadoop.yarn.server.resourcemanager.scheduler.capacity.CapacityScheduler: nodeUpdate: slave2:38494 clusterResources: <memory:8192, vCores:2>
2019-06-07 07:52:21,236 DEBUG org.apache.hadoop.yarn.server.resourcemanager.scheduler.capacity.CapacityScheduler: nodeUpdate: slave2:38494 clusterResources: <memory:8192, vCores:2>
2019-06-07 07:52:21,236 DEBUG org.apache.hadoop.yarn.server.resourcemanager.scheduler.capacity.CapacityScheduler: Node being looked for scheduling slave2:38494 availableResource: <memory:1024, vCores:0>
2019-06-07 07:52:21,236 DEBUG org.apache.hadoop.yarn.server.resourcemanager.scheduler.capacity.CapacityScheduler: Node being looked for scheduling slave2:38494 availableResource: <memory:1024, vCores:0>
2019-06-07 07:52:21,236 DEBUG org.apache.hadoop.yarn.server.resourcemanager.scheduler.capacity.CapacityScheduler: Trying to schedule on node: slave2, available: <memory:1024, vCores:0>
2019-06-07 07:52:21,236 DEBUG org.apache.hadoop.yarn.server.resourcemanager.scheduler.capacity.CapacityScheduler: Trying to schedule on node: slave2, available: <memory:1024, vCores:0>
2019-06-07 07:52:21,236 DEBUG org.apache.hadoop.yarn.server.resourcemanager.scheduler.capacity.ParentQueue: Skip this queue=root, because it doesn't need more resource, schedulingMode=RESPECT_PARTITION_EXCLUSIVITY node-partition=
2019-06-07 07:52:21,236 DEBUG org.apache.hadoop.yarn.server.resourcemanager.scheduler.capacity.ParentQueue: Skip this queue=root, because it doesn't need more resource, schedulingMode=RESPECT_PARTITION_EXCLUSIVITY node-partition=
2019-06-07 07:52:21,276 DEBUG org.apache.hadoop.yarn.server.resourcemanager.rmnode.RMNodeImpl: Processing slave1:39995 of type STATUS_UPDATE
2019-06-07 07:52:21,276 DEBUG org.apache.hadoop.yarn.server.resourcemanager.rmnode.RMNodeImpl: Processing slave1:39995 of type STATUS_UPDATE
2019-06-07 07:52:21,276 DEBUG org.apache.hadoop.yarn.server.resourcemanager.scheduler.capacity.CapacityScheduler: nodeUpdate: slave1:39995 clusterResources: <memory:8192, vCores:2>
2019-06-07 07:52:21,276 DEBUG org.apache.hadoop.yarn.server.resourcemanager.scheduler.capacity.CapacityScheduler: nodeUpdate: slave1:39995 clusterResources: <memory:8192, vCores:2>
2019-06-07 07:52:21,276 DEBUG org.apache.hadoop.yarn.server.resourcemanager.scheduler.capacity.CapacityScheduler: Node being looked for scheduling slave1:39995 availableResource: <memory:0, vCores:-1>
2019-06-07 07:52:21,276 DEBUG org.apache.hadoop.yarn.server.resourcemanager.scheduler.capacity.CapacityScheduler: Node being looked for scheduling slave1:39995 availableResource: <memory:0, vCores:-1>
2019-06-07 07:52:21,352 DEBUG org.apache.hadoop.yarn.server.resourcemanager.rmapp.attempt.RMAppAttemptImpl: Processing event for appattempt_1559893901343_0001_000001 of type STATUS_UPDATE
2019-06-07 07:52:21,352 DEBUG org.apache.hadoop.yarn.server.resourcemanager.rmapp.attempt.RMAppAttemptImpl: Processing event for appattempt_1559893901343_0001_000001 of type STATUS_UPDATE
2019-06-07 07:52:21,352 DEBUG org.apache.hadoop.yarn.server.resourcemanager.scheduler.capacity.LeafQueue: User limit computation for root in queue default userLimitPercent=100 userLimitFactor=1.0 required: <memory:1024, vCores:1> consumed: <memory:7168, vCores:1> user-limit-resource: <memory:8192, vCores:1> queueCapacity: <memory:8192, vCores:1> qconsumed: <memory:7168, vCores:3> consumedRatio: 0.0 currentCapacity: <memory:8192, vCores:1> activeUsers: 0.0 clusterCapacity: <memory:8192, vCores:2> resourceByLabel: <memory:8192, vCores:2> usageratio: 0.875 Partition:  maxUserLimit=<memory:8192, vCores:1> userWeight=1.0
2019-06-07 07:52:21,352 DEBUG org.apache.hadoop.yarn.server.resourcemanager.scheduler.capacity.LeafQueue: User limit computation for root in queue default userLimitPercent=100 userLimitFactor=1.0 required: <memory:1024, vCores:1> consumed: <memory:7168, vCores:1> user-limit-resource: <memory:8192, vCores:1> queueCapacity: <memory:8192, vCores:1> qconsumed: <memory:7168, vCores:3> consumedRatio: 0.0 currentCapacity: <memory:8192, vCores:1> activeUsers: 0.0 clusterCapacity: <memory:8192, vCores:2> resourceByLabel: <memory:8192, vCores:2> usageratio: 0.875 Partition:  maxUserLimit=<memory:8192, vCores:1> userWeight=1.0
2019-06-07 07:52:22,248 DEBUG org.apache.hadoop.yarn.server.resourcemanager.rmnode.RMNodeImpl: Processing slave2:38494 of type STATUS_UPDATE
2019-06-07 07:52:22,248 DEBUG org.apache.hadoop.yarn.server.resourcemanager.rmnode.RMNodeImpl: Processing slave2:38494 of type STATUS_UPDATE
2019-06-07 07:52:22,248 DEBUG org.apache.hadoop.yarn.server.resourcemanager.scheduler.capacity.CapacityScheduler: nodeUpdate: slave2:38494 clusterResources: <memory:8192, vCores:2>
2019-06-07 07:52:22,248 DEBUG org.apache.hadoop.yarn.server.resourcemanager.scheduler.capacity.CapacityScheduler: nodeUpdate: slave2:38494 clusterResources: <memory:8192, vCores:2>
2019-06-07 07:52:22,248 DEBUG org.apache.hadoop.yarn.server.resourcemanager.scheduler.capacity.CapacityScheduler: Node being looked for scheduling slave2:38494 availableResource: <memory:1024, vCores:0>
2019-06-07 07:52:22,248 DEBUG org.apache.hadoop.yarn.server.resourcemanager.scheduler.capacity.CapacityScheduler: Node being looked for scheduling slave2:38494 availableResource: <memory:1024, vCores:0>
2019-06-07 07:52:22,248 DEBUG org.apache.hadoop.yarn.server.resourcemanager.scheduler.capacity.CapacityScheduler: Trying to schedule on node: slave2, available: <memory:1024, vCores:0>
2019-06-07 07:52:22,248 DEBUG org.apache.hadoop.yarn.server.resourcemanager.scheduler.capacity.CapacityScheduler: Trying to schedule on node: slave2, available: <memory:1024, vCores:0>
2019-06-07 07:52:22,248 DEBUG org.apache.hadoop.yarn.server.resourcemanager.scheduler.capacity.ParentQueue: Skip this queue=root, because it doesn't need more resource, schedulingMode=RESPECT_PARTITION_EXCLUSIVITY node-partition=
2019-06-07 07:52:22,248 DEBUG org.apache.hadoop.yarn.server.resourcemanager.scheduler.capacity.ParentQueue: Skip this queue=root, because it doesn't need more resource, schedulingMode=RESPECT_PARTITION_EXCLUSIVITY node-partition=
2019-06-07 07:52:22,278 DEBUG org.apache.hadoop.yarn.server.resourcemanager.rmnode.RMNodeImpl: Processing slave1:39995 of type STATUS_UPDATE
2019-06-07 07:52:22,278 DEBUG org.apache.hadoop.yarn.server.resourcemanager.rmnode.RMNodeImpl: Processing slave1:39995 of type STATUS_UPDATE
2019-06-07 07:52:22,278 DEBUG org.apache.hadoop.yarn.server.resourcemanager.scheduler.capacity.CapacityScheduler: nodeUpdate: slave1:39995 clusterResources: <memory:8192, vCores:2>
2019-06-07 07:52:22,278 DEBUG org.apache.hadoop.yarn.server.resourcemanager.scheduler.capacity.CapacityScheduler: nodeUpdate: slave1:39995 clusterResources: <memory:8192, vCores:2>
2019-06-07 07:52:22,278 DEBUG org.apache.hadoop.yarn.server.resourcemanager.scheduler.capacity.CapacityScheduler: Node being looked for scheduling slave1:39995 availableResource: <memory:0, vCores:-1>
2019-06-07 07:52:22,278 DEBUG org.apache.hadoop.yarn.server.resourcemanager.scheduler.capacity.CapacityScheduler: Node being looked for scheduling slave1:39995 availableResource: <memory:0, vCores:-1>
2019-06-07 07:52:23,271 DEBUG org.apache.hadoop.yarn.server.resourcemanager.rmnode.RMNodeImpl: Processing slave2:38494 of type STATUS_UPDATE
2019-06-07 07:52:23,271 DEBUG org.apache.hadoop.yarn.server.resourcemanager.rmnode.RMNodeImpl: Processing slave2:38494 of type STATUS_UPDATE
2019-06-07 07:52:23,272 DEBUG org.apache.hadoop.yarn.server.resourcemanager.scheduler.capacity.CapacityScheduler: nodeUpdate: slave2:38494 clusterResources: <memory:8192, vCores:2>
2019-06-07 07:52:23,272 DEBUG org.apache.hadoop.yarn.server.resourcemanager.scheduler.capacity.CapacityScheduler: nodeUpdate: slave2:38494 clusterResources: <memory:8192, vCores:2>
2019-06-07 07:52:23,272 DEBUG org.apache.hadoop.yarn.server.resourcemanager.scheduler.capacity.CapacityScheduler: Node being looked for scheduling slave2:38494 availableResource: <memory:1024, vCores:0>
2019-06-07 07:52:23,272 DEBUG org.apache.hadoop.yarn.server.resourcemanager.scheduler.capacity.CapacityScheduler: Node being looked for scheduling slave2:38494 availableResource: <memory:1024, vCores:0>
2019-06-07 07:52:23,272 DEBUG org.apache.hadoop.yarn.server.resourcemanager.scheduler.capacity.CapacityScheduler: Trying to schedule on node: slave2, available: <memory:1024, vCores:0>
2019-06-07 07:52:23,272 DEBUG org.apache.hadoop.yarn.server.resourcemanager.scheduler.capacity.CapacityScheduler: Trying to schedule on node: slave2, available: <memory:1024, vCores:0>
2019-06-07 07:52:23,272 DEBUG org.apache.hadoop.yarn.server.resourcemanager.scheduler.capacity.ParentQueue: Skip this queue=root, because it doesn't need more resource, schedulingMode=RESPECT_PARTITION_EXCLUSIVITY node-partition=
2019-06-07 07:52:23,272 DEBUG org.apache.hadoop.yarn.server.resourcemanager.scheduler.capacity.ParentQueue: Skip this queue=root, because it doesn't need more resource, schedulingMode=RESPECT_PARTITION_EXCLUSIVITY node-partition=
2019-06-07 07:52:23,282 DEBUG org.apache.hadoop.yarn.server.resourcemanager.rmnode.RMNodeImpl: Processing slave1:39995 of type STATUS_UPDATE
2019-06-07 07:52:23,282 DEBUG org.apache.hadoop.yarn.server.resourcemanager.rmnode.RMNodeImpl: Processing slave1:39995 of type STATUS_UPDATE
2019-06-07 07:52:23,283 DEBUG org.apache.hadoop.yarn.server.resourcemanager.scheduler.capacity.CapacityScheduler: nodeUpdate: slave1:39995 clusterResources: <memory:8192, vCores:2>
2019-06-07 07:52:23,283 DEBUG org.apache.hadoop.yarn.server.resourcemanager.scheduler.capacity.CapacityScheduler: nodeUpdate: slave1:39995 clusterResources: <memory:8192, vCores:2>
2019-06-07 07:52:23,283 DEBUG org.apache.hadoop.yarn.server.resourcemanager.scheduler.capacity.CapacityScheduler: Node being looked for scheduling slave1:39995 availableResource: <memory:0, vCores:-1>
2019-06-07 07:52:23,283 DEBUG org.apache.hadoop.yarn.server.resourcemanager.scheduler.capacity.CapacityScheduler: Node being looked for scheduling slave1:39995 availableResource: <memory:0, vCores:-1>
2019-06-07 07:52:24,280 DEBUG org.apache.hadoop.yarn.server.resourcemanager.rmnode.RMNodeImpl: Processing slave2:38494 of type STATUS_UPDATE
2019-06-07 07:52:24,280 DEBUG org.apache.hadoop.yarn.server.resourcemanager.rmnode.RMNodeImpl: Processing slave2:38494 of type STATUS_UPDATE
2019-06-07 07:52:24,281 DEBUG org.apache.hadoop.yarn.server.resourcemanager.scheduler.capacity.CapacityScheduler: nodeUpdate: slave2:38494 clusterResources: <memory:8192, vCores:2>
2019-06-07 07:52:24,281 DEBUG org.apache.hadoop.yarn.server.resourcemanager.scheduler.capacity.CapacityScheduler: nodeUpdate: slave2:38494 clusterResources: <memory:8192, vCores:2>
2019-06-07 07:52:24,282 DEBUG org.apache.hadoop.yarn.server.resourcemanager.scheduler.capacity.CapacityScheduler: Node being looked for scheduling slave2:38494 availableResource: <memory:1024, vCores:0>
2019-06-07 07:52:24,282 DEBUG org.apache.hadoop.yarn.server.resourcemanager.scheduler.capacity.CapacityScheduler: Node being looked for scheduling slave2:38494 availableResource: <memory:1024, vCores:0>
2019-06-07 07:52:24,282 DEBUG org.apache.hadoop.yarn.server.resourcemanager.scheduler.capacity.CapacityScheduler: Trying to schedule on node: slave2, available: <memory:1024, vCores:0>
2019-06-07 07:52:24,282 DEBUG org.apache.hadoop.yarn.server.resourcemanager.scheduler.capacity.CapacityScheduler: Trying to schedule on node: slave2, available: <memory:1024, vCores:0>
2019-06-07 07:52:24,282 DEBUG org.apache.hadoop.yarn.server.resourcemanager.scheduler.capacity.ParentQueue: Skip this queue=root, because it doesn't need more resource, schedulingMode=RESPECT_PARTITION_EXCLUSIVITY node-partition=
2019-06-07 07:52:24,282 DEBUG org.apache.hadoop.yarn.server.resourcemanager.scheduler.capacity.ParentQueue: Skip this queue=root, because it doesn't need more resource, schedulingMode=RESPECT_PARTITION_EXCLUSIVITY node-partition=
2019-06-07 07:52:24,285 DEBUG org.apache.hadoop.yarn.server.resourcemanager.rmnode.RMNodeImpl: Processing slave1:39995 of type STATUS_UPDATE
2019-06-07 07:52:24,285 DEBUG org.apache.hadoop.yarn.server.resourcemanager.rmnode.RMNodeImpl: Processing slave1:39995 of type STATUS_UPDATE
2019-06-07 07:52:24,285 DEBUG org.apache.hadoop.yarn.server.resourcemanager.scheduler.capacity.CapacityScheduler: nodeUpdate: slave1:39995 clusterResources: <memory:8192, vCores:2>
2019-06-07 07:52:24,285 DEBUG org.apache.hadoop.yarn.server.resourcemanager.scheduler.capacity.CapacityScheduler: nodeUpdate: slave1:39995 clusterResources: <memory:8192, vCores:2>
2019-06-07 07:52:24,286 DEBUG org.apache.hadoop.yarn.server.resourcemanager.scheduler.capacity.CapacityScheduler: Node being looked for scheduling slave1:39995 availableResource: <memory:0, vCores:-1>
2019-06-07 07:52:24,286 DEBUG org.apache.hadoop.yarn.server.resourcemanager.scheduler.capacity.CapacityScheduler: Node being looked for scheduling slave1:39995 availableResource: <memory:0, vCores:-1>
2019-06-07 07:52:24,358 DEBUG org.apache.hadoop.yarn.server.resourcemanager.scheduler.capacity.LeafQueue: User limit computation for root in queue default userLimitPercent=100 userLimitFactor=1.0 required: <memory:1024, vCores:1> consumed: <memory:7168, vCores:1> user-limit-resource: <memory:8192, vCores:1> queueCapacity: <memory:8192, vCores:1> qconsumed: <memory:7168, vCores:3> consumedRatio: 0.0 currentCapacity: <memory:8192, vCores:1> activeUsers: 0.0 clusterCapacity: <memory:8192, vCores:2> resourceByLabel: <memory:8192, vCores:2> usageratio: 0.875 Partition:  maxUserLimit=<memory:8192, vCores:1> userWeight=1.0
2019-06-07 07:52:24,358 DEBUG org.apache.hadoop.yarn.server.resourcemanager.scheduler.capacity.LeafQueue: User limit computation for root in queue default userLimitPercent=100 userLimitFactor=1.0 required: <memory:1024, vCores:1> consumed: <memory:7168, vCores:1> user-limit-resource: <memory:8192, vCores:1> queueCapacity: <memory:8192, vCores:1> qconsumed: <memory:7168, vCores:3> consumedRatio: 0.0 currentCapacity: <memory:8192, vCores:1> activeUsers: 0.0 clusterCapacity: <memory:8192, vCores:2> resourceByLabel: <memory:8192, vCores:2> usageratio: 0.875 Partition:  maxUserLimit=<memory:8192, vCores:1> userWeight=1.0
2019-06-07 07:52:24,359 DEBUG org.apache.hadoop.yarn.server.resourcemanager.rmapp.attempt.RMAppAttemptImpl: Processing event for appattempt_1559893901343_0001_000001 of type STATUS_UPDATE
2019-06-07 07:52:24,359 DEBUG org.apache.hadoop.yarn.server.resourcemanager.rmapp.attempt.RMAppAttemptImpl: Processing event for appattempt_1559893901343_0001_000001 of type STATUS_UPDATE
2019-06-07 07:52:24,715 DEBUG org.apache.hadoop.yarn.server.resourcemanager.scheduler.capacity.LeafQueue: User limit computation for root in queue default userLimitPercent=100 userLimitFactor=1.0 required: <memory:1024, vCores:1> consumed: <memory:7168, vCores:1> user-limit-resource: <memory:8192, vCores:1> queueCapacity: <memory:8192, vCores:1> qconsumed: <memory:7168, vCores:3> consumedRatio: 0.0 currentCapacity: <memory:8192, vCores:1> activeUsers: 0.0 clusterCapacity: <memory:8192, vCores:2> resourceByLabel: <memory:8192, vCores:2> usageratio: 0.875 Partition:  maxUserLimit=<memory:8192, vCores:1> userWeight=1.0
2019-06-07 07:52:24,715 DEBUG org.apache.hadoop.yarn.server.resourcemanager.rmapp.attempt.RMAppAttemptImpl: Processing event for appattempt_1559893901343_0001_000001 of type STATUS_UPDATE
2019-06-07 07:52:24,715 DEBUG org.apache.hadoop.yarn.server.resourcemanager.scheduler.capacity.LeafQueue: User limit computation for root in queue default userLimitPercent=100 userLimitFactor=1.0 required: <memory:1024, vCores:1> consumed: <memory:7168, vCores:1> user-limit-resource: <memory:8192, vCores:1> queueCapacity: <memory:8192, vCores:1> qconsumed: <memory:7168, vCores:3> consumedRatio: 0.0 currentCapacity: <memory:8192, vCores:1> activeUsers: 0.0 clusterCapacity: <memory:8192, vCores:2> resourceByLabel: <memory:8192, vCores:2> usageratio: 0.875 Partition:  maxUserLimit=<memory:8192, vCores:1> userWeight=1.0
2019-06-07 07:52:24,715 DEBUG org.apache.hadoop.yarn.server.resourcemanager.rmapp.attempt.RMAppAttemptImpl: Processing event for appattempt_1559893901343_0001_000001 of type STATUS_UPDATE
2019-06-07 07:52:24,863 DEBUG org.apache.hadoop.yarn.server.resourcemanager.rmapp.attempt.RMAppAttemptImpl: Processing event for appattempt_1559893901343_0001_000001 of type UNREGISTERED
2019-06-07 07:52:24,863 DEBUG org.apache.hadoop.yarn.server.resourcemanager.rmapp.attempt.RMAppAttemptImpl: Processing event for appattempt_1559893901343_0001_000001 of type UNREGISTERED
2019-06-07 07:52:24,864 INFO org.apache.hadoop.yarn.server.resourcemanager.rmapp.attempt.RMAppAttemptImpl: Updating application attempt appattempt_1559893901343_0001_000001 with final state: FINISHING, and exit status: -1000
2019-06-07 07:52:24,864 INFO org.apache.hadoop.yarn.server.resourcemanager.rmapp.attempt.RMAppAttemptImpl: Updating application attempt appattempt_1559893901343_0001_000001 with final state: FINISHING, and exit status: -1000
2019-06-07 07:52:24,872 DEBUG org.apache.hadoop.yarn.server.resourcemanager.recovery.RMStateStore: Processing event of type UPDATE_APP_ATTEMPT
2019-06-07 07:52:24,872 DEBUG org.apache.hadoop.yarn.server.resourcemanager.recovery.RMStateStore: Processing event of type UPDATE_APP_ATTEMPT
2019-06-07 07:52:24,872 DEBUG org.apache.hadoop.yarn.server.resourcemanager.recovery.RMStateStore: Updating info for attempt: appattempt_1559893901343_0001_000001
2019-06-07 07:52:24,872 DEBUG org.apache.hadoop.yarn.server.resourcemanager.recovery.RMStateStore: Updating info for attempt: appattempt_1559893901343_0001_000001
2019-06-07 07:52:24,872 INFO org.apache.hadoop.yarn.server.resourcemanager.rmapp.attempt.RMAppAttemptImpl: appattempt_1559893901343_0001_000001 State change from RUNNING to FINAL_SAVING
2019-06-07 07:52:24,872 INFO org.apache.hadoop.yarn.server.resourcemanager.rmapp.attempt.RMAppAttemptImpl: appattempt_1559893901343_0001_000001 State change from RUNNING to FINAL_SAVING
2019-06-07 07:52:24,872 DEBUG org.apache.hadoop.yarn.server.resourcemanager.rmapp.attempt.RMAppAttemptImpl: Processing event for appattempt_1559893901343_0001_000001 of type ATTEMPT_UPDATE_SAVED
2019-06-07 07:52:24,872 DEBUG org.apache.hadoop.yarn.server.resourcemanager.rmapp.attempt.RMAppAttemptImpl: Processing event for appattempt_1559893901343_0001_000001 of type ATTEMPT_UPDATE_SAVED
2019-06-07 07:52:24,873 INFO org.apache.hadoop.yarn.server.resourcemanager.rmapp.attempt.RMAppAttemptImpl: appattempt_1559893901343_0001_000001 State change from FINAL_SAVING to FINISHING
2019-06-07 07:52:24,873 INFO org.apache.hadoop.yarn.server.resourcemanager.rmapp.attempt.RMAppAttemptImpl: appattempt_1559893901343_0001_000001 State change from FINAL_SAVING to FINISHING
2019-06-07 07:52:24,873 DEBUG org.apache.hadoop.yarn.server.resourcemanager.rmapp.RMAppImpl: Processing event for application_1559893901343_0001 of type ATTEMPT_UNREGISTERED
2019-06-07 07:52:24,873 DEBUG org.apache.hadoop.yarn.server.resourcemanager.rmapp.RMAppImpl: Processing event for application_1559893901343_0001 of type ATTEMPT_UNREGISTERED
2019-06-07 07:52:24,873 INFO org.apache.hadoop.yarn.server.resourcemanager.rmapp.RMAppImpl: Updating application application_1559893901343_0001 with final state: FINISHING
2019-06-07 07:52:24,873 INFO org.apache.hadoop.yarn.server.resourcemanager.rmapp.RMAppImpl: Updating application application_1559893901343_0001 with final state: FINISHING
2019-06-07 07:52:24,873 DEBUG org.apache.hadoop.yarn.server.resourcemanager.recovery.RMStateStore: Processing event of type UPDATE_APP
2019-06-07 07:52:24,873 DEBUG org.apache.hadoop.yarn.server.resourcemanager.recovery.RMStateStore: Processing event of type UPDATE_APP
2019-06-07 07:52:24,873 INFO org.apache.hadoop.yarn.server.resourcemanager.recovery.RMStateStore: Updating info for app: application_1559893901343_0001
2019-06-07 07:52:24,873 INFO org.apache.hadoop.yarn.server.resourcemanager.recovery.RMStateStore: Updating info for app: application_1559893901343_0001
2019-06-07 07:52:24,873 INFO org.apache.hadoop.yarn.server.resourcemanager.rmapp.RMAppImpl: application_1559893901343_0001 State change from RUNNING to FINAL_SAVING on event=ATTEMPT_UNREGISTERED
2019-06-07 07:52:24,873 INFO org.apache.hadoop.yarn.server.resourcemanager.rmapp.RMAppImpl: application_1559893901343_0001 State change from RUNNING to FINAL_SAVING on event=ATTEMPT_UNREGISTERED
2019-06-07 07:52:24,873 DEBUG org.apache.hadoop.yarn.server.resourcemanager.rmapp.RMAppImpl: Processing event for application_1559893901343_0001 of type APP_UPDATE_SAVED
2019-06-07 07:52:24,873 DEBUG org.apache.hadoop.yarn.server.resourcemanager.rmapp.RMAppImpl: Processing event for application_1559893901343_0001 of type APP_UPDATE_SAVED
2019-06-07 07:52:24,873 INFO org.apache.hadoop.yarn.server.resourcemanager.rmapp.RMAppImpl: application_1559893901343_0001 State change from FINAL_SAVING to FINISHING on event=APP_UPDATE_SAVED
2019-06-07 07:52:24,873 INFO org.apache.hadoop.yarn.server.resourcemanager.rmapp.RMAppImpl: application_1559893901343_0001 State change from FINAL_SAVING to FINISHING on event=APP_UPDATE_SAVED
2019-06-07 07:52:24,940 DEBUG org.apache.hadoop.yarn.server.resourcemanager.rmnode.RMNodeImpl: Processing slave1:39995 of type STATUS_UPDATE
2019-06-07 07:52:24,940 DEBUG org.apache.hadoop.yarn.server.resourcemanager.rmnode.RMNodeImpl: Processing slave1:39995 of type STATUS_UPDATE
2019-06-07 07:52:24,941 DEBUG org.apache.hadoop.yarn.server.resourcemanager.scheduler.capacity.CapacityScheduler: nodeUpdate: slave1:39995 clusterResources: <memory:8192, vCores:2>
2019-06-07 07:52:24,941 DEBUG org.apache.hadoop.yarn.server.resourcemanager.scheduler.capacity.CapacityScheduler: nodeUpdate: slave1:39995 clusterResources: <memory:8192, vCores:2>
2019-06-07 07:52:24,941 DEBUG org.apache.hadoop.yarn.server.resourcemanager.rmcontainer.RMContainerImpl: Processing container_1559893901343_0001_01_000003 of type FINISHED
2019-06-07 07:52:24,941 DEBUG org.apache.hadoop.yarn.server.resourcemanager.rmcontainer.RMContainerImpl: Processing container_1559893901343_0001_01_000003 of type FINISHED
2019-06-07 07:52:24,942 INFO org.apache.hadoop.yarn.server.resourcemanager.rmcontainer.RMContainerImpl: container_1559893901343_0001_01_000003 Container Transitioned from RUNNING to COMPLETED
2019-06-07 07:52:24,942 INFO org.apache.hadoop.yarn.server.resourcemanager.rmcontainer.RMContainerImpl: container_1559893901343_0001_01_000003 Container Transitioned from RUNNING to COMPLETED
2019-06-07 07:52:24,942 INFO org.apache.hadoop.yarn.server.resourcemanager.RMAuditLogger: USER=root	OPERATION=AM Released Container	TARGET=SchedulerApp	RESULT=SUCCESS	APPID=application_1559893901343_0001	CONTAINERID=container_1559893901343_0001_01_000003
2019-06-07 07:52:24,942 INFO org.apache.hadoop.yarn.server.resourcemanager.RMAuditLogger: USER=root	OPERATION=AM Released Container	TARGET=SchedulerApp	RESULT=SUCCESS	APPID=application_1559893901343_0001	CONTAINERID=container_1559893901343_0001_01_000003
2019-06-07 07:52:24,942 DEBUG org.apache.hadoop.yarn.server.resourcemanager.scheduler.capacity.LeafQueue: User limit computation for root in queue default userLimitPercent=100 userLimitFactor=1.0 required: <memory:1024, vCores:1> consumed: <memory:4096, vCores:1> user-limit-resource: <memory:8192, vCores:1> queueCapacity: <memory:8192, vCores:1> qconsumed: <memory:4096, vCores:2> consumedRatio: 0.0 currentCapacity: <memory:8192, vCores:1> activeUsers: 0.0 clusterCapacity: <memory:8192, vCores:2> resourceByLabel: <memory:8192, vCores:2> usageratio: 0.5 Partition:  maxUserLimit=<memory:8192, vCores:1> userWeight=1.0
2019-06-07 07:52:24,942 DEBUG org.apache.hadoop.yarn.server.resourcemanager.scheduler.capacity.LeafQueue: User limit computation for root in queue default userLimitPercent=100 userLimitFactor=1.0 required: <memory:1024, vCores:1> consumed: <memory:4096, vCores:1> user-limit-resource: <memory:8192, vCores:1> queueCapacity: <memory:8192, vCores:1> qconsumed: <memory:4096, vCores:2> consumedRatio: 0.0 currentCapacity: <memory:8192, vCores:1> activeUsers: 0.0 clusterCapacity: <memory:8192, vCores:2> resourceByLabel: <memory:8192, vCores:2> usageratio: 0.5 Partition:  maxUserLimit=<memory:8192, vCores:1> userWeight=1.0
2019-06-07 07:52:24,942 DEBUG org.apache.hadoop.yarn.server.resourcemanager.scheduler.capacity.LeafQueue: default used=<memory:4096, vCores:2> numContainers=2 user=root user-resources=<memory:4096, vCores:2>
2019-06-07 07:52:24,942 DEBUG org.apache.hadoop.yarn.server.resourcemanager.scheduler.capacity.LeafQueue: default used=<memory:4096, vCores:2> numContainers=2 user=root user-resources=<memory:4096, vCores:2>
2019-06-07 07:52:24,942 DEBUG org.apache.hadoop.yarn.server.resourcemanager.scheduler.capacity.ParentQueue: completedContainer root: numChildQueue= 1, capacity=1.0, absoluteCapacity=1.0, usedResources=<memory:4096, vCores:2>usedCapacity=0.5, numApps=1, numContainers=2, cluster=<memory:8192, vCores:2>
2019-06-07 07:52:24,942 DEBUG org.apache.hadoop.yarn.server.resourcemanager.scheduler.capacity.ParentQueue: completedContainer root: numChildQueue= 1, capacity=1.0, absoluteCapacity=1.0, usedResources=<memory:4096, vCores:2>usedCapacity=0.5, numApps=1, numContainers=2, cluster=<memory:8192, vCores:2>
2019-06-07 07:52:24,942 DEBUG org.apache.hadoop.yarn.server.resourcemanager.scheduler.capacity.ParentQueue: Re-sorting completed queue: default: capacity=1.0, absoluteCapacity=1.0, usedResources=<memory:4096, vCores:2>, usedCapacity=0.5, absoluteUsedCapacity=0.5, numApps=1, numContainers=2
2019-06-07 07:52:24,942 DEBUG org.apache.hadoop.yarn.server.resourcemanager.scheduler.capacity.ParentQueue: Re-sorting completed queue: default: capacity=1.0, absoluteCapacity=1.0, usedResources=<memory:4096, vCores:2>, usedCapacity=0.5, absoluteUsedCapacity=0.5, numApps=1, numContainers=2
2019-06-07 07:52:24,943 INFO org.apache.hadoop.yarn.server.resourcemanager.scheduler.SchedulerNode: Released container container_1559893901343_0001_01_000003 of capacity <memory:3072, vCores:1> on host slave1:39995, which currently has 1 containers, <memory:1024, vCores:1> used and <memory:3072, vCores:0> available, release resources=true
2019-06-07 07:52:24,943 INFO org.apache.hadoop.yarn.server.resourcemanager.scheduler.SchedulerNode: Released container container_1559893901343_0001_01_000003 of capacity <memory:3072, vCores:1> on host slave1:39995, which currently has 1 containers, <memory:1024, vCores:1> used and <memory:3072, vCores:0> available, release resources=true
2019-06-07 07:52:24,943 DEBUG org.apache.hadoop.yarn.server.resourcemanager.scheduler.capacity.CapacityScheduler: Node being looked for scheduling slave1:39995 availableResource: <memory:3072, vCores:0>
2019-06-07 07:52:24,943 DEBUG org.apache.hadoop.yarn.server.resourcemanager.scheduler.capacity.CapacityScheduler: Node being looked for scheduling slave1:39995 availableResource: <memory:3072, vCores:0>
2019-06-07 07:52:24,943 DEBUG org.apache.hadoop.yarn.server.resourcemanager.scheduler.capacity.CapacityScheduler: Trying to schedule on node: slave1, available: <memory:3072, vCores:0>
2019-06-07 07:52:24,943 DEBUG org.apache.hadoop.yarn.server.resourcemanager.scheduler.capacity.CapacityScheduler: Trying to schedule on node: slave1, available: <memory:3072, vCores:0>
2019-06-07 07:52:24,943 DEBUG org.apache.hadoop.yarn.server.resourcemanager.scheduler.capacity.ParentQueue: Skip this queue=root, because it doesn't need more resource, schedulingMode=RESPECT_PARTITION_EXCLUSIVITY node-partition=
2019-06-07 07:52:24,943 DEBUG org.apache.hadoop.yarn.server.resourcemanager.scheduler.capacity.ParentQueue: Skip this queue=root, because it doesn't need more resource, schedulingMode=RESPECT_PARTITION_EXCLUSIVITY node-partition=
2019-06-07 07:52:24,944 DEBUG org.apache.hadoop.yarn.server.resourcemanager.rmapp.attempt.RMAppAttemptImpl: Processing event for appattempt_1559893901343_0001_000001 of type CONTAINER_FINISHED
2019-06-07 07:52:24,944 DEBUG org.apache.hadoop.yarn.server.resourcemanager.rmapp.attempt.RMAppAttemptImpl: Processing event for appattempt_1559893901343_0001_000001 of type CONTAINER_FINISHED
2019-06-07 07:52:24,969 INFO org.apache.hadoop.yarn.server.resourcemanager.ApplicationMasterService: application_1559893901343_0001 unregistered successfully. 
2019-06-07 07:52:24,969 INFO org.apache.hadoop.yarn.server.resourcemanager.ApplicationMasterService: application_1559893901343_0001 unregistered successfully. 
2019-06-07 07:52:24,971 DEBUG org.apache.hadoop.yarn.server.resourcemanager.rmnode.RMNodeImpl: Processing slave2:38494 of type STATUS_UPDATE
2019-06-07 07:52:24,971 DEBUG org.apache.hadoop.yarn.server.resourcemanager.rmnode.RMNodeImpl: Processing slave2:38494 of type STATUS_UPDATE
2019-06-07 07:52:24,972 DEBUG org.apache.hadoop.yarn.server.resourcemanager.scheduler.capacity.CapacityScheduler: nodeUpdate: slave2:38494 clusterResources: <memory:8192, vCores:2>
2019-06-07 07:52:24,972 DEBUG org.apache.hadoop.yarn.server.resourcemanager.scheduler.capacity.CapacityScheduler: nodeUpdate: slave2:38494 clusterResources: <memory:8192, vCores:2>
2019-06-07 07:52:24,972 DEBUG org.apache.hadoop.yarn.server.resourcemanager.rmcontainer.RMContainerImpl: Processing container_1559893901343_0001_01_000002 of type FINISHED
2019-06-07 07:52:24,972 DEBUG org.apache.hadoop.yarn.server.resourcemanager.rmcontainer.RMContainerImpl: Processing container_1559893901343_0001_01_000002 of type FINISHED
2019-06-07 07:52:24,972 INFO org.apache.hadoop.yarn.server.resourcemanager.rmcontainer.RMContainerImpl: container_1559893901343_0001_01_000002 Container Transitioned from RUNNING to COMPLETED
2019-06-07 07:52:24,972 INFO org.apache.hadoop.yarn.server.resourcemanager.rmcontainer.RMContainerImpl: container_1559893901343_0001_01_000002 Container Transitioned from RUNNING to COMPLETED
2019-06-07 07:52:24,972 INFO org.apache.hadoop.yarn.server.resourcemanager.RMAuditLogger: USER=root	OPERATION=AM Released Container	TARGET=SchedulerApp	RESULT=SUCCESS	APPID=application_1559893901343_0001	CONTAINERID=container_1559893901343_0001_01_000002
2019-06-07 07:52:24,972 INFO org.apache.hadoop.yarn.server.resourcemanager.RMAuditLogger: USER=root	OPERATION=AM Released Container	TARGET=SchedulerApp	RESULT=SUCCESS	APPID=application_1559893901343_0001	CONTAINERID=container_1559893901343_0001_01_000002
2019-06-07 07:52:24,972 DEBUG org.apache.hadoop.yarn.server.resourcemanager.scheduler.capacity.LeafQueue: User limit computation for root in queue default userLimitPercent=100 userLimitFactor=1.0 required: <memory:1024, vCores:1> consumed: <memory:1024, vCores:1> user-limit-resource: <memory:8192, vCores:1> queueCapacity: <memory:8192, vCores:1> qconsumed: <memory:1024, vCores:1> consumedRatio: 0.0 currentCapacity: <memory:8192, vCores:1> activeUsers: 0.0 clusterCapacity: <memory:8192, vCores:2> resourceByLabel: <memory:8192, vCores:2> usageratio: 0.125 Partition:  maxUserLimit=<memory:8192, vCores:1> userWeight=1.0
2019-06-07 07:52:24,972 DEBUG org.apache.hadoop.yarn.server.resourcemanager.scheduler.capacity.LeafQueue: User limit computation for root in queue default userLimitPercent=100 userLimitFactor=1.0 required: <memory:1024, vCores:1> consumed: <memory:1024, vCores:1> user-limit-resource: <memory:8192, vCores:1> queueCapacity: <memory:8192, vCores:1> qconsumed: <memory:1024, vCores:1> consumedRatio: 0.0 currentCapacity: <memory:8192, vCores:1> activeUsers: 0.0 clusterCapacity: <memory:8192, vCores:2> resourceByLabel: <memory:8192, vCores:2> usageratio: 0.125 Partition:  maxUserLimit=<memory:8192, vCores:1> userWeight=1.0
2019-06-07 07:52:24,972 DEBUG org.apache.hadoop.yarn.server.resourcemanager.scheduler.capacity.LeafQueue: default used=<memory:1024, vCores:1> numContainers=1 user=root user-resources=<memory:1024, vCores:1>
2019-06-07 07:52:24,972 DEBUG org.apache.hadoop.yarn.server.resourcemanager.scheduler.capacity.LeafQueue: default used=<memory:1024, vCores:1> numContainers=1 user=root user-resources=<memory:1024, vCores:1>
2019-06-07 07:52:24,972 DEBUG org.apache.hadoop.yarn.server.resourcemanager.scheduler.capacity.ParentQueue: completedContainer root: numChildQueue= 1, capacity=1.0, absoluteCapacity=1.0, usedResources=<memory:1024, vCores:1>usedCapacity=0.125, numApps=1, numContainers=1, cluster=<memory:8192, vCores:2>
2019-06-07 07:52:24,972 DEBUG org.apache.hadoop.yarn.server.resourcemanager.scheduler.capacity.ParentQueue: completedContainer root: numChildQueue= 1, capacity=1.0, absoluteCapacity=1.0, usedResources=<memory:1024, vCores:1>usedCapacity=0.125, numApps=1, numContainers=1, cluster=<memory:8192, vCores:2>
2019-06-07 07:52:24,973 DEBUG org.apache.hadoop.yarn.server.resourcemanager.scheduler.capacity.ParentQueue: Re-sorting completed queue: default: capacity=1.0, absoluteCapacity=1.0, usedResources=<memory:1024, vCores:1>, usedCapacity=0.125, absoluteUsedCapacity=0.125, numApps=1, numContainers=1
2019-06-07 07:52:24,973 DEBUG org.apache.hadoop.yarn.server.resourcemanager.scheduler.capacity.ParentQueue: Re-sorting completed queue: default: capacity=1.0, absoluteCapacity=1.0, usedResources=<memory:1024, vCores:1>, usedCapacity=0.125, absoluteUsedCapacity=0.125, numApps=1, numContainers=1
2019-06-07 07:52:24,973 INFO org.apache.hadoop.yarn.server.resourcemanager.scheduler.SchedulerNode: Released container container_1559893901343_0001_01_000002 of capacity <memory:3072, vCores:1> on host slave2:38494, which currently has 0 containers, <memory:0, vCores:0> used and <memory:4096, vCores:1> available, release resources=true
2019-06-07 07:52:24,973 INFO org.apache.hadoop.yarn.server.resourcemanager.scheduler.SchedulerNode: Released container container_1559893901343_0001_01_000002 of capacity <memory:3072, vCores:1> on host slave2:38494, which currently has 0 containers, <memory:0, vCores:0> used and <memory:4096, vCores:1> available, release resources=true
2019-06-07 07:52:24,973 DEBUG org.apache.hadoop.yarn.server.resourcemanager.scheduler.capacity.CapacityScheduler: Node being looked for scheduling slave2:38494 availableResource: <memory:4096, vCores:1>
2019-06-07 07:52:24,973 DEBUG org.apache.hadoop.yarn.server.resourcemanager.scheduler.capacity.CapacityScheduler: Node being looked for scheduling slave2:38494 availableResource: <memory:4096, vCores:1>
2019-06-07 07:52:24,973 DEBUG org.apache.hadoop.yarn.server.resourcemanager.scheduler.capacity.CapacityScheduler: Trying to schedule on node: slave2, available: <memory:4096, vCores:1>
2019-06-07 07:52:24,973 DEBUG org.apache.hadoop.yarn.server.resourcemanager.scheduler.capacity.CapacityScheduler: Trying to schedule on node: slave2, available: <memory:4096, vCores:1>
2019-06-07 07:52:24,973 DEBUG org.apache.hadoop.yarn.server.resourcemanager.scheduler.capacity.ParentQueue: Skip this queue=root, because it doesn't need more resource, schedulingMode=RESPECT_PARTITION_EXCLUSIVITY node-partition=
2019-06-07 07:52:24,973 DEBUG org.apache.hadoop.yarn.server.resourcemanager.scheduler.capacity.ParentQueue: Skip this queue=root, because it doesn't need more resource, schedulingMode=RESPECT_PARTITION_EXCLUSIVITY node-partition=
2019-06-07 07:52:24,973 DEBUG org.apache.hadoop.yarn.server.resourcemanager.rmapp.attempt.RMAppAttemptImpl: Processing event for appattempt_1559893901343_0001_000001 of type CONTAINER_FINISHED
2019-06-07 07:52:24,973 DEBUG org.apache.hadoop.yarn.server.resourcemanager.rmapp.attempt.RMAppAttemptImpl: Processing event for appattempt_1559893901343_0001_000001 of type CONTAINER_FINISHED
2019-06-07 07:52:25,395 DEBUG org.apache.hadoop.yarn.server.resourcemanager.rmnode.RMNodeImpl: Processing slave1:39995 of type STATUS_UPDATE
2019-06-07 07:52:25,395 DEBUG org.apache.hadoop.yarn.server.resourcemanager.rmnode.RMNodeImpl: Processing slave1:39995 of type STATUS_UPDATE
2019-06-07 07:52:25,395 DEBUG org.apache.hadoop.yarn.server.resourcemanager.scheduler.capacity.CapacityScheduler: nodeUpdate: slave1:39995 clusterResources: <memory:8192, vCores:2>
2019-06-07 07:52:25,395 DEBUG org.apache.hadoop.yarn.server.resourcemanager.scheduler.capacity.CapacityScheduler: nodeUpdate: slave1:39995 clusterResources: <memory:8192, vCores:2>
2019-06-07 07:52:25,396 DEBUG org.apache.hadoop.yarn.server.resourcemanager.rmcontainer.RMContainerImpl: Processing container_1559893901343_0001_01_000001 of type FINISHED
2019-06-07 07:52:25,396 DEBUG org.apache.hadoop.yarn.server.resourcemanager.rmcontainer.RMContainerImpl: Processing container_1559893901343_0001_01_000001 of type FINISHED
2019-06-07 07:52:25,396 INFO org.apache.hadoop.yarn.server.resourcemanager.rmcontainer.RMContainerImpl: container_1559893901343_0001_01_000001 Container Transitioned from RUNNING to COMPLETED
2019-06-07 07:52:25,396 INFO org.apache.hadoop.yarn.server.resourcemanager.rmcontainer.RMContainerImpl: container_1559893901343_0001_01_000001 Container Transitioned from RUNNING to COMPLETED
2019-06-07 07:52:25,396 INFO org.apache.hadoop.yarn.server.resourcemanager.RMAuditLogger: USER=root	OPERATION=AM Released Container	TARGET=SchedulerApp	RESULT=SUCCESS	APPID=application_1559893901343_0001	CONTAINERID=container_1559893901343_0001_01_000001
2019-06-07 07:52:25,396 INFO org.apache.hadoop.yarn.server.resourcemanager.RMAuditLogger: USER=root	OPERATION=AM Released Container	TARGET=SchedulerApp	RESULT=SUCCESS	APPID=application_1559893901343_0001	CONTAINERID=container_1559893901343_0001_01_000001
2019-06-07 07:52:25,396 DEBUG org.apache.hadoop.yarn.server.resourcemanager.scheduler.capacity.LeafQueue: User limit computation for root in queue default userLimitPercent=100 userLimitFactor=1.0 required: <memory:1024, vCores:1> consumed: <memory:0, vCores:0> user-limit-resource: <memory:8192, vCores:1> queueCapacity: <memory:8192, vCores:1> qconsumed: <memory:0, vCores:0> consumedRatio: 0.0 currentCapacity: <memory:8192, vCores:1> activeUsers: 0.0 clusterCapacity: <memory:8192, vCores:2> resourceByLabel: <memory:8192, vCores:2> usageratio: 0.0 Partition:  maxUserLimit=<memory:8192, vCores:1> userWeight=1.0
2019-06-07 07:52:25,396 DEBUG org.apache.hadoop.yarn.server.resourcemanager.scheduler.capacity.LeafQueue: User limit computation for root in queue default userLimitPercent=100 userLimitFactor=1.0 required: <memory:1024, vCores:1> consumed: <memory:0, vCores:0> user-limit-resource: <memory:8192, vCores:1> queueCapacity: <memory:8192, vCores:1> qconsumed: <memory:0, vCores:0> consumedRatio: 0.0 currentCapacity: <memory:8192, vCores:1> activeUsers: 0.0 clusterCapacity: <memory:8192, vCores:2> resourceByLabel: <memory:8192, vCores:2> usageratio: 0.0 Partition:  maxUserLimit=<memory:8192, vCores:1> userWeight=1.0
2019-06-07 07:52:25,396 DEBUG org.apache.hadoop.yarn.server.resourcemanager.scheduler.capacity.LeafQueue: default used=<memory:0, vCores:0> numContainers=0 user=root user-resources=<memory:0, vCores:0>
2019-06-07 07:52:25,396 DEBUG org.apache.hadoop.yarn.server.resourcemanager.scheduler.capacity.LeafQueue: default used=<memory:0, vCores:0> numContainers=0 user=root user-resources=<memory:0, vCores:0>
2019-06-07 07:52:25,396 DEBUG org.apache.hadoop.yarn.server.resourcemanager.scheduler.capacity.ParentQueue: completedContainer root: numChildQueue= 1, capacity=1.0, absoluteCapacity=1.0, usedResources=<memory:0, vCores:0>usedCapacity=0.0, numApps=1, numContainers=0, cluster=<memory:8192, vCores:2>
2019-06-07 07:52:25,396 DEBUG org.apache.hadoop.yarn.server.resourcemanager.scheduler.capacity.ParentQueue: completedContainer root: numChildQueue= 1, capacity=1.0, absoluteCapacity=1.0, usedResources=<memory:0, vCores:0>usedCapacity=0.0, numApps=1, numContainers=0, cluster=<memory:8192, vCores:2>
2019-06-07 07:52:25,396 DEBUG org.apache.hadoop.yarn.server.resourcemanager.scheduler.capacity.ParentQueue: Re-sorting completed queue: default: capacity=1.0, absoluteCapacity=1.0, usedResources=<memory:0, vCores:0>, usedCapacity=0.0, absoluteUsedCapacity=0.0, numApps=1, numContainers=0
2019-06-07 07:52:25,396 DEBUG org.apache.hadoop.yarn.server.resourcemanager.scheduler.capacity.ParentQueue: Re-sorting completed queue: default: capacity=1.0, absoluteCapacity=1.0, usedResources=<memory:0, vCores:0>, usedCapacity=0.0, absoluteUsedCapacity=0.0, numApps=1, numContainers=0
2019-06-07 07:52:25,397 INFO org.apache.hadoop.yarn.server.resourcemanager.scheduler.SchedulerNode: Released container container_1559893901343_0001_01_000001 of capacity <memory:1024, vCores:1> on host slave1:39995, which currently has 0 containers, <memory:0, vCores:0> used and <memory:4096, vCores:1> available, release resources=true
2019-06-07 07:52:25,397 INFO org.apache.hadoop.yarn.server.resourcemanager.scheduler.SchedulerNode: Released container container_1559893901343_0001_01_000001 of capacity <memory:1024, vCores:1> on host slave1:39995, which currently has 0 containers, <memory:0, vCores:0> used and <memory:4096, vCores:1> available, release resources=true
2019-06-07 07:52:25,397 DEBUG org.apache.hadoop.yarn.server.resourcemanager.scheduler.capacity.CapacityScheduler: Node being looked for scheduling slave1:39995 availableResource: <memory:4096, vCores:1>
2019-06-07 07:52:25,397 DEBUG org.apache.hadoop.yarn.server.resourcemanager.scheduler.capacity.CapacityScheduler: Node being looked for scheduling slave1:39995 availableResource: <memory:4096, vCores:1>
2019-06-07 07:52:25,397 DEBUG org.apache.hadoop.yarn.server.resourcemanager.scheduler.capacity.CapacityScheduler: Trying to schedule on node: slave1, available: <memory:4096, vCores:1>
2019-06-07 07:52:25,397 DEBUG org.apache.hadoop.yarn.server.resourcemanager.scheduler.capacity.CapacityScheduler: Trying to schedule on node: slave1, available: <memory:4096, vCores:1>
2019-06-07 07:52:25,397 DEBUG org.apache.hadoop.yarn.server.resourcemanager.scheduler.capacity.ParentQueue: Skip this queue=root, because it doesn't need more resource, schedulingMode=RESPECT_PARTITION_EXCLUSIVITY node-partition=
2019-06-07 07:52:25,397 DEBUG org.apache.hadoop.yarn.server.resourcemanager.scheduler.capacity.ParentQueue: Skip this queue=root, because it doesn't need more resource, schedulingMode=RESPECT_PARTITION_EXCLUSIVITY node-partition=
2019-06-07 07:52:25,397 DEBUG org.apache.hadoop.yarn.server.resourcemanager.rmapp.attempt.RMAppAttemptImpl: Processing event for appattempt_1559893901343_0001_000001 of type CONTAINER_FINISHED
2019-06-07 07:52:25,397 DEBUG org.apache.hadoop.yarn.server.resourcemanager.rmapp.attempt.RMAppAttemptImpl: Processing event for appattempt_1559893901343_0001_000001 of type CONTAINER_FINISHED
2019-06-07 07:52:25,397 INFO org.apache.hadoop.yarn.server.resourcemanager.ApplicationMasterService: Unregistering app attempt : appattempt_1559893901343_0001_000001
2019-06-07 07:52:25,397 INFO org.apache.hadoop.yarn.server.resourcemanager.ApplicationMasterService: Unregistering app attempt : appattempt_1559893901343_0001_000001
2019-06-07 07:52:25,398 INFO org.apache.hadoop.yarn.server.resourcemanager.security.AMRMTokenSecretManager: Application finished, removing password for appattempt_1559893901343_0001_000001
2019-06-07 07:52:25,398 INFO org.apache.hadoop.yarn.server.resourcemanager.security.AMRMTokenSecretManager: Application finished, removing password for appattempt_1559893901343_0001_000001
2019-06-07 07:52:25,399 INFO org.apache.hadoop.yarn.server.resourcemanager.rmapp.attempt.RMAppAttemptImpl: appattempt_1559893901343_0001_000001 State change from FINISHING to FINISHED
2019-06-07 07:52:25,399 INFO org.apache.hadoop.yarn.server.resourcemanager.rmapp.attempt.RMAppAttemptImpl: appattempt_1559893901343_0001_000001 State change from FINISHING to FINISHED
2019-06-07 07:52:25,399 DEBUG org.apache.hadoop.yarn.server.resourcemanager.rmapp.RMAppImpl: Processing event for application_1559893901343_0001 of type ATTEMPT_FINISHED
2019-06-07 07:52:25,399 DEBUG org.apache.hadoop.yarn.server.resourcemanager.rmapp.RMAppImpl: Processing event for application_1559893901343_0001 of type ATTEMPT_FINISHED
2019-06-07 07:52:25,401 INFO org.apache.hadoop.yarn.server.resourcemanager.rmapp.RMAppImpl: application_1559893901343_0001 State change from FINISHING to FINISHED on event=ATTEMPT_FINISHED
2019-06-07 07:52:25,401 INFO org.apache.hadoop.yarn.server.resourcemanager.rmapp.RMAppImpl: application_1559893901343_0001 State change from FINISHING to FINISHED on event=ATTEMPT_FINISHED
2019-06-07 07:52:25,401 INFO org.apache.hadoop.yarn.server.resourcemanager.scheduler.capacity.CapacityScheduler: Application Attempt appattempt_1559893901343_0001_000001 is done. finalState=FINISHED
2019-06-07 07:52:25,401 INFO org.apache.hadoop.yarn.server.resourcemanager.scheduler.capacity.CapacityScheduler: Application Attempt appattempt_1559893901343_0001_000001 is done. finalState=FINISHED
2019-06-07 07:52:25,401 INFO org.apache.hadoop.yarn.server.resourcemanager.scheduler.AppSchedulingInfo: Application application_1559893901343_0001 requests cleared
2019-06-07 07:52:25,401 INFO org.apache.hadoop.yarn.server.resourcemanager.scheduler.AppSchedulingInfo: Application application_1559893901343_0001 requests cleared
2019-06-07 07:52:25,402 INFO org.apache.hadoop.yarn.server.resourcemanager.scheduler.capacity.LeafQueue: Application removed - appId: application_1559893901343_0001 user: root queue: default #user-pending-applications: 0 #user-active-applications: 0 #queue-pending-applications: 0 #queue-active-applications: 0
2019-06-07 07:52:25,402 INFO org.apache.hadoop.yarn.server.resourcemanager.scheduler.capacity.LeafQueue: Application removed - appId: application_1559893901343_0001 user: root queue: default #user-pending-applications: 0 #user-active-applications: 0 #queue-pending-applications: 0 #queue-active-applications: 0
2019-06-07 07:52:25,402 DEBUG org.apache.hadoop.yarn.server.resourcemanager.rmnode.RMNodeImpl: Processing slave1:39995 of type FINISHED_CONTAINERS_PULLED_BY_AM
2019-06-07 07:52:25,402 DEBUG org.apache.hadoop.yarn.server.resourcemanager.rmnode.RMNodeImpl: Processing slave1:39995 of type FINISHED_CONTAINERS_PULLED_BY_AM
2019-06-07 07:52:25,402 DEBUG org.apache.hadoop.yarn.server.resourcemanager.rmnode.RMNodeImpl: Processing slave1:39995 of type CLEANUP_APP
2019-06-07 07:52:25,402 DEBUG org.apache.hadoop.yarn.server.resourcemanager.rmnode.RMNodeImpl: Processing slave1:39995 of type CLEANUP_APP
2019-06-07 07:52:25,402 DEBUG org.apache.hadoop.yarn.server.resourcemanager.rmnode.RMNodeImpl: Processing slave2:38494 of type CLEANUP_APP
2019-06-07 07:52:25,402 DEBUG org.apache.hadoop.yarn.server.resourcemanager.rmnode.RMNodeImpl: Processing slave2:38494 of type CLEANUP_APP
2019-06-07 07:52:25,402 INFO org.apache.hadoop.yarn.server.resourcemanager.scheduler.capacity.ParentQueue: Application removed - appId: application_1559893901343_0001 user: root leaf-queue of parent: root #applications: 0
2019-06-07 07:52:25,402 INFO org.apache.hadoop.yarn.server.resourcemanager.scheduler.capacity.ParentQueue: Application removed - appId: application_1559893901343_0001 user: root leaf-queue of parent: root #applications: 0
2019-06-07 07:52:25,403 DEBUG org.apache.hadoop.yarn.server.resourcemanager.RMAppManager: RMAppManager processing event for application_1559893901343_0001 of type APP_COMPLETED
2019-06-07 07:52:25,403 DEBUG org.apache.hadoop.yarn.server.resourcemanager.RMAppManager: RMAppManager processing event for application_1559893901343_0001 of type APP_COMPLETED
2019-06-07 07:52:25,403 INFO org.apache.hadoop.yarn.server.resourcemanager.RMAuditLogger: USER=root	OPERATION=Application Finished - Succeeded	TARGET=RMAppManager	RESULT=SUCCESS	APPID=application_1559893901343_0001
2019-06-07 07:52:25,403 INFO org.apache.hadoop.yarn.server.resourcemanager.RMAuditLogger: USER=root	OPERATION=Application Finished - Succeeded	TARGET=RMAppManager	RESULT=SUCCESS	APPID=application_1559893901343_0001
2019-06-07 07:52:25,404 DEBUG org.apache.hadoop.yarn.server.resourcemanager.scheduler.AbstractYarnScheduler: Request for appInfo of unknown attempt appattempt_1559893901343_0001_000001
2019-06-07 07:52:25,404 DEBUG org.apache.hadoop.yarn.server.resourcemanager.scheduler.AbstractYarnScheduler: Request for appInfo of unknown attempt appattempt_1559893901343_0001_000001
2019-06-07 07:52:25,405 INFO org.apache.hadoop.yarn.server.resourcemanager.RMAppManager$ApplicationSummary: appId=application_1559893901343_0001,name=Spark Pi,user=root,queue=default,state=FINISHED,trackingUrl=http://master:8088/proxy/application_1559893901343_0001/,appMasterHost=172.17.0.3,startTime=1559893924491,finishTime=1559893944873,finalStatus=SUCCEEDED,memorySeconds=99283,vcoreSeconds=44,preemptedMemorySeconds=0,preemptedVcoreSeconds=0,preemptedAMContainers=0,preemptedNonAMContainers=0,preemptedResources=<memory:0\, vCores:0>,applicationType=SPARK
2019-06-07 07:52:25,408 INFO org.apache.hadoop.yarn.server.resourcemanager.amlauncher.AMLauncher: Cleaning master appattempt_1559893901343_0001_000001
2019-06-07 07:52:25,408 INFO org.apache.hadoop.yarn.server.resourcemanager.amlauncher.AMLauncher: Cleaning master appattempt_1559893901343_0001_000001
2019-06-07 07:52:25,978 DEBUG org.apache.hadoop.yarn.server.resourcemanager.rmnode.RMNodeImpl: Processing slave2:38494 of type STATUS_UPDATE
2019-06-07 07:52:25,978 DEBUG org.apache.hadoop.yarn.server.resourcemanager.rmnode.RMNodeImpl: Processing slave2:38494 of type STATUS_UPDATE
2019-06-07 07:52:25,980 DEBUG org.apache.hadoop.yarn.server.resourcemanager.scheduler.capacity.CapacityScheduler: nodeUpdate: slave2:38494 clusterResources: <memory:8192, vCores:2>
2019-06-07 07:52:25,980 DEBUG org.apache.hadoop.yarn.server.resourcemanager.scheduler.capacity.CapacityScheduler: nodeUpdate: slave2:38494 clusterResources: <memory:8192, vCores:2>
2019-06-07 07:52:25,980 DEBUG org.apache.hadoop.yarn.server.resourcemanager.scheduler.capacity.CapacityScheduler: Node being looked for scheduling slave2:38494 availableResource: <memory:4096, vCores:1>
2019-06-07 07:52:25,980 DEBUG org.apache.hadoop.yarn.server.resourcemanager.scheduler.capacity.CapacityScheduler: Node being looked for scheduling slave2:38494 availableResource: <memory:4096, vCores:1>
2019-06-07 07:52:25,980 DEBUG org.apache.hadoop.yarn.server.resourcemanager.scheduler.capacity.CapacityScheduler: Trying to schedule on node: slave2, available: <memory:4096, vCores:1>
2019-06-07 07:52:25,980 DEBUG org.apache.hadoop.yarn.server.resourcemanager.scheduler.capacity.CapacityScheduler: Trying to schedule on node: slave2, available: <memory:4096, vCores:1>
2019-06-07 07:52:25,980 DEBUG org.apache.hadoop.yarn.server.resourcemanager.scheduler.capacity.ParentQueue: Skip this queue=root, because it doesn't need more resource, schedulingMode=RESPECT_PARTITION_EXCLUSIVITY node-partition=
2019-06-07 07:52:25,980 DEBUG org.apache.hadoop.yarn.server.resourcemanager.scheduler.capacity.ParentQueue: Skip this queue=root, because it doesn't need more resource, schedulingMode=RESPECT_PARTITION_EXCLUSIVITY node-partition=
2019-06-07 07:52:26,400 DEBUG org.apache.hadoop.yarn.server.resourcemanager.rmnode.RMNodeImpl: Processing slave1:39995 of type STATUS_UPDATE
2019-06-07 07:52:26,400 DEBUG org.apache.hadoop.yarn.server.resourcemanager.rmnode.RMNodeImpl: Processing slave1:39995 of type STATUS_UPDATE
2019-06-07 07:52:26,400 DEBUG org.apache.hadoop.yarn.server.resourcemanager.scheduler.capacity.CapacityScheduler: nodeUpdate: slave1:39995 clusterResources: <memory:8192, vCores:2>
2019-06-07 07:52:26,400 DEBUG org.apache.hadoop.yarn.server.resourcemanager.scheduler.capacity.CapacityScheduler: nodeUpdate: slave1:39995 clusterResources: <memory:8192, vCores:2>
2019-06-07 07:52:26,402 DEBUG org.apache.hadoop.yarn.server.resourcemanager.scheduler.capacity.CapacityScheduler: Node being looked for scheduling slave1:39995 availableResource: <memory:4096, vCores:1>
2019-06-07 07:52:26,402 DEBUG org.apache.hadoop.yarn.server.resourcemanager.scheduler.capacity.CapacityScheduler: Node being looked for scheduling slave1:39995 availableResource: <memory:4096, vCores:1>
2019-06-07 07:52:26,402 DEBUG org.apache.hadoop.yarn.server.resourcemanager.scheduler.capacity.CapacityScheduler: Trying to schedule on node: slave1, available: <memory:4096, vCores:1>
2019-06-07 07:52:26,402 DEBUG org.apache.hadoop.yarn.server.resourcemanager.scheduler.capacity.CapacityScheduler: Trying to schedule on node: slave1, available: <memory:4096, vCores:1>
2019-06-07 07:52:26,402 DEBUG org.apache.hadoop.yarn.server.resourcemanager.scheduler.capacity.ParentQueue: Skip this queue=root, because it doesn't need more resource, schedulingMode=RESPECT_PARTITION_EXCLUSIVITY node-partition=
2019-06-07 07:52:26,402 DEBUG org.apache.hadoop.yarn.server.resourcemanager.scheduler.capacity.ParentQueue: Skip this queue=root, because it doesn't need more resource, schedulingMode=RESPECT_PARTITION_EXCLUSIVITY node-partition=
2019-06-07 07:52:26,985 DEBUG org.apache.hadoop.yarn.server.resourcemanager.rmnode.RMNodeImpl: Processing slave2:38494 of type STATUS_UPDATE
2019-06-07 07:52:26,985 DEBUG org.apache.hadoop.yarn.server.resourcemanager.rmnode.RMNodeImpl: Processing slave2:38494 of type STATUS_UPDATE
2019-06-07 07:52:26,985 DEBUG org.apache.hadoop.yarn.server.resourcemanager.rmnode.RMNodeImpl: Container container_1559893901343_0001_01_000002 is the first container get launched for application application_1559893901343_0001
2019-06-07 07:52:26,985 DEBUG org.apache.hadoop.yarn.server.resourcemanager.rmnode.RMNodeImpl: Container container_1559893901343_0001_01_000002 is the first container get launched for application application_1559893901343_0001
2019-06-07 07:52:26,985 DEBUG org.apache.hadoop.yarn.server.resourcemanager.rmapp.RMAppImpl: Processing event for application_1559893901343_0001 of type APP_RUNNING_ON_NODE
2019-06-07 07:52:26,985 DEBUG org.apache.hadoop.yarn.server.resourcemanager.rmapp.RMAppImpl: Processing event for application_1559893901343_0001 of type APP_RUNNING_ON_NODE
2019-06-07 07:52:26,985 DEBUG org.apache.hadoop.yarn.server.resourcemanager.rmnode.RMNodeImpl: Processing slave2:38494 of type CLEANUP_APP
2019-06-07 07:52:26,985 DEBUG org.apache.hadoop.yarn.server.resourcemanager.rmnode.RMNodeImpl: Processing slave2:38494 of type CLEANUP_APP
2019-06-07 07:52:26,985 DEBUG org.apache.hadoop.yarn.server.resourcemanager.scheduler.capacity.CapacityScheduler: nodeUpdate: slave2:38494 clusterResources: <memory:8192, vCores:2>
2019-06-07 07:52:26,985 DEBUG org.apache.hadoop.yarn.server.resourcemanager.scheduler.capacity.CapacityScheduler: nodeUpdate: slave2:38494 clusterResources: <memory:8192, vCores:2>
2019-06-07 07:52:26,990 INFO org.apache.hadoop.yarn.server.resourcemanager.scheduler.AbstractYarnScheduler: Container container_1559893901343_0001_01_000002 completed with event FINISHED, but corresponding RMContainer doesn't exist.
2019-06-07 07:52:26,990 INFO org.apache.hadoop.yarn.server.resourcemanager.scheduler.AbstractYarnScheduler: Container container_1559893901343_0001_01_000002 completed with event FINISHED, but corresponding RMContainer doesn't exist.
2019-06-07 07:52:26,990 DEBUG org.apache.hadoop.yarn.server.resourcemanager.scheduler.capacity.CapacityScheduler: Node being looked for scheduling slave2:38494 availableResource: <memory:4096, vCores:1>
2019-06-07 07:52:26,990 DEBUG org.apache.hadoop.yarn.server.resourcemanager.scheduler.capacity.CapacityScheduler: Node being looked for scheduling slave2:38494 availableResource: <memory:4096, vCores:1>
2019-06-07 07:52:26,990 DEBUG org.apache.hadoop.yarn.server.resourcemanager.scheduler.capacity.CapacityScheduler: Trying to schedule on node: slave2, available: <memory:4096, vCores:1>
2019-06-07 07:52:26,990 DEBUG org.apache.hadoop.yarn.server.resourcemanager.scheduler.capacity.CapacityScheduler: Trying to schedule on node: slave2, available: <memory:4096, vCores:1>
2019-06-07 07:52:26,990 DEBUG org.apache.hadoop.yarn.server.resourcemanager.scheduler.capacity.ParentQueue: Skip this queue=root, because it doesn't need more resource, schedulingMode=RESPECT_PARTITION_EXCLUSIVITY node-partition=
2019-06-07 07:52:26,990 DEBUG org.apache.hadoop.yarn.server.resourcemanager.scheduler.capacity.ParentQueue: Skip this queue=root, because it doesn't need more resource, schedulingMode=RESPECT_PARTITION_EXCLUSIVITY node-partition=
2019-06-07 07:52:27,407 DEBUG org.apache.hadoop.yarn.server.resourcemanager.rmnode.RMNodeImpl: Processing slave1:39995 of type STATUS_UPDATE
2019-06-07 07:52:27,407 DEBUG org.apache.hadoop.yarn.server.resourcemanager.rmnode.RMNodeImpl: Processing slave1:39995 of type STATUS_UPDATE
2019-06-07 07:52:27,408 DEBUG org.apache.hadoop.yarn.server.resourcemanager.rmnode.RMNodeImpl: Container container_1559893901343_0001_01_000003 is the first container get launched for application application_1559893901343_0001
2019-06-07 07:52:27,408 DEBUG org.apache.hadoop.yarn.server.resourcemanager.rmnode.RMNodeImpl: Container container_1559893901343_0001_01_000003 is the first container get launched for application application_1559893901343_0001
2019-06-07 07:52:27,408 DEBUG org.apache.hadoop.yarn.server.resourcemanager.rmapp.RMAppImpl: Processing event for application_1559893901343_0001 of type APP_RUNNING_ON_NODE
2019-06-07 07:52:27,408 DEBUG org.apache.hadoop.yarn.server.resourcemanager.rmapp.RMAppImpl: Processing event for application_1559893901343_0001 of type APP_RUNNING_ON_NODE
2019-06-07 07:52:27,408 DEBUG org.apache.hadoop.yarn.server.resourcemanager.rmnode.RMNodeImpl: Processing slave1:39995 of type CLEANUP_APP
2019-06-07 07:52:27,408 DEBUG org.apache.hadoop.yarn.server.resourcemanager.rmnode.RMNodeImpl: Processing slave1:39995 of type CLEANUP_APP
2019-06-07 07:52:27,408 DEBUG org.apache.hadoop.yarn.server.resourcemanager.scheduler.capacity.CapacityScheduler: nodeUpdate: slave1:39995 clusterResources: <memory:8192, vCores:2>
2019-06-07 07:52:27,408 DEBUG org.apache.hadoop.yarn.server.resourcemanager.scheduler.capacity.CapacityScheduler: nodeUpdate: slave1:39995 clusterResources: <memory:8192, vCores:2>
2019-06-07 07:52:27,409 INFO org.apache.hadoop.yarn.server.resourcemanager.scheduler.AbstractYarnScheduler: Container container_1559893901343_0001_01_000003 completed with event FINISHED, but corresponding RMContainer doesn't exist.
2019-06-07 07:52:27,409 INFO org.apache.hadoop.yarn.server.resourcemanager.scheduler.AbstractYarnScheduler: Container container_1559893901343_0001_01_000003 completed with event FINISHED, but corresponding RMContainer doesn't exist.
2019-06-07 07:52:27,409 DEBUG org.apache.hadoop.yarn.server.resourcemanager.scheduler.capacity.CapacityScheduler: Node being looked for scheduling slave1:39995 availableResource: <memory:4096, vCores:1>
2019-06-07 07:52:27,409 DEBUG org.apache.hadoop.yarn.server.resourcemanager.scheduler.capacity.CapacityScheduler: Node being looked for scheduling slave1:39995 availableResource: <memory:4096, vCores:1>
2019-06-07 07:52:27,409 DEBUG org.apache.hadoop.yarn.server.resourcemanager.scheduler.capacity.CapacityScheduler: Trying to schedule on node: slave1, available: <memory:4096, vCores:1>
2019-06-07 07:52:27,409 DEBUG org.apache.hadoop.yarn.server.resourcemanager.scheduler.capacity.CapacityScheduler: Trying to schedule on node: slave1, available: <memory:4096, vCores:1>
2019-06-07 07:52:27,410 DEBUG org.apache.hadoop.yarn.server.resourcemanager.scheduler.capacity.ParentQueue: Skip this queue=root, because it doesn't need more resource, schedulingMode=RESPECT_PARTITION_EXCLUSIVITY node-partition=
2019-06-07 07:52:27,410 DEBUG org.apache.hadoop.yarn.server.resourcemanager.scheduler.capacity.ParentQueue: Skip this queue=root, because it doesn't need more resource, schedulingMode=RESPECT_PARTITION_EXCLUSIVITY node-partition=
2019-06-07 07:52:27,991 DEBUG org.apache.hadoop.yarn.server.resourcemanager.rmnode.RMNodeImpl: Processing slave2:38494 of type STATUS_UPDATE
2019-06-07 07:52:27,991 DEBUG org.apache.hadoop.yarn.server.resourcemanager.rmnode.RMNodeImpl: Processing slave2:38494 of type STATUS_UPDATE
2019-06-07 07:52:27,992 DEBUG org.apache.hadoop.yarn.server.resourcemanager.scheduler.capacity.CapacityScheduler: nodeUpdate: slave2:38494 clusterResources: <memory:8192, vCores:2>
2019-06-07 07:52:27,992 DEBUG org.apache.hadoop.yarn.server.resourcemanager.scheduler.capacity.CapacityScheduler: nodeUpdate: slave2:38494 clusterResources: <memory:8192, vCores:2>
2019-06-07 07:52:27,992 DEBUG org.apache.hadoop.yarn.server.resourcemanager.scheduler.capacity.CapacityScheduler: Node being looked for scheduling slave2:38494 availableResource: <memory:4096, vCores:1>
2019-06-07 07:52:27,992 DEBUG org.apache.hadoop.yarn.server.resourcemanager.scheduler.capacity.CapacityScheduler: Node being looked for scheduling slave2:38494 availableResource: <memory:4096, vCores:1>
2019-06-07 07:52:27,992 DEBUG org.apache.hadoop.yarn.server.resourcemanager.scheduler.capacity.CapacityScheduler: Trying to schedule on node: slave2, available: <memory:4096, vCores:1>
2019-06-07 07:52:27,992 DEBUG org.apache.hadoop.yarn.server.resourcemanager.scheduler.capacity.CapacityScheduler: Trying to schedule on node: slave2, available: <memory:4096, vCores:1>
2019-06-07 07:52:27,992 DEBUG org.apache.hadoop.yarn.server.resourcemanager.scheduler.capacity.ParentQueue: Skip this queue=root, because it doesn't need more resource, schedulingMode=RESPECT_PARTITION_EXCLUSIVITY node-partition=
2019-06-07 07:52:27,992 DEBUG org.apache.hadoop.yarn.server.resourcemanager.scheduler.capacity.ParentQueue: Skip this queue=root, because it doesn't need more resource, schedulingMode=RESPECT_PARTITION_EXCLUSIVITY node-partition=
2019-06-07 07:52:28,411 DEBUG org.apache.hadoop.yarn.server.resourcemanager.rmnode.RMNodeImpl: Processing slave1:39995 of type STATUS_UPDATE
2019-06-07 07:52:28,411 DEBUG org.apache.hadoop.yarn.server.resourcemanager.rmnode.RMNodeImpl: Processing slave1:39995 of type STATUS_UPDATE
2019-06-07 07:52:28,411 DEBUG org.apache.hadoop.yarn.server.resourcemanager.scheduler.capacity.CapacityScheduler: nodeUpdate: slave1:39995 clusterResources: <memory:8192, vCores:2>
2019-06-07 07:52:28,411 DEBUG org.apache.hadoop.yarn.server.resourcemanager.scheduler.capacity.CapacityScheduler: nodeUpdate: slave1:39995 clusterResources: <memory:8192, vCores:2>
2019-06-07 07:52:28,411 DEBUG org.apache.hadoop.yarn.server.resourcemanager.scheduler.capacity.CapacityScheduler: Node being looked for scheduling slave1:39995 availableResource: <memory:4096, vCores:1>
2019-06-07 07:52:28,411 DEBUG org.apache.hadoop.yarn.server.resourcemanager.scheduler.capacity.CapacityScheduler: Node being looked for scheduling slave1:39995 availableResource: <memory:4096, vCores:1>
2019-06-07 07:52:28,411 DEBUG org.apache.hadoop.yarn.server.resourcemanager.scheduler.capacity.CapacityScheduler: Trying to schedule on node: slave1, available: <memory:4096, vCores:1>
2019-06-07 07:52:28,411 DEBUG org.apache.hadoop.yarn.server.resourcemanager.scheduler.capacity.CapacityScheduler: Trying to schedule on node: slave1, available: <memory:4096, vCores:1>
2019-06-07 07:52:28,411 DEBUG org.apache.hadoop.yarn.server.resourcemanager.scheduler.capacity.ParentQueue: Skip this queue=root, because it doesn't need more resource, schedulingMode=RESPECT_PARTITION_EXCLUSIVITY node-partition=
2019-06-07 07:52:28,411 DEBUG org.apache.hadoop.yarn.server.resourcemanager.scheduler.capacity.ParentQueue: Skip this queue=root, because it doesn't need more resource, schedulingMode=RESPECT_PARTITION_EXCLUSIVITY node-partition=
2019-06-07 07:52:28,994 DEBUG org.apache.hadoop.yarn.server.resourcemanager.rmnode.RMNodeImpl: Processing slave2:38494 of type STATUS_UPDATE
2019-06-07 07:52:28,994 DEBUG org.apache.hadoop.yarn.server.resourcemanager.rmnode.RMNodeImpl: Processing slave2:38494 of type STATUS_UPDATE
2019-06-07 07:52:28,994 DEBUG org.apache.hadoop.yarn.server.resourcemanager.scheduler.capacity.CapacityScheduler: nodeUpdate: slave2:38494 clusterResources: <memory:8192, vCores:2>
2019-06-07 07:52:28,994 DEBUG org.apache.hadoop.yarn.server.resourcemanager.scheduler.capacity.CapacityScheduler: nodeUpdate: slave2:38494 clusterResources: <memory:8192, vCores:2>
2019-06-07 07:52:28,994 DEBUG org.apache.hadoop.yarn.server.resourcemanager.scheduler.capacity.CapacityScheduler: Node being looked for scheduling slave2:38494 availableResource: <memory:4096, vCores:1>
2019-06-07 07:52:28,994 DEBUG org.apache.hadoop.yarn.server.resourcemanager.scheduler.capacity.CapacityScheduler: Node being looked for scheduling slave2:38494 availableResource: <memory:4096, vCores:1>
2019-06-07 07:52:28,994 DEBUG org.apache.hadoop.yarn.server.resourcemanager.scheduler.capacity.CapacityScheduler: Trying to schedule on node: slave2, available: <memory:4096, vCores:1>
2019-06-07 07:52:28,994 DEBUG org.apache.hadoop.yarn.server.resourcemanager.scheduler.capacity.CapacityScheduler: Trying to schedule on node: slave2, available: <memory:4096, vCores:1>
2019-06-07 07:52:28,995 DEBUG org.apache.hadoop.yarn.server.resourcemanager.scheduler.capacity.ParentQueue: Skip this queue=root, because it doesn't need more resource, schedulingMode=RESPECT_PARTITION_EXCLUSIVITY node-partition=
2019-06-07 07:52:28,995 DEBUG org.apache.hadoop.yarn.server.resourcemanager.scheduler.capacity.ParentQueue: Skip this queue=root, because it doesn't need more resource, schedulingMode=RESPECT_PARTITION_EXCLUSIVITY node-partition=
2019-06-07 07:52:29,415 DEBUG org.apache.hadoop.yarn.server.resourcemanager.rmnode.RMNodeImpl: Processing slave1:39995 of type STATUS_UPDATE
2019-06-07 07:52:29,415 DEBUG org.apache.hadoop.yarn.server.resourcemanager.rmnode.RMNodeImpl: Processing slave1:39995 of type STATUS_UPDATE
2019-06-07 07:52:29,416 DEBUG org.apache.hadoop.yarn.server.resourcemanager.scheduler.capacity.CapacityScheduler: nodeUpdate: slave1:39995 clusterResources: <memory:8192, vCores:2>
2019-06-07 07:52:29,416 DEBUG org.apache.hadoop.yarn.server.resourcemanager.scheduler.capacity.CapacityScheduler: nodeUpdate: slave1:39995 clusterResources: <memory:8192, vCores:2>
2019-06-07 07:52:29,416 DEBUG org.apache.hadoop.yarn.server.resourcemanager.scheduler.capacity.CapacityScheduler: Node being looked for scheduling slave1:39995 availableResource: <memory:4096, vCores:1>
2019-06-07 07:52:29,416 DEBUG org.apache.hadoop.yarn.server.resourcemanager.scheduler.capacity.CapacityScheduler: Node being looked for scheduling slave1:39995 availableResource: <memory:4096, vCores:1>
2019-06-07 07:52:29,416 DEBUG org.apache.hadoop.yarn.server.resourcemanager.scheduler.capacity.CapacityScheduler: Trying to schedule on node: slave1, available: <memory:4096, vCores:1>
2019-06-07 07:52:29,416 DEBUG org.apache.hadoop.yarn.server.resourcemanager.scheduler.capacity.CapacityScheduler: Trying to schedule on node: slave1, available: <memory:4096, vCores:1>
2019-06-07 07:52:29,416 DEBUG org.apache.hadoop.yarn.server.resourcemanager.scheduler.capacity.ParentQueue: Skip this queue=root, because it doesn't need more resource, schedulingMode=RESPECT_PARTITION_EXCLUSIVITY node-partition=
2019-06-07 07:52:29,416 DEBUG org.apache.hadoop.yarn.server.resourcemanager.scheduler.capacity.ParentQueue: Skip this queue=root, because it doesn't need more resource, schedulingMode=RESPECT_PARTITION_EXCLUSIVITY node-partition=
2019-06-07 07:52:29,999 DEBUG org.apache.hadoop.yarn.server.resourcemanager.rmnode.RMNodeImpl: Processing slave2:38494 of type STATUS_UPDATE
2019-06-07 07:52:29,999 DEBUG org.apache.hadoop.yarn.server.resourcemanager.rmnode.RMNodeImpl: Processing slave2:38494 of type STATUS_UPDATE
2019-06-07 07:52:29,999 DEBUG org.apache.hadoop.yarn.server.resourcemanager.scheduler.capacity.CapacityScheduler: nodeUpdate: slave2:38494 clusterResources: <memory:8192, vCores:2>
2019-06-07 07:52:29,999 DEBUG org.apache.hadoop.yarn.server.resourcemanager.scheduler.capacity.CapacityScheduler: nodeUpdate: slave2:38494 clusterResources: <memory:8192, vCores:2>
2019-06-07 07:52:29,999 DEBUG org.apache.hadoop.yarn.server.resourcemanager.scheduler.capacity.CapacityScheduler: Node being looked for scheduling slave2:38494 availableResource: <memory:4096, vCores:1>
2019-06-07 07:52:29,999 DEBUG org.apache.hadoop.yarn.server.resourcemanager.scheduler.capacity.CapacityScheduler: Node being looked for scheduling slave2:38494 availableResource: <memory:4096, vCores:1>
2019-06-07 07:52:29,999 DEBUG org.apache.hadoop.yarn.server.resourcemanager.scheduler.capacity.CapacityScheduler: Trying to schedule on node: slave2, available: <memory:4096, vCores:1>
2019-06-07 07:52:29,999 DEBUG org.apache.hadoop.yarn.server.resourcemanager.scheduler.capacity.CapacityScheduler: Trying to schedule on node: slave2, available: <memory:4096, vCores:1>
2019-06-07 07:52:29,999 DEBUG org.apache.hadoop.yarn.server.resourcemanager.scheduler.capacity.ParentQueue: Skip this queue=root, because it doesn't need more resource, schedulingMode=RESPECT_PARTITION_EXCLUSIVITY node-partition=
2019-06-07 07:52:29,999 DEBUG org.apache.hadoop.yarn.server.resourcemanager.scheduler.capacity.ParentQueue: Skip this queue=root, because it doesn't need more resource, schedulingMode=RESPECT_PARTITION_EXCLUSIVITY node-partition=
2019-06-07 07:52:30,419 DEBUG org.apache.hadoop.yarn.server.resourcemanager.rmnode.RMNodeImpl: Processing slave1:39995 of type STATUS_UPDATE
2019-06-07 07:52:30,419 DEBUG org.apache.hadoop.yarn.server.resourcemanager.rmnode.RMNodeImpl: Processing slave1:39995 of type STATUS_UPDATE
2019-06-07 07:52:30,419 DEBUG org.apache.hadoop.yarn.server.resourcemanager.scheduler.capacity.CapacityScheduler: nodeUpdate: slave1:39995 clusterResources: <memory:8192, vCores:2>
2019-06-07 07:52:30,419 DEBUG org.apache.hadoop.yarn.server.resourcemanager.scheduler.capacity.CapacityScheduler: nodeUpdate: slave1:39995 clusterResources: <memory:8192, vCores:2>
2019-06-07 07:52:30,420 DEBUG org.apache.hadoop.yarn.server.resourcemanager.scheduler.capacity.CapacityScheduler: Node being looked for scheduling slave1:39995 availableResource: <memory:4096, vCores:1>
2019-06-07 07:52:30,420 DEBUG org.apache.hadoop.yarn.server.resourcemanager.scheduler.capacity.CapacityScheduler: Node being looked for scheduling slave1:39995 availableResource: <memory:4096, vCores:1>
2019-06-07 07:52:30,420 DEBUG org.apache.hadoop.yarn.server.resourcemanager.scheduler.capacity.CapacityScheduler: Trying to schedule on node: slave1, available: <memory:4096, vCores:1>
2019-06-07 07:52:30,420 DEBUG org.apache.hadoop.yarn.server.resourcemanager.scheduler.capacity.CapacityScheduler: Trying to schedule on node: slave1, available: <memory:4096, vCores:1>
2019-06-07 07:52:30,420 DEBUG org.apache.hadoop.yarn.server.resourcemanager.scheduler.capacity.ParentQueue: Skip this queue=root, because it doesn't need more resource, schedulingMode=RESPECT_PARTITION_EXCLUSIVITY node-partition=
2019-06-07 07:52:30,420 DEBUG org.apache.hadoop.yarn.server.resourcemanager.scheduler.capacity.ParentQueue: Skip this queue=root, because it doesn't need more resource, schedulingMode=RESPECT_PARTITION_EXCLUSIVITY node-partition=
2019-06-07 07:52:31,002 DEBUG org.apache.hadoop.yarn.server.resourcemanager.rmnode.RMNodeImpl: Processing slave2:38494 of type STATUS_UPDATE
2019-06-07 07:52:31,002 DEBUG org.apache.hadoop.yarn.server.resourcemanager.rmnode.RMNodeImpl: Processing slave2:38494 of type STATUS_UPDATE
2019-06-07 07:52:31,003 DEBUG org.apache.hadoop.yarn.server.resourcemanager.scheduler.capacity.CapacityScheduler: nodeUpdate: slave2:38494 clusterResources: <memory:8192, vCores:2>
2019-06-07 07:52:31,003 DEBUG org.apache.hadoop.yarn.server.resourcemanager.scheduler.capacity.CapacityScheduler: nodeUpdate: slave2:38494 clusterResources: <memory:8192, vCores:2>
2019-06-07 07:52:31,003 DEBUG org.apache.hadoop.yarn.server.resourcemanager.scheduler.capacity.CapacityScheduler: Node being looked for scheduling slave2:38494 availableResource: <memory:4096, vCores:1>
2019-06-07 07:52:31,003 DEBUG org.apache.hadoop.yarn.server.resourcemanager.scheduler.capacity.CapacityScheduler: Node being looked for scheduling slave2:38494 availableResource: <memory:4096, vCores:1>
2019-06-07 07:52:31,003 DEBUG org.apache.hadoop.yarn.server.resourcemanager.scheduler.capacity.CapacityScheduler: Trying to schedule on node: slave2, available: <memory:4096, vCores:1>
2019-06-07 07:52:31,003 DEBUG org.apache.hadoop.yarn.server.resourcemanager.scheduler.capacity.CapacityScheduler: Trying to schedule on node: slave2, available: <memory:4096, vCores:1>
2019-06-07 07:52:31,003 DEBUG org.apache.hadoop.yarn.server.resourcemanager.scheduler.capacity.ParentQueue: Skip this queue=root, because it doesn't need more resource, schedulingMode=RESPECT_PARTITION_EXCLUSIVITY node-partition=
2019-06-07 07:52:31,003 DEBUG org.apache.hadoop.yarn.server.resourcemanager.scheduler.capacity.ParentQueue: Skip this queue=root, because it doesn't need more resource, schedulingMode=RESPECT_PARTITION_EXCLUSIVITY node-partition=
2019-06-07 07:52:31,424 DEBUG org.apache.hadoop.yarn.server.resourcemanager.rmnode.RMNodeImpl: Processing slave1:39995 of type STATUS_UPDATE
2019-06-07 07:52:31,424 DEBUG org.apache.hadoop.yarn.server.resourcemanager.rmnode.RMNodeImpl: Processing slave1:39995 of type STATUS_UPDATE
2019-06-07 07:52:31,424 DEBUG org.apache.hadoop.yarn.server.resourcemanager.scheduler.capacity.CapacityScheduler: nodeUpdate: slave1:39995 clusterResources: <memory:8192, vCores:2>
2019-06-07 07:52:31,424 DEBUG org.apache.hadoop.yarn.server.resourcemanager.scheduler.capacity.CapacityScheduler: nodeUpdate: slave1:39995 clusterResources: <memory:8192, vCores:2>
2019-06-07 07:52:31,424 DEBUG org.apache.hadoop.yarn.server.resourcemanager.scheduler.capacity.CapacityScheduler: Node being looked for scheduling slave1:39995 availableResource: <memory:4096, vCores:1>
2019-06-07 07:52:31,424 DEBUG org.apache.hadoop.yarn.server.resourcemanager.scheduler.capacity.CapacityScheduler: Node being looked for scheduling slave1:39995 availableResource: <memory:4096, vCores:1>
2019-06-07 07:52:31,424 DEBUG org.apache.hadoop.yarn.server.resourcemanager.scheduler.capacity.CapacityScheduler: Trying to schedule on node: slave1, available: <memory:4096, vCores:1>
2019-06-07 07:52:31,424 DEBUG org.apache.hadoop.yarn.server.resourcemanager.scheduler.capacity.CapacityScheduler: Trying to schedule on node: slave1, available: <memory:4096, vCores:1>
2019-06-07 07:52:31,424 DEBUG org.apache.hadoop.yarn.server.resourcemanager.scheduler.capacity.ParentQueue: Skip this queue=root, because it doesn't need more resource, schedulingMode=RESPECT_PARTITION_EXCLUSIVITY node-partition=
2019-06-07 07:52:31,424 DEBUG org.apache.hadoop.yarn.server.resourcemanager.scheduler.capacity.ParentQueue: Skip this queue=root, because it doesn't need more resource, schedulingMode=RESPECT_PARTITION_EXCLUSIVITY node-partition=
2019-06-07 07:52:32,005 DEBUG org.apache.hadoop.yarn.server.resourcemanager.rmnode.RMNodeImpl: Processing slave2:38494 of type STATUS_UPDATE
2019-06-07 07:52:32,005 DEBUG org.apache.hadoop.yarn.server.resourcemanager.rmnode.RMNodeImpl: Processing slave2:38494 of type STATUS_UPDATE
2019-06-07 07:52:32,005 DEBUG org.apache.hadoop.yarn.server.resourcemanager.scheduler.capacity.CapacityScheduler: nodeUpdate: slave2:38494 clusterResources: <memory:8192, vCores:2>
2019-06-07 07:52:32,005 DEBUG org.apache.hadoop.yarn.server.resourcemanager.scheduler.capacity.CapacityScheduler: nodeUpdate: slave2:38494 clusterResources: <memory:8192, vCores:2>
2019-06-07 07:52:32,006 DEBUG org.apache.hadoop.yarn.server.resourcemanager.scheduler.capacity.CapacityScheduler: Node being looked for scheduling slave2:38494 availableResource: <memory:4096, vCores:1>
2019-06-07 07:52:32,006 DEBUG org.apache.hadoop.yarn.server.resourcemanager.scheduler.capacity.CapacityScheduler: Node being looked for scheduling slave2:38494 availableResource: <memory:4096, vCores:1>
2019-06-07 07:52:32,006 DEBUG org.apache.hadoop.yarn.server.resourcemanager.scheduler.capacity.CapacityScheduler: Trying to schedule on node: slave2, available: <memory:4096, vCores:1>
2019-06-07 07:52:32,006 DEBUG org.apache.hadoop.yarn.server.resourcemanager.scheduler.capacity.CapacityScheduler: Trying to schedule on node: slave2, available: <memory:4096, vCores:1>
2019-06-07 07:52:32,006 DEBUG org.apache.hadoop.yarn.server.resourcemanager.scheduler.capacity.ParentQueue: Skip this queue=root, because it doesn't need more resource, schedulingMode=RESPECT_PARTITION_EXCLUSIVITY node-partition=
2019-06-07 07:52:32,006 DEBUG org.apache.hadoop.yarn.server.resourcemanager.scheduler.capacity.ParentQueue: Skip this queue=root, because it doesn't need more resource, schedulingMode=RESPECT_PARTITION_EXCLUSIVITY node-partition=
2019-06-07 07:52:32,427 DEBUG org.apache.hadoop.yarn.server.resourcemanager.rmnode.RMNodeImpl: Processing slave1:39995 of type STATUS_UPDATE
2019-06-07 07:52:32,427 DEBUG org.apache.hadoop.yarn.server.resourcemanager.rmnode.RMNodeImpl: Processing slave1:39995 of type STATUS_UPDATE
2019-06-07 07:52:32,427 DEBUG org.apache.hadoop.yarn.server.resourcemanager.scheduler.capacity.CapacityScheduler: nodeUpdate: slave1:39995 clusterResources: <memory:8192, vCores:2>
2019-06-07 07:52:32,427 DEBUG org.apache.hadoop.yarn.server.resourcemanager.scheduler.capacity.CapacityScheduler: nodeUpdate: slave1:39995 clusterResources: <memory:8192, vCores:2>
2019-06-07 07:52:32,427 DEBUG org.apache.hadoop.yarn.server.resourcemanager.scheduler.capacity.CapacityScheduler: Node being looked for scheduling slave1:39995 availableResource: <memory:4096, vCores:1>
2019-06-07 07:52:32,427 DEBUG org.apache.hadoop.yarn.server.resourcemanager.scheduler.capacity.CapacityScheduler: Node being looked for scheduling slave1:39995 availableResource: <memory:4096, vCores:1>
2019-06-07 07:52:32,427 DEBUG org.apache.hadoop.yarn.server.resourcemanager.scheduler.capacity.CapacityScheduler: Trying to schedule on node: slave1, available: <memory:4096, vCores:1>
2019-06-07 07:52:32,427 DEBUG org.apache.hadoop.yarn.server.resourcemanager.scheduler.capacity.CapacityScheduler: Trying to schedule on node: slave1, available: <memory:4096, vCores:1>
2019-06-07 07:52:32,427 DEBUG org.apache.hadoop.yarn.server.resourcemanager.scheduler.capacity.ParentQueue: Skip this queue=root, because it doesn't need more resource, schedulingMode=RESPECT_PARTITION_EXCLUSIVITY node-partition=
2019-06-07 07:52:32,427 DEBUG org.apache.hadoop.yarn.server.resourcemanager.scheduler.capacity.ParentQueue: Skip this queue=root, because it doesn't need more resource, schedulingMode=RESPECT_PARTITION_EXCLUSIVITY node-partition=
2019-06-07 07:52:33,008 DEBUG org.apache.hadoop.yarn.server.resourcemanager.rmnode.RMNodeImpl: Processing slave2:38494 of type STATUS_UPDATE
2019-06-07 07:52:33,008 DEBUG org.apache.hadoop.yarn.server.resourcemanager.rmnode.RMNodeImpl: Processing slave2:38494 of type STATUS_UPDATE
2019-06-07 07:52:33,008 DEBUG org.apache.hadoop.yarn.server.resourcemanager.scheduler.capacity.CapacityScheduler: nodeUpdate: slave2:38494 clusterResources: <memory:8192, vCores:2>
2019-06-07 07:52:33,008 DEBUG org.apache.hadoop.yarn.server.resourcemanager.scheduler.capacity.CapacityScheduler: nodeUpdate: slave2:38494 clusterResources: <memory:8192, vCores:2>
2019-06-07 07:52:33,008 DEBUG org.apache.hadoop.yarn.server.resourcemanager.scheduler.capacity.CapacityScheduler: Node being looked for scheduling slave2:38494 availableResource: <memory:4096, vCores:1>
2019-06-07 07:52:33,008 DEBUG org.apache.hadoop.yarn.server.resourcemanager.scheduler.capacity.CapacityScheduler: Node being looked for scheduling slave2:38494 availableResource: <memory:4096, vCores:1>
2019-06-07 07:52:33,008 DEBUG org.apache.hadoop.yarn.server.resourcemanager.scheduler.capacity.CapacityScheduler: Trying to schedule on node: slave2, available: <memory:4096, vCores:1>
2019-06-07 07:52:33,008 DEBUG org.apache.hadoop.yarn.server.resourcemanager.scheduler.capacity.CapacityScheduler: Trying to schedule on node: slave2, available: <memory:4096, vCores:1>
2019-06-07 07:52:33,008 DEBUG org.apache.hadoop.yarn.server.resourcemanager.scheduler.capacity.ParentQueue: Skip this queue=root, because it doesn't need more resource, schedulingMode=RESPECT_PARTITION_EXCLUSIVITY node-partition=
2019-06-07 07:52:33,008 DEBUG org.apache.hadoop.yarn.server.resourcemanager.scheduler.capacity.ParentQueue: Skip this queue=root, because it doesn't need more resource, schedulingMode=RESPECT_PARTITION_EXCLUSIVITY node-partition=
2019-06-07 07:52:33,430 DEBUG org.apache.hadoop.yarn.server.resourcemanager.rmnode.RMNodeImpl: Processing slave1:39995 of type STATUS_UPDATE
2019-06-07 07:52:33,430 DEBUG org.apache.hadoop.yarn.server.resourcemanager.rmnode.RMNodeImpl: Processing slave1:39995 of type STATUS_UPDATE
2019-06-07 07:52:33,430 DEBUG org.apache.hadoop.yarn.server.resourcemanager.scheduler.capacity.CapacityScheduler: nodeUpdate: slave1:39995 clusterResources: <memory:8192, vCores:2>
2019-06-07 07:52:33,430 DEBUG org.apache.hadoop.yarn.server.resourcemanager.scheduler.capacity.CapacityScheduler: nodeUpdate: slave1:39995 clusterResources: <memory:8192, vCores:2>
2019-06-07 07:52:33,430 DEBUG org.apache.hadoop.yarn.server.resourcemanager.scheduler.capacity.CapacityScheduler: Node being looked for scheduling slave1:39995 availableResource: <memory:4096, vCores:1>
2019-06-07 07:52:33,430 DEBUG org.apache.hadoop.yarn.server.resourcemanager.scheduler.capacity.CapacityScheduler: Node being looked for scheduling slave1:39995 availableResource: <memory:4096, vCores:1>
2019-06-07 07:52:33,430 DEBUG org.apache.hadoop.yarn.server.resourcemanager.scheduler.capacity.CapacityScheduler: Trying to schedule on node: slave1, available: <memory:4096, vCores:1>
2019-06-07 07:52:33,430 DEBUG org.apache.hadoop.yarn.server.resourcemanager.scheduler.capacity.CapacityScheduler: Trying to schedule on node: slave1, available: <memory:4096, vCores:1>
2019-06-07 07:52:33,431 DEBUG org.apache.hadoop.yarn.server.resourcemanager.scheduler.capacity.ParentQueue: Skip this queue=root, because it doesn't need more resource, schedulingMode=RESPECT_PARTITION_EXCLUSIVITY node-partition=
2019-06-07 07:52:33,431 DEBUG org.apache.hadoop.yarn.server.resourcemanager.scheduler.capacity.ParentQueue: Skip this queue=root, because it doesn't need more resource, schedulingMode=RESPECT_PARTITION_EXCLUSIVITY node-partition=
2019-06-07 07:52:34,011 DEBUG org.apache.hadoop.yarn.server.resourcemanager.rmnode.RMNodeImpl: Processing slave2:38494 of type STATUS_UPDATE
2019-06-07 07:52:34,011 DEBUG org.apache.hadoop.yarn.server.resourcemanager.rmnode.RMNodeImpl: Processing slave2:38494 of type STATUS_UPDATE
2019-06-07 07:52:34,011 DEBUG org.apache.hadoop.yarn.server.resourcemanager.scheduler.capacity.CapacityScheduler: nodeUpdate: slave2:38494 clusterResources: <memory:8192, vCores:2>
2019-06-07 07:52:34,011 DEBUG org.apache.hadoop.yarn.server.resourcemanager.scheduler.capacity.CapacityScheduler: nodeUpdate: slave2:38494 clusterResources: <memory:8192, vCores:2>
2019-06-07 07:52:34,011 DEBUG org.apache.hadoop.yarn.server.resourcemanager.scheduler.capacity.CapacityScheduler: Node being looked for scheduling slave2:38494 availableResource: <memory:4096, vCores:1>
2019-06-07 07:52:34,011 DEBUG org.apache.hadoop.yarn.server.resourcemanager.scheduler.capacity.CapacityScheduler: Node being looked for scheduling slave2:38494 availableResource: <memory:4096, vCores:1>
2019-06-07 07:52:34,011 DEBUG org.apache.hadoop.yarn.server.resourcemanager.scheduler.capacity.CapacityScheduler: Trying to schedule on node: slave2, available: <memory:4096, vCores:1>
2019-06-07 07:52:34,011 DEBUG org.apache.hadoop.yarn.server.resourcemanager.scheduler.capacity.CapacityScheduler: Trying to schedule on node: slave2, available: <memory:4096, vCores:1>
2019-06-07 07:52:34,011 DEBUG org.apache.hadoop.yarn.server.resourcemanager.scheduler.capacity.ParentQueue: Skip this queue=root, because it doesn't need more resource, schedulingMode=RESPECT_PARTITION_EXCLUSIVITY node-partition=
2019-06-07 07:52:34,011 DEBUG org.apache.hadoop.yarn.server.resourcemanager.scheduler.capacity.ParentQueue: Skip this queue=root, because it doesn't need more resource, schedulingMode=RESPECT_PARTITION_EXCLUSIVITY node-partition=
2019-06-07 07:52:34,433 DEBUG org.apache.hadoop.yarn.server.resourcemanager.rmnode.RMNodeImpl: Processing slave1:39995 of type STATUS_UPDATE
2019-06-07 07:52:34,433 DEBUG org.apache.hadoop.yarn.server.resourcemanager.rmnode.RMNodeImpl: Processing slave1:39995 of type STATUS_UPDATE
2019-06-07 07:52:34,433 DEBUG org.apache.hadoop.yarn.server.resourcemanager.scheduler.capacity.CapacityScheduler: nodeUpdate: slave1:39995 clusterResources: <memory:8192, vCores:2>
2019-06-07 07:52:34,433 DEBUG org.apache.hadoop.yarn.server.resourcemanager.scheduler.capacity.CapacityScheduler: nodeUpdate: slave1:39995 clusterResources: <memory:8192, vCores:2>
2019-06-07 07:52:34,433 DEBUG org.apache.hadoop.yarn.server.resourcemanager.scheduler.capacity.CapacityScheduler: Node being looked for scheduling slave1:39995 availableResource: <memory:4096, vCores:1>
2019-06-07 07:52:34,433 DEBUG org.apache.hadoop.yarn.server.resourcemanager.scheduler.capacity.CapacityScheduler: Node being looked for scheduling slave1:39995 availableResource: <memory:4096, vCores:1>
2019-06-07 07:52:34,433 DEBUG org.apache.hadoop.yarn.server.resourcemanager.scheduler.capacity.CapacityScheduler: Trying to schedule on node: slave1, available: <memory:4096, vCores:1>
2019-06-07 07:52:34,433 DEBUG org.apache.hadoop.yarn.server.resourcemanager.scheduler.capacity.CapacityScheduler: Trying to schedule on node: slave1, available: <memory:4096, vCores:1>
2019-06-07 07:52:34,433 DEBUG org.apache.hadoop.yarn.server.resourcemanager.scheduler.capacity.ParentQueue: Skip this queue=root, because it doesn't need more resource, schedulingMode=RESPECT_PARTITION_EXCLUSIVITY node-partition=
2019-06-07 07:52:34,433 DEBUG org.apache.hadoop.yarn.server.resourcemanager.scheduler.capacity.ParentQueue: Skip this queue=root, because it doesn't need more resource, schedulingMode=RESPECT_PARTITION_EXCLUSIVITY node-partition=
2019-06-07 07:52:36,741 DEBUG org.apache.hadoop.yarn.server.resourcemanager.rmnode.RMNodeImpl: Processing slave1:39995 of type STATUS_UPDATE
2019-06-07 07:52:36,741 DEBUG org.apache.hadoop.yarn.server.resourcemanager.rmnode.RMNodeImpl: Processing slave1:39995 of type STATUS_UPDATE
2019-06-07 07:52:36,741 DEBUG org.apache.hadoop.yarn.server.resourcemanager.scheduler.capacity.CapacityScheduler: nodeUpdate: slave1:39995 clusterResources: <memory:8192, vCores:2>
2019-06-07 07:52:36,741 DEBUG org.apache.hadoop.yarn.server.resourcemanager.scheduler.capacity.CapacityScheduler: nodeUpdate: slave1:39995 clusterResources: <memory:8192, vCores:2>
2019-06-07 07:52:36,742 DEBUG org.apache.hadoop.yarn.server.resourcemanager.scheduler.capacity.CapacityScheduler: Node being looked for scheduling slave1:39995 availableResource: <memory:4096, vCores:1>
2019-06-07 07:52:36,742 DEBUG org.apache.hadoop.yarn.server.resourcemanager.scheduler.capacity.CapacityScheduler: Node being looked for scheduling slave1:39995 availableResource: <memory:4096, vCores:1>
2019-06-07 07:52:36,742 DEBUG org.apache.hadoop.yarn.server.resourcemanager.scheduler.capacity.CapacityScheduler: Trying to schedule on node: slave1, available: <memory:4096, vCores:1>
2019-06-07 07:52:36,742 DEBUG org.apache.hadoop.yarn.server.resourcemanager.scheduler.capacity.CapacityScheduler: Trying to schedule on node: slave1, available: <memory:4096, vCores:1>
2019-06-07 07:52:36,742 DEBUG org.apache.hadoop.yarn.server.resourcemanager.scheduler.capacity.ParentQueue: Skip this queue=root, because it doesn't need more resource, schedulingMode=RESPECT_PARTITION_EXCLUSIVITY node-partition=
2019-06-07 07:52:36,742 DEBUG org.apache.hadoop.yarn.server.resourcemanager.scheduler.capacity.ParentQueue: Skip this queue=root, because it doesn't need more resource, schedulingMode=RESPECT_PARTITION_EXCLUSIVITY node-partition=
2019-06-07 07:52:36,743 DEBUG org.apache.hadoop.yarn.server.resourcemanager.rmnode.RMNodeImpl: Processing slave2:38494 of type STATUS_UPDATE
2019-06-07 07:52:36,743 DEBUG org.apache.hadoop.yarn.server.resourcemanager.rmnode.RMNodeImpl: Processing slave2:38494 of type STATUS_UPDATE
2019-06-07 07:52:36,743 DEBUG org.apache.hadoop.yarn.server.resourcemanager.scheduler.capacity.CapacityScheduler: nodeUpdate: slave2:38494 clusterResources: <memory:8192, vCores:2>
2019-06-07 07:52:36,743 DEBUG org.apache.hadoop.yarn.server.resourcemanager.scheduler.capacity.CapacityScheduler: nodeUpdate: slave2:38494 clusterResources: <memory:8192, vCores:2>
2019-06-07 07:52:36,743 DEBUG org.apache.hadoop.yarn.server.resourcemanager.scheduler.capacity.CapacityScheduler: Node being looked for scheduling slave2:38494 availableResource: <memory:4096, vCores:1>
2019-06-07 07:52:36,743 DEBUG org.apache.hadoop.yarn.server.resourcemanager.scheduler.capacity.CapacityScheduler: Node being looked for scheduling slave2:38494 availableResource: <memory:4096, vCores:1>
2019-06-07 07:52:36,743 DEBUG org.apache.hadoop.yarn.server.resourcemanager.scheduler.capacity.CapacityScheduler: Trying to schedule on node: slave2, available: <memory:4096, vCores:1>
2019-06-07 07:52:36,743 DEBUG org.apache.hadoop.yarn.server.resourcemanager.scheduler.capacity.CapacityScheduler: Trying to schedule on node: slave2, available: <memory:4096, vCores:1>
2019-06-07 07:52:36,743 DEBUG org.apache.hadoop.yarn.server.resourcemanager.scheduler.capacity.ParentQueue: Skip this queue=root, because it doesn't need more resource, schedulingMode=RESPECT_PARTITION_EXCLUSIVITY node-partition=
2019-06-07 07:52:36,743 DEBUG org.apache.hadoop.yarn.server.resourcemanager.scheduler.capacity.ParentQueue: Skip this queue=root, because it doesn't need more resource, schedulingMode=RESPECT_PARTITION_EXCLUSIVITY node-partition=
2019-06-07 07:52:37,746 DEBUG org.apache.hadoop.yarn.server.resourcemanager.rmnode.RMNodeImpl: Processing slave1:39995 of type STATUS_UPDATE
2019-06-07 07:52:37,746 DEBUG org.apache.hadoop.yarn.server.resourcemanager.rmnode.RMNodeImpl: Processing slave1:39995 of type STATUS_UPDATE
2019-06-07 07:52:37,747 DEBUG org.apache.hadoop.yarn.server.resourcemanager.rmnode.RMNodeImpl: Processing slave2:38494 of type STATUS_UPDATE
2019-06-07 07:52:37,747 DEBUG org.apache.hadoop.yarn.server.resourcemanager.rmnode.RMNodeImpl: Processing slave2:38494 of type STATUS_UPDATE
2019-06-07 07:52:37,747 DEBUG org.apache.hadoop.yarn.server.resourcemanager.scheduler.capacity.CapacityScheduler: nodeUpdate: slave1:39995 clusterResources: <memory:8192, vCores:2>
2019-06-07 07:52:37,747 DEBUG org.apache.hadoop.yarn.server.resourcemanager.scheduler.capacity.CapacityScheduler: nodeUpdate: slave1:39995 clusterResources: <memory:8192, vCores:2>
2019-06-07 07:52:37,747 DEBUG org.apache.hadoop.yarn.server.resourcemanager.scheduler.capacity.CapacityScheduler: Node being looked for scheduling slave1:39995 availableResource: <memory:4096, vCores:1>
2019-06-07 07:52:37,747 DEBUG org.apache.hadoop.yarn.server.resourcemanager.scheduler.capacity.CapacityScheduler: Node being looked for scheduling slave1:39995 availableResource: <memory:4096, vCores:1>
2019-06-07 07:52:37,747 DEBUG org.apache.hadoop.yarn.server.resourcemanager.scheduler.capacity.CapacityScheduler: Trying to schedule on node: slave1, available: <memory:4096, vCores:1>
2019-06-07 07:52:37,747 DEBUG org.apache.hadoop.yarn.server.resourcemanager.scheduler.capacity.CapacityScheduler: Trying to schedule on node: slave1, available: <memory:4096, vCores:1>
2019-06-07 07:52:37,747 DEBUG org.apache.hadoop.yarn.server.resourcemanager.scheduler.capacity.ParentQueue: Skip this queue=root, because it doesn't need more resource, schedulingMode=RESPECT_PARTITION_EXCLUSIVITY node-partition=
2019-06-07 07:52:37,747 DEBUG org.apache.hadoop.yarn.server.resourcemanager.scheduler.capacity.ParentQueue: Skip this queue=root, because it doesn't need more resource, schedulingMode=RESPECT_PARTITION_EXCLUSIVITY node-partition=
2019-06-07 07:52:37,747 DEBUG org.apache.hadoop.yarn.server.resourcemanager.scheduler.capacity.CapacityScheduler: nodeUpdate: slave2:38494 clusterResources: <memory:8192, vCores:2>
2019-06-07 07:52:37,747 DEBUG org.apache.hadoop.yarn.server.resourcemanager.scheduler.capacity.CapacityScheduler: nodeUpdate: slave2:38494 clusterResources: <memory:8192, vCores:2>
2019-06-07 07:52:37,747 DEBUG org.apache.hadoop.yarn.server.resourcemanager.scheduler.capacity.CapacityScheduler: Node being looked for scheduling slave2:38494 availableResource: <memory:4096, vCores:1>
2019-06-07 07:52:37,747 DEBUG org.apache.hadoop.yarn.server.resourcemanager.scheduler.capacity.CapacityScheduler: Node being looked for scheduling slave2:38494 availableResource: <memory:4096, vCores:1>
2019-06-07 07:52:37,747 DEBUG org.apache.hadoop.yarn.server.resourcemanager.scheduler.capacity.CapacityScheduler: Trying to schedule on node: slave2, available: <memory:4096, vCores:1>
2019-06-07 07:52:37,747 DEBUG org.apache.hadoop.yarn.server.resourcemanager.scheduler.capacity.CapacityScheduler: Trying to schedule on node: slave2, available: <memory:4096, vCores:1>
2019-06-07 07:52:37,747 DEBUG org.apache.hadoop.yarn.server.resourcemanager.scheduler.capacity.ParentQueue: Skip this queue=root, because it doesn't need more resource, schedulingMode=RESPECT_PARTITION_EXCLUSIVITY node-partition=
2019-06-07 07:52:37,747 DEBUG org.apache.hadoop.yarn.server.resourcemanager.scheduler.capacity.ParentQueue: Skip this queue=root, because it doesn't need more resource, schedulingMode=RESPECT_PARTITION_EXCLUSIVITY node-partition=
2019-06-07 07:52:38,751 DEBUG org.apache.hadoop.yarn.server.resourcemanager.rmnode.RMNodeImpl: Processing slave1:39995 of type STATUS_UPDATE
2019-06-07 07:52:38,751 DEBUG org.apache.hadoop.yarn.server.resourcemanager.rmnode.RMNodeImpl: Processing slave1:39995 of type STATUS_UPDATE
2019-06-07 07:52:38,751 DEBUG org.apache.hadoop.yarn.server.resourcemanager.scheduler.capacity.CapacityScheduler: nodeUpdate: slave1:39995 clusterResources: <memory:8192, vCores:2>
2019-06-07 07:52:38,751 DEBUG org.apache.hadoop.yarn.server.resourcemanager.scheduler.capacity.CapacityScheduler: nodeUpdate: slave1:39995 clusterResources: <memory:8192, vCores:2>
2019-06-07 07:52:38,751 DEBUG org.apache.hadoop.yarn.server.resourcemanager.scheduler.capacity.CapacityScheduler: Node being looked for scheduling slave1:39995 availableResource: <memory:4096, vCores:1>
2019-06-07 07:52:38,751 DEBUG org.apache.hadoop.yarn.server.resourcemanager.scheduler.capacity.CapacityScheduler: Node being looked for scheduling slave1:39995 availableResource: <memory:4096, vCores:1>
2019-06-07 07:52:38,751 DEBUG org.apache.hadoop.yarn.server.resourcemanager.scheduler.capacity.CapacityScheduler: Trying to schedule on node: slave1, available: <memory:4096, vCores:1>
2019-06-07 07:52:38,751 DEBUG org.apache.hadoop.yarn.server.resourcemanager.scheduler.capacity.CapacityScheduler: Trying to schedule on node: slave1, available: <memory:4096, vCores:1>
2019-06-07 07:52:38,751 DEBUG org.apache.hadoop.yarn.server.resourcemanager.scheduler.capacity.ParentQueue: Skip this queue=root, because it doesn't need more resource, schedulingMode=RESPECT_PARTITION_EXCLUSIVITY node-partition=
2019-06-07 07:52:38,751 DEBUG org.apache.hadoop.yarn.server.resourcemanager.scheduler.capacity.ParentQueue: Skip this queue=root, because it doesn't need more resource, schedulingMode=RESPECT_PARTITION_EXCLUSIVITY node-partition=
2019-06-07 07:52:38,754 DEBUG org.apache.hadoop.yarn.server.resourcemanager.rmnode.RMNodeImpl: Processing slave2:38494 of type STATUS_UPDATE
2019-06-07 07:52:38,754 DEBUG org.apache.hadoop.yarn.server.resourcemanager.rmnode.RMNodeImpl: Processing slave2:38494 of type STATUS_UPDATE
2019-06-07 07:52:38,754 DEBUG org.apache.hadoop.yarn.server.resourcemanager.scheduler.capacity.CapacityScheduler: nodeUpdate: slave2:38494 clusterResources: <memory:8192, vCores:2>
2019-06-07 07:52:38,754 DEBUG org.apache.hadoop.yarn.server.resourcemanager.scheduler.capacity.CapacityScheduler: nodeUpdate: slave2:38494 clusterResources: <memory:8192, vCores:2>
2019-06-07 07:52:38,754 DEBUG org.apache.hadoop.yarn.server.resourcemanager.scheduler.capacity.CapacityScheduler: Node being looked for scheduling slave2:38494 availableResource: <memory:4096, vCores:1>
2019-06-07 07:52:38,754 DEBUG org.apache.hadoop.yarn.server.resourcemanager.scheduler.capacity.CapacityScheduler: Node being looked for scheduling slave2:38494 availableResource: <memory:4096, vCores:1>
2019-06-07 07:52:38,755 DEBUG org.apache.hadoop.yarn.server.resourcemanager.scheduler.capacity.CapacityScheduler: Trying to schedule on node: slave2, available: <memory:4096, vCores:1>
2019-06-07 07:52:38,755 DEBUG org.apache.hadoop.yarn.server.resourcemanager.scheduler.capacity.CapacityScheduler: Trying to schedule on node: slave2, available: <memory:4096, vCores:1>
2019-06-07 07:52:38,755 DEBUG org.apache.hadoop.yarn.server.resourcemanager.scheduler.capacity.ParentQueue: Skip this queue=root, because it doesn't need more resource, schedulingMode=RESPECT_PARTITION_EXCLUSIVITY node-partition=
2019-06-07 07:52:38,755 DEBUG org.apache.hadoop.yarn.server.resourcemanager.scheduler.capacity.ParentQueue: Skip this queue=root, because it doesn't need more resource, schedulingMode=RESPECT_PARTITION_EXCLUSIVITY node-partition=
2019-06-07 07:52:39,752 DEBUG org.apache.hadoop.yarn.server.resourcemanager.rmnode.RMNodeImpl: Processing slave1:39995 of type STATUS_UPDATE
2019-06-07 07:52:39,752 DEBUG org.apache.hadoop.yarn.server.resourcemanager.rmnode.RMNodeImpl: Processing slave1:39995 of type STATUS_UPDATE
2019-06-07 07:52:39,752 DEBUG org.apache.hadoop.yarn.server.resourcemanager.scheduler.capacity.CapacityScheduler: nodeUpdate: slave1:39995 clusterResources: <memory:8192, vCores:2>
2019-06-07 07:52:39,752 DEBUG org.apache.hadoop.yarn.server.resourcemanager.scheduler.capacity.CapacityScheduler: nodeUpdate: slave1:39995 clusterResources: <memory:8192, vCores:2>
2019-06-07 07:52:39,752 DEBUG org.apache.hadoop.yarn.server.resourcemanager.scheduler.capacity.CapacityScheduler: Node being looked for scheduling slave1:39995 availableResource: <memory:4096, vCores:1>
2019-06-07 07:52:39,752 DEBUG org.apache.hadoop.yarn.server.resourcemanager.scheduler.capacity.CapacityScheduler: Node being looked for scheduling slave1:39995 availableResource: <memory:4096, vCores:1>
2019-06-07 07:52:39,752 DEBUG org.apache.hadoop.yarn.server.resourcemanager.scheduler.capacity.CapacityScheduler: Trying to schedule on node: slave1, available: <memory:4096, vCores:1>
2019-06-07 07:52:39,752 DEBUG org.apache.hadoop.yarn.server.resourcemanager.scheduler.capacity.CapacityScheduler: Trying to schedule on node: slave1, available: <memory:4096, vCores:1>
2019-06-07 07:52:39,752 DEBUG org.apache.hadoop.yarn.server.resourcemanager.scheduler.capacity.ParentQueue: Skip this queue=root, because it doesn't need more resource, schedulingMode=RESPECT_PARTITION_EXCLUSIVITY node-partition=
2019-06-07 07:52:39,752 DEBUG org.apache.hadoop.yarn.server.resourcemanager.scheduler.capacity.ParentQueue: Skip this queue=root, because it doesn't need more resource, schedulingMode=RESPECT_PARTITION_EXCLUSIVITY node-partition=
2019-06-07 07:52:39,757 DEBUG org.apache.hadoop.yarn.server.resourcemanager.rmnode.RMNodeImpl: Processing slave2:38494 of type STATUS_UPDATE
2019-06-07 07:52:39,757 DEBUG org.apache.hadoop.yarn.server.resourcemanager.rmnode.RMNodeImpl: Processing slave2:38494 of type STATUS_UPDATE
2019-06-07 07:52:39,758 DEBUG org.apache.hadoop.yarn.server.resourcemanager.scheduler.capacity.CapacityScheduler: nodeUpdate: slave2:38494 clusterResources: <memory:8192, vCores:2>
2019-06-07 07:52:39,758 DEBUG org.apache.hadoop.yarn.server.resourcemanager.scheduler.capacity.CapacityScheduler: nodeUpdate: slave2:38494 clusterResources: <memory:8192, vCores:2>
2019-06-07 07:52:39,759 DEBUG org.apache.hadoop.yarn.server.resourcemanager.scheduler.capacity.CapacityScheduler: Node being looked for scheduling slave2:38494 availableResource: <memory:4096, vCores:1>
2019-06-07 07:52:39,759 DEBUG org.apache.hadoop.yarn.server.resourcemanager.scheduler.capacity.CapacityScheduler: Node being looked for scheduling slave2:38494 availableResource: <memory:4096, vCores:1>
2019-06-07 07:52:39,759 DEBUG org.apache.hadoop.yarn.server.resourcemanager.scheduler.capacity.CapacityScheduler: Trying to schedule on node: slave2, available: <memory:4096, vCores:1>
2019-06-07 07:52:39,759 DEBUG org.apache.hadoop.yarn.server.resourcemanager.scheduler.capacity.CapacityScheduler: Trying to schedule on node: slave2, available: <memory:4096, vCores:1>
2019-06-07 07:52:39,759 DEBUG org.apache.hadoop.yarn.server.resourcemanager.scheduler.capacity.ParentQueue: Skip this queue=root, because it doesn't need more resource, schedulingMode=RESPECT_PARTITION_EXCLUSIVITY node-partition=
2019-06-07 07:52:39,759 DEBUG org.apache.hadoop.yarn.server.resourcemanager.scheduler.capacity.ParentQueue: Skip this queue=root, because it doesn't need more resource, schedulingMode=RESPECT_PARTITION_EXCLUSIVITY node-partition=
2019-06-07 07:52:40,756 DEBUG org.apache.hadoop.yarn.server.resourcemanager.rmnode.RMNodeImpl: Processing slave1:39995 of type STATUS_UPDATE
2019-06-07 07:52:40,756 DEBUG org.apache.hadoop.yarn.server.resourcemanager.rmnode.RMNodeImpl: Processing slave1:39995 of type STATUS_UPDATE
2019-06-07 07:52:40,757 DEBUG org.apache.hadoop.yarn.server.resourcemanager.scheduler.capacity.CapacityScheduler: nodeUpdate: slave1:39995 clusterResources: <memory:8192, vCores:2>
2019-06-07 07:52:40,757 DEBUG org.apache.hadoop.yarn.server.resourcemanager.scheduler.capacity.CapacityScheduler: nodeUpdate: slave1:39995 clusterResources: <memory:8192, vCores:2>
2019-06-07 07:52:40,757 DEBUG org.apache.hadoop.yarn.server.resourcemanager.scheduler.capacity.CapacityScheduler: Node being looked for scheduling slave1:39995 availableResource: <memory:4096, vCores:1>
2019-06-07 07:52:40,757 DEBUG org.apache.hadoop.yarn.server.resourcemanager.scheduler.capacity.CapacityScheduler: Node being looked for scheduling slave1:39995 availableResource: <memory:4096, vCores:1>
2019-06-07 07:52:40,757 DEBUG org.apache.hadoop.yarn.server.resourcemanager.scheduler.capacity.CapacityScheduler: Trying to schedule on node: slave1, available: <memory:4096, vCores:1>
2019-06-07 07:52:40,757 DEBUG org.apache.hadoop.yarn.server.resourcemanager.scheduler.capacity.CapacityScheduler: Trying to schedule on node: slave1, available: <memory:4096, vCores:1>
2019-06-07 07:52:40,757 DEBUG org.apache.hadoop.yarn.server.resourcemanager.scheduler.capacity.ParentQueue: Skip this queue=root, because it doesn't need more resource, schedulingMode=RESPECT_PARTITION_EXCLUSIVITY node-partition=
2019-06-07 07:52:40,757 DEBUG org.apache.hadoop.yarn.server.resourcemanager.scheduler.capacity.ParentQueue: Skip this queue=root, because it doesn't need more resource, schedulingMode=RESPECT_PARTITION_EXCLUSIVITY node-partition=
2019-06-07 07:52:40,762 DEBUG org.apache.hadoop.yarn.server.resourcemanager.rmnode.RMNodeImpl: Processing slave2:38494 of type STATUS_UPDATE
2019-06-07 07:52:40,762 DEBUG org.apache.hadoop.yarn.server.resourcemanager.rmnode.RMNodeImpl: Processing slave2:38494 of type STATUS_UPDATE
2019-06-07 07:52:40,763 DEBUG org.apache.hadoop.yarn.server.resourcemanager.scheduler.capacity.CapacityScheduler: nodeUpdate: slave2:38494 clusterResources: <memory:8192, vCores:2>
2019-06-07 07:52:40,763 DEBUG org.apache.hadoop.yarn.server.resourcemanager.scheduler.capacity.CapacityScheduler: nodeUpdate: slave2:38494 clusterResources: <memory:8192, vCores:2>
2019-06-07 07:52:40,763 DEBUG org.apache.hadoop.yarn.server.resourcemanager.scheduler.capacity.CapacityScheduler: Node being looked for scheduling slave2:38494 availableResource: <memory:4096, vCores:1>
2019-06-07 07:52:40,763 DEBUG org.apache.hadoop.yarn.server.resourcemanager.scheduler.capacity.CapacityScheduler: Node being looked for scheduling slave2:38494 availableResource: <memory:4096, vCores:1>
2019-06-07 07:52:40,763 DEBUG org.apache.hadoop.yarn.server.resourcemanager.scheduler.capacity.CapacityScheduler: Trying to schedule on node: slave2, available: <memory:4096, vCores:1>
2019-06-07 07:52:40,763 DEBUG org.apache.hadoop.yarn.server.resourcemanager.scheduler.capacity.CapacityScheduler: Trying to schedule on node: slave2, available: <memory:4096, vCores:1>
2019-06-07 07:52:40,763 DEBUG org.apache.hadoop.yarn.server.resourcemanager.scheduler.capacity.ParentQueue: Skip this queue=root, because it doesn't need more resource, schedulingMode=RESPECT_PARTITION_EXCLUSIVITY node-partition=
2019-06-07 07:52:40,763 DEBUG org.apache.hadoop.yarn.server.resourcemanager.scheduler.capacity.ParentQueue: Skip this queue=root, because it doesn't need more resource, schedulingMode=RESPECT_PARTITION_EXCLUSIVITY node-partition=
2019-06-07 07:52:41,760 DEBUG org.apache.hadoop.yarn.server.resourcemanager.rmnode.RMNodeImpl: Processing slave1:39995 of type STATUS_UPDATE
2019-06-07 07:52:41,760 DEBUG org.apache.hadoop.yarn.server.resourcemanager.rmnode.RMNodeImpl: Processing slave1:39995 of type STATUS_UPDATE
2019-06-07 07:52:41,760 DEBUG org.apache.hadoop.yarn.server.resourcemanager.scheduler.capacity.CapacityScheduler: nodeUpdate: slave1:39995 clusterResources: <memory:8192, vCores:2>
2019-06-07 07:52:41,760 DEBUG org.apache.hadoop.yarn.server.resourcemanager.scheduler.capacity.CapacityScheduler: nodeUpdate: slave1:39995 clusterResources: <memory:8192, vCores:2>
2019-06-07 07:52:41,760 DEBUG org.apache.hadoop.yarn.server.resourcemanager.scheduler.capacity.CapacityScheduler: Node being looked for scheduling slave1:39995 availableResource: <memory:4096, vCores:1>
2019-06-07 07:52:41,760 DEBUG org.apache.hadoop.yarn.server.resourcemanager.scheduler.capacity.CapacityScheduler: Node being looked for scheduling slave1:39995 availableResource: <memory:4096, vCores:1>
2019-06-07 07:52:41,760 DEBUG org.apache.hadoop.yarn.server.resourcemanager.scheduler.capacity.CapacityScheduler: Trying to schedule on node: slave1, available: <memory:4096, vCores:1>
2019-06-07 07:52:41,760 DEBUG org.apache.hadoop.yarn.server.resourcemanager.scheduler.capacity.CapacityScheduler: Trying to schedule on node: slave1, available: <memory:4096, vCores:1>
2019-06-07 07:52:41,760 DEBUG org.apache.hadoop.yarn.server.resourcemanager.scheduler.capacity.ParentQueue: Skip this queue=root, because it doesn't need more resource, schedulingMode=RESPECT_PARTITION_EXCLUSIVITY node-partition=
2019-06-07 07:52:41,760 DEBUG org.apache.hadoop.yarn.server.resourcemanager.scheduler.capacity.ParentQueue: Skip this queue=root, because it doesn't need more resource, schedulingMode=RESPECT_PARTITION_EXCLUSIVITY node-partition=
2019-06-07 07:52:41,765 DEBUG org.apache.hadoop.yarn.server.resourcemanager.rmnode.RMNodeImpl: Processing slave2:38494 of type STATUS_UPDATE
2019-06-07 07:52:41,765 DEBUG org.apache.hadoop.yarn.server.resourcemanager.rmnode.RMNodeImpl: Processing slave2:38494 of type STATUS_UPDATE
2019-06-07 07:52:41,765 DEBUG org.apache.hadoop.yarn.server.resourcemanager.scheduler.capacity.CapacityScheduler: nodeUpdate: slave2:38494 clusterResources: <memory:8192, vCores:2>
2019-06-07 07:52:41,765 DEBUG org.apache.hadoop.yarn.server.resourcemanager.scheduler.capacity.CapacityScheduler: nodeUpdate: slave2:38494 clusterResources: <memory:8192, vCores:2>
2019-06-07 07:52:41,765 DEBUG org.apache.hadoop.yarn.server.resourcemanager.scheduler.capacity.CapacityScheduler: Node being looked for scheduling slave2:38494 availableResource: <memory:4096, vCores:1>
2019-06-07 07:52:41,765 DEBUG org.apache.hadoop.yarn.server.resourcemanager.scheduler.capacity.CapacityScheduler: Node being looked for scheduling slave2:38494 availableResource: <memory:4096, vCores:1>
2019-06-07 07:52:41,766 DEBUG org.apache.hadoop.yarn.server.resourcemanager.scheduler.capacity.CapacityScheduler: Trying to schedule on node: slave2, available: <memory:4096, vCores:1>
2019-06-07 07:52:41,766 DEBUG org.apache.hadoop.yarn.server.resourcemanager.scheduler.capacity.CapacityScheduler: Trying to schedule on node: slave2, available: <memory:4096, vCores:1>
2019-06-07 07:52:41,766 DEBUG org.apache.hadoop.yarn.server.resourcemanager.scheduler.capacity.ParentQueue: Skip this queue=root, because it doesn't need more resource, schedulingMode=RESPECT_PARTITION_EXCLUSIVITY node-partition=
2019-06-07 07:52:41,766 DEBUG org.apache.hadoop.yarn.server.resourcemanager.scheduler.capacity.ParentQueue: Skip this queue=root, because it doesn't need more resource, schedulingMode=RESPECT_PARTITION_EXCLUSIVITY node-partition=
2019-06-07 07:52:42,763 DEBUG org.apache.hadoop.yarn.server.resourcemanager.rmnode.RMNodeImpl: Processing slave1:39995 of type STATUS_UPDATE
2019-06-07 07:52:42,763 DEBUG org.apache.hadoop.yarn.server.resourcemanager.rmnode.RMNodeImpl: Processing slave1:39995 of type STATUS_UPDATE
2019-06-07 07:52:42,763 DEBUG org.apache.hadoop.yarn.server.resourcemanager.scheduler.capacity.CapacityScheduler: nodeUpdate: slave1:39995 clusterResources: <memory:8192, vCores:2>
2019-06-07 07:52:42,763 DEBUG org.apache.hadoop.yarn.server.resourcemanager.scheduler.capacity.CapacityScheduler: nodeUpdate: slave1:39995 clusterResources: <memory:8192, vCores:2>
2019-06-07 07:52:42,763 DEBUG org.apache.hadoop.yarn.server.resourcemanager.scheduler.capacity.CapacityScheduler: Node being looked for scheduling slave1:39995 availableResource: <memory:4096, vCores:1>
2019-06-07 07:52:42,763 DEBUG org.apache.hadoop.yarn.server.resourcemanager.scheduler.capacity.CapacityScheduler: Node being looked for scheduling slave1:39995 availableResource: <memory:4096, vCores:1>
2019-06-07 07:52:42,763 DEBUG org.apache.hadoop.yarn.server.resourcemanager.scheduler.capacity.CapacityScheduler: Trying to schedule on node: slave1, available: <memory:4096, vCores:1>
2019-06-07 07:52:42,763 DEBUG org.apache.hadoop.yarn.server.resourcemanager.scheduler.capacity.CapacityScheduler: Trying to schedule on node: slave1, available: <memory:4096, vCores:1>
2019-06-07 07:52:42,763 DEBUG org.apache.hadoop.yarn.server.resourcemanager.scheduler.capacity.ParentQueue: Skip this queue=root, because it doesn't need more resource, schedulingMode=RESPECT_PARTITION_EXCLUSIVITY node-partition=
2019-06-07 07:52:42,763 DEBUG org.apache.hadoop.yarn.server.resourcemanager.scheduler.capacity.ParentQueue: Skip this queue=root, because it doesn't need more resource, schedulingMode=RESPECT_PARTITION_EXCLUSIVITY node-partition=
2019-06-07 07:52:42,768 DEBUG org.apache.hadoop.yarn.server.resourcemanager.rmnode.RMNodeImpl: Processing slave2:38494 of type STATUS_UPDATE
2019-06-07 07:52:42,768 DEBUG org.apache.hadoop.yarn.server.resourcemanager.rmnode.RMNodeImpl: Processing slave2:38494 of type STATUS_UPDATE
2019-06-07 07:52:42,769 DEBUG org.apache.hadoop.yarn.server.resourcemanager.scheduler.capacity.CapacityScheduler: nodeUpdate: slave2:38494 clusterResources: <memory:8192, vCores:2>
2019-06-07 07:52:42,769 DEBUG org.apache.hadoop.yarn.server.resourcemanager.scheduler.capacity.CapacityScheduler: nodeUpdate: slave2:38494 clusterResources: <memory:8192, vCores:2>
2019-06-07 07:52:42,769 DEBUG org.apache.hadoop.yarn.server.resourcemanager.scheduler.capacity.CapacityScheduler: Node being looked for scheduling slave2:38494 availableResource: <memory:4096, vCores:1>
2019-06-07 07:52:42,769 DEBUG org.apache.hadoop.yarn.server.resourcemanager.scheduler.capacity.CapacityScheduler: Node being looked for scheduling slave2:38494 availableResource: <memory:4096, vCores:1>
2019-06-07 07:52:42,769 DEBUG org.apache.hadoop.yarn.server.resourcemanager.scheduler.capacity.CapacityScheduler: Trying to schedule on node: slave2, available: <memory:4096, vCores:1>
2019-06-07 07:52:42,769 DEBUG org.apache.hadoop.yarn.server.resourcemanager.scheduler.capacity.CapacityScheduler: Trying to schedule on node: slave2, available: <memory:4096, vCores:1>
2019-06-07 07:52:42,769 DEBUG org.apache.hadoop.yarn.server.resourcemanager.scheduler.capacity.ParentQueue: Skip this queue=root, because it doesn't need more resource, schedulingMode=RESPECT_PARTITION_EXCLUSIVITY node-partition=
2019-06-07 07:52:42,769 DEBUG org.apache.hadoop.yarn.server.resourcemanager.scheduler.capacity.ParentQueue: Skip this queue=root, because it doesn't need more resource, schedulingMode=RESPECT_PARTITION_EXCLUSIVITY node-partition=
2019-06-07 07:52:43,766 DEBUG org.apache.hadoop.yarn.server.resourcemanager.rmnode.RMNodeImpl: Processing slave1:39995 of type STATUS_UPDATE
2019-06-07 07:52:43,766 DEBUG org.apache.hadoop.yarn.server.resourcemanager.rmnode.RMNodeImpl: Processing slave1:39995 of type STATUS_UPDATE
2019-06-07 07:52:43,766 DEBUG org.apache.hadoop.yarn.server.resourcemanager.scheduler.capacity.CapacityScheduler: nodeUpdate: slave1:39995 clusterResources: <memory:8192, vCores:2>
2019-06-07 07:52:43,766 DEBUG org.apache.hadoop.yarn.server.resourcemanager.scheduler.capacity.CapacityScheduler: nodeUpdate: slave1:39995 clusterResources: <memory:8192, vCores:2>
2019-06-07 07:52:43,766 DEBUG org.apache.hadoop.yarn.server.resourcemanager.scheduler.capacity.CapacityScheduler: Node being looked for scheduling slave1:39995 availableResource: <memory:4096, vCores:1>
2019-06-07 07:52:43,766 DEBUG org.apache.hadoop.yarn.server.resourcemanager.scheduler.capacity.CapacityScheduler: Node being looked for scheduling slave1:39995 availableResource: <memory:4096, vCores:1>
2019-06-07 07:52:43,766 DEBUG org.apache.hadoop.yarn.server.resourcemanager.scheduler.capacity.CapacityScheduler: Trying to schedule on node: slave1, available: <memory:4096, vCores:1>
2019-06-07 07:52:43,766 DEBUG org.apache.hadoop.yarn.server.resourcemanager.scheduler.capacity.CapacityScheduler: Trying to schedule on node: slave1, available: <memory:4096, vCores:1>
2019-06-07 07:52:43,766 DEBUG org.apache.hadoop.yarn.server.resourcemanager.scheduler.capacity.ParentQueue: Skip this queue=root, because it doesn't need more resource, schedulingMode=RESPECT_PARTITION_EXCLUSIVITY node-partition=
2019-06-07 07:52:43,766 DEBUG org.apache.hadoop.yarn.server.resourcemanager.scheduler.capacity.ParentQueue: Skip this queue=root, because it doesn't need more resource, schedulingMode=RESPECT_PARTITION_EXCLUSIVITY node-partition=
2019-06-07 07:52:43,771 DEBUG org.apache.hadoop.yarn.server.resourcemanager.rmnode.RMNodeImpl: Processing slave2:38494 of type STATUS_UPDATE
2019-06-07 07:52:43,771 DEBUG org.apache.hadoop.yarn.server.resourcemanager.rmnode.RMNodeImpl: Processing slave2:38494 of type STATUS_UPDATE
2019-06-07 07:52:43,771 DEBUG org.apache.hadoop.yarn.server.resourcemanager.scheduler.capacity.CapacityScheduler: nodeUpdate: slave2:38494 clusterResources: <memory:8192, vCores:2>
2019-06-07 07:52:43,771 DEBUG org.apache.hadoop.yarn.server.resourcemanager.scheduler.capacity.CapacityScheduler: nodeUpdate: slave2:38494 clusterResources: <memory:8192, vCores:2>
2019-06-07 07:52:43,771 DEBUG org.apache.hadoop.yarn.server.resourcemanager.scheduler.capacity.CapacityScheduler: Node being looked for scheduling slave2:38494 availableResource: <memory:4096, vCores:1>
2019-06-07 07:52:43,771 DEBUG org.apache.hadoop.yarn.server.resourcemanager.scheduler.capacity.CapacityScheduler: Node being looked for scheduling slave2:38494 availableResource: <memory:4096, vCores:1>
2019-06-07 07:52:43,771 DEBUG org.apache.hadoop.yarn.server.resourcemanager.scheduler.capacity.CapacityScheduler: Trying to schedule on node: slave2, available: <memory:4096, vCores:1>
2019-06-07 07:52:43,771 DEBUG org.apache.hadoop.yarn.server.resourcemanager.scheduler.capacity.CapacityScheduler: Trying to schedule on node: slave2, available: <memory:4096, vCores:1>
2019-06-07 07:52:43,771 DEBUG org.apache.hadoop.yarn.server.resourcemanager.scheduler.capacity.ParentQueue: Skip this queue=root, because it doesn't need more resource, schedulingMode=RESPECT_PARTITION_EXCLUSIVITY node-partition=
2019-06-07 07:52:43,771 DEBUG org.apache.hadoop.yarn.server.resourcemanager.scheduler.capacity.ParentQueue: Skip this queue=root, because it doesn't need more resource, schedulingMode=RESPECT_PARTITION_EXCLUSIVITY node-partition=
2019-06-07 07:52:44,768 DEBUG org.apache.hadoop.yarn.server.resourcemanager.rmnode.RMNodeImpl: Processing slave1:39995 of type STATUS_UPDATE
2019-06-07 07:52:44,768 DEBUG org.apache.hadoop.yarn.server.resourcemanager.rmnode.RMNodeImpl: Processing slave1:39995 of type STATUS_UPDATE
2019-06-07 07:52:44,768 DEBUG org.apache.hadoop.yarn.server.resourcemanager.scheduler.capacity.CapacityScheduler: nodeUpdate: slave1:39995 clusterResources: <memory:8192, vCores:2>
2019-06-07 07:52:44,768 DEBUG org.apache.hadoop.yarn.server.resourcemanager.scheduler.capacity.CapacityScheduler: nodeUpdate: slave1:39995 clusterResources: <memory:8192, vCores:2>
2019-06-07 07:52:44,768 DEBUG org.apache.hadoop.yarn.server.resourcemanager.scheduler.capacity.CapacityScheduler: Node being looked for scheduling slave1:39995 availableResource: <memory:4096, vCores:1>
2019-06-07 07:52:44,768 DEBUG org.apache.hadoop.yarn.server.resourcemanager.scheduler.capacity.CapacityScheduler: Node being looked for scheduling slave1:39995 availableResource: <memory:4096, vCores:1>
2019-06-07 07:52:44,768 DEBUG org.apache.hadoop.yarn.server.resourcemanager.scheduler.capacity.CapacityScheduler: Trying to schedule on node: slave1, available: <memory:4096, vCores:1>
2019-06-07 07:52:44,768 DEBUG org.apache.hadoop.yarn.server.resourcemanager.scheduler.capacity.CapacityScheduler: Trying to schedule on node: slave1, available: <memory:4096, vCores:1>
2019-06-07 07:52:44,768 DEBUG org.apache.hadoop.yarn.server.resourcemanager.scheduler.capacity.ParentQueue: Skip this queue=root, because it doesn't need more resource, schedulingMode=RESPECT_PARTITION_EXCLUSIVITY node-partition=
2019-06-07 07:52:44,768 DEBUG org.apache.hadoop.yarn.server.resourcemanager.scheduler.capacity.ParentQueue: Skip this queue=root, because it doesn't need more resource, schedulingMode=RESPECT_PARTITION_EXCLUSIVITY node-partition=
2019-06-07 07:52:44,773 DEBUG org.apache.hadoop.yarn.server.resourcemanager.rmnode.RMNodeImpl: Processing slave2:38494 of type STATUS_UPDATE
2019-06-07 07:52:44,773 DEBUG org.apache.hadoop.yarn.server.resourcemanager.rmnode.RMNodeImpl: Processing slave2:38494 of type STATUS_UPDATE
2019-06-07 07:52:44,773 DEBUG org.apache.hadoop.yarn.server.resourcemanager.scheduler.capacity.CapacityScheduler: nodeUpdate: slave2:38494 clusterResources: <memory:8192, vCores:2>
2019-06-07 07:52:44,773 DEBUG org.apache.hadoop.yarn.server.resourcemanager.scheduler.capacity.CapacityScheduler: nodeUpdate: slave2:38494 clusterResources: <memory:8192, vCores:2>
2019-06-07 07:52:44,773 DEBUG org.apache.hadoop.yarn.server.resourcemanager.scheduler.capacity.CapacityScheduler: Node being looked for scheduling slave2:38494 availableResource: <memory:4096, vCores:1>
2019-06-07 07:52:44,773 DEBUG org.apache.hadoop.yarn.server.resourcemanager.scheduler.capacity.CapacityScheduler: Node being looked for scheduling slave2:38494 availableResource: <memory:4096, vCores:1>
2019-06-07 07:52:44,773 DEBUG org.apache.hadoop.yarn.server.resourcemanager.scheduler.capacity.CapacityScheduler: Trying to schedule on node: slave2, available: <memory:4096, vCores:1>
2019-06-07 07:52:44,773 DEBUG org.apache.hadoop.yarn.server.resourcemanager.scheduler.capacity.CapacityScheduler: Trying to schedule on node: slave2, available: <memory:4096, vCores:1>
2019-06-07 07:52:44,773 DEBUG org.apache.hadoop.yarn.server.resourcemanager.scheduler.capacity.ParentQueue: Skip this queue=root, because it doesn't need more resource, schedulingMode=RESPECT_PARTITION_EXCLUSIVITY node-partition=
2019-06-07 07:52:44,773 DEBUG org.apache.hadoop.yarn.server.resourcemanager.scheduler.capacity.ParentQueue: Skip this queue=root, because it doesn't need more resource, schedulingMode=RESPECT_PARTITION_EXCLUSIVITY node-partition=
2019-06-07 07:52:45,772 DEBUG org.apache.hadoop.yarn.server.resourcemanager.rmnode.RMNodeImpl: Processing slave1:39995 of type STATUS_UPDATE
2019-06-07 07:52:45,772 DEBUG org.apache.hadoop.yarn.server.resourcemanager.rmnode.RMNodeImpl: Processing slave1:39995 of type STATUS_UPDATE
2019-06-07 07:52:45,772 DEBUG org.apache.hadoop.yarn.server.resourcemanager.scheduler.capacity.CapacityScheduler: nodeUpdate: slave1:39995 clusterResources: <memory:8192, vCores:2>
2019-06-07 07:52:45,772 DEBUG org.apache.hadoop.yarn.server.resourcemanager.scheduler.capacity.CapacityScheduler: nodeUpdate: slave1:39995 clusterResources: <memory:8192, vCores:2>
2019-06-07 07:52:45,772 DEBUG org.apache.hadoop.yarn.server.resourcemanager.scheduler.capacity.CapacityScheduler: Node being looked for scheduling slave1:39995 availableResource: <memory:4096, vCores:1>
2019-06-07 07:52:45,772 DEBUG org.apache.hadoop.yarn.server.resourcemanager.scheduler.capacity.CapacityScheduler: Node being looked for scheduling slave1:39995 availableResource: <memory:4096, vCores:1>
2019-06-07 07:52:45,772 DEBUG org.apache.hadoop.yarn.server.resourcemanager.scheduler.capacity.CapacityScheduler: Trying to schedule on node: slave1, available: <memory:4096, vCores:1>
2019-06-07 07:52:45,772 DEBUG org.apache.hadoop.yarn.server.resourcemanager.scheduler.capacity.CapacityScheduler: Trying to schedule on node: slave1, available: <memory:4096, vCores:1>
2019-06-07 07:52:45,773 DEBUG org.apache.hadoop.yarn.server.resourcemanager.scheduler.capacity.ParentQueue: Skip this queue=root, because it doesn't need more resource, schedulingMode=RESPECT_PARTITION_EXCLUSIVITY node-partition=
2019-06-07 07:52:45,773 DEBUG org.apache.hadoop.yarn.server.resourcemanager.scheduler.capacity.ParentQueue: Skip this queue=root, because it doesn't need more resource, schedulingMode=RESPECT_PARTITION_EXCLUSIVITY node-partition=
2019-06-07 07:52:45,776 DEBUG org.apache.hadoop.yarn.server.resourcemanager.rmnode.RMNodeImpl: Processing slave2:38494 of type STATUS_UPDATE
2019-06-07 07:52:45,776 DEBUG org.apache.hadoop.yarn.server.resourcemanager.rmnode.RMNodeImpl: Processing slave2:38494 of type STATUS_UPDATE
2019-06-07 07:52:45,776 DEBUG org.apache.hadoop.yarn.server.resourcemanager.scheduler.capacity.CapacityScheduler: nodeUpdate: slave2:38494 clusterResources: <memory:8192, vCores:2>
2019-06-07 07:52:45,776 DEBUG org.apache.hadoop.yarn.server.resourcemanager.scheduler.capacity.CapacityScheduler: nodeUpdate: slave2:38494 clusterResources: <memory:8192, vCores:2>
2019-06-07 07:52:45,776 DEBUG org.apache.hadoop.yarn.server.resourcemanager.scheduler.capacity.CapacityScheduler: Node being looked for scheduling slave2:38494 availableResource: <memory:4096, vCores:1>
2019-06-07 07:52:45,776 DEBUG org.apache.hadoop.yarn.server.resourcemanager.scheduler.capacity.CapacityScheduler: Node being looked for scheduling slave2:38494 availableResource: <memory:4096, vCores:1>
2019-06-07 07:52:45,776 DEBUG org.apache.hadoop.yarn.server.resourcemanager.scheduler.capacity.CapacityScheduler: Trying to schedule on node: slave2, available: <memory:4096, vCores:1>
2019-06-07 07:52:45,776 DEBUG org.apache.hadoop.yarn.server.resourcemanager.scheduler.capacity.CapacityScheduler: Trying to schedule on node: slave2, available: <memory:4096, vCores:1>
2019-06-07 07:52:45,776 DEBUG org.apache.hadoop.yarn.server.resourcemanager.scheduler.capacity.ParentQueue: Skip this queue=root, because it doesn't need more resource, schedulingMode=RESPECT_PARTITION_EXCLUSIVITY node-partition=
2019-06-07 07:52:45,776 DEBUG org.apache.hadoop.yarn.server.resourcemanager.scheduler.capacity.ParentQueue: Skip this queue=root, because it doesn't need more resource, schedulingMode=RESPECT_PARTITION_EXCLUSIVITY node-partition=
2019-06-07 07:52:46,775 DEBUG org.apache.hadoop.yarn.server.resourcemanager.rmnode.RMNodeImpl: Processing slave1:39995 of type STATUS_UPDATE
2019-06-07 07:52:46,775 DEBUG org.apache.hadoop.yarn.server.resourcemanager.rmnode.RMNodeImpl: Processing slave1:39995 of type STATUS_UPDATE
2019-06-07 07:52:46,776 DEBUG org.apache.hadoop.yarn.server.resourcemanager.scheduler.capacity.CapacityScheduler: nodeUpdate: slave1:39995 clusterResources: <memory:8192, vCores:2>
2019-06-07 07:52:46,776 DEBUG org.apache.hadoop.yarn.server.resourcemanager.scheduler.capacity.CapacityScheduler: nodeUpdate: slave1:39995 clusterResources: <memory:8192, vCores:2>
2019-06-07 07:52:46,776 DEBUG org.apache.hadoop.yarn.server.resourcemanager.scheduler.capacity.CapacityScheduler: Node being looked for scheduling slave1:39995 availableResource: <memory:4096, vCores:1>
2019-06-07 07:52:46,776 DEBUG org.apache.hadoop.yarn.server.resourcemanager.scheduler.capacity.CapacityScheduler: Node being looked for scheduling slave1:39995 availableResource: <memory:4096, vCores:1>
2019-06-07 07:52:46,776 DEBUG org.apache.hadoop.yarn.server.resourcemanager.scheduler.capacity.CapacityScheduler: Trying to schedule on node: slave1, available: <memory:4096, vCores:1>
2019-06-07 07:52:46,776 DEBUG org.apache.hadoop.yarn.server.resourcemanager.scheduler.capacity.CapacityScheduler: Trying to schedule on node: slave1, available: <memory:4096, vCores:1>
2019-06-07 07:52:46,776 DEBUG org.apache.hadoop.yarn.server.resourcemanager.scheduler.capacity.ParentQueue: Skip this queue=root, because it doesn't need more resource, schedulingMode=RESPECT_PARTITION_EXCLUSIVITY node-partition=
2019-06-07 07:52:46,776 DEBUG org.apache.hadoop.yarn.server.resourcemanager.scheduler.capacity.ParentQueue: Skip this queue=root, because it doesn't need more resource, schedulingMode=RESPECT_PARTITION_EXCLUSIVITY node-partition=
2019-06-07 07:52:46,778 DEBUG org.apache.hadoop.yarn.server.resourcemanager.rmnode.RMNodeImpl: Processing slave2:38494 of type STATUS_UPDATE
2019-06-07 07:52:46,778 DEBUG org.apache.hadoop.yarn.server.resourcemanager.rmnode.RMNodeImpl: Processing slave2:38494 of type STATUS_UPDATE
2019-06-07 07:52:46,779 DEBUG org.apache.hadoop.yarn.server.resourcemanager.scheduler.capacity.CapacityScheduler: nodeUpdate: slave2:38494 clusterResources: <memory:8192, vCores:2>
2019-06-07 07:52:46,779 DEBUG org.apache.hadoop.yarn.server.resourcemanager.scheduler.capacity.CapacityScheduler: nodeUpdate: slave2:38494 clusterResources: <memory:8192, vCores:2>
2019-06-07 07:52:46,779 DEBUG org.apache.hadoop.yarn.server.resourcemanager.scheduler.capacity.CapacityScheduler: Node being looked for scheduling slave2:38494 availableResource: <memory:4096, vCores:1>
2019-06-07 07:52:46,779 DEBUG org.apache.hadoop.yarn.server.resourcemanager.scheduler.capacity.CapacityScheduler: Node being looked for scheduling slave2:38494 availableResource: <memory:4096, vCores:1>
2019-06-07 07:52:46,779 DEBUG org.apache.hadoop.yarn.server.resourcemanager.scheduler.capacity.CapacityScheduler: Trying to schedule on node: slave2, available: <memory:4096, vCores:1>
2019-06-07 07:52:46,779 DEBUG org.apache.hadoop.yarn.server.resourcemanager.scheduler.capacity.CapacityScheduler: Trying to schedule on node: slave2, available: <memory:4096, vCores:1>
2019-06-07 07:52:46,779 DEBUG org.apache.hadoop.yarn.server.resourcemanager.scheduler.capacity.ParentQueue: Skip this queue=root, because it doesn't need more resource, schedulingMode=RESPECT_PARTITION_EXCLUSIVITY node-partition=
2019-06-07 07:52:46,779 DEBUG org.apache.hadoop.yarn.server.resourcemanager.scheduler.capacity.ParentQueue: Skip this queue=root, because it doesn't need more resource, schedulingMode=RESPECT_PARTITION_EXCLUSIVITY node-partition=
2019-06-07 07:52:47,781 DEBUG org.apache.hadoop.yarn.server.resourcemanager.rmnode.RMNodeImpl: Processing slave1:39995 of type STATUS_UPDATE
2019-06-07 07:52:47,781 DEBUG org.apache.hadoop.yarn.server.resourcemanager.rmnode.RMNodeImpl: Processing slave1:39995 of type STATUS_UPDATE
2019-06-07 07:52:47,781 DEBUG org.apache.hadoop.yarn.server.resourcemanager.scheduler.capacity.CapacityScheduler: nodeUpdate: slave1:39995 clusterResources: <memory:8192, vCores:2>
2019-06-07 07:52:47,781 DEBUG org.apache.hadoop.yarn.server.resourcemanager.scheduler.capacity.CapacityScheduler: nodeUpdate: slave1:39995 clusterResources: <memory:8192, vCores:2>
2019-06-07 07:52:47,781 DEBUG org.apache.hadoop.yarn.server.resourcemanager.scheduler.capacity.CapacityScheduler: Node being looked for scheduling slave1:39995 availableResource: <memory:4096, vCores:1>
2019-06-07 07:52:47,781 DEBUG org.apache.hadoop.yarn.server.resourcemanager.scheduler.capacity.CapacityScheduler: Node being looked for scheduling slave1:39995 availableResource: <memory:4096, vCores:1>
2019-06-07 07:52:47,781 DEBUG org.apache.hadoop.yarn.server.resourcemanager.scheduler.capacity.CapacityScheduler: Trying to schedule on node: slave1, available: <memory:4096, vCores:1>
2019-06-07 07:52:47,781 DEBUG org.apache.hadoop.yarn.server.resourcemanager.scheduler.capacity.CapacityScheduler: Trying to schedule on node: slave1, available: <memory:4096, vCores:1>
2019-06-07 07:52:47,781 DEBUG org.apache.hadoop.yarn.server.resourcemanager.scheduler.capacity.ParentQueue: Skip this queue=root, because it doesn't need more resource, schedulingMode=RESPECT_PARTITION_EXCLUSIVITY node-partition=
2019-06-07 07:52:47,781 DEBUG org.apache.hadoop.yarn.server.resourcemanager.scheduler.capacity.ParentQueue: Skip this queue=root, because it doesn't need more resource, schedulingMode=RESPECT_PARTITION_EXCLUSIVITY node-partition=
2019-06-07 07:52:47,784 DEBUG org.apache.hadoop.yarn.server.resourcemanager.rmnode.RMNodeImpl: Processing slave2:38494 of type STATUS_UPDATE
2019-06-07 07:52:47,784 DEBUG org.apache.hadoop.yarn.server.resourcemanager.rmnode.RMNodeImpl: Processing slave2:38494 of type STATUS_UPDATE
2019-06-07 07:52:47,784 DEBUG org.apache.hadoop.yarn.server.resourcemanager.scheduler.capacity.CapacityScheduler: nodeUpdate: slave2:38494 clusterResources: <memory:8192, vCores:2>
2019-06-07 07:52:47,784 DEBUG org.apache.hadoop.yarn.server.resourcemanager.scheduler.capacity.CapacityScheduler: nodeUpdate: slave2:38494 clusterResources: <memory:8192, vCores:2>
2019-06-07 07:52:47,784 DEBUG org.apache.hadoop.yarn.server.resourcemanager.scheduler.capacity.CapacityScheduler: Node being looked for scheduling slave2:38494 availableResource: <memory:4096, vCores:1>
2019-06-07 07:52:47,784 DEBUG org.apache.hadoop.yarn.server.resourcemanager.scheduler.capacity.CapacityScheduler: Node being looked for scheduling slave2:38494 availableResource: <memory:4096, vCores:1>
2019-06-07 07:52:47,784 DEBUG org.apache.hadoop.yarn.server.resourcemanager.scheduler.capacity.CapacityScheduler: Trying to schedule on node: slave2, available: <memory:4096, vCores:1>
2019-06-07 07:52:47,784 DEBUG org.apache.hadoop.yarn.server.resourcemanager.scheduler.capacity.CapacityScheduler: Trying to schedule on node: slave2, available: <memory:4096, vCores:1>
2019-06-07 07:52:47,784 DEBUG org.apache.hadoop.yarn.server.resourcemanager.scheduler.capacity.ParentQueue: Skip this queue=root, because it doesn't need more resource, schedulingMode=RESPECT_PARTITION_EXCLUSIVITY node-partition=
2019-06-07 07:52:47,784 DEBUG org.apache.hadoop.yarn.server.resourcemanager.scheduler.capacity.ParentQueue: Skip this queue=root, because it doesn't need more resource, schedulingMode=RESPECT_PARTITION_EXCLUSIVITY node-partition=
2019-06-07 07:52:48,784 DEBUG org.apache.hadoop.yarn.server.resourcemanager.rmnode.RMNodeImpl: Processing slave1:39995 of type STATUS_UPDATE
2019-06-07 07:52:48,784 DEBUG org.apache.hadoop.yarn.server.resourcemanager.rmnode.RMNodeImpl: Processing slave1:39995 of type STATUS_UPDATE
2019-06-07 07:52:48,784 DEBUG org.apache.hadoop.yarn.server.resourcemanager.scheduler.capacity.CapacityScheduler: nodeUpdate: slave1:39995 clusterResources: <memory:8192, vCores:2>
2019-06-07 07:52:48,784 DEBUG org.apache.hadoop.yarn.server.resourcemanager.scheduler.capacity.CapacityScheduler: nodeUpdate: slave1:39995 clusterResources: <memory:8192, vCores:2>
2019-06-07 07:52:48,784 DEBUG org.apache.hadoop.yarn.server.resourcemanager.scheduler.capacity.CapacityScheduler: Node being looked for scheduling slave1:39995 availableResource: <memory:4096, vCores:1>
2019-06-07 07:52:48,784 DEBUG org.apache.hadoop.yarn.server.resourcemanager.scheduler.capacity.CapacityScheduler: Node being looked for scheduling slave1:39995 availableResource: <memory:4096, vCores:1>
2019-06-07 07:52:48,785 DEBUG org.apache.hadoop.yarn.server.resourcemanager.scheduler.capacity.CapacityScheduler: Trying to schedule on node: slave1, available: <memory:4096, vCores:1>
2019-06-07 07:52:48,785 DEBUG org.apache.hadoop.yarn.server.resourcemanager.scheduler.capacity.CapacityScheduler: Trying to schedule on node: slave1, available: <memory:4096, vCores:1>
2019-06-07 07:52:48,785 DEBUG org.apache.hadoop.yarn.server.resourcemanager.scheduler.capacity.ParentQueue: Skip this queue=root, because it doesn't need more resource, schedulingMode=RESPECT_PARTITION_EXCLUSIVITY node-partition=
2019-06-07 07:52:48,785 DEBUG org.apache.hadoop.yarn.server.resourcemanager.scheduler.capacity.ParentQueue: Skip this queue=root, because it doesn't need more resource, schedulingMode=RESPECT_PARTITION_EXCLUSIVITY node-partition=
2019-06-07 07:52:48,786 DEBUG org.apache.hadoop.yarn.server.resourcemanager.rmnode.RMNodeImpl: Processing slave2:38494 of type STATUS_UPDATE
2019-06-07 07:52:48,786 DEBUG org.apache.hadoop.yarn.server.resourcemanager.rmnode.RMNodeImpl: Processing slave2:38494 of type STATUS_UPDATE
2019-06-07 07:52:48,786 DEBUG org.apache.hadoop.yarn.server.resourcemanager.scheduler.capacity.CapacityScheduler: nodeUpdate: slave2:38494 clusterResources: <memory:8192, vCores:2>
2019-06-07 07:52:48,786 DEBUG org.apache.hadoop.yarn.server.resourcemanager.scheduler.capacity.CapacityScheduler: nodeUpdate: slave2:38494 clusterResources: <memory:8192, vCores:2>
2019-06-07 07:52:48,786 DEBUG org.apache.hadoop.yarn.server.resourcemanager.scheduler.capacity.CapacityScheduler: Node being looked for scheduling slave2:38494 availableResource: <memory:4096, vCores:1>
2019-06-07 07:52:48,786 DEBUG org.apache.hadoop.yarn.server.resourcemanager.scheduler.capacity.CapacityScheduler: Node being looked for scheduling slave2:38494 availableResource: <memory:4096, vCores:1>
2019-06-07 07:52:48,786 DEBUG org.apache.hadoop.yarn.server.resourcemanager.scheduler.capacity.CapacityScheduler: Trying to schedule on node: slave2, available: <memory:4096, vCores:1>
2019-06-07 07:52:48,786 DEBUG org.apache.hadoop.yarn.server.resourcemanager.scheduler.capacity.CapacityScheduler: Trying to schedule on node: slave2, available: <memory:4096, vCores:1>
2019-06-07 07:52:48,786 DEBUG org.apache.hadoop.yarn.server.resourcemanager.scheduler.capacity.ParentQueue: Skip this queue=root, because it doesn't need more resource, schedulingMode=RESPECT_PARTITION_EXCLUSIVITY node-partition=
2019-06-07 07:52:48,786 DEBUG org.apache.hadoop.yarn.server.resourcemanager.scheduler.capacity.ParentQueue: Skip this queue=root, because it doesn't need more resource, schedulingMode=RESPECT_PARTITION_EXCLUSIVITY node-partition=
2019-06-07 07:52:49,786 DEBUG org.apache.hadoop.yarn.server.resourcemanager.rmnode.RMNodeImpl: Processing slave1:39995 of type STATUS_UPDATE
2019-06-07 07:52:49,786 DEBUG org.apache.hadoop.yarn.server.resourcemanager.rmnode.RMNodeImpl: Processing slave1:39995 of type STATUS_UPDATE
2019-06-07 07:52:49,788 DEBUG org.apache.hadoop.yarn.server.resourcemanager.rmnode.RMNodeImpl: Processing slave2:38494 of type STATUS_UPDATE
2019-06-07 07:52:49,788 DEBUG org.apache.hadoop.yarn.server.resourcemanager.rmnode.RMNodeImpl: Processing slave2:38494 of type STATUS_UPDATE
2019-06-07 07:52:49,788 DEBUG org.apache.hadoop.yarn.server.resourcemanager.scheduler.capacity.CapacityScheduler: nodeUpdate: slave1:39995 clusterResources: <memory:8192, vCores:2>
2019-06-07 07:52:49,788 DEBUG org.apache.hadoop.yarn.server.resourcemanager.scheduler.capacity.CapacityScheduler: nodeUpdate: slave1:39995 clusterResources: <memory:8192, vCores:2>
2019-06-07 07:52:49,788 DEBUG org.apache.hadoop.yarn.server.resourcemanager.scheduler.capacity.CapacityScheduler: Node being looked for scheduling slave1:39995 availableResource: <memory:4096, vCores:1>
2019-06-07 07:52:49,788 DEBUG org.apache.hadoop.yarn.server.resourcemanager.scheduler.capacity.CapacityScheduler: Node being looked for scheduling slave1:39995 availableResource: <memory:4096, vCores:1>
2019-06-07 07:52:49,788 DEBUG org.apache.hadoop.yarn.server.resourcemanager.scheduler.capacity.CapacityScheduler: Trying to schedule on node: slave1, available: <memory:4096, vCores:1>
2019-06-07 07:52:49,788 DEBUG org.apache.hadoop.yarn.server.resourcemanager.scheduler.capacity.CapacityScheduler: Trying to schedule on node: slave1, available: <memory:4096, vCores:1>
2019-06-07 07:52:49,788 DEBUG org.apache.hadoop.yarn.server.resourcemanager.scheduler.capacity.ParentQueue: Skip this queue=root, because it doesn't need more resource, schedulingMode=RESPECT_PARTITION_EXCLUSIVITY node-partition=
2019-06-07 07:52:49,788 DEBUG org.apache.hadoop.yarn.server.resourcemanager.scheduler.capacity.ParentQueue: Skip this queue=root, because it doesn't need more resource, schedulingMode=RESPECT_PARTITION_EXCLUSIVITY node-partition=
2019-06-07 07:52:49,788 DEBUG org.apache.hadoop.yarn.server.resourcemanager.scheduler.capacity.CapacityScheduler: nodeUpdate: slave2:38494 clusterResources: <memory:8192, vCores:2>
2019-06-07 07:52:49,788 DEBUG org.apache.hadoop.yarn.server.resourcemanager.scheduler.capacity.CapacityScheduler: nodeUpdate: slave2:38494 clusterResources: <memory:8192, vCores:2>
2019-06-07 07:52:49,788 DEBUG org.apache.hadoop.yarn.server.resourcemanager.scheduler.capacity.CapacityScheduler: Node being looked for scheduling slave2:38494 availableResource: <memory:4096, vCores:1>
2019-06-07 07:52:49,788 DEBUG org.apache.hadoop.yarn.server.resourcemanager.scheduler.capacity.CapacityScheduler: Node being looked for scheduling slave2:38494 availableResource: <memory:4096, vCores:1>
2019-06-07 07:52:49,788 DEBUG org.apache.hadoop.yarn.server.resourcemanager.scheduler.capacity.CapacityScheduler: Trying to schedule on node: slave2, available: <memory:4096, vCores:1>
2019-06-07 07:52:49,788 DEBUG org.apache.hadoop.yarn.server.resourcemanager.scheduler.capacity.CapacityScheduler: Trying to schedule on node: slave2, available: <memory:4096, vCores:1>
2019-06-07 07:52:49,788 DEBUG org.apache.hadoop.yarn.server.resourcemanager.scheduler.capacity.ParentQueue: Skip this queue=root, because it doesn't need more resource, schedulingMode=RESPECT_PARTITION_EXCLUSIVITY node-partition=
2019-06-07 07:52:49,788 DEBUG org.apache.hadoop.yarn.server.resourcemanager.scheduler.capacity.ParentQueue: Skip this queue=root, because it doesn't need more resource, schedulingMode=RESPECT_PARTITION_EXCLUSIVITY node-partition=
2019-06-07 07:52:50,789 DEBUG org.apache.hadoop.yarn.server.resourcemanager.rmnode.RMNodeImpl: Processing slave1:39995 of type STATUS_UPDATE
2019-06-07 07:52:50,789 DEBUG org.apache.hadoop.yarn.server.resourcemanager.rmnode.RMNodeImpl: Processing slave1:39995 of type STATUS_UPDATE
2019-06-07 07:52:50,790 DEBUG org.apache.hadoop.yarn.server.resourcemanager.scheduler.capacity.CapacityScheduler: nodeUpdate: slave1:39995 clusterResources: <memory:8192, vCores:2>
2019-06-07 07:52:50,790 DEBUG org.apache.hadoop.yarn.server.resourcemanager.scheduler.capacity.CapacityScheduler: nodeUpdate: slave1:39995 clusterResources: <memory:8192, vCores:2>
2019-06-07 07:52:50,790 DEBUG org.apache.hadoop.yarn.server.resourcemanager.scheduler.capacity.CapacityScheduler: Node being looked for scheduling slave1:39995 availableResource: <memory:4096, vCores:1>
2019-06-07 07:52:50,790 DEBUG org.apache.hadoop.yarn.server.resourcemanager.scheduler.capacity.CapacityScheduler: Node being looked for scheduling slave1:39995 availableResource: <memory:4096, vCores:1>
2019-06-07 07:52:50,790 DEBUG org.apache.hadoop.yarn.server.resourcemanager.scheduler.capacity.CapacityScheduler: Trying to schedule on node: slave1, available: <memory:4096, vCores:1>
2019-06-07 07:52:50,790 DEBUG org.apache.hadoop.yarn.server.resourcemanager.scheduler.capacity.CapacityScheduler: Trying to schedule on node: slave1, available: <memory:4096, vCores:1>
2019-06-07 07:52:50,790 DEBUG org.apache.hadoop.yarn.server.resourcemanager.scheduler.capacity.ParentQueue: Skip this queue=root, because it doesn't need more resource, schedulingMode=RESPECT_PARTITION_EXCLUSIVITY node-partition=
2019-06-07 07:52:50,790 DEBUG org.apache.hadoop.yarn.server.resourcemanager.scheduler.capacity.ParentQueue: Skip this queue=root, because it doesn't need more resource, schedulingMode=RESPECT_PARTITION_EXCLUSIVITY node-partition=
2019-06-07 07:52:50,794 DEBUG org.apache.hadoop.yarn.server.resourcemanager.rmnode.RMNodeImpl: Processing slave2:38494 of type STATUS_UPDATE
2019-06-07 07:52:50,794 DEBUG org.apache.hadoop.yarn.server.resourcemanager.rmnode.RMNodeImpl: Processing slave2:38494 of type STATUS_UPDATE
2019-06-07 07:52:50,794 DEBUG org.apache.hadoop.yarn.server.resourcemanager.scheduler.capacity.CapacityScheduler: nodeUpdate: slave2:38494 clusterResources: <memory:8192, vCores:2>
2019-06-07 07:52:50,794 DEBUG org.apache.hadoop.yarn.server.resourcemanager.scheduler.capacity.CapacityScheduler: nodeUpdate: slave2:38494 clusterResources: <memory:8192, vCores:2>
2019-06-07 07:52:50,794 DEBUG org.apache.hadoop.yarn.server.resourcemanager.scheduler.capacity.CapacityScheduler: Node being looked for scheduling slave2:38494 availableResource: <memory:4096, vCores:1>
2019-06-07 07:52:50,794 DEBUG org.apache.hadoop.yarn.server.resourcemanager.scheduler.capacity.CapacityScheduler: Node being looked for scheduling slave2:38494 availableResource: <memory:4096, vCores:1>
2019-06-07 07:52:50,794 DEBUG org.apache.hadoop.yarn.server.resourcemanager.scheduler.capacity.CapacityScheduler: Trying to schedule on node: slave2, available: <memory:4096, vCores:1>
2019-06-07 07:52:50,794 DEBUG org.apache.hadoop.yarn.server.resourcemanager.scheduler.capacity.CapacityScheduler: Trying to schedule on node: slave2, available: <memory:4096, vCores:1>
2019-06-07 07:52:50,794 DEBUG org.apache.hadoop.yarn.server.resourcemanager.scheduler.capacity.ParentQueue: Skip this queue=root, because it doesn't need more resource, schedulingMode=RESPECT_PARTITION_EXCLUSIVITY node-partition=
2019-06-07 07:52:50,794 DEBUG org.apache.hadoop.yarn.server.resourcemanager.scheduler.capacity.ParentQueue: Skip this queue=root, because it doesn't need more resource, schedulingMode=RESPECT_PARTITION_EXCLUSIVITY node-partition=
2019-06-07 07:52:51,792 DEBUG org.apache.hadoop.yarn.server.resourcemanager.rmnode.RMNodeImpl: Processing slave1:39995 of type STATUS_UPDATE
2019-06-07 07:52:51,792 DEBUG org.apache.hadoop.yarn.server.resourcemanager.rmnode.RMNodeImpl: Processing slave1:39995 of type STATUS_UPDATE
2019-06-07 07:52:51,793 DEBUG org.apache.hadoop.yarn.server.resourcemanager.scheduler.capacity.CapacityScheduler: nodeUpdate: slave1:39995 clusterResources: <memory:8192, vCores:2>
2019-06-07 07:52:51,793 DEBUG org.apache.hadoop.yarn.server.resourcemanager.scheduler.capacity.CapacityScheduler: nodeUpdate: slave1:39995 clusterResources: <memory:8192, vCores:2>
2019-06-07 07:52:51,793 DEBUG org.apache.hadoop.yarn.server.resourcemanager.scheduler.capacity.CapacityScheduler: Node being looked for scheduling slave1:39995 availableResource: <memory:4096, vCores:1>
2019-06-07 07:52:51,793 DEBUG org.apache.hadoop.yarn.server.resourcemanager.scheduler.capacity.CapacityScheduler: Node being looked for scheduling slave1:39995 availableResource: <memory:4096, vCores:1>
2019-06-07 07:52:51,793 DEBUG org.apache.hadoop.yarn.server.resourcemanager.scheduler.capacity.CapacityScheduler: Trying to schedule on node: slave1, available: <memory:4096, vCores:1>
2019-06-07 07:52:51,793 DEBUG org.apache.hadoop.yarn.server.resourcemanager.scheduler.capacity.CapacityScheduler: Trying to schedule on node: slave1, available: <memory:4096, vCores:1>
2019-06-07 07:52:51,793 DEBUG org.apache.hadoop.yarn.server.resourcemanager.scheduler.capacity.ParentQueue: Skip this queue=root, because it doesn't need more resource, schedulingMode=RESPECT_PARTITION_EXCLUSIVITY node-partition=
2019-06-07 07:52:51,793 DEBUG org.apache.hadoop.yarn.server.resourcemanager.scheduler.capacity.ParentQueue: Skip this queue=root, because it doesn't need more resource, schedulingMode=RESPECT_PARTITION_EXCLUSIVITY node-partition=
2019-06-07 07:52:51,797 DEBUG org.apache.hadoop.yarn.server.resourcemanager.rmnode.RMNodeImpl: Processing slave2:38494 of type STATUS_UPDATE
2019-06-07 07:52:51,797 DEBUG org.apache.hadoop.yarn.server.resourcemanager.rmnode.RMNodeImpl: Processing slave2:38494 of type STATUS_UPDATE
2019-06-07 07:52:51,797 DEBUG org.apache.hadoop.yarn.server.resourcemanager.scheduler.capacity.CapacityScheduler: nodeUpdate: slave2:38494 clusterResources: <memory:8192, vCores:2>
2019-06-07 07:52:51,797 DEBUG org.apache.hadoop.yarn.server.resourcemanager.scheduler.capacity.CapacityScheduler: nodeUpdate: slave2:38494 clusterResources: <memory:8192, vCores:2>
2019-06-07 07:52:51,797 DEBUG org.apache.hadoop.yarn.server.resourcemanager.scheduler.capacity.CapacityScheduler: Node being looked for scheduling slave2:38494 availableResource: <memory:4096, vCores:1>
2019-06-07 07:52:51,797 DEBUG org.apache.hadoop.yarn.server.resourcemanager.scheduler.capacity.CapacityScheduler: Node being looked for scheduling slave2:38494 availableResource: <memory:4096, vCores:1>
2019-06-07 07:52:51,797 DEBUG org.apache.hadoop.yarn.server.resourcemanager.scheduler.capacity.CapacityScheduler: Trying to schedule on node: slave2, available: <memory:4096, vCores:1>
2019-06-07 07:52:51,797 DEBUG org.apache.hadoop.yarn.server.resourcemanager.scheduler.capacity.CapacityScheduler: Trying to schedule on node: slave2, available: <memory:4096, vCores:1>
2019-06-07 07:52:51,797 DEBUG org.apache.hadoop.yarn.server.resourcemanager.scheduler.capacity.ParentQueue: Skip this queue=root, because it doesn't need more resource, schedulingMode=RESPECT_PARTITION_EXCLUSIVITY node-partition=
2019-06-07 07:52:51,797 DEBUG org.apache.hadoop.yarn.server.resourcemanager.scheduler.capacity.ParentQueue: Skip this queue=root, because it doesn't need more resource, schedulingMode=RESPECT_PARTITION_EXCLUSIVITY node-partition=
2019-06-07 07:52:52,796 DEBUG org.apache.hadoop.yarn.server.resourcemanager.rmnode.RMNodeImpl: Processing slave1:39995 of type STATUS_UPDATE
2019-06-07 07:52:52,796 DEBUG org.apache.hadoop.yarn.server.resourcemanager.rmnode.RMNodeImpl: Processing slave1:39995 of type STATUS_UPDATE
2019-06-07 07:52:52,796 DEBUG org.apache.hadoop.yarn.server.resourcemanager.scheduler.capacity.CapacityScheduler: nodeUpdate: slave1:39995 clusterResources: <memory:8192, vCores:2>
2019-06-07 07:52:52,796 DEBUG org.apache.hadoop.yarn.server.resourcemanager.scheduler.capacity.CapacityScheduler: nodeUpdate: slave1:39995 clusterResources: <memory:8192, vCores:2>
2019-06-07 07:52:52,796 DEBUG org.apache.hadoop.yarn.server.resourcemanager.scheduler.capacity.CapacityScheduler: Node being looked for scheduling slave1:39995 availableResource: <memory:4096, vCores:1>
2019-06-07 07:52:52,796 DEBUG org.apache.hadoop.yarn.server.resourcemanager.scheduler.capacity.CapacityScheduler: Node being looked for scheduling slave1:39995 availableResource: <memory:4096, vCores:1>
2019-06-07 07:52:52,797 DEBUG org.apache.hadoop.yarn.server.resourcemanager.scheduler.capacity.CapacityScheduler: Trying to schedule on node: slave1, available: <memory:4096, vCores:1>
2019-06-07 07:52:52,797 DEBUG org.apache.hadoop.yarn.server.resourcemanager.scheduler.capacity.CapacityScheduler: Trying to schedule on node: slave1, available: <memory:4096, vCores:1>
2019-06-07 07:52:52,797 DEBUG org.apache.hadoop.yarn.server.resourcemanager.scheduler.capacity.ParentQueue: Skip this queue=root, because it doesn't need more resource, schedulingMode=RESPECT_PARTITION_EXCLUSIVITY node-partition=
2019-06-07 07:52:52,797 DEBUG org.apache.hadoop.yarn.server.resourcemanager.scheduler.capacity.ParentQueue: Skip this queue=root, because it doesn't need more resource, schedulingMode=RESPECT_PARTITION_EXCLUSIVITY node-partition=
2019-06-07 07:52:52,798 DEBUG org.apache.hadoop.yarn.server.resourcemanager.rmnode.RMNodeImpl: Processing slave2:38494 of type STATUS_UPDATE
2019-06-07 07:52:52,798 DEBUG org.apache.hadoop.yarn.server.resourcemanager.rmnode.RMNodeImpl: Processing slave2:38494 of type STATUS_UPDATE
2019-06-07 07:52:52,799 DEBUG org.apache.hadoop.yarn.server.resourcemanager.scheduler.capacity.CapacityScheduler: nodeUpdate: slave2:38494 clusterResources: <memory:8192, vCores:2>
2019-06-07 07:52:52,799 DEBUG org.apache.hadoop.yarn.server.resourcemanager.scheduler.capacity.CapacityScheduler: nodeUpdate: slave2:38494 clusterResources: <memory:8192, vCores:2>
2019-06-07 07:52:52,799 DEBUG org.apache.hadoop.yarn.server.resourcemanager.scheduler.capacity.CapacityScheduler: Node being looked for scheduling slave2:38494 availableResource: <memory:4096, vCores:1>
2019-06-07 07:52:52,799 DEBUG org.apache.hadoop.yarn.server.resourcemanager.scheduler.capacity.CapacityScheduler: Node being looked for scheduling slave2:38494 availableResource: <memory:4096, vCores:1>
2019-06-07 07:52:52,799 DEBUG org.apache.hadoop.yarn.server.resourcemanager.scheduler.capacity.CapacityScheduler: Trying to schedule on node: slave2, available: <memory:4096, vCores:1>
2019-06-07 07:52:52,799 DEBUG org.apache.hadoop.yarn.server.resourcemanager.scheduler.capacity.CapacityScheduler: Trying to schedule on node: slave2, available: <memory:4096, vCores:1>
2019-06-07 07:52:52,799 DEBUG org.apache.hadoop.yarn.server.resourcemanager.scheduler.capacity.ParentQueue: Skip this queue=root, because it doesn't need more resource, schedulingMode=RESPECT_PARTITION_EXCLUSIVITY node-partition=
2019-06-07 07:52:52,799 DEBUG org.apache.hadoop.yarn.server.resourcemanager.scheduler.capacity.ParentQueue: Skip this queue=root, because it doesn't need more resource, schedulingMode=RESPECT_PARTITION_EXCLUSIVITY node-partition=
2019-06-07 07:52:53,802 DEBUG org.apache.hadoop.yarn.server.resourcemanager.rmnode.RMNodeImpl: Processing slave1:39995 of type STATUS_UPDATE
2019-06-07 07:52:53,802 DEBUG org.apache.hadoop.yarn.server.resourcemanager.rmnode.RMNodeImpl: Processing slave1:39995 of type STATUS_UPDATE
2019-06-07 07:52:53,802 DEBUG org.apache.hadoop.yarn.server.resourcemanager.rmnode.RMNodeImpl: Processing slave2:38494 of type STATUS_UPDATE
2019-06-07 07:52:53,802 DEBUG org.apache.hadoop.yarn.server.resourcemanager.rmnode.RMNodeImpl: Processing slave2:38494 of type STATUS_UPDATE
2019-06-07 07:52:53,802 DEBUG org.apache.hadoop.yarn.server.resourcemanager.scheduler.capacity.CapacityScheduler: nodeUpdate: slave1:39995 clusterResources: <memory:8192, vCores:2>
2019-06-07 07:52:53,802 DEBUG org.apache.hadoop.yarn.server.resourcemanager.scheduler.capacity.CapacityScheduler: nodeUpdate: slave1:39995 clusterResources: <memory:8192, vCores:2>
2019-06-07 07:52:53,802 DEBUG org.apache.hadoop.yarn.server.resourcemanager.scheduler.capacity.CapacityScheduler: Node being looked for scheduling slave1:39995 availableResource: <memory:4096, vCores:1>
2019-06-07 07:52:53,802 DEBUG org.apache.hadoop.yarn.server.resourcemanager.scheduler.capacity.CapacityScheduler: Node being looked for scheduling slave1:39995 availableResource: <memory:4096, vCores:1>
2019-06-07 07:52:53,802 DEBUG org.apache.hadoop.yarn.server.resourcemanager.scheduler.capacity.CapacityScheduler: Trying to schedule on node: slave1, available: <memory:4096, vCores:1>
2019-06-07 07:52:53,802 DEBUG org.apache.hadoop.yarn.server.resourcemanager.scheduler.capacity.CapacityScheduler: Trying to schedule on node: slave1, available: <memory:4096, vCores:1>
