2019-06-07 07:43:08,501 INFO org.apache.hadoop.yarn.server.resourcemanager.ResourceManager: STARTUP_MSG: 
/************************************************************
STARTUP_MSG: Starting ResourceManager
STARTUP_MSG:   user = root
STARTUP_MSG:   host = master/172.17.0.2
STARTUP_MSG:   args = []
STARTUP_MSG:   version = 2.8.5
STARTUP_MSG:   build = https://git-wip-us.apache.org/repos/asf/hadoop.git -r 0b8464d75227fcee2c6e7f2410377b3d53d3d5f8; compiled by 'jdu' on 2018-09-10T03:32Z
STARTUP_MSG:   java = 1.8.0_191
************************************************************/
2019-06-07 07:43:08,501 INFO org.apache.hadoop.yarn.server.resourcemanager.ResourceManager: STARTUP_MSG: 
/************************************************************
STARTUP_MSG: Starting ResourceManager
STARTUP_MSG:   user = root
STARTUP_MSG:   host = master/172.17.0.2
STARTUP_MSG:   args = []
STARTUP_MSG:   version = 2.8.5
STARTUP_MSG:   build = https://git-wip-us.apache.org/repos/asf/hadoop.git -r 0b8464d75227fcee2c6e7f2410377b3d53d3d5f8; compiled by 'jdu' on 2018-09-10T03:32Z
STARTUP_MSG:   java = 1.8.0_191
************************************************************/
2019-06-07 07:43:08,508 INFO org.apache.hadoop.yarn.server.resourcemanager.ResourceManager: registered UNIX signal handlers for [TERM, HUP, INT]
2019-06-07 07:43:08,508 INFO org.apache.hadoop.yarn.server.resourcemanager.ResourceManager: registered UNIX signal handlers for [TERM, HUP, INT]
2019-06-07 07:43:08,758 INFO org.apache.hadoop.conf.Configuration: found resource core-site.xml at file:/hadoop-2.8.5/etc/hadoop/core-site.xml
2019-06-07 07:43:08,855 WARN org.apache.hadoop.conf.Configuration: core-site.xml:an attempt to override final parameter: fs.defaultFS;  Ignoring.
2019-06-07 07:43:08,873 INFO org.apache.hadoop.security.Groups: clearing userToGroupsMap cache
2019-06-07 07:43:08,921 INFO org.apache.hadoop.conf.Configuration: found resource yarn-site.xml at file:/hadoop-2.8.5/etc/hadoop/yarn-site.xml
2019-06-07 07:43:09,033 INFO org.apache.hadoop.yarn.event.AsyncDispatcher: Registering class org.apache.hadoop.yarn.server.resourcemanager.RMFatalEventType for class org.apache.hadoop.yarn.server.resourcemanager.ResourceManager$RMFatalEventDispatcher
2019-06-07 07:43:09,065 INFO org.apache.hadoop.yarn.server.resourcemanager.security.NMTokenSecretManagerInRM: NMTokenKeyRollingInterval: 86400000ms and NMTokenKeyActivationDelay: 900000ms
2019-06-07 07:43:09,065 INFO org.apache.hadoop.yarn.server.resourcemanager.security.NMTokenSecretManagerInRM: NMTokenKeyRollingInterval: 86400000ms and NMTokenKeyActivationDelay: 900000ms
2019-06-07 07:43:09,068 INFO org.apache.hadoop.yarn.server.resourcemanager.security.RMContainerTokenSecretManager: ContainerTokenKeyRollingInterval: 86400000ms and ContainerTokenKeyActivationDelay: 900000ms
2019-06-07 07:43:09,068 INFO org.apache.hadoop.yarn.server.resourcemanager.security.RMContainerTokenSecretManager: ContainerTokenKeyRollingInterval: 86400000ms and ContainerTokenKeyActivationDelay: 900000ms
2019-06-07 07:43:09,071 INFO org.apache.hadoop.yarn.server.resourcemanager.security.AMRMTokenSecretManager: AMRMTokenKeyRollingInterval: 86400000ms and AMRMTokenKeyActivationDelay: 900000 ms
2019-06-07 07:43:09,071 INFO org.apache.hadoop.yarn.server.resourcemanager.security.AMRMTokenSecretManager: AMRMTokenKeyRollingInterval: 86400000ms and AMRMTokenKeyActivationDelay: 900000 ms
2019-06-07 07:43:09,092 INFO org.apache.hadoop.yarn.event.AsyncDispatcher: Registering class org.apache.hadoop.yarn.server.resourcemanager.recovery.RMStateStoreEventType for class org.apache.hadoop.yarn.server.resourcemanager.recovery.RMStateStore$ForwardingEventHandler
2019-06-07 07:43:09,094 INFO org.apache.hadoop.yarn.event.AsyncDispatcher: Registering class org.apache.hadoop.yarn.server.resourcemanager.NodesListManagerEventType for class org.apache.hadoop.yarn.server.resourcemanager.NodesListManager
2019-06-07 07:43:09,094 INFO org.apache.hadoop.yarn.server.resourcemanager.ResourceManager: Using Scheduler: org.apache.hadoop.yarn.server.resourcemanager.scheduler.capacity.CapacityScheduler
2019-06-07 07:43:09,094 INFO org.apache.hadoop.yarn.server.resourcemanager.ResourceManager: Using Scheduler: org.apache.hadoop.yarn.server.resourcemanager.scheduler.capacity.CapacityScheduler
2019-06-07 07:43:09,110 INFO org.apache.hadoop.yarn.event.AsyncDispatcher: Registering class org.apache.hadoop.yarn.server.resourcemanager.scheduler.event.SchedulerEventType for class org.apache.hadoop.yarn.server.resourcemanager.ResourceManager$SchedulerEventDispatcher
2019-06-07 07:43:09,111 INFO org.apache.hadoop.yarn.event.AsyncDispatcher: Registering class org.apache.hadoop.yarn.server.resourcemanager.rmapp.RMAppEventType for class org.apache.hadoop.yarn.server.resourcemanager.ResourceManager$ApplicationEventDispatcher
2019-06-07 07:43:09,112 INFO org.apache.hadoop.yarn.event.AsyncDispatcher: Registering class org.apache.hadoop.yarn.server.resourcemanager.rmapp.attempt.RMAppAttemptEventType for class org.apache.hadoop.yarn.server.resourcemanager.ResourceManager$ApplicationAttemptEventDispatcher
2019-06-07 07:43:09,112 INFO org.apache.hadoop.yarn.event.AsyncDispatcher: Registering class org.apache.hadoop.yarn.server.resourcemanager.rmnode.RMNodeEventType for class org.apache.hadoop.yarn.server.resourcemanager.ResourceManager$NodeEventDispatcher
2019-06-07 07:43:09,150 INFO org.apache.hadoop.metrics2.impl.MetricsConfig: loaded properties from hadoop-metrics2.properties
2019-06-07 07:43:09,202 INFO org.apache.hadoop.metrics2.impl.MetricsSystemImpl: Scheduled Metric snapshot period at 10 second(s).
2019-06-07 07:43:09,202 INFO org.apache.hadoop.metrics2.impl.MetricsSystemImpl: ResourceManager metrics system started
2019-06-07 07:43:09,213 INFO org.apache.hadoop.yarn.event.AsyncDispatcher: Registering class org.apache.hadoop.yarn.server.resourcemanager.RMAppManagerEventType for class org.apache.hadoop.yarn.server.resourcemanager.RMAppManager
2019-06-07 07:43:09,219 INFO org.apache.hadoop.yarn.event.AsyncDispatcher: Registering class org.apache.hadoop.yarn.server.resourcemanager.amlauncher.AMLauncherEventType for class org.apache.hadoop.yarn.server.resourcemanager.amlauncher.ApplicationMasterLauncher
2019-06-07 07:43:09,220 INFO org.apache.hadoop.yarn.server.resourcemanager.RMNMInfo: Registered RMNMInfo MBean
2019-06-07 07:43:09,220 INFO org.apache.hadoop.yarn.server.resourcemanager.RMNMInfo: Registered RMNMInfo MBean
2019-06-07 07:43:09,225 INFO org.apache.hadoop.yarn.security.YarnAuthorizationProvider: org.apache.hadoop.yarn.security.ConfiguredYarnAuthorizer is instiantiated.
2019-06-07 07:43:09,226 INFO org.apache.hadoop.util.HostsFileReader: Refreshing hosts (include/exclude) list
2019-06-07 07:43:09,226 DEBUG org.apache.hadoop.yarn.server.resourcemanager.NodesListManager: hostsReader: in= out=
2019-06-07 07:43:09,226 DEBUG org.apache.hadoop.yarn.server.resourcemanager.NodesListManager: hostsReader: in= out=
2019-06-07 07:43:09,231 INFO org.apache.hadoop.conf.Configuration: found resource capacity-scheduler.xml at file:/hadoop-2.8.5/etc/hadoop/capacity-scheduler.xml
2019-06-07 07:43:09,251 DEBUG org.apache.hadoop.yarn.server.resourcemanager.scheduler.capacity.CapacitySchedulerConfiguration: CSConf - getQueues called for: queuePrefix=yarn.scheduler.capacity.root.
2019-06-07 07:43:09,251 DEBUG org.apache.hadoop.yarn.server.resourcemanager.scheduler.capacity.CapacitySchedulerConfiguration: CSConf - getQueues called for: queuePrefix=yarn.scheduler.capacity.root.
2019-06-07 07:43:09,251 DEBUG org.apache.hadoop.yarn.server.resourcemanager.scheduler.capacity.CapacitySchedulerConfiguration: CSConf - getQueues: queuePrefix=yarn.scheduler.capacity.root., queues=default
2019-06-07 07:43:09,251 DEBUG org.apache.hadoop.yarn.server.resourcemanager.scheduler.capacity.CapacitySchedulerConfiguration: CSConf - getQueues: queuePrefix=yarn.scheduler.capacity.root., queues=default
2019-06-07 07:43:09,268 DEBUG org.apache.hadoop.yarn.server.resourcemanager.scheduler.capacity.CapacitySchedulerConfiguration: CSConf - getCapacity: queuePrefix=yarn.scheduler.capacity.root., capacity=100.0
2019-06-07 07:43:09,268 DEBUG org.apache.hadoop.yarn.server.resourcemanager.scheduler.capacity.CapacitySchedulerConfiguration: CSConf - getCapacity: queuePrefix=yarn.scheduler.capacity.root., capacity=100.0
2019-06-07 07:43:09,269 DEBUG org.apache.hadoop.yarn.server.resourcemanager.scheduler.capacity.CapacitySchedulerConfiguration: CSConf - getCapacity: queuePrefix=yarn.scheduler.capacity.root., capacity=100.0
2019-06-07 07:43:09,269 DEBUG org.apache.hadoop.yarn.server.resourcemanager.scheduler.capacity.CapacitySchedulerConfiguration: CSConf - getCapacity: queuePrefix=yarn.scheduler.capacity.root., capacity=100.0
2019-06-07 07:43:09,281 DEBUG org.apache.hadoop.yarn.server.resourcemanager.scheduler.capacity.CapacitySchedulerConfiguration: max alloc mb per queue for root is -1
2019-06-07 07:43:09,281 DEBUG org.apache.hadoop.yarn.server.resourcemanager.scheduler.capacity.CapacitySchedulerConfiguration: max alloc mb per queue for root is -1
2019-06-07 07:43:09,282 DEBUG org.apache.hadoop.yarn.server.resourcemanager.scheduler.capacity.CapacitySchedulerConfiguration: max alloc vcores per queue for root is -1
2019-06-07 07:43:09,282 DEBUG org.apache.hadoop.yarn.server.resourcemanager.scheduler.capacity.CapacitySchedulerConfiguration: max alloc vcores per queue for root is -1
2019-06-07 07:43:09,282 INFO org.apache.hadoop.yarn.server.resourcemanager.scheduler.capacity.CapacitySchedulerConfiguration: max alloc mb per queue for root is undefined
2019-06-07 07:43:09,282 INFO org.apache.hadoop.yarn.server.resourcemanager.scheduler.capacity.CapacitySchedulerConfiguration: max alloc mb per queue for root is undefined
2019-06-07 07:43:09,282 INFO org.apache.hadoop.yarn.server.resourcemanager.scheduler.capacity.CapacitySchedulerConfiguration: max alloc vcore per queue for root is undefined
2019-06-07 07:43:09,282 INFO org.apache.hadoop.yarn.server.resourcemanager.scheduler.capacity.CapacitySchedulerConfiguration: max alloc vcore per queue for root is undefined
2019-06-07 07:43:09,305 INFO org.apache.hadoop.yarn.server.resourcemanager.scheduler.capacity.ParentQueue: root, capacity=1.0, asboluteCapacity=1.0, maxCapacity=1.0, asboluteMaxCapacity=1.0, state=RUNNING, acls=ADMINISTER_QUEUE:*SUBMIT_APP:*, labels=*,, offswitchPerHeartbeatLimit = 1, reservationsContinueLooking=true
2019-06-07 07:43:09,305 INFO org.apache.hadoop.yarn.server.resourcemanager.scheduler.capacity.ParentQueue: root, capacity=1.0, asboluteCapacity=1.0, maxCapacity=1.0, asboluteMaxCapacity=1.0, state=RUNNING, acls=ADMINISTER_QUEUE:*SUBMIT_APP:*, labels=*,, offswitchPerHeartbeatLimit = 1, reservationsContinueLooking=true
2019-06-07 07:43:09,305 INFO org.apache.hadoop.yarn.server.resourcemanager.scheduler.capacity.ParentQueue: Initialized parent-queue root name=root, fullname=root
2019-06-07 07:43:09,305 INFO org.apache.hadoop.yarn.server.resourcemanager.scheduler.capacity.ParentQueue: Initialized parent-queue root name=root, fullname=root
2019-06-07 07:43:09,305 DEBUG org.apache.hadoop.yarn.server.resourcemanager.scheduler.capacity.CapacitySchedulerConfiguration: CSConf - getQueues called for: queuePrefix=yarn.scheduler.capacity.root.default.
2019-06-07 07:43:09,305 DEBUG org.apache.hadoop.yarn.server.resourcemanager.scheduler.capacity.CapacitySchedulerConfiguration: CSConf - getQueues called for: queuePrefix=yarn.scheduler.capacity.root.default.
2019-06-07 07:43:09,305 DEBUG org.apache.hadoop.yarn.server.resourcemanager.scheduler.capacity.CapacitySchedulerConfiguration: CSConf - getQueues: queuePrefix=yarn.scheduler.capacity.root.default., queues=
2019-06-07 07:43:09,305 DEBUG org.apache.hadoop.yarn.server.resourcemanager.scheduler.capacity.CapacitySchedulerConfiguration: CSConf - getQueues: queuePrefix=yarn.scheduler.capacity.root.default., queues=
2019-06-07 07:43:09,316 DEBUG org.apache.hadoop.yarn.server.resourcemanager.scheduler.capacity.LeafQueue: LeafQueue: name=default, fullname=root.default
2019-06-07 07:43:09,316 DEBUG org.apache.hadoop.yarn.server.resourcemanager.scheduler.capacity.LeafQueue: LeafQueue: name=default, fullname=root.default
2019-06-07 07:43:09,317 DEBUG org.apache.hadoop.yarn.server.resourcemanager.scheduler.capacity.CapacitySchedulerConfiguration: CSConf - getCapacity: queuePrefix=yarn.scheduler.capacity.root.default., capacity=100.0
2019-06-07 07:43:09,317 DEBUG org.apache.hadoop.yarn.server.resourcemanager.scheduler.capacity.CapacitySchedulerConfiguration: CSConf - getCapacity: queuePrefix=yarn.scheduler.capacity.root.default., capacity=100.0
2019-06-07 07:43:09,317 DEBUG org.apache.hadoop.yarn.server.resourcemanager.scheduler.capacity.CapacitySchedulerConfiguration: max alloc mb per queue for root.default is -1
2019-06-07 07:43:09,317 DEBUG org.apache.hadoop.yarn.server.resourcemanager.scheduler.capacity.CapacitySchedulerConfiguration: max alloc mb per queue for root.default is -1
2019-06-07 07:43:09,317 DEBUG org.apache.hadoop.yarn.server.resourcemanager.scheduler.capacity.CapacitySchedulerConfiguration: max alloc vcores per queue for root.default is -1
2019-06-07 07:43:09,317 DEBUG org.apache.hadoop.yarn.server.resourcemanager.scheduler.capacity.CapacitySchedulerConfiguration: max alloc vcores per queue for root.default is -1
2019-06-07 07:43:09,317 INFO org.apache.hadoop.yarn.server.resourcemanager.scheduler.capacity.CapacitySchedulerConfiguration: max alloc mb per queue for root.default is undefined
2019-06-07 07:43:09,317 INFO org.apache.hadoop.yarn.server.resourcemanager.scheduler.capacity.CapacitySchedulerConfiguration: max alloc mb per queue for root.default is undefined
2019-06-07 07:43:09,317 INFO org.apache.hadoop.yarn.server.resourcemanager.scheduler.capacity.CapacitySchedulerConfiguration: max alloc vcore per queue for root.default is undefined
2019-06-07 07:43:09,317 INFO org.apache.hadoop.yarn.server.resourcemanager.scheduler.capacity.CapacitySchedulerConfiguration: max alloc vcore per queue for root.default is undefined
2019-06-07 07:43:09,319 INFO org.apache.hadoop.yarn.server.resourcemanager.scheduler.capacity.LeafQueue: Initializing default
capacity = 1.0 [= (float) configuredCapacity / 100 ]
asboluteCapacity = 1.0 [= parentAbsoluteCapacity * capacity ]
maxCapacity = 1.0 [= configuredMaxCapacity ]
absoluteMaxCapacity = 1.0 [= 1.0 maximumCapacity undefined, (parentAbsoluteMaxCapacity * maximumCapacity) / 100 otherwise ]
userLimit = 100 [= configuredUserLimit ]
userLimitFactor = 1.0 [= configuredUserLimitFactor ]
maxApplications = 10000 [= configuredMaximumSystemApplicationsPerQueue or (int)(configuredMaximumSystemApplications * absoluteCapacity)]
maxApplicationsPerUser = 10000 [= (int)(maxApplications * (userLimit / 100.0f) * userLimitFactor) ]
usedCapacity = 0.0 [= usedResourcesMemory / (clusterResourceMemory * absoluteCapacity)]
absoluteUsedCapacity = 0.0 [= usedResourcesMemory / clusterResourceMemory]
maxAMResourcePerQueuePercent = 0.1 [= configuredMaximumAMResourcePercent ]
minimumAllocationFactor = 0.875 [= (float)(maximumAllocationMemory - minimumAllocationMemory) / maximumAllocationMemory ]
maximumAllocation = <memory:8192, vCores:4> [= configuredMaxAllocation ]
numContainers = 0 [= currentNumContainers ]
state = RUNNING [= configuredState ]
acls = ADMINISTER_QUEUE:*SUBMIT_APP:* [= configuredAcls ]
nodeLocalityDelay = 40
labels=*,
reservationsContinueLooking = true
preemptionDisabled = true
defaultAppPriorityPerQueue = 0
2019-06-07 07:43:09,319 INFO org.apache.hadoop.yarn.server.resourcemanager.scheduler.capacity.LeafQueue: Initializing default
capacity = 1.0 [= (float) configuredCapacity / 100 ]
asboluteCapacity = 1.0 [= parentAbsoluteCapacity * capacity ]
maxCapacity = 1.0 [= configuredMaxCapacity ]
absoluteMaxCapacity = 1.0 [= 1.0 maximumCapacity undefined, (parentAbsoluteMaxCapacity * maximumCapacity) / 100 otherwise ]
userLimit = 100 [= configuredUserLimit ]
userLimitFactor = 1.0 [= configuredUserLimitFactor ]
maxApplications = 10000 [= configuredMaximumSystemApplicationsPerQueue or (int)(configuredMaximumSystemApplications * absoluteCapacity)]
maxApplicationsPerUser = 10000 [= (int)(maxApplications * (userLimit / 100.0f) * userLimitFactor) ]
usedCapacity = 0.0 [= usedResourcesMemory / (clusterResourceMemory * absoluteCapacity)]
absoluteUsedCapacity = 0.0 [= usedResourcesMemory / clusterResourceMemory]
maxAMResourcePerQueuePercent = 0.1 [= configuredMaximumAMResourcePercent ]
minimumAllocationFactor = 0.875 [= (float)(maximumAllocationMemory - minimumAllocationMemory) / maximumAllocationMemory ]
maximumAllocation = <memory:8192, vCores:4> [= configuredMaxAllocation ]
numContainers = 0 [= currentNumContainers ]
state = RUNNING [= configuredState ]
acls = ADMINISTER_QUEUE:*SUBMIT_APP:* [= configuredAcls ]
nodeLocalityDelay = 40
labels=*,
reservationsContinueLooking = true
preemptionDisabled = true
defaultAppPriorityPerQueue = 0
2019-06-07 07:43:09,319 INFO org.apache.hadoop.yarn.server.resourcemanager.scheduler.capacity.CapacityScheduler: Initialized queue: default: capacity=1.0, absoluteCapacity=1.0, usedResources=<memory:0, vCores:0>, usedCapacity=0.0, absoluteUsedCapacity=0.0, numApps=0, numContainers=0
2019-06-07 07:43:09,319 INFO org.apache.hadoop.yarn.server.resourcemanager.scheduler.capacity.CapacityScheduler: Initialized queue: default: capacity=1.0, absoluteCapacity=1.0, usedResources=<memory:0, vCores:0>, usedCapacity=0.0, absoluteUsedCapacity=0.0, numApps=0, numContainers=0
2019-06-07 07:43:09,320 DEBUG org.apache.hadoop.yarn.server.resourcemanager.scheduler.capacity.ParentQueue: setChildQueues: root.defaultusedCapacity=(0.0),  label=(*)
2019-06-07 07:43:09,320 DEBUG org.apache.hadoop.yarn.server.resourcemanager.scheduler.capacity.ParentQueue: setChildQueues: root.defaultusedCapacity=(0.0),  label=(*)
2019-06-07 07:43:09,320 INFO org.apache.hadoop.yarn.server.resourcemanager.scheduler.capacity.CapacityScheduler: Initialized queue: root: numChildQueue= 1, capacity=1.0, absoluteCapacity=1.0, usedResources=<memory:0, vCores:0>usedCapacity=0.0, numApps=0, numContainers=0
2019-06-07 07:43:09,320 INFO org.apache.hadoop.yarn.server.resourcemanager.scheduler.capacity.CapacityScheduler: Initialized queue: root: numChildQueue= 1, capacity=1.0, absoluteCapacity=1.0, usedResources=<memory:0, vCores:0>usedCapacity=0.0, numApps=0, numContainers=0
2019-06-07 07:43:09,321 INFO org.apache.hadoop.yarn.server.resourcemanager.scheduler.capacity.CapacityScheduler: Initialized root queue root: numChildQueue= 1, capacity=1.0, absoluteCapacity=1.0, usedResources=<memory:0, vCores:0>usedCapacity=0.0, numApps=0, numContainers=0
2019-06-07 07:43:09,321 INFO org.apache.hadoop.yarn.server.resourcemanager.scheduler.capacity.CapacityScheduler: Initialized root queue root: numChildQueue= 1, capacity=1.0, absoluteCapacity=1.0, usedResources=<memory:0, vCores:0>usedCapacity=0.0, numApps=0, numContainers=0
2019-06-07 07:43:09,321 INFO org.apache.hadoop.yarn.server.resourcemanager.scheduler.capacity.CapacityScheduler: Initialized queue mappings, override: false
2019-06-07 07:43:09,321 INFO org.apache.hadoop.yarn.server.resourcemanager.scheduler.capacity.CapacityScheduler: Initialized queue mappings, override: false
2019-06-07 07:43:09,322 INFO org.apache.hadoop.yarn.server.resourcemanager.scheduler.capacity.CapacityScheduler: Initialized CapacityScheduler with calculator=class org.apache.hadoop.yarn.util.resource.DefaultResourceCalculator, minimumAllocation=<<memory:1024, vCores:1>>, maximumAllocation=<<memory:8192, vCores:4>>, asynchronousScheduling=false, asyncScheduleInterval=5ms
2019-06-07 07:43:09,322 INFO org.apache.hadoop.yarn.server.resourcemanager.scheduler.capacity.CapacityScheduler: Initialized CapacityScheduler with calculator=class org.apache.hadoop.yarn.util.resource.DefaultResourceCalculator, minimumAllocation=<<memory:1024, vCores:1>>, maximumAllocation=<<memory:8192, vCores:4>>, asynchronousScheduling=false, asyncScheduleInterval=5ms
2019-06-07 07:43:09,324 INFO org.apache.hadoop.conf.Configuration: dynamic-resources.xml not found
2019-06-07 07:43:09,339 INFO org.apache.hadoop.yarn.server.resourcemanager.metrics.SystemMetricsPublisher: YARN system metrics publishing service is not enabled
2019-06-07 07:43:09,339 INFO org.apache.hadoop.yarn.server.resourcemanager.metrics.SystemMetricsPublisher: YARN system metrics publishing service is not enabled
2019-06-07 07:43:09,339 INFO org.apache.hadoop.yarn.server.resourcemanager.ResourceManager: Transitioning to active state
2019-06-07 07:43:09,339 INFO org.apache.hadoop.yarn.server.resourcemanager.ResourceManager: Transitioning to active state
2019-06-07 07:43:09,383 INFO org.apache.hadoop.util.JvmPauseMonitor: Starting JVM pause monitor
2019-06-07 07:43:09,387 DEBUG org.apache.hadoop.yarn.server.resourcemanager.recovery.RMStateStore: Processing event of type UPDATE_AMRM_TOKEN
2019-06-07 07:43:09,387 DEBUG org.apache.hadoop.yarn.server.resourcemanager.recovery.RMStateStore: Processing event of type UPDATE_AMRM_TOKEN
2019-06-07 07:43:09,388 INFO org.apache.hadoop.yarn.server.resourcemanager.recovery.RMStateStore: Updating AMRMToken
2019-06-07 07:43:09,388 INFO org.apache.hadoop.yarn.server.resourcemanager.recovery.RMStateStore: Updating AMRMToken
2019-06-07 07:43:09,388 INFO org.apache.hadoop.yarn.server.resourcemanager.security.RMContainerTokenSecretManager: Rolling master-key for container-tokens
2019-06-07 07:43:09,388 INFO org.apache.hadoop.yarn.server.resourcemanager.security.RMContainerTokenSecretManager: Rolling master-key for container-tokens
2019-06-07 07:43:09,388 INFO org.apache.hadoop.yarn.server.resourcemanager.security.NMTokenSecretManagerInRM: Rolling master-key for nm-tokens
2019-06-07 07:43:09,388 INFO org.apache.hadoop.yarn.server.resourcemanager.security.NMTokenSecretManagerInRM: Rolling master-key for nm-tokens
2019-06-07 07:43:09,388 INFO org.apache.hadoop.security.token.delegation.AbstractDelegationTokenSecretManager: Updating the current master key for generating delegation tokens
2019-06-07 07:43:09,388 INFO org.apache.hadoop.yarn.server.resourcemanager.security.RMDelegationTokenSecretManager: storing master key with keyID 1
2019-06-07 07:43:09,388 INFO org.apache.hadoop.yarn.server.resourcemanager.security.RMDelegationTokenSecretManager: storing master key with keyID 1
2019-06-07 07:43:09,389 DEBUG org.apache.hadoop.yarn.server.resourcemanager.recovery.RMStateStore: Processing event of type STORE_MASTERKEY
2019-06-07 07:43:09,389 DEBUG org.apache.hadoop.yarn.server.resourcemanager.recovery.RMStateStore: Processing event of type STORE_MASTERKEY
2019-06-07 07:43:09,389 INFO org.apache.hadoop.yarn.server.resourcemanager.recovery.RMStateStore: Storing RMDTMasterKey.
2019-06-07 07:43:09,389 INFO org.apache.hadoop.yarn.server.resourcemanager.recovery.RMStateStore: Storing RMDTMasterKey.
2019-06-07 07:43:09,390 INFO org.apache.hadoop.security.token.delegation.AbstractDelegationTokenSecretManager: Starting expired delegation token remover thread, tokenRemoverScanInterval=60 min(s)
2019-06-07 07:43:09,390 INFO org.apache.hadoop.security.token.delegation.AbstractDelegationTokenSecretManager: Updating the current master key for generating delegation tokens
2019-06-07 07:43:09,391 INFO org.apache.hadoop.yarn.server.resourcemanager.security.RMDelegationTokenSecretManager: storing master key with keyID 2
2019-06-07 07:43:09,391 INFO org.apache.hadoop.yarn.server.resourcemanager.security.RMDelegationTokenSecretManager: storing master key with keyID 2
2019-06-07 07:43:09,391 DEBUG org.apache.hadoop.yarn.server.resourcemanager.recovery.RMStateStore: Processing event of type STORE_MASTERKEY
2019-06-07 07:43:09,391 DEBUG org.apache.hadoop.yarn.server.resourcemanager.recovery.RMStateStore: Processing event of type STORE_MASTERKEY
2019-06-07 07:43:09,391 INFO org.apache.hadoop.yarn.server.resourcemanager.recovery.RMStateStore: Storing RMDTMasterKey.
2019-06-07 07:43:09,391 INFO org.apache.hadoop.yarn.server.resourcemanager.recovery.RMStateStore: Storing RMDTMasterKey.
2019-06-07 07:43:09,392 INFO org.apache.hadoop.yarn.event.AsyncDispatcher: Registering class org.apache.hadoop.yarn.nodelabels.event.NodeLabelsStoreEventType for class org.apache.hadoop.yarn.nodelabels.CommonNodeLabelsManager$ForwardingEventHandler
2019-06-07 07:43:09,418 INFO org.apache.hadoop.ipc.CallQueueManager: Using callQueue: class java.util.concurrent.LinkedBlockingQueue queueCapacity: 5000 scheduler: class org.apache.hadoop.ipc.DefaultRpcScheduler
2019-06-07 07:43:09,435 INFO org.apache.hadoop.ipc.Server: Starting Socket Reader #1 for port 8031
2019-06-07 07:43:09,788 INFO org.apache.hadoop.yarn.factories.impl.pb.RpcServerFactoryPBImpl: Adding protocol org.apache.hadoop.yarn.server.api.ResourceTrackerPB to the server
2019-06-07 07:43:09,791 INFO org.apache.hadoop.ipc.Server: IPC Server Responder: starting
2019-06-07 07:43:09,792 INFO org.apache.hadoop.ipc.Server: IPC Server listener on 8031: starting
2019-06-07 07:43:09,825 INFO org.apache.hadoop.ipc.CallQueueManager: Using callQueue: class java.util.concurrent.LinkedBlockingQueue queueCapacity: 5000 scheduler: class org.apache.hadoop.ipc.DefaultRpcScheduler
2019-06-07 07:43:09,919 INFO org.apache.hadoop.ipc.Server: Starting Socket Reader #1 for port 8030
2019-06-07 07:43:09,950 INFO org.apache.hadoop.yarn.factories.impl.pb.RpcServerFactoryPBImpl: Adding protocol org.apache.hadoop.yarn.api.ApplicationMasterProtocolPB to the server
2019-06-07 07:43:09,971 INFO org.apache.hadoop.ipc.Server: IPC Server Responder: starting
2019-06-07 07:43:09,971 INFO org.apache.hadoop.ipc.Server: IPC Server listener on 8030: starting
2019-06-07 07:43:10,357 INFO org.apache.hadoop.ipc.CallQueueManager: Using callQueue: class java.util.concurrent.LinkedBlockingQueue queueCapacity: 5000 scheduler: class org.apache.hadoop.ipc.DefaultRpcScheduler
2019-06-07 07:43:10,386 INFO org.apache.hadoop.ipc.Server: Starting Socket Reader #1 for port 8032
2019-06-07 07:43:10,401 INFO org.apache.hadoop.yarn.factories.impl.pb.RpcServerFactoryPBImpl: Adding protocol org.apache.hadoop.yarn.api.ApplicationClientProtocolPB to the server
2019-06-07 07:43:10,415 INFO org.apache.hadoop.ipc.Server: IPC Server Responder: starting
2019-06-07 07:43:10,422 INFO org.apache.hadoop.ipc.Server: IPC Server listener on 8032: starting
2019-06-07 07:43:10,778 INFO org.apache.hadoop.yarn.server.resourcemanager.ResourceManager: Transitioned to active state
2019-06-07 07:43:10,778 INFO org.apache.hadoop.yarn.server.resourcemanager.ResourceManager: Transitioned to active state
2019-06-07 07:43:10,999 INFO org.mortbay.log: Logging to org.slf4j.impl.Log4jLoggerAdapter(org.mortbay.log) via org.mortbay.log.Slf4jLog
2019-06-07 07:43:11,029 INFO org.apache.hadoop.security.authentication.server.AuthenticationFilter: Unable to initialize FileSignerSecretProvider, falling back to use random secrets.
2019-06-07 07:43:11,051 INFO org.apache.hadoop.http.HttpRequestLog: Http request log for http.requests.resourcemanager is not defined
2019-06-07 07:43:11,105 INFO org.apache.hadoop.http.HttpServer2: Added global filter 'safety' (class=org.apache.hadoop.http.HttpServer2$QuotingInputFilter)
2019-06-07 07:43:11,109 INFO org.apache.hadoop.http.HttpServer2: Added filter RMAuthenticationFilter (class=org.apache.hadoop.yarn.server.security.http.RMAuthenticationFilter) to context cluster
2019-06-07 07:43:11,109 INFO org.apache.hadoop.http.HttpServer2: Added filter RMAuthenticationFilter (class=org.apache.hadoop.yarn.server.security.http.RMAuthenticationFilter) to context static
2019-06-07 07:43:11,109 INFO org.apache.hadoop.http.HttpServer2: Added filter RMAuthenticationFilter (class=org.apache.hadoop.yarn.server.security.http.RMAuthenticationFilter) to context logs
2019-06-07 07:43:11,109 INFO org.apache.hadoop.http.HttpServer2: Added filter static_user_filter (class=org.apache.hadoop.http.lib.StaticUserWebFilter$StaticUserFilter) to context cluster
2019-06-07 07:43:11,109 INFO org.apache.hadoop.http.HttpServer2: Added filter static_user_filter (class=org.apache.hadoop.http.lib.StaticUserWebFilter$StaticUserFilter) to context static
2019-06-07 07:43:11,130 INFO org.apache.hadoop.http.HttpServer2: Added filter static_user_filter (class=org.apache.hadoop.http.lib.StaticUserWebFilter$StaticUserFilter) to context logs
2019-06-07 07:43:11,134 INFO org.apache.hadoop.http.HttpServer2: adding path spec: /cluster/*
2019-06-07 07:43:11,134 INFO org.apache.hadoop.http.HttpServer2: adding path spec: /ws/*
2019-06-07 07:43:12,788 INFO org.apache.hadoop.yarn.webapp.WebApps: Registered webapp guice modules
2019-06-07 07:43:12,790 INFO org.apache.hadoop.http.HttpServer2: Jetty bound to port 8088
2019-06-07 07:43:12,790 INFO org.mortbay.log: jetty-6.1.26
2019-06-07 07:43:12,971 INFO org.mortbay.log: Extract jar:file:/hadoop-2.8.5/share/hadoop/yarn/hadoop-yarn-common-2.8.5.jar!/webapps/cluster to /tmp/Jetty_master_8088_cluster____i4ls4w/webapp
2019-06-07 07:43:13,398 INFO org.apache.hadoop.security.token.delegation.AbstractDelegationTokenSecretManager: Updating the current master key for generating delegation tokens
2019-06-07 07:43:13,440 INFO org.apache.hadoop.security.token.delegation.AbstractDelegationTokenSecretManager: Starting expired delegation token remover thread, tokenRemoverScanInterval=60 min(s)
2019-06-07 07:43:13,441 INFO org.apache.hadoop.security.token.delegation.AbstractDelegationTokenSecretManager: Updating the current master key for generating delegation tokens
2019-06-07 07:43:16,842 INFO org.apache.hadoop.yarn.server.resourcemanager.ResourceTrackerService: NodeManager from node slave2(cmPort: 33474 httpPort: 8042) registered with capability: <memory:4096, vCores:1>, assigned nodeId slave2:33474
2019-06-07 07:43:16,842 INFO org.apache.hadoop.yarn.server.resourcemanager.ResourceTrackerService: NodeManager from node slave2(cmPort: 33474 httpPort: 8042) registered with capability: <memory:4096, vCores:1>, assigned nodeId slave2:33474
2019-06-07 07:43:16,844 INFO org.apache.hadoop.yarn.server.resourcemanager.ResourceTrackerService: NodeManager from node slave1(cmPort: 35126 httpPort: 8042) registered with capability: <memory:4096, vCores:1>, assigned nodeId slave1:35126
2019-06-07 07:43:16,844 INFO org.apache.hadoop.yarn.server.resourcemanager.ResourceTrackerService: NodeManager from node slave1(cmPort: 35126 httpPort: 8042) registered with capability: <memory:4096, vCores:1>, assigned nodeId slave1:35126
2019-06-07 07:43:17,256 INFO org.mortbay.log: Started HttpServer2$SelectChannelConnectorWithSafeStartup@master:8088
2019-06-07 07:43:17,256 INFO org.apache.hadoop.yarn.webapp.WebApps: Web app cluster started at 8088
2019-06-07 07:43:17,267 DEBUG org.apache.hadoop.yarn.server.resourcemanager.rmnode.RMNodeImpl: Processing slave2:33474 of type STARTED
2019-06-07 07:43:17,267 DEBUG org.apache.hadoop.yarn.server.resourcemanager.rmnode.RMNodeImpl: Processing slave2:33474 of type STARTED
2019-06-07 07:43:17,276 INFO org.apache.hadoop.yarn.server.resourcemanager.rmnode.RMNodeImpl: slave2:33474 Node Transitioned from NEW to RUNNING
2019-06-07 07:43:17,276 INFO org.apache.hadoop.yarn.server.resourcemanager.rmnode.RMNodeImpl: slave2:33474 Node Transitioned from NEW to RUNNING
2019-06-07 07:43:17,276 DEBUG org.apache.hadoop.yarn.server.resourcemanager.rmnode.RMNodeImpl: Processing slave1:35126 of type STARTED
2019-06-07 07:43:17,276 DEBUG org.apache.hadoop.yarn.server.resourcemanager.rmnode.RMNodeImpl: Processing slave1:35126 of type STARTED
2019-06-07 07:43:17,276 INFO org.apache.hadoop.yarn.server.resourcemanager.rmnode.RMNodeImpl: slave1:35126 Node Transitioned from NEW to RUNNING
2019-06-07 07:43:17,276 INFO org.apache.hadoop.yarn.server.resourcemanager.rmnode.RMNodeImpl: slave1:35126 Node Transitioned from NEW to RUNNING
2019-06-07 07:43:17,276 DEBUG org.apache.hadoop.yarn.server.resourcemanager.rmnode.RMNodeImpl: Processing slave1:35126 of type STATUS_UPDATE
2019-06-07 07:43:17,276 DEBUG org.apache.hadoop.yarn.server.resourcemanager.rmnode.RMNodeImpl: Processing slave1:35126 of type STATUS_UPDATE
2019-06-07 07:43:17,277 DEBUG org.apache.hadoop.yarn.server.resourcemanager.rmnode.RMNodeImpl: Processing slave2:33474 of type STATUS_UPDATE
2019-06-07 07:43:17,277 DEBUG org.apache.hadoop.yarn.server.resourcemanager.rmnode.RMNodeImpl: Processing slave2:33474 of type STATUS_UPDATE
2019-06-07 07:43:17,289 INFO org.apache.hadoop.yarn.server.resourcemanager.scheduler.capacity.CapacityScheduler: Added node slave2:33474 clusterResource: <memory:4096, vCores:1>
2019-06-07 07:43:17,289 INFO org.apache.hadoop.yarn.server.resourcemanager.scheduler.capacity.CapacityScheduler: Added node slave2:33474 clusterResource: <memory:4096, vCores:1>
2019-06-07 07:43:17,290 DEBUG org.apache.hadoop.yarn.server.resourcemanager.NodesListManager: slave2:33474 reported usable
2019-06-07 07:43:17,290 DEBUG org.apache.hadoop.yarn.server.resourcemanager.NodesListManager: slave2:33474 reported usable
2019-06-07 07:43:17,290 DEBUG org.apache.hadoop.yarn.server.resourcemanager.NodesListManager: slave1:35126 reported usable
2019-06-07 07:43:17,290 DEBUG org.apache.hadoop.yarn.server.resourcemanager.NodesListManager: slave1:35126 reported usable
2019-06-07 07:43:17,291 INFO org.apache.hadoop.yarn.server.resourcemanager.scheduler.capacity.CapacityScheduler: Added node slave1:35126 clusterResource: <memory:8192, vCores:2>
2019-06-07 07:43:17,291 INFO org.apache.hadoop.yarn.server.resourcemanager.scheduler.capacity.CapacityScheduler: Added node slave1:35126 clusterResource: <memory:8192, vCores:2>
2019-06-07 07:43:17,291 DEBUG org.apache.hadoop.yarn.server.resourcemanager.scheduler.capacity.CapacityScheduler: nodeUpdate: slave1:35126 clusterResources: <memory:8192, vCores:2>
2019-06-07 07:43:17,291 DEBUG org.apache.hadoop.yarn.server.resourcemanager.scheduler.capacity.CapacityScheduler: nodeUpdate: slave1:35126 clusterResources: <memory:8192, vCores:2>
2019-06-07 07:43:17,292 DEBUG org.apache.hadoop.yarn.server.resourcemanager.scheduler.capacity.CapacityScheduler: Node being looked for scheduling slave1:35126 availableResource: <memory:4096, vCores:1>
2019-06-07 07:43:17,292 DEBUG org.apache.hadoop.yarn.server.resourcemanager.scheduler.capacity.CapacityScheduler: Node being looked for scheduling slave1:35126 availableResource: <memory:4096, vCores:1>
2019-06-07 07:43:17,294 DEBUG org.apache.hadoop.yarn.server.resourcemanager.scheduler.capacity.CapacityScheduler: Trying to schedule on node: slave1, available: <memory:4096, vCores:1>
2019-06-07 07:43:17,294 DEBUG org.apache.hadoop.yarn.server.resourcemanager.scheduler.capacity.CapacityScheduler: Trying to schedule on node: slave1, available: <memory:4096, vCores:1>
2019-06-07 07:43:17,295 DEBUG org.apache.hadoop.yarn.server.resourcemanager.scheduler.capacity.ParentQueue: Skip this queue=root, because it doesn't need more resource, schedulingMode=RESPECT_PARTITION_EXCLUSIVITY node-partition=
2019-06-07 07:43:17,295 DEBUG org.apache.hadoop.yarn.server.resourcemanager.scheduler.capacity.ParentQueue: Skip this queue=root, because it doesn't need more resource, schedulingMode=RESPECT_PARTITION_EXCLUSIVITY node-partition=
2019-06-07 07:43:17,295 DEBUG org.apache.hadoop.yarn.server.resourcemanager.scheduler.capacity.CapacityScheduler: nodeUpdate: slave2:33474 clusterResources: <memory:8192, vCores:2>
2019-06-07 07:43:17,295 DEBUG org.apache.hadoop.yarn.server.resourcemanager.scheduler.capacity.CapacityScheduler: nodeUpdate: slave2:33474 clusterResources: <memory:8192, vCores:2>
2019-06-07 07:43:17,295 DEBUG org.apache.hadoop.yarn.server.resourcemanager.scheduler.capacity.CapacityScheduler: Node being looked for scheduling slave2:33474 availableResource: <memory:4096, vCores:1>
2019-06-07 07:43:17,295 DEBUG org.apache.hadoop.yarn.server.resourcemanager.scheduler.capacity.CapacityScheduler: Node being looked for scheduling slave2:33474 availableResource: <memory:4096, vCores:1>
2019-06-07 07:43:17,295 DEBUG org.apache.hadoop.yarn.server.resourcemanager.scheduler.capacity.CapacityScheduler: Trying to schedule on node: slave2, available: <memory:4096, vCores:1>
2019-06-07 07:43:17,295 DEBUG org.apache.hadoop.yarn.server.resourcemanager.scheduler.capacity.CapacityScheduler: Trying to schedule on node: slave2, available: <memory:4096, vCores:1>
2019-06-07 07:43:17,295 DEBUG org.apache.hadoop.yarn.server.resourcemanager.scheduler.capacity.ParentQueue: Skip this queue=root, because it doesn't need more resource, schedulingMode=RESPECT_PARTITION_EXCLUSIVITY node-partition=
2019-06-07 07:43:17,295 DEBUG org.apache.hadoop.yarn.server.resourcemanager.scheduler.capacity.ParentQueue: Skip this queue=root, because it doesn't need more resource, schedulingMode=RESPECT_PARTITION_EXCLUSIVITY node-partition=
2019-06-07 07:43:17,309 INFO org.apache.hadoop.ipc.CallQueueManager: Using callQueue: class java.util.concurrent.LinkedBlockingQueue queueCapacity: 100 scheduler: class org.apache.hadoop.ipc.DefaultRpcScheduler
2019-06-07 07:43:17,310 INFO org.apache.hadoop.ipc.Server: Starting Socket Reader #1 for port 8033
2019-06-07 07:43:17,317 INFO org.apache.hadoop.yarn.factories.impl.pb.RpcServerFactoryPBImpl: Adding protocol org.apache.hadoop.yarn.server.api.ResourceManagerAdministrationProtocolPB to the server
2019-06-07 07:43:17,317 INFO org.apache.hadoop.ipc.Server: IPC Server Responder: starting
2019-06-07 07:43:17,317 INFO org.apache.hadoop.ipc.Server: IPC Server listener on 8033: starting
2019-06-07 07:43:17,980 DEBUG org.apache.hadoop.yarn.server.resourcemanager.rmnode.RMNodeImpl: Processing slave2:33474 of type STATUS_UPDATE
2019-06-07 07:43:17,980 DEBUG org.apache.hadoop.yarn.server.resourcemanager.rmnode.RMNodeImpl: Processing slave2:33474 of type STATUS_UPDATE
2019-06-07 07:43:17,980 DEBUG org.apache.hadoop.yarn.server.resourcemanager.scheduler.capacity.CapacityScheduler: nodeUpdate: slave2:33474 clusterResources: <memory:8192, vCores:2>
2019-06-07 07:43:17,980 DEBUG org.apache.hadoop.yarn.server.resourcemanager.scheduler.capacity.CapacityScheduler: nodeUpdate: slave2:33474 clusterResources: <memory:8192, vCores:2>
2019-06-07 07:43:17,981 DEBUG org.apache.hadoop.yarn.server.resourcemanager.scheduler.capacity.CapacityScheduler: Node being looked for scheduling slave2:33474 availableResource: <memory:4096, vCores:1>
2019-06-07 07:43:17,981 DEBUG org.apache.hadoop.yarn.server.resourcemanager.scheduler.capacity.CapacityScheduler: Node being looked for scheduling slave2:33474 availableResource: <memory:4096, vCores:1>
2019-06-07 07:43:17,981 DEBUG org.apache.hadoop.yarn.server.resourcemanager.scheduler.capacity.CapacityScheduler: Trying to schedule on node: slave2, available: <memory:4096, vCores:1>
2019-06-07 07:43:17,981 DEBUG org.apache.hadoop.yarn.server.resourcemanager.scheduler.capacity.CapacityScheduler: Trying to schedule on node: slave2, available: <memory:4096, vCores:1>
2019-06-07 07:43:17,981 DEBUG org.apache.hadoop.yarn.server.resourcemanager.scheduler.capacity.ParentQueue: Skip this queue=root, because it doesn't need more resource, schedulingMode=RESPECT_PARTITION_EXCLUSIVITY node-partition=
2019-06-07 07:43:17,981 DEBUG org.apache.hadoop.yarn.server.resourcemanager.scheduler.capacity.ParentQueue: Skip this queue=root, because it doesn't need more resource, schedulingMode=RESPECT_PARTITION_EXCLUSIVITY node-partition=
2019-06-07 07:43:17,986 DEBUG org.apache.hadoop.yarn.server.resourcemanager.rmnode.RMNodeImpl: Processing slave1:35126 of type STATUS_UPDATE
2019-06-07 07:43:17,986 DEBUG org.apache.hadoop.yarn.server.resourcemanager.rmnode.RMNodeImpl: Processing slave1:35126 of type STATUS_UPDATE
2019-06-07 07:43:17,987 DEBUG org.apache.hadoop.yarn.server.resourcemanager.scheduler.capacity.CapacityScheduler: nodeUpdate: slave1:35126 clusterResources: <memory:8192, vCores:2>
2019-06-07 07:43:17,987 DEBUG org.apache.hadoop.yarn.server.resourcemanager.scheduler.capacity.CapacityScheduler: nodeUpdate: slave1:35126 clusterResources: <memory:8192, vCores:2>
2019-06-07 07:43:17,987 DEBUG org.apache.hadoop.yarn.server.resourcemanager.scheduler.capacity.CapacityScheduler: Node being looked for scheduling slave1:35126 availableResource: <memory:4096, vCores:1>
2019-06-07 07:43:17,987 DEBUG org.apache.hadoop.yarn.server.resourcemanager.scheduler.capacity.CapacityScheduler: Node being looked for scheduling slave1:35126 availableResource: <memory:4096, vCores:1>
2019-06-07 07:43:17,987 DEBUG org.apache.hadoop.yarn.server.resourcemanager.scheduler.capacity.CapacityScheduler: Trying to schedule on node: slave1, available: <memory:4096, vCores:1>
2019-06-07 07:43:17,987 DEBUG org.apache.hadoop.yarn.server.resourcemanager.scheduler.capacity.CapacityScheduler: Trying to schedule on node: slave1, available: <memory:4096, vCores:1>
2019-06-07 07:43:17,987 DEBUG org.apache.hadoop.yarn.server.resourcemanager.scheduler.capacity.ParentQueue: Skip this queue=root, because it doesn't need more resource, schedulingMode=RESPECT_PARTITION_EXCLUSIVITY node-partition=
2019-06-07 07:43:17,987 DEBUG org.apache.hadoop.yarn.server.resourcemanager.scheduler.capacity.ParentQueue: Skip this queue=root, because it doesn't need more resource, schedulingMode=RESPECT_PARTITION_EXCLUSIVITY node-partition=
2019-06-07 07:43:18,982 DEBUG org.apache.hadoop.yarn.server.resourcemanager.rmnode.RMNodeImpl: Processing slave2:33474 of type STATUS_UPDATE
2019-06-07 07:43:18,982 DEBUG org.apache.hadoop.yarn.server.resourcemanager.rmnode.RMNodeImpl: Processing slave2:33474 of type STATUS_UPDATE
2019-06-07 07:43:18,983 DEBUG org.apache.hadoop.yarn.server.resourcemanager.scheduler.capacity.CapacityScheduler: nodeUpdate: slave2:33474 clusterResources: <memory:8192, vCores:2>
2019-06-07 07:43:18,983 DEBUG org.apache.hadoop.yarn.server.resourcemanager.scheduler.capacity.CapacityScheduler: nodeUpdate: slave2:33474 clusterResources: <memory:8192, vCores:2>
2019-06-07 07:43:18,983 DEBUG org.apache.hadoop.yarn.server.resourcemanager.scheduler.capacity.CapacityScheduler: Node being looked for scheduling slave2:33474 availableResource: <memory:4096, vCores:1>
2019-06-07 07:43:18,983 DEBUG org.apache.hadoop.yarn.server.resourcemanager.scheduler.capacity.CapacityScheduler: Node being looked for scheduling slave2:33474 availableResource: <memory:4096, vCores:1>
2019-06-07 07:43:18,984 DEBUG org.apache.hadoop.yarn.server.resourcemanager.scheduler.capacity.CapacityScheduler: Trying to schedule on node: slave2, available: <memory:4096, vCores:1>
2019-06-07 07:43:18,984 DEBUG org.apache.hadoop.yarn.server.resourcemanager.scheduler.capacity.CapacityScheduler: Trying to schedule on node: slave2, available: <memory:4096, vCores:1>
2019-06-07 07:43:18,984 DEBUG org.apache.hadoop.yarn.server.resourcemanager.scheduler.capacity.ParentQueue: Skip this queue=root, because it doesn't need more resource, schedulingMode=RESPECT_PARTITION_EXCLUSIVITY node-partition=
2019-06-07 07:43:18,984 DEBUG org.apache.hadoop.yarn.server.resourcemanager.scheduler.capacity.ParentQueue: Skip this queue=root, because it doesn't need more resource, schedulingMode=RESPECT_PARTITION_EXCLUSIVITY node-partition=
2019-06-07 07:43:18,993 DEBUG org.apache.hadoop.yarn.server.resourcemanager.rmnode.RMNodeImpl: Processing slave1:35126 of type STATUS_UPDATE
2019-06-07 07:43:18,993 DEBUG org.apache.hadoop.yarn.server.resourcemanager.rmnode.RMNodeImpl: Processing slave1:35126 of type STATUS_UPDATE
2019-06-07 07:43:18,995 DEBUG org.apache.hadoop.yarn.server.resourcemanager.scheduler.capacity.CapacityScheduler: nodeUpdate: slave1:35126 clusterResources: <memory:8192, vCores:2>
2019-06-07 07:43:18,995 DEBUG org.apache.hadoop.yarn.server.resourcemanager.scheduler.capacity.CapacityScheduler: nodeUpdate: slave1:35126 clusterResources: <memory:8192, vCores:2>
2019-06-07 07:43:18,995 DEBUG org.apache.hadoop.yarn.server.resourcemanager.scheduler.capacity.CapacityScheduler: Node being looked for scheduling slave1:35126 availableResource: <memory:4096, vCores:1>
2019-06-07 07:43:18,995 DEBUG org.apache.hadoop.yarn.server.resourcemanager.scheduler.capacity.CapacityScheduler: Node being looked for scheduling slave1:35126 availableResource: <memory:4096, vCores:1>
2019-06-07 07:43:18,995 DEBUG org.apache.hadoop.yarn.server.resourcemanager.scheduler.capacity.CapacityScheduler: Trying to schedule on node: slave1, available: <memory:4096, vCores:1>
2019-06-07 07:43:18,995 DEBUG org.apache.hadoop.yarn.server.resourcemanager.scheduler.capacity.CapacityScheduler: Trying to schedule on node: slave1, available: <memory:4096, vCores:1>
2019-06-07 07:43:18,995 DEBUG org.apache.hadoop.yarn.server.resourcemanager.scheduler.capacity.ParentQueue: Skip this queue=root, because it doesn't need more resource, schedulingMode=RESPECT_PARTITION_EXCLUSIVITY node-partition=
2019-06-07 07:43:18,995 DEBUG org.apache.hadoop.yarn.server.resourcemanager.scheduler.capacity.ParentQueue: Skip this queue=root, because it doesn't need more resource, schedulingMode=RESPECT_PARTITION_EXCLUSIVITY node-partition=
2019-06-07 07:43:20,001 DEBUG org.apache.hadoop.yarn.server.resourcemanager.rmnode.RMNodeImpl: Processing slave1:35126 of type STATUS_UPDATE
2019-06-07 07:43:20,001 DEBUG org.apache.hadoop.yarn.server.resourcemanager.rmnode.RMNodeImpl: Processing slave1:35126 of type STATUS_UPDATE
2019-06-07 07:43:20,002 DEBUG org.apache.hadoop.yarn.server.resourcemanager.scheduler.capacity.CapacityScheduler: nodeUpdate: slave1:35126 clusterResources: <memory:8192, vCores:2>
2019-06-07 07:43:20,002 DEBUG org.apache.hadoop.yarn.server.resourcemanager.scheduler.capacity.CapacityScheduler: nodeUpdate: slave1:35126 clusterResources: <memory:8192, vCores:2>
2019-06-07 07:43:20,002 DEBUG org.apache.hadoop.yarn.server.resourcemanager.scheduler.capacity.CapacityScheduler: Node being looked for scheduling slave1:35126 availableResource: <memory:4096, vCores:1>
2019-06-07 07:43:20,002 DEBUG org.apache.hadoop.yarn.server.resourcemanager.scheduler.capacity.CapacityScheduler: Node being looked for scheduling slave1:35126 availableResource: <memory:4096, vCores:1>
2019-06-07 07:43:20,002 DEBUG org.apache.hadoop.yarn.server.resourcemanager.scheduler.capacity.CapacityScheduler: Trying to schedule on node: slave1, available: <memory:4096, vCores:1>
2019-06-07 07:43:20,002 DEBUG org.apache.hadoop.yarn.server.resourcemanager.scheduler.capacity.CapacityScheduler: Trying to schedule on node: slave1, available: <memory:4096, vCores:1>
2019-06-07 07:43:20,002 DEBUG org.apache.hadoop.yarn.server.resourcemanager.scheduler.capacity.ParentQueue: Skip this queue=root, because it doesn't need more resource, schedulingMode=RESPECT_PARTITION_EXCLUSIVITY node-partition=
2019-06-07 07:43:20,002 DEBUG org.apache.hadoop.yarn.server.resourcemanager.scheduler.capacity.ParentQueue: Skip this queue=root, because it doesn't need more resource, schedulingMode=RESPECT_PARTITION_EXCLUSIVITY node-partition=
2019-06-07 07:43:20,002 DEBUG org.apache.hadoop.yarn.server.resourcemanager.rmnode.RMNodeImpl: Processing slave2:33474 of type STATUS_UPDATE
2019-06-07 07:43:20,002 DEBUG org.apache.hadoop.yarn.server.resourcemanager.rmnode.RMNodeImpl: Processing slave2:33474 of type STATUS_UPDATE
2019-06-07 07:43:20,003 DEBUG org.apache.hadoop.yarn.server.resourcemanager.scheduler.capacity.CapacityScheduler: nodeUpdate: slave2:33474 clusterResources: <memory:8192, vCores:2>
2019-06-07 07:43:20,003 DEBUG org.apache.hadoop.yarn.server.resourcemanager.scheduler.capacity.CapacityScheduler: nodeUpdate: slave2:33474 clusterResources: <memory:8192, vCores:2>
2019-06-07 07:43:20,003 DEBUG org.apache.hadoop.yarn.server.resourcemanager.scheduler.capacity.CapacityScheduler: Node being looked for scheduling slave2:33474 availableResource: <memory:4096, vCores:1>
2019-06-07 07:43:20,003 DEBUG org.apache.hadoop.yarn.server.resourcemanager.scheduler.capacity.CapacityScheduler: Node being looked for scheduling slave2:33474 availableResource: <memory:4096, vCores:1>
2019-06-07 07:43:20,003 DEBUG org.apache.hadoop.yarn.server.resourcemanager.scheduler.capacity.CapacityScheduler: Trying to schedule on node: slave2, available: <memory:4096, vCores:1>
2019-06-07 07:43:20,003 DEBUG org.apache.hadoop.yarn.server.resourcemanager.scheduler.capacity.CapacityScheduler: Trying to schedule on node: slave2, available: <memory:4096, vCores:1>
2019-06-07 07:43:20,003 DEBUG org.apache.hadoop.yarn.server.resourcemanager.scheduler.capacity.ParentQueue: Skip this queue=root, because it doesn't need more resource, schedulingMode=RESPECT_PARTITION_EXCLUSIVITY node-partition=
2019-06-07 07:43:20,003 DEBUG org.apache.hadoop.yarn.server.resourcemanager.scheduler.capacity.ParentQueue: Skip this queue=root, because it doesn't need more resource, schedulingMode=RESPECT_PARTITION_EXCLUSIVITY node-partition=
2019-06-07 07:43:21,015 DEBUG org.apache.hadoop.yarn.server.resourcemanager.rmnode.RMNodeImpl: Processing slave1:35126 of type STATUS_UPDATE
2019-06-07 07:43:21,015 DEBUG org.apache.hadoop.yarn.server.resourcemanager.rmnode.RMNodeImpl: Processing slave1:35126 of type STATUS_UPDATE
2019-06-07 07:43:21,017 DEBUG org.apache.hadoop.yarn.server.resourcemanager.rmnode.RMNodeImpl: Processing slave2:33474 of type STATUS_UPDATE
2019-06-07 07:43:21,017 DEBUG org.apache.hadoop.yarn.server.resourcemanager.rmnode.RMNodeImpl: Processing slave2:33474 of type STATUS_UPDATE
2019-06-07 07:43:21,017 DEBUG org.apache.hadoop.yarn.server.resourcemanager.scheduler.capacity.CapacityScheduler: nodeUpdate: slave1:35126 clusterResources: <memory:8192, vCores:2>
2019-06-07 07:43:21,017 DEBUG org.apache.hadoop.yarn.server.resourcemanager.scheduler.capacity.CapacityScheduler: nodeUpdate: slave1:35126 clusterResources: <memory:8192, vCores:2>
2019-06-07 07:43:21,017 DEBUG org.apache.hadoop.yarn.server.resourcemanager.scheduler.capacity.CapacityScheduler: Node being looked for scheduling slave1:35126 availableResource: <memory:4096, vCores:1>
2019-06-07 07:43:21,017 DEBUG org.apache.hadoop.yarn.server.resourcemanager.scheduler.capacity.CapacityScheduler: Node being looked for scheduling slave1:35126 availableResource: <memory:4096, vCores:1>
2019-06-07 07:43:21,017 DEBUG org.apache.hadoop.yarn.server.resourcemanager.scheduler.capacity.CapacityScheduler: Trying to schedule on node: slave1, available: <memory:4096, vCores:1>
2019-06-07 07:43:21,017 DEBUG org.apache.hadoop.yarn.server.resourcemanager.scheduler.capacity.CapacityScheduler: Trying to schedule on node: slave1, available: <memory:4096, vCores:1>
2019-06-07 07:43:21,018 DEBUG org.apache.hadoop.yarn.server.resourcemanager.scheduler.capacity.ParentQueue: Skip this queue=root, because it doesn't need more resource, schedulingMode=RESPECT_PARTITION_EXCLUSIVITY node-partition=
2019-06-07 07:43:21,018 DEBUG org.apache.hadoop.yarn.server.resourcemanager.scheduler.capacity.ParentQueue: Skip this queue=root, because it doesn't need more resource, schedulingMode=RESPECT_PARTITION_EXCLUSIVITY node-partition=
2019-06-07 07:43:21,018 DEBUG org.apache.hadoop.yarn.server.resourcemanager.scheduler.capacity.CapacityScheduler: nodeUpdate: slave2:33474 clusterResources: <memory:8192, vCores:2>
2019-06-07 07:43:21,018 DEBUG org.apache.hadoop.yarn.server.resourcemanager.scheduler.capacity.CapacityScheduler: nodeUpdate: slave2:33474 clusterResources: <memory:8192, vCores:2>
2019-06-07 07:43:21,018 DEBUG org.apache.hadoop.yarn.server.resourcemanager.scheduler.capacity.CapacityScheduler: Node being looked for scheduling slave2:33474 availableResource: <memory:4096, vCores:1>
2019-06-07 07:43:21,018 DEBUG org.apache.hadoop.yarn.server.resourcemanager.scheduler.capacity.CapacityScheduler: Node being looked for scheduling slave2:33474 availableResource: <memory:4096, vCores:1>
2019-06-07 07:43:21,018 DEBUG org.apache.hadoop.yarn.server.resourcemanager.scheduler.capacity.CapacityScheduler: Trying to schedule on node: slave2, available: <memory:4096, vCores:1>
2019-06-07 07:43:21,018 DEBUG org.apache.hadoop.yarn.server.resourcemanager.scheduler.capacity.CapacityScheduler: Trying to schedule on node: slave2, available: <memory:4096, vCores:1>
2019-06-07 07:43:21,018 DEBUG org.apache.hadoop.yarn.server.resourcemanager.scheduler.capacity.ParentQueue: Skip this queue=root, because it doesn't need more resource, schedulingMode=RESPECT_PARTITION_EXCLUSIVITY node-partition=
2019-06-07 07:43:21,018 DEBUG org.apache.hadoop.yarn.server.resourcemanager.scheduler.capacity.ParentQueue: Skip this queue=root, because it doesn't need more resource, schedulingMode=RESPECT_PARTITION_EXCLUSIVITY node-partition=
2019-06-07 07:43:22,019 DEBUG org.apache.hadoop.yarn.server.resourcemanager.rmnode.RMNodeImpl: Processing slave1:35126 of type STATUS_UPDATE
2019-06-07 07:43:22,019 DEBUG org.apache.hadoop.yarn.server.resourcemanager.rmnode.RMNodeImpl: Processing slave1:35126 of type STATUS_UPDATE
2019-06-07 07:43:22,023 DEBUG org.apache.hadoop.yarn.server.resourcemanager.scheduler.capacity.CapacityScheduler: nodeUpdate: slave1:35126 clusterResources: <memory:8192, vCores:2>
2019-06-07 07:43:22,023 DEBUG org.apache.hadoop.yarn.server.resourcemanager.scheduler.capacity.CapacityScheduler: nodeUpdate: slave1:35126 clusterResources: <memory:8192, vCores:2>
2019-06-07 07:43:22,023 DEBUG org.apache.hadoop.yarn.server.resourcemanager.scheduler.capacity.CapacityScheduler: Node being looked for scheduling slave1:35126 availableResource: <memory:4096, vCores:1>
2019-06-07 07:43:22,023 DEBUG org.apache.hadoop.yarn.server.resourcemanager.scheduler.capacity.CapacityScheduler: Node being looked for scheduling slave1:35126 availableResource: <memory:4096, vCores:1>
2019-06-07 07:43:22,024 DEBUG org.apache.hadoop.yarn.server.resourcemanager.scheduler.capacity.CapacityScheduler: Trying to schedule on node: slave1, available: <memory:4096, vCores:1>
2019-06-07 07:43:22,024 DEBUG org.apache.hadoop.yarn.server.resourcemanager.scheduler.capacity.CapacityScheduler: Trying to schedule on node: slave1, available: <memory:4096, vCores:1>
2019-06-07 07:43:22,024 DEBUG org.apache.hadoop.yarn.server.resourcemanager.scheduler.capacity.ParentQueue: Skip this queue=root, because it doesn't need more resource, schedulingMode=RESPECT_PARTITION_EXCLUSIVITY node-partition=
2019-06-07 07:43:22,024 DEBUG org.apache.hadoop.yarn.server.resourcemanager.scheduler.capacity.ParentQueue: Skip this queue=root, because it doesn't need more resource, schedulingMode=RESPECT_PARTITION_EXCLUSIVITY node-partition=
2019-06-07 07:43:22,025 DEBUG org.apache.hadoop.yarn.server.resourcemanager.rmnode.RMNodeImpl: Processing slave2:33474 of type STATUS_UPDATE
2019-06-07 07:43:22,025 DEBUG org.apache.hadoop.yarn.server.resourcemanager.rmnode.RMNodeImpl: Processing slave2:33474 of type STATUS_UPDATE
2019-06-07 07:43:22,025 DEBUG org.apache.hadoop.yarn.server.resourcemanager.scheduler.capacity.CapacityScheduler: nodeUpdate: slave2:33474 clusterResources: <memory:8192, vCores:2>
2019-06-07 07:43:22,025 DEBUG org.apache.hadoop.yarn.server.resourcemanager.scheduler.capacity.CapacityScheduler: nodeUpdate: slave2:33474 clusterResources: <memory:8192, vCores:2>
2019-06-07 07:43:22,026 DEBUG org.apache.hadoop.yarn.server.resourcemanager.scheduler.capacity.CapacityScheduler: Node being looked for scheduling slave2:33474 availableResource: <memory:4096, vCores:1>
2019-06-07 07:43:22,026 DEBUG org.apache.hadoop.yarn.server.resourcemanager.scheduler.capacity.CapacityScheduler: Node being looked for scheduling slave2:33474 availableResource: <memory:4096, vCores:1>
2019-06-07 07:43:22,026 DEBUG org.apache.hadoop.yarn.server.resourcemanager.scheduler.capacity.CapacityScheduler: Trying to schedule on node: slave2, available: <memory:4096, vCores:1>
2019-06-07 07:43:22,026 DEBUG org.apache.hadoop.yarn.server.resourcemanager.scheduler.capacity.CapacityScheduler: Trying to schedule on node: slave2, available: <memory:4096, vCores:1>
2019-06-07 07:43:22,026 DEBUG org.apache.hadoop.yarn.server.resourcemanager.scheduler.capacity.ParentQueue: Skip this queue=root, because it doesn't need more resource, schedulingMode=RESPECT_PARTITION_EXCLUSIVITY node-partition=
2019-06-07 07:43:22,026 DEBUG org.apache.hadoop.yarn.server.resourcemanager.scheduler.capacity.ParentQueue: Skip this queue=root, because it doesn't need more resource, schedulingMode=RESPECT_PARTITION_EXCLUSIVITY node-partition=
2019-06-07 07:43:23,023 DEBUG org.apache.hadoop.yarn.server.resourcemanager.rmnode.RMNodeImpl: Processing slave1:35126 of type STATUS_UPDATE
2019-06-07 07:43:23,023 DEBUG org.apache.hadoop.yarn.server.resourcemanager.rmnode.RMNodeImpl: Processing slave1:35126 of type STATUS_UPDATE
2019-06-07 07:43:23,024 DEBUG org.apache.hadoop.yarn.server.resourcemanager.scheduler.capacity.CapacityScheduler: nodeUpdate: slave1:35126 clusterResources: <memory:8192, vCores:2>
2019-06-07 07:43:23,024 DEBUG org.apache.hadoop.yarn.server.resourcemanager.scheduler.capacity.CapacityScheduler: nodeUpdate: slave1:35126 clusterResources: <memory:8192, vCores:2>
2019-06-07 07:43:23,024 DEBUG org.apache.hadoop.yarn.server.resourcemanager.scheduler.capacity.CapacityScheduler: Node being looked for scheduling slave1:35126 availableResource: <memory:4096, vCores:1>
2019-06-07 07:43:23,024 DEBUG org.apache.hadoop.yarn.server.resourcemanager.scheduler.capacity.CapacityScheduler: Node being looked for scheduling slave1:35126 availableResource: <memory:4096, vCores:1>
2019-06-07 07:43:23,025 DEBUG org.apache.hadoop.yarn.server.resourcemanager.scheduler.capacity.CapacityScheduler: Trying to schedule on node: slave1, available: <memory:4096, vCores:1>
2019-06-07 07:43:23,025 DEBUG org.apache.hadoop.yarn.server.resourcemanager.scheduler.capacity.CapacityScheduler: Trying to schedule on node: slave1, available: <memory:4096, vCores:1>
2019-06-07 07:43:23,025 DEBUG org.apache.hadoop.yarn.server.resourcemanager.scheduler.capacity.ParentQueue: Skip this queue=root, because it doesn't need more resource, schedulingMode=RESPECT_PARTITION_EXCLUSIVITY node-partition=
2019-06-07 07:43:23,025 DEBUG org.apache.hadoop.yarn.server.resourcemanager.scheduler.capacity.ParentQueue: Skip this queue=root, because it doesn't need more resource, schedulingMode=RESPECT_PARTITION_EXCLUSIVITY node-partition=
2019-06-07 07:43:23,034 DEBUG org.apache.hadoop.yarn.server.resourcemanager.rmnode.RMNodeImpl: Processing slave2:33474 of type STATUS_UPDATE
2019-06-07 07:43:23,034 DEBUG org.apache.hadoop.yarn.server.resourcemanager.rmnode.RMNodeImpl: Processing slave2:33474 of type STATUS_UPDATE
2019-06-07 07:43:23,035 DEBUG org.apache.hadoop.yarn.server.resourcemanager.scheduler.capacity.CapacityScheduler: nodeUpdate: slave2:33474 clusterResources: <memory:8192, vCores:2>
2019-06-07 07:43:23,035 DEBUG org.apache.hadoop.yarn.server.resourcemanager.scheduler.capacity.CapacityScheduler: nodeUpdate: slave2:33474 clusterResources: <memory:8192, vCores:2>
2019-06-07 07:43:23,035 DEBUG org.apache.hadoop.yarn.server.resourcemanager.scheduler.capacity.CapacityScheduler: Node being looked for scheduling slave2:33474 availableResource: <memory:4096, vCores:1>
2019-06-07 07:43:23,035 DEBUG org.apache.hadoop.yarn.server.resourcemanager.scheduler.capacity.CapacityScheduler: Node being looked for scheduling slave2:33474 availableResource: <memory:4096, vCores:1>
2019-06-07 07:43:23,035 DEBUG org.apache.hadoop.yarn.server.resourcemanager.scheduler.capacity.CapacityScheduler: Trying to schedule on node: slave2, available: <memory:4096, vCores:1>
2019-06-07 07:43:23,035 DEBUG org.apache.hadoop.yarn.server.resourcemanager.scheduler.capacity.CapacityScheduler: Trying to schedule on node: slave2, available: <memory:4096, vCores:1>
2019-06-07 07:43:23,035 DEBUG org.apache.hadoop.yarn.server.resourcemanager.scheduler.capacity.ParentQueue: Skip this queue=root, because it doesn't need more resource, schedulingMode=RESPECT_PARTITION_EXCLUSIVITY node-partition=
2019-06-07 07:43:23,035 DEBUG org.apache.hadoop.yarn.server.resourcemanager.scheduler.capacity.ParentQueue: Skip this queue=root, because it doesn't need more resource, schedulingMode=RESPECT_PARTITION_EXCLUSIVITY node-partition=
2019-06-07 07:43:24,027 DEBUG org.apache.hadoop.yarn.server.resourcemanager.rmnode.RMNodeImpl: Processing slave1:35126 of type STATUS_UPDATE
2019-06-07 07:43:24,027 DEBUG org.apache.hadoop.yarn.server.resourcemanager.rmnode.RMNodeImpl: Processing slave1:35126 of type STATUS_UPDATE
2019-06-07 07:43:24,028 DEBUG org.apache.hadoop.yarn.server.resourcemanager.scheduler.capacity.CapacityScheduler: nodeUpdate: slave1:35126 clusterResources: <memory:8192, vCores:2>
2019-06-07 07:43:24,028 DEBUG org.apache.hadoop.yarn.server.resourcemanager.scheduler.capacity.CapacityScheduler: nodeUpdate: slave1:35126 clusterResources: <memory:8192, vCores:2>
2019-06-07 07:43:24,029 DEBUG org.apache.hadoop.yarn.server.resourcemanager.scheduler.capacity.CapacityScheduler: Node being looked for scheduling slave1:35126 availableResource: <memory:4096, vCores:1>
2019-06-07 07:43:24,029 DEBUG org.apache.hadoop.yarn.server.resourcemanager.scheduler.capacity.CapacityScheduler: Node being looked for scheduling slave1:35126 availableResource: <memory:4096, vCores:1>
2019-06-07 07:43:24,029 DEBUG org.apache.hadoop.yarn.server.resourcemanager.scheduler.capacity.CapacityScheduler: Trying to schedule on node: slave1, available: <memory:4096, vCores:1>
2019-06-07 07:43:24,029 DEBUG org.apache.hadoop.yarn.server.resourcemanager.scheduler.capacity.CapacityScheduler: Trying to schedule on node: slave1, available: <memory:4096, vCores:1>
2019-06-07 07:43:24,029 DEBUG org.apache.hadoop.yarn.server.resourcemanager.scheduler.capacity.ParentQueue: Skip this queue=root, because it doesn't need more resource, schedulingMode=RESPECT_PARTITION_EXCLUSIVITY node-partition=
2019-06-07 07:43:24,029 DEBUG org.apache.hadoop.yarn.server.resourcemanager.scheduler.capacity.ParentQueue: Skip this queue=root, because it doesn't need more resource, schedulingMode=RESPECT_PARTITION_EXCLUSIVITY node-partition=
2019-06-07 07:43:24,037 DEBUG org.apache.hadoop.yarn.server.resourcemanager.rmnode.RMNodeImpl: Processing slave2:33474 of type STATUS_UPDATE
2019-06-07 07:43:24,037 DEBUG org.apache.hadoop.yarn.server.resourcemanager.rmnode.RMNodeImpl: Processing slave2:33474 of type STATUS_UPDATE
2019-06-07 07:43:24,038 DEBUG org.apache.hadoop.yarn.server.resourcemanager.scheduler.capacity.CapacityScheduler: nodeUpdate: slave2:33474 clusterResources: <memory:8192, vCores:2>
2019-06-07 07:43:24,038 DEBUG org.apache.hadoop.yarn.server.resourcemanager.scheduler.capacity.CapacityScheduler: nodeUpdate: slave2:33474 clusterResources: <memory:8192, vCores:2>
2019-06-07 07:43:24,038 DEBUG org.apache.hadoop.yarn.server.resourcemanager.scheduler.capacity.CapacityScheduler: Node being looked for scheduling slave2:33474 availableResource: <memory:4096, vCores:1>
2019-06-07 07:43:24,038 DEBUG org.apache.hadoop.yarn.server.resourcemanager.scheduler.capacity.CapacityScheduler: Node being looked for scheduling slave2:33474 availableResource: <memory:4096, vCores:1>
2019-06-07 07:43:24,038 DEBUG org.apache.hadoop.yarn.server.resourcemanager.scheduler.capacity.CapacityScheduler: Trying to schedule on node: slave2, available: <memory:4096, vCores:1>
2019-06-07 07:43:24,038 DEBUG org.apache.hadoop.yarn.server.resourcemanager.scheduler.capacity.CapacityScheduler: Trying to schedule on node: slave2, available: <memory:4096, vCores:1>
2019-06-07 07:43:24,038 DEBUG org.apache.hadoop.yarn.server.resourcemanager.scheduler.capacity.ParentQueue: Skip this queue=root, because it doesn't need more resource, schedulingMode=RESPECT_PARTITION_EXCLUSIVITY node-partition=
2019-06-07 07:43:24,038 DEBUG org.apache.hadoop.yarn.server.resourcemanager.scheduler.capacity.ParentQueue: Skip this queue=root, because it doesn't need more resource, schedulingMode=RESPECT_PARTITION_EXCLUSIVITY node-partition=
2019-06-07 07:43:25,030 DEBUG org.apache.hadoop.yarn.server.resourcemanager.rmnode.RMNodeImpl: Processing slave1:35126 of type STATUS_UPDATE
2019-06-07 07:43:25,030 DEBUG org.apache.hadoop.yarn.server.resourcemanager.rmnode.RMNodeImpl: Processing slave1:35126 of type STATUS_UPDATE
2019-06-07 07:43:25,032 DEBUG org.apache.hadoop.yarn.server.resourcemanager.scheduler.capacity.CapacityScheduler: nodeUpdate: slave1:35126 clusterResources: <memory:8192, vCores:2>
2019-06-07 07:43:25,032 DEBUG org.apache.hadoop.yarn.server.resourcemanager.scheduler.capacity.CapacityScheduler: nodeUpdate: slave1:35126 clusterResources: <memory:8192, vCores:2>
2019-06-07 07:43:25,032 DEBUG org.apache.hadoop.yarn.server.resourcemanager.scheduler.capacity.CapacityScheduler: Node being looked for scheduling slave1:35126 availableResource: <memory:4096, vCores:1>
2019-06-07 07:43:25,032 DEBUG org.apache.hadoop.yarn.server.resourcemanager.scheduler.capacity.CapacityScheduler: Node being looked for scheduling slave1:35126 availableResource: <memory:4096, vCores:1>
2019-06-07 07:43:25,032 DEBUG org.apache.hadoop.yarn.server.resourcemanager.scheduler.capacity.CapacityScheduler: Trying to schedule on node: slave1, available: <memory:4096, vCores:1>
2019-06-07 07:43:25,032 DEBUG org.apache.hadoop.yarn.server.resourcemanager.scheduler.capacity.CapacityScheduler: Trying to schedule on node: slave1, available: <memory:4096, vCores:1>
2019-06-07 07:43:25,033 DEBUG org.apache.hadoop.yarn.server.resourcemanager.scheduler.capacity.ParentQueue: Skip this queue=root, because it doesn't need more resource, schedulingMode=RESPECT_PARTITION_EXCLUSIVITY node-partition=
2019-06-07 07:43:25,033 DEBUG org.apache.hadoop.yarn.server.resourcemanager.scheduler.capacity.ParentQueue: Skip this queue=root, because it doesn't need more resource, schedulingMode=RESPECT_PARTITION_EXCLUSIVITY node-partition=
2019-06-07 07:43:25,041 DEBUG org.apache.hadoop.yarn.server.resourcemanager.rmnode.RMNodeImpl: Processing slave2:33474 of type STATUS_UPDATE
2019-06-07 07:43:25,041 DEBUG org.apache.hadoop.yarn.server.resourcemanager.rmnode.RMNodeImpl: Processing slave2:33474 of type STATUS_UPDATE
2019-06-07 07:43:25,041 DEBUG org.apache.hadoop.yarn.server.resourcemanager.scheduler.capacity.CapacityScheduler: nodeUpdate: slave2:33474 clusterResources: <memory:8192, vCores:2>
2019-06-07 07:43:25,041 DEBUG org.apache.hadoop.yarn.server.resourcemanager.scheduler.capacity.CapacityScheduler: nodeUpdate: slave2:33474 clusterResources: <memory:8192, vCores:2>
2019-06-07 07:43:25,042 DEBUG org.apache.hadoop.yarn.server.resourcemanager.scheduler.capacity.CapacityScheduler: Node being looked for scheduling slave2:33474 availableResource: <memory:4096, vCores:1>
2019-06-07 07:43:25,042 DEBUG org.apache.hadoop.yarn.server.resourcemanager.scheduler.capacity.CapacityScheduler: Node being looked for scheduling slave2:33474 availableResource: <memory:4096, vCores:1>
2019-06-07 07:43:25,042 DEBUG org.apache.hadoop.yarn.server.resourcemanager.scheduler.capacity.CapacityScheduler: Trying to schedule on node: slave2, available: <memory:4096, vCores:1>
2019-06-07 07:43:25,042 DEBUG org.apache.hadoop.yarn.server.resourcemanager.scheduler.capacity.CapacityScheduler: Trying to schedule on node: slave2, available: <memory:4096, vCores:1>
2019-06-07 07:43:25,042 DEBUG org.apache.hadoop.yarn.server.resourcemanager.scheduler.capacity.ParentQueue: Skip this queue=root, because it doesn't need more resource, schedulingMode=RESPECT_PARTITION_EXCLUSIVITY node-partition=
2019-06-07 07:43:25,042 DEBUG org.apache.hadoop.yarn.server.resourcemanager.scheduler.capacity.ParentQueue: Skip this queue=root, because it doesn't need more resource, schedulingMode=RESPECT_PARTITION_EXCLUSIVITY node-partition=
2019-06-07 07:43:26,034 DEBUG org.apache.hadoop.yarn.server.resourcemanager.rmnode.RMNodeImpl: Processing slave1:35126 of type STATUS_UPDATE
2019-06-07 07:43:26,034 DEBUG org.apache.hadoop.yarn.server.resourcemanager.rmnode.RMNodeImpl: Processing slave1:35126 of type STATUS_UPDATE
2019-06-07 07:43:26,036 DEBUG org.apache.hadoop.yarn.server.resourcemanager.scheduler.capacity.CapacityScheduler: nodeUpdate: slave1:35126 clusterResources: <memory:8192, vCores:2>
2019-06-07 07:43:26,036 DEBUG org.apache.hadoop.yarn.server.resourcemanager.scheduler.capacity.CapacityScheduler: nodeUpdate: slave1:35126 clusterResources: <memory:8192, vCores:2>
2019-06-07 07:43:26,036 DEBUG org.apache.hadoop.yarn.server.resourcemanager.scheduler.capacity.CapacityScheduler: Node being looked for scheduling slave1:35126 availableResource: <memory:4096, vCores:1>
2019-06-07 07:43:26,036 DEBUG org.apache.hadoop.yarn.server.resourcemanager.scheduler.capacity.CapacityScheduler: Node being looked for scheduling slave1:35126 availableResource: <memory:4096, vCores:1>
2019-06-07 07:43:26,036 DEBUG org.apache.hadoop.yarn.server.resourcemanager.scheduler.capacity.CapacityScheduler: Trying to schedule on node: slave1, available: <memory:4096, vCores:1>
2019-06-07 07:43:26,036 DEBUG org.apache.hadoop.yarn.server.resourcemanager.scheduler.capacity.CapacityScheduler: Trying to schedule on node: slave1, available: <memory:4096, vCores:1>
2019-06-07 07:43:26,036 DEBUG org.apache.hadoop.yarn.server.resourcemanager.scheduler.capacity.ParentQueue: Skip this queue=root, because it doesn't need more resource, schedulingMode=RESPECT_PARTITION_EXCLUSIVITY node-partition=
2019-06-07 07:43:26,036 DEBUG org.apache.hadoop.yarn.server.resourcemanager.scheduler.capacity.ParentQueue: Skip this queue=root, because it doesn't need more resource, schedulingMode=RESPECT_PARTITION_EXCLUSIVITY node-partition=
2019-06-07 07:43:26,044 DEBUG org.apache.hadoop.yarn.server.resourcemanager.rmnode.RMNodeImpl: Processing slave2:33474 of type STATUS_UPDATE
2019-06-07 07:43:26,044 DEBUG org.apache.hadoop.yarn.server.resourcemanager.rmnode.RMNodeImpl: Processing slave2:33474 of type STATUS_UPDATE
2019-06-07 07:43:26,046 DEBUG org.apache.hadoop.yarn.server.resourcemanager.scheduler.capacity.CapacityScheduler: nodeUpdate: slave2:33474 clusterResources: <memory:8192, vCores:2>
2019-06-07 07:43:26,046 DEBUG org.apache.hadoop.yarn.server.resourcemanager.scheduler.capacity.CapacityScheduler: nodeUpdate: slave2:33474 clusterResources: <memory:8192, vCores:2>
2019-06-07 07:43:26,046 DEBUG org.apache.hadoop.yarn.server.resourcemanager.scheduler.capacity.CapacityScheduler: Node being looked for scheduling slave2:33474 availableResource: <memory:4096, vCores:1>
2019-06-07 07:43:26,046 DEBUG org.apache.hadoop.yarn.server.resourcemanager.scheduler.capacity.CapacityScheduler: Node being looked for scheduling slave2:33474 availableResource: <memory:4096, vCores:1>
2019-06-07 07:43:26,046 DEBUG org.apache.hadoop.yarn.server.resourcemanager.scheduler.capacity.CapacityScheduler: Trying to schedule on node: slave2, available: <memory:4096, vCores:1>
2019-06-07 07:43:26,046 DEBUG org.apache.hadoop.yarn.server.resourcemanager.scheduler.capacity.CapacityScheduler: Trying to schedule on node: slave2, available: <memory:4096, vCores:1>
2019-06-07 07:43:26,046 DEBUG org.apache.hadoop.yarn.server.resourcemanager.scheduler.capacity.ParentQueue: Skip this queue=root, because it doesn't need more resource, schedulingMode=RESPECT_PARTITION_EXCLUSIVITY node-partition=
2019-06-07 07:43:26,046 DEBUG org.apache.hadoop.yarn.server.resourcemanager.scheduler.capacity.ParentQueue: Skip this queue=root, because it doesn't need more resource, schedulingMode=RESPECT_PARTITION_EXCLUSIVITY node-partition=
2019-06-07 07:43:27,040 DEBUG org.apache.hadoop.yarn.server.resourcemanager.rmnode.RMNodeImpl: Processing slave1:35126 of type STATUS_UPDATE
2019-06-07 07:43:27,040 DEBUG org.apache.hadoop.yarn.server.resourcemanager.rmnode.RMNodeImpl: Processing slave1:35126 of type STATUS_UPDATE
2019-06-07 07:43:27,041 DEBUG org.apache.hadoop.yarn.server.resourcemanager.scheduler.capacity.CapacityScheduler: nodeUpdate: slave1:35126 clusterResources: <memory:8192, vCores:2>
2019-06-07 07:43:27,041 DEBUG org.apache.hadoop.yarn.server.resourcemanager.scheduler.capacity.CapacityScheduler: nodeUpdate: slave1:35126 clusterResources: <memory:8192, vCores:2>
2019-06-07 07:43:27,041 DEBUG org.apache.hadoop.yarn.server.resourcemanager.scheduler.capacity.CapacityScheduler: Node being looked for scheduling slave1:35126 availableResource: <memory:4096, vCores:1>
2019-06-07 07:43:27,041 DEBUG org.apache.hadoop.yarn.server.resourcemanager.scheduler.capacity.CapacityScheduler: Node being looked for scheduling slave1:35126 availableResource: <memory:4096, vCores:1>
2019-06-07 07:43:27,041 DEBUG org.apache.hadoop.yarn.server.resourcemanager.scheduler.capacity.CapacityScheduler: Trying to schedule on node: slave1, available: <memory:4096, vCores:1>
2019-06-07 07:43:27,041 DEBUG org.apache.hadoop.yarn.server.resourcemanager.scheduler.capacity.CapacityScheduler: Trying to schedule on node: slave1, available: <memory:4096, vCores:1>
2019-06-07 07:43:27,042 DEBUG org.apache.hadoop.yarn.server.resourcemanager.scheduler.capacity.ParentQueue: Skip this queue=root, because it doesn't need more resource, schedulingMode=RESPECT_PARTITION_EXCLUSIVITY node-partition=
2019-06-07 07:43:27,042 DEBUG org.apache.hadoop.yarn.server.resourcemanager.scheduler.capacity.ParentQueue: Skip this queue=root, because it doesn't need more resource, schedulingMode=RESPECT_PARTITION_EXCLUSIVITY node-partition=
2019-06-07 07:43:27,048 DEBUG org.apache.hadoop.yarn.server.resourcemanager.rmnode.RMNodeImpl: Processing slave2:33474 of type STATUS_UPDATE
2019-06-07 07:43:27,048 DEBUG org.apache.hadoop.yarn.server.resourcemanager.rmnode.RMNodeImpl: Processing slave2:33474 of type STATUS_UPDATE
2019-06-07 07:43:27,049 DEBUG org.apache.hadoop.yarn.server.resourcemanager.scheduler.capacity.CapacityScheduler: nodeUpdate: slave2:33474 clusterResources: <memory:8192, vCores:2>
2019-06-07 07:43:27,049 DEBUG org.apache.hadoop.yarn.server.resourcemanager.scheduler.capacity.CapacityScheduler: nodeUpdate: slave2:33474 clusterResources: <memory:8192, vCores:2>
2019-06-07 07:43:27,050 DEBUG org.apache.hadoop.yarn.server.resourcemanager.scheduler.capacity.CapacityScheduler: Node being looked for scheduling slave2:33474 availableResource: <memory:4096, vCores:1>
2019-06-07 07:43:27,050 DEBUG org.apache.hadoop.yarn.server.resourcemanager.scheduler.capacity.CapacityScheduler: Node being looked for scheduling slave2:33474 availableResource: <memory:4096, vCores:1>
2019-06-07 07:43:27,051 DEBUG org.apache.hadoop.yarn.server.resourcemanager.scheduler.capacity.CapacityScheduler: Trying to schedule on node: slave2, available: <memory:4096, vCores:1>
2019-06-07 07:43:27,051 DEBUG org.apache.hadoop.yarn.server.resourcemanager.scheduler.capacity.CapacityScheduler: Trying to schedule on node: slave2, available: <memory:4096, vCores:1>
2019-06-07 07:43:27,051 DEBUG org.apache.hadoop.yarn.server.resourcemanager.scheduler.capacity.ParentQueue: Skip this queue=root, because it doesn't need more resource, schedulingMode=RESPECT_PARTITION_EXCLUSIVITY node-partition=
2019-06-07 07:43:27,051 DEBUG org.apache.hadoop.yarn.server.resourcemanager.scheduler.capacity.ParentQueue: Skip this queue=root, because it doesn't need more resource, schedulingMode=RESPECT_PARTITION_EXCLUSIVITY node-partition=
2019-06-07 07:43:28,044 DEBUG org.apache.hadoop.yarn.server.resourcemanager.rmnode.RMNodeImpl: Processing slave1:35126 of type STATUS_UPDATE
2019-06-07 07:43:28,044 DEBUG org.apache.hadoop.yarn.server.resourcemanager.rmnode.RMNodeImpl: Processing slave1:35126 of type STATUS_UPDATE
2019-06-07 07:43:28,045 DEBUG org.apache.hadoop.yarn.server.resourcemanager.scheduler.capacity.CapacityScheduler: nodeUpdate: slave1:35126 clusterResources: <memory:8192, vCores:2>
2019-06-07 07:43:28,045 DEBUG org.apache.hadoop.yarn.server.resourcemanager.scheduler.capacity.CapacityScheduler: nodeUpdate: slave1:35126 clusterResources: <memory:8192, vCores:2>
2019-06-07 07:43:28,045 DEBUG org.apache.hadoop.yarn.server.resourcemanager.scheduler.capacity.CapacityScheduler: Node being looked for scheduling slave1:35126 availableResource: <memory:4096, vCores:1>
2019-06-07 07:43:28,045 DEBUG org.apache.hadoop.yarn.server.resourcemanager.scheduler.capacity.CapacityScheduler: Node being looked for scheduling slave1:35126 availableResource: <memory:4096, vCores:1>
2019-06-07 07:43:28,046 DEBUG org.apache.hadoop.yarn.server.resourcemanager.scheduler.capacity.CapacityScheduler: Trying to schedule on node: slave1, available: <memory:4096, vCores:1>
2019-06-07 07:43:28,046 DEBUG org.apache.hadoop.yarn.server.resourcemanager.scheduler.capacity.CapacityScheduler: Trying to schedule on node: slave1, available: <memory:4096, vCores:1>
2019-06-07 07:43:28,046 DEBUG org.apache.hadoop.yarn.server.resourcemanager.scheduler.capacity.ParentQueue: Skip this queue=root, because it doesn't need more resource, schedulingMode=RESPECT_PARTITION_EXCLUSIVITY node-partition=
2019-06-07 07:43:28,046 DEBUG org.apache.hadoop.yarn.server.resourcemanager.scheduler.capacity.ParentQueue: Skip this queue=root, because it doesn't need more resource, schedulingMode=RESPECT_PARTITION_EXCLUSIVITY node-partition=
2019-06-07 07:43:28,053 DEBUG org.apache.hadoop.yarn.server.resourcemanager.rmnode.RMNodeImpl: Processing slave2:33474 of type STATUS_UPDATE
2019-06-07 07:43:28,053 DEBUG org.apache.hadoop.yarn.server.resourcemanager.rmnode.RMNodeImpl: Processing slave2:33474 of type STATUS_UPDATE
2019-06-07 07:43:28,055 DEBUG org.apache.hadoop.yarn.server.resourcemanager.scheduler.capacity.CapacityScheduler: nodeUpdate: slave2:33474 clusterResources: <memory:8192, vCores:2>
2019-06-07 07:43:28,055 DEBUG org.apache.hadoop.yarn.server.resourcemanager.scheduler.capacity.CapacityScheduler: nodeUpdate: slave2:33474 clusterResources: <memory:8192, vCores:2>
2019-06-07 07:43:28,055 DEBUG org.apache.hadoop.yarn.server.resourcemanager.scheduler.capacity.CapacityScheduler: Node being looked for scheduling slave2:33474 availableResource: <memory:4096, vCores:1>
2019-06-07 07:43:28,055 DEBUG org.apache.hadoop.yarn.server.resourcemanager.scheduler.capacity.CapacityScheduler: Node being looked for scheduling slave2:33474 availableResource: <memory:4096, vCores:1>
2019-06-07 07:43:28,055 DEBUG org.apache.hadoop.yarn.server.resourcemanager.scheduler.capacity.CapacityScheduler: Trying to schedule on node: slave2, available: <memory:4096, vCores:1>
2019-06-07 07:43:28,055 DEBUG org.apache.hadoop.yarn.server.resourcemanager.scheduler.capacity.CapacityScheduler: Trying to schedule on node: slave2, available: <memory:4096, vCores:1>
2019-06-07 07:43:28,055 DEBUG org.apache.hadoop.yarn.server.resourcemanager.scheduler.capacity.ParentQueue: Skip this queue=root, because it doesn't need more resource, schedulingMode=RESPECT_PARTITION_EXCLUSIVITY node-partition=
2019-06-07 07:43:28,055 DEBUG org.apache.hadoop.yarn.server.resourcemanager.scheduler.capacity.ParentQueue: Skip this queue=root, because it doesn't need more resource, schedulingMode=RESPECT_PARTITION_EXCLUSIVITY node-partition=
2019-06-07 07:43:29,048 DEBUG org.apache.hadoop.yarn.server.resourcemanager.rmnode.RMNodeImpl: Processing slave1:35126 of type STATUS_UPDATE
2019-06-07 07:43:29,048 DEBUG org.apache.hadoop.yarn.server.resourcemanager.rmnode.RMNodeImpl: Processing slave1:35126 of type STATUS_UPDATE
2019-06-07 07:43:29,049 DEBUG org.apache.hadoop.yarn.server.resourcemanager.scheduler.capacity.CapacityScheduler: nodeUpdate: slave1:35126 clusterResources: <memory:8192, vCores:2>
2019-06-07 07:43:29,049 DEBUG org.apache.hadoop.yarn.server.resourcemanager.scheduler.capacity.CapacityScheduler: nodeUpdate: slave1:35126 clusterResources: <memory:8192, vCores:2>
2019-06-07 07:43:29,050 DEBUG org.apache.hadoop.yarn.server.resourcemanager.scheduler.capacity.CapacityScheduler: Node being looked for scheduling slave1:35126 availableResource: <memory:4096, vCores:1>
2019-06-07 07:43:29,050 DEBUG org.apache.hadoop.yarn.server.resourcemanager.scheduler.capacity.CapacityScheduler: Node being looked for scheduling slave1:35126 availableResource: <memory:4096, vCores:1>
2019-06-07 07:43:29,050 DEBUG org.apache.hadoop.yarn.server.resourcemanager.scheduler.capacity.CapacityScheduler: Trying to schedule on node: slave1, available: <memory:4096, vCores:1>
2019-06-07 07:43:29,050 DEBUG org.apache.hadoop.yarn.server.resourcemanager.scheduler.capacity.CapacityScheduler: Trying to schedule on node: slave1, available: <memory:4096, vCores:1>
2019-06-07 07:43:29,050 DEBUG org.apache.hadoop.yarn.server.resourcemanager.scheduler.capacity.ParentQueue: Skip this queue=root, because it doesn't need more resource, schedulingMode=RESPECT_PARTITION_EXCLUSIVITY node-partition=
2019-06-07 07:43:29,050 DEBUG org.apache.hadoop.yarn.server.resourcemanager.scheduler.capacity.ParentQueue: Skip this queue=root, because it doesn't need more resource, schedulingMode=RESPECT_PARTITION_EXCLUSIVITY node-partition=
2019-06-07 07:43:29,058 DEBUG org.apache.hadoop.yarn.server.resourcemanager.rmnode.RMNodeImpl: Processing slave2:33474 of type STATUS_UPDATE
2019-06-07 07:43:29,058 DEBUG org.apache.hadoop.yarn.server.resourcemanager.rmnode.RMNodeImpl: Processing slave2:33474 of type STATUS_UPDATE
2019-06-07 07:43:29,060 DEBUG org.apache.hadoop.yarn.server.resourcemanager.scheduler.capacity.CapacityScheduler: nodeUpdate: slave2:33474 clusterResources: <memory:8192, vCores:2>
2019-06-07 07:43:29,060 DEBUG org.apache.hadoop.yarn.server.resourcemanager.scheduler.capacity.CapacityScheduler: nodeUpdate: slave2:33474 clusterResources: <memory:8192, vCores:2>
2019-06-07 07:43:29,060 DEBUG org.apache.hadoop.yarn.server.resourcemanager.scheduler.capacity.CapacityScheduler: Node being looked for scheduling slave2:33474 availableResource: <memory:4096, vCores:1>
2019-06-07 07:43:29,060 DEBUG org.apache.hadoop.yarn.server.resourcemanager.scheduler.capacity.CapacityScheduler: Node being looked for scheduling slave2:33474 availableResource: <memory:4096, vCores:1>
2019-06-07 07:43:29,060 DEBUG org.apache.hadoop.yarn.server.resourcemanager.scheduler.capacity.CapacityScheduler: Trying to schedule on node: slave2, available: <memory:4096, vCores:1>
2019-06-07 07:43:29,060 DEBUG org.apache.hadoop.yarn.server.resourcemanager.scheduler.capacity.CapacityScheduler: Trying to schedule on node: slave2, available: <memory:4096, vCores:1>
2019-06-07 07:43:29,060 DEBUG org.apache.hadoop.yarn.server.resourcemanager.scheduler.capacity.ParentQueue: Skip this queue=root, because it doesn't need more resource, schedulingMode=RESPECT_PARTITION_EXCLUSIVITY node-partition=
2019-06-07 07:43:29,060 DEBUG org.apache.hadoop.yarn.server.resourcemanager.scheduler.capacity.ParentQueue: Skip this queue=root, because it doesn't need more resource, schedulingMode=RESPECT_PARTITION_EXCLUSIVITY node-partition=
2019-06-07 07:43:30,052 DEBUG org.apache.hadoop.yarn.server.resourcemanager.rmnode.RMNodeImpl: Processing slave1:35126 of type STATUS_UPDATE
2019-06-07 07:43:30,052 DEBUG org.apache.hadoop.yarn.server.resourcemanager.rmnode.RMNodeImpl: Processing slave1:35126 of type STATUS_UPDATE
2019-06-07 07:43:30,057 DEBUG org.apache.hadoop.yarn.server.resourcemanager.scheduler.capacity.CapacityScheduler: nodeUpdate: slave1:35126 clusterResources: <memory:8192, vCores:2>
2019-06-07 07:43:30,057 DEBUG org.apache.hadoop.yarn.server.resourcemanager.scheduler.capacity.CapacityScheduler: nodeUpdate: slave1:35126 clusterResources: <memory:8192, vCores:2>
2019-06-07 07:43:30,058 DEBUG org.apache.hadoop.yarn.server.resourcemanager.scheduler.capacity.CapacityScheduler: Node being looked for scheduling slave1:35126 availableResource: <memory:4096, vCores:1>
2019-06-07 07:43:30,058 DEBUG org.apache.hadoop.yarn.server.resourcemanager.scheduler.capacity.CapacityScheduler: Node being looked for scheduling slave1:35126 availableResource: <memory:4096, vCores:1>
2019-06-07 07:43:30,058 DEBUG org.apache.hadoop.yarn.server.resourcemanager.scheduler.capacity.CapacityScheduler: Trying to schedule on node: slave1, available: <memory:4096, vCores:1>
2019-06-07 07:43:30,058 DEBUG org.apache.hadoop.yarn.server.resourcemanager.scheduler.capacity.CapacityScheduler: Trying to schedule on node: slave1, available: <memory:4096, vCores:1>
2019-06-07 07:43:30,058 DEBUG org.apache.hadoop.yarn.server.resourcemanager.scheduler.capacity.ParentQueue: Skip this queue=root, because it doesn't need more resource, schedulingMode=RESPECT_PARTITION_EXCLUSIVITY node-partition=
2019-06-07 07:43:30,058 DEBUG org.apache.hadoop.yarn.server.resourcemanager.scheduler.capacity.ParentQueue: Skip this queue=root, because it doesn't need more resource, schedulingMode=RESPECT_PARTITION_EXCLUSIVITY node-partition=
2019-06-07 07:43:30,066 DEBUG org.apache.hadoop.yarn.server.resourcemanager.rmnode.RMNodeImpl: Processing slave2:33474 of type STATUS_UPDATE
2019-06-07 07:43:30,066 DEBUG org.apache.hadoop.yarn.server.resourcemanager.rmnode.RMNodeImpl: Processing slave2:33474 of type STATUS_UPDATE
2019-06-07 07:43:30,067 DEBUG org.apache.hadoop.yarn.server.resourcemanager.scheduler.capacity.CapacityScheduler: nodeUpdate: slave2:33474 clusterResources: <memory:8192, vCores:2>
2019-06-07 07:43:30,067 DEBUG org.apache.hadoop.yarn.server.resourcemanager.scheduler.capacity.CapacityScheduler: nodeUpdate: slave2:33474 clusterResources: <memory:8192, vCores:2>
2019-06-07 07:43:30,067 DEBUG org.apache.hadoop.yarn.server.resourcemanager.scheduler.capacity.CapacityScheduler: Node being looked for scheduling slave2:33474 availableResource: <memory:4096, vCores:1>
2019-06-07 07:43:30,067 DEBUG org.apache.hadoop.yarn.server.resourcemanager.scheduler.capacity.CapacityScheduler: Node being looked for scheduling slave2:33474 availableResource: <memory:4096, vCores:1>
2019-06-07 07:43:30,067 DEBUG org.apache.hadoop.yarn.server.resourcemanager.scheduler.capacity.CapacityScheduler: Trying to schedule on node: slave2, available: <memory:4096, vCores:1>
2019-06-07 07:43:30,067 DEBUG org.apache.hadoop.yarn.server.resourcemanager.scheduler.capacity.CapacityScheduler: Trying to schedule on node: slave2, available: <memory:4096, vCores:1>
2019-06-07 07:43:30,067 DEBUG org.apache.hadoop.yarn.server.resourcemanager.scheduler.capacity.ParentQueue: Skip this queue=root, because it doesn't need more resource, schedulingMode=RESPECT_PARTITION_EXCLUSIVITY node-partition=
2019-06-07 07:43:30,067 DEBUG org.apache.hadoop.yarn.server.resourcemanager.scheduler.capacity.ParentQueue: Skip this queue=root, because it doesn't need more resource, schedulingMode=RESPECT_PARTITION_EXCLUSIVITY node-partition=
2019-06-07 07:43:31,055 DEBUG org.apache.hadoop.yarn.server.resourcemanager.rmnode.RMNodeImpl: Processing slave1:35126 of type STATUS_UPDATE
2019-06-07 07:43:31,055 DEBUG org.apache.hadoop.yarn.server.resourcemanager.rmnode.RMNodeImpl: Processing slave1:35126 of type STATUS_UPDATE
2019-06-07 07:43:31,056 DEBUG org.apache.hadoop.yarn.server.resourcemanager.scheduler.capacity.CapacityScheduler: nodeUpdate: slave1:35126 clusterResources: <memory:8192, vCores:2>
2019-06-07 07:43:31,056 DEBUG org.apache.hadoop.yarn.server.resourcemanager.scheduler.capacity.CapacityScheduler: nodeUpdate: slave1:35126 clusterResources: <memory:8192, vCores:2>
2019-06-07 07:43:31,056 DEBUG org.apache.hadoop.yarn.server.resourcemanager.scheduler.capacity.CapacityScheduler: Node being looked for scheduling slave1:35126 availableResource: <memory:4096, vCores:1>
2019-06-07 07:43:31,056 DEBUG org.apache.hadoop.yarn.server.resourcemanager.scheduler.capacity.CapacityScheduler: Node being looked for scheduling slave1:35126 availableResource: <memory:4096, vCores:1>
2019-06-07 07:43:31,057 DEBUG org.apache.hadoop.yarn.server.resourcemanager.scheduler.capacity.CapacityScheduler: Trying to schedule on node: slave1, available: <memory:4096, vCores:1>
2019-06-07 07:43:31,057 DEBUG org.apache.hadoop.yarn.server.resourcemanager.scheduler.capacity.CapacityScheduler: Trying to schedule on node: slave1, available: <memory:4096, vCores:1>
2019-06-07 07:43:31,057 DEBUG org.apache.hadoop.yarn.server.resourcemanager.scheduler.capacity.ParentQueue: Skip this queue=root, because it doesn't need more resource, schedulingMode=RESPECT_PARTITION_EXCLUSIVITY node-partition=
2019-06-07 07:43:31,057 DEBUG org.apache.hadoop.yarn.server.resourcemanager.scheduler.capacity.ParentQueue: Skip this queue=root, because it doesn't need more resource, schedulingMode=RESPECT_PARTITION_EXCLUSIVITY node-partition=
2019-06-07 07:43:31,070 DEBUG org.apache.hadoop.yarn.server.resourcemanager.rmnode.RMNodeImpl: Processing slave2:33474 of type STATUS_UPDATE
2019-06-07 07:43:31,070 DEBUG org.apache.hadoop.yarn.server.resourcemanager.rmnode.RMNodeImpl: Processing slave2:33474 of type STATUS_UPDATE
2019-06-07 07:43:31,070 DEBUG org.apache.hadoop.yarn.server.resourcemanager.scheduler.capacity.CapacityScheduler: nodeUpdate: slave2:33474 clusterResources: <memory:8192, vCores:2>
2019-06-07 07:43:31,070 DEBUG org.apache.hadoop.yarn.server.resourcemanager.scheduler.capacity.CapacityScheduler: nodeUpdate: slave2:33474 clusterResources: <memory:8192, vCores:2>
2019-06-07 07:43:31,071 DEBUG org.apache.hadoop.yarn.server.resourcemanager.scheduler.capacity.CapacityScheduler: Node being looked for scheduling slave2:33474 availableResource: <memory:4096, vCores:1>
2019-06-07 07:43:31,071 DEBUG org.apache.hadoop.yarn.server.resourcemanager.scheduler.capacity.CapacityScheduler: Node being looked for scheduling slave2:33474 availableResource: <memory:4096, vCores:1>
2019-06-07 07:43:31,071 DEBUG org.apache.hadoop.yarn.server.resourcemanager.scheduler.capacity.CapacityScheduler: Trying to schedule on node: slave2, available: <memory:4096, vCores:1>
2019-06-07 07:43:31,071 DEBUG org.apache.hadoop.yarn.server.resourcemanager.scheduler.capacity.CapacityScheduler: Trying to schedule on node: slave2, available: <memory:4096, vCores:1>
2019-06-07 07:43:31,071 DEBUG org.apache.hadoop.yarn.server.resourcemanager.scheduler.capacity.ParentQueue: Skip this queue=root, because it doesn't need more resource, schedulingMode=RESPECT_PARTITION_EXCLUSIVITY node-partition=
2019-06-07 07:43:31,071 DEBUG org.apache.hadoop.yarn.server.resourcemanager.scheduler.capacity.ParentQueue: Skip this queue=root, because it doesn't need more resource, schedulingMode=RESPECT_PARTITION_EXCLUSIVITY node-partition=
2019-06-07 07:43:32,062 DEBUG org.apache.hadoop.yarn.server.resourcemanager.rmnode.RMNodeImpl: Processing slave1:35126 of type STATUS_UPDATE
2019-06-07 07:43:32,062 DEBUG org.apache.hadoop.yarn.server.resourcemanager.rmnode.RMNodeImpl: Processing slave1:35126 of type STATUS_UPDATE
2019-06-07 07:43:32,063 DEBUG org.apache.hadoop.yarn.server.resourcemanager.scheduler.capacity.CapacityScheduler: nodeUpdate: slave1:35126 clusterResources: <memory:8192, vCores:2>
2019-06-07 07:43:32,063 DEBUG org.apache.hadoop.yarn.server.resourcemanager.scheduler.capacity.CapacityScheduler: nodeUpdate: slave1:35126 clusterResources: <memory:8192, vCores:2>
2019-06-07 07:43:32,063 DEBUG org.apache.hadoop.yarn.server.resourcemanager.scheduler.capacity.CapacityScheduler: Node being looked for scheduling slave1:35126 availableResource: <memory:4096, vCores:1>
2019-06-07 07:43:32,063 DEBUG org.apache.hadoop.yarn.server.resourcemanager.scheduler.capacity.CapacityScheduler: Node being looked for scheduling slave1:35126 availableResource: <memory:4096, vCores:1>
2019-06-07 07:43:32,063 DEBUG org.apache.hadoop.yarn.server.resourcemanager.scheduler.capacity.CapacityScheduler: Trying to schedule on node: slave1, available: <memory:4096, vCores:1>
2019-06-07 07:43:32,063 DEBUG org.apache.hadoop.yarn.server.resourcemanager.scheduler.capacity.CapacityScheduler: Trying to schedule on node: slave1, available: <memory:4096, vCores:1>
2019-06-07 07:43:32,063 DEBUG org.apache.hadoop.yarn.server.resourcemanager.scheduler.capacity.ParentQueue: Skip this queue=root, because it doesn't need more resource, schedulingMode=RESPECT_PARTITION_EXCLUSIVITY node-partition=
2019-06-07 07:43:32,063 DEBUG org.apache.hadoop.yarn.server.resourcemanager.scheduler.capacity.ParentQueue: Skip this queue=root, because it doesn't need more resource, schedulingMode=RESPECT_PARTITION_EXCLUSIVITY node-partition=
2019-06-07 07:43:32,077 DEBUG org.apache.hadoop.yarn.server.resourcemanager.rmnode.RMNodeImpl: Processing slave2:33474 of type STATUS_UPDATE
2019-06-07 07:43:32,077 DEBUG org.apache.hadoop.yarn.server.resourcemanager.rmnode.RMNodeImpl: Processing slave2:33474 of type STATUS_UPDATE
2019-06-07 07:43:32,078 DEBUG org.apache.hadoop.yarn.server.resourcemanager.scheduler.capacity.CapacityScheduler: nodeUpdate: slave2:33474 clusterResources: <memory:8192, vCores:2>
2019-06-07 07:43:32,078 DEBUG org.apache.hadoop.yarn.server.resourcemanager.scheduler.capacity.CapacityScheduler: nodeUpdate: slave2:33474 clusterResources: <memory:8192, vCores:2>
2019-06-07 07:43:32,078 DEBUG org.apache.hadoop.yarn.server.resourcemanager.scheduler.capacity.CapacityScheduler: Node being looked for scheduling slave2:33474 availableResource: <memory:4096, vCores:1>
2019-06-07 07:43:32,078 DEBUG org.apache.hadoop.yarn.server.resourcemanager.scheduler.capacity.CapacityScheduler: Node being looked for scheduling slave2:33474 availableResource: <memory:4096, vCores:1>
2019-06-07 07:43:32,078 DEBUG org.apache.hadoop.yarn.server.resourcemanager.scheduler.capacity.CapacityScheduler: Trying to schedule on node: slave2, available: <memory:4096, vCores:1>
2019-06-07 07:43:32,078 DEBUG org.apache.hadoop.yarn.server.resourcemanager.scheduler.capacity.CapacityScheduler: Trying to schedule on node: slave2, available: <memory:4096, vCores:1>
2019-06-07 07:43:32,078 DEBUG org.apache.hadoop.yarn.server.resourcemanager.scheduler.capacity.ParentQueue: Skip this queue=root, because it doesn't need more resource, schedulingMode=RESPECT_PARTITION_EXCLUSIVITY node-partition=
2019-06-07 07:43:32,078 DEBUG org.apache.hadoop.yarn.server.resourcemanager.scheduler.capacity.ParentQueue: Skip this queue=root, because it doesn't need more resource, schedulingMode=RESPECT_PARTITION_EXCLUSIVITY node-partition=
2019-06-07 07:43:33,066 DEBUG org.apache.hadoop.yarn.server.resourcemanager.rmnode.RMNodeImpl: Processing slave1:35126 of type STATUS_UPDATE
2019-06-07 07:43:33,066 DEBUG org.apache.hadoop.yarn.server.resourcemanager.rmnode.RMNodeImpl: Processing slave1:35126 of type STATUS_UPDATE
2019-06-07 07:43:33,067 DEBUG org.apache.hadoop.yarn.server.resourcemanager.scheduler.capacity.CapacityScheduler: nodeUpdate: slave1:35126 clusterResources: <memory:8192, vCores:2>
2019-06-07 07:43:33,067 DEBUG org.apache.hadoop.yarn.server.resourcemanager.scheduler.capacity.CapacityScheduler: nodeUpdate: slave1:35126 clusterResources: <memory:8192, vCores:2>
2019-06-07 07:43:33,068 DEBUG org.apache.hadoop.yarn.server.resourcemanager.scheduler.capacity.CapacityScheduler: Node being looked for scheduling slave1:35126 availableResource: <memory:4096, vCores:1>
2019-06-07 07:43:33,068 DEBUG org.apache.hadoop.yarn.server.resourcemanager.scheduler.capacity.CapacityScheduler: Node being looked for scheduling slave1:35126 availableResource: <memory:4096, vCores:1>
2019-06-07 07:43:33,068 DEBUG org.apache.hadoop.yarn.server.resourcemanager.scheduler.capacity.CapacityScheduler: Trying to schedule on node: slave1, available: <memory:4096, vCores:1>
2019-06-07 07:43:33,068 DEBUG org.apache.hadoop.yarn.server.resourcemanager.scheduler.capacity.CapacityScheduler: Trying to schedule on node: slave1, available: <memory:4096, vCores:1>
2019-06-07 07:43:33,068 DEBUG org.apache.hadoop.yarn.server.resourcemanager.scheduler.capacity.ParentQueue: Skip this queue=root, because it doesn't need more resource, schedulingMode=RESPECT_PARTITION_EXCLUSIVITY node-partition=
2019-06-07 07:43:33,068 DEBUG org.apache.hadoop.yarn.server.resourcemanager.scheduler.capacity.ParentQueue: Skip this queue=root, because it doesn't need more resource, schedulingMode=RESPECT_PARTITION_EXCLUSIVITY node-partition=
2019-06-07 07:43:33,080 DEBUG org.apache.hadoop.yarn.server.resourcemanager.rmnode.RMNodeImpl: Processing slave2:33474 of type STATUS_UPDATE
2019-06-07 07:43:33,080 DEBUG org.apache.hadoop.yarn.server.resourcemanager.rmnode.RMNodeImpl: Processing slave2:33474 of type STATUS_UPDATE
2019-06-07 07:43:33,081 DEBUG org.apache.hadoop.yarn.server.resourcemanager.scheduler.capacity.CapacityScheduler: nodeUpdate: slave2:33474 clusterResources: <memory:8192, vCores:2>
2019-06-07 07:43:33,081 DEBUG org.apache.hadoop.yarn.server.resourcemanager.scheduler.capacity.CapacityScheduler: nodeUpdate: slave2:33474 clusterResources: <memory:8192, vCores:2>
2019-06-07 07:43:33,081 DEBUG org.apache.hadoop.yarn.server.resourcemanager.scheduler.capacity.CapacityScheduler: Node being looked for scheduling slave2:33474 availableResource: <memory:4096, vCores:1>
2019-06-07 07:43:33,081 DEBUG org.apache.hadoop.yarn.server.resourcemanager.scheduler.capacity.CapacityScheduler: Node being looked for scheduling slave2:33474 availableResource: <memory:4096, vCores:1>
2019-06-07 07:43:33,082 DEBUG org.apache.hadoop.yarn.server.resourcemanager.scheduler.capacity.CapacityScheduler: Trying to schedule on node: slave2, available: <memory:4096, vCores:1>
2019-06-07 07:43:33,082 DEBUG org.apache.hadoop.yarn.server.resourcemanager.scheduler.capacity.CapacityScheduler: Trying to schedule on node: slave2, available: <memory:4096, vCores:1>
2019-06-07 07:43:33,082 DEBUG org.apache.hadoop.yarn.server.resourcemanager.scheduler.capacity.ParentQueue: Skip this queue=root, because it doesn't need more resource, schedulingMode=RESPECT_PARTITION_EXCLUSIVITY node-partition=
2019-06-07 07:43:33,082 DEBUG org.apache.hadoop.yarn.server.resourcemanager.scheduler.capacity.ParentQueue: Skip this queue=root, because it doesn't need more resource, schedulingMode=RESPECT_PARTITION_EXCLUSIVITY node-partition=
2019-06-07 07:43:34,070 DEBUG org.apache.hadoop.yarn.server.resourcemanager.rmnode.RMNodeImpl: Processing slave1:35126 of type STATUS_UPDATE
2019-06-07 07:43:34,070 DEBUG org.apache.hadoop.yarn.server.resourcemanager.rmnode.RMNodeImpl: Processing slave1:35126 of type STATUS_UPDATE
2019-06-07 07:43:34,072 DEBUG org.apache.hadoop.yarn.server.resourcemanager.scheduler.capacity.CapacityScheduler: nodeUpdate: slave1:35126 clusterResources: <memory:8192, vCores:2>
2019-06-07 07:43:34,072 DEBUG org.apache.hadoop.yarn.server.resourcemanager.scheduler.capacity.CapacityScheduler: nodeUpdate: slave1:35126 clusterResources: <memory:8192, vCores:2>
2019-06-07 07:43:34,072 DEBUG org.apache.hadoop.yarn.server.resourcemanager.scheduler.capacity.CapacityScheduler: Node being looked for scheduling slave1:35126 availableResource: <memory:4096, vCores:1>
2019-06-07 07:43:34,072 DEBUG org.apache.hadoop.yarn.server.resourcemanager.scheduler.capacity.CapacityScheduler: Node being looked for scheduling slave1:35126 availableResource: <memory:4096, vCores:1>
2019-06-07 07:43:34,072 DEBUG org.apache.hadoop.yarn.server.resourcemanager.scheduler.capacity.CapacityScheduler: Trying to schedule on node: slave1, available: <memory:4096, vCores:1>
2019-06-07 07:43:34,072 DEBUG org.apache.hadoop.yarn.server.resourcemanager.scheduler.capacity.CapacityScheduler: Trying to schedule on node: slave1, available: <memory:4096, vCores:1>
2019-06-07 07:43:34,072 DEBUG org.apache.hadoop.yarn.server.resourcemanager.scheduler.capacity.ParentQueue: Skip this queue=root, because it doesn't need more resource, schedulingMode=RESPECT_PARTITION_EXCLUSIVITY node-partition=
2019-06-07 07:43:34,072 DEBUG org.apache.hadoop.yarn.server.resourcemanager.scheduler.capacity.ParentQueue: Skip this queue=root, because it doesn't need more resource, schedulingMode=RESPECT_PARTITION_EXCLUSIVITY node-partition=
2019-06-07 07:43:34,084 DEBUG org.apache.hadoop.yarn.server.resourcemanager.rmnode.RMNodeImpl: Processing slave2:33474 of type STATUS_UPDATE
2019-06-07 07:43:34,084 DEBUG org.apache.hadoop.yarn.server.resourcemanager.rmnode.RMNodeImpl: Processing slave2:33474 of type STATUS_UPDATE
2019-06-07 07:43:34,085 DEBUG org.apache.hadoop.yarn.server.resourcemanager.scheduler.capacity.CapacityScheduler: nodeUpdate: slave2:33474 clusterResources: <memory:8192, vCores:2>
2019-06-07 07:43:34,085 DEBUG org.apache.hadoop.yarn.server.resourcemanager.scheduler.capacity.CapacityScheduler: nodeUpdate: slave2:33474 clusterResources: <memory:8192, vCores:2>
2019-06-07 07:43:34,085 DEBUG org.apache.hadoop.yarn.server.resourcemanager.scheduler.capacity.CapacityScheduler: Node being looked for scheduling slave2:33474 availableResource: <memory:4096, vCores:1>
2019-06-07 07:43:34,085 DEBUG org.apache.hadoop.yarn.server.resourcemanager.scheduler.capacity.CapacityScheduler: Node being looked for scheduling slave2:33474 availableResource: <memory:4096, vCores:1>
2019-06-07 07:43:34,085 DEBUG org.apache.hadoop.yarn.server.resourcemanager.scheduler.capacity.CapacityScheduler: Trying to schedule on node: slave2, available: <memory:4096, vCores:1>
2019-06-07 07:43:34,085 DEBUG org.apache.hadoop.yarn.server.resourcemanager.scheduler.capacity.CapacityScheduler: Trying to schedule on node: slave2, available: <memory:4096, vCores:1>
2019-06-07 07:43:34,085 DEBUG org.apache.hadoop.yarn.server.resourcemanager.scheduler.capacity.ParentQueue: Skip this queue=root, because it doesn't need more resource, schedulingMode=RESPECT_PARTITION_EXCLUSIVITY node-partition=
2019-06-07 07:43:34,085 DEBUG org.apache.hadoop.yarn.server.resourcemanager.scheduler.capacity.ParentQueue: Skip this queue=root, because it doesn't need more resource, schedulingMode=RESPECT_PARTITION_EXCLUSIVITY node-partition=
2019-06-07 07:43:35,076 DEBUG org.apache.hadoop.yarn.server.resourcemanager.rmnode.RMNodeImpl: Processing slave1:35126 of type STATUS_UPDATE
2019-06-07 07:43:35,076 DEBUG org.apache.hadoop.yarn.server.resourcemanager.rmnode.RMNodeImpl: Processing slave1:35126 of type STATUS_UPDATE
2019-06-07 07:43:35,077 DEBUG org.apache.hadoop.yarn.server.resourcemanager.scheduler.capacity.CapacityScheduler: nodeUpdate: slave1:35126 clusterResources: <memory:8192, vCores:2>
2019-06-07 07:43:35,077 DEBUG org.apache.hadoop.yarn.server.resourcemanager.scheduler.capacity.CapacityScheduler: nodeUpdate: slave1:35126 clusterResources: <memory:8192, vCores:2>
2019-06-07 07:43:35,077 DEBUG org.apache.hadoop.yarn.server.resourcemanager.scheduler.capacity.CapacityScheduler: Node being looked for scheduling slave1:35126 availableResource: <memory:4096, vCores:1>
2019-06-07 07:43:35,077 DEBUG org.apache.hadoop.yarn.server.resourcemanager.scheduler.capacity.CapacityScheduler: Node being looked for scheduling slave1:35126 availableResource: <memory:4096, vCores:1>
2019-06-07 07:43:35,077 DEBUG org.apache.hadoop.yarn.server.resourcemanager.scheduler.capacity.CapacityScheduler: Trying to schedule on node: slave1, available: <memory:4096, vCores:1>
2019-06-07 07:43:35,077 DEBUG org.apache.hadoop.yarn.server.resourcemanager.scheduler.capacity.CapacityScheduler: Trying to schedule on node: slave1, available: <memory:4096, vCores:1>
2019-06-07 07:43:35,077 DEBUG org.apache.hadoop.yarn.server.resourcemanager.scheduler.capacity.ParentQueue: Skip this queue=root, because it doesn't need more resource, schedulingMode=RESPECT_PARTITION_EXCLUSIVITY node-partition=
2019-06-07 07:43:35,077 DEBUG org.apache.hadoop.yarn.server.resourcemanager.scheduler.capacity.ParentQueue: Skip this queue=root, because it doesn't need more resource, schedulingMode=RESPECT_PARTITION_EXCLUSIVITY node-partition=
2019-06-07 07:43:35,090 DEBUG org.apache.hadoop.yarn.server.resourcemanager.rmnode.RMNodeImpl: Processing slave2:33474 of type STATUS_UPDATE
2019-06-07 07:43:35,090 DEBUG org.apache.hadoop.yarn.server.resourcemanager.rmnode.RMNodeImpl: Processing slave2:33474 of type STATUS_UPDATE
2019-06-07 07:43:35,091 DEBUG org.apache.hadoop.yarn.server.resourcemanager.scheduler.capacity.CapacityScheduler: nodeUpdate: slave2:33474 clusterResources: <memory:8192, vCores:2>
2019-06-07 07:43:35,091 DEBUG org.apache.hadoop.yarn.server.resourcemanager.scheduler.capacity.CapacityScheduler: nodeUpdate: slave2:33474 clusterResources: <memory:8192, vCores:2>
2019-06-07 07:43:35,091 DEBUG org.apache.hadoop.yarn.server.resourcemanager.scheduler.capacity.CapacityScheduler: Node being looked for scheduling slave2:33474 availableResource: <memory:4096, vCores:1>
2019-06-07 07:43:35,091 DEBUG org.apache.hadoop.yarn.server.resourcemanager.scheduler.capacity.CapacityScheduler: Node being looked for scheduling slave2:33474 availableResource: <memory:4096, vCores:1>
2019-06-07 07:43:35,091 DEBUG org.apache.hadoop.yarn.server.resourcemanager.scheduler.capacity.CapacityScheduler: Trying to schedule on node: slave2, available: <memory:4096, vCores:1>
2019-06-07 07:43:35,091 DEBUG org.apache.hadoop.yarn.server.resourcemanager.scheduler.capacity.CapacityScheduler: Trying to schedule on node: slave2, available: <memory:4096, vCores:1>
2019-06-07 07:43:35,091 DEBUG org.apache.hadoop.yarn.server.resourcemanager.scheduler.capacity.ParentQueue: Skip this queue=root, because it doesn't need more resource, schedulingMode=RESPECT_PARTITION_EXCLUSIVITY node-partition=
2019-06-07 07:43:35,091 DEBUG org.apache.hadoop.yarn.server.resourcemanager.scheduler.capacity.ParentQueue: Skip this queue=root, because it doesn't need more resource, schedulingMode=RESPECT_PARTITION_EXCLUSIVITY node-partition=
2019-06-07 07:43:36,080 DEBUG org.apache.hadoop.yarn.server.resourcemanager.rmnode.RMNodeImpl: Processing slave1:35126 of type STATUS_UPDATE
2019-06-07 07:43:36,080 DEBUG org.apache.hadoop.yarn.server.resourcemanager.rmnode.RMNodeImpl: Processing slave1:35126 of type STATUS_UPDATE
2019-06-07 07:43:36,081 DEBUG org.apache.hadoop.yarn.server.resourcemanager.scheduler.capacity.CapacityScheduler: nodeUpdate: slave1:35126 clusterResources: <memory:8192, vCores:2>
2019-06-07 07:43:36,081 DEBUG org.apache.hadoop.yarn.server.resourcemanager.scheduler.capacity.CapacityScheduler: nodeUpdate: slave1:35126 clusterResources: <memory:8192, vCores:2>
2019-06-07 07:43:36,081 DEBUG org.apache.hadoop.yarn.server.resourcemanager.scheduler.capacity.CapacityScheduler: Node being looked for scheduling slave1:35126 availableResource: <memory:4096, vCores:1>
2019-06-07 07:43:36,081 DEBUG org.apache.hadoop.yarn.server.resourcemanager.scheduler.capacity.CapacityScheduler: Node being looked for scheduling slave1:35126 availableResource: <memory:4096, vCores:1>
2019-06-07 07:43:36,082 DEBUG org.apache.hadoop.yarn.server.resourcemanager.scheduler.capacity.CapacityScheduler: Trying to schedule on node: slave1, available: <memory:4096, vCores:1>
2019-06-07 07:43:36,082 DEBUG org.apache.hadoop.yarn.server.resourcemanager.scheduler.capacity.CapacityScheduler: Trying to schedule on node: slave1, available: <memory:4096, vCores:1>
2019-06-07 07:43:36,082 DEBUG org.apache.hadoop.yarn.server.resourcemanager.scheduler.capacity.ParentQueue: Skip this queue=root, because it doesn't need more resource, schedulingMode=RESPECT_PARTITION_EXCLUSIVITY node-partition=
2019-06-07 07:43:36,082 DEBUG org.apache.hadoop.yarn.server.resourcemanager.scheduler.capacity.ParentQueue: Skip this queue=root, because it doesn't need more resource, schedulingMode=RESPECT_PARTITION_EXCLUSIVITY node-partition=
2019-06-07 07:43:36,093 DEBUG org.apache.hadoop.yarn.server.resourcemanager.rmnode.RMNodeImpl: Processing slave2:33474 of type STATUS_UPDATE
2019-06-07 07:43:36,093 DEBUG org.apache.hadoop.yarn.server.resourcemanager.rmnode.RMNodeImpl: Processing slave2:33474 of type STATUS_UPDATE
2019-06-07 07:43:36,095 DEBUG org.apache.hadoop.yarn.server.resourcemanager.scheduler.capacity.CapacityScheduler: nodeUpdate: slave2:33474 clusterResources: <memory:8192, vCores:2>
2019-06-07 07:43:36,095 DEBUG org.apache.hadoop.yarn.server.resourcemanager.scheduler.capacity.CapacityScheduler: nodeUpdate: slave2:33474 clusterResources: <memory:8192, vCores:2>
2019-06-07 07:43:36,095 DEBUG org.apache.hadoop.yarn.server.resourcemanager.scheduler.capacity.CapacityScheduler: Node being looked for scheduling slave2:33474 availableResource: <memory:4096, vCores:1>
2019-06-07 07:43:36,095 DEBUG org.apache.hadoop.yarn.server.resourcemanager.scheduler.capacity.CapacityScheduler: Node being looked for scheduling slave2:33474 availableResource: <memory:4096, vCores:1>
2019-06-07 07:43:36,095 DEBUG org.apache.hadoop.yarn.server.resourcemanager.scheduler.capacity.CapacityScheduler: Trying to schedule on node: slave2, available: <memory:4096, vCores:1>
2019-06-07 07:43:36,095 DEBUG org.apache.hadoop.yarn.server.resourcemanager.scheduler.capacity.CapacityScheduler: Trying to schedule on node: slave2, available: <memory:4096, vCores:1>
2019-06-07 07:43:36,095 DEBUG org.apache.hadoop.yarn.server.resourcemanager.scheduler.capacity.ParentQueue: Skip this queue=root, because it doesn't need more resource, schedulingMode=RESPECT_PARTITION_EXCLUSIVITY node-partition=
2019-06-07 07:43:36,095 DEBUG org.apache.hadoop.yarn.server.resourcemanager.scheduler.capacity.ParentQueue: Skip this queue=root, because it doesn't need more resource, schedulingMode=RESPECT_PARTITION_EXCLUSIVITY node-partition=
2019-06-07 07:43:37,085 DEBUG org.apache.hadoop.yarn.server.resourcemanager.rmnode.RMNodeImpl: Processing slave1:35126 of type STATUS_UPDATE
2019-06-07 07:43:37,085 DEBUG org.apache.hadoop.yarn.server.resourcemanager.rmnode.RMNodeImpl: Processing slave1:35126 of type STATUS_UPDATE
2019-06-07 07:43:37,085 DEBUG org.apache.hadoop.yarn.server.resourcemanager.scheduler.capacity.CapacityScheduler: nodeUpdate: slave1:35126 clusterResources: <memory:8192, vCores:2>
2019-06-07 07:43:37,085 DEBUG org.apache.hadoop.yarn.server.resourcemanager.scheduler.capacity.CapacityScheduler: nodeUpdate: slave1:35126 clusterResources: <memory:8192, vCores:2>
2019-06-07 07:43:37,085 DEBUG org.apache.hadoop.yarn.server.resourcemanager.scheduler.capacity.CapacityScheduler: Node being looked for scheduling slave1:35126 availableResource: <memory:4096, vCores:1>
2019-06-07 07:43:37,085 DEBUG org.apache.hadoop.yarn.server.resourcemanager.scheduler.capacity.CapacityScheduler: Node being looked for scheduling slave1:35126 availableResource: <memory:4096, vCores:1>
2019-06-07 07:43:37,085 DEBUG org.apache.hadoop.yarn.server.resourcemanager.scheduler.capacity.CapacityScheduler: Trying to schedule on node: slave1, available: <memory:4096, vCores:1>
2019-06-07 07:43:37,085 DEBUG org.apache.hadoop.yarn.server.resourcemanager.scheduler.capacity.CapacityScheduler: Trying to schedule on node: slave1, available: <memory:4096, vCores:1>
2019-06-07 07:43:37,085 DEBUG org.apache.hadoop.yarn.server.resourcemanager.scheduler.capacity.ParentQueue: Skip this queue=root, because it doesn't need more resource, schedulingMode=RESPECT_PARTITION_EXCLUSIVITY node-partition=
2019-06-07 07:43:37,085 DEBUG org.apache.hadoop.yarn.server.resourcemanager.scheduler.capacity.ParentQueue: Skip this queue=root, because it doesn't need more resource, schedulingMode=RESPECT_PARTITION_EXCLUSIVITY node-partition=
2019-06-07 07:43:37,098 DEBUG org.apache.hadoop.yarn.server.resourcemanager.rmnode.RMNodeImpl: Processing slave2:33474 of type STATUS_UPDATE
2019-06-07 07:43:37,098 DEBUG org.apache.hadoop.yarn.server.resourcemanager.rmnode.RMNodeImpl: Processing slave2:33474 of type STATUS_UPDATE
2019-06-07 07:43:37,099 DEBUG org.apache.hadoop.yarn.server.resourcemanager.scheduler.capacity.CapacityScheduler: nodeUpdate: slave2:33474 clusterResources: <memory:8192, vCores:2>
2019-06-07 07:43:37,099 DEBUG org.apache.hadoop.yarn.server.resourcemanager.scheduler.capacity.CapacityScheduler: nodeUpdate: slave2:33474 clusterResources: <memory:8192, vCores:2>
2019-06-07 07:43:37,099 DEBUG org.apache.hadoop.yarn.server.resourcemanager.scheduler.capacity.CapacityScheduler: Node being looked for scheduling slave2:33474 availableResource: <memory:4096, vCores:1>
2019-06-07 07:43:37,099 DEBUG org.apache.hadoop.yarn.server.resourcemanager.scheduler.capacity.CapacityScheduler: Node being looked for scheduling slave2:33474 availableResource: <memory:4096, vCores:1>
2019-06-07 07:43:37,099 DEBUG org.apache.hadoop.yarn.server.resourcemanager.scheduler.capacity.CapacityScheduler: Trying to schedule on node: slave2, available: <memory:4096, vCores:1>
2019-06-07 07:43:37,099 DEBUG org.apache.hadoop.yarn.server.resourcemanager.scheduler.capacity.CapacityScheduler: Trying to schedule on node: slave2, available: <memory:4096, vCores:1>
2019-06-07 07:43:37,099 DEBUG org.apache.hadoop.yarn.server.resourcemanager.scheduler.capacity.ParentQueue: Skip this queue=root, because it doesn't need more resource, schedulingMode=RESPECT_PARTITION_EXCLUSIVITY node-partition=
2019-06-07 07:43:37,099 DEBUG org.apache.hadoop.yarn.server.resourcemanager.scheduler.capacity.ParentQueue: Skip this queue=root, because it doesn't need more resource, schedulingMode=RESPECT_PARTITION_EXCLUSIVITY node-partition=
2019-06-07 07:43:38,089 DEBUG org.apache.hadoop.yarn.server.resourcemanager.rmnode.RMNodeImpl: Processing slave1:35126 of type STATUS_UPDATE
2019-06-07 07:43:38,089 DEBUG org.apache.hadoop.yarn.server.resourcemanager.rmnode.RMNodeImpl: Processing slave1:35126 of type STATUS_UPDATE
2019-06-07 07:43:38,089 DEBUG org.apache.hadoop.yarn.server.resourcemanager.scheduler.capacity.CapacityScheduler: nodeUpdate: slave1:35126 clusterResources: <memory:8192, vCores:2>
2019-06-07 07:43:38,089 DEBUG org.apache.hadoop.yarn.server.resourcemanager.scheduler.capacity.CapacityScheduler: nodeUpdate: slave1:35126 clusterResources: <memory:8192, vCores:2>
2019-06-07 07:43:38,089 DEBUG org.apache.hadoop.yarn.server.resourcemanager.scheduler.capacity.CapacityScheduler: Node being looked for scheduling slave1:35126 availableResource: <memory:4096, vCores:1>
2019-06-07 07:43:38,089 DEBUG org.apache.hadoop.yarn.server.resourcemanager.scheduler.capacity.CapacityScheduler: Node being looked for scheduling slave1:35126 availableResource: <memory:4096, vCores:1>
2019-06-07 07:43:38,090 DEBUG org.apache.hadoop.yarn.server.resourcemanager.scheduler.capacity.CapacityScheduler: Trying to schedule on node: slave1, available: <memory:4096, vCores:1>
2019-06-07 07:43:38,090 DEBUG org.apache.hadoop.yarn.server.resourcemanager.scheduler.capacity.CapacityScheduler: Trying to schedule on node: slave1, available: <memory:4096, vCores:1>
2019-06-07 07:43:38,090 DEBUG org.apache.hadoop.yarn.server.resourcemanager.scheduler.capacity.ParentQueue: Skip this queue=root, because it doesn't need more resource, schedulingMode=RESPECT_PARTITION_EXCLUSIVITY node-partition=
2019-06-07 07:43:38,090 DEBUG org.apache.hadoop.yarn.server.resourcemanager.scheduler.capacity.ParentQueue: Skip this queue=root, because it doesn't need more resource, schedulingMode=RESPECT_PARTITION_EXCLUSIVITY node-partition=
2019-06-07 07:43:38,103 DEBUG org.apache.hadoop.yarn.server.resourcemanager.rmnode.RMNodeImpl: Processing slave2:33474 of type STATUS_UPDATE
2019-06-07 07:43:38,103 DEBUG org.apache.hadoop.yarn.server.resourcemanager.rmnode.RMNodeImpl: Processing slave2:33474 of type STATUS_UPDATE
2019-06-07 07:43:38,103 DEBUG org.apache.hadoop.yarn.server.resourcemanager.scheduler.capacity.CapacityScheduler: nodeUpdate: slave2:33474 clusterResources: <memory:8192, vCores:2>
2019-06-07 07:43:38,103 DEBUG org.apache.hadoop.yarn.server.resourcemanager.scheduler.capacity.CapacityScheduler: nodeUpdate: slave2:33474 clusterResources: <memory:8192, vCores:2>
2019-06-07 07:43:38,103 DEBUG org.apache.hadoop.yarn.server.resourcemanager.scheduler.capacity.CapacityScheduler: Node being looked for scheduling slave2:33474 availableResource: <memory:4096, vCores:1>
2019-06-07 07:43:38,103 DEBUG org.apache.hadoop.yarn.server.resourcemanager.scheduler.capacity.CapacityScheduler: Node being looked for scheduling slave2:33474 availableResource: <memory:4096, vCores:1>
2019-06-07 07:43:38,103 DEBUG org.apache.hadoop.yarn.server.resourcemanager.scheduler.capacity.CapacityScheduler: Trying to schedule on node: slave2, available: <memory:4096, vCores:1>
2019-06-07 07:43:38,103 DEBUG org.apache.hadoop.yarn.server.resourcemanager.scheduler.capacity.CapacityScheduler: Trying to schedule on node: slave2, available: <memory:4096, vCores:1>
2019-06-07 07:43:38,103 DEBUG org.apache.hadoop.yarn.server.resourcemanager.scheduler.capacity.ParentQueue: Skip this queue=root, because it doesn't need more resource, schedulingMode=RESPECT_PARTITION_EXCLUSIVITY node-partition=
2019-06-07 07:43:38,103 DEBUG org.apache.hadoop.yarn.server.resourcemanager.scheduler.capacity.ParentQueue: Skip this queue=root, because it doesn't need more resource, schedulingMode=RESPECT_PARTITION_EXCLUSIVITY node-partition=
2019-06-07 07:43:39,095 DEBUG org.apache.hadoop.yarn.server.resourcemanager.rmnode.RMNodeImpl: Processing slave1:35126 of type STATUS_UPDATE
2019-06-07 07:43:39,095 DEBUG org.apache.hadoop.yarn.server.resourcemanager.rmnode.RMNodeImpl: Processing slave1:35126 of type STATUS_UPDATE
2019-06-07 07:43:39,096 DEBUG org.apache.hadoop.yarn.server.resourcemanager.scheduler.capacity.CapacityScheduler: nodeUpdate: slave1:35126 clusterResources: <memory:8192, vCores:2>
2019-06-07 07:43:39,096 DEBUG org.apache.hadoop.yarn.server.resourcemanager.scheduler.capacity.CapacityScheduler: nodeUpdate: slave1:35126 clusterResources: <memory:8192, vCores:2>
2019-06-07 07:43:39,096 DEBUG org.apache.hadoop.yarn.server.resourcemanager.scheduler.capacity.CapacityScheduler: Node being looked for scheduling slave1:35126 availableResource: <memory:4096, vCores:1>
2019-06-07 07:43:39,096 DEBUG org.apache.hadoop.yarn.server.resourcemanager.scheduler.capacity.CapacityScheduler: Node being looked for scheduling slave1:35126 availableResource: <memory:4096, vCores:1>
2019-06-07 07:43:39,096 DEBUG org.apache.hadoop.yarn.server.resourcemanager.scheduler.capacity.CapacityScheduler: Trying to schedule on node: slave1, available: <memory:4096, vCores:1>
2019-06-07 07:43:39,096 DEBUG org.apache.hadoop.yarn.server.resourcemanager.scheduler.capacity.CapacityScheduler: Trying to schedule on node: slave1, available: <memory:4096, vCores:1>
2019-06-07 07:43:39,096 DEBUG org.apache.hadoop.yarn.server.resourcemanager.scheduler.capacity.ParentQueue: Skip this queue=root, because it doesn't need more resource, schedulingMode=RESPECT_PARTITION_EXCLUSIVITY node-partition=
2019-06-07 07:43:39,096 DEBUG org.apache.hadoop.yarn.server.resourcemanager.scheduler.capacity.ParentQueue: Skip this queue=root, because it doesn't need more resource, schedulingMode=RESPECT_PARTITION_EXCLUSIVITY node-partition=
2019-06-07 07:43:39,106 DEBUG org.apache.hadoop.yarn.server.resourcemanager.rmnode.RMNodeImpl: Processing slave2:33474 of type STATUS_UPDATE
2019-06-07 07:43:39,106 DEBUG org.apache.hadoop.yarn.server.resourcemanager.rmnode.RMNodeImpl: Processing slave2:33474 of type STATUS_UPDATE
2019-06-07 07:43:39,106 DEBUG org.apache.hadoop.yarn.server.resourcemanager.scheduler.capacity.CapacityScheduler: nodeUpdate: slave2:33474 clusterResources: <memory:8192, vCores:2>
2019-06-07 07:43:39,106 DEBUG org.apache.hadoop.yarn.server.resourcemanager.scheduler.capacity.CapacityScheduler: nodeUpdate: slave2:33474 clusterResources: <memory:8192, vCores:2>
2019-06-07 07:43:39,107 DEBUG org.apache.hadoop.yarn.server.resourcemanager.scheduler.capacity.CapacityScheduler: Node being looked for scheduling slave2:33474 availableResource: <memory:4096, vCores:1>
2019-06-07 07:43:39,107 DEBUG org.apache.hadoop.yarn.server.resourcemanager.scheduler.capacity.CapacityScheduler: Node being looked for scheduling slave2:33474 availableResource: <memory:4096, vCores:1>
2019-06-07 07:43:39,107 DEBUG org.apache.hadoop.yarn.server.resourcemanager.scheduler.capacity.CapacityScheduler: Trying to schedule on node: slave2, available: <memory:4096, vCores:1>
2019-06-07 07:43:39,107 DEBUG org.apache.hadoop.yarn.server.resourcemanager.scheduler.capacity.CapacityScheduler: Trying to schedule on node: slave2, available: <memory:4096, vCores:1>
2019-06-07 07:43:39,107 DEBUG org.apache.hadoop.yarn.server.resourcemanager.scheduler.capacity.ParentQueue: Skip this queue=root, because it doesn't need more resource, schedulingMode=RESPECT_PARTITION_EXCLUSIVITY node-partition=
2019-06-07 07:43:39,107 DEBUG org.apache.hadoop.yarn.server.resourcemanager.scheduler.capacity.ParentQueue: Skip this queue=root, because it doesn't need more resource, schedulingMode=RESPECT_PARTITION_EXCLUSIVITY node-partition=
2019-06-07 07:43:40,100 DEBUG org.apache.hadoop.yarn.server.resourcemanager.rmnode.RMNodeImpl: Processing slave1:35126 of type STATUS_UPDATE
2019-06-07 07:43:40,100 DEBUG org.apache.hadoop.yarn.server.resourcemanager.rmnode.RMNodeImpl: Processing slave1:35126 of type STATUS_UPDATE
2019-06-07 07:43:40,101 DEBUG org.apache.hadoop.yarn.server.resourcemanager.scheduler.capacity.CapacityScheduler: nodeUpdate: slave1:35126 clusterResources: <memory:8192, vCores:2>
2019-06-07 07:43:40,101 DEBUG org.apache.hadoop.yarn.server.resourcemanager.scheduler.capacity.CapacityScheduler: nodeUpdate: slave1:35126 clusterResources: <memory:8192, vCores:2>
2019-06-07 07:43:40,101 DEBUG org.apache.hadoop.yarn.server.resourcemanager.scheduler.capacity.CapacityScheduler: Node being looked for scheduling slave1:35126 availableResource: <memory:4096, vCores:1>
2019-06-07 07:43:40,101 DEBUG org.apache.hadoop.yarn.server.resourcemanager.scheduler.capacity.CapacityScheduler: Node being looked for scheduling slave1:35126 availableResource: <memory:4096, vCores:1>
2019-06-07 07:43:40,101 DEBUG org.apache.hadoop.yarn.server.resourcemanager.scheduler.capacity.CapacityScheduler: Trying to schedule on node: slave1, available: <memory:4096, vCores:1>
2019-06-07 07:43:40,101 DEBUG org.apache.hadoop.yarn.server.resourcemanager.scheduler.capacity.CapacityScheduler: Trying to schedule on node: slave1, available: <memory:4096, vCores:1>
2019-06-07 07:43:40,101 DEBUG org.apache.hadoop.yarn.server.resourcemanager.scheduler.capacity.ParentQueue: Skip this queue=root, because it doesn't need more resource, schedulingMode=RESPECT_PARTITION_EXCLUSIVITY node-partition=
2019-06-07 07:43:40,101 DEBUG org.apache.hadoop.yarn.server.resourcemanager.scheduler.capacity.ParentQueue: Skip this queue=root, because it doesn't need more resource, schedulingMode=RESPECT_PARTITION_EXCLUSIVITY node-partition=
2019-06-07 07:43:40,111 DEBUG org.apache.hadoop.yarn.server.resourcemanager.rmnode.RMNodeImpl: Processing slave2:33474 of type STATUS_UPDATE
2019-06-07 07:43:40,111 DEBUG org.apache.hadoop.yarn.server.resourcemanager.rmnode.RMNodeImpl: Processing slave2:33474 of type STATUS_UPDATE
2019-06-07 07:43:40,111 DEBUG org.apache.hadoop.yarn.server.resourcemanager.scheduler.capacity.CapacityScheduler: nodeUpdate: slave2:33474 clusterResources: <memory:8192, vCores:2>
2019-06-07 07:43:40,111 DEBUG org.apache.hadoop.yarn.server.resourcemanager.scheduler.capacity.CapacityScheduler: nodeUpdate: slave2:33474 clusterResources: <memory:8192, vCores:2>
2019-06-07 07:43:40,111 DEBUG org.apache.hadoop.yarn.server.resourcemanager.scheduler.capacity.CapacityScheduler: Node being looked for scheduling slave2:33474 availableResource: <memory:4096, vCores:1>
2019-06-07 07:43:40,111 DEBUG org.apache.hadoop.yarn.server.resourcemanager.scheduler.capacity.CapacityScheduler: Node being looked for scheduling slave2:33474 availableResource: <memory:4096, vCores:1>
2019-06-07 07:43:40,111 DEBUG org.apache.hadoop.yarn.server.resourcemanager.scheduler.capacity.CapacityScheduler: Trying to schedule on node: slave2, available: <memory:4096, vCores:1>
2019-06-07 07:43:40,111 DEBUG org.apache.hadoop.yarn.server.resourcemanager.scheduler.capacity.CapacityScheduler: Trying to schedule on node: slave2, available: <memory:4096, vCores:1>
2019-06-07 07:43:40,111 DEBUG org.apache.hadoop.yarn.server.resourcemanager.scheduler.capacity.ParentQueue: Skip this queue=root, because it doesn't need more resource, schedulingMode=RESPECT_PARTITION_EXCLUSIVITY node-partition=
2019-06-07 07:43:40,111 DEBUG org.apache.hadoop.yarn.server.resourcemanager.scheduler.capacity.ParentQueue: Skip this queue=root, because it doesn't need more resource, schedulingMode=RESPECT_PARTITION_EXCLUSIVITY node-partition=
2019-06-07 07:43:41,103 DEBUG org.apache.hadoop.yarn.server.resourcemanager.rmnode.RMNodeImpl: Processing slave1:35126 of type STATUS_UPDATE
2019-06-07 07:43:41,103 DEBUG org.apache.hadoop.yarn.server.resourcemanager.rmnode.RMNodeImpl: Processing slave1:35126 of type STATUS_UPDATE
2019-06-07 07:43:41,104 DEBUG org.apache.hadoop.yarn.server.resourcemanager.scheduler.capacity.CapacityScheduler: nodeUpdate: slave1:35126 clusterResources: <memory:8192, vCores:2>
2019-06-07 07:43:41,104 DEBUG org.apache.hadoop.yarn.server.resourcemanager.scheduler.capacity.CapacityScheduler: nodeUpdate: slave1:35126 clusterResources: <memory:8192, vCores:2>
2019-06-07 07:43:41,104 DEBUG org.apache.hadoop.yarn.server.resourcemanager.scheduler.capacity.CapacityScheduler: Node being looked for scheduling slave1:35126 availableResource: <memory:4096, vCores:1>
2019-06-07 07:43:41,104 DEBUG org.apache.hadoop.yarn.server.resourcemanager.scheduler.capacity.CapacityScheduler: Node being looked for scheduling slave1:35126 availableResource: <memory:4096, vCores:1>
2019-06-07 07:43:41,104 DEBUG org.apache.hadoop.yarn.server.resourcemanager.scheduler.capacity.CapacityScheduler: Trying to schedule on node: slave1, available: <memory:4096, vCores:1>
2019-06-07 07:43:41,104 DEBUG org.apache.hadoop.yarn.server.resourcemanager.scheduler.capacity.CapacityScheduler: Trying to schedule on node: slave1, available: <memory:4096, vCores:1>
2019-06-07 07:43:41,104 DEBUG org.apache.hadoop.yarn.server.resourcemanager.scheduler.capacity.ParentQueue: Skip this queue=root, because it doesn't need more resource, schedulingMode=RESPECT_PARTITION_EXCLUSIVITY node-partition=
2019-06-07 07:43:41,104 DEBUG org.apache.hadoop.yarn.server.resourcemanager.scheduler.capacity.ParentQueue: Skip this queue=root, because it doesn't need more resource, schedulingMode=RESPECT_PARTITION_EXCLUSIVITY node-partition=
2019-06-07 07:43:41,115 DEBUG org.apache.hadoop.yarn.server.resourcemanager.rmnode.RMNodeImpl: Processing slave2:33474 of type STATUS_UPDATE
2019-06-07 07:43:41,115 DEBUG org.apache.hadoop.yarn.server.resourcemanager.rmnode.RMNodeImpl: Processing slave2:33474 of type STATUS_UPDATE
2019-06-07 07:43:41,115 DEBUG org.apache.hadoop.yarn.server.resourcemanager.scheduler.capacity.CapacityScheduler: nodeUpdate: slave2:33474 clusterResources: <memory:8192, vCores:2>
2019-06-07 07:43:41,115 DEBUG org.apache.hadoop.yarn.server.resourcemanager.scheduler.capacity.CapacityScheduler: nodeUpdate: slave2:33474 clusterResources: <memory:8192, vCores:2>
2019-06-07 07:43:41,115 DEBUG org.apache.hadoop.yarn.server.resourcemanager.scheduler.capacity.CapacityScheduler: Node being looked for scheduling slave2:33474 availableResource: <memory:4096, vCores:1>
2019-06-07 07:43:41,115 DEBUG org.apache.hadoop.yarn.server.resourcemanager.scheduler.capacity.CapacityScheduler: Node being looked for scheduling slave2:33474 availableResource: <memory:4096, vCores:1>
2019-06-07 07:43:41,115 DEBUG org.apache.hadoop.yarn.server.resourcemanager.scheduler.capacity.CapacityScheduler: Trying to schedule on node: slave2, available: <memory:4096, vCores:1>
2019-06-07 07:43:41,115 DEBUG org.apache.hadoop.yarn.server.resourcemanager.scheduler.capacity.CapacityScheduler: Trying to schedule on node: slave2, available: <memory:4096, vCores:1>
2019-06-07 07:43:41,115 DEBUG org.apache.hadoop.yarn.server.resourcemanager.scheduler.capacity.ParentQueue: Skip this queue=root, because it doesn't need more resource, schedulingMode=RESPECT_PARTITION_EXCLUSIVITY node-partition=
2019-06-07 07:43:41,115 DEBUG org.apache.hadoop.yarn.server.resourcemanager.scheduler.capacity.ParentQueue: Skip this queue=root, because it doesn't need more resource, schedulingMode=RESPECT_PARTITION_EXCLUSIVITY node-partition=
2019-06-07 07:43:42,113 DEBUG org.apache.hadoop.yarn.server.resourcemanager.rmnode.RMNodeImpl: Processing slave1:35126 of type STATUS_UPDATE
2019-06-07 07:43:42,113 DEBUG org.apache.hadoop.yarn.server.resourcemanager.rmnode.RMNodeImpl: Processing slave1:35126 of type STATUS_UPDATE
2019-06-07 07:43:42,113 DEBUG org.apache.hadoop.yarn.server.resourcemanager.scheduler.capacity.CapacityScheduler: nodeUpdate: slave1:35126 clusterResources: <memory:8192, vCores:2>
2019-06-07 07:43:42,113 DEBUG org.apache.hadoop.yarn.server.resourcemanager.scheduler.capacity.CapacityScheduler: nodeUpdate: slave1:35126 clusterResources: <memory:8192, vCores:2>
2019-06-07 07:43:42,113 DEBUG org.apache.hadoop.yarn.server.resourcemanager.scheduler.capacity.CapacityScheduler: Node being looked for scheduling slave1:35126 availableResource: <memory:4096, vCores:1>
2019-06-07 07:43:42,113 DEBUG org.apache.hadoop.yarn.server.resourcemanager.scheduler.capacity.CapacityScheduler: Node being looked for scheduling slave1:35126 availableResource: <memory:4096, vCores:1>
2019-06-07 07:43:42,114 DEBUG org.apache.hadoop.yarn.server.resourcemanager.scheduler.capacity.CapacityScheduler: Trying to schedule on node: slave1, available: <memory:4096, vCores:1>
2019-06-07 07:43:42,114 DEBUG org.apache.hadoop.yarn.server.resourcemanager.scheduler.capacity.CapacityScheduler: Trying to schedule on node: slave1, available: <memory:4096, vCores:1>
2019-06-07 07:43:42,114 DEBUG org.apache.hadoop.yarn.server.resourcemanager.scheduler.capacity.ParentQueue: Skip this queue=root, because it doesn't need more resource, schedulingMode=RESPECT_PARTITION_EXCLUSIVITY node-partition=
2019-06-07 07:43:42,114 DEBUG org.apache.hadoop.yarn.server.resourcemanager.scheduler.capacity.ParentQueue: Skip this queue=root, because it doesn't need more resource, schedulingMode=RESPECT_PARTITION_EXCLUSIVITY node-partition=
2019-06-07 07:43:42,118 DEBUG org.apache.hadoop.yarn.server.resourcemanager.rmnode.RMNodeImpl: Processing slave2:33474 of type STATUS_UPDATE
2019-06-07 07:43:42,118 DEBUG org.apache.hadoop.yarn.server.resourcemanager.rmnode.RMNodeImpl: Processing slave2:33474 of type STATUS_UPDATE
2019-06-07 07:43:42,118 DEBUG org.apache.hadoop.yarn.server.resourcemanager.scheduler.capacity.CapacityScheduler: nodeUpdate: slave2:33474 clusterResources: <memory:8192, vCores:2>
2019-06-07 07:43:42,118 DEBUG org.apache.hadoop.yarn.server.resourcemanager.scheduler.capacity.CapacityScheduler: nodeUpdate: slave2:33474 clusterResources: <memory:8192, vCores:2>
2019-06-07 07:43:42,118 DEBUG org.apache.hadoop.yarn.server.resourcemanager.scheduler.capacity.CapacityScheduler: Node being looked for scheduling slave2:33474 availableResource: <memory:4096, vCores:1>
2019-06-07 07:43:42,118 DEBUG org.apache.hadoop.yarn.server.resourcemanager.scheduler.capacity.CapacityScheduler: Node being looked for scheduling slave2:33474 availableResource: <memory:4096, vCores:1>
2019-06-07 07:43:42,119 DEBUG org.apache.hadoop.yarn.server.resourcemanager.scheduler.capacity.CapacityScheduler: Trying to schedule on node: slave2, available: <memory:4096, vCores:1>
2019-06-07 07:43:42,119 DEBUG org.apache.hadoop.yarn.server.resourcemanager.scheduler.capacity.CapacityScheduler: Trying to schedule on node: slave2, available: <memory:4096, vCores:1>
2019-06-07 07:43:42,119 DEBUG org.apache.hadoop.yarn.server.resourcemanager.scheduler.capacity.ParentQueue: Skip this queue=root, because it doesn't need more resource, schedulingMode=RESPECT_PARTITION_EXCLUSIVITY node-partition=
2019-06-07 07:43:42,119 DEBUG org.apache.hadoop.yarn.server.resourcemanager.scheduler.capacity.ParentQueue: Skip this queue=root, because it doesn't need more resource, schedulingMode=RESPECT_PARTITION_EXCLUSIVITY node-partition=
2019-06-07 07:43:43,117 DEBUG org.apache.hadoop.yarn.server.resourcemanager.rmnode.RMNodeImpl: Processing slave1:35126 of type STATUS_UPDATE
2019-06-07 07:43:43,117 DEBUG org.apache.hadoop.yarn.server.resourcemanager.rmnode.RMNodeImpl: Processing slave1:35126 of type STATUS_UPDATE
2019-06-07 07:43:43,117 DEBUG org.apache.hadoop.yarn.server.resourcemanager.scheduler.capacity.CapacityScheduler: nodeUpdate: slave1:35126 clusterResources: <memory:8192, vCores:2>
2019-06-07 07:43:43,117 DEBUG org.apache.hadoop.yarn.server.resourcemanager.scheduler.capacity.CapacityScheduler: nodeUpdate: slave1:35126 clusterResources: <memory:8192, vCores:2>
2019-06-07 07:43:43,117 DEBUG org.apache.hadoop.yarn.server.resourcemanager.scheduler.capacity.CapacityScheduler: Node being looked for scheduling slave1:35126 availableResource: <memory:4096, vCores:1>
2019-06-07 07:43:43,117 DEBUG org.apache.hadoop.yarn.server.resourcemanager.scheduler.capacity.CapacityScheduler: Node being looked for scheduling slave1:35126 availableResource: <memory:4096, vCores:1>
2019-06-07 07:43:43,117 DEBUG org.apache.hadoop.yarn.server.resourcemanager.scheduler.capacity.CapacityScheduler: Trying to schedule on node: slave1, available: <memory:4096, vCores:1>
2019-06-07 07:43:43,117 DEBUG org.apache.hadoop.yarn.server.resourcemanager.scheduler.capacity.CapacityScheduler: Trying to schedule on node: slave1, available: <memory:4096, vCores:1>
2019-06-07 07:43:43,117 DEBUG org.apache.hadoop.yarn.server.resourcemanager.scheduler.capacity.ParentQueue: Skip this queue=root, because it doesn't need more resource, schedulingMode=RESPECT_PARTITION_EXCLUSIVITY node-partition=
2019-06-07 07:43:43,117 DEBUG org.apache.hadoop.yarn.server.resourcemanager.scheduler.capacity.ParentQueue: Skip this queue=root, because it doesn't need more resource, schedulingMode=RESPECT_PARTITION_EXCLUSIVITY node-partition=
2019-06-07 07:43:43,121 DEBUG org.apache.hadoop.yarn.server.resourcemanager.rmnode.RMNodeImpl: Processing slave2:33474 of type STATUS_UPDATE
2019-06-07 07:43:43,121 DEBUG org.apache.hadoop.yarn.server.resourcemanager.rmnode.RMNodeImpl: Processing slave2:33474 of type STATUS_UPDATE
2019-06-07 07:43:43,122 DEBUG org.apache.hadoop.yarn.server.resourcemanager.scheduler.capacity.CapacityScheduler: nodeUpdate: slave2:33474 clusterResources: <memory:8192, vCores:2>
2019-06-07 07:43:43,122 DEBUG org.apache.hadoop.yarn.server.resourcemanager.scheduler.capacity.CapacityScheduler: nodeUpdate: slave2:33474 clusterResources: <memory:8192, vCores:2>
2019-06-07 07:43:43,122 DEBUG org.apache.hadoop.yarn.server.resourcemanager.scheduler.capacity.CapacityScheduler: Node being looked for scheduling slave2:33474 availableResource: <memory:4096, vCores:1>
2019-06-07 07:43:43,122 DEBUG org.apache.hadoop.yarn.server.resourcemanager.scheduler.capacity.CapacityScheduler: Node being looked for scheduling slave2:33474 availableResource: <memory:4096, vCores:1>
2019-06-07 07:43:43,122 DEBUG org.apache.hadoop.yarn.server.resourcemanager.scheduler.capacity.CapacityScheduler: Trying to schedule on node: slave2, available: <memory:4096, vCores:1>
2019-06-07 07:43:43,122 DEBUG org.apache.hadoop.yarn.server.resourcemanager.scheduler.capacity.CapacityScheduler: Trying to schedule on node: slave2, available: <memory:4096, vCores:1>
2019-06-07 07:43:43,122 DEBUG org.apache.hadoop.yarn.server.resourcemanager.scheduler.capacity.ParentQueue: Skip this queue=root, because it doesn't need more resource, schedulingMode=RESPECT_PARTITION_EXCLUSIVITY node-partition=
2019-06-07 07:43:43,122 DEBUG org.apache.hadoop.yarn.server.resourcemanager.scheduler.capacity.ParentQueue: Skip this queue=root, because it doesn't need more resource, schedulingMode=RESPECT_PARTITION_EXCLUSIVITY node-partition=
2019-06-07 07:43:44,123 DEBUG org.apache.hadoop.yarn.server.resourcemanager.rmnode.RMNodeImpl: Processing slave1:35126 of type STATUS_UPDATE
2019-06-07 07:43:44,123 DEBUG org.apache.hadoop.yarn.server.resourcemanager.rmnode.RMNodeImpl: Processing slave1:35126 of type STATUS_UPDATE
2019-06-07 07:43:44,124 DEBUG org.apache.hadoop.yarn.server.resourcemanager.scheduler.capacity.CapacityScheduler: nodeUpdate: slave1:35126 clusterResources: <memory:8192, vCores:2>
2019-06-07 07:43:44,124 DEBUG org.apache.hadoop.yarn.server.resourcemanager.scheduler.capacity.CapacityScheduler: nodeUpdate: slave1:35126 clusterResources: <memory:8192, vCores:2>
2019-06-07 07:43:44,124 DEBUG org.apache.hadoop.yarn.server.resourcemanager.scheduler.capacity.CapacityScheduler: Node being looked for scheduling slave1:35126 availableResource: <memory:4096, vCores:1>
2019-06-07 07:43:44,124 DEBUG org.apache.hadoop.yarn.server.resourcemanager.scheduler.capacity.CapacityScheduler: Node being looked for scheduling slave1:35126 availableResource: <memory:4096, vCores:1>
2019-06-07 07:43:44,125 DEBUG org.apache.hadoop.yarn.server.resourcemanager.scheduler.capacity.CapacityScheduler: Trying to schedule on node: slave1, available: <memory:4096, vCores:1>
2019-06-07 07:43:44,125 DEBUG org.apache.hadoop.yarn.server.resourcemanager.scheduler.capacity.CapacityScheduler: Trying to schedule on node: slave1, available: <memory:4096, vCores:1>
2019-06-07 07:43:44,125 DEBUG org.apache.hadoop.yarn.server.resourcemanager.scheduler.capacity.ParentQueue: Skip this queue=root, because it doesn't need more resource, schedulingMode=RESPECT_PARTITION_EXCLUSIVITY node-partition=
2019-06-07 07:43:44,125 DEBUG org.apache.hadoop.yarn.server.resourcemanager.scheduler.capacity.ParentQueue: Skip this queue=root, because it doesn't need more resource, schedulingMode=RESPECT_PARTITION_EXCLUSIVITY node-partition=
2019-06-07 07:43:44,126 DEBUG org.apache.hadoop.yarn.server.resourcemanager.rmnode.RMNodeImpl: Processing slave2:33474 of type STATUS_UPDATE
2019-06-07 07:43:44,126 DEBUG org.apache.hadoop.yarn.server.resourcemanager.rmnode.RMNodeImpl: Processing slave2:33474 of type STATUS_UPDATE
2019-06-07 07:43:44,126 DEBUG org.apache.hadoop.yarn.server.resourcemanager.scheduler.capacity.CapacityScheduler: nodeUpdate: slave2:33474 clusterResources: <memory:8192, vCores:2>
2019-06-07 07:43:44,126 DEBUG org.apache.hadoop.yarn.server.resourcemanager.scheduler.capacity.CapacityScheduler: nodeUpdate: slave2:33474 clusterResources: <memory:8192, vCores:2>
2019-06-07 07:43:44,126 DEBUG org.apache.hadoop.yarn.server.resourcemanager.scheduler.capacity.CapacityScheduler: Node being looked for scheduling slave2:33474 availableResource: <memory:4096, vCores:1>
2019-06-07 07:43:44,126 DEBUG org.apache.hadoop.yarn.server.resourcemanager.scheduler.capacity.CapacityScheduler: Node being looked for scheduling slave2:33474 availableResource: <memory:4096, vCores:1>
2019-06-07 07:43:44,126 DEBUG org.apache.hadoop.yarn.server.resourcemanager.scheduler.capacity.CapacityScheduler: Trying to schedule on node: slave2, available: <memory:4096, vCores:1>
2019-06-07 07:43:44,126 DEBUG org.apache.hadoop.yarn.server.resourcemanager.scheduler.capacity.CapacityScheduler: Trying to schedule on node: slave2, available: <memory:4096, vCores:1>
2019-06-07 07:43:44,126 DEBUG org.apache.hadoop.yarn.server.resourcemanager.scheduler.capacity.ParentQueue: Skip this queue=root, because it doesn't need more resource, schedulingMode=RESPECT_PARTITION_EXCLUSIVITY node-partition=
2019-06-07 07:43:44,126 DEBUG org.apache.hadoop.yarn.server.resourcemanager.scheduler.capacity.ParentQueue: Skip this queue=root, because it doesn't need more resource, schedulingMode=RESPECT_PARTITION_EXCLUSIVITY node-partition=
2019-06-07 07:43:45,129 DEBUG org.apache.hadoop.yarn.server.resourcemanager.rmnode.RMNodeImpl: Processing slave1:35126 of type STATUS_UPDATE
2019-06-07 07:43:45,129 DEBUG org.apache.hadoop.yarn.server.resourcemanager.rmnode.RMNodeImpl: Processing slave1:35126 of type STATUS_UPDATE
2019-06-07 07:43:45,129 DEBUG org.apache.hadoop.yarn.server.resourcemanager.scheduler.capacity.CapacityScheduler: nodeUpdate: slave1:35126 clusterResources: <memory:8192, vCores:2>
2019-06-07 07:43:45,129 DEBUG org.apache.hadoop.yarn.server.resourcemanager.scheduler.capacity.CapacityScheduler: nodeUpdate: slave1:35126 clusterResources: <memory:8192, vCores:2>
2019-06-07 07:43:45,129 DEBUG org.apache.hadoop.yarn.server.resourcemanager.scheduler.capacity.CapacityScheduler: Node being looked for scheduling slave1:35126 availableResource: <memory:4096, vCores:1>
2019-06-07 07:43:45,129 DEBUG org.apache.hadoop.yarn.server.resourcemanager.scheduler.capacity.CapacityScheduler: Node being looked for scheduling slave1:35126 availableResource: <memory:4096, vCores:1>
2019-06-07 07:43:45,129 DEBUG org.apache.hadoop.yarn.server.resourcemanager.scheduler.capacity.CapacityScheduler: Trying to schedule on node: slave1, available: <memory:4096, vCores:1>
2019-06-07 07:43:45,129 DEBUG org.apache.hadoop.yarn.server.resourcemanager.scheduler.capacity.CapacityScheduler: Trying to schedule on node: slave1, available: <memory:4096, vCores:1>
2019-06-07 07:43:45,129 DEBUG org.apache.hadoop.yarn.server.resourcemanager.scheduler.capacity.ParentQueue: Skip this queue=root, because it doesn't need more resource, schedulingMode=RESPECT_PARTITION_EXCLUSIVITY node-partition=
2019-06-07 07:43:45,129 DEBUG org.apache.hadoop.yarn.server.resourcemanager.scheduler.capacity.ParentQueue: Skip this queue=root, because it doesn't need more resource, schedulingMode=RESPECT_PARTITION_EXCLUSIVITY node-partition=
2019-06-07 07:43:45,131 DEBUG org.apache.hadoop.yarn.server.resourcemanager.rmnode.RMNodeImpl: Processing slave2:33474 of type STATUS_UPDATE
2019-06-07 07:43:45,131 DEBUG org.apache.hadoop.yarn.server.resourcemanager.rmnode.RMNodeImpl: Processing slave2:33474 of type STATUS_UPDATE
2019-06-07 07:43:45,131 DEBUG org.apache.hadoop.yarn.server.resourcemanager.scheduler.capacity.CapacityScheduler: nodeUpdate: slave2:33474 clusterResources: <memory:8192, vCores:2>
2019-06-07 07:43:45,131 DEBUG org.apache.hadoop.yarn.server.resourcemanager.scheduler.capacity.CapacityScheduler: nodeUpdate: slave2:33474 clusterResources: <memory:8192, vCores:2>
2019-06-07 07:43:45,131 DEBUG org.apache.hadoop.yarn.server.resourcemanager.scheduler.capacity.CapacityScheduler: Node being looked for scheduling slave2:33474 availableResource: <memory:4096, vCores:1>
2019-06-07 07:43:45,131 DEBUG org.apache.hadoop.yarn.server.resourcemanager.scheduler.capacity.CapacityScheduler: Node being looked for scheduling slave2:33474 availableResource: <memory:4096, vCores:1>
2019-06-07 07:43:45,131 DEBUG org.apache.hadoop.yarn.server.resourcemanager.scheduler.capacity.CapacityScheduler: Trying to schedule on node: slave2, available: <memory:4096, vCores:1>
2019-06-07 07:43:45,131 DEBUG org.apache.hadoop.yarn.server.resourcemanager.scheduler.capacity.CapacityScheduler: Trying to schedule on node: slave2, available: <memory:4096, vCores:1>
2019-06-07 07:43:45,131 DEBUG org.apache.hadoop.yarn.server.resourcemanager.scheduler.capacity.ParentQueue: Skip this queue=root, because it doesn't need more resource, schedulingMode=RESPECT_PARTITION_EXCLUSIVITY node-partition=
2019-06-07 07:43:45,131 DEBUG org.apache.hadoop.yarn.server.resourcemanager.scheduler.capacity.ParentQueue: Skip this queue=root, because it doesn't need more resource, schedulingMode=RESPECT_PARTITION_EXCLUSIVITY node-partition=
2019-06-07 07:43:46,132 DEBUG org.apache.hadoop.yarn.server.resourcemanager.rmnode.RMNodeImpl: Processing slave1:35126 of type STATUS_UPDATE
2019-06-07 07:43:46,132 DEBUG org.apache.hadoop.yarn.server.resourcemanager.rmnode.RMNodeImpl: Processing slave1:35126 of type STATUS_UPDATE
2019-06-07 07:43:46,133 DEBUG org.apache.hadoop.yarn.server.resourcemanager.scheduler.capacity.CapacityScheduler: nodeUpdate: slave1:35126 clusterResources: <memory:8192, vCores:2>
2019-06-07 07:43:46,133 DEBUG org.apache.hadoop.yarn.server.resourcemanager.scheduler.capacity.CapacityScheduler: nodeUpdate: slave1:35126 clusterResources: <memory:8192, vCores:2>
2019-06-07 07:43:46,133 DEBUG org.apache.hadoop.yarn.server.resourcemanager.scheduler.capacity.CapacityScheduler: Node being looked for scheduling slave1:35126 availableResource: <memory:4096, vCores:1>
2019-06-07 07:43:46,133 DEBUG org.apache.hadoop.yarn.server.resourcemanager.scheduler.capacity.CapacityScheduler: Node being looked for scheduling slave1:35126 availableResource: <memory:4096, vCores:1>
2019-06-07 07:43:46,133 DEBUG org.apache.hadoop.yarn.server.resourcemanager.scheduler.capacity.CapacityScheduler: Trying to schedule on node: slave1, available: <memory:4096, vCores:1>
2019-06-07 07:43:46,133 DEBUG org.apache.hadoop.yarn.server.resourcemanager.scheduler.capacity.CapacityScheduler: Trying to schedule on node: slave1, available: <memory:4096, vCores:1>
2019-06-07 07:43:46,133 DEBUG org.apache.hadoop.yarn.server.resourcemanager.scheduler.capacity.ParentQueue: Skip this queue=root, because it doesn't need more resource, schedulingMode=RESPECT_PARTITION_EXCLUSIVITY node-partition=
2019-06-07 07:43:46,133 DEBUG org.apache.hadoop.yarn.server.resourcemanager.scheduler.capacity.ParentQueue: Skip this queue=root, because it doesn't need more resource, schedulingMode=RESPECT_PARTITION_EXCLUSIVITY node-partition=
2019-06-07 07:43:46,137 DEBUG org.apache.hadoop.yarn.server.resourcemanager.rmnode.RMNodeImpl: Processing slave2:33474 of type STATUS_UPDATE
2019-06-07 07:43:46,137 DEBUG org.apache.hadoop.yarn.server.resourcemanager.rmnode.RMNodeImpl: Processing slave2:33474 of type STATUS_UPDATE
2019-06-07 07:43:46,138 DEBUG org.apache.hadoop.yarn.server.resourcemanager.scheduler.capacity.CapacityScheduler: nodeUpdate: slave2:33474 clusterResources: <memory:8192, vCores:2>
2019-06-07 07:43:46,138 DEBUG org.apache.hadoop.yarn.server.resourcemanager.scheduler.capacity.CapacityScheduler: nodeUpdate: slave2:33474 clusterResources: <memory:8192, vCores:2>
2019-06-07 07:43:46,138 DEBUG org.apache.hadoop.yarn.server.resourcemanager.scheduler.capacity.CapacityScheduler: Node being looked for scheduling slave2:33474 availableResource: <memory:4096, vCores:1>
2019-06-07 07:43:46,138 DEBUG org.apache.hadoop.yarn.server.resourcemanager.scheduler.capacity.CapacityScheduler: Node being looked for scheduling slave2:33474 availableResource: <memory:4096, vCores:1>
2019-06-07 07:43:46,138 DEBUG org.apache.hadoop.yarn.server.resourcemanager.scheduler.capacity.CapacityScheduler: Trying to schedule on node: slave2, available: <memory:4096, vCores:1>
2019-06-07 07:43:46,138 DEBUG org.apache.hadoop.yarn.server.resourcemanager.scheduler.capacity.CapacityScheduler: Trying to schedule on node: slave2, available: <memory:4096, vCores:1>
2019-06-07 07:43:46,138 DEBUG org.apache.hadoop.yarn.server.resourcemanager.scheduler.capacity.ParentQueue: Skip this queue=root, because it doesn't need more resource, schedulingMode=RESPECT_PARTITION_EXCLUSIVITY node-partition=
2019-06-07 07:43:46,138 DEBUG org.apache.hadoop.yarn.server.resourcemanager.scheduler.capacity.ParentQueue: Skip this queue=root, because it doesn't need more resource, schedulingMode=RESPECT_PARTITION_EXCLUSIVITY node-partition=
2019-06-07 07:43:47,141 DEBUG org.apache.hadoop.yarn.server.resourcemanager.rmnode.RMNodeImpl: Processing slave1:35126 of type STATUS_UPDATE
2019-06-07 07:43:47,141 DEBUG org.apache.hadoop.yarn.server.resourcemanager.rmnode.RMNodeImpl: Processing slave1:35126 of type STATUS_UPDATE
2019-06-07 07:43:47,141 DEBUG org.apache.hadoop.yarn.server.resourcemanager.rmnode.RMNodeImpl: Processing slave2:33474 of type STATUS_UPDATE
2019-06-07 07:43:47,141 DEBUG org.apache.hadoop.yarn.server.resourcemanager.rmnode.RMNodeImpl: Processing slave2:33474 of type STATUS_UPDATE
2019-06-07 07:43:47,141 DEBUG org.apache.hadoop.yarn.server.resourcemanager.scheduler.capacity.CapacityScheduler: nodeUpdate: slave1:35126 clusterResources: <memory:8192, vCores:2>
2019-06-07 07:43:47,141 DEBUG org.apache.hadoop.yarn.server.resourcemanager.scheduler.capacity.CapacityScheduler: nodeUpdate: slave1:35126 clusterResources: <memory:8192, vCores:2>
2019-06-07 07:43:47,141 DEBUG org.apache.hadoop.yarn.server.resourcemanager.scheduler.capacity.CapacityScheduler: Node being looked for scheduling slave1:35126 availableResource: <memory:4096, vCores:1>
2019-06-07 07:43:47,141 DEBUG org.apache.hadoop.yarn.server.resourcemanager.scheduler.capacity.CapacityScheduler: Node being looked for scheduling slave1:35126 availableResource: <memory:4096, vCores:1>
2019-06-07 07:43:47,141 DEBUG org.apache.hadoop.yarn.server.resourcemanager.scheduler.capacity.CapacityScheduler: Trying to schedule on node: slave1, available: <memory:4096, vCores:1>
2019-06-07 07:43:47,141 DEBUG org.apache.hadoop.yarn.server.resourcemanager.scheduler.capacity.CapacityScheduler: Trying to schedule on node: slave1, available: <memory:4096, vCores:1>
2019-06-07 07:43:47,141 DEBUG org.apache.hadoop.yarn.server.resourcemanager.scheduler.capacity.ParentQueue: Skip this queue=root, because it doesn't need more resource, schedulingMode=RESPECT_PARTITION_EXCLUSIVITY node-partition=
2019-06-07 07:43:47,141 DEBUG org.apache.hadoop.yarn.server.resourcemanager.scheduler.capacity.ParentQueue: Skip this queue=root, because it doesn't need more resource, schedulingMode=RESPECT_PARTITION_EXCLUSIVITY node-partition=
2019-06-07 07:43:47,141 DEBUG org.apache.hadoop.yarn.server.resourcemanager.scheduler.capacity.CapacityScheduler: nodeUpdate: slave2:33474 clusterResources: <memory:8192, vCores:2>
2019-06-07 07:43:47,141 DEBUG org.apache.hadoop.yarn.server.resourcemanager.scheduler.capacity.CapacityScheduler: nodeUpdate: slave2:33474 clusterResources: <memory:8192, vCores:2>
2019-06-07 07:43:47,141 DEBUG org.apache.hadoop.yarn.server.resourcemanager.scheduler.capacity.CapacityScheduler: Node being looked for scheduling slave2:33474 availableResource: <memory:4096, vCores:1>
2019-06-07 07:43:47,141 DEBUG org.apache.hadoop.yarn.server.resourcemanager.scheduler.capacity.CapacityScheduler: Node being looked for scheduling slave2:33474 availableResource: <memory:4096, vCores:1>
2019-06-07 07:43:47,141 DEBUG org.apache.hadoop.yarn.server.resourcemanager.scheduler.capacity.CapacityScheduler: Trying to schedule on node: slave2, available: <memory:4096, vCores:1>
2019-06-07 07:43:47,141 DEBUG org.apache.hadoop.yarn.server.resourcemanager.scheduler.capacity.CapacityScheduler: Trying to schedule on node: slave2, available: <memory:4096, vCores:1>
2019-06-07 07:43:47,141 DEBUG org.apache.hadoop.yarn.server.resourcemanager.scheduler.capacity.ParentQueue: Skip this queue=root, because it doesn't need more resource, schedulingMode=RESPECT_PARTITION_EXCLUSIVITY node-partition=
2019-06-07 07:43:47,141 DEBUG org.apache.hadoop.yarn.server.resourcemanager.scheduler.capacity.ParentQueue: Skip this queue=root, because it doesn't need more resource, schedulingMode=RESPECT_PARTITION_EXCLUSIVITY node-partition=
2019-06-07 07:43:48,145 DEBUG org.apache.hadoop.yarn.server.resourcemanager.rmnode.RMNodeImpl: Processing slave2:33474 of type STATUS_UPDATE
2019-06-07 07:43:48,145 DEBUG org.apache.hadoop.yarn.server.resourcemanager.rmnode.RMNodeImpl: Processing slave2:33474 of type STATUS_UPDATE
2019-06-07 07:43:48,145 DEBUG org.apache.hadoop.yarn.server.resourcemanager.scheduler.capacity.CapacityScheduler: nodeUpdate: slave2:33474 clusterResources: <memory:8192, vCores:2>
2019-06-07 07:43:48,145 DEBUG org.apache.hadoop.yarn.server.resourcemanager.scheduler.capacity.CapacityScheduler: nodeUpdate: slave2:33474 clusterResources: <memory:8192, vCores:2>
2019-06-07 07:43:48,145 DEBUG org.apache.hadoop.yarn.server.resourcemanager.scheduler.capacity.CapacityScheduler: Node being looked for scheduling slave2:33474 availableResource: <memory:4096, vCores:1>
2019-06-07 07:43:48,145 DEBUG org.apache.hadoop.yarn.server.resourcemanager.scheduler.capacity.CapacityScheduler: Node being looked for scheduling slave2:33474 availableResource: <memory:4096, vCores:1>
2019-06-07 07:43:48,145 DEBUG org.apache.hadoop.yarn.server.resourcemanager.scheduler.capacity.CapacityScheduler: Trying to schedule on node: slave2, available: <memory:4096, vCores:1>
2019-06-07 07:43:48,145 DEBUG org.apache.hadoop.yarn.server.resourcemanager.scheduler.capacity.CapacityScheduler: Trying to schedule on node: slave2, available: <memory:4096, vCores:1>
2019-06-07 07:43:48,145 DEBUG org.apache.hadoop.yarn.server.resourcemanager.scheduler.capacity.ParentQueue: Skip this queue=root, because it doesn't need more resource, schedulingMode=RESPECT_PARTITION_EXCLUSIVITY node-partition=
2019-06-07 07:43:48,145 DEBUG org.apache.hadoop.yarn.server.resourcemanager.scheduler.capacity.ParentQueue: Skip this queue=root, because it doesn't need more resource, schedulingMode=RESPECT_PARTITION_EXCLUSIVITY node-partition=
2019-06-07 07:43:48,145 DEBUG org.apache.hadoop.yarn.server.resourcemanager.rmnode.RMNodeImpl: Processing slave1:35126 of type STATUS_UPDATE
2019-06-07 07:43:48,145 DEBUG org.apache.hadoop.yarn.server.resourcemanager.rmnode.RMNodeImpl: Processing slave1:35126 of type STATUS_UPDATE
2019-06-07 07:43:48,146 DEBUG org.apache.hadoop.yarn.server.resourcemanager.scheduler.capacity.CapacityScheduler: nodeUpdate: slave1:35126 clusterResources: <memory:8192, vCores:2>
2019-06-07 07:43:48,146 DEBUG org.apache.hadoop.yarn.server.resourcemanager.scheduler.capacity.CapacityScheduler: nodeUpdate: slave1:35126 clusterResources: <memory:8192, vCores:2>
2019-06-07 07:43:48,146 DEBUG org.apache.hadoop.yarn.server.resourcemanager.scheduler.capacity.CapacityScheduler: Node being looked for scheduling slave1:35126 availableResource: <memory:4096, vCores:1>
2019-06-07 07:43:48,146 DEBUG org.apache.hadoop.yarn.server.resourcemanager.scheduler.capacity.CapacityScheduler: Node being looked for scheduling slave1:35126 availableResource: <memory:4096, vCores:1>
2019-06-07 07:43:48,146 DEBUG org.apache.hadoop.yarn.server.resourcemanager.scheduler.capacity.CapacityScheduler: Trying to schedule on node: slave1, available: <memory:4096, vCores:1>
2019-06-07 07:43:48,146 DEBUG org.apache.hadoop.yarn.server.resourcemanager.scheduler.capacity.CapacityScheduler: Trying to schedule on node: slave1, available: <memory:4096, vCores:1>
2019-06-07 07:43:48,146 DEBUG org.apache.hadoop.yarn.server.resourcemanager.scheduler.capacity.ParentQueue: Skip this queue=root, because it doesn't need more resource, schedulingMode=RESPECT_PARTITION_EXCLUSIVITY node-partition=
2019-06-07 07:43:48,146 DEBUG org.apache.hadoop.yarn.server.resourcemanager.scheduler.capacity.ParentQueue: Skip this queue=root, because it doesn't need more resource, schedulingMode=RESPECT_PARTITION_EXCLUSIVITY node-partition=
2019-06-07 07:43:49,149 DEBUG org.apache.hadoop.yarn.server.resourcemanager.rmnode.RMNodeImpl: Processing slave1:35126 of type STATUS_UPDATE
2019-06-07 07:43:49,149 DEBUG org.apache.hadoop.yarn.server.resourcemanager.rmnode.RMNodeImpl: Processing slave1:35126 of type STATUS_UPDATE
2019-06-07 07:43:49,149 DEBUG org.apache.hadoop.yarn.server.resourcemanager.scheduler.capacity.CapacityScheduler: nodeUpdate: slave1:35126 clusterResources: <memory:8192, vCores:2>
2019-06-07 07:43:49,149 DEBUG org.apache.hadoop.yarn.server.resourcemanager.scheduler.capacity.CapacityScheduler: nodeUpdate: slave1:35126 clusterResources: <memory:8192, vCores:2>
2019-06-07 07:43:49,149 DEBUG org.apache.hadoop.yarn.server.resourcemanager.scheduler.capacity.CapacityScheduler: Node being looked for scheduling slave1:35126 availableResource: <memory:4096, vCores:1>
2019-06-07 07:43:49,149 DEBUG org.apache.hadoop.yarn.server.resourcemanager.scheduler.capacity.CapacityScheduler: Node being looked for scheduling slave1:35126 availableResource: <memory:4096, vCores:1>
2019-06-07 07:43:49,149 DEBUG org.apache.hadoop.yarn.server.resourcemanager.scheduler.capacity.CapacityScheduler: Trying to schedule on node: slave1, available: <memory:4096, vCores:1>
2019-06-07 07:43:49,149 DEBUG org.apache.hadoop.yarn.server.resourcemanager.scheduler.capacity.CapacityScheduler: Trying to schedule on node: slave1, available: <memory:4096, vCores:1>
2019-06-07 07:43:49,149 DEBUG org.apache.hadoop.yarn.server.resourcemanager.scheduler.capacity.ParentQueue: Skip this queue=root, because it doesn't need more resource, schedulingMode=RESPECT_PARTITION_EXCLUSIVITY node-partition=
2019-06-07 07:43:49,149 DEBUG org.apache.hadoop.yarn.server.resourcemanager.scheduler.capacity.ParentQueue: Skip this queue=root, because it doesn't need more resource, schedulingMode=RESPECT_PARTITION_EXCLUSIVITY node-partition=
2019-06-07 07:43:49,152 DEBUG org.apache.hadoop.yarn.server.resourcemanager.rmnode.RMNodeImpl: Processing slave2:33474 of type STATUS_UPDATE
2019-06-07 07:43:49,152 DEBUG org.apache.hadoop.yarn.server.resourcemanager.rmnode.RMNodeImpl: Processing slave2:33474 of type STATUS_UPDATE
2019-06-07 07:43:49,153 DEBUG org.apache.hadoop.yarn.server.resourcemanager.scheduler.capacity.CapacityScheduler: nodeUpdate: slave2:33474 clusterResources: <memory:8192, vCores:2>
2019-06-07 07:43:49,153 DEBUG org.apache.hadoop.yarn.server.resourcemanager.scheduler.capacity.CapacityScheduler: nodeUpdate: slave2:33474 clusterResources: <memory:8192, vCores:2>
2019-06-07 07:43:49,153 DEBUG org.apache.hadoop.yarn.server.resourcemanager.scheduler.capacity.CapacityScheduler: Node being looked for scheduling slave2:33474 availableResource: <memory:4096, vCores:1>
2019-06-07 07:43:49,153 DEBUG org.apache.hadoop.yarn.server.resourcemanager.scheduler.capacity.CapacityScheduler: Node being looked for scheduling slave2:33474 availableResource: <memory:4096, vCores:1>
2019-06-07 07:43:49,153 DEBUG org.apache.hadoop.yarn.server.resourcemanager.scheduler.capacity.CapacityScheduler: Trying to schedule on node: slave2, available: <memory:4096, vCores:1>
2019-06-07 07:43:49,153 DEBUG org.apache.hadoop.yarn.server.resourcemanager.scheduler.capacity.CapacityScheduler: Trying to schedule on node: slave2, available: <memory:4096, vCores:1>
2019-06-07 07:43:49,153 DEBUG org.apache.hadoop.yarn.server.resourcemanager.scheduler.capacity.ParentQueue: Skip this queue=root, because it doesn't need more resource, schedulingMode=RESPECT_PARTITION_EXCLUSIVITY node-partition=
2019-06-07 07:43:49,153 DEBUG org.apache.hadoop.yarn.server.resourcemanager.scheduler.capacity.ParentQueue: Skip this queue=root, because it doesn't need more resource, schedulingMode=RESPECT_PARTITION_EXCLUSIVITY node-partition=
2019-06-07 07:43:50,155 DEBUG org.apache.hadoop.yarn.server.resourcemanager.rmnode.RMNodeImpl: Processing slave2:33474 of type STATUS_UPDATE
2019-06-07 07:43:50,155 DEBUG org.apache.hadoop.yarn.server.resourcemanager.rmnode.RMNodeImpl: Processing slave2:33474 of type STATUS_UPDATE
2019-06-07 07:43:50,155 DEBUG org.apache.hadoop.yarn.server.resourcemanager.scheduler.capacity.CapacityScheduler: nodeUpdate: slave2:33474 clusterResources: <memory:8192, vCores:2>
2019-06-07 07:43:50,155 DEBUG org.apache.hadoop.yarn.server.resourcemanager.scheduler.capacity.CapacityScheduler: nodeUpdate: slave2:33474 clusterResources: <memory:8192, vCores:2>
2019-06-07 07:43:50,155 DEBUG org.apache.hadoop.yarn.server.resourcemanager.scheduler.capacity.CapacityScheduler: Node being looked for scheduling slave2:33474 availableResource: <memory:4096, vCores:1>
2019-06-07 07:43:50,155 DEBUG org.apache.hadoop.yarn.server.resourcemanager.scheduler.capacity.CapacityScheduler: Node being looked for scheduling slave2:33474 availableResource: <memory:4096, vCores:1>
2019-06-07 07:43:50,155 DEBUG org.apache.hadoop.yarn.server.resourcemanager.scheduler.capacity.CapacityScheduler: Trying to schedule on node: slave2, available: <memory:4096, vCores:1>
2019-06-07 07:43:50,155 DEBUG org.apache.hadoop.yarn.server.resourcemanager.scheduler.capacity.CapacityScheduler: Trying to schedule on node: slave2, available: <memory:4096, vCores:1>
2019-06-07 07:43:50,155 DEBUG org.apache.hadoop.yarn.server.resourcemanager.scheduler.capacity.ParentQueue: Skip this queue=root, because it doesn't need more resource, schedulingMode=RESPECT_PARTITION_EXCLUSIVITY node-partition=
2019-06-07 07:43:50,155 DEBUG org.apache.hadoop.yarn.server.resourcemanager.scheduler.capacity.ParentQueue: Skip this queue=root, because it doesn't need more resource, schedulingMode=RESPECT_PARTITION_EXCLUSIVITY node-partition=
2019-06-07 07:43:50,156 DEBUG org.apache.hadoop.yarn.server.resourcemanager.rmnode.RMNodeImpl: Processing slave1:35126 of type STATUS_UPDATE
2019-06-07 07:43:50,156 DEBUG org.apache.hadoop.yarn.server.resourcemanager.rmnode.RMNodeImpl: Processing slave1:35126 of type STATUS_UPDATE
2019-06-07 07:43:50,156 DEBUG org.apache.hadoop.yarn.server.resourcemanager.scheduler.capacity.CapacityScheduler: nodeUpdate: slave1:35126 clusterResources: <memory:8192, vCores:2>
2019-06-07 07:43:50,156 DEBUG org.apache.hadoop.yarn.server.resourcemanager.scheduler.capacity.CapacityScheduler: nodeUpdate: slave1:35126 clusterResources: <memory:8192, vCores:2>
2019-06-07 07:43:50,156 DEBUG org.apache.hadoop.yarn.server.resourcemanager.scheduler.capacity.CapacityScheduler: Node being looked for scheduling slave1:35126 availableResource: <memory:4096, vCores:1>
2019-06-07 07:43:50,156 DEBUG org.apache.hadoop.yarn.server.resourcemanager.scheduler.capacity.CapacityScheduler: Node being looked for scheduling slave1:35126 availableResource: <memory:4096, vCores:1>
2019-06-07 07:43:50,156 DEBUG org.apache.hadoop.yarn.server.resourcemanager.scheduler.capacity.CapacityScheduler: Trying to schedule on node: slave1, available: <memory:4096, vCores:1>
2019-06-07 07:43:50,156 DEBUG org.apache.hadoop.yarn.server.resourcemanager.scheduler.capacity.CapacityScheduler: Trying to schedule on node: slave1, available: <memory:4096, vCores:1>
2019-06-07 07:43:50,156 DEBUG org.apache.hadoop.yarn.server.resourcemanager.scheduler.capacity.ParentQueue: Skip this queue=root, because it doesn't need more resource, schedulingMode=RESPECT_PARTITION_EXCLUSIVITY node-partition=
2019-06-07 07:43:50,156 DEBUG org.apache.hadoop.yarn.server.resourcemanager.scheduler.capacity.ParentQueue: Skip this queue=root, because it doesn't need more resource, schedulingMode=RESPECT_PARTITION_EXCLUSIVITY node-partition=
2019-06-07 07:43:51,160 DEBUG org.apache.hadoop.yarn.server.resourcemanager.rmnode.RMNodeImpl: Processing slave1:35126 of type STATUS_UPDATE
2019-06-07 07:43:51,160 DEBUG org.apache.hadoop.yarn.server.resourcemanager.rmnode.RMNodeImpl: Processing slave1:35126 of type STATUS_UPDATE
2019-06-07 07:43:51,160 DEBUG org.apache.hadoop.yarn.server.resourcemanager.rmnode.RMNodeImpl: Processing slave2:33474 of type STATUS_UPDATE
2019-06-07 07:43:51,160 DEBUG org.apache.hadoop.yarn.server.resourcemanager.rmnode.RMNodeImpl: Processing slave2:33474 of type STATUS_UPDATE
2019-06-07 07:43:51,160 DEBUG org.apache.hadoop.yarn.server.resourcemanager.scheduler.capacity.CapacityScheduler: nodeUpdate: slave1:35126 clusterResources: <memory:8192, vCores:2>
2019-06-07 07:43:51,160 DEBUG org.apache.hadoop.yarn.server.resourcemanager.scheduler.capacity.CapacityScheduler: nodeUpdate: slave1:35126 clusterResources: <memory:8192, vCores:2>
2019-06-07 07:43:51,161 DEBUG org.apache.hadoop.yarn.server.resourcemanager.scheduler.capacity.CapacityScheduler: Node being looked for scheduling slave1:35126 availableResource: <memory:4096, vCores:1>
2019-06-07 07:43:51,161 DEBUG org.apache.hadoop.yarn.server.resourcemanager.scheduler.capacity.CapacityScheduler: Node being looked for scheduling slave1:35126 availableResource: <memory:4096, vCores:1>
2019-06-07 07:43:51,161 DEBUG org.apache.hadoop.yarn.server.resourcemanager.scheduler.capacity.CapacityScheduler: Trying to schedule on node: slave1, available: <memory:4096, vCores:1>
2019-06-07 07:43:51,161 DEBUG org.apache.hadoop.yarn.server.resourcemanager.scheduler.capacity.CapacityScheduler: Trying to schedule on node: slave1, available: <memory:4096, vCores:1>
2019-06-07 07:43:51,161 DEBUG org.apache.hadoop.yarn.server.resourcemanager.scheduler.capacity.ParentQueue: Skip this queue=root, because it doesn't need more resource, schedulingMode=RESPECT_PARTITION_EXCLUSIVITY node-partition=
2019-06-07 07:43:51,161 DEBUG org.apache.hadoop.yarn.server.resourcemanager.scheduler.capacity.ParentQueue: Skip this queue=root, because it doesn't need more resource, schedulingMode=RESPECT_PARTITION_EXCLUSIVITY node-partition=
2019-06-07 07:43:51,161 DEBUG org.apache.hadoop.yarn.server.resourcemanager.scheduler.capacity.CapacityScheduler: nodeUpdate: slave2:33474 clusterResources: <memory:8192, vCores:2>
2019-06-07 07:43:51,161 DEBUG org.apache.hadoop.yarn.server.resourcemanager.scheduler.capacity.CapacityScheduler: nodeUpdate: slave2:33474 clusterResources: <memory:8192, vCores:2>
2019-06-07 07:43:51,161 DEBUG org.apache.hadoop.yarn.server.resourcemanager.scheduler.capacity.CapacityScheduler: Node being looked for scheduling slave2:33474 availableResource: <memory:4096, vCores:1>
2019-06-07 07:43:51,161 DEBUG org.apache.hadoop.yarn.server.resourcemanager.scheduler.capacity.CapacityScheduler: Node being looked for scheduling slave2:33474 availableResource: <memory:4096, vCores:1>
2019-06-07 07:43:51,161 DEBUG org.apache.hadoop.yarn.server.resourcemanager.scheduler.capacity.CapacityScheduler: Trying to schedule on node: slave2, available: <memory:4096, vCores:1>
2019-06-07 07:43:51,161 DEBUG org.apache.hadoop.yarn.server.resourcemanager.scheduler.capacity.CapacityScheduler: Trying to schedule on node: slave2, available: <memory:4096, vCores:1>
2019-06-07 07:43:51,161 DEBUG org.apache.hadoop.yarn.server.resourcemanager.scheduler.capacity.ParentQueue: Skip this queue=root, because it doesn't need more resource, schedulingMode=RESPECT_PARTITION_EXCLUSIVITY node-partition=
2019-06-07 07:43:51,161 DEBUG org.apache.hadoop.yarn.server.resourcemanager.scheduler.capacity.ParentQueue: Skip this queue=root, because it doesn't need more resource, schedulingMode=RESPECT_PARTITION_EXCLUSIVITY node-partition=
2019-06-07 07:43:52,165 DEBUG org.apache.hadoop.yarn.server.resourcemanager.rmnode.RMNodeImpl: Processing slave1:35126 of type STATUS_UPDATE
2019-06-07 07:43:52,165 DEBUG org.apache.hadoop.yarn.server.resourcemanager.rmnode.RMNodeImpl: Processing slave1:35126 of type STATUS_UPDATE
2019-06-07 07:43:52,165 DEBUG org.apache.hadoop.yarn.server.resourcemanager.scheduler.capacity.CapacityScheduler: nodeUpdate: slave1:35126 clusterResources: <memory:8192, vCores:2>
2019-06-07 07:43:52,165 DEBUG org.apache.hadoop.yarn.server.resourcemanager.scheduler.capacity.CapacityScheduler: nodeUpdate: slave1:35126 clusterResources: <memory:8192, vCores:2>
2019-06-07 07:43:52,166 DEBUG org.apache.hadoop.yarn.server.resourcemanager.scheduler.capacity.CapacityScheduler: Node being looked for scheduling slave1:35126 availableResource: <memory:4096, vCores:1>
2019-06-07 07:43:52,166 DEBUG org.apache.hadoop.yarn.server.resourcemanager.scheduler.capacity.CapacityScheduler: Node being looked for scheduling slave1:35126 availableResource: <memory:4096, vCores:1>
2019-06-07 07:43:52,166 DEBUG org.apache.hadoop.yarn.server.resourcemanager.scheduler.capacity.CapacityScheduler: Trying to schedule on node: slave1, available: <memory:4096, vCores:1>
2019-06-07 07:43:52,166 DEBUG org.apache.hadoop.yarn.server.resourcemanager.scheduler.capacity.CapacityScheduler: Trying to schedule on node: slave1, available: <memory:4096, vCores:1>
2019-06-07 07:43:52,166 DEBUG org.apache.hadoop.yarn.server.resourcemanager.scheduler.capacity.ParentQueue: Skip this queue=root, because it doesn't need more resource, schedulingMode=RESPECT_PARTITION_EXCLUSIVITY node-partition=
2019-06-07 07:43:52,166 DEBUG org.apache.hadoop.yarn.server.resourcemanager.scheduler.capacity.ParentQueue: Skip this queue=root, because it doesn't need more resource, schedulingMode=RESPECT_PARTITION_EXCLUSIVITY node-partition=
2019-06-07 07:43:52,168 DEBUG org.apache.hadoop.yarn.server.resourcemanager.rmnode.RMNodeImpl: Processing slave2:33474 of type STATUS_UPDATE
2019-06-07 07:43:52,168 DEBUG org.apache.hadoop.yarn.server.resourcemanager.rmnode.RMNodeImpl: Processing slave2:33474 of type STATUS_UPDATE
2019-06-07 07:43:52,168 DEBUG org.apache.hadoop.yarn.server.resourcemanager.scheduler.capacity.CapacityScheduler: nodeUpdate: slave2:33474 clusterResources: <memory:8192, vCores:2>
2019-06-07 07:43:52,168 DEBUG org.apache.hadoop.yarn.server.resourcemanager.scheduler.capacity.CapacityScheduler: nodeUpdate: slave2:33474 clusterResources: <memory:8192, vCores:2>
2019-06-07 07:43:52,168 DEBUG org.apache.hadoop.yarn.server.resourcemanager.scheduler.capacity.CapacityScheduler: Node being looked for scheduling slave2:33474 availableResource: <memory:4096, vCores:1>
2019-06-07 07:43:52,168 DEBUG org.apache.hadoop.yarn.server.resourcemanager.scheduler.capacity.CapacityScheduler: Node being looked for scheduling slave2:33474 availableResource: <memory:4096, vCores:1>
2019-06-07 07:43:52,168 DEBUG org.apache.hadoop.yarn.server.resourcemanager.scheduler.capacity.CapacityScheduler: Trying to schedule on node: slave2, available: <memory:4096, vCores:1>
2019-06-07 07:43:52,168 DEBUG org.apache.hadoop.yarn.server.resourcemanager.scheduler.capacity.CapacityScheduler: Trying to schedule on node: slave2, available: <memory:4096, vCores:1>
2019-06-07 07:43:52,168 DEBUG org.apache.hadoop.yarn.server.resourcemanager.scheduler.capacity.ParentQueue: Skip this queue=root, because it doesn't need more resource, schedulingMode=RESPECT_PARTITION_EXCLUSIVITY node-partition=
2019-06-07 07:43:52,168 DEBUG org.apache.hadoop.yarn.server.resourcemanager.scheduler.capacity.ParentQueue: Skip this queue=root, because it doesn't need more resource, schedulingMode=RESPECT_PARTITION_EXCLUSIVITY node-partition=
2019-06-07 07:43:53,171 DEBUG org.apache.hadoop.yarn.server.resourcemanager.rmnode.RMNodeImpl: Processing slave1:35126 of type STATUS_UPDATE
2019-06-07 07:43:53,171 DEBUG org.apache.hadoop.yarn.server.resourcemanager.rmnode.RMNodeImpl: Processing slave1:35126 of type STATUS_UPDATE
2019-06-07 07:43:53,171 DEBUG org.apache.hadoop.yarn.server.resourcemanager.scheduler.capacity.CapacityScheduler: nodeUpdate: slave1:35126 clusterResources: <memory:8192, vCores:2>
2019-06-07 07:43:53,171 DEBUG org.apache.hadoop.yarn.server.resourcemanager.scheduler.capacity.CapacityScheduler: nodeUpdate: slave1:35126 clusterResources: <memory:8192, vCores:2>
2019-06-07 07:43:53,171 DEBUG org.apache.hadoop.yarn.server.resourcemanager.scheduler.capacity.CapacityScheduler: Node being looked for scheduling slave1:35126 availableResource: <memory:4096, vCores:1>
2019-06-07 07:43:53,171 DEBUG org.apache.hadoop.yarn.server.resourcemanager.scheduler.capacity.CapacityScheduler: Node being looked for scheduling slave1:35126 availableResource: <memory:4096, vCores:1>
2019-06-07 07:43:53,171 DEBUG org.apache.hadoop.yarn.server.resourcemanager.scheduler.capacity.CapacityScheduler: Trying to schedule on node: slave1, available: <memory:4096, vCores:1>
2019-06-07 07:43:53,171 DEBUG org.apache.hadoop.yarn.server.resourcemanager.scheduler.capacity.CapacityScheduler: Trying to schedule on node: slave1, available: <memory:4096, vCores:1>
2019-06-07 07:43:53,172 DEBUG org.apache.hadoop.yarn.server.resourcemanager.scheduler.capacity.ParentQueue: Skip this queue=root, because it doesn't need more resource, schedulingMode=RESPECT_PARTITION_EXCLUSIVITY node-partition=
2019-06-07 07:43:53,172 DEBUG org.apache.hadoop.yarn.server.resourcemanager.scheduler.capacity.ParentQueue: Skip this queue=root, because it doesn't need more resource, schedulingMode=RESPECT_PARTITION_EXCLUSIVITY node-partition=
2019-06-07 07:43:53,173 DEBUG org.apache.hadoop.yarn.server.resourcemanager.rmnode.RMNodeImpl: Processing slave2:33474 of type STATUS_UPDATE
2019-06-07 07:43:53,173 DEBUG org.apache.hadoop.yarn.server.resourcemanager.rmnode.RMNodeImpl: Processing slave2:33474 of type STATUS_UPDATE
2019-06-07 07:43:53,173 DEBUG org.apache.hadoop.yarn.server.resourcemanager.scheduler.capacity.CapacityScheduler: nodeUpdate: slave2:33474 clusterResources: <memory:8192, vCores:2>
2019-06-07 07:43:53,173 DEBUG org.apache.hadoop.yarn.server.resourcemanager.scheduler.capacity.CapacityScheduler: nodeUpdate: slave2:33474 clusterResources: <memory:8192, vCores:2>
2019-06-07 07:43:53,173 DEBUG org.apache.hadoop.yarn.server.resourcemanager.scheduler.capacity.CapacityScheduler: Node being looked for scheduling slave2:33474 availableResource: <memory:4096, vCores:1>
2019-06-07 07:43:53,173 DEBUG org.apache.hadoop.yarn.server.resourcemanager.scheduler.capacity.CapacityScheduler: Node being looked for scheduling slave2:33474 availableResource: <memory:4096, vCores:1>
2019-06-07 07:43:53,173 DEBUG org.apache.hadoop.yarn.server.resourcemanager.scheduler.capacity.CapacityScheduler: Trying to schedule on node: slave2, available: <memory:4096, vCores:1>
2019-06-07 07:43:53,173 DEBUG org.apache.hadoop.yarn.server.resourcemanager.scheduler.capacity.CapacityScheduler: Trying to schedule on node: slave2, available: <memory:4096, vCores:1>
2019-06-07 07:43:53,173 DEBUG org.apache.hadoop.yarn.server.resourcemanager.scheduler.capacity.ParentQueue: Skip this queue=root, because it doesn't need more resource, schedulingMode=RESPECT_PARTITION_EXCLUSIVITY node-partition=
2019-06-07 07:43:53,173 DEBUG org.apache.hadoop.yarn.server.resourcemanager.scheduler.capacity.ParentQueue: Skip this queue=root, because it doesn't need more resource, schedulingMode=RESPECT_PARTITION_EXCLUSIVITY node-partition=
2019-06-07 07:43:54,173 DEBUG org.apache.hadoop.yarn.server.resourcemanager.rmnode.RMNodeImpl: Processing slave1:35126 of type STATUS_UPDATE
2019-06-07 07:43:54,173 DEBUG org.apache.hadoop.yarn.server.resourcemanager.rmnode.RMNodeImpl: Processing slave1:35126 of type STATUS_UPDATE
2019-06-07 07:43:54,173 DEBUG org.apache.hadoop.yarn.server.resourcemanager.scheduler.capacity.CapacityScheduler: nodeUpdate: slave1:35126 clusterResources: <memory:8192, vCores:2>
2019-06-07 07:43:54,173 DEBUG org.apache.hadoop.yarn.server.resourcemanager.scheduler.capacity.CapacityScheduler: nodeUpdate: slave1:35126 clusterResources: <memory:8192, vCores:2>
2019-06-07 07:43:54,173 DEBUG org.apache.hadoop.yarn.server.resourcemanager.scheduler.capacity.CapacityScheduler: Node being looked for scheduling slave1:35126 availableResource: <memory:4096, vCores:1>
2019-06-07 07:43:54,173 DEBUG org.apache.hadoop.yarn.server.resourcemanager.scheduler.capacity.CapacityScheduler: Node being looked for scheduling slave1:35126 availableResource: <memory:4096, vCores:1>
2019-06-07 07:43:54,174 DEBUG org.apache.hadoop.yarn.server.resourcemanager.scheduler.capacity.CapacityScheduler: Trying to schedule on node: slave1, available: <memory:4096, vCores:1>
2019-06-07 07:43:54,174 DEBUG org.apache.hadoop.yarn.server.resourcemanager.scheduler.capacity.CapacityScheduler: Trying to schedule on node: slave1, available: <memory:4096, vCores:1>
2019-06-07 07:43:54,174 DEBUG org.apache.hadoop.yarn.server.resourcemanager.scheduler.capacity.ParentQueue: Skip this queue=root, because it doesn't need more resource, schedulingMode=RESPECT_PARTITION_EXCLUSIVITY node-partition=
2019-06-07 07:43:54,174 DEBUG org.apache.hadoop.yarn.server.resourcemanager.scheduler.capacity.ParentQueue: Skip this queue=root, because it doesn't need more resource, schedulingMode=RESPECT_PARTITION_EXCLUSIVITY node-partition=
2019-06-07 07:43:54,177 DEBUG org.apache.hadoop.yarn.server.resourcemanager.rmnode.RMNodeImpl: Processing slave2:33474 of type STATUS_UPDATE
2019-06-07 07:43:54,177 DEBUG org.apache.hadoop.yarn.server.resourcemanager.rmnode.RMNodeImpl: Processing slave2:33474 of type STATUS_UPDATE
2019-06-07 07:43:54,177 DEBUG org.apache.hadoop.yarn.server.resourcemanager.scheduler.capacity.CapacityScheduler: nodeUpdate: slave2:33474 clusterResources: <memory:8192, vCores:2>
2019-06-07 07:43:54,177 DEBUG org.apache.hadoop.yarn.server.resourcemanager.scheduler.capacity.CapacityScheduler: nodeUpdate: slave2:33474 clusterResources: <memory:8192, vCores:2>
2019-06-07 07:43:54,177 DEBUG org.apache.hadoop.yarn.server.resourcemanager.scheduler.capacity.CapacityScheduler: Node being looked for scheduling slave2:33474 availableResource: <memory:4096, vCores:1>
2019-06-07 07:43:54,177 DEBUG org.apache.hadoop.yarn.server.resourcemanager.scheduler.capacity.CapacityScheduler: Node being looked for scheduling slave2:33474 availableResource: <memory:4096, vCores:1>
2019-06-07 07:43:54,177 DEBUG org.apache.hadoop.yarn.server.resourcemanager.scheduler.capacity.CapacityScheduler: Trying to schedule on node: slave2, available: <memory:4096, vCores:1>
2019-06-07 07:43:54,177 DEBUG org.apache.hadoop.yarn.server.resourcemanager.scheduler.capacity.CapacityScheduler: Trying to schedule on node: slave2, available: <memory:4096, vCores:1>
2019-06-07 07:43:54,177 DEBUG org.apache.hadoop.yarn.server.resourcemanager.scheduler.capacity.ParentQueue: Skip this queue=root, because it doesn't need more resource, schedulingMode=RESPECT_PARTITION_EXCLUSIVITY node-partition=
2019-06-07 07:43:54,177 DEBUG org.apache.hadoop.yarn.server.resourcemanager.scheduler.capacity.ParentQueue: Skip this queue=root, because it doesn't need more resource, schedulingMode=RESPECT_PARTITION_EXCLUSIVITY node-partition=
2019-06-07 07:43:55,184 DEBUG org.apache.hadoop.yarn.server.resourcemanager.rmnode.RMNodeImpl: Processing slave1:35126 of type STATUS_UPDATE
2019-06-07 07:43:55,184 DEBUG org.apache.hadoop.yarn.server.resourcemanager.rmnode.RMNodeImpl: Processing slave1:35126 of type STATUS_UPDATE
2019-06-07 07:43:55,184 DEBUG org.apache.hadoop.yarn.server.resourcemanager.scheduler.capacity.CapacityScheduler: nodeUpdate: slave1:35126 clusterResources: <memory:8192, vCores:2>
2019-06-07 07:43:55,184 DEBUG org.apache.hadoop.yarn.server.resourcemanager.scheduler.capacity.CapacityScheduler: nodeUpdate: slave1:35126 clusterResources: <memory:8192, vCores:2>
2019-06-07 07:43:55,184 DEBUG org.apache.hadoop.yarn.server.resourcemanager.scheduler.capacity.CapacityScheduler: Node being looked for scheduling slave1:35126 availableResource: <memory:4096, vCores:1>
2019-06-07 07:43:55,184 DEBUG org.apache.hadoop.yarn.server.resourcemanager.scheduler.capacity.CapacityScheduler: Node being looked for scheduling slave1:35126 availableResource: <memory:4096, vCores:1>
2019-06-07 07:43:55,184 DEBUG org.apache.hadoop.yarn.server.resourcemanager.scheduler.capacity.CapacityScheduler: Trying to schedule on node: slave1, available: <memory:4096, vCores:1>
2019-06-07 07:43:55,184 DEBUG org.apache.hadoop.yarn.server.resourcemanager.scheduler.capacity.CapacityScheduler: Trying to schedule on node: slave1, available: <memory:4096, vCores:1>
2019-06-07 07:43:55,184 DEBUG org.apache.hadoop.yarn.server.resourcemanager.scheduler.capacity.ParentQueue: Skip this queue=root, because it doesn't need more resource, schedulingMode=RESPECT_PARTITION_EXCLUSIVITY node-partition=
2019-06-07 07:43:55,184 DEBUG org.apache.hadoop.yarn.server.resourcemanager.scheduler.capacity.ParentQueue: Skip this queue=root, because it doesn't need more resource, schedulingMode=RESPECT_PARTITION_EXCLUSIVITY node-partition=
2019-06-07 07:43:55,186 DEBUG org.apache.hadoop.yarn.server.resourcemanager.rmnode.RMNodeImpl: Processing slave2:33474 of type STATUS_UPDATE
2019-06-07 07:43:55,186 DEBUG org.apache.hadoop.yarn.server.resourcemanager.rmnode.RMNodeImpl: Processing slave2:33474 of type STATUS_UPDATE
2019-06-07 07:43:55,187 DEBUG org.apache.hadoop.yarn.server.resourcemanager.scheduler.capacity.CapacityScheduler: nodeUpdate: slave2:33474 clusterResources: <memory:8192, vCores:2>
2019-06-07 07:43:55,187 DEBUG org.apache.hadoop.yarn.server.resourcemanager.scheduler.capacity.CapacityScheduler: nodeUpdate: slave2:33474 clusterResources: <memory:8192, vCores:2>
2019-06-07 07:43:55,187 DEBUG org.apache.hadoop.yarn.server.resourcemanager.scheduler.capacity.CapacityScheduler: Node being looked for scheduling slave2:33474 availableResource: <memory:4096, vCores:1>
2019-06-07 07:43:55,187 DEBUG org.apache.hadoop.yarn.server.resourcemanager.scheduler.capacity.CapacityScheduler: Node being looked for scheduling slave2:33474 availableResource: <memory:4096, vCores:1>
2019-06-07 07:43:55,187 DEBUG org.apache.hadoop.yarn.server.resourcemanager.scheduler.capacity.CapacityScheduler: Trying to schedule on node: slave2, available: <memory:4096, vCores:1>
2019-06-07 07:43:55,187 DEBUG org.apache.hadoop.yarn.server.resourcemanager.scheduler.capacity.CapacityScheduler: Trying to schedule on node: slave2, available: <memory:4096, vCores:1>
2019-06-07 07:43:55,187 DEBUG org.apache.hadoop.yarn.server.resourcemanager.scheduler.capacity.ParentQueue: Skip this queue=root, because it doesn't need more resource, schedulingMode=RESPECT_PARTITION_EXCLUSIVITY node-partition=
2019-06-07 07:43:55,187 DEBUG org.apache.hadoop.yarn.server.resourcemanager.scheduler.capacity.ParentQueue: Skip this queue=root, because it doesn't need more resource, schedulingMode=RESPECT_PARTITION_EXCLUSIVITY node-partition=
2019-06-07 07:43:56,190 DEBUG org.apache.hadoop.yarn.server.resourcemanager.rmnode.RMNodeImpl: Processing slave1:35126 of type STATUS_UPDATE
2019-06-07 07:43:56,190 DEBUG org.apache.hadoop.yarn.server.resourcemanager.rmnode.RMNodeImpl: Processing slave1:35126 of type STATUS_UPDATE
2019-06-07 07:43:56,191 DEBUG org.apache.hadoop.yarn.server.resourcemanager.rmnode.RMNodeImpl: Processing slave2:33474 of type STATUS_UPDATE
2019-06-07 07:43:56,191 DEBUG org.apache.hadoop.yarn.server.resourcemanager.rmnode.RMNodeImpl: Processing slave2:33474 of type STATUS_UPDATE
2019-06-07 07:43:56,192 DEBUG org.apache.hadoop.yarn.server.resourcemanager.scheduler.capacity.CapacityScheduler: nodeUpdate: slave1:35126 clusterResources: <memory:8192, vCores:2>
2019-06-07 07:43:56,192 DEBUG org.apache.hadoop.yarn.server.resourcemanager.scheduler.capacity.CapacityScheduler: nodeUpdate: slave1:35126 clusterResources: <memory:8192, vCores:2>
2019-06-07 07:43:56,192 DEBUG org.apache.hadoop.yarn.server.resourcemanager.scheduler.capacity.CapacityScheduler: Node being looked for scheduling slave1:35126 availableResource: <memory:4096, vCores:1>
2019-06-07 07:43:56,192 DEBUG org.apache.hadoop.yarn.server.resourcemanager.scheduler.capacity.CapacityScheduler: Node being looked for scheduling slave1:35126 availableResource: <memory:4096, vCores:1>
2019-06-07 07:43:56,192 DEBUG org.apache.hadoop.yarn.server.resourcemanager.scheduler.capacity.CapacityScheduler: Trying to schedule on node: slave1, available: <memory:4096, vCores:1>
2019-06-07 07:43:56,192 DEBUG org.apache.hadoop.yarn.server.resourcemanager.scheduler.capacity.CapacityScheduler: Trying to schedule on node: slave1, available: <memory:4096, vCores:1>
2019-06-07 07:43:56,192 DEBUG org.apache.hadoop.yarn.server.resourcemanager.scheduler.capacity.ParentQueue: Skip this queue=root, because it doesn't need more resource, schedulingMode=RESPECT_PARTITION_EXCLUSIVITY node-partition=
2019-06-07 07:43:56,192 DEBUG org.apache.hadoop.yarn.server.resourcemanager.scheduler.capacity.ParentQueue: Skip this queue=root, because it doesn't need more resource, schedulingMode=RESPECT_PARTITION_EXCLUSIVITY node-partition=
2019-06-07 07:43:56,192 DEBUG org.apache.hadoop.yarn.server.resourcemanager.scheduler.capacity.CapacityScheduler: nodeUpdate: slave2:33474 clusterResources: <memory:8192, vCores:2>
2019-06-07 07:43:56,192 DEBUG org.apache.hadoop.yarn.server.resourcemanager.scheduler.capacity.CapacityScheduler: nodeUpdate: slave2:33474 clusterResources: <memory:8192, vCores:2>
2019-06-07 07:43:56,192 DEBUG org.apache.hadoop.yarn.server.resourcemanager.scheduler.capacity.CapacityScheduler: Node being looked for scheduling slave2:33474 availableResource: <memory:4096, vCores:1>
2019-06-07 07:43:56,192 DEBUG org.apache.hadoop.yarn.server.resourcemanager.scheduler.capacity.CapacityScheduler: Node being looked for scheduling slave2:33474 availableResource: <memory:4096, vCores:1>
2019-06-07 07:43:56,192 DEBUG org.apache.hadoop.yarn.server.resourcemanager.scheduler.capacity.CapacityScheduler: Trying to schedule on node: slave2, available: <memory:4096, vCores:1>
2019-06-07 07:43:56,192 DEBUG org.apache.hadoop.yarn.server.resourcemanager.scheduler.capacity.CapacityScheduler: Trying to schedule on node: slave2, available: <memory:4096, vCores:1>
2019-06-07 07:43:56,192 DEBUG org.apache.hadoop.yarn.server.resourcemanager.scheduler.capacity.ParentQueue: Skip this queue=root, because it doesn't need more resource, schedulingMode=RESPECT_PARTITION_EXCLUSIVITY node-partition=
2019-06-07 07:43:56,192 DEBUG org.apache.hadoop.yarn.server.resourcemanager.scheduler.capacity.ParentQueue: Skip this queue=root, because it doesn't need more resource, schedulingMode=RESPECT_PARTITION_EXCLUSIVITY node-partition=
2019-06-07 07:43:57,196 DEBUG org.apache.hadoop.yarn.server.resourcemanager.rmnode.RMNodeImpl: Processing slave1:35126 of type STATUS_UPDATE
2019-06-07 07:43:57,196 DEBUG org.apache.hadoop.yarn.server.resourcemanager.rmnode.RMNodeImpl: Processing slave1:35126 of type STATUS_UPDATE
2019-06-07 07:43:57,196 DEBUG org.apache.hadoop.yarn.server.resourcemanager.rmnode.RMNodeImpl: Processing slave2:33474 of type STATUS_UPDATE
2019-06-07 07:43:57,196 DEBUG org.apache.hadoop.yarn.server.resourcemanager.rmnode.RMNodeImpl: Processing slave2:33474 of type STATUS_UPDATE
2019-06-07 07:43:57,197 DEBUG org.apache.hadoop.yarn.server.resourcemanager.scheduler.capacity.CapacityScheduler: nodeUpdate: slave1:35126 clusterResources: <memory:8192, vCores:2>
2019-06-07 07:43:57,197 DEBUG org.apache.hadoop.yarn.server.resourcemanager.scheduler.capacity.CapacityScheduler: nodeUpdate: slave1:35126 clusterResources: <memory:8192, vCores:2>
2019-06-07 07:43:57,197 DEBUG org.apache.hadoop.yarn.server.resourcemanager.scheduler.capacity.CapacityScheduler: Node being looked for scheduling slave1:35126 availableResource: <memory:4096, vCores:1>
2019-06-07 07:43:57,197 DEBUG org.apache.hadoop.yarn.server.resourcemanager.scheduler.capacity.CapacityScheduler: Node being looked for scheduling slave1:35126 availableResource: <memory:4096, vCores:1>
2019-06-07 07:43:57,197 DEBUG org.apache.hadoop.yarn.server.resourcemanager.scheduler.capacity.CapacityScheduler: Trying to schedule on node: slave1, available: <memory:4096, vCores:1>
2019-06-07 07:43:57,197 DEBUG org.apache.hadoop.yarn.server.resourcemanager.scheduler.capacity.CapacityScheduler: Trying to schedule on node: slave1, available: <memory:4096, vCores:1>
2019-06-07 07:43:57,197 DEBUG org.apache.hadoop.yarn.server.resourcemanager.scheduler.capacity.ParentQueue: Skip this queue=root, because it doesn't need more resource, schedulingMode=RESPECT_PARTITION_EXCLUSIVITY node-partition=
2019-06-07 07:43:57,197 DEBUG org.apache.hadoop.yarn.server.resourcemanager.scheduler.capacity.ParentQueue: Skip this queue=root, because it doesn't need more resource, schedulingMode=RESPECT_PARTITION_EXCLUSIVITY node-partition=
2019-06-07 07:43:57,197 DEBUG org.apache.hadoop.yarn.server.resourcemanager.scheduler.capacity.CapacityScheduler: nodeUpdate: slave2:33474 clusterResources: <memory:8192, vCores:2>
2019-06-07 07:43:57,197 DEBUG org.apache.hadoop.yarn.server.resourcemanager.scheduler.capacity.CapacityScheduler: nodeUpdate: slave2:33474 clusterResources: <memory:8192, vCores:2>
2019-06-07 07:43:57,197 DEBUG org.apache.hadoop.yarn.server.resourcemanager.scheduler.capacity.CapacityScheduler: Node being looked for scheduling slave2:33474 availableResource: <memory:4096, vCores:1>
2019-06-07 07:43:57,197 DEBUG org.apache.hadoop.yarn.server.resourcemanager.scheduler.capacity.CapacityScheduler: Node being looked for scheduling slave2:33474 availableResource: <memory:4096, vCores:1>
2019-06-07 07:43:57,197 DEBUG org.apache.hadoop.yarn.server.resourcemanager.scheduler.capacity.CapacityScheduler: Trying to schedule on node: slave2, available: <memory:4096, vCores:1>
2019-06-07 07:43:57,197 DEBUG org.apache.hadoop.yarn.server.resourcemanager.scheduler.capacity.CapacityScheduler: Trying to schedule on node: slave2, available: <memory:4096, vCores:1>
2019-06-07 07:43:57,197 DEBUG org.apache.hadoop.yarn.server.resourcemanager.scheduler.capacity.ParentQueue: Skip this queue=root, because it doesn't need more resource, schedulingMode=RESPECT_PARTITION_EXCLUSIVITY node-partition=
2019-06-07 07:43:57,197 DEBUG org.apache.hadoop.yarn.server.resourcemanager.scheduler.capacity.ParentQueue: Skip this queue=root, because it doesn't need more resource, schedulingMode=RESPECT_PARTITION_EXCLUSIVITY node-partition=
2019-06-07 07:43:58,200 DEBUG org.apache.hadoop.yarn.server.resourcemanager.rmnode.RMNodeImpl: Processing slave1:35126 of type STATUS_UPDATE
2019-06-07 07:43:58,200 DEBUG org.apache.hadoop.yarn.server.resourcemanager.rmnode.RMNodeImpl: Processing slave1:35126 of type STATUS_UPDATE
2019-06-07 07:43:58,200 DEBUG org.apache.hadoop.yarn.server.resourcemanager.scheduler.capacity.CapacityScheduler: nodeUpdate: slave1:35126 clusterResources: <memory:8192, vCores:2>
2019-06-07 07:43:58,200 DEBUG org.apache.hadoop.yarn.server.resourcemanager.scheduler.capacity.CapacityScheduler: nodeUpdate: slave1:35126 clusterResources: <memory:8192, vCores:2>
2019-06-07 07:43:58,200 DEBUG org.apache.hadoop.yarn.server.resourcemanager.scheduler.capacity.CapacityScheduler: Node being looked for scheduling slave1:35126 availableResource: <memory:4096, vCores:1>
2019-06-07 07:43:58,200 DEBUG org.apache.hadoop.yarn.server.resourcemanager.scheduler.capacity.CapacityScheduler: Node being looked for scheduling slave1:35126 availableResource: <memory:4096, vCores:1>
2019-06-07 07:43:58,200 DEBUG org.apache.hadoop.yarn.server.resourcemanager.scheduler.capacity.CapacityScheduler: Trying to schedule on node: slave1, available: <memory:4096, vCores:1>
2019-06-07 07:43:58,200 DEBUG org.apache.hadoop.yarn.server.resourcemanager.scheduler.capacity.CapacityScheduler: Trying to schedule on node: slave1, available: <memory:4096, vCores:1>
2019-06-07 07:43:58,200 DEBUG org.apache.hadoop.yarn.server.resourcemanager.scheduler.capacity.ParentQueue: Skip this queue=root, because it doesn't need more resource, schedulingMode=RESPECT_PARTITION_EXCLUSIVITY node-partition=
2019-06-07 07:43:58,200 DEBUG org.apache.hadoop.yarn.server.resourcemanager.scheduler.capacity.ParentQueue: Skip this queue=root, because it doesn't need more resource, schedulingMode=RESPECT_PARTITION_EXCLUSIVITY node-partition=
2019-06-07 07:43:58,201 DEBUG org.apache.hadoop.yarn.server.resourcemanager.rmnode.RMNodeImpl: Processing slave2:33474 of type STATUS_UPDATE
2019-06-07 07:43:58,201 DEBUG org.apache.hadoop.yarn.server.resourcemanager.rmnode.RMNodeImpl: Processing slave2:33474 of type STATUS_UPDATE
2019-06-07 07:43:58,201 DEBUG org.apache.hadoop.yarn.server.resourcemanager.scheduler.capacity.CapacityScheduler: nodeUpdate: slave2:33474 clusterResources: <memory:8192, vCores:2>
2019-06-07 07:43:58,201 DEBUG org.apache.hadoop.yarn.server.resourcemanager.scheduler.capacity.CapacityScheduler: nodeUpdate: slave2:33474 clusterResources: <memory:8192, vCores:2>
2019-06-07 07:43:58,201 DEBUG org.apache.hadoop.yarn.server.resourcemanager.scheduler.capacity.CapacityScheduler: Node being looked for scheduling slave2:33474 availableResource: <memory:4096, vCores:1>
2019-06-07 07:43:58,201 DEBUG org.apache.hadoop.yarn.server.resourcemanager.scheduler.capacity.CapacityScheduler: Node being looked for scheduling slave2:33474 availableResource: <memory:4096, vCores:1>
2019-06-07 07:43:58,201 DEBUG org.apache.hadoop.yarn.server.resourcemanager.scheduler.capacity.CapacityScheduler: Trying to schedule on node: slave2, available: <memory:4096, vCores:1>
2019-06-07 07:43:58,201 DEBUG org.apache.hadoop.yarn.server.resourcemanager.scheduler.capacity.CapacityScheduler: Trying to schedule on node: slave2, available: <memory:4096, vCores:1>
2019-06-07 07:43:58,201 DEBUG org.apache.hadoop.yarn.server.resourcemanager.scheduler.capacity.ParentQueue: Skip this queue=root, because it doesn't need more resource, schedulingMode=RESPECT_PARTITION_EXCLUSIVITY node-partition=
2019-06-07 07:43:58,201 DEBUG org.apache.hadoop.yarn.server.resourcemanager.scheduler.capacity.ParentQueue: Skip this queue=root, because it doesn't need more resource, schedulingMode=RESPECT_PARTITION_EXCLUSIVITY node-partition=
2019-06-07 07:43:59,208 DEBUG org.apache.hadoop.yarn.server.resourcemanager.rmnode.RMNodeImpl: Processing slave2:33474 of type STATUS_UPDATE
2019-06-07 07:43:59,208 DEBUG org.apache.hadoop.yarn.server.resourcemanager.rmnode.RMNodeImpl: Processing slave2:33474 of type STATUS_UPDATE
2019-06-07 07:43:59,209 DEBUG org.apache.hadoop.yarn.server.resourcemanager.rmnode.RMNodeImpl: Processing slave1:35126 of type STATUS_UPDATE
2019-06-07 07:43:59,209 DEBUG org.apache.hadoop.yarn.server.resourcemanager.rmnode.RMNodeImpl: Processing slave1:35126 of type STATUS_UPDATE
2019-06-07 07:43:59,209 DEBUG org.apache.hadoop.yarn.server.resourcemanager.scheduler.capacity.CapacityScheduler: nodeUpdate: slave2:33474 clusterResources: <memory:8192, vCores:2>
2019-06-07 07:43:59,209 DEBUG org.apache.hadoop.yarn.server.resourcemanager.scheduler.capacity.CapacityScheduler: nodeUpdate: slave2:33474 clusterResources: <memory:8192, vCores:2>
2019-06-07 07:43:59,210 DEBUG org.apache.hadoop.yarn.server.resourcemanager.scheduler.capacity.CapacityScheduler: Node being looked for scheduling slave2:33474 availableResource: <memory:4096, vCores:1>
2019-06-07 07:43:59,210 DEBUG org.apache.hadoop.yarn.server.resourcemanager.scheduler.capacity.CapacityScheduler: Node being looked for scheduling slave2:33474 availableResource: <memory:4096, vCores:1>
2019-06-07 07:43:59,210 DEBUG org.apache.hadoop.yarn.server.resourcemanager.scheduler.capacity.CapacityScheduler: Trying to schedule on node: slave2, available: <memory:4096, vCores:1>
2019-06-07 07:43:59,210 DEBUG org.apache.hadoop.yarn.server.resourcemanager.scheduler.capacity.CapacityScheduler: Trying to schedule on node: slave2, available: <memory:4096, vCores:1>
2019-06-07 07:43:59,210 DEBUG org.apache.hadoop.yarn.server.resourcemanager.scheduler.capacity.ParentQueue: Skip this queue=root, because it doesn't need more resource, schedulingMode=RESPECT_PARTITION_EXCLUSIVITY node-partition=
2019-06-07 07:43:59,210 DEBUG org.apache.hadoop.yarn.server.resourcemanager.scheduler.capacity.ParentQueue: Skip this queue=root, because it doesn't need more resource, schedulingMode=RESPECT_PARTITION_EXCLUSIVITY node-partition=
2019-06-07 07:43:59,210 DEBUG org.apache.hadoop.yarn.server.resourcemanager.scheduler.capacity.CapacityScheduler: nodeUpdate: slave1:35126 clusterResources: <memory:8192, vCores:2>
2019-06-07 07:43:59,210 DEBUG org.apache.hadoop.yarn.server.resourcemanager.scheduler.capacity.CapacityScheduler: nodeUpdate: slave1:35126 clusterResources: <memory:8192, vCores:2>
2019-06-07 07:43:59,210 DEBUG org.apache.hadoop.yarn.server.resourcemanager.scheduler.capacity.CapacityScheduler: Node being looked for scheduling slave1:35126 availableResource: <memory:4096, vCores:1>
2019-06-07 07:43:59,210 DEBUG org.apache.hadoop.yarn.server.resourcemanager.scheduler.capacity.CapacityScheduler: Node being looked for scheduling slave1:35126 availableResource: <memory:4096, vCores:1>
2019-06-07 07:43:59,210 DEBUG org.apache.hadoop.yarn.server.resourcemanager.scheduler.capacity.CapacityScheduler: Trying to schedule on node: slave1, available: <memory:4096, vCores:1>
2019-06-07 07:43:59,210 DEBUG org.apache.hadoop.yarn.server.resourcemanager.scheduler.capacity.CapacityScheduler: Trying to schedule on node: slave1, available: <memory:4096, vCores:1>
2019-06-07 07:43:59,210 DEBUG org.apache.hadoop.yarn.server.resourcemanager.scheduler.capacity.ParentQueue: Skip this queue=root, because it doesn't need more resource, schedulingMode=RESPECT_PARTITION_EXCLUSIVITY node-partition=
2019-06-07 07:43:59,210 DEBUG org.apache.hadoop.yarn.server.resourcemanager.scheduler.capacity.ParentQueue: Skip this queue=root, because it doesn't need more resource, schedulingMode=RESPECT_PARTITION_EXCLUSIVITY node-partition=
2019-06-07 07:44:00,213 DEBUG org.apache.hadoop.yarn.server.resourcemanager.rmnode.RMNodeImpl: Processing slave1:35126 of type STATUS_UPDATE
2019-06-07 07:44:00,213 DEBUG org.apache.hadoop.yarn.server.resourcemanager.rmnode.RMNodeImpl: Processing slave1:35126 of type STATUS_UPDATE
2019-06-07 07:44:00,213 DEBUG org.apache.hadoop.yarn.server.resourcemanager.rmnode.RMNodeImpl: Processing slave2:33474 of type STATUS_UPDATE
2019-06-07 07:44:00,213 DEBUG org.apache.hadoop.yarn.server.resourcemanager.rmnode.RMNodeImpl: Processing slave2:33474 of type STATUS_UPDATE
2019-06-07 07:44:00,213 DEBUG org.apache.hadoop.yarn.server.resourcemanager.scheduler.capacity.CapacityScheduler: nodeUpdate: slave1:35126 clusterResources: <memory:8192, vCores:2>
2019-06-07 07:44:00,213 DEBUG org.apache.hadoop.yarn.server.resourcemanager.scheduler.capacity.CapacityScheduler: nodeUpdate: slave1:35126 clusterResources: <memory:8192, vCores:2>
2019-06-07 07:44:00,213 DEBUG org.apache.hadoop.yarn.server.resourcemanager.scheduler.capacity.CapacityScheduler: Node being looked for scheduling slave1:35126 availableResource: <memory:4096, vCores:1>
2019-06-07 07:44:00,213 DEBUG org.apache.hadoop.yarn.server.resourcemanager.scheduler.capacity.CapacityScheduler: Node being looked for scheduling slave1:35126 availableResource: <memory:4096, vCores:1>
2019-06-07 07:44:00,213 DEBUG org.apache.hadoop.yarn.server.resourcemanager.scheduler.capacity.CapacityScheduler: Trying to schedule on node: slave1, available: <memory:4096, vCores:1>
2019-06-07 07:44:00,213 DEBUG org.apache.hadoop.yarn.server.resourcemanager.scheduler.capacity.CapacityScheduler: Trying to schedule on node: slave1, available: <memory:4096, vCores:1>
2019-06-07 07:44:00,214 DEBUG org.apache.hadoop.yarn.server.resourcemanager.scheduler.capacity.ParentQueue: Skip this queue=root, because it doesn't need more resource, schedulingMode=RESPECT_PARTITION_EXCLUSIVITY node-partition=
2019-06-07 07:44:00,214 DEBUG org.apache.hadoop.yarn.server.resourcemanager.scheduler.capacity.ParentQueue: Skip this queue=root, because it doesn't need more resource, schedulingMode=RESPECT_PARTITION_EXCLUSIVITY node-partition=
2019-06-07 07:44:00,214 DEBUG org.apache.hadoop.yarn.server.resourcemanager.scheduler.capacity.CapacityScheduler: nodeUpdate: slave2:33474 clusterResources: <memory:8192, vCores:2>
2019-06-07 07:44:00,214 DEBUG org.apache.hadoop.yarn.server.resourcemanager.scheduler.capacity.CapacityScheduler: nodeUpdate: slave2:33474 clusterResources: <memory:8192, vCores:2>
2019-06-07 07:44:00,214 DEBUG org.apache.hadoop.yarn.server.resourcemanager.scheduler.capacity.CapacityScheduler: Node being looked for scheduling slave2:33474 availableResource: <memory:4096, vCores:1>
2019-06-07 07:44:00,214 DEBUG org.apache.hadoop.yarn.server.resourcemanager.scheduler.capacity.CapacityScheduler: Node being looked for scheduling slave2:33474 availableResource: <memory:4096, vCores:1>
2019-06-07 07:44:00,214 DEBUG org.apache.hadoop.yarn.server.resourcemanager.scheduler.capacity.CapacityScheduler: Trying to schedule on node: slave2, available: <memory:4096, vCores:1>
2019-06-07 07:44:00,214 DEBUG org.apache.hadoop.yarn.server.resourcemanager.scheduler.capacity.CapacityScheduler: Trying to schedule on node: slave2, available: <memory:4096, vCores:1>
2019-06-07 07:44:00,214 DEBUG org.apache.hadoop.yarn.server.resourcemanager.scheduler.capacity.ParentQueue: Skip this queue=root, because it doesn't need more resource, schedulingMode=RESPECT_PARTITION_EXCLUSIVITY node-partition=
2019-06-07 07:44:00,214 DEBUG org.apache.hadoop.yarn.server.resourcemanager.scheduler.capacity.ParentQueue: Skip this queue=root, because it doesn't need more resource, schedulingMode=RESPECT_PARTITION_EXCLUSIVITY node-partition=
2019-06-07 07:44:01,217 DEBUG org.apache.hadoop.yarn.server.resourcemanager.rmnode.RMNodeImpl: Processing slave2:33474 of type STATUS_UPDATE
2019-06-07 07:44:01,217 DEBUG org.apache.hadoop.yarn.server.resourcemanager.rmnode.RMNodeImpl: Processing slave2:33474 of type STATUS_UPDATE
2019-06-07 07:44:01,217 DEBUG org.apache.hadoop.yarn.server.resourcemanager.scheduler.capacity.CapacityScheduler: nodeUpdate: slave2:33474 clusterResources: <memory:8192, vCores:2>
2019-06-07 07:44:01,217 DEBUG org.apache.hadoop.yarn.server.resourcemanager.scheduler.capacity.CapacityScheduler: nodeUpdate: slave2:33474 clusterResources: <memory:8192, vCores:2>
2019-06-07 07:44:01,217 DEBUG org.apache.hadoop.yarn.server.resourcemanager.scheduler.capacity.CapacityScheduler: Node being looked for scheduling slave2:33474 availableResource: <memory:4096, vCores:1>
2019-06-07 07:44:01,217 DEBUG org.apache.hadoop.yarn.server.resourcemanager.scheduler.capacity.CapacityScheduler: Node being looked for scheduling slave2:33474 availableResource: <memory:4096, vCores:1>
2019-06-07 07:44:01,217 DEBUG org.apache.hadoop.yarn.server.resourcemanager.scheduler.capacity.CapacityScheduler: Trying to schedule on node: slave2, available: <memory:4096, vCores:1>
2019-06-07 07:44:01,217 DEBUG org.apache.hadoop.yarn.server.resourcemanager.scheduler.capacity.CapacityScheduler: Trying to schedule on node: slave2, available: <memory:4096, vCores:1>
2019-06-07 07:44:01,217 DEBUG org.apache.hadoop.yarn.server.resourcemanager.scheduler.capacity.ParentQueue: Skip this queue=root, because it doesn't need more resource, schedulingMode=RESPECT_PARTITION_EXCLUSIVITY node-partition=
2019-06-07 07:44:01,217 DEBUG org.apache.hadoop.yarn.server.resourcemanager.scheduler.capacity.ParentQueue: Skip this queue=root, because it doesn't need more resource, schedulingMode=RESPECT_PARTITION_EXCLUSIVITY node-partition=
2019-06-07 07:44:01,219 DEBUG org.apache.hadoop.yarn.server.resourcemanager.rmnode.RMNodeImpl: Processing slave1:35126 of type STATUS_UPDATE
2019-06-07 07:44:01,219 DEBUG org.apache.hadoop.yarn.server.resourcemanager.rmnode.RMNodeImpl: Processing slave1:35126 of type STATUS_UPDATE
2019-06-07 07:44:01,219 DEBUG org.apache.hadoop.yarn.server.resourcemanager.scheduler.capacity.CapacityScheduler: nodeUpdate: slave1:35126 clusterResources: <memory:8192, vCores:2>
2019-06-07 07:44:01,219 DEBUG org.apache.hadoop.yarn.server.resourcemanager.scheduler.capacity.CapacityScheduler: nodeUpdate: slave1:35126 clusterResources: <memory:8192, vCores:2>
2019-06-07 07:44:01,220 DEBUG org.apache.hadoop.yarn.server.resourcemanager.scheduler.capacity.CapacityScheduler: Node being looked for scheduling slave1:35126 availableResource: <memory:4096, vCores:1>
2019-06-07 07:44:01,220 DEBUG org.apache.hadoop.yarn.server.resourcemanager.scheduler.capacity.CapacityScheduler: Node being looked for scheduling slave1:35126 availableResource: <memory:4096, vCores:1>
2019-06-07 07:44:01,220 DEBUG org.apache.hadoop.yarn.server.resourcemanager.scheduler.capacity.CapacityScheduler: Trying to schedule on node: slave1, available: <memory:4096, vCores:1>
2019-06-07 07:44:01,220 DEBUG org.apache.hadoop.yarn.server.resourcemanager.scheduler.capacity.CapacityScheduler: Trying to schedule on node: slave1, available: <memory:4096, vCores:1>
2019-06-07 07:44:01,220 DEBUG org.apache.hadoop.yarn.server.resourcemanager.scheduler.capacity.ParentQueue: Skip this queue=root, because it doesn't need more resource, schedulingMode=RESPECT_PARTITION_EXCLUSIVITY node-partition=
2019-06-07 07:44:01,220 DEBUG org.apache.hadoop.yarn.server.resourcemanager.scheduler.capacity.ParentQueue: Skip this queue=root, because it doesn't need more resource, schedulingMode=RESPECT_PARTITION_EXCLUSIVITY node-partition=
2019-06-07 07:44:02,220 DEBUG org.apache.hadoop.yarn.server.resourcemanager.rmnode.RMNodeImpl: Processing slave2:33474 of type STATUS_UPDATE
2019-06-07 07:44:02,220 DEBUG org.apache.hadoop.yarn.server.resourcemanager.rmnode.RMNodeImpl: Processing slave2:33474 of type STATUS_UPDATE
2019-06-07 07:44:02,221 DEBUG org.apache.hadoop.yarn.server.resourcemanager.scheduler.capacity.CapacityScheduler: nodeUpdate: slave2:33474 clusterResources: <memory:8192, vCores:2>
2019-06-07 07:44:02,221 DEBUG org.apache.hadoop.yarn.server.resourcemanager.scheduler.capacity.CapacityScheduler: nodeUpdate: slave2:33474 clusterResources: <memory:8192, vCores:2>
2019-06-07 07:44:02,221 DEBUG org.apache.hadoop.yarn.server.resourcemanager.scheduler.capacity.CapacityScheduler: Node being looked for scheduling slave2:33474 availableResource: <memory:4096, vCores:1>
2019-06-07 07:44:02,221 DEBUG org.apache.hadoop.yarn.server.resourcemanager.scheduler.capacity.CapacityScheduler: Node being looked for scheduling slave2:33474 availableResource: <memory:4096, vCores:1>
2019-06-07 07:44:02,221 DEBUG org.apache.hadoop.yarn.server.resourcemanager.scheduler.capacity.CapacityScheduler: Trying to schedule on node: slave2, available: <memory:4096, vCores:1>
2019-06-07 07:44:02,221 DEBUG org.apache.hadoop.yarn.server.resourcemanager.scheduler.capacity.CapacityScheduler: Trying to schedule on node: slave2, available: <memory:4096, vCores:1>
2019-06-07 07:44:02,221 DEBUG org.apache.hadoop.yarn.server.resourcemanager.scheduler.capacity.ParentQueue: Skip this queue=root, because it doesn't need more resource, schedulingMode=RESPECT_PARTITION_EXCLUSIVITY node-partition=
2019-06-07 07:44:02,221 DEBUG org.apache.hadoop.yarn.server.resourcemanager.scheduler.capacity.ParentQueue: Skip this queue=root, because it doesn't need more resource, schedulingMode=RESPECT_PARTITION_EXCLUSIVITY node-partition=
2019-06-07 07:44:02,223 DEBUG org.apache.hadoop.yarn.server.resourcemanager.rmnode.RMNodeImpl: Processing slave1:35126 of type STATUS_UPDATE
2019-06-07 07:44:02,223 DEBUG org.apache.hadoop.yarn.server.resourcemanager.rmnode.RMNodeImpl: Processing slave1:35126 of type STATUS_UPDATE
2019-06-07 07:44:02,223 DEBUG org.apache.hadoop.yarn.server.resourcemanager.scheduler.capacity.CapacityScheduler: nodeUpdate: slave1:35126 clusterResources: <memory:8192, vCores:2>
2019-06-07 07:44:02,223 DEBUG org.apache.hadoop.yarn.server.resourcemanager.scheduler.capacity.CapacityScheduler: nodeUpdate: slave1:35126 clusterResources: <memory:8192, vCores:2>
2019-06-07 07:44:02,223 DEBUG org.apache.hadoop.yarn.server.resourcemanager.scheduler.capacity.CapacityScheduler: Node being looked for scheduling slave1:35126 availableResource: <memory:4096, vCores:1>
2019-06-07 07:44:02,223 DEBUG org.apache.hadoop.yarn.server.resourcemanager.scheduler.capacity.CapacityScheduler: Node being looked for scheduling slave1:35126 availableResource: <memory:4096, vCores:1>
2019-06-07 07:44:02,223 DEBUG org.apache.hadoop.yarn.server.resourcemanager.scheduler.capacity.CapacityScheduler: Trying to schedule on node: slave1, available: <memory:4096, vCores:1>
2019-06-07 07:44:02,223 DEBUG org.apache.hadoop.yarn.server.resourcemanager.scheduler.capacity.CapacityScheduler: Trying to schedule on node: slave1, available: <memory:4096, vCores:1>
2019-06-07 07:44:02,223 DEBUG org.apache.hadoop.yarn.server.resourcemanager.scheduler.capacity.ParentQueue: Skip this queue=root, because it doesn't need more resource, schedulingMode=RESPECT_PARTITION_EXCLUSIVITY node-partition=
2019-06-07 07:44:02,223 DEBUG org.apache.hadoop.yarn.server.resourcemanager.scheduler.capacity.ParentQueue: Skip this queue=root, because it doesn't need more resource, schedulingMode=RESPECT_PARTITION_EXCLUSIVITY node-partition=
2019-06-07 07:44:03,224 DEBUG org.apache.hadoop.yarn.server.resourcemanager.rmnode.RMNodeImpl: Processing slave2:33474 of type STATUS_UPDATE
2019-06-07 07:44:03,224 DEBUG org.apache.hadoop.yarn.server.resourcemanager.rmnode.RMNodeImpl: Processing slave2:33474 of type STATUS_UPDATE
2019-06-07 07:44:03,224 DEBUG org.apache.hadoop.yarn.server.resourcemanager.scheduler.capacity.CapacityScheduler: nodeUpdate: slave2:33474 clusterResources: <memory:8192, vCores:2>
2019-06-07 07:44:03,224 DEBUG org.apache.hadoop.yarn.server.resourcemanager.scheduler.capacity.CapacityScheduler: nodeUpdate: slave2:33474 clusterResources: <memory:8192, vCores:2>
2019-06-07 07:44:03,224 DEBUG org.apache.hadoop.yarn.server.resourcemanager.scheduler.capacity.CapacityScheduler: Node being looked for scheduling slave2:33474 availableResource: <memory:4096, vCores:1>
2019-06-07 07:44:03,224 DEBUG org.apache.hadoop.yarn.server.resourcemanager.scheduler.capacity.CapacityScheduler: Node being looked for scheduling slave2:33474 availableResource: <memory:4096, vCores:1>
2019-06-07 07:44:03,224 DEBUG org.apache.hadoop.yarn.server.resourcemanager.scheduler.capacity.CapacityScheduler: Trying to schedule on node: slave2, available: <memory:4096, vCores:1>
2019-06-07 07:44:03,224 DEBUG org.apache.hadoop.yarn.server.resourcemanager.scheduler.capacity.CapacityScheduler: Trying to schedule on node: slave2, available: <memory:4096, vCores:1>
2019-06-07 07:44:03,224 DEBUG org.apache.hadoop.yarn.server.resourcemanager.scheduler.capacity.ParentQueue: Skip this queue=root, because it doesn't need more resource, schedulingMode=RESPECT_PARTITION_EXCLUSIVITY node-partition=
2019-06-07 07:44:03,224 DEBUG org.apache.hadoop.yarn.server.resourcemanager.scheduler.capacity.ParentQueue: Skip this queue=root, because it doesn't need more resource, schedulingMode=RESPECT_PARTITION_EXCLUSIVITY node-partition=
2019-06-07 07:44:03,228 DEBUG org.apache.hadoop.yarn.server.resourcemanager.rmnode.RMNodeImpl: Processing slave1:35126 of type STATUS_UPDATE
2019-06-07 07:44:03,228 DEBUG org.apache.hadoop.yarn.server.resourcemanager.rmnode.RMNodeImpl: Processing slave1:35126 of type STATUS_UPDATE
2019-06-07 07:44:03,228 DEBUG org.apache.hadoop.yarn.server.resourcemanager.scheduler.capacity.CapacityScheduler: nodeUpdate: slave1:35126 clusterResources: <memory:8192, vCores:2>
2019-06-07 07:44:03,228 DEBUG org.apache.hadoop.yarn.server.resourcemanager.scheduler.capacity.CapacityScheduler: nodeUpdate: slave1:35126 clusterResources: <memory:8192, vCores:2>
2019-06-07 07:44:03,228 DEBUG org.apache.hadoop.yarn.server.resourcemanager.scheduler.capacity.CapacityScheduler: Node being looked for scheduling slave1:35126 availableResource: <memory:4096, vCores:1>
2019-06-07 07:44:03,228 DEBUG org.apache.hadoop.yarn.server.resourcemanager.scheduler.capacity.CapacityScheduler: Node being looked for scheduling slave1:35126 availableResource: <memory:4096, vCores:1>
2019-06-07 07:44:03,228 DEBUG org.apache.hadoop.yarn.server.resourcemanager.scheduler.capacity.CapacityScheduler: Trying to schedule on node: slave1, available: <memory:4096, vCores:1>
2019-06-07 07:44:03,228 DEBUG org.apache.hadoop.yarn.server.resourcemanager.scheduler.capacity.CapacityScheduler: Trying to schedule on node: slave1, available: <memory:4096, vCores:1>
2019-06-07 07:44:03,228 DEBUG org.apache.hadoop.yarn.server.resourcemanager.scheduler.capacity.ParentQueue: Skip this queue=root, because it doesn't need more resource, schedulingMode=RESPECT_PARTITION_EXCLUSIVITY node-partition=
2019-06-07 07:44:03,228 DEBUG org.apache.hadoop.yarn.server.resourcemanager.scheduler.capacity.ParentQueue: Skip this queue=root, because it doesn't need more resource, schedulingMode=RESPECT_PARTITION_EXCLUSIVITY node-partition=
2019-06-07 07:44:04,227 DEBUG org.apache.hadoop.yarn.server.resourcemanager.rmnode.RMNodeImpl: Processing slave2:33474 of type STATUS_UPDATE
2019-06-07 07:44:04,227 DEBUG org.apache.hadoop.yarn.server.resourcemanager.rmnode.RMNodeImpl: Processing slave2:33474 of type STATUS_UPDATE
2019-06-07 07:44:04,227 DEBUG org.apache.hadoop.yarn.server.resourcemanager.scheduler.capacity.CapacityScheduler: nodeUpdate: slave2:33474 clusterResources: <memory:8192, vCores:2>
2019-06-07 07:44:04,227 DEBUG org.apache.hadoop.yarn.server.resourcemanager.scheduler.capacity.CapacityScheduler: nodeUpdate: slave2:33474 clusterResources: <memory:8192, vCores:2>
2019-06-07 07:44:04,227 DEBUG org.apache.hadoop.yarn.server.resourcemanager.scheduler.capacity.CapacityScheduler: Node being looked for scheduling slave2:33474 availableResource: <memory:4096, vCores:1>
2019-06-07 07:44:04,227 DEBUG org.apache.hadoop.yarn.server.resourcemanager.scheduler.capacity.CapacityScheduler: Node being looked for scheduling slave2:33474 availableResource: <memory:4096, vCores:1>
2019-06-07 07:44:04,227 DEBUG org.apache.hadoop.yarn.server.resourcemanager.scheduler.capacity.CapacityScheduler: Trying to schedule on node: slave2, available: <memory:4096, vCores:1>
2019-06-07 07:44:04,227 DEBUG org.apache.hadoop.yarn.server.resourcemanager.scheduler.capacity.CapacityScheduler: Trying to schedule on node: slave2, available: <memory:4096, vCores:1>
2019-06-07 07:44:04,228 DEBUG org.apache.hadoop.yarn.server.resourcemanager.scheduler.capacity.ParentQueue: Skip this queue=root, because it doesn't need more resource, schedulingMode=RESPECT_PARTITION_EXCLUSIVITY node-partition=
2019-06-07 07:44:04,228 DEBUG org.apache.hadoop.yarn.server.resourcemanager.scheduler.capacity.ParentQueue: Skip this queue=root, because it doesn't need more resource, schedulingMode=RESPECT_PARTITION_EXCLUSIVITY node-partition=
2019-06-07 07:44:04,230 DEBUG org.apache.hadoop.yarn.server.resourcemanager.rmnode.RMNodeImpl: Processing slave1:35126 of type STATUS_UPDATE
2019-06-07 07:44:04,230 DEBUG org.apache.hadoop.yarn.server.resourcemanager.rmnode.RMNodeImpl: Processing slave1:35126 of type STATUS_UPDATE
2019-06-07 07:44:04,230 DEBUG org.apache.hadoop.yarn.server.resourcemanager.scheduler.capacity.CapacityScheduler: nodeUpdate: slave1:35126 clusterResources: <memory:8192, vCores:2>
2019-06-07 07:44:04,230 DEBUG org.apache.hadoop.yarn.server.resourcemanager.scheduler.capacity.CapacityScheduler: nodeUpdate: slave1:35126 clusterResources: <memory:8192, vCores:2>
2019-06-07 07:44:04,230 DEBUG org.apache.hadoop.yarn.server.resourcemanager.scheduler.capacity.CapacityScheduler: Node being looked for scheduling slave1:35126 availableResource: <memory:4096, vCores:1>
2019-06-07 07:44:04,230 DEBUG org.apache.hadoop.yarn.server.resourcemanager.scheduler.capacity.CapacityScheduler: Node being looked for scheduling slave1:35126 availableResource: <memory:4096, vCores:1>
2019-06-07 07:44:04,230 DEBUG org.apache.hadoop.yarn.server.resourcemanager.scheduler.capacity.CapacityScheduler: Trying to schedule on node: slave1, available: <memory:4096, vCores:1>
2019-06-07 07:44:04,230 DEBUG org.apache.hadoop.yarn.server.resourcemanager.scheduler.capacity.CapacityScheduler: Trying to schedule on node: slave1, available: <memory:4096, vCores:1>
2019-06-07 07:44:04,230 DEBUG org.apache.hadoop.yarn.server.resourcemanager.scheduler.capacity.ParentQueue: Skip this queue=root, because it doesn't need more resource, schedulingMode=RESPECT_PARTITION_EXCLUSIVITY node-partition=
2019-06-07 07:44:04,230 DEBUG org.apache.hadoop.yarn.server.resourcemanager.scheduler.capacity.ParentQueue: Skip this queue=root, because it doesn't need more resource, schedulingMode=RESPECT_PARTITION_EXCLUSIVITY node-partition=
2019-06-07 07:44:05,235 DEBUG org.apache.hadoop.yarn.server.resourcemanager.rmnode.RMNodeImpl: Processing slave1:35126 of type STATUS_UPDATE
2019-06-07 07:44:05,235 DEBUG org.apache.hadoop.yarn.server.resourcemanager.rmnode.RMNodeImpl: Processing slave1:35126 of type STATUS_UPDATE
2019-06-07 07:44:05,235 DEBUG org.apache.hadoop.yarn.server.resourcemanager.rmnode.RMNodeImpl: Processing slave2:33474 of type STATUS_UPDATE
2019-06-07 07:44:05,235 DEBUG org.apache.hadoop.yarn.server.resourcemanager.rmnode.RMNodeImpl: Processing slave2:33474 of type STATUS_UPDATE
2019-06-07 07:44:05,236 DEBUG org.apache.hadoop.yarn.server.resourcemanager.scheduler.capacity.CapacityScheduler: nodeUpdate: slave1:35126 clusterResources: <memory:8192, vCores:2>
2019-06-07 07:44:05,236 DEBUG org.apache.hadoop.yarn.server.resourcemanager.scheduler.capacity.CapacityScheduler: nodeUpdate: slave1:35126 clusterResources: <memory:8192, vCores:2>
2019-06-07 07:44:05,236 DEBUG org.apache.hadoop.yarn.server.resourcemanager.scheduler.capacity.CapacityScheduler: Node being looked for scheduling slave1:35126 availableResource: <memory:4096, vCores:1>
2019-06-07 07:44:05,236 DEBUG org.apache.hadoop.yarn.server.resourcemanager.scheduler.capacity.CapacityScheduler: Node being looked for scheduling slave1:35126 availableResource: <memory:4096, vCores:1>
2019-06-07 07:44:05,236 DEBUG org.apache.hadoop.yarn.server.resourcemanager.scheduler.capacity.CapacityScheduler: Trying to schedule on node: slave1, available: <memory:4096, vCores:1>
2019-06-07 07:44:05,236 DEBUG org.apache.hadoop.yarn.server.resourcemanager.scheduler.capacity.CapacityScheduler: Trying to schedule on node: slave1, available: <memory:4096, vCores:1>
2019-06-07 07:44:05,236 DEBUG org.apache.hadoop.yarn.server.resourcemanager.scheduler.capacity.ParentQueue: Skip this queue=root, because it doesn't need more resource, schedulingMode=RESPECT_PARTITION_EXCLUSIVITY node-partition=
2019-06-07 07:44:05,236 DEBUG org.apache.hadoop.yarn.server.resourcemanager.scheduler.capacity.ParentQueue: Skip this queue=root, because it doesn't need more resource, schedulingMode=RESPECT_PARTITION_EXCLUSIVITY node-partition=
2019-06-07 07:44:05,236 DEBUG org.apache.hadoop.yarn.server.resourcemanager.scheduler.capacity.CapacityScheduler: nodeUpdate: slave2:33474 clusterResources: <memory:8192, vCores:2>
2019-06-07 07:44:05,236 DEBUG org.apache.hadoop.yarn.server.resourcemanager.scheduler.capacity.CapacityScheduler: nodeUpdate: slave2:33474 clusterResources: <memory:8192, vCores:2>
2019-06-07 07:44:05,236 DEBUG org.apache.hadoop.yarn.server.resourcemanager.scheduler.capacity.CapacityScheduler: Node being looked for scheduling slave2:33474 availableResource: <memory:4096, vCores:1>
2019-06-07 07:44:05,236 DEBUG org.apache.hadoop.yarn.server.resourcemanager.scheduler.capacity.CapacityScheduler: Node being looked for scheduling slave2:33474 availableResource: <memory:4096, vCores:1>
2019-06-07 07:44:05,236 DEBUG org.apache.hadoop.yarn.server.resourcemanager.scheduler.capacity.CapacityScheduler: Trying to schedule on node: slave2, available: <memory:4096, vCores:1>
2019-06-07 07:44:05,236 DEBUG org.apache.hadoop.yarn.server.resourcemanager.scheduler.capacity.CapacityScheduler: Trying to schedule on node: slave2, available: <memory:4096, vCores:1>
2019-06-07 07:44:05,236 DEBUG org.apache.hadoop.yarn.server.resourcemanager.scheduler.capacity.ParentQueue: Skip this queue=root, because it doesn't need more resource, schedulingMode=RESPECT_PARTITION_EXCLUSIVITY node-partition=
2019-06-07 07:44:05,236 DEBUG org.apache.hadoop.yarn.server.resourcemanager.scheduler.capacity.ParentQueue: Skip this queue=root, because it doesn't need more resource, schedulingMode=RESPECT_PARTITION_EXCLUSIVITY node-partition=
2019-06-07 07:44:06,237 DEBUG org.apache.hadoop.yarn.server.resourcemanager.rmnode.RMNodeImpl: Processing slave1:35126 of type STATUS_UPDATE
2019-06-07 07:44:06,237 DEBUG org.apache.hadoop.yarn.server.resourcemanager.rmnode.RMNodeImpl: Processing slave1:35126 of type STATUS_UPDATE
2019-06-07 07:44:06,238 DEBUG org.apache.hadoop.yarn.server.resourcemanager.scheduler.capacity.CapacityScheduler: nodeUpdate: slave1:35126 clusterResources: <memory:8192, vCores:2>
2019-06-07 07:44:06,238 DEBUG org.apache.hadoop.yarn.server.resourcemanager.scheduler.capacity.CapacityScheduler: nodeUpdate: slave1:35126 clusterResources: <memory:8192, vCores:2>
2019-06-07 07:44:06,238 DEBUG org.apache.hadoop.yarn.server.resourcemanager.scheduler.capacity.CapacityScheduler: Node being looked for scheduling slave1:35126 availableResource: <memory:4096, vCores:1>
2019-06-07 07:44:06,238 DEBUG org.apache.hadoop.yarn.server.resourcemanager.scheduler.capacity.CapacityScheduler: Node being looked for scheduling slave1:35126 availableResource: <memory:4096, vCores:1>
2019-06-07 07:44:06,238 DEBUG org.apache.hadoop.yarn.server.resourcemanager.scheduler.capacity.CapacityScheduler: Trying to schedule on node: slave1, available: <memory:4096, vCores:1>
2019-06-07 07:44:06,238 DEBUG org.apache.hadoop.yarn.server.resourcemanager.scheduler.capacity.CapacityScheduler: Trying to schedule on node: slave1, available: <memory:4096, vCores:1>
2019-06-07 07:44:06,238 DEBUG org.apache.hadoop.yarn.server.resourcemanager.scheduler.capacity.ParentQueue: Skip this queue=root, because it doesn't need more resource, schedulingMode=RESPECT_PARTITION_EXCLUSIVITY node-partition=
2019-06-07 07:44:06,238 DEBUG org.apache.hadoop.yarn.server.resourcemanager.scheduler.capacity.ParentQueue: Skip this queue=root, because it doesn't need more resource, schedulingMode=RESPECT_PARTITION_EXCLUSIVITY node-partition=
2019-06-07 07:44:06,238 DEBUG org.apache.hadoop.yarn.server.resourcemanager.rmnode.RMNodeImpl: Processing slave2:33474 of type STATUS_UPDATE
2019-06-07 07:44:06,238 DEBUG org.apache.hadoop.yarn.server.resourcemanager.rmnode.RMNodeImpl: Processing slave2:33474 of type STATUS_UPDATE
2019-06-07 07:44:06,238 DEBUG org.apache.hadoop.yarn.server.resourcemanager.scheduler.capacity.CapacityScheduler: nodeUpdate: slave2:33474 clusterResources: <memory:8192, vCores:2>
2019-06-07 07:44:06,238 DEBUG org.apache.hadoop.yarn.server.resourcemanager.scheduler.capacity.CapacityScheduler: nodeUpdate: slave2:33474 clusterResources: <memory:8192, vCores:2>
2019-06-07 07:44:06,238 DEBUG org.apache.hadoop.yarn.server.resourcemanager.scheduler.capacity.CapacityScheduler: Node being looked for scheduling slave2:33474 availableResource: <memory:4096, vCores:1>
2019-06-07 07:44:06,238 DEBUG org.apache.hadoop.yarn.server.resourcemanager.scheduler.capacity.CapacityScheduler: Node being looked for scheduling slave2:33474 availableResource: <memory:4096, vCores:1>
2019-06-07 07:44:06,238 DEBUG org.apache.hadoop.yarn.server.resourcemanager.scheduler.capacity.CapacityScheduler: Trying to schedule on node: slave2, available: <memory:4096, vCores:1>
2019-06-07 07:44:06,238 DEBUG org.apache.hadoop.yarn.server.resourcemanager.scheduler.capacity.CapacityScheduler: Trying to schedule on node: slave2, available: <memory:4096, vCores:1>
2019-06-07 07:44:06,238 DEBUG org.apache.hadoop.yarn.server.resourcemanager.scheduler.capacity.ParentQueue: Skip this queue=root, because it doesn't need more resource, schedulingMode=RESPECT_PARTITION_EXCLUSIVITY node-partition=
2019-06-07 07:44:06,238 DEBUG org.apache.hadoop.yarn.server.resourcemanager.scheduler.capacity.ParentQueue: Skip this queue=root, because it doesn't need more resource, schedulingMode=RESPECT_PARTITION_EXCLUSIVITY node-partition=
2019-06-07 07:44:07,241 DEBUG org.apache.hadoop.yarn.server.resourcemanager.rmnode.RMNodeImpl: Processing slave1:35126 of type STATUS_UPDATE
2019-06-07 07:44:07,241 DEBUG org.apache.hadoop.yarn.server.resourcemanager.rmnode.RMNodeImpl: Processing slave1:35126 of type STATUS_UPDATE
2019-06-07 07:44:07,241 DEBUG org.apache.hadoop.yarn.server.resourcemanager.rmnode.RMNodeImpl: Processing slave2:33474 of type STATUS_UPDATE
2019-06-07 07:44:07,241 DEBUG org.apache.hadoop.yarn.server.resourcemanager.rmnode.RMNodeImpl: Processing slave2:33474 of type STATUS_UPDATE
2019-06-07 07:44:07,241 DEBUG org.apache.hadoop.yarn.server.resourcemanager.scheduler.capacity.CapacityScheduler: nodeUpdate: slave1:35126 clusterResources: <memory:8192, vCores:2>
2019-06-07 07:44:07,241 DEBUG org.apache.hadoop.yarn.server.resourcemanager.scheduler.capacity.CapacityScheduler: nodeUpdate: slave1:35126 clusterResources: <memory:8192, vCores:2>
2019-06-07 07:44:07,241 DEBUG org.apache.hadoop.yarn.server.resourcemanager.scheduler.capacity.CapacityScheduler: Node being looked for scheduling slave1:35126 availableResource: <memory:4096, vCores:1>
2019-06-07 07:44:07,241 DEBUG org.apache.hadoop.yarn.server.resourcemanager.scheduler.capacity.CapacityScheduler: Node being looked for scheduling slave1:35126 availableResource: <memory:4096, vCores:1>
2019-06-07 07:44:07,242 DEBUG org.apache.hadoop.yarn.server.resourcemanager.scheduler.capacity.CapacityScheduler: Trying to schedule on node: slave1, available: <memory:4096, vCores:1>
2019-06-07 07:44:07,242 DEBUG org.apache.hadoop.yarn.server.resourcemanager.scheduler.capacity.CapacityScheduler: Trying to schedule on node: slave1, available: <memory:4096, vCores:1>
2019-06-07 07:44:07,242 DEBUG org.apache.hadoop.yarn.server.resourcemanager.scheduler.capacity.ParentQueue: Skip this queue=root, because it doesn't need more resource, schedulingMode=RESPECT_PARTITION_EXCLUSIVITY node-partition=
2019-06-07 07:44:07,242 DEBUG org.apache.hadoop.yarn.server.resourcemanager.scheduler.capacity.ParentQueue: Skip this queue=root, because it doesn't need more resource, schedulingMode=RESPECT_PARTITION_EXCLUSIVITY node-partition=
2019-06-07 07:44:07,242 DEBUG org.apache.hadoop.yarn.server.resourcemanager.scheduler.capacity.CapacityScheduler: nodeUpdate: slave2:33474 clusterResources: <memory:8192, vCores:2>
2019-06-07 07:44:07,242 DEBUG org.apache.hadoop.yarn.server.resourcemanager.scheduler.capacity.CapacityScheduler: nodeUpdate: slave2:33474 clusterResources: <memory:8192, vCores:2>
2019-06-07 07:44:07,242 DEBUG org.apache.hadoop.yarn.server.resourcemanager.scheduler.capacity.CapacityScheduler: Node being looked for scheduling slave2:33474 availableResource: <memory:4096, vCores:1>
2019-06-07 07:44:07,242 DEBUG org.apache.hadoop.yarn.server.resourcemanager.scheduler.capacity.CapacityScheduler: Node being looked for scheduling slave2:33474 availableResource: <memory:4096, vCores:1>
2019-06-07 07:44:07,242 DEBUG org.apache.hadoop.yarn.server.resourcemanager.scheduler.capacity.CapacityScheduler: Trying to schedule on node: slave2, available: <memory:4096, vCores:1>
2019-06-07 07:44:07,242 DEBUG org.apache.hadoop.yarn.server.resourcemanager.scheduler.capacity.CapacityScheduler: Trying to schedule on node: slave2, available: <memory:4096, vCores:1>
2019-06-07 07:44:07,242 DEBUG org.apache.hadoop.yarn.server.resourcemanager.scheduler.capacity.ParentQueue: Skip this queue=root, because it doesn't need more resource, schedulingMode=RESPECT_PARTITION_EXCLUSIVITY node-partition=
2019-06-07 07:44:07,242 DEBUG org.apache.hadoop.yarn.server.resourcemanager.scheduler.capacity.ParentQueue: Skip this queue=root, because it doesn't need more resource, schedulingMode=RESPECT_PARTITION_EXCLUSIVITY node-partition=
2019-06-07 07:44:08,244 DEBUG org.apache.hadoop.yarn.server.resourcemanager.rmnode.RMNodeImpl: Processing slave1:35126 of type STATUS_UPDATE
2019-06-07 07:44:08,244 DEBUG org.apache.hadoop.yarn.server.resourcemanager.rmnode.RMNodeImpl: Processing slave1:35126 of type STATUS_UPDATE
2019-06-07 07:44:08,245 DEBUG org.apache.hadoop.yarn.server.resourcemanager.scheduler.capacity.CapacityScheduler: nodeUpdate: slave1:35126 clusterResources: <memory:8192, vCores:2>
2019-06-07 07:44:08,245 DEBUG org.apache.hadoop.yarn.server.resourcemanager.scheduler.capacity.CapacityScheduler: nodeUpdate: slave1:35126 clusterResources: <memory:8192, vCores:2>
2019-06-07 07:44:08,245 DEBUG org.apache.hadoop.yarn.server.resourcemanager.scheduler.capacity.CapacityScheduler: Node being looked for scheduling slave1:35126 availableResource: <memory:4096, vCores:1>
2019-06-07 07:44:08,245 DEBUG org.apache.hadoop.yarn.server.resourcemanager.scheduler.capacity.CapacityScheduler: Node being looked for scheduling slave1:35126 availableResource: <memory:4096, vCores:1>
2019-06-07 07:44:08,245 DEBUG org.apache.hadoop.yarn.server.resourcemanager.scheduler.capacity.CapacityScheduler: Trying to schedule on node: slave1, available: <memory:4096, vCores:1>
2019-06-07 07:44:08,245 DEBUG org.apache.hadoop.yarn.server.resourcemanager.scheduler.capacity.CapacityScheduler: Trying to schedule on node: slave1, available: <memory:4096, vCores:1>
2019-06-07 07:44:08,245 DEBUG org.apache.hadoop.yarn.server.resourcemanager.scheduler.capacity.ParentQueue: Skip this queue=root, because it doesn't need more resource, schedulingMode=RESPECT_PARTITION_EXCLUSIVITY node-partition=
2019-06-07 07:44:08,245 DEBUG org.apache.hadoop.yarn.server.resourcemanager.scheduler.capacity.ParentQueue: Skip this queue=root, because it doesn't need more resource, schedulingMode=RESPECT_PARTITION_EXCLUSIVITY node-partition=
2019-06-07 07:44:08,245 DEBUG org.apache.hadoop.yarn.server.resourcemanager.rmnode.RMNodeImpl: Processing slave2:33474 of type STATUS_UPDATE
2019-06-07 07:44:08,245 DEBUG org.apache.hadoop.yarn.server.resourcemanager.rmnode.RMNodeImpl: Processing slave2:33474 of type STATUS_UPDATE
2019-06-07 07:44:08,245 DEBUG org.apache.hadoop.yarn.server.resourcemanager.scheduler.capacity.CapacityScheduler: nodeUpdate: slave2:33474 clusterResources: <memory:8192, vCores:2>
2019-06-07 07:44:08,245 DEBUG org.apache.hadoop.yarn.server.resourcemanager.scheduler.capacity.CapacityScheduler: nodeUpdate: slave2:33474 clusterResources: <memory:8192, vCores:2>
2019-06-07 07:44:08,245 DEBUG org.apache.hadoop.yarn.server.resourcemanager.scheduler.capacity.CapacityScheduler: Node being looked for scheduling slave2:33474 availableResource: <memory:4096, vCores:1>
2019-06-07 07:44:08,245 DEBUG org.apache.hadoop.yarn.server.resourcemanager.scheduler.capacity.CapacityScheduler: Node being looked for scheduling slave2:33474 availableResource: <memory:4096, vCores:1>
2019-06-07 07:44:08,245 DEBUG org.apache.hadoop.yarn.server.resourcemanager.scheduler.capacity.CapacityScheduler: Trying to schedule on node: slave2, available: <memory:4096, vCores:1>
2019-06-07 07:44:08,245 DEBUG org.apache.hadoop.yarn.server.resourcemanager.scheduler.capacity.CapacityScheduler: Trying to schedule on node: slave2, available: <memory:4096, vCores:1>
2019-06-07 07:44:08,245 DEBUG org.apache.hadoop.yarn.server.resourcemanager.scheduler.capacity.ParentQueue: Skip this queue=root, because it doesn't need more resource, schedulingMode=RESPECT_PARTITION_EXCLUSIVITY node-partition=
2019-06-07 07:44:08,245 DEBUG org.apache.hadoop.yarn.server.resourcemanager.scheduler.capacity.ParentQueue: Skip this queue=root, because it doesn't need more resource, schedulingMode=RESPECT_PARTITION_EXCLUSIVITY node-partition=
2019-06-07 07:44:09,248 DEBUG org.apache.hadoop.yarn.server.resourcemanager.rmnode.RMNodeImpl: Processing slave2:33474 of type STATUS_UPDATE
2019-06-07 07:44:09,248 DEBUG org.apache.hadoop.yarn.server.resourcemanager.rmnode.RMNodeImpl: Processing slave2:33474 of type STATUS_UPDATE
2019-06-07 07:44:09,249 DEBUG org.apache.hadoop.yarn.server.resourcemanager.scheduler.capacity.CapacityScheduler: nodeUpdate: slave2:33474 clusterResources: <memory:8192, vCores:2>
2019-06-07 07:44:09,249 DEBUG org.apache.hadoop.yarn.server.resourcemanager.scheduler.capacity.CapacityScheduler: nodeUpdate: slave2:33474 clusterResources: <memory:8192, vCores:2>
2019-06-07 07:44:09,249 DEBUG org.apache.hadoop.yarn.server.resourcemanager.scheduler.capacity.CapacityScheduler: Node being looked for scheduling slave2:33474 availableResource: <memory:4096, vCores:1>
2019-06-07 07:44:09,249 DEBUG org.apache.hadoop.yarn.server.resourcemanager.scheduler.capacity.CapacityScheduler: Node being looked for scheduling slave2:33474 availableResource: <memory:4096, vCores:1>
2019-06-07 07:44:09,249 DEBUG org.apache.hadoop.yarn.server.resourcemanager.scheduler.capacity.CapacityScheduler: Trying to schedule on node: slave2, available: <memory:4096, vCores:1>
2019-06-07 07:44:09,249 DEBUG org.apache.hadoop.yarn.server.resourcemanager.scheduler.capacity.CapacityScheduler: Trying to schedule on node: slave2, available: <memory:4096, vCores:1>
2019-06-07 07:44:09,249 DEBUG org.apache.hadoop.yarn.server.resourcemanager.scheduler.capacity.ParentQueue: Skip this queue=root, because it doesn't need more resource, schedulingMode=RESPECT_PARTITION_EXCLUSIVITY node-partition=
2019-06-07 07:44:09,249 DEBUG org.apache.hadoop.yarn.server.resourcemanager.scheduler.capacity.ParentQueue: Skip this queue=root, because it doesn't need more resource, schedulingMode=RESPECT_PARTITION_EXCLUSIVITY node-partition=
2019-06-07 07:44:09,250 DEBUG org.apache.hadoop.yarn.server.resourcemanager.rmnode.RMNodeImpl: Processing slave1:35126 of type STATUS_UPDATE
2019-06-07 07:44:09,250 DEBUG org.apache.hadoop.yarn.server.resourcemanager.rmnode.RMNodeImpl: Processing slave1:35126 of type STATUS_UPDATE
2019-06-07 07:44:09,250 DEBUG org.apache.hadoop.yarn.server.resourcemanager.scheduler.capacity.CapacityScheduler: nodeUpdate: slave1:35126 clusterResources: <memory:8192, vCores:2>
2019-06-07 07:44:09,250 DEBUG org.apache.hadoop.yarn.server.resourcemanager.scheduler.capacity.CapacityScheduler: nodeUpdate: slave1:35126 clusterResources: <memory:8192, vCores:2>
2019-06-07 07:44:09,250 DEBUG org.apache.hadoop.yarn.server.resourcemanager.scheduler.capacity.CapacityScheduler: Node being looked for scheduling slave1:35126 availableResource: <memory:4096, vCores:1>
2019-06-07 07:44:09,250 DEBUG org.apache.hadoop.yarn.server.resourcemanager.scheduler.capacity.CapacityScheduler: Node being looked for scheduling slave1:35126 availableResource: <memory:4096, vCores:1>
2019-06-07 07:44:09,250 DEBUG org.apache.hadoop.yarn.server.resourcemanager.scheduler.capacity.CapacityScheduler: Trying to schedule on node: slave1, available: <memory:4096, vCores:1>
2019-06-07 07:44:09,250 DEBUG org.apache.hadoop.yarn.server.resourcemanager.scheduler.capacity.CapacityScheduler: Trying to schedule on node: slave1, available: <memory:4096, vCores:1>
2019-06-07 07:44:09,251 DEBUG org.apache.hadoop.yarn.server.resourcemanager.scheduler.capacity.ParentQueue: Skip this queue=root, because it doesn't need more resource, schedulingMode=RESPECT_PARTITION_EXCLUSIVITY node-partition=
2019-06-07 07:44:09,251 DEBUG org.apache.hadoop.yarn.server.resourcemanager.scheduler.capacity.ParentQueue: Skip this queue=root, because it doesn't need more resource, schedulingMode=RESPECT_PARTITION_EXCLUSIVITY node-partition=
2019-06-07 07:44:10,253 DEBUG org.apache.hadoop.yarn.server.resourcemanager.rmnode.RMNodeImpl: Processing slave2:33474 of type STATUS_UPDATE
2019-06-07 07:44:10,253 DEBUG org.apache.hadoop.yarn.server.resourcemanager.rmnode.RMNodeImpl: Processing slave2:33474 of type STATUS_UPDATE
2019-06-07 07:44:10,253 DEBUG org.apache.hadoop.yarn.server.resourcemanager.scheduler.capacity.CapacityScheduler: nodeUpdate: slave2:33474 clusterResources: <memory:8192, vCores:2>
2019-06-07 07:44:10,253 DEBUG org.apache.hadoop.yarn.server.resourcemanager.scheduler.capacity.CapacityScheduler: nodeUpdate: slave2:33474 clusterResources: <memory:8192, vCores:2>
2019-06-07 07:44:10,254 DEBUG org.apache.hadoop.yarn.server.resourcemanager.scheduler.capacity.CapacityScheduler: Node being looked for scheduling slave2:33474 availableResource: <memory:4096, vCores:1>
2019-06-07 07:44:10,254 DEBUG org.apache.hadoop.yarn.server.resourcemanager.scheduler.capacity.CapacityScheduler: Node being looked for scheduling slave2:33474 availableResource: <memory:4096, vCores:1>
2019-06-07 07:44:10,254 DEBUG org.apache.hadoop.yarn.server.resourcemanager.scheduler.capacity.CapacityScheduler: Trying to schedule on node: slave2, available: <memory:4096, vCores:1>
2019-06-07 07:44:10,254 DEBUG org.apache.hadoop.yarn.server.resourcemanager.scheduler.capacity.CapacityScheduler: Trying to schedule on node: slave2, available: <memory:4096, vCores:1>
2019-06-07 07:44:10,254 DEBUG org.apache.hadoop.yarn.server.resourcemanager.scheduler.capacity.ParentQueue: Skip this queue=root, because it doesn't need more resource, schedulingMode=RESPECT_PARTITION_EXCLUSIVITY node-partition=
2019-06-07 07:44:10,254 DEBUG org.apache.hadoop.yarn.server.resourcemanager.scheduler.capacity.ParentQueue: Skip this queue=root, because it doesn't need more resource, schedulingMode=RESPECT_PARTITION_EXCLUSIVITY node-partition=
2019-06-07 07:44:10,254 DEBUG org.apache.hadoop.yarn.server.resourcemanager.rmnode.RMNodeImpl: Processing slave1:35126 of type STATUS_UPDATE
2019-06-07 07:44:10,254 DEBUG org.apache.hadoop.yarn.server.resourcemanager.rmnode.RMNodeImpl: Processing slave1:35126 of type STATUS_UPDATE
2019-06-07 07:44:10,254 DEBUG org.apache.hadoop.yarn.server.resourcemanager.scheduler.capacity.CapacityScheduler: nodeUpdate: slave1:35126 clusterResources: <memory:8192, vCores:2>
2019-06-07 07:44:10,254 DEBUG org.apache.hadoop.yarn.server.resourcemanager.scheduler.capacity.CapacityScheduler: nodeUpdate: slave1:35126 clusterResources: <memory:8192, vCores:2>
2019-06-07 07:44:10,254 DEBUG org.apache.hadoop.yarn.server.resourcemanager.scheduler.capacity.CapacityScheduler: Node being looked for scheduling slave1:35126 availableResource: <memory:4096, vCores:1>
2019-06-07 07:44:10,254 DEBUG org.apache.hadoop.yarn.server.resourcemanager.scheduler.capacity.CapacityScheduler: Node being looked for scheduling slave1:35126 availableResource: <memory:4096, vCores:1>
2019-06-07 07:44:10,254 DEBUG org.apache.hadoop.yarn.server.resourcemanager.scheduler.capacity.CapacityScheduler: Trying to schedule on node: slave1, available: <memory:4096, vCores:1>
2019-06-07 07:44:10,254 DEBUG org.apache.hadoop.yarn.server.resourcemanager.scheduler.capacity.CapacityScheduler: Trying to schedule on node: slave1, available: <memory:4096, vCores:1>
2019-06-07 07:44:10,255 DEBUG org.apache.hadoop.yarn.server.resourcemanager.scheduler.capacity.ParentQueue: Skip this queue=root, because it doesn't need more resource, schedulingMode=RESPECT_PARTITION_EXCLUSIVITY node-partition=
2019-06-07 07:44:10,255 DEBUG org.apache.hadoop.yarn.server.resourcemanager.scheduler.capacity.ParentQueue: Skip this queue=root, because it doesn't need more resource, schedulingMode=RESPECT_PARTITION_EXCLUSIVITY node-partition=
2019-06-07 07:44:11,261 DEBUG org.apache.hadoop.yarn.server.resourcemanager.rmnode.RMNodeImpl: Processing slave2:33474 of type STATUS_UPDATE
2019-06-07 07:44:11,261 DEBUG org.apache.hadoop.yarn.server.resourcemanager.rmnode.RMNodeImpl: Processing slave2:33474 of type STATUS_UPDATE
2019-06-07 07:44:11,261 DEBUG org.apache.hadoop.yarn.server.resourcemanager.rmnode.RMNodeImpl: Processing slave1:35126 of type STATUS_UPDATE
2019-06-07 07:44:11,261 DEBUG org.apache.hadoop.yarn.server.resourcemanager.rmnode.RMNodeImpl: Processing slave1:35126 of type STATUS_UPDATE
2019-06-07 07:44:11,261 DEBUG org.apache.hadoop.yarn.server.resourcemanager.scheduler.capacity.CapacityScheduler: nodeUpdate: slave2:33474 clusterResources: <memory:8192, vCores:2>
2019-06-07 07:44:11,261 DEBUG org.apache.hadoop.yarn.server.resourcemanager.scheduler.capacity.CapacityScheduler: nodeUpdate: slave2:33474 clusterResources: <memory:8192, vCores:2>
2019-06-07 07:44:11,261 DEBUG org.apache.hadoop.yarn.server.resourcemanager.scheduler.capacity.CapacityScheduler: Node being looked for scheduling slave2:33474 availableResource: <memory:4096, vCores:1>
2019-06-07 07:44:11,261 DEBUG org.apache.hadoop.yarn.server.resourcemanager.scheduler.capacity.CapacityScheduler: Node being looked for scheduling slave2:33474 availableResource: <memory:4096, vCores:1>
2019-06-07 07:44:11,261 DEBUG org.apache.hadoop.yarn.server.resourcemanager.scheduler.capacity.CapacityScheduler: Trying to schedule on node: slave2, available: <memory:4096, vCores:1>
2019-06-07 07:44:11,261 DEBUG org.apache.hadoop.yarn.server.resourcemanager.scheduler.capacity.CapacityScheduler: Trying to schedule on node: slave2, available: <memory:4096, vCores:1>
2019-06-07 07:44:11,261 DEBUG org.apache.hadoop.yarn.server.resourcemanager.scheduler.capacity.ParentQueue: Skip this queue=root, because it doesn't need more resource, schedulingMode=RESPECT_PARTITION_EXCLUSIVITY node-partition=
2019-06-07 07:44:11,261 DEBUG org.apache.hadoop.yarn.server.resourcemanager.scheduler.capacity.ParentQueue: Skip this queue=root, because it doesn't need more resource, schedulingMode=RESPECT_PARTITION_EXCLUSIVITY node-partition=
2019-06-07 07:44:11,261 DEBUG org.apache.hadoop.yarn.server.resourcemanager.scheduler.capacity.CapacityScheduler: nodeUpdate: slave1:35126 clusterResources: <memory:8192, vCores:2>
2019-06-07 07:44:11,261 DEBUG org.apache.hadoop.yarn.server.resourcemanager.scheduler.capacity.CapacityScheduler: nodeUpdate: slave1:35126 clusterResources: <memory:8192, vCores:2>
2019-06-07 07:44:11,261 DEBUG org.apache.hadoop.yarn.server.resourcemanager.scheduler.capacity.CapacityScheduler: Node being looked for scheduling slave1:35126 availableResource: <memory:4096, vCores:1>
2019-06-07 07:44:11,261 DEBUG org.apache.hadoop.yarn.server.resourcemanager.scheduler.capacity.CapacityScheduler: Node being looked for scheduling slave1:35126 availableResource: <memory:4096, vCores:1>
2019-06-07 07:44:11,261 DEBUG org.apache.hadoop.yarn.server.resourcemanager.scheduler.capacity.CapacityScheduler: Trying to schedule on node: slave1, available: <memory:4096, vCores:1>
2019-06-07 07:44:11,261 DEBUG org.apache.hadoop.yarn.server.resourcemanager.scheduler.capacity.CapacityScheduler: Trying to schedule on node: slave1, available: <memory:4096, vCores:1>
2019-06-07 07:44:11,261 DEBUG org.apache.hadoop.yarn.server.resourcemanager.scheduler.capacity.ParentQueue: Skip this queue=root, because it doesn't need more resource, schedulingMode=RESPECT_PARTITION_EXCLUSIVITY node-partition=
2019-06-07 07:44:11,261 DEBUG org.apache.hadoop.yarn.server.resourcemanager.scheduler.capacity.ParentQueue: Skip this queue=root, because it doesn't need more resource, schedulingMode=RESPECT_PARTITION_EXCLUSIVITY node-partition=
2019-06-07 07:44:12,262 DEBUG org.apache.hadoop.yarn.server.resourcemanager.rmnode.RMNodeImpl: Processing slave2:33474 of type STATUS_UPDATE
2019-06-07 07:44:12,262 DEBUG org.apache.hadoop.yarn.server.resourcemanager.rmnode.RMNodeImpl: Processing slave2:33474 of type STATUS_UPDATE
2019-06-07 07:44:12,263 DEBUG org.apache.hadoop.yarn.server.resourcemanager.scheduler.capacity.CapacityScheduler: nodeUpdate: slave2:33474 clusterResources: <memory:8192, vCores:2>
2019-06-07 07:44:12,263 DEBUG org.apache.hadoop.yarn.server.resourcemanager.scheduler.capacity.CapacityScheduler: nodeUpdate: slave2:33474 clusterResources: <memory:8192, vCores:2>
2019-06-07 07:44:12,263 DEBUG org.apache.hadoop.yarn.server.resourcemanager.scheduler.capacity.CapacityScheduler: Node being looked for scheduling slave2:33474 availableResource: <memory:4096, vCores:1>
2019-06-07 07:44:12,263 DEBUG org.apache.hadoop.yarn.server.resourcemanager.scheduler.capacity.CapacityScheduler: Node being looked for scheduling slave2:33474 availableResource: <memory:4096, vCores:1>
2019-06-07 07:44:12,263 DEBUG org.apache.hadoop.yarn.server.resourcemanager.scheduler.capacity.CapacityScheduler: Trying to schedule on node: slave2, available: <memory:4096, vCores:1>
2019-06-07 07:44:12,263 DEBUG org.apache.hadoop.yarn.server.resourcemanager.scheduler.capacity.CapacityScheduler: Trying to schedule on node: slave2, available: <memory:4096, vCores:1>
2019-06-07 07:44:12,263 DEBUG org.apache.hadoop.yarn.server.resourcemanager.rmnode.RMNodeImpl: Processing slave1:35126 of type STATUS_UPDATE
2019-06-07 07:44:12,263 DEBUG org.apache.hadoop.yarn.server.resourcemanager.rmnode.RMNodeImpl: Processing slave1:35126 of type STATUS_UPDATE
2019-06-07 07:44:12,264 DEBUG org.apache.hadoop.yarn.server.resourcemanager.scheduler.capacity.ParentQueue: Skip this queue=root, because it doesn't need more resource, schedulingMode=RESPECT_PARTITION_EXCLUSIVITY node-partition=
2019-06-07 07:44:12,264 DEBUG org.apache.hadoop.yarn.server.resourcemanager.scheduler.capacity.ParentQueue: Skip this queue=root, because it doesn't need more resource, schedulingMode=RESPECT_PARTITION_EXCLUSIVITY node-partition=
2019-06-07 07:44:12,264 DEBUG org.apache.hadoop.yarn.server.resourcemanager.scheduler.capacity.CapacityScheduler: nodeUpdate: slave1:35126 clusterResources: <memory:8192, vCores:2>
2019-06-07 07:44:12,264 DEBUG org.apache.hadoop.yarn.server.resourcemanager.scheduler.capacity.CapacityScheduler: nodeUpdate: slave1:35126 clusterResources: <memory:8192, vCores:2>
2019-06-07 07:44:12,264 DEBUG org.apache.hadoop.yarn.server.resourcemanager.scheduler.capacity.CapacityScheduler: Node being looked for scheduling slave1:35126 availableResource: <memory:4096, vCores:1>
2019-06-07 07:44:12,264 DEBUG org.apache.hadoop.yarn.server.resourcemanager.scheduler.capacity.CapacityScheduler: Node being looked for scheduling slave1:35126 availableResource: <memory:4096, vCores:1>
2019-06-07 07:44:12,264 DEBUG org.apache.hadoop.yarn.server.resourcemanager.scheduler.capacity.CapacityScheduler: Trying to schedule on node: slave1, available: <memory:4096, vCores:1>
2019-06-07 07:44:12,264 DEBUG org.apache.hadoop.yarn.server.resourcemanager.scheduler.capacity.CapacityScheduler: Trying to schedule on node: slave1, available: <memory:4096, vCores:1>
2019-06-07 07:44:12,264 DEBUG org.apache.hadoop.yarn.server.resourcemanager.scheduler.capacity.ParentQueue: Skip this queue=root, because it doesn't need more resource, schedulingMode=RESPECT_PARTITION_EXCLUSIVITY node-partition=
2019-06-07 07:44:12,264 DEBUG org.apache.hadoop.yarn.server.resourcemanager.scheduler.capacity.ParentQueue: Skip this queue=root, because it doesn't need more resource, schedulingMode=RESPECT_PARTITION_EXCLUSIVITY node-partition=
2019-06-07 07:44:13,265 DEBUG org.apache.hadoop.yarn.server.resourcemanager.rmnode.RMNodeImpl: Processing slave2:33474 of type STATUS_UPDATE
2019-06-07 07:44:13,265 DEBUG org.apache.hadoop.yarn.server.resourcemanager.rmnode.RMNodeImpl: Processing slave2:33474 of type STATUS_UPDATE
2019-06-07 07:44:13,265 DEBUG org.apache.hadoop.yarn.server.resourcemanager.scheduler.capacity.CapacityScheduler: nodeUpdate: slave2:33474 clusterResources: <memory:8192, vCores:2>
2019-06-07 07:44:13,265 DEBUG org.apache.hadoop.yarn.server.resourcemanager.scheduler.capacity.CapacityScheduler: nodeUpdate: slave2:33474 clusterResources: <memory:8192, vCores:2>
2019-06-07 07:44:13,265 DEBUG org.apache.hadoop.yarn.server.resourcemanager.scheduler.capacity.CapacityScheduler: Node being looked for scheduling slave2:33474 availableResource: <memory:4096, vCores:1>
2019-06-07 07:44:13,265 DEBUG org.apache.hadoop.yarn.server.resourcemanager.scheduler.capacity.CapacityScheduler: Node being looked for scheduling slave2:33474 availableResource: <memory:4096, vCores:1>
2019-06-07 07:44:13,265 DEBUG org.apache.hadoop.yarn.server.resourcemanager.scheduler.capacity.CapacityScheduler: Trying to schedule on node: slave2, available: <memory:4096, vCores:1>
2019-06-07 07:44:13,265 DEBUG org.apache.hadoop.yarn.server.resourcemanager.scheduler.capacity.CapacityScheduler: Trying to schedule on node: slave2, available: <memory:4096, vCores:1>
2019-06-07 07:44:13,265 DEBUG org.apache.hadoop.yarn.server.resourcemanager.scheduler.capacity.ParentQueue: Skip this queue=root, because it doesn't need more resource, schedulingMode=RESPECT_PARTITION_EXCLUSIVITY node-partition=
2019-06-07 07:44:13,265 DEBUG org.apache.hadoop.yarn.server.resourcemanager.scheduler.capacity.ParentQueue: Skip this queue=root, because it doesn't need more resource, schedulingMode=RESPECT_PARTITION_EXCLUSIVITY node-partition=
2019-06-07 07:44:13,269 DEBUG org.apache.hadoop.yarn.server.resourcemanager.rmnode.RMNodeImpl: Processing slave1:35126 of type STATUS_UPDATE
2019-06-07 07:44:13,269 DEBUG org.apache.hadoop.yarn.server.resourcemanager.rmnode.RMNodeImpl: Processing slave1:35126 of type STATUS_UPDATE
2019-06-07 07:44:13,269 DEBUG org.apache.hadoop.yarn.server.resourcemanager.scheduler.capacity.CapacityScheduler: nodeUpdate: slave1:35126 clusterResources: <memory:8192, vCores:2>
2019-06-07 07:44:13,269 DEBUG org.apache.hadoop.yarn.server.resourcemanager.scheduler.capacity.CapacityScheduler: nodeUpdate: slave1:35126 clusterResources: <memory:8192, vCores:2>
2019-06-07 07:44:13,269 DEBUG org.apache.hadoop.yarn.server.resourcemanager.scheduler.capacity.CapacityScheduler: Node being looked for scheduling slave1:35126 availableResource: <memory:4096, vCores:1>
2019-06-07 07:44:13,269 DEBUG org.apache.hadoop.yarn.server.resourcemanager.scheduler.capacity.CapacityScheduler: Node being looked for scheduling slave1:35126 availableResource: <memory:4096, vCores:1>
2019-06-07 07:44:13,269 DEBUG org.apache.hadoop.yarn.server.resourcemanager.scheduler.capacity.CapacityScheduler: Trying to schedule on node: slave1, available: <memory:4096, vCores:1>
2019-06-07 07:44:13,269 DEBUG org.apache.hadoop.yarn.server.resourcemanager.scheduler.capacity.CapacityScheduler: Trying to schedule on node: slave1, available: <memory:4096, vCores:1>
2019-06-07 07:44:13,269 DEBUG org.apache.hadoop.yarn.server.resourcemanager.scheduler.capacity.ParentQueue: Skip this queue=root, because it doesn't need more resource, schedulingMode=RESPECT_PARTITION_EXCLUSIVITY node-partition=
2019-06-07 07:44:13,269 DEBUG org.apache.hadoop.yarn.server.resourcemanager.scheduler.capacity.ParentQueue: Skip this queue=root, because it doesn't need more resource, schedulingMode=RESPECT_PARTITION_EXCLUSIVITY node-partition=
2019-06-07 07:44:14,270 DEBUG org.apache.hadoop.yarn.server.resourcemanager.rmnode.RMNodeImpl: Processing slave2:33474 of type STATUS_UPDATE
2019-06-07 07:44:14,270 DEBUG org.apache.hadoop.yarn.server.resourcemanager.rmnode.RMNodeImpl: Processing slave2:33474 of type STATUS_UPDATE
2019-06-07 07:44:14,271 DEBUG org.apache.hadoop.yarn.server.resourcemanager.scheduler.capacity.CapacityScheduler: nodeUpdate: slave2:33474 clusterResources: <memory:8192, vCores:2>
2019-06-07 07:44:14,271 DEBUG org.apache.hadoop.yarn.server.resourcemanager.scheduler.capacity.CapacityScheduler: nodeUpdate: slave2:33474 clusterResources: <memory:8192, vCores:2>
2019-06-07 07:44:14,271 DEBUG org.apache.hadoop.yarn.server.resourcemanager.scheduler.capacity.CapacityScheduler: Node being looked for scheduling slave2:33474 availableResource: <memory:4096, vCores:1>
2019-06-07 07:44:14,271 DEBUG org.apache.hadoop.yarn.server.resourcemanager.scheduler.capacity.CapacityScheduler: Node being looked for scheduling slave2:33474 availableResource: <memory:4096, vCores:1>
2019-06-07 07:44:14,271 DEBUG org.apache.hadoop.yarn.server.resourcemanager.scheduler.capacity.CapacityScheduler: Trying to schedule on node: slave2, available: <memory:4096, vCores:1>
2019-06-07 07:44:14,271 DEBUG org.apache.hadoop.yarn.server.resourcemanager.scheduler.capacity.CapacityScheduler: Trying to schedule on node: slave2, available: <memory:4096, vCores:1>
2019-06-07 07:44:14,271 DEBUG org.apache.hadoop.yarn.server.resourcemanager.scheduler.capacity.ParentQueue: Skip this queue=root, because it doesn't need more resource, schedulingMode=RESPECT_PARTITION_EXCLUSIVITY node-partition=
2019-06-07 07:44:14,271 DEBUG org.apache.hadoop.yarn.server.resourcemanager.scheduler.capacity.ParentQueue: Skip this queue=root, because it doesn't need more resource, schedulingMode=RESPECT_PARTITION_EXCLUSIVITY node-partition=
2019-06-07 07:44:14,275 DEBUG org.apache.hadoop.yarn.server.resourcemanager.rmnode.RMNodeImpl: Processing slave1:35126 of type STATUS_UPDATE
2019-06-07 07:44:14,275 DEBUG org.apache.hadoop.yarn.server.resourcemanager.rmnode.RMNodeImpl: Processing slave1:35126 of type STATUS_UPDATE
2019-06-07 07:44:14,275 DEBUG org.apache.hadoop.yarn.server.resourcemanager.scheduler.capacity.CapacityScheduler: nodeUpdate: slave1:35126 clusterResources: <memory:8192, vCores:2>
2019-06-07 07:44:14,275 DEBUG org.apache.hadoop.yarn.server.resourcemanager.scheduler.capacity.CapacityScheduler: nodeUpdate: slave1:35126 clusterResources: <memory:8192, vCores:2>
2019-06-07 07:44:14,275 DEBUG org.apache.hadoop.yarn.server.resourcemanager.scheduler.capacity.CapacityScheduler: Node being looked for scheduling slave1:35126 availableResource: <memory:4096, vCores:1>
2019-06-07 07:44:14,275 DEBUG org.apache.hadoop.yarn.server.resourcemanager.scheduler.capacity.CapacityScheduler: Node being looked for scheduling slave1:35126 availableResource: <memory:4096, vCores:1>
2019-06-07 07:44:14,275 DEBUG org.apache.hadoop.yarn.server.resourcemanager.scheduler.capacity.CapacityScheduler: Trying to schedule on node: slave1, available: <memory:4096, vCores:1>
2019-06-07 07:44:14,275 DEBUG org.apache.hadoop.yarn.server.resourcemanager.scheduler.capacity.CapacityScheduler: Trying to schedule on node: slave1, available: <memory:4096, vCores:1>
2019-06-07 07:44:14,275 DEBUG org.apache.hadoop.yarn.server.resourcemanager.scheduler.capacity.ParentQueue: Skip this queue=root, because it doesn't need more resource, schedulingMode=RESPECT_PARTITION_EXCLUSIVITY node-partition=
2019-06-07 07:44:14,275 DEBUG org.apache.hadoop.yarn.server.resourcemanager.scheduler.capacity.ParentQueue: Skip this queue=root, because it doesn't need more resource, schedulingMode=RESPECT_PARTITION_EXCLUSIVITY node-partition=
2019-06-07 07:44:15,274 DEBUG org.apache.hadoop.yarn.server.resourcemanager.rmnode.RMNodeImpl: Processing slave2:33474 of type STATUS_UPDATE
2019-06-07 07:44:15,274 DEBUG org.apache.hadoop.yarn.server.resourcemanager.rmnode.RMNodeImpl: Processing slave2:33474 of type STATUS_UPDATE
2019-06-07 07:44:15,274 DEBUG org.apache.hadoop.yarn.server.resourcemanager.scheduler.capacity.CapacityScheduler: nodeUpdate: slave2:33474 clusterResources: <memory:8192, vCores:2>
2019-06-07 07:44:15,274 DEBUG org.apache.hadoop.yarn.server.resourcemanager.scheduler.capacity.CapacityScheduler: nodeUpdate: slave2:33474 clusterResources: <memory:8192, vCores:2>
2019-06-07 07:44:15,274 DEBUG org.apache.hadoop.yarn.server.resourcemanager.scheduler.capacity.CapacityScheduler: Node being looked for scheduling slave2:33474 availableResource: <memory:4096, vCores:1>
2019-06-07 07:44:15,274 DEBUG org.apache.hadoop.yarn.server.resourcemanager.scheduler.capacity.CapacityScheduler: Node being looked for scheduling slave2:33474 availableResource: <memory:4096, vCores:1>
2019-06-07 07:44:15,275 DEBUG org.apache.hadoop.yarn.server.resourcemanager.scheduler.capacity.CapacityScheduler: Trying to schedule on node: slave2, available: <memory:4096, vCores:1>
2019-06-07 07:44:15,275 DEBUG org.apache.hadoop.yarn.server.resourcemanager.scheduler.capacity.CapacityScheduler: Trying to schedule on node: slave2, available: <memory:4096, vCores:1>
2019-06-07 07:44:15,279 DEBUG org.apache.hadoop.yarn.server.resourcemanager.scheduler.capacity.ParentQueue: Skip this queue=root, because it doesn't need more resource, schedulingMode=RESPECT_PARTITION_EXCLUSIVITY node-partition=
2019-06-07 07:44:15,279 DEBUG org.apache.hadoop.yarn.server.resourcemanager.scheduler.capacity.ParentQueue: Skip this queue=root, because it doesn't need more resource, schedulingMode=RESPECT_PARTITION_EXCLUSIVITY node-partition=
2019-06-07 07:44:15,280 DEBUG org.apache.hadoop.yarn.server.resourcemanager.rmnode.RMNodeImpl: Processing slave1:35126 of type STATUS_UPDATE
2019-06-07 07:44:15,280 DEBUG org.apache.hadoop.yarn.server.resourcemanager.rmnode.RMNodeImpl: Processing slave1:35126 of type STATUS_UPDATE
2019-06-07 07:44:15,280 DEBUG org.apache.hadoop.yarn.server.resourcemanager.scheduler.capacity.CapacityScheduler: nodeUpdate: slave1:35126 clusterResources: <memory:8192, vCores:2>
2019-06-07 07:44:15,280 DEBUG org.apache.hadoop.yarn.server.resourcemanager.scheduler.capacity.CapacityScheduler: nodeUpdate: slave1:35126 clusterResources: <memory:8192, vCores:2>
2019-06-07 07:44:15,280 DEBUG org.apache.hadoop.yarn.server.resourcemanager.scheduler.capacity.CapacityScheduler: Node being looked for scheduling slave1:35126 availableResource: <memory:4096, vCores:1>
2019-06-07 07:44:15,280 DEBUG org.apache.hadoop.yarn.server.resourcemanager.scheduler.capacity.CapacityScheduler: Node being looked for scheduling slave1:35126 availableResource: <memory:4096, vCores:1>
2019-06-07 07:44:15,280 DEBUG org.apache.hadoop.yarn.server.resourcemanager.scheduler.capacity.CapacityScheduler: Trying to schedule on node: slave1, available: <memory:4096, vCores:1>
2019-06-07 07:44:15,280 DEBUG org.apache.hadoop.yarn.server.resourcemanager.scheduler.capacity.CapacityScheduler: Trying to schedule on node: slave1, available: <memory:4096, vCores:1>
2019-06-07 07:44:15,280 DEBUG org.apache.hadoop.yarn.server.resourcemanager.scheduler.capacity.ParentQueue: Skip this queue=root, because it doesn't need more resource, schedulingMode=RESPECT_PARTITION_EXCLUSIVITY node-partition=
2019-06-07 07:44:15,280 DEBUG org.apache.hadoop.yarn.server.resourcemanager.scheduler.capacity.ParentQueue: Skip this queue=root, because it doesn't need more resource, schedulingMode=RESPECT_PARTITION_EXCLUSIVITY node-partition=
2019-06-07 07:44:16,276 DEBUG org.apache.hadoop.yarn.server.resourcemanager.rmnode.RMNodeImpl: Processing slave2:33474 of type STATUS_UPDATE
2019-06-07 07:44:16,276 DEBUG org.apache.hadoop.yarn.server.resourcemanager.rmnode.RMNodeImpl: Processing slave2:33474 of type STATUS_UPDATE
2019-06-07 07:44:16,276 DEBUG org.apache.hadoop.yarn.server.resourcemanager.scheduler.capacity.CapacityScheduler: nodeUpdate: slave2:33474 clusterResources: <memory:8192, vCores:2>
2019-06-07 07:44:16,276 DEBUG org.apache.hadoop.yarn.server.resourcemanager.scheduler.capacity.CapacityScheduler: nodeUpdate: slave2:33474 clusterResources: <memory:8192, vCores:2>
2019-06-07 07:44:16,276 DEBUG org.apache.hadoop.yarn.server.resourcemanager.scheduler.capacity.CapacityScheduler: Node being looked for scheduling slave2:33474 availableResource: <memory:4096, vCores:1>
2019-06-07 07:44:16,276 DEBUG org.apache.hadoop.yarn.server.resourcemanager.scheduler.capacity.CapacityScheduler: Node being looked for scheduling slave2:33474 availableResource: <memory:4096, vCores:1>
2019-06-07 07:44:16,276 DEBUG org.apache.hadoop.yarn.server.resourcemanager.scheduler.capacity.CapacityScheduler: Trying to schedule on node: slave2, available: <memory:4096, vCores:1>
2019-06-07 07:44:16,276 DEBUG org.apache.hadoop.yarn.server.resourcemanager.scheduler.capacity.CapacityScheduler: Trying to schedule on node: slave2, available: <memory:4096, vCores:1>
2019-06-07 07:44:16,276 DEBUG org.apache.hadoop.yarn.server.resourcemanager.scheduler.capacity.ParentQueue: Skip this queue=root, because it doesn't need more resource, schedulingMode=RESPECT_PARTITION_EXCLUSIVITY node-partition=
2019-06-07 07:44:16,276 DEBUG org.apache.hadoop.yarn.server.resourcemanager.scheduler.capacity.ParentQueue: Skip this queue=root, because it doesn't need more resource, schedulingMode=RESPECT_PARTITION_EXCLUSIVITY node-partition=
2019-06-07 07:44:16,284 DEBUG org.apache.hadoop.yarn.server.resourcemanager.rmnode.RMNodeImpl: Processing slave1:35126 of type STATUS_UPDATE
2019-06-07 07:44:16,284 DEBUG org.apache.hadoop.yarn.server.resourcemanager.rmnode.RMNodeImpl: Processing slave1:35126 of type STATUS_UPDATE
2019-06-07 07:44:16,284 DEBUG org.apache.hadoop.yarn.server.resourcemanager.scheduler.capacity.CapacityScheduler: nodeUpdate: slave1:35126 clusterResources: <memory:8192, vCores:2>
2019-06-07 07:44:16,284 DEBUG org.apache.hadoop.yarn.server.resourcemanager.scheduler.capacity.CapacityScheduler: nodeUpdate: slave1:35126 clusterResources: <memory:8192, vCores:2>
2019-06-07 07:44:16,284 DEBUG org.apache.hadoop.yarn.server.resourcemanager.scheduler.capacity.CapacityScheduler: Node being looked for scheduling slave1:35126 availableResource: <memory:4096, vCores:1>
2019-06-07 07:44:16,284 DEBUG org.apache.hadoop.yarn.server.resourcemanager.scheduler.capacity.CapacityScheduler: Node being looked for scheduling slave1:35126 availableResource: <memory:4096, vCores:1>
2019-06-07 07:44:16,284 DEBUG org.apache.hadoop.yarn.server.resourcemanager.scheduler.capacity.CapacityScheduler: Trying to schedule on node: slave1, available: <memory:4096, vCores:1>
2019-06-07 07:44:16,284 DEBUG org.apache.hadoop.yarn.server.resourcemanager.scheduler.capacity.CapacityScheduler: Trying to schedule on node: slave1, available: <memory:4096, vCores:1>
2019-06-07 07:44:16,284 DEBUG org.apache.hadoop.yarn.server.resourcemanager.scheduler.capacity.ParentQueue: Skip this queue=root, because it doesn't need more resource, schedulingMode=RESPECT_PARTITION_EXCLUSIVITY node-partition=
2019-06-07 07:44:16,284 DEBUG org.apache.hadoop.yarn.server.resourcemanager.scheduler.capacity.ParentQueue: Skip this queue=root, because it doesn't need more resource, schedulingMode=RESPECT_PARTITION_EXCLUSIVITY node-partition=
2019-06-07 07:44:17,280 DEBUG org.apache.hadoop.yarn.server.resourcemanager.rmnode.RMNodeImpl: Processing slave2:33474 of type STATUS_UPDATE
2019-06-07 07:44:17,280 DEBUG org.apache.hadoop.yarn.server.resourcemanager.rmnode.RMNodeImpl: Processing slave2:33474 of type STATUS_UPDATE
2019-06-07 07:44:17,280 DEBUG org.apache.hadoop.yarn.server.resourcemanager.scheduler.capacity.CapacityScheduler: nodeUpdate: slave2:33474 clusterResources: <memory:8192, vCores:2>
2019-06-07 07:44:17,280 DEBUG org.apache.hadoop.yarn.server.resourcemanager.scheduler.capacity.CapacityScheduler: nodeUpdate: slave2:33474 clusterResources: <memory:8192, vCores:2>
2019-06-07 07:44:17,280 DEBUG org.apache.hadoop.yarn.server.resourcemanager.scheduler.capacity.CapacityScheduler: Node being looked for scheduling slave2:33474 availableResource: <memory:4096, vCores:1>
2019-06-07 07:44:17,280 DEBUG org.apache.hadoop.yarn.server.resourcemanager.scheduler.capacity.CapacityScheduler: Node being looked for scheduling slave2:33474 availableResource: <memory:4096, vCores:1>
2019-06-07 07:44:17,280 DEBUG org.apache.hadoop.yarn.server.resourcemanager.scheduler.capacity.CapacityScheduler: Trying to schedule on node: slave2, available: <memory:4096, vCores:1>
2019-06-07 07:44:17,280 DEBUG org.apache.hadoop.yarn.server.resourcemanager.scheduler.capacity.CapacityScheduler: Trying to schedule on node: slave2, available: <memory:4096, vCores:1>
2019-06-07 07:44:17,280 DEBUG org.apache.hadoop.yarn.server.resourcemanager.scheduler.capacity.ParentQueue: Skip this queue=root, because it doesn't need more resource, schedulingMode=RESPECT_PARTITION_EXCLUSIVITY node-partition=
2019-06-07 07:44:17,280 DEBUG org.apache.hadoop.yarn.server.resourcemanager.scheduler.capacity.ParentQueue: Skip this queue=root, because it doesn't need more resource, schedulingMode=RESPECT_PARTITION_EXCLUSIVITY node-partition=
2019-06-07 07:44:17,287 DEBUG org.apache.hadoop.yarn.server.resourcemanager.rmnode.RMNodeImpl: Processing slave1:35126 of type STATUS_UPDATE
2019-06-07 07:44:17,287 DEBUG org.apache.hadoop.yarn.server.resourcemanager.rmnode.RMNodeImpl: Processing slave1:35126 of type STATUS_UPDATE
2019-06-07 07:44:17,287 DEBUG org.apache.hadoop.yarn.server.resourcemanager.scheduler.capacity.CapacityScheduler: nodeUpdate: slave1:35126 clusterResources: <memory:8192, vCores:2>
2019-06-07 07:44:17,287 DEBUG org.apache.hadoop.yarn.server.resourcemanager.scheduler.capacity.CapacityScheduler: nodeUpdate: slave1:35126 clusterResources: <memory:8192, vCores:2>
2019-06-07 07:44:17,287 DEBUG org.apache.hadoop.yarn.server.resourcemanager.scheduler.capacity.CapacityScheduler: Node being looked for scheduling slave1:35126 availableResource: <memory:4096, vCores:1>
2019-06-07 07:44:17,287 DEBUG org.apache.hadoop.yarn.server.resourcemanager.scheduler.capacity.CapacityScheduler: Node being looked for scheduling slave1:35126 availableResource: <memory:4096, vCores:1>
2019-06-07 07:44:17,287 DEBUG org.apache.hadoop.yarn.server.resourcemanager.scheduler.capacity.CapacityScheduler: Trying to schedule on node: slave1, available: <memory:4096, vCores:1>
2019-06-07 07:44:17,287 DEBUG org.apache.hadoop.yarn.server.resourcemanager.scheduler.capacity.CapacityScheduler: Trying to schedule on node: slave1, available: <memory:4096, vCores:1>
2019-06-07 07:44:17,287 DEBUG org.apache.hadoop.yarn.server.resourcemanager.scheduler.capacity.ParentQueue: Skip this queue=root, because it doesn't need more resource, schedulingMode=RESPECT_PARTITION_EXCLUSIVITY node-partition=
2019-06-07 07:44:17,287 DEBUG org.apache.hadoop.yarn.server.resourcemanager.scheduler.capacity.ParentQueue: Skip this queue=root, because it doesn't need more resource, schedulingMode=RESPECT_PARTITION_EXCLUSIVITY node-partition=
2019-06-07 07:44:18,283 DEBUG org.apache.hadoop.yarn.server.resourcemanager.rmnode.RMNodeImpl: Processing slave2:33474 of type STATUS_UPDATE
2019-06-07 07:44:18,283 DEBUG org.apache.hadoop.yarn.server.resourcemanager.rmnode.RMNodeImpl: Processing slave2:33474 of type STATUS_UPDATE
2019-06-07 07:44:18,283 DEBUG org.apache.hadoop.yarn.server.resourcemanager.scheduler.capacity.CapacityScheduler: nodeUpdate: slave2:33474 clusterResources: <memory:8192, vCores:2>
2019-06-07 07:44:18,283 DEBUG org.apache.hadoop.yarn.server.resourcemanager.scheduler.capacity.CapacityScheduler: nodeUpdate: slave2:33474 clusterResources: <memory:8192, vCores:2>
2019-06-07 07:44:18,283 DEBUG org.apache.hadoop.yarn.server.resourcemanager.scheduler.capacity.CapacityScheduler: Node being looked for scheduling slave2:33474 availableResource: <memory:4096, vCores:1>
2019-06-07 07:44:18,283 DEBUG org.apache.hadoop.yarn.server.resourcemanager.scheduler.capacity.CapacityScheduler: Node being looked for scheduling slave2:33474 availableResource: <memory:4096, vCores:1>
2019-06-07 07:44:18,283 DEBUG org.apache.hadoop.yarn.server.resourcemanager.scheduler.capacity.CapacityScheduler: Trying to schedule on node: slave2, available: <memory:4096, vCores:1>
2019-06-07 07:44:18,283 DEBUG org.apache.hadoop.yarn.server.resourcemanager.scheduler.capacity.CapacityScheduler: Trying to schedule on node: slave2, available: <memory:4096, vCores:1>
2019-06-07 07:44:18,283 DEBUG org.apache.hadoop.yarn.server.resourcemanager.scheduler.capacity.ParentQueue: Skip this queue=root, because it doesn't need more resource, schedulingMode=RESPECT_PARTITION_EXCLUSIVITY node-partition=
2019-06-07 07:44:18,283 DEBUG org.apache.hadoop.yarn.server.resourcemanager.scheduler.capacity.ParentQueue: Skip this queue=root, because it doesn't need more resource, schedulingMode=RESPECT_PARTITION_EXCLUSIVITY node-partition=
2019-06-07 07:44:18,290 DEBUG org.apache.hadoop.yarn.server.resourcemanager.rmnode.RMNodeImpl: Processing slave1:35126 of type STATUS_UPDATE
2019-06-07 07:44:18,290 DEBUG org.apache.hadoop.yarn.server.resourcemanager.rmnode.RMNodeImpl: Processing slave1:35126 of type STATUS_UPDATE
2019-06-07 07:44:18,290 DEBUG org.apache.hadoop.yarn.server.resourcemanager.scheduler.capacity.CapacityScheduler: nodeUpdate: slave1:35126 clusterResources: <memory:8192, vCores:2>
2019-06-07 07:44:18,290 DEBUG org.apache.hadoop.yarn.server.resourcemanager.scheduler.capacity.CapacityScheduler: nodeUpdate: slave1:35126 clusterResources: <memory:8192, vCores:2>
2019-06-07 07:44:18,290 DEBUG org.apache.hadoop.yarn.server.resourcemanager.scheduler.capacity.CapacityScheduler: Node being looked for scheduling slave1:35126 availableResource: <memory:4096, vCores:1>
2019-06-07 07:44:18,290 DEBUG org.apache.hadoop.yarn.server.resourcemanager.scheduler.capacity.CapacityScheduler: Node being looked for scheduling slave1:35126 availableResource: <memory:4096, vCores:1>
2019-06-07 07:44:18,290 DEBUG org.apache.hadoop.yarn.server.resourcemanager.scheduler.capacity.CapacityScheduler: Trying to schedule on node: slave1, available: <memory:4096, vCores:1>
2019-06-07 07:44:18,290 DEBUG org.apache.hadoop.yarn.server.resourcemanager.scheduler.capacity.CapacityScheduler: Trying to schedule on node: slave1, available: <memory:4096, vCores:1>
2019-06-07 07:44:18,290 DEBUG org.apache.hadoop.yarn.server.resourcemanager.scheduler.capacity.ParentQueue: Skip this queue=root, because it doesn't need more resource, schedulingMode=RESPECT_PARTITION_EXCLUSIVITY node-partition=
2019-06-07 07:44:18,290 DEBUG org.apache.hadoop.yarn.server.resourcemanager.scheduler.capacity.ParentQueue: Skip this queue=root, because it doesn't need more resource, schedulingMode=RESPECT_PARTITION_EXCLUSIVITY node-partition=
2019-06-07 07:44:19,286 DEBUG org.apache.hadoop.yarn.server.resourcemanager.rmnode.RMNodeImpl: Processing slave2:33474 of type STATUS_UPDATE
2019-06-07 07:44:19,286 DEBUG org.apache.hadoop.yarn.server.resourcemanager.rmnode.RMNodeImpl: Processing slave2:33474 of type STATUS_UPDATE
2019-06-07 07:44:19,287 DEBUG org.apache.hadoop.yarn.server.resourcemanager.scheduler.capacity.CapacityScheduler: nodeUpdate: slave2:33474 clusterResources: <memory:8192, vCores:2>
2019-06-07 07:44:19,287 DEBUG org.apache.hadoop.yarn.server.resourcemanager.scheduler.capacity.CapacityScheduler: nodeUpdate: slave2:33474 clusterResources: <memory:8192, vCores:2>
2019-06-07 07:44:19,287 DEBUG org.apache.hadoop.yarn.server.resourcemanager.scheduler.capacity.CapacityScheduler: Node being looked for scheduling slave2:33474 availableResource: <memory:4096, vCores:1>
2019-06-07 07:44:19,287 DEBUG org.apache.hadoop.yarn.server.resourcemanager.scheduler.capacity.CapacityScheduler: Node being looked for scheduling slave2:33474 availableResource: <memory:4096, vCores:1>
2019-06-07 07:44:19,287 DEBUG org.apache.hadoop.yarn.server.resourcemanager.scheduler.capacity.CapacityScheduler: Trying to schedule on node: slave2, available: <memory:4096, vCores:1>
2019-06-07 07:44:19,287 DEBUG org.apache.hadoop.yarn.server.resourcemanager.scheduler.capacity.CapacityScheduler: Trying to schedule on node: slave2, available: <memory:4096, vCores:1>
2019-06-07 07:44:19,287 DEBUG org.apache.hadoop.yarn.server.resourcemanager.scheduler.capacity.ParentQueue: Skip this queue=root, because it doesn't need more resource, schedulingMode=RESPECT_PARTITION_EXCLUSIVITY node-partition=
2019-06-07 07:44:19,287 DEBUG org.apache.hadoop.yarn.server.resourcemanager.scheduler.capacity.ParentQueue: Skip this queue=root, because it doesn't need more resource, schedulingMode=RESPECT_PARTITION_EXCLUSIVITY node-partition=
2019-06-07 07:44:19,294 DEBUG org.apache.hadoop.yarn.server.resourcemanager.rmnode.RMNodeImpl: Processing slave1:35126 of type STATUS_UPDATE
2019-06-07 07:44:19,294 DEBUG org.apache.hadoop.yarn.server.resourcemanager.rmnode.RMNodeImpl: Processing slave1:35126 of type STATUS_UPDATE
2019-06-07 07:44:19,294 DEBUG org.apache.hadoop.yarn.server.resourcemanager.scheduler.capacity.CapacityScheduler: nodeUpdate: slave1:35126 clusterResources: <memory:8192, vCores:2>
2019-06-07 07:44:19,294 DEBUG org.apache.hadoop.yarn.server.resourcemanager.scheduler.capacity.CapacityScheduler: nodeUpdate: slave1:35126 clusterResources: <memory:8192, vCores:2>
2019-06-07 07:44:19,295 DEBUG org.apache.hadoop.yarn.server.resourcemanager.scheduler.capacity.CapacityScheduler: Node being looked for scheduling slave1:35126 availableResource: <memory:4096, vCores:1>
2019-06-07 07:44:19,295 DEBUG org.apache.hadoop.yarn.server.resourcemanager.scheduler.capacity.CapacityScheduler: Node being looked for scheduling slave1:35126 availableResource: <memory:4096, vCores:1>
2019-06-07 07:44:19,295 DEBUG org.apache.hadoop.yarn.server.resourcemanager.scheduler.capacity.CapacityScheduler: Trying to schedule on node: slave1, available: <memory:4096, vCores:1>
2019-06-07 07:44:19,295 DEBUG org.apache.hadoop.yarn.server.resourcemanager.scheduler.capacity.CapacityScheduler: Trying to schedule on node: slave1, available: <memory:4096, vCores:1>
2019-06-07 07:44:19,295 DEBUG org.apache.hadoop.yarn.server.resourcemanager.scheduler.capacity.ParentQueue: Skip this queue=root, because it doesn't need more resource, schedulingMode=RESPECT_PARTITION_EXCLUSIVITY node-partition=
2019-06-07 07:44:19,295 DEBUG org.apache.hadoop.yarn.server.resourcemanager.scheduler.capacity.ParentQueue: Skip this queue=root, because it doesn't need more resource, schedulingMode=RESPECT_PARTITION_EXCLUSIVITY node-partition=
2019-06-07 07:44:20,290 DEBUG org.apache.hadoop.yarn.server.resourcemanager.rmnode.RMNodeImpl: Processing slave2:33474 of type STATUS_UPDATE
2019-06-07 07:44:20,290 DEBUG org.apache.hadoop.yarn.server.resourcemanager.rmnode.RMNodeImpl: Processing slave2:33474 of type STATUS_UPDATE
2019-06-07 07:44:20,290 DEBUG org.apache.hadoop.yarn.server.resourcemanager.scheduler.capacity.CapacityScheduler: nodeUpdate: slave2:33474 clusterResources: <memory:8192, vCores:2>
2019-06-07 07:44:20,290 DEBUG org.apache.hadoop.yarn.server.resourcemanager.scheduler.capacity.CapacityScheduler: nodeUpdate: slave2:33474 clusterResources: <memory:8192, vCores:2>
2019-06-07 07:44:20,290 DEBUG org.apache.hadoop.yarn.server.resourcemanager.scheduler.capacity.CapacityScheduler: Node being looked for scheduling slave2:33474 availableResource: <memory:4096, vCores:1>
2019-06-07 07:44:20,290 DEBUG org.apache.hadoop.yarn.server.resourcemanager.scheduler.capacity.CapacityScheduler: Node being looked for scheduling slave2:33474 availableResource: <memory:4096, vCores:1>
2019-06-07 07:44:20,290 DEBUG org.apache.hadoop.yarn.server.resourcemanager.scheduler.capacity.CapacityScheduler: Trying to schedule on node: slave2, available: <memory:4096, vCores:1>
2019-06-07 07:44:20,290 DEBUG org.apache.hadoop.yarn.server.resourcemanager.scheduler.capacity.CapacityScheduler: Trying to schedule on node: slave2, available: <memory:4096, vCores:1>
2019-06-07 07:44:20,290 DEBUG org.apache.hadoop.yarn.server.resourcemanager.scheduler.capacity.ParentQueue: Skip this queue=root, because it doesn't need more resource, schedulingMode=RESPECT_PARTITION_EXCLUSIVITY node-partition=
2019-06-07 07:44:20,290 DEBUG org.apache.hadoop.yarn.server.resourcemanager.scheduler.capacity.ParentQueue: Skip this queue=root, because it doesn't need more resource, schedulingMode=RESPECT_PARTITION_EXCLUSIVITY node-partition=
2019-06-07 07:44:20,297 DEBUG org.apache.hadoop.yarn.server.resourcemanager.rmnode.RMNodeImpl: Processing slave1:35126 of type STATUS_UPDATE
2019-06-07 07:44:20,297 DEBUG org.apache.hadoop.yarn.server.resourcemanager.rmnode.RMNodeImpl: Processing slave1:35126 of type STATUS_UPDATE
2019-06-07 07:44:20,298 DEBUG org.apache.hadoop.yarn.server.resourcemanager.scheduler.capacity.CapacityScheduler: nodeUpdate: slave1:35126 clusterResources: <memory:8192, vCores:2>
2019-06-07 07:44:20,298 DEBUG org.apache.hadoop.yarn.server.resourcemanager.scheduler.capacity.CapacityScheduler: nodeUpdate: slave1:35126 clusterResources: <memory:8192, vCores:2>
2019-06-07 07:44:20,298 DEBUG org.apache.hadoop.yarn.server.resourcemanager.scheduler.capacity.CapacityScheduler: Node being looked for scheduling slave1:35126 availableResource: <memory:4096, vCores:1>
2019-06-07 07:44:20,298 DEBUG org.apache.hadoop.yarn.server.resourcemanager.scheduler.capacity.CapacityScheduler: Node being looked for scheduling slave1:35126 availableResource: <memory:4096, vCores:1>
2019-06-07 07:44:20,298 DEBUG org.apache.hadoop.yarn.server.resourcemanager.scheduler.capacity.CapacityScheduler: Trying to schedule on node: slave1, available: <memory:4096, vCores:1>
2019-06-07 07:44:20,298 DEBUG org.apache.hadoop.yarn.server.resourcemanager.scheduler.capacity.CapacityScheduler: Trying to schedule on node: slave1, available: <memory:4096, vCores:1>
2019-06-07 07:44:20,298 DEBUG org.apache.hadoop.yarn.server.resourcemanager.scheduler.capacity.ParentQueue: Skip this queue=root, because it doesn't need more resource, schedulingMode=RESPECT_PARTITION_EXCLUSIVITY node-partition=
2019-06-07 07:44:20,298 DEBUG org.apache.hadoop.yarn.server.resourcemanager.scheduler.capacity.ParentQueue: Skip this queue=root, because it doesn't need more resource, schedulingMode=RESPECT_PARTITION_EXCLUSIVITY node-partition=
2019-06-07 07:44:20,894 INFO org.apache.hadoop.yarn.server.resourcemanager.ClientRMService: Allocated new applicationId: 1
2019-06-07 07:44:20,894 INFO org.apache.hadoop.yarn.server.resourcemanager.ClientRMService: Allocated new applicationId: 1
2019-06-07 07:44:21,293 DEBUG org.apache.hadoop.yarn.server.resourcemanager.rmnode.RMNodeImpl: Processing slave2:33474 of type STATUS_UPDATE
2019-06-07 07:44:21,293 DEBUG org.apache.hadoop.yarn.server.resourcemanager.rmnode.RMNodeImpl: Processing slave2:33474 of type STATUS_UPDATE
2019-06-07 07:44:21,293 DEBUG org.apache.hadoop.yarn.server.resourcemanager.scheduler.capacity.CapacityScheduler: nodeUpdate: slave2:33474 clusterResources: <memory:8192, vCores:2>
2019-06-07 07:44:21,293 DEBUG org.apache.hadoop.yarn.server.resourcemanager.scheduler.capacity.CapacityScheduler: nodeUpdate: slave2:33474 clusterResources: <memory:8192, vCores:2>
2019-06-07 07:44:21,293 DEBUG org.apache.hadoop.yarn.server.resourcemanager.scheduler.capacity.CapacityScheduler: Node being looked for scheduling slave2:33474 availableResource: <memory:4096, vCores:1>
2019-06-07 07:44:21,293 DEBUG org.apache.hadoop.yarn.server.resourcemanager.scheduler.capacity.CapacityScheduler: Node being looked for scheduling slave2:33474 availableResource: <memory:4096, vCores:1>
2019-06-07 07:44:21,293 DEBUG org.apache.hadoop.yarn.server.resourcemanager.scheduler.capacity.CapacityScheduler: Trying to schedule on node: slave2, available: <memory:4096, vCores:1>
2019-06-07 07:44:21,293 DEBUG org.apache.hadoop.yarn.server.resourcemanager.scheduler.capacity.CapacityScheduler: Trying to schedule on node: slave2, available: <memory:4096, vCores:1>
2019-06-07 07:44:21,293 DEBUG org.apache.hadoop.yarn.server.resourcemanager.scheduler.capacity.ParentQueue: Skip this queue=root, because it doesn't need more resource, schedulingMode=RESPECT_PARTITION_EXCLUSIVITY node-partition=
2019-06-07 07:44:21,293 DEBUG org.apache.hadoop.yarn.server.resourcemanager.scheduler.capacity.ParentQueue: Skip this queue=root, because it doesn't need more resource, schedulingMode=RESPECT_PARTITION_EXCLUSIVITY node-partition=
2019-06-07 07:44:21,300 DEBUG org.apache.hadoop.yarn.server.resourcemanager.rmnode.RMNodeImpl: Processing slave1:35126 of type STATUS_UPDATE
2019-06-07 07:44:21,300 DEBUG org.apache.hadoop.yarn.server.resourcemanager.rmnode.RMNodeImpl: Processing slave1:35126 of type STATUS_UPDATE
2019-06-07 07:44:21,301 DEBUG org.apache.hadoop.yarn.server.resourcemanager.scheduler.capacity.CapacityScheduler: nodeUpdate: slave1:35126 clusterResources: <memory:8192, vCores:2>
2019-06-07 07:44:21,301 DEBUG org.apache.hadoop.yarn.server.resourcemanager.scheduler.capacity.CapacityScheduler: nodeUpdate: slave1:35126 clusterResources: <memory:8192, vCores:2>
2019-06-07 07:44:21,301 DEBUG org.apache.hadoop.yarn.server.resourcemanager.scheduler.capacity.CapacityScheduler: Node being looked for scheduling slave1:35126 availableResource: <memory:4096, vCores:1>
2019-06-07 07:44:21,301 DEBUG org.apache.hadoop.yarn.server.resourcemanager.scheduler.capacity.CapacityScheduler: Node being looked for scheduling slave1:35126 availableResource: <memory:4096, vCores:1>
2019-06-07 07:44:21,301 DEBUG org.apache.hadoop.yarn.server.resourcemanager.scheduler.capacity.CapacityScheduler: Trying to schedule on node: slave1, available: <memory:4096, vCores:1>
2019-06-07 07:44:21,301 DEBUG org.apache.hadoop.yarn.server.resourcemanager.scheduler.capacity.CapacityScheduler: Trying to schedule on node: slave1, available: <memory:4096, vCores:1>
2019-06-07 07:44:21,301 DEBUG org.apache.hadoop.yarn.server.resourcemanager.scheduler.capacity.ParentQueue: Skip this queue=root, because it doesn't need more resource, schedulingMode=RESPECT_PARTITION_EXCLUSIVITY node-partition=
2019-06-07 07:44:21,301 DEBUG org.apache.hadoop.yarn.server.resourcemanager.scheduler.capacity.ParentQueue: Skip this queue=root, because it doesn't need more resource, schedulingMode=RESPECT_PARTITION_EXCLUSIVITY node-partition=
2019-06-07 07:44:22,295 DEBUG org.apache.hadoop.yarn.server.resourcemanager.rmnode.RMNodeImpl: Processing slave2:33474 of type STATUS_UPDATE
2019-06-07 07:44:22,295 DEBUG org.apache.hadoop.yarn.server.resourcemanager.rmnode.RMNodeImpl: Processing slave2:33474 of type STATUS_UPDATE
2019-06-07 07:44:22,295 DEBUG org.apache.hadoop.yarn.server.resourcemanager.scheduler.capacity.CapacityScheduler: nodeUpdate: slave2:33474 clusterResources: <memory:8192, vCores:2>
2019-06-07 07:44:22,295 DEBUG org.apache.hadoop.yarn.server.resourcemanager.scheduler.capacity.CapacityScheduler: nodeUpdate: slave2:33474 clusterResources: <memory:8192, vCores:2>
2019-06-07 07:44:22,295 DEBUG org.apache.hadoop.yarn.server.resourcemanager.scheduler.capacity.CapacityScheduler: Node being looked for scheduling slave2:33474 availableResource: <memory:4096, vCores:1>
2019-06-07 07:44:22,295 DEBUG org.apache.hadoop.yarn.server.resourcemanager.scheduler.capacity.CapacityScheduler: Node being looked for scheduling slave2:33474 availableResource: <memory:4096, vCores:1>
2019-06-07 07:44:22,295 DEBUG org.apache.hadoop.yarn.server.resourcemanager.scheduler.capacity.CapacityScheduler: Trying to schedule on node: slave2, available: <memory:4096, vCores:1>
2019-06-07 07:44:22,295 DEBUG org.apache.hadoop.yarn.server.resourcemanager.scheduler.capacity.CapacityScheduler: Trying to schedule on node: slave2, available: <memory:4096, vCores:1>
2019-06-07 07:44:22,295 DEBUG org.apache.hadoop.yarn.server.resourcemanager.scheduler.capacity.ParentQueue: Skip this queue=root, because it doesn't need more resource, schedulingMode=RESPECT_PARTITION_EXCLUSIVITY node-partition=
2019-06-07 07:44:22,295 DEBUG org.apache.hadoop.yarn.server.resourcemanager.scheduler.capacity.ParentQueue: Skip this queue=root, because it doesn't need more resource, schedulingMode=RESPECT_PARTITION_EXCLUSIVITY node-partition=
2019-06-07 07:44:22,302 DEBUG org.apache.hadoop.yarn.server.resourcemanager.rmnode.RMNodeImpl: Processing slave1:35126 of type STATUS_UPDATE
2019-06-07 07:44:22,302 DEBUG org.apache.hadoop.yarn.server.resourcemanager.rmnode.RMNodeImpl: Processing slave1:35126 of type STATUS_UPDATE
2019-06-07 07:44:22,302 DEBUG org.apache.hadoop.yarn.server.resourcemanager.scheduler.capacity.CapacityScheduler: nodeUpdate: slave1:35126 clusterResources: <memory:8192, vCores:2>
2019-06-07 07:44:22,302 DEBUG org.apache.hadoop.yarn.server.resourcemanager.scheduler.capacity.CapacityScheduler: nodeUpdate: slave1:35126 clusterResources: <memory:8192, vCores:2>
2019-06-07 07:44:22,302 DEBUG org.apache.hadoop.yarn.server.resourcemanager.scheduler.capacity.CapacityScheduler: Node being looked for scheduling slave1:35126 availableResource: <memory:4096, vCores:1>
2019-06-07 07:44:22,302 DEBUG org.apache.hadoop.yarn.server.resourcemanager.scheduler.capacity.CapacityScheduler: Node being looked for scheduling slave1:35126 availableResource: <memory:4096, vCores:1>
2019-06-07 07:44:22,302 DEBUG org.apache.hadoop.yarn.server.resourcemanager.scheduler.capacity.CapacityScheduler: Trying to schedule on node: slave1, available: <memory:4096, vCores:1>
2019-06-07 07:44:22,302 DEBUG org.apache.hadoop.yarn.server.resourcemanager.scheduler.capacity.CapacityScheduler: Trying to schedule on node: slave1, available: <memory:4096, vCores:1>
2019-06-07 07:44:22,302 DEBUG org.apache.hadoop.yarn.server.resourcemanager.scheduler.capacity.ParentQueue: Skip this queue=root, because it doesn't need more resource, schedulingMode=RESPECT_PARTITION_EXCLUSIVITY node-partition=
2019-06-07 07:44:22,302 DEBUG org.apache.hadoop.yarn.server.resourcemanager.scheduler.capacity.ParentQueue: Skip this queue=root, because it doesn't need more resource, schedulingMode=RESPECT_PARTITION_EXCLUSIVITY node-partition=
2019-06-07 07:44:23,302 DEBUG org.apache.hadoop.yarn.server.resourcemanager.rmnode.RMNodeImpl: Processing slave2:33474 of type STATUS_UPDATE
2019-06-07 07:44:23,302 DEBUG org.apache.hadoop.yarn.server.resourcemanager.rmnode.RMNodeImpl: Processing slave2:33474 of type STATUS_UPDATE
2019-06-07 07:44:23,302 DEBUG org.apache.hadoop.yarn.server.resourcemanager.scheduler.capacity.CapacityScheduler: nodeUpdate: slave2:33474 clusterResources: <memory:8192, vCores:2>
2019-06-07 07:44:23,302 DEBUG org.apache.hadoop.yarn.server.resourcemanager.scheduler.capacity.CapacityScheduler: nodeUpdate: slave2:33474 clusterResources: <memory:8192, vCores:2>
2019-06-07 07:44:23,302 DEBUG org.apache.hadoop.yarn.server.resourcemanager.scheduler.capacity.CapacityScheduler: Node being looked for scheduling slave2:33474 availableResource: <memory:4096, vCores:1>
2019-06-07 07:44:23,302 DEBUG org.apache.hadoop.yarn.server.resourcemanager.scheduler.capacity.CapacityScheduler: Node being looked for scheduling slave2:33474 availableResource: <memory:4096, vCores:1>
2019-06-07 07:44:23,302 DEBUG org.apache.hadoop.yarn.server.resourcemanager.scheduler.capacity.CapacityScheduler: Trying to schedule on node: slave2, available: <memory:4096, vCores:1>
2019-06-07 07:44:23,302 DEBUG org.apache.hadoop.yarn.server.resourcemanager.scheduler.capacity.CapacityScheduler: Trying to schedule on node: slave2, available: <memory:4096, vCores:1>
2019-06-07 07:44:23,302 DEBUG org.apache.hadoop.yarn.server.resourcemanager.scheduler.capacity.ParentQueue: Skip this queue=root, because it doesn't need more resource, schedulingMode=RESPECT_PARTITION_EXCLUSIVITY node-partition=
2019-06-07 07:44:23,302 DEBUG org.apache.hadoop.yarn.server.resourcemanager.scheduler.capacity.ParentQueue: Skip this queue=root, because it doesn't need more resource, schedulingMode=RESPECT_PARTITION_EXCLUSIVITY node-partition=
2019-06-07 07:44:23,306 DEBUG org.apache.hadoop.yarn.server.resourcemanager.rmnode.RMNodeImpl: Processing slave1:35126 of type STATUS_UPDATE
2019-06-07 07:44:23,306 DEBUG org.apache.hadoop.yarn.server.resourcemanager.rmnode.RMNodeImpl: Processing slave1:35126 of type STATUS_UPDATE
2019-06-07 07:44:23,306 DEBUG org.apache.hadoop.yarn.server.resourcemanager.scheduler.capacity.CapacityScheduler: nodeUpdate: slave1:35126 clusterResources: <memory:8192, vCores:2>
2019-06-07 07:44:23,306 DEBUG org.apache.hadoop.yarn.server.resourcemanager.scheduler.capacity.CapacityScheduler: nodeUpdate: slave1:35126 clusterResources: <memory:8192, vCores:2>
2019-06-07 07:44:23,306 DEBUG org.apache.hadoop.yarn.server.resourcemanager.scheduler.capacity.CapacityScheduler: Node being looked for scheduling slave1:35126 availableResource: <memory:4096, vCores:1>
2019-06-07 07:44:23,306 DEBUG org.apache.hadoop.yarn.server.resourcemanager.scheduler.capacity.CapacityScheduler: Node being looked for scheduling slave1:35126 availableResource: <memory:4096, vCores:1>
2019-06-07 07:44:23,306 DEBUG org.apache.hadoop.yarn.server.resourcemanager.scheduler.capacity.CapacityScheduler: Trying to schedule on node: slave1, available: <memory:4096, vCores:1>
2019-06-07 07:44:23,306 DEBUG org.apache.hadoop.yarn.server.resourcemanager.scheduler.capacity.CapacityScheduler: Trying to schedule on node: slave1, available: <memory:4096, vCores:1>
2019-06-07 07:44:23,306 DEBUG org.apache.hadoop.yarn.server.resourcemanager.scheduler.capacity.ParentQueue: Skip this queue=root, because it doesn't need more resource, schedulingMode=RESPECT_PARTITION_EXCLUSIVITY node-partition=
2019-06-07 07:44:23,306 DEBUG org.apache.hadoop.yarn.server.resourcemanager.scheduler.capacity.ParentQueue: Skip this queue=root, because it doesn't need more resource, schedulingMode=RESPECT_PARTITION_EXCLUSIVITY node-partition=
2019-06-07 07:44:24,305 DEBUG org.apache.hadoop.yarn.server.resourcemanager.rmnode.RMNodeImpl: Processing slave2:33474 of type STATUS_UPDATE
2019-06-07 07:44:24,305 DEBUG org.apache.hadoop.yarn.server.resourcemanager.rmnode.RMNodeImpl: Processing slave2:33474 of type STATUS_UPDATE
2019-06-07 07:44:24,306 DEBUG org.apache.hadoop.yarn.server.resourcemanager.scheduler.capacity.CapacityScheduler: nodeUpdate: slave2:33474 clusterResources: <memory:8192, vCores:2>
2019-06-07 07:44:24,306 DEBUG org.apache.hadoop.yarn.server.resourcemanager.scheduler.capacity.CapacityScheduler: nodeUpdate: slave2:33474 clusterResources: <memory:8192, vCores:2>
2019-06-07 07:44:24,306 DEBUG org.apache.hadoop.yarn.server.resourcemanager.scheduler.capacity.CapacityScheduler: Node being looked for scheduling slave2:33474 availableResource: <memory:4096, vCores:1>
2019-06-07 07:44:24,306 DEBUG org.apache.hadoop.yarn.server.resourcemanager.scheduler.capacity.CapacityScheduler: Node being looked for scheduling slave2:33474 availableResource: <memory:4096, vCores:1>
2019-06-07 07:44:24,306 DEBUG org.apache.hadoop.yarn.server.resourcemanager.scheduler.capacity.CapacityScheduler: Trying to schedule on node: slave2, available: <memory:4096, vCores:1>
2019-06-07 07:44:24,306 DEBUG org.apache.hadoop.yarn.server.resourcemanager.scheduler.capacity.CapacityScheduler: Trying to schedule on node: slave2, available: <memory:4096, vCores:1>
2019-06-07 07:44:24,306 DEBUG org.apache.hadoop.yarn.server.resourcemanager.scheduler.capacity.ParentQueue: Skip this queue=root, because it doesn't need more resource, schedulingMode=RESPECT_PARTITION_EXCLUSIVITY node-partition=
2019-06-07 07:44:24,306 DEBUG org.apache.hadoop.yarn.server.resourcemanager.scheduler.capacity.ParentQueue: Skip this queue=root, because it doesn't need more resource, schedulingMode=RESPECT_PARTITION_EXCLUSIVITY node-partition=
2019-06-07 07:44:24,309 DEBUG org.apache.hadoop.yarn.server.resourcemanager.rmnode.RMNodeImpl: Processing slave1:35126 of type STATUS_UPDATE
2019-06-07 07:44:24,309 DEBUG org.apache.hadoop.yarn.server.resourcemanager.rmnode.RMNodeImpl: Processing slave1:35126 of type STATUS_UPDATE
2019-06-07 07:44:24,309 DEBUG org.apache.hadoop.yarn.server.resourcemanager.scheduler.capacity.CapacityScheduler: nodeUpdate: slave1:35126 clusterResources: <memory:8192, vCores:2>
2019-06-07 07:44:24,309 DEBUG org.apache.hadoop.yarn.server.resourcemanager.scheduler.capacity.CapacityScheduler: nodeUpdate: slave1:35126 clusterResources: <memory:8192, vCores:2>
2019-06-07 07:44:24,309 DEBUG org.apache.hadoop.yarn.server.resourcemanager.scheduler.capacity.CapacityScheduler: Node being looked for scheduling slave1:35126 availableResource: <memory:4096, vCores:1>
2019-06-07 07:44:24,309 DEBUG org.apache.hadoop.yarn.server.resourcemanager.scheduler.capacity.CapacityScheduler: Node being looked for scheduling slave1:35126 availableResource: <memory:4096, vCores:1>
2019-06-07 07:44:24,309 DEBUG org.apache.hadoop.yarn.server.resourcemanager.scheduler.capacity.CapacityScheduler: Trying to schedule on node: slave1, available: <memory:4096, vCores:1>
2019-06-07 07:44:24,309 DEBUG org.apache.hadoop.yarn.server.resourcemanager.scheduler.capacity.CapacityScheduler: Trying to schedule on node: slave1, available: <memory:4096, vCores:1>
2019-06-07 07:44:24,309 DEBUG org.apache.hadoop.yarn.server.resourcemanager.scheduler.capacity.ParentQueue: Skip this queue=root, because it doesn't need more resource, schedulingMode=RESPECT_PARTITION_EXCLUSIVITY node-partition=
2019-06-07 07:44:24,309 DEBUG org.apache.hadoop.yarn.server.resourcemanager.scheduler.capacity.ParentQueue: Skip this queue=root, because it doesn't need more resource, schedulingMode=RESPECT_PARTITION_EXCLUSIVITY node-partition=
2019-06-07 07:44:25,314 DEBUG org.apache.hadoop.yarn.server.resourcemanager.rmnode.RMNodeImpl: Processing slave2:33474 of type STATUS_UPDATE
2019-06-07 07:44:25,314 DEBUG org.apache.hadoop.yarn.server.resourcemanager.rmnode.RMNodeImpl: Processing slave2:33474 of type STATUS_UPDATE
2019-06-07 07:44:25,315 DEBUG org.apache.hadoop.yarn.server.resourcemanager.scheduler.capacity.CapacityScheduler: nodeUpdate: slave2:33474 clusterResources: <memory:8192, vCores:2>
2019-06-07 07:44:25,315 DEBUG org.apache.hadoop.yarn.server.resourcemanager.scheduler.capacity.CapacityScheduler: nodeUpdate: slave2:33474 clusterResources: <memory:8192, vCores:2>
2019-06-07 07:44:25,315 DEBUG org.apache.hadoop.yarn.server.resourcemanager.scheduler.capacity.CapacityScheduler: Node being looked for scheduling slave2:33474 availableResource: <memory:4096, vCores:1>
2019-06-07 07:44:25,315 DEBUG org.apache.hadoop.yarn.server.resourcemanager.scheduler.capacity.CapacityScheduler: Node being looked for scheduling slave2:33474 availableResource: <memory:4096, vCores:1>
2019-06-07 07:44:25,315 DEBUG org.apache.hadoop.yarn.server.resourcemanager.scheduler.capacity.CapacityScheduler: Trying to schedule on node: slave2, available: <memory:4096, vCores:1>
2019-06-07 07:44:25,315 DEBUG org.apache.hadoop.yarn.server.resourcemanager.scheduler.capacity.CapacityScheduler: Trying to schedule on node: slave2, available: <memory:4096, vCores:1>
2019-06-07 07:44:25,315 DEBUG org.apache.hadoop.yarn.server.resourcemanager.scheduler.capacity.ParentQueue: Skip this queue=root, because it doesn't need more resource, schedulingMode=RESPECT_PARTITION_EXCLUSIVITY node-partition=
2019-06-07 07:44:25,315 DEBUG org.apache.hadoop.yarn.server.resourcemanager.scheduler.capacity.ParentQueue: Skip this queue=root, because it doesn't need more resource, schedulingMode=RESPECT_PARTITION_EXCLUSIVITY node-partition=
2019-06-07 07:44:25,316 DEBUG org.apache.hadoop.yarn.server.resourcemanager.rmnode.RMNodeImpl: Processing slave1:35126 of type STATUS_UPDATE
2019-06-07 07:44:25,316 DEBUG org.apache.hadoop.yarn.server.resourcemanager.rmnode.RMNodeImpl: Processing slave1:35126 of type STATUS_UPDATE
2019-06-07 07:44:25,318 DEBUG org.apache.hadoop.yarn.server.resourcemanager.scheduler.capacity.CapacityScheduler: nodeUpdate: slave1:35126 clusterResources: <memory:8192, vCores:2>
2019-06-07 07:44:25,318 DEBUG org.apache.hadoop.yarn.server.resourcemanager.scheduler.capacity.CapacityScheduler: nodeUpdate: slave1:35126 clusterResources: <memory:8192, vCores:2>
2019-06-07 07:44:25,319 DEBUG org.apache.hadoop.yarn.server.resourcemanager.scheduler.capacity.CapacityScheduler: Node being looked for scheduling slave1:35126 availableResource: <memory:4096, vCores:1>
2019-06-07 07:44:25,319 DEBUG org.apache.hadoop.yarn.server.resourcemanager.scheduler.capacity.CapacityScheduler: Node being looked for scheduling slave1:35126 availableResource: <memory:4096, vCores:1>
2019-06-07 07:44:25,319 DEBUG org.apache.hadoop.yarn.server.resourcemanager.scheduler.capacity.CapacityScheduler: Trying to schedule on node: slave1, available: <memory:4096, vCores:1>
2019-06-07 07:44:25,319 DEBUG org.apache.hadoop.yarn.server.resourcemanager.scheduler.capacity.CapacityScheduler: Trying to schedule on node: slave1, available: <memory:4096, vCores:1>
2019-06-07 07:44:25,319 DEBUG org.apache.hadoop.yarn.server.resourcemanager.scheduler.capacity.ParentQueue: Skip this queue=root, because it doesn't need more resource, schedulingMode=RESPECT_PARTITION_EXCLUSIVITY node-partition=
2019-06-07 07:44:25,319 DEBUG org.apache.hadoop.yarn.server.resourcemanager.scheduler.capacity.ParentQueue: Skip this queue=root, because it doesn't need more resource, schedulingMode=RESPECT_PARTITION_EXCLUSIVITY node-partition=
2019-06-07 07:44:26,338 DEBUG org.apache.hadoop.yarn.server.resourcemanager.rmnode.RMNodeImpl: Processing slave1:35126 of type STATUS_UPDATE
2019-06-07 07:44:26,338 DEBUG org.apache.hadoop.yarn.server.resourcemanager.rmnode.RMNodeImpl: Processing slave1:35126 of type STATUS_UPDATE
2019-06-07 07:44:26,339 DEBUG org.apache.hadoop.yarn.server.resourcemanager.rmnode.RMNodeImpl: Processing slave2:33474 of type STATUS_UPDATE
2019-06-07 07:44:26,339 DEBUG org.apache.hadoop.yarn.server.resourcemanager.rmnode.RMNodeImpl: Processing slave2:33474 of type STATUS_UPDATE
2019-06-07 07:44:26,350 DEBUG org.apache.hadoop.yarn.server.resourcemanager.scheduler.capacity.CapacityScheduler: nodeUpdate: slave1:35126 clusterResources: <memory:8192, vCores:2>
2019-06-07 07:44:26,350 DEBUG org.apache.hadoop.yarn.server.resourcemanager.scheduler.capacity.CapacityScheduler: nodeUpdate: slave1:35126 clusterResources: <memory:8192, vCores:2>
2019-06-07 07:44:26,351 DEBUG org.apache.hadoop.yarn.server.resourcemanager.scheduler.capacity.CapacityScheduler: Node being looked for scheduling slave1:35126 availableResource: <memory:4096, vCores:1>
2019-06-07 07:44:26,351 DEBUG org.apache.hadoop.yarn.server.resourcemanager.scheduler.capacity.CapacityScheduler: Node being looked for scheduling slave1:35126 availableResource: <memory:4096, vCores:1>
2019-06-07 07:44:26,351 DEBUG org.apache.hadoop.yarn.server.resourcemanager.scheduler.capacity.CapacityScheduler: Trying to schedule on node: slave1, available: <memory:4096, vCores:1>
2019-06-07 07:44:26,351 DEBUG org.apache.hadoop.yarn.server.resourcemanager.scheduler.capacity.CapacityScheduler: Trying to schedule on node: slave1, available: <memory:4096, vCores:1>
2019-06-07 07:44:26,351 DEBUG org.apache.hadoop.yarn.server.resourcemanager.scheduler.capacity.ParentQueue: Skip this queue=root, because it doesn't need more resource, schedulingMode=RESPECT_PARTITION_EXCLUSIVITY node-partition=
2019-06-07 07:44:26,351 DEBUG org.apache.hadoop.yarn.server.resourcemanager.scheduler.capacity.ParentQueue: Skip this queue=root, because it doesn't need more resource, schedulingMode=RESPECT_PARTITION_EXCLUSIVITY node-partition=
2019-06-07 07:44:26,351 DEBUG org.apache.hadoop.yarn.server.resourcemanager.scheduler.capacity.CapacityScheduler: nodeUpdate: slave2:33474 clusterResources: <memory:8192, vCores:2>
2019-06-07 07:44:26,351 DEBUG org.apache.hadoop.yarn.server.resourcemanager.scheduler.capacity.CapacityScheduler: nodeUpdate: slave2:33474 clusterResources: <memory:8192, vCores:2>
2019-06-07 07:44:26,351 DEBUG org.apache.hadoop.yarn.server.resourcemanager.scheduler.capacity.CapacityScheduler: Node being looked for scheduling slave2:33474 availableResource: <memory:4096, vCores:1>
2019-06-07 07:44:26,351 DEBUG org.apache.hadoop.yarn.server.resourcemanager.scheduler.capacity.CapacityScheduler: Node being looked for scheduling slave2:33474 availableResource: <memory:4096, vCores:1>
2019-06-07 07:44:26,351 DEBUG org.apache.hadoop.yarn.server.resourcemanager.scheduler.capacity.CapacityScheduler: Trying to schedule on node: slave2, available: <memory:4096, vCores:1>
2019-06-07 07:44:26,351 DEBUG org.apache.hadoop.yarn.server.resourcemanager.scheduler.capacity.CapacityScheduler: Trying to schedule on node: slave2, available: <memory:4096, vCores:1>
2019-06-07 07:44:26,351 DEBUG org.apache.hadoop.yarn.server.resourcemanager.scheduler.capacity.ParentQueue: Skip this queue=root, because it doesn't need more resource, schedulingMode=RESPECT_PARTITION_EXCLUSIVITY node-partition=
2019-06-07 07:44:26,351 DEBUG org.apache.hadoop.yarn.server.resourcemanager.scheduler.capacity.ParentQueue: Skip this queue=root, because it doesn't need more resource, schedulingMode=RESPECT_PARTITION_EXCLUSIVITY node-partition=
2019-06-07 07:44:27,342 DEBUG org.apache.hadoop.yarn.server.resourcemanager.rmnode.RMNodeImpl: Processing slave1:35126 of type STATUS_UPDATE
2019-06-07 07:44:27,342 DEBUG org.apache.hadoop.yarn.server.resourcemanager.rmnode.RMNodeImpl: Processing slave1:35126 of type STATUS_UPDATE
2019-06-07 07:44:27,342 DEBUG org.apache.hadoop.yarn.server.resourcemanager.scheduler.capacity.CapacityScheduler: nodeUpdate: slave1:35126 clusterResources: <memory:8192, vCores:2>
2019-06-07 07:44:27,342 DEBUG org.apache.hadoop.yarn.server.resourcemanager.scheduler.capacity.CapacityScheduler: nodeUpdate: slave1:35126 clusterResources: <memory:8192, vCores:2>
2019-06-07 07:44:27,343 DEBUG org.apache.hadoop.yarn.server.resourcemanager.scheduler.capacity.CapacityScheduler: Node being looked for scheduling slave1:35126 availableResource: <memory:4096, vCores:1>
2019-06-07 07:44:27,343 DEBUG org.apache.hadoop.yarn.server.resourcemanager.scheduler.capacity.CapacityScheduler: Node being looked for scheduling slave1:35126 availableResource: <memory:4096, vCores:1>
2019-06-07 07:44:27,343 DEBUG org.apache.hadoop.yarn.server.resourcemanager.scheduler.capacity.CapacityScheduler: Trying to schedule on node: slave1, available: <memory:4096, vCores:1>
2019-06-07 07:44:27,343 DEBUG org.apache.hadoop.yarn.server.resourcemanager.scheduler.capacity.CapacityScheduler: Trying to schedule on node: slave1, available: <memory:4096, vCores:1>
2019-06-07 07:44:27,343 DEBUG org.apache.hadoop.yarn.server.resourcemanager.scheduler.capacity.ParentQueue: Skip this queue=root, because it doesn't need more resource, schedulingMode=RESPECT_PARTITION_EXCLUSIVITY node-partition=
2019-06-07 07:44:27,343 DEBUG org.apache.hadoop.yarn.server.resourcemanager.scheduler.capacity.ParentQueue: Skip this queue=root, because it doesn't need more resource, schedulingMode=RESPECT_PARTITION_EXCLUSIVITY node-partition=
2019-06-07 07:44:27,355 DEBUG org.apache.hadoop.yarn.server.resourcemanager.rmnode.RMNodeImpl: Processing slave2:33474 of type STATUS_UPDATE
2019-06-07 07:44:27,355 DEBUG org.apache.hadoop.yarn.server.resourcemanager.rmnode.RMNodeImpl: Processing slave2:33474 of type STATUS_UPDATE
2019-06-07 07:44:27,355 DEBUG org.apache.hadoop.yarn.server.resourcemanager.scheduler.capacity.CapacityScheduler: nodeUpdate: slave2:33474 clusterResources: <memory:8192, vCores:2>
2019-06-07 07:44:27,355 DEBUG org.apache.hadoop.yarn.server.resourcemanager.scheduler.capacity.CapacityScheduler: nodeUpdate: slave2:33474 clusterResources: <memory:8192, vCores:2>
2019-06-07 07:44:27,355 DEBUG org.apache.hadoop.yarn.server.resourcemanager.scheduler.capacity.CapacityScheduler: Node being looked for scheduling slave2:33474 availableResource: <memory:4096, vCores:1>
2019-06-07 07:44:27,355 DEBUG org.apache.hadoop.yarn.server.resourcemanager.scheduler.capacity.CapacityScheduler: Node being looked for scheduling slave2:33474 availableResource: <memory:4096, vCores:1>
2019-06-07 07:44:27,355 DEBUG org.apache.hadoop.yarn.server.resourcemanager.scheduler.capacity.CapacityScheduler: Trying to schedule on node: slave2, available: <memory:4096, vCores:1>
2019-06-07 07:44:27,355 DEBUG org.apache.hadoop.yarn.server.resourcemanager.scheduler.capacity.CapacityScheduler: Trying to schedule on node: slave2, available: <memory:4096, vCores:1>
2019-06-07 07:44:27,355 DEBUG org.apache.hadoop.yarn.server.resourcemanager.scheduler.capacity.ParentQueue: Skip this queue=root, because it doesn't need more resource, schedulingMode=RESPECT_PARTITION_EXCLUSIVITY node-partition=
2019-06-07 07:44:27,355 DEBUG org.apache.hadoop.yarn.server.resourcemanager.scheduler.capacity.ParentQueue: Skip this queue=root, because it doesn't need more resource, schedulingMode=RESPECT_PARTITION_EXCLUSIVITY node-partition=
2019-06-07 07:44:28,345 DEBUG org.apache.hadoop.yarn.server.resourcemanager.rmnode.RMNodeImpl: Processing slave1:35126 of type STATUS_UPDATE
2019-06-07 07:44:28,345 DEBUG org.apache.hadoop.yarn.server.resourcemanager.rmnode.RMNodeImpl: Processing slave1:35126 of type STATUS_UPDATE
2019-06-07 07:44:28,345 DEBUG org.apache.hadoop.yarn.server.resourcemanager.scheduler.capacity.CapacityScheduler: nodeUpdate: slave1:35126 clusterResources: <memory:8192, vCores:2>
2019-06-07 07:44:28,345 DEBUG org.apache.hadoop.yarn.server.resourcemanager.scheduler.capacity.CapacityScheduler: nodeUpdate: slave1:35126 clusterResources: <memory:8192, vCores:2>
2019-06-07 07:44:28,345 DEBUG org.apache.hadoop.yarn.server.resourcemanager.scheduler.capacity.CapacityScheduler: Node being looked for scheduling slave1:35126 availableResource: <memory:4096, vCores:1>
2019-06-07 07:44:28,345 DEBUG org.apache.hadoop.yarn.server.resourcemanager.scheduler.capacity.CapacityScheduler: Node being looked for scheduling slave1:35126 availableResource: <memory:4096, vCores:1>
2019-06-07 07:44:28,345 DEBUG org.apache.hadoop.yarn.server.resourcemanager.scheduler.capacity.CapacityScheduler: Trying to schedule on node: slave1, available: <memory:4096, vCores:1>
2019-06-07 07:44:28,345 DEBUG org.apache.hadoop.yarn.server.resourcemanager.scheduler.capacity.CapacityScheduler: Trying to schedule on node: slave1, available: <memory:4096, vCores:1>
2019-06-07 07:44:28,345 DEBUG org.apache.hadoop.yarn.server.resourcemanager.scheduler.capacity.ParentQueue: Skip this queue=root, because it doesn't need more resource, schedulingMode=RESPECT_PARTITION_EXCLUSIVITY node-partition=
2019-06-07 07:44:28,345 DEBUG org.apache.hadoop.yarn.server.resourcemanager.scheduler.capacity.ParentQueue: Skip this queue=root, because it doesn't need more resource, schedulingMode=RESPECT_PARTITION_EXCLUSIVITY node-partition=
2019-06-07 07:44:28,358 DEBUG org.apache.hadoop.yarn.server.resourcemanager.rmnode.RMNodeImpl: Processing slave2:33474 of type STATUS_UPDATE
2019-06-07 07:44:28,358 DEBUG org.apache.hadoop.yarn.server.resourcemanager.rmnode.RMNodeImpl: Processing slave2:33474 of type STATUS_UPDATE
2019-06-07 07:44:28,359 DEBUG org.apache.hadoop.yarn.server.resourcemanager.scheduler.capacity.CapacityScheduler: nodeUpdate: slave2:33474 clusterResources: <memory:8192, vCores:2>
2019-06-07 07:44:28,359 DEBUG org.apache.hadoop.yarn.server.resourcemanager.scheduler.capacity.CapacityScheduler: nodeUpdate: slave2:33474 clusterResources: <memory:8192, vCores:2>
2019-06-07 07:44:28,359 DEBUG org.apache.hadoop.yarn.server.resourcemanager.scheduler.capacity.CapacityScheduler: Node being looked for scheduling slave2:33474 availableResource: <memory:4096, vCores:1>
2019-06-07 07:44:28,359 DEBUG org.apache.hadoop.yarn.server.resourcemanager.scheduler.capacity.CapacityScheduler: Node being looked for scheduling slave2:33474 availableResource: <memory:4096, vCores:1>
2019-06-07 07:44:28,359 DEBUG org.apache.hadoop.yarn.server.resourcemanager.scheduler.capacity.CapacityScheduler: Trying to schedule on node: slave2, available: <memory:4096, vCores:1>
2019-06-07 07:44:28,359 DEBUG org.apache.hadoop.yarn.server.resourcemanager.scheduler.capacity.CapacityScheduler: Trying to schedule on node: slave2, available: <memory:4096, vCores:1>
2019-06-07 07:44:28,359 DEBUG org.apache.hadoop.yarn.server.resourcemanager.scheduler.capacity.ParentQueue: Skip this queue=root, because it doesn't need more resource, schedulingMode=RESPECT_PARTITION_EXCLUSIVITY node-partition=
2019-06-07 07:44:28,359 DEBUG org.apache.hadoop.yarn.server.resourcemanager.scheduler.capacity.ParentQueue: Skip this queue=root, because it doesn't need more resource, schedulingMode=RESPECT_PARTITION_EXCLUSIVITY node-partition=
2019-06-07 07:44:29,353 DEBUG org.apache.hadoop.yarn.server.resourcemanager.rmnode.RMNodeImpl: Processing slave1:35126 of type STATUS_UPDATE
2019-06-07 07:44:29,353 DEBUG org.apache.hadoop.yarn.server.resourcemanager.rmnode.RMNodeImpl: Processing slave1:35126 of type STATUS_UPDATE
2019-06-07 07:44:29,354 DEBUG org.apache.hadoop.yarn.server.resourcemanager.scheduler.capacity.CapacityScheduler: nodeUpdate: slave1:35126 clusterResources: <memory:8192, vCores:2>
2019-06-07 07:44:29,354 DEBUG org.apache.hadoop.yarn.server.resourcemanager.scheduler.capacity.CapacityScheduler: nodeUpdate: slave1:35126 clusterResources: <memory:8192, vCores:2>
2019-06-07 07:44:29,355 DEBUG org.apache.hadoop.yarn.server.resourcemanager.scheduler.capacity.CapacityScheduler: Node being looked for scheduling slave1:35126 availableResource: <memory:4096, vCores:1>
2019-06-07 07:44:29,355 DEBUG org.apache.hadoop.yarn.server.resourcemanager.scheduler.capacity.CapacityScheduler: Node being looked for scheduling slave1:35126 availableResource: <memory:4096, vCores:1>
2019-06-07 07:44:29,355 DEBUG org.apache.hadoop.yarn.server.resourcemanager.scheduler.capacity.CapacityScheduler: Trying to schedule on node: slave1, available: <memory:4096, vCores:1>
2019-06-07 07:44:29,355 DEBUG org.apache.hadoop.yarn.server.resourcemanager.scheduler.capacity.CapacityScheduler: Trying to schedule on node: slave1, available: <memory:4096, vCores:1>
2019-06-07 07:44:29,355 DEBUG org.apache.hadoop.yarn.server.resourcemanager.scheduler.capacity.ParentQueue: Skip this queue=root, because it doesn't need more resource, schedulingMode=RESPECT_PARTITION_EXCLUSIVITY node-partition=
2019-06-07 07:44:29,355 DEBUG org.apache.hadoop.yarn.server.resourcemanager.scheduler.capacity.ParentQueue: Skip this queue=root, because it doesn't need more resource, schedulingMode=RESPECT_PARTITION_EXCLUSIVITY node-partition=
2019-06-07 07:44:29,360 DEBUG org.apache.hadoop.yarn.server.resourcemanager.rmnode.RMNodeImpl: Processing slave2:33474 of type STATUS_UPDATE
2019-06-07 07:44:29,360 DEBUG org.apache.hadoop.yarn.server.resourcemanager.rmnode.RMNodeImpl: Processing slave2:33474 of type STATUS_UPDATE
2019-06-07 07:44:29,361 DEBUG org.apache.hadoop.yarn.server.resourcemanager.scheduler.capacity.CapacityScheduler: nodeUpdate: slave2:33474 clusterResources: <memory:8192, vCores:2>
2019-06-07 07:44:29,361 DEBUG org.apache.hadoop.yarn.server.resourcemanager.scheduler.capacity.CapacityScheduler: nodeUpdate: slave2:33474 clusterResources: <memory:8192, vCores:2>
2019-06-07 07:44:29,361 DEBUG org.apache.hadoop.yarn.server.resourcemanager.scheduler.capacity.CapacityScheduler: Node being looked for scheduling slave2:33474 availableResource: <memory:4096, vCores:1>
2019-06-07 07:44:29,361 DEBUG org.apache.hadoop.yarn.server.resourcemanager.scheduler.capacity.CapacityScheduler: Node being looked for scheduling slave2:33474 availableResource: <memory:4096, vCores:1>
2019-06-07 07:44:29,361 DEBUG org.apache.hadoop.yarn.server.resourcemanager.scheduler.capacity.CapacityScheduler: Trying to schedule on node: slave2, available: <memory:4096, vCores:1>
2019-06-07 07:44:29,361 DEBUG org.apache.hadoop.yarn.server.resourcemanager.scheduler.capacity.CapacityScheduler: Trying to schedule on node: slave2, available: <memory:4096, vCores:1>
2019-06-07 07:44:29,361 DEBUG org.apache.hadoop.yarn.server.resourcemanager.scheduler.capacity.ParentQueue: Skip this queue=root, because it doesn't need more resource, schedulingMode=RESPECT_PARTITION_EXCLUSIVITY node-partition=
2019-06-07 07:44:29,361 DEBUG org.apache.hadoop.yarn.server.resourcemanager.scheduler.capacity.ParentQueue: Skip this queue=root, because it doesn't need more resource, schedulingMode=RESPECT_PARTITION_EXCLUSIVITY node-partition=
2019-06-07 07:44:30,357 DEBUG org.apache.hadoop.yarn.server.resourcemanager.rmnode.RMNodeImpl: Processing slave1:35126 of type STATUS_UPDATE
2019-06-07 07:44:30,357 DEBUG org.apache.hadoop.yarn.server.resourcemanager.rmnode.RMNodeImpl: Processing slave1:35126 of type STATUS_UPDATE
2019-06-07 07:44:30,357 DEBUG org.apache.hadoop.yarn.server.resourcemanager.scheduler.capacity.CapacityScheduler: nodeUpdate: slave1:35126 clusterResources: <memory:8192, vCores:2>
2019-06-07 07:44:30,357 DEBUG org.apache.hadoop.yarn.server.resourcemanager.scheduler.capacity.CapacityScheduler: nodeUpdate: slave1:35126 clusterResources: <memory:8192, vCores:2>
2019-06-07 07:44:30,357 DEBUG org.apache.hadoop.yarn.server.resourcemanager.scheduler.capacity.CapacityScheduler: Node being looked for scheduling slave1:35126 availableResource: <memory:4096, vCores:1>
2019-06-07 07:44:30,357 DEBUG org.apache.hadoop.yarn.server.resourcemanager.scheduler.capacity.CapacityScheduler: Node being looked for scheduling slave1:35126 availableResource: <memory:4096, vCores:1>
2019-06-07 07:44:30,357 DEBUG org.apache.hadoop.yarn.server.resourcemanager.scheduler.capacity.CapacityScheduler: Trying to schedule on node: slave1, available: <memory:4096, vCores:1>
2019-06-07 07:44:30,357 DEBUG org.apache.hadoop.yarn.server.resourcemanager.scheduler.capacity.CapacityScheduler: Trying to schedule on node: slave1, available: <memory:4096, vCores:1>
2019-06-07 07:44:30,357 DEBUG org.apache.hadoop.yarn.server.resourcemanager.scheduler.capacity.ParentQueue: Skip this queue=root, because it doesn't need more resource, schedulingMode=RESPECT_PARTITION_EXCLUSIVITY node-partition=
2019-06-07 07:44:30,357 DEBUG org.apache.hadoop.yarn.server.resourcemanager.scheduler.capacity.ParentQueue: Skip this queue=root, because it doesn't need more resource, schedulingMode=RESPECT_PARTITION_EXCLUSIVITY node-partition=
2019-06-07 07:44:30,362 DEBUG org.apache.hadoop.yarn.server.resourcemanager.rmnode.RMNodeImpl: Processing slave2:33474 of type STATUS_UPDATE
2019-06-07 07:44:30,362 DEBUG org.apache.hadoop.yarn.server.resourcemanager.rmnode.RMNodeImpl: Processing slave2:33474 of type STATUS_UPDATE
2019-06-07 07:44:30,362 DEBUG org.apache.hadoop.yarn.server.resourcemanager.scheduler.capacity.CapacityScheduler: nodeUpdate: slave2:33474 clusterResources: <memory:8192, vCores:2>
2019-06-07 07:44:30,362 DEBUG org.apache.hadoop.yarn.server.resourcemanager.scheduler.capacity.CapacityScheduler: nodeUpdate: slave2:33474 clusterResources: <memory:8192, vCores:2>
2019-06-07 07:44:30,362 DEBUG org.apache.hadoop.yarn.server.resourcemanager.scheduler.capacity.CapacityScheduler: Node being looked for scheduling slave2:33474 availableResource: <memory:4096, vCores:1>
2019-06-07 07:44:30,362 DEBUG org.apache.hadoop.yarn.server.resourcemanager.scheduler.capacity.CapacityScheduler: Node being looked for scheduling slave2:33474 availableResource: <memory:4096, vCores:1>
2019-06-07 07:44:30,362 DEBUG org.apache.hadoop.yarn.server.resourcemanager.scheduler.capacity.CapacityScheduler: Trying to schedule on node: slave2, available: <memory:4096, vCores:1>
2019-06-07 07:44:30,362 DEBUG org.apache.hadoop.yarn.server.resourcemanager.scheduler.capacity.CapacityScheduler: Trying to schedule on node: slave2, available: <memory:4096, vCores:1>
2019-06-07 07:44:30,362 DEBUG org.apache.hadoop.yarn.server.resourcemanager.scheduler.capacity.ParentQueue: Skip this queue=root, because it doesn't need more resource, schedulingMode=RESPECT_PARTITION_EXCLUSIVITY node-partition=
2019-06-07 07:44:30,362 DEBUG org.apache.hadoop.yarn.server.resourcemanager.scheduler.capacity.ParentQueue: Skip this queue=root, because it doesn't need more resource, schedulingMode=RESPECT_PARTITION_EXCLUSIVITY node-partition=
2019-06-07 07:44:30,430 INFO org.apache.hadoop.yarn.server.resourcemanager.scheduler.capacity.CapacityScheduler: Application 'application_1559893389340_0001' is submitted without priority hence considering default queue/cluster priority: 0
2019-06-07 07:44:30,430 INFO org.apache.hadoop.yarn.server.resourcemanager.scheduler.capacity.CapacityScheduler: Application 'application_1559893389340_0001' is submitted without priority hence considering default queue/cluster priority: 0
2019-06-07 07:44:30,430 INFO org.apache.hadoop.yarn.server.resourcemanager.scheduler.capacity.CapacityScheduler: Priority '0' is acceptable in queue : default for application: application_1559893389340_0001 for the user: root
2019-06-07 07:44:30,430 INFO org.apache.hadoop.yarn.server.resourcemanager.scheduler.capacity.CapacityScheduler: Priority '0' is acceptable in queue : default for application: application_1559893389340_0001 for the user: root
2019-06-07 07:44:30,443 WARN org.apache.hadoop.yarn.server.resourcemanager.rmapp.RMAppImpl: The specific max attempts: 0 for application: 1 is invalid, because it is out of the range [1, 2]. Use the global max attempts instead.
2019-06-07 07:44:30,443 WARN org.apache.hadoop.yarn.server.resourcemanager.rmapp.RMAppImpl: The specific max attempts: 0 for application: 1 is invalid, because it is out of the range [1, 2]. Use the global max attempts instead.
2019-06-07 07:44:30,448 DEBUG org.apache.hadoop.yarn.server.resourcemanager.rmapp.RMAppImpl: Processing event for application_1559893389340_0001 of type START
2019-06-07 07:44:30,448 DEBUG org.apache.hadoop.yarn.server.resourcemanager.rmapp.RMAppImpl: Processing event for application_1559893389340_0001 of type START
2019-06-07 07:44:30,448 INFO org.apache.hadoop.yarn.server.resourcemanager.rmapp.RMAppImpl: Storing application with id application_1559893389340_0001
2019-06-07 07:44:30,448 INFO org.apache.hadoop.yarn.server.resourcemanager.rmapp.RMAppImpl: Storing application with id application_1559893389340_0001
2019-06-07 07:44:30,452 INFO org.apache.hadoop.yarn.server.resourcemanager.ClientRMService: Application with id 1 submitted by user root
2019-06-07 07:44:30,452 INFO org.apache.hadoop.yarn.server.resourcemanager.ClientRMService: Application with id 1 submitted by user root
2019-06-07 07:44:30,454 INFO org.apache.hadoop.yarn.server.resourcemanager.rmapp.RMAppImpl: application_1559893389340_0001 State change from NEW to NEW_SAVING on event=START
2019-06-07 07:44:30,454 INFO org.apache.hadoop.yarn.server.resourcemanager.rmapp.RMAppImpl: application_1559893389340_0001 State change from NEW to NEW_SAVING on event=START
2019-06-07 07:44:30,454 DEBUG org.apache.hadoop.yarn.server.resourcemanager.recovery.RMStateStore: Processing event of type STORE_APP
2019-06-07 07:44:30,454 DEBUG org.apache.hadoop.yarn.server.resourcemanager.recovery.RMStateStore: Processing event of type STORE_APP
2019-06-07 07:44:30,454 INFO org.apache.hadoop.yarn.server.resourcemanager.recovery.RMStateStore: Storing info for app: application_1559893389340_0001
2019-06-07 07:44:30,454 INFO org.apache.hadoop.yarn.server.resourcemanager.recovery.RMStateStore: Storing info for app: application_1559893389340_0001
2019-06-07 07:44:30,455 DEBUG org.apache.hadoop.yarn.server.resourcemanager.rmapp.RMAppImpl: Processing event for application_1559893389340_0001 of type APP_NEW_SAVED
2019-06-07 07:44:30,455 DEBUG org.apache.hadoop.yarn.server.resourcemanager.rmapp.RMAppImpl: Processing event for application_1559893389340_0001 of type APP_NEW_SAVED
2019-06-07 07:44:30,455 INFO org.apache.hadoop.yarn.server.resourcemanager.RMAuditLogger: USER=root	IP=172.17.0.2	OPERATION=Submit Application Request	TARGET=ClientRMService	RESULT=SUCCESS	APPID=application_1559893389340_0001
2019-06-07 07:44:30,455 INFO org.apache.hadoop.yarn.server.resourcemanager.RMAuditLogger: USER=root	IP=172.17.0.2	OPERATION=Submit Application Request	TARGET=ClientRMService	RESULT=SUCCESS	APPID=application_1559893389340_0001
2019-06-07 07:44:30,455 INFO org.apache.hadoop.yarn.server.resourcemanager.rmapp.RMAppImpl: application_1559893389340_0001 State change from NEW_SAVING to SUBMITTED on event=APP_NEW_SAVED
2019-06-07 07:44:30,455 INFO org.apache.hadoop.yarn.server.resourcemanager.rmapp.RMAppImpl: application_1559893389340_0001 State change from NEW_SAVING to SUBMITTED on event=APP_NEW_SAVED
2019-06-07 07:44:30,457 INFO org.apache.hadoop.yarn.server.resourcemanager.scheduler.capacity.ParentQueue: Application added - appId: application_1559893389340_0001 user: root leaf-queue of parent: root #applications: 1
2019-06-07 07:44:30,457 INFO org.apache.hadoop.yarn.server.resourcemanager.scheduler.capacity.ParentQueue: Application added - appId: application_1559893389340_0001 user: root leaf-queue of parent: root #applications: 1
2019-06-07 07:44:30,458 INFO org.apache.hadoop.yarn.server.resourcemanager.scheduler.capacity.CapacityScheduler: Accepted application application_1559893389340_0001 from user: root, in queue: default
2019-06-07 07:44:30,458 INFO org.apache.hadoop.yarn.server.resourcemanager.scheduler.capacity.CapacityScheduler: Accepted application application_1559893389340_0001 from user: root, in queue: default
2019-06-07 07:44:30,459 DEBUG org.apache.hadoop.yarn.server.resourcemanager.rmapp.RMAppImpl: Processing event for application_1559893389340_0001 of type APP_ACCEPTED
2019-06-07 07:44:30,459 DEBUG org.apache.hadoop.yarn.server.resourcemanager.rmapp.RMAppImpl: Processing event for application_1559893389340_0001 of type APP_ACCEPTED
2019-06-07 07:44:30,471 INFO org.apache.hadoop.yarn.server.resourcemanager.rmapp.RMAppImpl: application_1559893389340_0001 State change from SUBMITTED to ACCEPTED on event=APP_ACCEPTED
2019-06-07 07:44:30,471 INFO org.apache.hadoop.yarn.server.resourcemanager.rmapp.RMAppImpl: application_1559893389340_0001 State change from SUBMITTED to ACCEPTED on event=APP_ACCEPTED
2019-06-07 07:44:30,471 DEBUG org.apache.hadoop.yarn.server.resourcemanager.rmapp.attempt.RMAppAttemptImpl: Processing event for appattempt_1559893389340_0001_000001 of type START
2019-06-07 07:44:30,471 DEBUG org.apache.hadoop.yarn.server.resourcemanager.rmapp.attempt.RMAppAttemptImpl: Processing event for appattempt_1559893389340_0001_000001 of type START
2019-06-07 07:44:30,495 INFO org.apache.hadoop.yarn.server.resourcemanager.ApplicationMasterService: Registering app attempt : appattempt_1559893389340_0001_000001
2019-06-07 07:44:30,495 INFO org.apache.hadoop.yarn.server.resourcemanager.ApplicationMasterService: Registering app attempt : appattempt_1559893389340_0001_000001
2019-06-07 07:44:30,496 INFO org.apache.hadoop.yarn.server.resourcemanager.rmapp.attempt.RMAppAttemptImpl: appattempt_1559893389340_0001_000001 State change from NEW to SUBMITTED
2019-06-07 07:44:30,496 INFO org.apache.hadoop.yarn.server.resourcemanager.rmapp.attempt.RMAppAttemptImpl: appattempt_1559893389340_0001_000001 State change from NEW to SUBMITTED
2019-06-07 07:44:30,497 DEBUG org.apache.hadoop.yarn.server.resourcemanager.scheduler.AbstractYarnScheduler: Request for appInfo of unknown attempt appattempt_1559893389340_0001_000001
2019-06-07 07:44:30,497 DEBUG org.apache.hadoop.yarn.server.resourcemanager.scheduler.AbstractYarnScheduler: Request for appInfo of unknown attempt appattempt_1559893389340_0001_000001
2019-06-07 07:44:30,497 DEBUG org.apache.hadoop.yarn.server.resourcemanager.scheduler.AbstractYarnScheduler: Request for appInfo of unknown attempt appattempt_1559893389340_0001_000001
2019-06-07 07:44:30,497 DEBUG org.apache.hadoop.yarn.server.resourcemanager.scheduler.AbstractYarnScheduler: Request for appInfo of unknown attempt appattempt_1559893389340_0001_000001
2019-06-07 07:44:30,498 DEBUG org.apache.hadoop.yarn.server.resourcemanager.scheduler.AbstractYarnScheduler: Request for appInfo of unknown attempt appattempt_1559893389340_0001_000001
2019-06-07 07:44:30,498 DEBUG org.apache.hadoop.yarn.server.resourcemanager.scheduler.AbstractYarnScheduler: Request for appInfo of unknown attempt appattempt_1559893389340_0001_000001
2019-06-07 07:44:30,523 DEBUG org.apache.hadoop.yarn.server.resourcemanager.scheduler.capacity.LeafQueue: application application_1559893389340_0001 AMResource <memory:1024, vCores:1> maxAMResourcePerQueuePercent 0.1 amLimit <memory:1024, vCores:1> lastClusterResource <memory:8192, vCores:2> amIfStarted <memory:1024, vCores:1> AM node-partition name 
2019-06-07 07:44:30,523 DEBUG org.apache.hadoop.yarn.server.resourcemanager.scheduler.capacity.LeafQueue: application application_1559893389340_0001 AMResource <memory:1024, vCores:1> maxAMResourcePerQueuePercent 0.1 amLimit <memory:1024, vCores:1> lastClusterResource <memory:8192, vCores:2> amIfStarted <memory:1024, vCores:1> AM node-partition name 
2019-06-07 07:44:30,523 DEBUG org.apache.hadoop.yarn.server.resourcemanager.scheduler.capacity.LeafQueue: Effective user AM limit for "root":<memory:1024, vCores:1>. Effective weighted user AM limit: <memory:1024, vCores:1>. User weight: 1.0
2019-06-07 07:44:30,523 DEBUG org.apache.hadoop.yarn.server.resourcemanager.scheduler.capacity.LeafQueue: Effective user AM limit for "root":<memory:1024, vCores:1>. Effective weighted user AM limit: <memory:1024, vCores:1>. User weight: 1.0
2019-06-07 07:44:30,524 INFO org.apache.hadoop.yarn.server.resourcemanager.scheduler.capacity.LeafQueue: Application application_1559893389340_0001 from user: root activated in queue: default
2019-06-07 07:44:30,524 INFO org.apache.hadoop.yarn.server.resourcemanager.scheduler.capacity.LeafQueue: Application application_1559893389340_0001 from user: root activated in queue: default
2019-06-07 07:44:30,524 INFO org.apache.hadoop.yarn.server.resourcemanager.scheduler.capacity.LeafQueue: Application added - appId: application_1559893389340_0001 user: root, leaf-queue: default #user-pending-applications: 0 #user-active-applications: 1 #queue-pending-applications: 0 #queue-active-applications: 1
2019-06-07 07:44:30,524 INFO org.apache.hadoop.yarn.server.resourcemanager.scheduler.capacity.LeafQueue: Application added - appId: application_1559893389340_0001 user: root, leaf-queue: default #user-pending-applications: 0 #user-active-applications: 1 #queue-pending-applications: 0 #queue-active-applications: 1
2019-06-07 07:44:30,524 INFO org.apache.hadoop.yarn.server.resourcemanager.scheduler.capacity.CapacityScheduler: Added Application Attempt appattempt_1559893389340_0001_000001 to scheduler from user root in queue default
2019-06-07 07:44:30,524 INFO org.apache.hadoop.yarn.server.resourcemanager.scheduler.capacity.CapacityScheduler: Added Application Attempt appattempt_1559893389340_0001_000001 to scheduler from user root in queue default
2019-06-07 07:44:30,524 DEBUG org.apache.hadoop.yarn.server.resourcemanager.rmapp.attempt.RMAppAttemptImpl: Processing event for appattempt_1559893389340_0001_000001 of type ATTEMPT_ADDED
2019-06-07 07:44:30,524 DEBUG org.apache.hadoop.yarn.server.resourcemanager.rmapp.attempt.RMAppAttemptImpl: Processing event for appattempt_1559893389340_0001_000001 of type ATTEMPT_ADDED
2019-06-07 07:44:30,526 DEBUG org.apache.hadoop.yarn.server.resourcemanager.rmapp.attempt.RMAppAttemptImpl: Using blacklist for AM: additions([]) and removals([])
2019-06-07 07:44:30,526 DEBUG org.apache.hadoop.yarn.server.resourcemanager.rmapp.attempt.RMAppAttemptImpl: Using blacklist for AM: additions([]) and removals([])
2019-06-07 07:44:30,526 DEBUG org.apache.hadoop.yarn.server.resourcemanager.scheduler.capacity.CapacityScheduler: allocate: pre-update appattempt_1559893389340_0001_000001 ask size =1
2019-06-07 07:44:30,526 DEBUG org.apache.hadoop.yarn.server.resourcemanager.scheduler.capacity.CapacityScheduler: allocate: pre-update appattempt_1559893389340_0001_000001 ask size =1
2019-06-07 07:44:30,527 DEBUG org.apache.hadoop.yarn.server.resourcemanager.scheduler.ActiveUsersManager: User root added to activeUsers, currently: 1
2019-06-07 07:44:30,527 DEBUG org.apache.hadoop.yarn.server.resourcemanager.scheduler.ActiveUsersManager: User root added to activeUsers, currently: 1
2019-06-07 07:44:30,527 DEBUG org.apache.hadoop.yarn.server.resourcemanager.scheduler.capacity.CapacityScheduler: allocate: post-update
2019-06-07 07:44:30,527 DEBUG org.apache.hadoop.yarn.server.resourcemanager.scheduler.capacity.CapacityScheduler: allocate: post-update
2019-06-07 07:44:30,527 DEBUG org.apache.hadoop.yarn.server.resourcemanager.scheduler.SchedulerApplicationAttempt: showRequests: application=application_1559893389340_0001 headRoom=<memory:0, vCores:0> currentConsumption=0
2019-06-07 07:44:30,527 DEBUG org.apache.hadoop.yarn.server.resourcemanager.scheduler.SchedulerApplicationAttempt: showRequests: application=application_1559893389340_0001 headRoom=<memory:0, vCores:0> currentConsumption=0
2019-06-07 07:44:30,527 DEBUG org.apache.hadoop.yarn.server.resourcemanager.scheduler.SchedulerApplicationAttempt: showRequests: application=application_1559893389340_0001 request={Priority: 0, Capability: <memory:1024, vCores:1>, # Containers: 1, Location: *, Relax Locality: true, Node Label Expression: }
2019-06-07 07:44:30,527 DEBUG org.apache.hadoop.yarn.server.resourcemanager.scheduler.SchedulerApplicationAttempt: showRequests: application=application_1559893389340_0001 request={Priority: 0, Capability: <memory:1024, vCores:1>, # Containers: 1, Location: *, Relax Locality: true, Node Label Expression: }
2019-06-07 07:44:30,528 INFO org.apache.hadoop.yarn.server.resourcemanager.rmapp.attempt.RMAppAttemptImpl: appattempt_1559893389340_0001_000001 State change from SUBMITTED to SCHEDULED
2019-06-07 07:44:30,528 INFO org.apache.hadoop.yarn.server.resourcemanager.rmapp.attempt.RMAppAttemptImpl: appattempt_1559893389340_0001_000001 State change from SUBMITTED to SCHEDULED
2019-06-07 07:44:31,361 DEBUG org.apache.hadoop.yarn.server.resourcemanager.rmnode.RMNodeImpl: Processing slave1:35126 of type STATUS_UPDATE
2019-06-07 07:44:31,361 DEBUG org.apache.hadoop.yarn.server.resourcemanager.rmnode.RMNodeImpl: Processing slave1:35126 of type STATUS_UPDATE
2019-06-07 07:44:31,361 DEBUG org.apache.hadoop.yarn.server.resourcemanager.scheduler.capacity.CapacityScheduler: nodeUpdate: slave1:35126 clusterResources: <memory:8192, vCores:2>
2019-06-07 07:44:31,361 DEBUG org.apache.hadoop.yarn.server.resourcemanager.scheduler.capacity.CapacityScheduler: nodeUpdate: slave1:35126 clusterResources: <memory:8192, vCores:2>
2019-06-07 07:44:31,361 DEBUG org.apache.hadoop.yarn.server.resourcemanager.scheduler.capacity.CapacityScheduler: Node being looked for scheduling slave1:35126 availableResource: <memory:4096, vCores:1>
2019-06-07 07:44:31,361 DEBUG org.apache.hadoop.yarn.server.resourcemanager.scheduler.capacity.CapacityScheduler: Node being looked for scheduling slave1:35126 availableResource: <memory:4096, vCores:1>
2019-06-07 07:44:31,361 DEBUG org.apache.hadoop.yarn.server.resourcemanager.scheduler.capacity.CapacityScheduler: Trying to schedule on node: slave1, available: <memory:4096, vCores:1>
2019-06-07 07:44:31,361 DEBUG org.apache.hadoop.yarn.server.resourcemanager.scheduler.capacity.CapacityScheduler: Trying to schedule on node: slave1, available: <memory:4096, vCores:1>
2019-06-07 07:44:31,361 DEBUG org.apache.hadoop.yarn.server.resourcemanager.scheduler.capacity.ParentQueue: Trying to assign containers to child-queue of root
2019-06-07 07:44:31,361 DEBUG org.apache.hadoop.yarn.server.resourcemanager.scheduler.capacity.ParentQueue: Trying to assign containers to child-queue of root
2019-06-07 07:44:31,361 DEBUG org.apache.hadoop.yarn.server.resourcemanager.scheduler.capacity.ParentQueue: printChildQueues - queue: root child-queues: root.defaultusedCapacity=(0.0),  label=(*)
2019-06-07 07:44:31,361 DEBUG org.apache.hadoop.yarn.server.resourcemanager.scheduler.capacity.ParentQueue: printChildQueues - queue: root child-queues: root.defaultusedCapacity=(0.0),  label=(*)
2019-06-07 07:44:31,362 DEBUG org.apache.hadoop.yarn.server.resourcemanager.scheduler.capacity.ParentQueue: Trying to assign to queue: root.default stats: default: capacity=1.0, absoluteCapacity=1.0, usedResources=<memory:0, vCores:0>, usedCapacity=0.0, absoluteUsedCapacity=0.0, numApps=1, numContainers=0
2019-06-07 07:44:31,362 DEBUG org.apache.hadoop.yarn.server.resourcemanager.scheduler.capacity.ParentQueue: Trying to assign to queue: root.default stats: default: capacity=1.0, absoluteCapacity=1.0, usedResources=<memory:0, vCores:0>, usedCapacity=0.0, absoluteUsedCapacity=0.0, numApps=1, numContainers=0
2019-06-07 07:44:31,362 DEBUG org.apache.hadoop.yarn.server.resourcemanager.scheduler.capacity.LeafQueue: assignContainers: node=slave1 #applications=1
2019-06-07 07:44:31,362 DEBUG org.apache.hadoop.yarn.server.resourcemanager.scheduler.capacity.LeafQueue: assignContainers: node=slave1 #applications=1
2019-06-07 07:44:31,364 DEBUG org.apache.hadoop.yarn.server.resourcemanager.scheduler.capacity.LeafQueue: User limit computation for root in queue default userLimitPercent=100 userLimitFactor=1.0 required: <memory:1024, vCores:1> consumed: <memory:0, vCores:0> user-limit-resource: <memory:8192, vCores:1> queueCapacity: <memory:8192, vCores:1> qconsumed: <memory:0, vCores:0> consumedRatio: 0.0 currentCapacity: <memory:8192, vCores:1> activeUsers: 1.0 clusterCapacity: <memory:8192, vCores:2> resourceByLabel: <memory:8192, vCores:2> usageratio: 0.0 Partition:  maxUserLimit=<memory:8192, vCores:1> userWeight=1.0
2019-06-07 07:44:31,364 DEBUG org.apache.hadoop.yarn.server.resourcemanager.scheduler.capacity.LeafQueue: User limit computation for root in queue default userLimitPercent=100 userLimitFactor=1.0 required: <memory:1024, vCores:1> consumed: <memory:0, vCores:0> user-limit-resource: <memory:8192, vCores:1> queueCapacity: <memory:8192, vCores:1> qconsumed: <memory:0, vCores:0> consumedRatio: 0.0 currentCapacity: <memory:8192, vCores:1> activeUsers: 1.0 clusterCapacity: <memory:8192, vCores:2> resourceByLabel: <memory:8192, vCores:2> usageratio: 0.0 Partition:  maxUserLimit=<memory:8192, vCores:1> userWeight=1.0
2019-06-07 07:44:31,365 DEBUG org.apache.hadoop.yarn.server.resourcemanager.scheduler.capacity.LeafQueue: Headroom calculation for user root:  userLimit=<memory:8192, vCores:1> queueMaxAvailRes=<memory:8192, vCores:1> consumed=<memory:0, vCores:0>
2019-06-07 07:44:31,365 DEBUG org.apache.hadoop.yarn.server.resourcemanager.scheduler.capacity.LeafQueue: Headroom calculation for user root:  userLimit=<memory:8192, vCores:1> queueMaxAvailRes=<memory:8192, vCores:1> consumed=<memory:0, vCores:0>
2019-06-07 07:44:31,367 DEBUG org.apache.hadoop.yarn.server.resourcemanager.scheduler.common.fica.FiCaSchedulerApp: pre-assignContainers for application application_1559893389340_0001
2019-06-07 07:44:31,367 DEBUG org.apache.hadoop.yarn.server.resourcemanager.scheduler.common.fica.FiCaSchedulerApp: pre-assignContainers for application application_1559893389340_0001
2019-06-07 07:44:31,367 DEBUG org.apache.hadoop.yarn.server.resourcemanager.scheduler.capacity.LeafQueue: User limit computation for root in queue default userLimitPercent=100 userLimitFactor=1.0 required: <memory:1024, vCores:1> consumed: <memory:0, vCores:0> user-limit-resource: <memory:8192, vCores:1> queueCapacity: <memory:8192, vCores:1> qconsumed: <memory:0, vCores:0> consumedRatio: 0.0 currentCapacity: <memory:8192, vCores:1> activeUsers: 1.0 clusterCapacity: <memory:8192, vCores:2> resourceByLabel: <memory:8192, vCores:2> usageratio: 0.0 Partition:  maxUserLimit=<memory:8192, vCores:1> userWeight=1.0
2019-06-07 07:44:31,367 DEBUG org.apache.hadoop.yarn.server.resourcemanager.scheduler.capacity.LeafQueue: User limit computation for root in queue default userLimitPercent=100 userLimitFactor=1.0 required: <memory:1024, vCores:1> consumed: <memory:0, vCores:0> user-limit-resource: <memory:8192, vCores:1> queueCapacity: <memory:8192, vCores:1> qconsumed: <memory:0, vCores:0> consumedRatio: 0.0 currentCapacity: <memory:8192, vCores:1> activeUsers: 1.0 clusterCapacity: <memory:8192, vCores:2> resourceByLabel: <memory:8192, vCores:2> usageratio: 0.0 Partition:  maxUserLimit=<memory:8192, vCores:1> userWeight=1.0
2019-06-07 07:44:31,367 DEBUG org.apache.hadoop.yarn.server.resourcemanager.scheduler.SchedulerApplicationAttempt: showRequests: application=application_1559893389340_0001 headRoom=<memory:8192, vCores:2> currentConsumption=0
2019-06-07 07:44:31,367 DEBUG org.apache.hadoop.yarn.server.resourcemanager.scheduler.SchedulerApplicationAttempt: showRequests: application=application_1559893389340_0001 headRoom=<memory:8192, vCores:2> currentConsumption=0
2019-06-07 07:44:31,367 DEBUG org.apache.hadoop.yarn.server.resourcemanager.scheduler.SchedulerApplicationAttempt: showRequests: application=application_1559893389340_0001 request={Priority: 0, Capability: <memory:1024, vCores:1>, # Containers: 1, Location: *, Relax Locality: true, Node Label Expression: }
2019-06-07 07:44:31,367 DEBUG org.apache.hadoop.yarn.server.resourcemanager.scheduler.SchedulerApplicationAttempt: showRequests: application=application_1559893389340_0001 request={Priority: 0, Capability: <memory:1024, vCores:1>, # Containers: 1, Location: *, Relax Locality: true, Node Label Expression: }
2019-06-07 07:44:31,368 DEBUG org.apache.hadoop.yarn.server.resourcemanager.scheduler.capacity.allocator.IncreaseContainerAllocator: Skip allocating increase request since we don't have any increase request on this node=slave1:35126
2019-06-07 07:44:31,368 DEBUG org.apache.hadoop.yarn.server.resourcemanager.scheduler.capacity.allocator.IncreaseContainerAllocator: Skip allocating increase request since we don't have any increase request on this node=slave1:35126
2019-06-07 07:44:31,370 DEBUG org.apache.hadoop.yarn.server.resourcemanager.scheduler.capacity.allocator.RegularContainerAllocator: assignContainers: node=slave1 application=application_1559893389340_0001 priority=0 request={Priority: 0, Capability: <memory:1024, vCores:1>, # Containers: 1, Location: *, Relax Locality: true, Node Label Expression: } type=OFF_SWITCH
2019-06-07 07:44:31,370 DEBUG org.apache.hadoop.yarn.server.resourcemanager.scheduler.capacity.allocator.RegularContainerAllocator: assignContainers: node=slave1 application=application_1559893389340_0001 priority=0 request={Priority: 0, Capability: <memory:1024, vCores:1>, # Containers: 1, Location: *, Relax Locality: true, Node Label Expression: } type=OFF_SWITCH
2019-06-07 07:44:31,374 DEBUG org.apache.hadoop.yarn.server.resourcemanager.rmnode.RMNodeImpl: Processing slave2:33474 of type STATUS_UPDATE
2019-06-07 07:44:31,374 DEBUG org.apache.hadoop.yarn.server.resourcemanager.rmnode.RMNodeImpl: Processing slave2:33474 of type STATUS_UPDATE
2019-06-07 07:44:31,504 DEBUG org.apache.hadoop.yarn.server.resourcemanager.scheduler.ActiveUsersManager: User root removed from activeUsers, currently: 0
2019-06-07 07:44:31,504 DEBUG org.apache.hadoop.yarn.server.resourcemanager.scheduler.ActiveUsersManager: User root removed from activeUsers, currently: 0
2019-06-07 07:44:31,504 DEBUG org.apache.hadoop.yarn.server.resourcemanager.scheduler.AppSchedulingInfo: allocate: applicationId=application_1559893389340_0001 container=container_1559893389340_0001_01_000001 host=slave1:35126 user=root resource=<memory:1024, vCores:1> type=OFF_SWITCH
2019-06-07 07:44:31,504 DEBUG org.apache.hadoop.yarn.server.resourcemanager.scheduler.AppSchedulingInfo: allocate: applicationId=application_1559893389340_0001 container=container_1559893389340_0001_01_000001 host=slave1:35126 user=root resource=<memory:1024, vCores:1> type=OFF_SWITCH
2019-06-07 07:44:31,504 DEBUG org.apache.hadoop.yarn.server.resourcemanager.rmcontainer.RMContainerImpl: Processing container_1559893389340_0001_01_000001 of type START
2019-06-07 07:44:31,504 DEBUG org.apache.hadoop.yarn.server.resourcemanager.rmcontainer.RMContainerImpl: Processing container_1559893389340_0001_01_000001 of type START
2019-06-07 07:44:31,504 DEBUG org.apache.hadoop.yarn.server.resourcemanager.rmapp.attempt.RMAppAttemptImpl: Processing event for appattempt_1559893389340_0001_000001 of type CONTAINER_ALLOCATED
2019-06-07 07:44:31,504 DEBUG org.apache.hadoop.yarn.server.resourcemanager.rmapp.attempt.RMAppAttemptImpl: Processing event for appattempt_1559893389340_0001_000001 of type CONTAINER_ALLOCATED
2019-06-07 07:44:31,505 INFO org.apache.hadoop.yarn.server.resourcemanager.rmcontainer.RMContainerImpl: container_1559893389340_0001_01_000001 Container Transitioned from NEW to ALLOCATED
2019-06-07 07:44:31,505 INFO org.apache.hadoop.yarn.server.resourcemanager.rmcontainer.RMContainerImpl: container_1559893389340_0001_01_000001 Container Transitioned from NEW to ALLOCATED
2019-06-07 07:44:31,505 DEBUG org.apache.hadoop.yarn.server.resourcemanager.scheduler.common.fica.FiCaSchedulerApp: allocate: applicationAttemptId=appattempt_1559893389340_0001_000001 container=container_1559893389340_0001_01_000001 host=slave1 type=OFF_SWITCH
2019-06-07 07:44:31,505 DEBUG org.apache.hadoop.yarn.server.resourcemanager.scheduler.common.fica.FiCaSchedulerApp: allocate: applicationAttemptId=appattempt_1559893389340_0001_000001 container=container_1559893389340_0001_01_000001 host=slave1 type=OFF_SWITCH
2019-06-07 07:44:31,505 INFO org.apache.hadoop.yarn.server.resourcemanager.RMAuditLogger: USER=root	OPERATION=AM Allocated Container	TARGET=SchedulerApp	RESULT=SUCCESS	APPID=application_1559893389340_0001	CONTAINERID=container_1559893389340_0001_01_000001
2019-06-07 07:44:31,505 INFO org.apache.hadoop.yarn.server.resourcemanager.RMAuditLogger: USER=root	OPERATION=AM Allocated Container	TARGET=SchedulerApp	RESULT=SUCCESS	APPID=application_1559893389340_0001	CONTAINERID=container_1559893389340_0001_01_000001
2019-06-07 07:44:31,506 INFO org.apache.hadoop.yarn.server.resourcemanager.scheduler.SchedulerNode: Assigned container container_1559893389340_0001_01_000001 of capacity <memory:1024, vCores:1> on host slave1:35126, which has 1 containers, <memory:1024, vCores:1> used and <memory:3072, vCores:0> available after allocation
2019-06-07 07:44:31,506 INFO org.apache.hadoop.yarn.server.resourcemanager.scheduler.SchedulerNode: Assigned container container_1559893389340_0001_01_000001 of capacity <memory:1024, vCores:1> on host slave1:35126, which has 1 containers, <memory:1024, vCores:1> used and <memory:3072, vCores:0> available after allocation
2019-06-07 07:44:31,506 INFO org.apache.hadoop.yarn.server.resourcemanager.scheduler.capacity.allocator.AbstractContainerAllocator: assignedContainer application attempt=appattempt_1559893389340_0001_000001 container=container_1559893389340_0001_01_000001 queue=org.apache.hadoop.yarn.server.resourcemanager.scheduler.capacity.allocator.RegularContainerAllocator@5fb11a1b clusterResource=<memory:8192, vCores:2> type=OFF_SWITCH requestedPartition=
2019-06-07 07:44:31,506 INFO org.apache.hadoop.yarn.server.resourcemanager.scheduler.capacity.allocator.AbstractContainerAllocator: assignedContainer application attempt=appattempt_1559893389340_0001_000001 container=container_1559893389340_0001_01_000001 queue=org.apache.hadoop.yarn.server.resourcemanager.scheduler.capacity.allocator.RegularContainerAllocator@5fb11a1b clusterResource=<memory:8192, vCores:2> type=OFF_SWITCH requestedPartition=
2019-06-07 07:44:31,509 DEBUG org.apache.hadoop.yarn.server.resourcemanager.scheduler.capacity.LeafQueue: post-assignContainers for application application_1559893389340_0001
2019-06-07 07:44:31,509 DEBUG org.apache.hadoop.yarn.server.resourcemanager.scheduler.capacity.LeafQueue: post-assignContainers for application application_1559893389340_0001
2019-06-07 07:44:31,522 INFO org.apache.hadoop.yarn.server.resourcemanager.security.NMTokenSecretManagerInRM: Sending NMToken for nodeId : slave1:35126 for container : container_1559893389340_0001_01_000001
2019-06-07 07:44:31,522 INFO org.apache.hadoop.yarn.server.resourcemanager.security.NMTokenSecretManagerInRM: Sending NMToken for nodeId : slave1:35126 for container : container_1559893389340_0001_01_000001
2019-06-07 07:44:31,529 DEBUG org.apache.hadoop.yarn.server.resourcemanager.rmcontainer.RMContainerImpl: Processing container_1559893389340_0001_01_000001 of type ACQUIRED
2019-06-07 07:44:31,529 DEBUG org.apache.hadoop.yarn.server.resourcemanager.rmcontainer.RMContainerImpl: Processing container_1559893389340_0001_01_000001 of type ACQUIRED
2019-06-07 07:44:31,530 INFO org.apache.hadoop.yarn.server.resourcemanager.rmcontainer.RMContainerImpl: container_1559893389340_0001_01_000001 Container Transitioned from ALLOCATED to ACQUIRED
2019-06-07 07:44:31,530 INFO org.apache.hadoop.yarn.server.resourcemanager.rmcontainer.RMContainerImpl: container_1559893389340_0001_01_000001 Container Transitioned from ALLOCATED to ACQUIRED
2019-06-07 07:44:31,531 DEBUG org.apache.hadoop.yarn.server.resourcemanager.scheduler.capacity.LeafQueue: User limit computation for root in queue default userLimitPercent=100 userLimitFactor=1.0 required: <memory:1024, vCores:1> consumed: <memory:0, vCores:0> user-limit-resource: <memory:8192, vCores:1> queueCapacity: <memory:8192, vCores:1> qconsumed: <memory:0, vCores:0> consumedRatio: 0.0 currentCapacity: <memory:8192, vCores:1> activeUsers: 0.0 clusterCapacity: <memory:8192, vCores:2> resourceByLabel: <memory:8192, vCores:2> usageratio: 0.0 Partition:  maxUserLimit=<memory:8192, vCores:1> userWeight=1.0
2019-06-07 07:44:31,531 DEBUG org.apache.hadoop.yarn.server.resourcemanager.scheduler.capacity.LeafQueue: User limit computation for root in queue default userLimitPercent=100 userLimitFactor=1.0 required: <memory:1024, vCores:1> consumed: <memory:0, vCores:0> user-limit-resource: <memory:8192, vCores:1> queueCapacity: <memory:8192, vCores:1> qconsumed: <memory:0, vCores:0> consumedRatio: 0.0 currentCapacity: <memory:8192, vCores:1> activeUsers: 0.0 clusterCapacity: <memory:8192, vCores:2> resourceByLabel: <memory:8192, vCores:2> usageratio: 0.0 Partition:  maxUserLimit=<memory:8192, vCores:1> userWeight=1.0
2019-06-07 07:44:31,531 INFO org.apache.hadoop.yarn.server.resourcemanager.security.NMTokenSecretManagerInRM: Clear node set for appattempt_1559893389340_0001_000001
2019-06-07 07:44:31,531 INFO org.apache.hadoop.yarn.server.resourcemanager.security.NMTokenSecretManagerInRM: Clear node set for appattempt_1559893389340_0001_000001
2019-06-07 07:44:31,531 INFO org.apache.hadoop.yarn.server.resourcemanager.rmapp.attempt.RMAppAttemptImpl: Storing attempt: AppId: application_1559893389340_0001 AttemptId: appattempt_1559893389340_0001_000001 MasterContainer: Container: [ContainerId: container_1559893389340_0001_01_000001, Version: 0, NodeId: slave1:35126, NodeHttpAddress: slave1:8042, Resource: <memory:1024, vCores:1>, Priority: 0, Token: Token { kind: ContainerToken, service: 172.17.0.3:35126 }, ]
2019-06-07 07:44:31,531 INFO org.apache.hadoop.yarn.server.resourcemanager.rmapp.attempt.RMAppAttemptImpl: Storing attempt: AppId: application_1559893389340_0001 AttemptId: appattempt_1559893389340_0001_000001 MasterContainer: Container: [ContainerId: container_1559893389340_0001_01_000001, Version: 0, NodeId: slave1:35126, NodeHttpAddress: slave1:8042, Resource: <memory:1024, vCores:1>, Priority: 0, Token: Token { kind: ContainerToken, service: 172.17.0.3:35126 }, ]
2019-06-07 07:44:31,532 DEBUG org.apache.hadoop.yarn.server.resourcemanager.scheduler.capacity.LeafQueue: User limit computation for root in queue default userLimitPercent=100 userLimitFactor=1.0 required: <memory:1024, vCores:1> consumed: <memory:1024, vCores:1> user-limit-resource: <memory:8192, vCores:1> queueCapacity: <memory:8192, vCores:1> qconsumed: <memory:1024, vCores:1> consumedRatio: 0.0 currentCapacity: <memory:8192, vCores:1> activeUsers: 0.0 clusterCapacity: <memory:8192, vCores:2> resourceByLabel: <memory:8192, vCores:2> usageratio: 0.125 Partition:  maxUserLimit=<memory:8192, vCores:1> userWeight=1.0
2019-06-07 07:44:31,532 DEBUG org.apache.hadoop.yarn.server.resourcemanager.scheduler.capacity.LeafQueue: User limit computation for root in queue default userLimitPercent=100 userLimitFactor=1.0 required: <memory:1024, vCores:1> consumed: <memory:1024, vCores:1> user-limit-resource: <memory:8192, vCores:1> queueCapacity: <memory:8192, vCores:1> qconsumed: <memory:1024, vCores:1> consumedRatio: 0.0 currentCapacity: <memory:8192, vCores:1> activeUsers: 0.0 clusterCapacity: <memory:8192, vCores:2> resourceByLabel: <memory:8192, vCores:2> usageratio: 0.125 Partition:  maxUserLimit=<memory:8192, vCores:1> userWeight=1.0
2019-06-07 07:44:31,532 DEBUG org.apache.hadoop.yarn.server.resourcemanager.scheduler.capacity.LeafQueue: User limit computation for root in queue default userLimitPercent=100 userLimitFactor=1.0 required: <memory:1024, vCores:1> consumed: <memory:1024, vCores:1> user-limit-resource: <memory:8192, vCores:1> queueCapacity: <memory:8192, vCores:1> qconsumed: <memory:1024, vCores:1> consumedRatio: 0.0 currentCapacity: <memory:8192, vCores:1> activeUsers: 0.0 clusterCapacity: <memory:8192, vCores:2> resourceByLabel: <memory:8192, vCores:2> usageratio: 0.125 Partition:  maxUserLimit=<memory:8192, vCores:1> userWeight=1.0
2019-06-07 07:44:31,532 DEBUG org.apache.hadoop.yarn.server.resourcemanager.scheduler.capacity.LeafQueue: User limit computation for root in queue default userLimitPercent=100 userLimitFactor=1.0 required: <memory:1024, vCores:1> consumed: <memory:1024, vCores:1> user-limit-resource: <memory:8192, vCores:1> queueCapacity: <memory:8192, vCores:1> qconsumed: <memory:1024, vCores:1> consumedRatio: 0.0 currentCapacity: <memory:8192, vCores:1> activeUsers: 0.0 clusterCapacity: <memory:8192, vCores:2> resourceByLabel: <memory:8192, vCores:2> usageratio: 0.125 Partition:  maxUserLimit=<memory:8192, vCores:1> userWeight=1.0
2019-06-07 07:44:31,533 DEBUG org.apache.hadoop.yarn.server.resourcemanager.scheduler.capacity.LeafQueue: User limit computation for root in queue default userLimitPercent=100 userLimitFactor=1.0 required: <memory:1024, vCores:1> consumed: <memory:1024, vCores:1> user-limit-resource: <memory:8192, vCores:1> queueCapacity: <memory:8192, vCores:1> qconsumed: <memory:1024, vCores:1> consumedRatio: 0.0 currentCapacity: <memory:8192, vCores:1> activeUsers: 0.0 clusterCapacity: <memory:8192, vCores:2> resourceByLabel: <memory:8192, vCores:2> usageratio: 0.125 Partition:  maxUserLimit=<memory:8192, vCores:1> userWeight=1.0
2019-06-07 07:44:31,533 DEBUG org.apache.hadoop.yarn.server.resourcemanager.scheduler.capacity.LeafQueue: User limit computation for root in queue default userLimitPercent=100 userLimitFactor=1.0 required: <memory:1024, vCores:1> consumed: <memory:1024, vCores:1> user-limit-resource: <memory:8192, vCores:1> queueCapacity: <memory:8192, vCores:1> qconsumed: <memory:1024, vCores:1> consumedRatio: 0.0 currentCapacity: <memory:8192, vCores:1> activeUsers: 0.0 clusterCapacity: <memory:8192, vCores:2> resourceByLabel: <memory:8192, vCores:2> usageratio: 0.125 Partition:  maxUserLimit=<memory:8192, vCores:1> userWeight=1.0
2019-06-07 07:44:31,533 DEBUG org.apache.hadoop.yarn.server.resourcemanager.scheduler.capacity.LeafQueue: default user=root used=<memory:1024, vCores:1> numContainers=1 headroom = <memory:7168, vCores:1> user-resources=<memory:1024, vCores:1>
2019-06-07 07:44:31,533 DEBUG org.apache.hadoop.yarn.server.resourcemanager.scheduler.capacity.LeafQueue: default user=root used=<memory:1024, vCores:1> numContainers=1 headroom = <memory:7168, vCores:1> user-resources=<memory:1024, vCores:1>
2019-06-07 07:44:31,533 DEBUG org.apache.hadoop.yarn.server.resourcemanager.scheduler.capacity.ParentQueue: Assigned to queue: root.default stats: default: capacity=1.0, absoluteCapacity=1.0, usedResources=<memory:1024, vCores:1>, usedCapacity=0.125, absoluteUsedCapacity=0.125, numApps=1, numContainers=1 --> <memory:1024, vCores:1>, OFF_SWITCH
2019-06-07 07:44:31,533 DEBUG org.apache.hadoop.yarn.server.resourcemanager.scheduler.capacity.ParentQueue: Assigned to queue: root.default stats: default: capacity=1.0, absoluteCapacity=1.0, usedResources=<memory:1024, vCores:1>, usedCapacity=0.125, absoluteUsedCapacity=0.125, numApps=1, numContainers=1 --> <memory:1024, vCores:1>, OFF_SWITCH
2019-06-07 07:44:31,533 INFO org.apache.hadoop.yarn.server.resourcemanager.scheduler.capacity.ParentQueue: Re-sorting assigned queue: root.default stats: default: capacity=1.0, absoluteCapacity=1.0, usedResources=<memory:1024, vCores:1>, usedCapacity=0.125, absoluteUsedCapacity=0.125, numApps=1, numContainers=1
2019-06-07 07:44:31,533 INFO org.apache.hadoop.yarn.server.resourcemanager.scheduler.capacity.ParentQueue: Re-sorting assigned queue: root.default stats: default: capacity=1.0, absoluteCapacity=1.0, usedResources=<memory:1024, vCores:1>, usedCapacity=0.125, absoluteUsedCapacity=0.125, numApps=1, numContainers=1
2019-06-07 07:44:31,533 DEBUG org.apache.hadoop.yarn.server.resourcemanager.scheduler.capacity.ParentQueue: printChildQueues - queue: root child-queues: root.defaultusedCapacity=(0.125),  label=(*)
2019-06-07 07:44:31,533 DEBUG org.apache.hadoop.yarn.server.resourcemanager.scheduler.capacity.ParentQueue: printChildQueues - queue: root child-queues: root.defaultusedCapacity=(0.125),  label=(*)
2019-06-07 07:44:31,533 INFO org.apache.hadoop.yarn.server.resourcemanager.scheduler.capacity.ParentQueue: assignedContainer queue=root usedCapacity=0.125 absoluteUsedCapacity=0.125 used=<memory:1024, vCores:1> cluster=<memory:8192, vCores:2>
2019-06-07 07:44:31,533 INFO org.apache.hadoop.yarn.server.resourcemanager.scheduler.capacity.ParentQueue: assignedContainer queue=root usedCapacity=0.125 absoluteUsedCapacity=0.125 used=<memory:1024, vCores:1> cluster=<memory:8192, vCores:2>
2019-06-07 07:44:31,533 DEBUG org.apache.hadoop.yarn.server.resourcemanager.scheduler.capacity.ParentQueue: ParentQ=root assignedSoFarInThisIteration=<memory:1024, vCores:1> usedCapacity=0.125 absoluteUsedCapacity=0.125
2019-06-07 07:44:31,533 DEBUG org.apache.hadoop.yarn.server.resourcemanager.scheduler.capacity.ParentQueue: ParentQ=root assignedSoFarInThisIteration=<memory:1024, vCores:1> usedCapacity=0.125 absoluteUsedCapacity=0.125
2019-06-07 07:44:31,533 DEBUG org.apache.hadoop.yarn.server.resourcemanager.scheduler.capacity.ParentQueue: Assigned maximum number of off-switch containers: 1, assignments so far: resource:<memory:1024, vCores:1>; type:OFF_SWITCH; excessReservation:null; applicationid:null; skipped:NONE; fulfilled reservation:false; allocations(count/resource):1/<memory:1024, vCores:1>; reservations(count/resource):0/<memory:0, vCores:0>
2019-06-07 07:44:31,533 DEBUG org.apache.hadoop.yarn.server.resourcemanager.scheduler.capacity.ParentQueue: Assigned maximum number of off-switch containers: 1, assignments so far: resource:<memory:1024, vCores:1>; type:OFF_SWITCH; excessReservation:null; applicationid:null; skipped:NONE; fulfilled reservation:false; allocations(count/resource):1/<memory:1024, vCores:1>; reservations(count/resource):0/<memory:0, vCores:0>
2019-06-07 07:44:31,534 DEBUG org.apache.hadoop.yarn.server.resourcemanager.scheduler.capacity.CapacityScheduler: nodeUpdate: slave2:33474 clusterResources: <memory:8192, vCores:2>
2019-06-07 07:44:31,534 DEBUG org.apache.hadoop.yarn.server.resourcemanager.scheduler.capacity.CapacityScheduler: nodeUpdate: slave2:33474 clusterResources: <memory:8192, vCores:2>
2019-06-07 07:44:31,534 DEBUG org.apache.hadoop.yarn.server.resourcemanager.scheduler.capacity.CapacityScheduler: Node being looked for scheduling slave2:33474 availableResource: <memory:4096, vCores:1>
2019-06-07 07:44:31,534 DEBUG org.apache.hadoop.yarn.server.resourcemanager.scheduler.capacity.CapacityScheduler: Node being looked for scheduling slave2:33474 availableResource: <memory:4096, vCores:1>
2019-06-07 07:44:31,534 DEBUG org.apache.hadoop.yarn.server.resourcemanager.scheduler.capacity.CapacityScheduler: Trying to schedule on node: slave2, available: <memory:4096, vCores:1>
2019-06-07 07:44:31,534 DEBUG org.apache.hadoop.yarn.server.resourcemanager.scheduler.capacity.CapacityScheduler: Trying to schedule on node: slave2, available: <memory:4096, vCores:1>
2019-06-07 07:44:31,534 DEBUG org.apache.hadoop.yarn.server.resourcemanager.scheduler.capacity.ParentQueue: Skip this queue=root, because it doesn't need more resource, schedulingMode=RESPECT_PARTITION_EXCLUSIVITY node-partition=
2019-06-07 07:44:31,534 DEBUG org.apache.hadoop.yarn.server.resourcemanager.scheduler.capacity.ParentQueue: Skip this queue=root, because it doesn't need more resource, schedulingMode=RESPECT_PARTITION_EXCLUSIVITY node-partition=
2019-06-07 07:44:31,541 DEBUG org.apache.hadoop.yarn.server.resourcemanager.recovery.RMStateStore: Processing event of type STORE_APP_ATTEMPT
2019-06-07 07:44:31,541 DEBUG org.apache.hadoop.yarn.server.resourcemanager.recovery.RMStateStore: Processing event of type STORE_APP_ATTEMPT
2019-06-07 07:44:31,541 DEBUG org.apache.hadoop.yarn.server.resourcemanager.recovery.RMStateStore: Storing info for attempt: appattempt_1559893389340_0001_000001
2019-06-07 07:44:31,541 DEBUG org.apache.hadoop.yarn.server.resourcemanager.recovery.RMStateStore: Storing info for attempt: appattempt_1559893389340_0001_000001
2019-06-07 07:44:31,541 INFO org.apache.hadoop.yarn.server.resourcemanager.rmapp.attempt.RMAppAttemptImpl: appattempt_1559893389340_0001_000001 State change from SCHEDULED to ALLOCATED_SAVING
2019-06-07 07:44:31,541 INFO org.apache.hadoop.yarn.server.resourcemanager.rmapp.attempt.RMAppAttemptImpl: appattempt_1559893389340_0001_000001 State change from SCHEDULED to ALLOCATED_SAVING
2019-06-07 07:44:31,542 DEBUG org.apache.hadoop.yarn.server.resourcemanager.rmapp.RMAppImpl: Processing event for application_1559893389340_0001 of type APP_RUNNING_ON_NODE
2019-06-07 07:44:31,542 DEBUG org.apache.hadoop.yarn.server.resourcemanager.rmapp.RMAppImpl: Processing event for application_1559893389340_0001 of type APP_RUNNING_ON_NODE
2019-06-07 07:44:31,546 DEBUG org.apache.hadoop.yarn.server.resourcemanager.rmapp.attempt.RMAppAttemptImpl: Processing event for appattempt_1559893389340_0001_000001 of type ATTEMPT_NEW_SAVED
2019-06-07 07:44:31,546 DEBUG org.apache.hadoop.yarn.server.resourcemanager.rmapp.attempt.RMAppAttemptImpl: Processing event for appattempt_1559893389340_0001_000001 of type ATTEMPT_NEW_SAVED
2019-06-07 07:44:31,547 INFO org.apache.hadoop.yarn.server.resourcemanager.rmapp.attempt.RMAppAttemptImpl: appattempt_1559893389340_0001_000001 State change from ALLOCATED_SAVING to ALLOCATED
2019-06-07 07:44:31,547 INFO org.apache.hadoop.yarn.server.resourcemanager.rmapp.attempt.RMAppAttemptImpl: appattempt_1559893389340_0001_000001 State change from ALLOCATED_SAVING to ALLOCATED
2019-06-07 07:44:31,549 INFO org.apache.hadoop.yarn.server.resourcemanager.amlauncher.AMLauncher: Launching masterappattempt_1559893389340_0001_000001
2019-06-07 07:44:31,549 INFO org.apache.hadoop.yarn.server.resourcemanager.amlauncher.AMLauncher: Launching masterappattempt_1559893389340_0001_000001
2019-06-07 07:44:31,587 INFO org.apache.hadoop.yarn.server.resourcemanager.amlauncher.AMLauncher: Setting up container Container: [ContainerId: container_1559893389340_0001_01_000001, Version: 0, NodeId: slave1:35126, NodeHttpAddress: slave1:8042, Resource: <memory:1024, vCores:1>, Priority: 0, Token: Token { kind: ContainerToken, service: 172.17.0.3:35126 }, ] for AM appattempt_1559893389340_0001_000001
2019-06-07 07:44:31,587 INFO org.apache.hadoop.yarn.server.resourcemanager.amlauncher.AMLauncher: Setting up container Container: [ContainerId: container_1559893389340_0001_01_000001, Version: 0, NodeId: slave1:35126, NodeHttpAddress: slave1:8042, Resource: <memory:1024, vCores:1>, Priority: 0, Token: Token { kind: ContainerToken, service: 172.17.0.3:35126 }, ] for AM appattempt_1559893389340_0001_000001
2019-06-07 07:44:31,587 INFO org.apache.hadoop.yarn.server.resourcemanager.security.AMRMTokenSecretManager: Create AMRMToken for ApplicationAttempt: appattempt_1559893389340_0001_000001
2019-06-07 07:44:31,587 INFO org.apache.hadoop.yarn.server.resourcemanager.security.AMRMTokenSecretManager: Create AMRMToken for ApplicationAttempt: appattempt_1559893389340_0001_000001
2019-06-07 07:44:31,590 INFO org.apache.hadoop.yarn.server.resourcemanager.security.AMRMTokenSecretManager: Creating password for appattempt_1559893389340_0001_000001
2019-06-07 07:44:31,590 INFO org.apache.hadoop.yarn.server.resourcemanager.security.AMRMTokenSecretManager: Creating password for appattempt_1559893389340_0001_000001
2019-06-07 07:44:31,892 INFO org.apache.hadoop.yarn.server.resourcemanager.amlauncher.AMLauncher: Done launching container Container: [ContainerId: container_1559893389340_0001_01_000001, Version: 0, NodeId: slave1:35126, NodeHttpAddress: slave1:8042, Resource: <memory:1024, vCores:1>, Priority: 0, Token: Token { kind: ContainerToken, service: 172.17.0.3:35126 }, ] for AM appattempt_1559893389340_0001_000001
2019-06-07 07:44:31,892 INFO org.apache.hadoop.yarn.server.resourcemanager.amlauncher.AMLauncher: Done launching container Container: [ContainerId: container_1559893389340_0001_01_000001, Version: 0, NodeId: slave1:35126, NodeHttpAddress: slave1:8042, Resource: <memory:1024, vCores:1>, Priority: 0, Token: Token { kind: ContainerToken, service: 172.17.0.3:35126 }, ] for AM appattempt_1559893389340_0001_000001
2019-06-07 07:44:31,892 DEBUG org.apache.hadoop.yarn.server.resourcemanager.rmapp.attempt.RMAppAttemptImpl: Processing event for appattempt_1559893389340_0001_000001 of type LAUNCHED
2019-06-07 07:44:31,892 DEBUG org.apache.hadoop.yarn.server.resourcemanager.rmapp.attempt.RMAppAttemptImpl: Processing event for appattempt_1559893389340_0001_000001 of type LAUNCHED
2019-06-07 07:44:31,892 INFO org.apache.hadoop.yarn.server.resourcemanager.rmapp.attempt.RMAppAttemptImpl: appattempt_1559893389340_0001_000001 State change from ALLOCATED to LAUNCHED
2019-06-07 07:44:31,892 INFO org.apache.hadoop.yarn.server.resourcemanager.rmapp.attempt.RMAppAttemptImpl: appattempt_1559893389340_0001_000001 State change from ALLOCATED to LAUNCHED
2019-06-07 07:44:32,377 DEBUG org.apache.hadoop.yarn.server.resourcemanager.rmnode.RMNodeImpl: Processing slave2:33474 of type STATUS_UPDATE
2019-06-07 07:44:32,377 DEBUG org.apache.hadoop.yarn.server.resourcemanager.rmnode.RMNodeImpl: Processing slave2:33474 of type STATUS_UPDATE
2019-06-07 07:44:32,377 DEBUG org.apache.hadoop.yarn.server.resourcemanager.scheduler.capacity.CapacityScheduler: nodeUpdate: slave2:33474 clusterResources: <memory:8192, vCores:2>
2019-06-07 07:44:32,377 DEBUG org.apache.hadoop.yarn.server.resourcemanager.scheduler.capacity.CapacityScheduler: nodeUpdate: slave2:33474 clusterResources: <memory:8192, vCores:2>
2019-06-07 07:44:32,377 DEBUG org.apache.hadoop.yarn.server.resourcemanager.scheduler.capacity.CapacityScheduler: Node being looked for scheduling slave2:33474 availableResource: <memory:4096, vCores:1>
2019-06-07 07:44:32,377 DEBUG org.apache.hadoop.yarn.server.resourcemanager.scheduler.capacity.CapacityScheduler: Node being looked for scheduling slave2:33474 availableResource: <memory:4096, vCores:1>
2019-06-07 07:44:32,377 DEBUG org.apache.hadoop.yarn.server.resourcemanager.scheduler.capacity.CapacityScheduler: Trying to schedule on node: slave2, available: <memory:4096, vCores:1>
2019-06-07 07:44:32,377 DEBUG org.apache.hadoop.yarn.server.resourcemanager.scheduler.capacity.CapacityScheduler: Trying to schedule on node: slave2, available: <memory:4096, vCores:1>
2019-06-07 07:44:32,377 DEBUG org.apache.hadoop.yarn.server.resourcemanager.scheduler.capacity.ParentQueue: Skip this queue=root, because it doesn't need more resource, schedulingMode=RESPECT_PARTITION_EXCLUSIVITY node-partition=
2019-06-07 07:44:32,377 DEBUG org.apache.hadoop.yarn.server.resourcemanager.scheduler.capacity.ParentQueue: Skip this queue=root, because it doesn't need more resource, schedulingMode=RESPECT_PARTITION_EXCLUSIVITY node-partition=
2019-06-07 07:44:32,496 DEBUG org.apache.hadoop.yarn.server.resourcemanager.rmnode.RMNodeImpl: Processing slave1:35126 of type STATUS_UPDATE
2019-06-07 07:44:32,496 DEBUG org.apache.hadoop.yarn.server.resourcemanager.rmnode.RMNodeImpl: Processing slave1:35126 of type STATUS_UPDATE
2019-06-07 07:44:32,497 DEBUG org.apache.hadoop.yarn.server.resourcemanager.rmnode.RMNodeImpl: Container container_1559893389340_0001_01_000001 is the first container get launched for application application_1559893389340_0001
2019-06-07 07:44:32,497 DEBUG org.apache.hadoop.yarn.server.resourcemanager.rmnode.RMNodeImpl: Container container_1559893389340_0001_01_000001 is the first container get launched for application application_1559893389340_0001
2019-06-07 07:44:32,498 DEBUG org.apache.hadoop.yarn.server.resourcemanager.rmapp.RMAppImpl: Processing event for application_1559893389340_0001 of type APP_RUNNING_ON_NODE
2019-06-07 07:44:32,498 DEBUG org.apache.hadoop.yarn.server.resourcemanager.rmapp.RMAppImpl: Processing event for application_1559893389340_0001 of type APP_RUNNING_ON_NODE
2019-06-07 07:44:32,498 DEBUG org.apache.hadoop.yarn.server.resourcemanager.scheduler.capacity.CapacityScheduler: nodeUpdate: slave1:35126 clusterResources: <memory:8192, vCores:2>
2019-06-07 07:44:32,498 DEBUG org.apache.hadoop.yarn.server.resourcemanager.scheduler.capacity.CapacityScheduler: nodeUpdate: slave1:35126 clusterResources: <memory:8192, vCores:2>
2019-06-07 07:44:32,504 DEBUG org.apache.hadoop.yarn.server.resourcemanager.rmcontainer.RMContainerImpl: Processing container_1559893389340_0001_01_000001 of type LAUNCHED
2019-06-07 07:44:32,504 DEBUG org.apache.hadoop.yarn.server.resourcemanager.rmcontainer.RMContainerImpl: Processing container_1559893389340_0001_01_000001 of type LAUNCHED
2019-06-07 07:44:32,504 INFO org.apache.hadoop.yarn.server.resourcemanager.rmcontainer.RMContainerImpl: container_1559893389340_0001_01_000001 Container Transitioned from ACQUIRED to RUNNING
2019-06-07 07:44:32,504 INFO org.apache.hadoop.yarn.server.resourcemanager.rmcontainer.RMContainerImpl: container_1559893389340_0001_01_000001 Container Transitioned from ACQUIRED to RUNNING
2019-06-07 07:44:32,504 DEBUG org.apache.hadoop.yarn.server.resourcemanager.scheduler.capacity.CapacityScheduler: Node being looked for scheduling slave1:35126 availableResource: <memory:3072, vCores:0>
2019-06-07 07:44:32,504 DEBUG org.apache.hadoop.yarn.server.resourcemanager.scheduler.capacity.CapacityScheduler: Node being looked for scheduling slave1:35126 availableResource: <memory:3072, vCores:0>
2019-06-07 07:44:32,504 DEBUG org.apache.hadoop.yarn.server.resourcemanager.scheduler.capacity.CapacityScheduler: Trying to schedule on node: slave1, available: <memory:3072, vCores:0>
2019-06-07 07:44:32,504 DEBUG org.apache.hadoop.yarn.server.resourcemanager.scheduler.capacity.CapacityScheduler: Trying to schedule on node: slave1, available: <memory:3072, vCores:0>
2019-06-07 07:44:32,504 DEBUG org.apache.hadoop.yarn.server.resourcemanager.scheduler.capacity.ParentQueue: Skip this queue=root, because it doesn't need more resource, schedulingMode=RESPECT_PARTITION_EXCLUSIVITY node-partition=
2019-06-07 07:44:32,504 DEBUG org.apache.hadoop.yarn.server.resourcemanager.scheduler.capacity.ParentQueue: Skip this queue=root, because it doesn't need more resource, schedulingMode=RESPECT_PARTITION_EXCLUSIVITY node-partition=
2019-06-07 07:44:33,378 DEBUG org.apache.hadoop.yarn.server.resourcemanager.rmnode.RMNodeImpl: Processing slave2:33474 of type STATUS_UPDATE
2019-06-07 07:44:33,378 DEBUG org.apache.hadoop.yarn.server.resourcemanager.rmnode.RMNodeImpl: Processing slave2:33474 of type STATUS_UPDATE
2019-06-07 07:44:33,379 DEBUG org.apache.hadoop.yarn.server.resourcemanager.scheduler.capacity.CapacityScheduler: nodeUpdate: slave2:33474 clusterResources: <memory:8192, vCores:2>
2019-06-07 07:44:33,379 DEBUG org.apache.hadoop.yarn.server.resourcemanager.scheduler.capacity.CapacityScheduler: nodeUpdate: slave2:33474 clusterResources: <memory:8192, vCores:2>
2019-06-07 07:44:33,379 DEBUG org.apache.hadoop.yarn.server.resourcemanager.scheduler.capacity.CapacityScheduler: Node being looked for scheduling slave2:33474 availableResource: <memory:4096, vCores:1>
2019-06-07 07:44:33,379 DEBUG org.apache.hadoop.yarn.server.resourcemanager.scheduler.capacity.CapacityScheduler: Node being looked for scheduling slave2:33474 availableResource: <memory:4096, vCores:1>
2019-06-07 07:44:33,379 DEBUG org.apache.hadoop.yarn.server.resourcemanager.scheduler.capacity.CapacityScheduler: Trying to schedule on node: slave2, available: <memory:4096, vCores:1>
2019-06-07 07:44:33,379 DEBUG org.apache.hadoop.yarn.server.resourcemanager.scheduler.capacity.CapacityScheduler: Trying to schedule on node: slave2, available: <memory:4096, vCores:1>
2019-06-07 07:44:33,379 DEBUG org.apache.hadoop.yarn.server.resourcemanager.scheduler.capacity.ParentQueue: Skip this queue=root, because it doesn't need more resource, schedulingMode=RESPECT_PARTITION_EXCLUSIVITY node-partition=
2019-06-07 07:44:33,379 DEBUG org.apache.hadoop.yarn.server.resourcemanager.scheduler.capacity.ParentQueue: Skip this queue=root, because it doesn't need more resource, schedulingMode=RESPECT_PARTITION_EXCLUSIVITY node-partition=
2019-06-07 07:44:33,507 DEBUG org.apache.hadoop.yarn.server.resourcemanager.rmnode.RMNodeImpl: Processing slave1:35126 of type STATUS_UPDATE
2019-06-07 07:44:33,507 DEBUG org.apache.hadoop.yarn.server.resourcemanager.rmnode.RMNodeImpl: Processing slave1:35126 of type STATUS_UPDATE
2019-06-07 07:44:33,507 DEBUG org.apache.hadoop.yarn.server.resourcemanager.scheduler.capacity.CapacityScheduler: nodeUpdate: slave1:35126 clusterResources: <memory:8192, vCores:2>
2019-06-07 07:44:33,507 DEBUG org.apache.hadoop.yarn.server.resourcemanager.scheduler.capacity.CapacityScheduler: nodeUpdate: slave1:35126 clusterResources: <memory:8192, vCores:2>
2019-06-07 07:44:33,507 DEBUG org.apache.hadoop.yarn.server.resourcemanager.scheduler.capacity.CapacityScheduler: Node being looked for scheduling slave1:35126 availableResource: <memory:3072, vCores:0>
2019-06-07 07:44:33,507 DEBUG org.apache.hadoop.yarn.server.resourcemanager.scheduler.capacity.CapacityScheduler: Node being looked for scheduling slave1:35126 availableResource: <memory:3072, vCores:0>
2019-06-07 07:44:33,507 DEBUG org.apache.hadoop.yarn.server.resourcemanager.scheduler.capacity.CapacityScheduler: Trying to schedule on node: slave1, available: <memory:3072, vCores:0>
2019-06-07 07:44:33,507 DEBUG org.apache.hadoop.yarn.server.resourcemanager.scheduler.capacity.CapacityScheduler: Trying to schedule on node: slave1, available: <memory:3072, vCores:0>
2019-06-07 07:44:33,507 DEBUG org.apache.hadoop.yarn.server.resourcemanager.scheduler.capacity.ParentQueue: Skip this queue=root, because it doesn't need more resource, schedulingMode=RESPECT_PARTITION_EXCLUSIVITY node-partition=
2019-06-07 07:44:33,507 DEBUG org.apache.hadoop.yarn.server.resourcemanager.scheduler.capacity.ParentQueue: Skip this queue=root, because it doesn't need more resource, schedulingMode=RESPECT_PARTITION_EXCLUSIVITY node-partition=
2019-06-07 07:44:34,380 DEBUG org.apache.hadoop.yarn.server.resourcemanager.rmnode.RMNodeImpl: Processing slave2:33474 of type STATUS_UPDATE
2019-06-07 07:44:34,380 DEBUG org.apache.hadoop.yarn.server.resourcemanager.rmnode.RMNodeImpl: Processing slave2:33474 of type STATUS_UPDATE
2019-06-07 07:44:34,381 DEBUG org.apache.hadoop.yarn.server.resourcemanager.scheduler.capacity.CapacityScheduler: nodeUpdate: slave2:33474 clusterResources: <memory:8192, vCores:2>
2019-06-07 07:44:34,381 DEBUG org.apache.hadoop.yarn.server.resourcemanager.scheduler.capacity.CapacityScheduler: nodeUpdate: slave2:33474 clusterResources: <memory:8192, vCores:2>
2019-06-07 07:44:34,381 DEBUG org.apache.hadoop.yarn.server.resourcemanager.scheduler.capacity.CapacityScheduler: Node being looked for scheduling slave2:33474 availableResource: <memory:4096, vCores:1>
2019-06-07 07:44:34,381 DEBUG org.apache.hadoop.yarn.server.resourcemanager.scheduler.capacity.CapacityScheduler: Node being looked for scheduling slave2:33474 availableResource: <memory:4096, vCores:1>
2019-06-07 07:44:34,381 DEBUG org.apache.hadoop.yarn.server.resourcemanager.scheduler.capacity.CapacityScheduler: Trying to schedule on node: slave2, available: <memory:4096, vCores:1>
2019-06-07 07:44:34,381 DEBUG org.apache.hadoop.yarn.server.resourcemanager.scheduler.capacity.CapacityScheduler: Trying to schedule on node: slave2, available: <memory:4096, vCores:1>
2019-06-07 07:44:34,381 DEBUG org.apache.hadoop.yarn.server.resourcemanager.scheduler.capacity.ParentQueue: Skip this queue=root, because it doesn't need more resource, schedulingMode=RESPECT_PARTITION_EXCLUSIVITY node-partition=
2019-06-07 07:44:34,381 DEBUG org.apache.hadoop.yarn.server.resourcemanager.scheduler.capacity.ParentQueue: Skip this queue=root, because it doesn't need more resource, schedulingMode=RESPECT_PARTITION_EXCLUSIVITY node-partition=
2019-06-07 07:44:34,509 DEBUG org.apache.hadoop.yarn.server.resourcemanager.rmnode.RMNodeImpl: Processing slave1:35126 of type STATUS_UPDATE
2019-06-07 07:44:34,509 DEBUG org.apache.hadoop.yarn.server.resourcemanager.rmnode.RMNodeImpl: Processing slave1:35126 of type STATUS_UPDATE
2019-06-07 07:44:34,510 DEBUG org.apache.hadoop.yarn.server.resourcemanager.scheduler.capacity.CapacityScheduler: nodeUpdate: slave1:35126 clusterResources: <memory:8192, vCores:2>
2019-06-07 07:44:34,510 DEBUG org.apache.hadoop.yarn.server.resourcemanager.scheduler.capacity.CapacityScheduler: nodeUpdate: slave1:35126 clusterResources: <memory:8192, vCores:2>
2019-06-07 07:44:34,510 DEBUG org.apache.hadoop.yarn.server.resourcemanager.scheduler.capacity.CapacityScheduler: Node being looked for scheduling slave1:35126 availableResource: <memory:3072, vCores:0>
2019-06-07 07:44:34,510 DEBUG org.apache.hadoop.yarn.server.resourcemanager.scheduler.capacity.CapacityScheduler: Node being looked for scheduling slave1:35126 availableResource: <memory:3072, vCores:0>
2019-06-07 07:44:34,510 DEBUG org.apache.hadoop.yarn.server.resourcemanager.scheduler.capacity.CapacityScheduler: Trying to schedule on node: slave1, available: <memory:3072, vCores:0>
2019-06-07 07:44:34,510 DEBUG org.apache.hadoop.yarn.server.resourcemanager.scheduler.capacity.CapacityScheduler: Trying to schedule on node: slave1, available: <memory:3072, vCores:0>
2019-06-07 07:44:34,510 DEBUG org.apache.hadoop.yarn.server.resourcemanager.scheduler.capacity.ParentQueue: Skip this queue=root, because it doesn't need more resource, schedulingMode=RESPECT_PARTITION_EXCLUSIVITY node-partition=
2019-06-07 07:44:34,510 DEBUG org.apache.hadoop.yarn.server.resourcemanager.scheduler.capacity.ParentQueue: Skip this queue=root, because it doesn't need more resource, schedulingMode=RESPECT_PARTITION_EXCLUSIVITY node-partition=
2019-06-07 07:44:35,383 DEBUG org.apache.hadoop.yarn.server.resourcemanager.rmnode.RMNodeImpl: Processing slave2:33474 of type STATUS_UPDATE
2019-06-07 07:44:35,383 DEBUG org.apache.hadoop.yarn.server.resourcemanager.rmnode.RMNodeImpl: Processing slave2:33474 of type STATUS_UPDATE
2019-06-07 07:44:35,383 DEBUG org.apache.hadoop.yarn.server.resourcemanager.scheduler.capacity.CapacityScheduler: nodeUpdate: slave2:33474 clusterResources: <memory:8192, vCores:2>
2019-06-07 07:44:35,383 DEBUG org.apache.hadoop.yarn.server.resourcemanager.scheduler.capacity.CapacityScheduler: nodeUpdate: slave2:33474 clusterResources: <memory:8192, vCores:2>
2019-06-07 07:44:35,383 DEBUG org.apache.hadoop.yarn.server.resourcemanager.scheduler.capacity.CapacityScheduler: Node being looked for scheduling slave2:33474 availableResource: <memory:4096, vCores:1>
2019-06-07 07:44:35,383 DEBUG org.apache.hadoop.yarn.server.resourcemanager.scheduler.capacity.CapacityScheduler: Node being looked for scheduling slave2:33474 availableResource: <memory:4096, vCores:1>
2019-06-07 07:44:35,383 DEBUG org.apache.hadoop.yarn.server.resourcemanager.scheduler.capacity.CapacityScheduler: Trying to schedule on node: slave2, available: <memory:4096, vCores:1>
2019-06-07 07:44:35,383 DEBUG org.apache.hadoop.yarn.server.resourcemanager.scheduler.capacity.CapacityScheduler: Trying to schedule on node: slave2, available: <memory:4096, vCores:1>
2019-06-07 07:44:35,383 DEBUG org.apache.hadoop.yarn.server.resourcemanager.scheduler.capacity.ParentQueue: Skip this queue=root, because it doesn't need more resource, schedulingMode=RESPECT_PARTITION_EXCLUSIVITY node-partition=
2019-06-07 07:44:35,383 DEBUG org.apache.hadoop.yarn.server.resourcemanager.scheduler.capacity.ParentQueue: Skip this queue=root, because it doesn't need more resource, schedulingMode=RESPECT_PARTITION_EXCLUSIVITY node-partition=
2019-06-07 07:44:35,514 DEBUG org.apache.hadoop.yarn.server.resourcemanager.rmnode.RMNodeImpl: Processing slave1:35126 of type STATUS_UPDATE
2019-06-07 07:44:35,514 DEBUG org.apache.hadoop.yarn.server.resourcemanager.rmnode.RMNodeImpl: Processing slave1:35126 of type STATUS_UPDATE
2019-06-07 07:44:35,514 DEBUG org.apache.hadoop.yarn.server.resourcemanager.scheduler.capacity.CapacityScheduler: nodeUpdate: slave1:35126 clusterResources: <memory:8192, vCores:2>
2019-06-07 07:44:35,514 DEBUG org.apache.hadoop.yarn.server.resourcemanager.scheduler.capacity.CapacityScheduler: nodeUpdate: slave1:35126 clusterResources: <memory:8192, vCores:2>
2019-06-07 07:44:35,514 DEBUG org.apache.hadoop.yarn.server.resourcemanager.scheduler.capacity.CapacityScheduler: Node being looked for scheduling slave1:35126 availableResource: <memory:3072, vCores:0>
2019-06-07 07:44:35,514 DEBUG org.apache.hadoop.yarn.server.resourcemanager.scheduler.capacity.CapacityScheduler: Node being looked for scheduling slave1:35126 availableResource: <memory:3072, vCores:0>
2019-06-07 07:44:35,514 DEBUG org.apache.hadoop.yarn.server.resourcemanager.scheduler.capacity.CapacityScheduler: Trying to schedule on node: slave1, available: <memory:3072, vCores:0>
2019-06-07 07:44:35,514 DEBUG org.apache.hadoop.yarn.server.resourcemanager.scheduler.capacity.CapacityScheduler: Trying to schedule on node: slave1, available: <memory:3072, vCores:0>
2019-06-07 07:44:35,514 DEBUG org.apache.hadoop.yarn.server.resourcemanager.scheduler.capacity.ParentQueue: Skip this queue=root, because it doesn't need more resource, schedulingMode=RESPECT_PARTITION_EXCLUSIVITY node-partition=
2019-06-07 07:44:35,514 DEBUG org.apache.hadoop.yarn.server.resourcemanager.scheduler.capacity.ParentQueue: Skip this queue=root, because it doesn't need more resource, schedulingMode=RESPECT_PARTITION_EXCLUSIVITY node-partition=
2019-06-07 07:44:36,387 DEBUG org.apache.hadoop.yarn.server.resourcemanager.rmnode.RMNodeImpl: Processing slave2:33474 of type STATUS_UPDATE
2019-06-07 07:44:36,387 DEBUG org.apache.hadoop.yarn.server.resourcemanager.rmnode.RMNodeImpl: Processing slave2:33474 of type STATUS_UPDATE
2019-06-07 07:44:36,387 DEBUG org.apache.hadoop.yarn.server.resourcemanager.scheduler.capacity.CapacityScheduler: nodeUpdate: slave2:33474 clusterResources: <memory:8192, vCores:2>
2019-06-07 07:44:36,387 DEBUG org.apache.hadoop.yarn.server.resourcemanager.scheduler.capacity.CapacityScheduler: nodeUpdate: slave2:33474 clusterResources: <memory:8192, vCores:2>
2019-06-07 07:44:36,387 DEBUG org.apache.hadoop.yarn.server.resourcemanager.scheduler.capacity.CapacityScheduler: Node being looked for scheduling slave2:33474 availableResource: <memory:4096, vCores:1>
2019-06-07 07:44:36,387 DEBUG org.apache.hadoop.yarn.server.resourcemanager.scheduler.capacity.CapacityScheduler: Node being looked for scheduling slave2:33474 availableResource: <memory:4096, vCores:1>
2019-06-07 07:44:36,387 DEBUG org.apache.hadoop.yarn.server.resourcemanager.scheduler.capacity.CapacityScheduler: Trying to schedule on node: slave2, available: <memory:4096, vCores:1>
2019-06-07 07:44:36,387 DEBUG org.apache.hadoop.yarn.server.resourcemanager.scheduler.capacity.CapacityScheduler: Trying to schedule on node: slave2, available: <memory:4096, vCores:1>
2019-06-07 07:44:36,387 DEBUG org.apache.hadoop.yarn.server.resourcemanager.scheduler.capacity.ParentQueue: Skip this queue=root, because it doesn't need more resource, schedulingMode=RESPECT_PARTITION_EXCLUSIVITY node-partition=
2019-06-07 07:44:36,387 DEBUG org.apache.hadoop.yarn.server.resourcemanager.scheduler.capacity.ParentQueue: Skip this queue=root, because it doesn't need more resource, schedulingMode=RESPECT_PARTITION_EXCLUSIVITY node-partition=
2019-06-07 07:44:36,516 DEBUG org.apache.hadoop.yarn.server.resourcemanager.rmnode.RMNodeImpl: Processing slave1:35126 of type STATUS_UPDATE
2019-06-07 07:44:36,516 DEBUG org.apache.hadoop.yarn.server.resourcemanager.rmnode.RMNodeImpl: Processing slave1:35126 of type STATUS_UPDATE
2019-06-07 07:44:36,517 DEBUG org.apache.hadoop.yarn.server.resourcemanager.scheduler.capacity.CapacityScheduler: nodeUpdate: slave1:35126 clusterResources: <memory:8192, vCores:2>
2019-06-07 07:44:36,517 DEBUG org.apache.hadoop.yarn.server.resourcemanager.scheduler.capacity.CapacityScheduler: nodeUpdate: slave1:35126 clusterResources: <memory:8192, vCores:2>
2019-06-07 07:44:36,517 DEBUG org.apache.hadoop.yarn.server.resourcemanager.scheduler.capacity.CapacityScheduler: Node being looked for scheduling slave1:35126 availableResource: <memory:3072, vCores:0>
2019-06-07 07:44:36,517 DEBUG org.apache.hadoop.yarn.server.resourcemanager.scheduler.capacity.CapacityScheduler: Node being looked for scheduling slave1:35126 availableResource: <memory:3072, vCores:0>
2019-06-07 07:44:36,517 DEBUG org.apache.hadoop.yarn.server.resourcemanager.scheduler.capacity.CapacityScheduler: Trying to schedule on node: slave1, available: <memory:3072, vCores:0>
2019-06-07 07:44:36,517 DEBUG org.apache.hadoop.yarn.server.resourcemanager.scheduler.capacity.CapacityScheduler: Trying to schedule on node: slave1, available: <memory:3072, vCores:0>
2019-06-07 07:44:36,517 DEBUG org.apache.hadoop.yarn.server.resourcemanager.scheduler.capacity.ParentQueue: Skip this queue=root, because it doesn't need more resource, schedulingMode=RESPECT_PARTITION_EXCLUSIVITY node-partition=
2019-06-07 07:44:36,517 DEBUG org.apache.hadoop.yarn.server.resourcemanager.scheduler.capacity.ParentQueue: Skip this queue=root, because it doesn't need more resource, schedulingMode=RESPECT_PARTITION_EXCLUSIVITY node-partition=
2019-06-07 07:44:37,389 DEBUG org.apache.hadoop.yarn.server.resourcemanager.rmnode.RMNodeImpl: Processing slave2:33474 of type STATUS_UPDATE
2019-06-07 07:44:37,389 DEBUG org.apache.hadoop.yarn.server.resourcemanager.rmnode.RMNodeImpl: Processing slave2:33474 of type STATUS_UPDATE
2019-06-07 07:44:37,390 DEBUG org.apache.hadoop.yarn.server.resourcemanager.scheduler.capacity.CapacityScheduler: nodeUpdate: slave2:33474 clusterResources: <memory:8192, vCores:2>
2019-06-07 07:44:37,390 DEBUG org.apache.hadoop.yarn.server.resourcemanager.scheduler.capacity.CapacityScheduler: nodeUpdate: slave2:33474 clusterResources: <memory:8192, vCores:2>
2019-06-07 07:44:37,390 DEBUG org.apache.hadoop.yarn.server.resourcemanager.scheduler.capacity.CapacityScheduler: Node being looked for scheduling slave2:33474 availableResource: <memory:4096, vCores:1>
2019-06-07 07:44:37,390 DEBUG org.apache.hadoop.yarn.server.resourcemanager.scheduler.capacity.CapacityScheduler: Node being looked for scheduling slave2:33474 availableResource: <memory:4096, vCores:1>
2019-06-07 07:44:37,390 DEBUG org.apache.hadoop.yarn.server.resourcemanager.scheduler.capacity.CapacityScheduler: Trying to schedule on node: slave2, available: <memory:4096, vCores:1>
2019-06-07 07:44:37,390 DEBUG org.apache.hadoop.yarn.server.resourcemanager.scheduler.capacity.CapacityScheduler: Trying to schedule on node: slave2, available: <memory:4096, vCores:1>
2019-06-07 07:44:37,390 DEBUG org.apache.hadoop.yarn.server.resourcemanager.scheduler.capacity.ParentQueue: Skip this queue=root, because it doesn't need more resource, schedulingMode=RESPECT_PARTITION_EXCLUSIVITY node-partition=
2019-06-07 07:44:37,390 DEBUG org.apache.hadoop.yarn.server.resourcemanager.scheduler.capacity.ParentQueue: Skip this queue=root, because it doesn't need more resource, schedulingMode=RESPECT_PARTITION_EXCLUSIVITY node-partition=
2019-06-07 07:44:37,508 DEBUG org.apache.hadoop.yarn.server.resourcemanager.security.AMRMTokenSecretManager: Trying to retrieve password for appattempt_1559893389340_0001_000001
2019-06-07 07:44:37,508 DEBUG org.apache.hadoop.yarn.server.resourcemanager.security.AMRMTokenSecretManager: Trying to retrieve password for appattempt_1559893389340_0001_000001
2019-06-07 07:44:37,509 INFO SecurityLogger.org.apache.hadoop.ipc.Server: Auth successful for appattempt_1559893389340_0001_000001 (auth:SIMPLE)
2019-06-07 07:44:37,523 DEBUG org.apache.hadoop.yarn.server.resourcemanager.rmnode.RMNodeImpl: Processing slave1:35126 of type STATUS_UPDATE
2019-06-07 07:44:37,523 DEBUG org.apache.hadoop.yarn.server.resourcemanager.rmnode.RMNodeImpl: Processing slave1:35126 of type STATUS_UPDATE
2019-06-07 07:44:37,523 DEBUG org.apache.hadoop.yarn.server.resourcemanager.scheduler.capacity.CapacityScheduler: nodeUpdate: slave1:35126 clusterResources: <memory:8192, vCores:2>
2019-06-07 07:44:37,523 DEBUG org.apache.hadoop.yarn.server.resourcemanager.scheduler.capacity.CapacityScheduler: nodeUpdate: slave1:35126 clusterResources: <memory:8192, vCores:2>
2019-06-07 07:44:37,523 DEBUG org.apache.hadoop.yarn.server.resourcemanager.scheduler.capacity.CapacityScheduler: Node being looked for scheduling slave1:35126 availableResource: <memory:3072, vCores:0>
2019-06-07 07:44:37,523 DEBUG org.apache.hadoop.yarn.server.resourcemanager.scheduler.capacity.CapacityScheduler: Node being looked for scheduling slave1:35126 availableResource: <memory:3072, vCores:0>
2019-06-07 07:44:37,523 DEBUG org.apache.hadoop.yarn.server.resourcemanager.scheduler.capacity.CapacityScheduler: Trying to schedule on node: slave1, available: <memory:3072, vCores:0>
2019-06-07 07:44:37,523 DEBUG org.apache.hadoop.yarn.server.resourcemanager.scheduler.capacity.CapacityScheduler: Trying to schedule on node: slave1, available: <memory:3072, vCores:0>
2019-06-07 07:44:37,523 DEBUG org.apache.hadoop.yarn.server.resourcemanager.scheduler.capacity.ParentQueue: Skip this queue=root, because it doesn't need more resource, schedulingMode=RESPECT_PARTITION_EXCLUSIVITY node-partition=
2019-06-07 07:44:37,523 DEBUG org.apache.hadoop.yarn.server.resourcemanager.scheduler.capacity.ParentQueue: Skip this queue=root, because it doesn't need more resource, schedulingMode=RESPECT_PARTITION_EXCLUSIVITY node-partition=
2019-06-07 07:44:37,524 INFO org.apache.hadoop.yarn.server.resourcemanager.ApplicationMasterService: AM registration appattempt_1559893389340_0001_000001
2019-06-07 07:44:37,524 INFO org.apache.hadoop.yarn.server.resourcemanager.ApplicationMasterService: AM registration appattempt_1559893389340_0001_000001
2019-06-07 07:44:37,525 INFO org.apache.hadoop.yarn.server.resourcemanager.RMAuditLogger: USER=root	IP=172.17.0.3	OPERATION=Register App Master	TARGET=ApplicationMasterService	RESULT=SUCCESS	APPID=application_1559893389340_0001	APPATTEMPTID=appattempt_1559893389340_0001_000001
2019-06-07 07:44:37,525 INFO org.apache.hadoop.yarn.server.resourcemanager.RMAuditLogger: USER=root	IP=172.17.0.3	OPERATION=Register App Master	TARGET=ApplicationMasterService	RESULT=SUCCESS	APPID=application_1559893389340_0001	APPATTEMPTID=appattempt_1559893389340_0001_000001
2019-06-07 07:44:37,525 DEBUG org.apache.hadoop.yarn.server.resourcemanager.rmapp.attempt.RMAppAttemptImpl: Processing event for appattempt_1559893389340_0001_000001 of type REGISTERED
2019-06-07 07:44:37,525 DEBUG org.apache.hadoop.yarn.server.resourcemanager.rmapp.attempt.RMAppAttemptImpl: Processing event for appattempt_1559893389340_0001_000001 of type REGISTERED
2019-06-07 07:44:37,525 INFO org.apache.hadoop.yarn.server.resourcemanager.rmapp.attempt.RMAppAttemptImpl: appattempt_1559893389340_0001_000001 State change from LAUNCHED to RUNNING
2019-06-07 07:44:37,525 INFO org.apache.hadoop.yarn.server.resourcemanager.rmapp.attempt.RMAppAttemptImpl: appattempt_1559893389340_0001_000001 State change from LAUNCHED to RUNNING
2019-06-07 07:44:37,525 DEBUG org.apache.hadoop.yarn.server.resourcemanager.rmapp.RMAppImpl: Processing event for application_1559893389340_0001 of type ATTEMPT_REGISTERED
2019-06-07 07:44:37,525 DEBUG org.apache.hadoop.yarn.server.resourcemanager.rmapp.RMAppImpl: Processing event for application_1559893389340_0001 of type ATTEMPT_REGISTERED
2019-06-07 07:44:37,525 INFO org.apache.hadoop.yarn.server.resourcemanager.rmapp.RMAppImpl: application_1559893389340_0001 State change from ACCEPTED to RUNNING on event=ATTEMPT_REGISTERED
2019-06-07 07:44:37,525 INFO org.apache.hadoop.yarn.server.resourcemanager.rmapp.RMAppImpl: application_1559893389340_0001 State change from ACCEPTED to RUNNING on event=ATTEMPT_REGISTERED
2019-06-07 07:44:37,628 DEBUG org.apache.hadoop.yarn.server.resourcemanager.rmapp.attempt.RMAppAttemptImpl: Processing event for appattempt_1559893389340_0001_000001 of type STATUS_UPDATE
2019-06-07 07:44:37,628 DEBUG org.apache.hadoop.yarn.server.resourcemanager.rmapp.attempt.RMAppAttemptImpl: Processing event for appattempt_1559893389340_0001_000001 of type STATUS_UPDATE
2019-06-07 07:44:37,628 DEBUG org.apache.hadoop.yarn.server.resourcemanager.scheduler.capacity.CapacityScheduler: allocate: pre-update appattempt_1559893389340_0001_000001 ask size =1
2019-06-07 07:44:37,628 DEBUG org.apache.hadoop.yarn.server.resourcemanager.scheduler.capacity.CapacityScheduler: allocate: pre-update appattempt_1559893389340_0001_000001 ask size =1
2019-06-07 07:44:37,628 DEBUG org.apache.hadoop.yarn.server.resourcemanager.scheduler.ActiveUsersManager: User root added to activeUsers, currently: 1
2019-06-07 07:44:37,628 DEBUG org.apache.hadoop.yarn.server.resourcemanager.scheduler.ActiveUsersManager: User root added to activeUsers, currently: 1
2019-06-07 07:44:37,628 DEBUG org.apache.hadoop.yarn.server.resourcemanager.scheduler.capacity.CapacityScheduler: allocate: post-update
2019-06-07 07:44:37,628 DEBUG org.apache.hadoop.yarn.server.resourcemanager.scheduler.capacity.CapacityScheduler: allocate: post-update
2019-06-07 07:44:37,629 DEBUG org.apache.hadoop.yarn.server.resourcemanager.scheduler.capacity.LeafQueue: User limit computation for root in queue default userLimitPercent=100 userLimitFactor=1.0 required: <memory:1024, vCores:1> consumed: <memory:1024, vCores:1> user-limit-resource: <memory:8192, vCores:1> queueCapacity: <memory:8192, vCores:1> qconsumed: <memory:1024, vCores:1> consumedRatio: 0.0 currentCapacity: <memory:8192, vCores:1> activeUsers: 1.0 clusterCapacity: <memory:8192, vCores:2> resourceByLabel: <memory:8192, vCores:2> usageratio: 0.125 Partition:  maxUserLimit=<memory:8192, vCores:1> userWeight=1.0
2019-06-07 07:44:37,629 DEBUG org.apache.hadoop.yarn.server.resourcemanager.scheduler.capacity.LeafQueue: User limit computation for root in queue default userLimitPercent=100 userLimitFactor=1.0 required: <memory:1024, vCores:1> consumed: <memory:1024, vCores:1> user-limit-resource: <memory:8192, vCores:1> queueCapacity: <memory:8192, vCores:1> qconsumed: <memory:1024, vCores:1> consumedRatio: 0.0 currentCapacity: <memory:8192, vCores:1> activeUsers: 1.0 clusterCapacity: <memory:8192, vCores:2> resourceByLabel: <memory:8192, vCores:2> usageratio: 0.125 Partition:  maxUserLimit=<memory:8192, vCores:1> userWeight=1.0
2019-06-07 07:44:37,629 DEBUG org.apache.hadoop.yarn.server.resourcemanager.scheduler.SchedulerApplicationAttempt: showRequests: application=application_1559893389340_0001 headRoom=<memory:7168, vCores:1> currentConsumption=1024
2019-06-07 07:44:37,629 DEBUG org.apache.hadoop.yarn.server.resourcemanager.scheduler.SchedulerApplicationAttempt: showRequests: application=application_1559893389340_0001 headRoom=<memory:7168, vCores:1> currentConsumption=1024
2019-06-07 07:44:37,629 DEBUG org.apache.hadoop.yarn.server.resourcemanager.scheduler.SchedulerApplicationAttempt: showRequests: application=application_1559893389340_0001 request={Priority: 1, Capability: <memory:3072, vCores:1>, # Containers: 2, Location: *, Relax Locality: true, Node Label Expression: }
2019-06-07 07:44:37,629 DEBUG org.apache.hadoop.yarn.server.resourcemanager.scheduler.SchedulerApplicationAttempt: showRequests: application=application_1559893389340_0001 request={Priority: 1, Capability: <memory:3072, vCores:1>, # Containers: 2, Location: *, Relax Locality: true, Node Label Expression: }
2019-06-07 07:44:37,629 DEBUG org.apache.hadoop.yarn.server.resourcemanager.scheduler.capacity.LeafQueue: User limit computation for root in queue default userLimitPercent=100 userLimitFactor=1.0 required: <memory:1024, vCores:1> consumed: <memory:1024, vCores:1> user-limit-resource: <memory:8192, vCores:1> queueCapacity: <memory:8192, vCores:1> qconsumed: <memory:1024, vCores:1> consumedRatio: 0.0 currentCapacity: <memory:8192, vCores:1> activeUsers: 1.0 clusterCapacity: <memory:8192, vCores:2> resourceByLabel: <memory:8192, vCores:2> usageratio: 0.125 Partition:  maxUserLimit=<memory:8192, vCores:1> userWeight=1.0
2019-06-07 07:44:37,629 DEBUG org.apache.hadoop.yarn.server.resourcemanager.scheduler.capacity.LeafQueue: User limit computation for root in queue default userLimitPercent=100 userLimitFactor=1.0 required: <memory:1024, vCores:1> consumed: <memory:1024, vCores:1> user-limit-resource: <memory:8192, vCores:1> queueCapacity: <memory:8192, vCores:1> qconsumed: <memory:1024, vCores:1> consumedRatio: 0.0 currentCapacity: <memory:8192, vCores:1> activeUsers: 1.0 clusterCapacity: <memory:8192, vCores:2> resourceByLabel: <memory:8192, vCores:2> usageratio: 0.125 Partition:  maxUserLimit=<memory:8192, vCores:1> userWeight=1.0
2019-06-07 07:44:37,694 DEBUG org.apache.hadoop.yarn.server.resourcemanager.rmapp.attempt.RMAppAttemptImpl: Processing event for appattempt_1559893389340_0001_000001 of type STATUS_UPDATE
2019-06-07 07:44:37,694 DEBUG org.apache.hadoop.yarn.server.resourcemanager.rmapp.attempt.RMAppAttemptImpl: Processing event for appattempt_1559893389340_0001_000001 of type STATUS_UPDATE
2019-06-07 07:44:37,694 DEBUG org.apache.hadoop.yarn.server.resourcemanager.scheduler.capacity.LeafQueue: User limit computation for root in queue default userLimitPercent=100 userLimitFactor=1.0 required: <memory:1024, vCores:1> consumed: <memory:1024, vCores:1> user-limit-resource: <memory:8192, vCores:1> queueCapacity: <memory:8192, vCores:1> qconsumed: <memory:1024, vCores:1> consumedRatio: 0.0 currentCapacity: <memory:8192, vCores:1> activeUsers: 1.0 clusterCapacity: <memory:8192, vCores:2> resourceByLabel: <memory:8192, vCores:2> usageratio: 0.125 Partition:  maxUserLimit=<memory:8192, vCores:1> userWeight=1.0
2019-06-07 07:44:37,694 DEBUG org.apache.hadoop.yarn.server.resourcemanager.scheduler.capacity.LeafQueue: User limit computation for root in queue default userLimitPercent=100 userLimitFactor=1.0 required: <memory:1024, vCores:1> consumed: <memory:1024, vCores:1> user-limit-resource: <memory:8192, vCores:1> queueCapacity: <memory:8192, vCores:1> qconsumed: <memory:1024, vCores:1> consumedRatio: 0.0 currentCapacity: <memory:8192, vCores:1> activeUsers: 1.0 clusterCapacity: <memory:8192, vCores:2> resourceByLabel: <memory:8192, vCores:2> usageratio: 0.125 Partition:  maxUserLimit=<memory:8192, vCores:1> userWeight=1.0
2019-06-07 07:44:37,905 DEBUG org.apache.hadoop.yarn.server.resourcemanager.scheduler.capacity.LeafQueue: User limit computation for root in queue default userLimitPercent=100 userLimitFactor=1.0 required: <memory:1024, vCores:1> consumed: <memory:1024, vCores:1> user-limit-resource: <memory:8192, vCores:1> queueCapacity: <memory:8192, vCores:1> qconsumed: <memory:1024, vCores:1> consumedRatio: 0.0 currentCapacity: <memory:8192, vCores:1> activeUsers: 1.0 clusterCapacity: <memory:8192, vCores:2> resourceByLabel: <memory:8192, vCores:2> usageratio: 0.125 Partition:  maxUserLimit=<memory:8192, vCores:1> userWeight=1.0
2019-06-07 07:44:37,905 DEBUG org.apache.hadoop.yarn.server.resourcemanager.scheduler.capacity.LeafQueue: User limit computation for root in queue default userLimitPercent=100 userLimitFactor=1.0 required: <memory:1024, vCores:1> consumed: <memory:1024, vCores:1> user-limit-resource: <memory:8192, vCores:1> queueCapacity: <memory:8192, vCores:1> qconsumed: <memory:1024, vCores:1> consumedRatio: 0.0 currentCapacity: <memory:8192, vCores:1> activeUsers: 1.0 clusterCapacity: <memory:8192, vCores:2> resourceByLabel: <memory:8192, vCores:2> usageratio: 0.125 Partition:  maxUserLimit=<memory:8192, vCores:1> userWeight=1.0
2019-06-07 07:44:37,906 DEBUG org.apache.hadoop.yarn.server.resourcemanager.rmapp.attempt.RMAppAttemptImpl: Processing event for appattempt_1559893389340_0001_000001 of type STATUS_UPDATE
2019-06-07 07:44:37,906 DEBUG org.apache.hadoop.yarn.server.resourcemanager.rmapp.attempt.RMAppAttemptImpl: Processing event for appattempt_1559893389340_0001_000001 of type STATUS_UPDATE
2019-06-07 07:44:38,315 DEBUG org.apache.hadoop.yarn.server.resourcemanager.scheduler.capacity.LeafQueue: User limit computation for root in queue default userLimitPercent=100 userLimitFactor=1.0 required: <memory:1024, vCores:1> consumed: <memory:1024, vCores:1> user-limit-resource: <memory:8192, vCores:1> queueCapacity: <memory:8192, vCores:1> qconsumed: <memory:1024, vCores:1> consumedRatio: 0.0 currentCapacity: <memory:8192, vCores:1> activeUsers: 1.0 clusterCapacity: <memory:8192, vCores:2> resourceByLabel: <memory:8192, vCores:2> usageratio: 0.125 Partition:  maxUserLimit=<memory:8192, vCores:1> userWeight=1.0
2019-06-07 07:44:38,315 DEBUG org.apache.hadoop.yarn.server.resourcemanager.rmapp.attempt.RMAppAttemptImpl: Processing event for appattempt_1559893389340_0001_000001 of type STATUS_UPDATE
2019-06-07 07:44:38,315 DEBUG org.apache.hadoop.yarn.server.resourcemanager.scheduler.capacity.LeafQueue: User limit computation for root in queue default userLimitPercent=100 userLimitFactor=1.0 required: <memory:1024, vCores:1> consumed: <memory:1024, vCores:1> user-limit-resource: <memory:8192, vCores:1> queueCapacity: <memory:8192, vCores:1> qconsumed: <memory:1024, vCores:1> consumedRatio: 0.0 currentCapacity: <memory:8192, vCores:1> activeUsers: 1.0 clusterCapacity: <memory:8192, vCores:2> resourceByLabel: <memory:8192, vCores:2> usageratio: 0.125 Partition:  maxUserLimit=<memory:8192, vCores:1> userWeight=1.0
2019-06-07 07:44:38,315 DEBUG org.apache.hadoop.yarn.server.resourcemanager.rmapp.attempt.RMAppAttemptImpl: Processing event for appattempt_1559893389340_0001_000001 of type STATUS_UPDATE
2019-06-07 07:44:38,390 DEBUG org.apache.hadoop.yarn.server.resourcemanager.rmnode.RMNodeImpl: Processing slave2:33474 of type STATUS_UPDATE
2019-06-07 07:44:38,390 DEBUG org.apache.hadoop.yarn.server.resourcemanager.rmnode.RMNodeImpl: Processing slave2:33474 of type STATUS_UPDATE
2019-06-07 07:44:38,390 DEBUG org.apache.hadoop.yarn.server.resourcemanager.scheduler.capacity.CapacityScheduler: nodeUpdate: slave2:33474 clusterResources: <memory:8192, vCores:2>
2019-06-07 07:44:38,390 DEBUG org.apache.hadoop.yarn.server.resourcemanager.scheduler.capacity.CapacityScheduler: nodeUpdate: slave2:33474 clusterResources: <memory:8192, vCores:2>
2019-06-07 07:44:38,391 DEBUG org.apache.hadoop.yarn.server.resourcemanager.scheduler.capacity.CapacityScheduler: Node being looked for scheduling slave2:33474 availableResource: <memory:4096, vCores:1>
2019-06-07 07:44:38,391 DEBUG org.apache.hadoop.yarn.server.resourcemanager.scheduler.capacity.CapacityScheduler: Node being looked for scheduling slave2:33474 availableResource: <memory:4096, vCores:1>
2019-06-07 07:44:38,392 DEBUG org.apache.hadoop.yarn.server.resourcemanager.scheduler.capacity.CapacityScheduler: Trying to schedule on node: slave2, available: <memory:4096, vCores:1>
2019-06-07 07:44:38,392 DEBUG org.apache.hadoop.yarn.server.resourcemanager.scheduler.capacity.CapacityScheduler: Trying to schedule on node: slave2, available: <memory:4096, vCores:1>
2019-06-07 07:44:38,392 DEBUG org.apache.hadoop.yarn.server.resourcemanager.scheduler.capacity.ParentQueue: Trying to assign containers to child-queue of root
2019-06-07 07:44:38,392 DEBUG org.apache.hadoop.yarn.server.resourcemanager.scheduler.capacity.ParentQueue: Trying to assign containers to child-queue of root
2019-06-07 07:44:38,392 DEBUG org.apache.hadoop.yarn.server.resourcemanager.scheduler.capacity.ParentQueue: printChildQueues - queue: root child-queues: root.defaultusedCapacity=(0.125),  label=(*)
2019-06-07 07:44:38,392 DEBUG org.apache.hadoop.yarn.server.resourcemanager.scheduler.capacity.ParentQueue: printChildQueues - queue: root child-queues: root.defaultusedCapacity=(0.125),  label=(*)
2019-06-07 07:44:38,392 DEBUG org.apache.hadoop.yarn.server.resourcemanager.scheduler.capacity.ParentQueue: Trying to assign to queue: root.default stats: default: capacity=1.0, absoluteCapacity=1.0, usedResources=<memory:1024, vCores:1>, usedCapacity=0.125, absoluteUsedCapacity=0.125, numApps=1, numContainers=1
2019-06-07 07:44:38,392 DEBUG org.apache.hadoop.yarn.server.resourcemanager.scheduler.capacity.ParentQueue: Trying to assign to queue: root.default stats: default: capacity=1.0, absoluteCapacity=1.0, usedResources=<memory:1024, vCores:1>, usedCapacity=0.125, absoluteUsedCapacity=0.125, numApps=1, numContainers=1
2019-06-07 07:44:38,392 DEBUG org.apache.hadoop.yarn.server.resourcemanager.scheduler.capacity.LeafQueue: assignContainers: node=slave2 #applications=1
2019-06-07 07:44:38,392 DEBUG org.apache.hadoop.yarn.server.resourcemanager.scheduler.capacity.LeafQueue: assignContainers: node=slave2 #applications=1
2019-06-07 07:44:38,392 DEBUG org.apache.hadoop.yarn.server.resourcemanager.scheduler.capacity.LeafQueue: User limit computation for root in queue default userLimitPercent=100 userLimitFactor=1.0 required: <memory:1024, vCores:1> consumed: <memory:1024, vCores:1> user-limit-resource: <memory:8192, vCores:1> queueCapacity: <memory:8192, vCores:1> qconsumed: <memory:1024, vCores:1> consumedRatio: 0.0 currentCapacity: <memory:8192, vCores:1> activeUsers: 1.0 clusterCapacity: <memory:8192, vCores:2> resourceByLabel: <memory:8192, vCores:2> usageratio: 0.125 Partition:  maxUserLimit=<memory:8192, vCores:1> userWeight=1.0
2019-06-07 07:44:38,392 DEBUG org.apache.hadoop.yarn.server.resourcemanager.scheduler.capacity.LeafQueue: User limit computation for root in queue default userLimitPercent=100 userLimitFactor=1.0 required: <memory:1024, vCores:1> consumed: <memory:1024, vCores:1> user-limit-resource: <memory:8192, vCores:1> queueCapacity: <memory:8192, vCores:1> qconsumed: <memory:1024, vCores:1> consumedRatio: 0.0 currentCapacity: <memory:8192, vCores:1> activeUsers: 1.0 clusterCapacity: <memory:8192, vCores:2> resourceByLabel: <memory:8192, vCores:2> usageratio: 0.125 Partition:  maxUserLimit=<memory:8192, vCores:1> userWeight=1.0
2019-06-07 07:44:38,392 DEBUG org.apache.hadoop.yarn.server.resourcemanager.scheduler.capacity.LeafQueue: Headroom calculation for user root:  userLimit=<memory:8192, vCores:1> queueMaxAvailRes=<memory:8192, vCores:1> consumed=<memory:1024, vCores:1>
2019-06-07 07:44:38,392 DEBUG org.apache.hadoop.yarn.server.resourcemanager.scheduler.capacity.LeafQueue: Headroom calculation for user root:  userLimit=<memory:8192, vCores:1> queueMaxAvailRes=<memory:8192, vCores:1> consumed=<memory:1024, vCores:1>
2019-06-07 07:44:38,392 DEBUG org.apache.hadoop.yarn.server.resourcemanager.scheduler.common.fica.FiCaSchedulerApp: pre-assignContainers for application application_1559893389340_0001
