2019-06-07 08:04:39,229 INFO org.apache.hadoop.yarn.server.resourcemanager.ResourceManager: STARTUP_MSG: 
/************************************************************
STARTUP_MSG: Starting ResourceManager
STARTUP_MSG:   user = root
STARTUP_MSG:   host = master/172.17.0.2
STARTUP_MSG:   args = []
STARTUP_MSG:   version = 2.8.5
STARTUP_MSG:   build = https://git-wip-us.apache.org/repos/asf/hadoop.git -r 0b8464d75227fcee2c6e7f2410377b3d53d3d5f8; compiled by 'jdu' on 2018-09-10T03:32Z
STARTUP_MSG:   java = 1.8.0_191
************************************************************/
2019-06-07 08:04:39,229 INFO org.apache.hadoop.yarn.server.resourcemanager.ResourceManager: STARTUP_MSG: 
/************************************************************
STARTUP_MSG: Starting ResourceManager
STARTUP_MSG:   user = root
STARTUP_MSG:   host = master/172.17.0.2
STARTUP_MSG:   args = []
STARTUP_MSG:   version = 2.8.5
STARTUP_MSG:   build = https://git-wip-us.apache.org/repos/asf/hadoop.git -r 0b8464d75227fcee2c6e7f2410377b3d53d3d5f8; compiled by 'jdu' on 2018-09-10T03:32Z
STARTUP_MSG:   java = 1.8.0_191
************************************************************/
2019-06-07 08:04:39,236 INFO org.apache.hadoop.yarn.server.resourcemanager.ResourceManager: registered UNIX signal handlers for [TERM, HUP, INT]
2019-06-07 08:04:39,236 INFO org.apache.hadoop.yarn.server.resourcemanager.ResourceManager: registered UNIX signal handlers for [TERM, HUP, INT]
2019-06-07 08:04:39,463 INFO org.apache.hadoop.conf.Configuration: found resource core-site.xml at file:/hadoop-2.8.5/etc/hadoop/core-site.xml
2019-06-07 08:04:39,536 WARN org.apache.hadoop.conf.Configuration: core-site.xml:an attempt to override final parameter: fs.defaultFS;  Ignoring.
2019-06-07 08:04:39,554 INFO org.apache.hadoop.security.Groups: clearing userToGroupsMap cache
2019-06-07 08:04:39,605 INFO org.apache.hadoop.conf.Configuration: found resource yarn-site.xml at file:/hadoop-2.8.5/etc/hadoop/yarn-site.xml
2019-06-07 08:04:39,783 INFO org.apache.hadoop.yarn.event.AsyncDispatcher: Registering class org.apache.hadoop.yarn.server.resourcemanager.RMFatalEventType for class org.apache.hadoop.yarn.server.resourcemanager.ResourceManager$RMFatalEventDispatcher
2019-06-07 08:04:39,835 INFO org.apache.hadoop.yarn.server.resourcemanager.security.NMTokenSecretManagerInRM: NMTokenKeyRollingInterval: 86400000ms and NMTokenKeyActivationDelay: 900000ms
2019-06-07 08:04:39,835 INFO org.apache.hadoop.yarn.server.resourcemanager.security.NMTokenSecretManagerInRM: NMTokenKeyRollingInterval: 86400000ms and NMTokenKeyActivationDelay: 900000ms
2019-06-07 08:04:39,838 INFO org.apache.hadoop.yarn.server.resourcemanager.security.RMContainerTokenSecretManager: ContainerTokenKeyRollingInterval: 86400000ms and ContainerTokenKeyActivationDelay: 900000ms
2019-06-07 08:04:39,838 INFO org.apache.hadoop.yarn.server.resourcemanager.security.RMContainerTokenSecretManager: ContainerTokenKeyRollingInterval: 86400000ms and ContainerTokenKeyActivationDelay: 900000ms
2019-06-07 08:04:39,842 INFO org.apache.hadoop.yarn.server.resourcemanager.security.AMRMTokenSecretManager: AMRMTokenKeyRollingInterval: 86400000ms and AMRMTokenKeyActivationDelay: 900000 ms
2019-06-07 08:04:39,842 INFO org.apache.hadoop.yarn.server.resourcemanager.security.AMRMTokenSecretManager: AMRMTokenKeyRollingInterval: 86400000ms and AMRMTokenKeyActivationDelay: 900000 ms
2019-06-07 08:04:39,866 INFO org.apache.hadoop.yarn.event.AsyncDispatcher: Registering class org.apache.hadoop.yarn.server.resourcemanager.recovery.RMStateStoreEventType for class org.apache.hadoop.yarn.server.resourcemanager.recovery.RMStateStore$ForwardingEventHandler
2019-06-07 08:04:39,868 INFO org.apache.hadoop.yarn.event.AsyncDispatcher: Registering class org.apache.hadoop.yarn.server.resourcemanager.NodesListManagerEventType for class org.apache.hadoop.yarn.server.resourcemanager.NodesListManager
2019-06-07 08:04:39,869 INFO org.apache.hadoop.yarn.server.resourcemanager.ResourceManager: Using Scheduler: org.apache.hadoop.yarn.server.resourcemanager.scheduler.capacity.CapacityScheduler
2019-06-07 08:04:39,869 INFO org.apache.hadoop.yarn.server.resourcemanager.ResourceManager: Using Scheduler: org.apache.hadoop.yarn.server.resourcemanager.scheduler.capacity.CapacityScheduler
2019-06-07 08:04:39,887 INFO org.apache.hadoop.yarn.event.AsyncDispatcher: Registering class org.apache.hadoop.yarn.server.resourcemanager.scheduler.event.SchedulerEventType for class org.apache.hadoop.yarn.server.resourcemanager.ResourceManager$SchedulerEventDispatcher
2019-06-07 08:04:39,887 INFO org.apache.hadoop.yarn.event.AsyncDispatcher: Registering class org.apache.hadoop.yarn.server.resourcemanager.rmapp.RMAppEventType for class org.apache.hadoop.yarn.server.resourcemanager.ResourceManager$ApplicationEventDispatcher
2019-06-07 08:04:39,888 INFO org.apache.hadoop.yarn.event.AsyncDispatcher: Registering class org.apache.hadoop.yarn.server.resourcemanager.rmapp.attempt.RMAppAttemptEventType for class org.apache.hadoop.yarn.server.resourcemanager.ResourceManager$ApplicationAttemptEventDispatcher
2019-06-07 08:04:39,889 INFO org.apache.hadoop.yarn.event.AsyncDispatcher: Registering class org.apache.hadoop.yarn.server.resourcemanager.rmnode.RMNodeEventType for class org.apache.hadoop.yarn.server.resourcemanager.ResourceManager$NodeEventDispatcher
2019-06-07 08:04:39,925 INFO org.apache.hadoop.metrics2.impl.MetricsConfig: loaded properties from hadoop-metrics2.properties
2019-06-07 08:04:39,969 INFO org.apache.hadoop.metrics2.impl.MetricsSystemImpl: Scheduled Metric snapshot period at 10 second(s).
2019-06-07 08:04:39,969 INFO org.apache.hadoop.metrics2.impl.MetricsSystemImpl: ResourceManager metrics system started
2019-06-07 08:04:39,981 INFO org.apache.hadoop.yarn.event.AsyncDispatcher: Registering class org.apache.hadoop.yarn.server.resourcemanager.RMAppManagerEventType for class org.apache.hadoop.yarn.server.resourcemanager.RMAppManager
2019-06-07 08:04:39,986 INFO org.apache.hadoop.yarn.event.AsyncDispatcher: Registering class org.apache.hadoop.yarn.server.resourcemanager.amlauncher.AMLauncherEventType for class org.apache.hadoop.yarn.server.resourcemanager.amlauncher.ApplicationMasterLauncher
2019-06-07 08:04:39,988 INFO org.apache.hadoop.yarn.server.resourcemanager.RMNMInfo: Registered RMNMInfo MBean
2019-06-07 08:04:39,988 INFO org.apache.hadoop.yarn.server.resourcemanager.RMNMInfo: Registered RMNMInfo MBean
2019-06-07 08:04:39,993 INFO org.apache.hadoop.yarn.security.YarnAuthorizationProvider: org.apache.hadoop.yarn.security.ConfiguredYarnAuthorizer is instiantiated.
2019-06-07 08:04:39,994 INFO org.apache.hadoop.util.HostsFileReader: Refreshing hosts (include/exclude) list
2019-06-07 08:04:39,995 DEBUG org.apache.hadoop.yarn.server.resourcemanager.NodesListManager: hostsReader: in= out=
2019-06-07 08:04:39,995 DEBUG org.apache.hadoop.yarn.server.resourcemanager.NodesListManager: hostsReader: in= out=
2019-06-07 08:04:39,999 INFO org.apache.hadoop.conf.Configuration: found resource capacity-scheduler.xml at file:/hadoop-2.8.5/etc/hadoop/capacity-scheduler.xml
2019-06-07 08:04:40,020 DEBUG org.apache.hadoop.yarn.server.resourcemanager.scheduler.capacity.CapacitySchedulerConfiguration: CSConf - getQueues called for: queuePrefix=yarn.scheduler.capacity.root.
2019-06-07 08:04:40,020 DEBUG org.apache.hadoop.yarn.server.resourcemanager.scheduler.capacity.CapacitySchedulerConfiguration: CSConf - getQueues called for: queuePrefix=yarn.scheduler.capacity.root.
2019-06-07 08:04:40,020 DEBUG org.apache.hadoop.yarn.server.resourcemanager.scheduler.capacity.CapacitySchedulerConfiguration: CSConf - getQueues: queuePrefix=yarn.scheduler.capacity.root., queues=default
2019-06-07 08:04:40,020 DEBUG org.apache.hadoop.yarn.server.resourcemanager.scheduler.capacity.CapacitySchedulerConfiguration: CSConf - getQueues: queuePrefix=yarn.scheduler.capacity.root., queues=default
2019-06-07 08:04:40,036 DEBUG org.apache.hadoop.yarn.server.resourcemanager.scheduler.capacity.CapacitySchedulerConfiguration: CSConf - getCapacity: queuePrefix=yarn.scheduler.capacity.root., capacity=100.0
2019-06-07 08:04:40,036 DEBUG org.apache.hadoop.yarn.server.resourcemanager.scheduler.capacity.CapacitySchedulerConfiguration: CSConf - getCapacity: queuePrefix=yarn.scheduler.capacity.root., capacity=100.0
2019-06-07 08:04:40,038 DEBUG org.apache.hadoop.yarn.server.resourcemanager.scheduler.capacity.CapacitySchedulerConfiguration: CSConf - getCapacity: queuePrefix=yarn.scheduler.capacity.root., capacity=100.0
2019-06-07 08:04:40,038 DEBUG org.apache.hadoop.yarn.server.resourcemanager.scheduler.capacity.CapacitySchedulerConfiguration: CSConf - getCapacity: queuePrefix=yarn.scheduler.capacity.root., capacity=100.0
2019-06-07 08:04:40,041 DEBUG org.apache.hadoop.yarn.server.resourcemanager.scheduler.capacity.CapacitySchedulerConfiguration: max alloc mb per queue for root is -1
2019-06-07 08:04:40,041 DEBUG org.apache.hadoop.yarn.server.resourcemanager.scheduler.capacity.CapacitySchedulerConfiguration: max alloc mb per queue for root is -1
2019-06-07 08:04:40,041 DEBUG org.apache.hadoop.yarn.server.resourcemanager.scheduler.capacity.CapacitySchedulerConfiguration: max alloc vcores per queue for root is -1
2019-06-07 08:04:40,041 DEBUG org.apache.hadoop.yarn.server.resourcemanager.scheduler.capacity.CapacitySchedulerConfiguration: max alloc vcores per queue for root is -1
2019-06-07 08:04:40,041 INFO org.apache.hadoop.yarn.server.resourcemanager.scheduler.capacity.CapacitySchedulerConfiguration: max alloc mb per queue for root is undefined
2019-06-07 08:04:40,041 INFO org.apache.hadoop.yarn.server.resourcemanager.scheduler.capacity.CapacitySchedulerConfiguration: max alloc mb per queue for root is undefined
2019-06-07 08:04:40,041 INFO org.apache.hadoop.yarn.server.resourcemanager.scheduler.capacity.CapacitySchedulerConfiguration: max alloc vcore per queue for root is undefined
2019-06-07 08:04:40,041 INFO org.apache.hadoop.yarn.server.resourcemanager.scheduler.capacity.CapacitySchedulerConfiguration: max alloc vcore per queue for root is undefined
2019-06-07 08:04:40,048 INFO org.apache.hadoop.yarn.server.resourcemanager.scheduler.capacity.ParentQueue: root, capacity=1.0, asboluteCapacity=1.0, maxCapacity=1.0, asboluteMaxCapacity=1.0, state=RUNNING, acls=ADMINISTER_QUEUE:*SUBMIT_APP:*, labels=*,, offswitchPerHeartbeatLimit = 1, reservationsContinueLooking=true
2019-06-07 08:04:40,048 INFO org.apache.hadoop.yarn.server.resourcemanager.scheduler.capacity.ParentQueue: root, capacity=1.0, asboluteCapacity=1.0, maxCapacity=1.0, asboluteMaxCapacity=1.0, state=RUNNING, acls=ADMINISTER_QUEUE:*SUBMIT_APP:*, labels=*,, offswitchPerHeartbeatLimit = 1, reservationsContinueLooking=true
2019-06-07 08:04:40,049 INFO org.apache.hadoop.yarn.server.resourcemanager.scheduler.capacity.ParentQueue: Initialized parent-queue root name=root, fullname=root
2019-06-07 08:04:40,049 INFO org.apache.hadoop.yarn.server.resourcemanager.scheduler.capacity.ParentQueue: Initialized parent-queue root name=root, fullname=root
2019-06-07 08:04:40,049 DEBUG org.apache.hadoop.yarn.server.resourcemanager.scheduler.capacity.CapacitySchedulerConfiguration: CSConf - getQueues called for: queuePrefix=yarn.scheduler.capacity.root.default.
2019-06-07 08:04:40,049 DEBUG org.apache.hadoop.yarn.server.resourcemanager.scheduler.capacity.CapacitySchedulerConfiguration: CSConf - getQueues called for: queuePrefix=yarn.scheduler.capacity.root.default.
2019-06-07 08:04:40,049 DEBUG org.apache.hadoop.yarn.server.resourcemanager.scheduler.capacity.CapacitySchedulerConfiguration: CSConf - getQueues: queuePrefix=yarn.scheduler.capacity.root.default., queues=
2019-06-07 08:04:40,049 DEBUG org.apache.hadoop.yarn.server.resourcemanager.scheduler.capacity.CapacitySchedulerConfiguration: CSConf - getQueues: queuePrefix=yarn.scheduler.capacity.root.default., queues=
2019-06-07 08:04:40,083 DEBUG org.apache.hadoop.yarn.server.resourcemanager.scheduler.capacity.LeafQueue: LeafQueue: name=default, fullname=root.default
2019-06-07 08:04:40,083 DEBUG org.apache.hadoop.yarn.server.resourcemanager.scheduler.capacity.LeafQueue: LeafQueue: name=default, fullname=root.default
2019-06-07 08:04:40,084 DEBUG org.apache.hadoop.yarn.server.resourcemanager.scheduler.capacity.CapacitySchedulerConfiguration: CSConf - getCapacity: queuePrefix=yarn.scheduler.capacity.root.default., capacity=100.0
2019-06-07 08:04:40,084 DEBUG org.apache.hadoop.yarn.server.resourcemanager.scheduler.capacity.CapacitySchedulerConfiguration: CSConf - getCapacity: queuePrefix=yarn.scheduler.capacity.root.default., capacity=100.0
2019-06-07 08:04:40,084 DEBUG org.apache.hadoop.yarn.server.resourcemanager.scheduler.capacity.CapacitySchedulerConfiguration: max alloc mb per queue for root.default is -1
2019-06-07 08:04:40,084 DEBUG org.apache.hadoop.yarn.server.resourcemanager.scheduler.capacity.CapacitySchedulerConfiguration: max alloc mb per queue for root.default is -1
2019-06-07 08:04:40,084 DEBUG org.apache.hadoop.yarn.server.resourcemanager.scheduler.capacity.CapacitySchedulerConfiguration: max alloc vcores per queue for root.default is -1
2019-06-07 08:04:40,084 DEBUG org.apache.hadoop.yarn.server.resourcemanager.scheduler.capacity.CapacitySchedulerConfiguration: max alloc vcores per queue for root.default is -1
2019-06-07 08:04:40,084 INFO org.apache.hadoop.yarn.server.resourcemanager.scheduler.capacity.CapacitySchedulerConfiguration: max alloc mb per queue for root.default is undefined
2019-06-07 08:04:40,084 INFO org.apache.hadoop.yarn.server.resourcemanager.scheduler.capacity.CapacitySchedulerConfiguration: max alloc mb per queue for root.default is undefined
2019-06-07 08:04:40,084 INFO org.apache.hadoop.yarn.server.resourcemanager.scheduler.capacity.CapacitySchedulerConfiguration: max alloc vcore per queue for root.default is undefined
2019-06-07 08:04:40,084 INFO org.apache.hadoop.yarn.server.resourcemanager.scheduler.capacity.CapacitySchedulerConfiguration: max alloc vcore per queue for root.default is undefined
2019-06-07 08:04:40,086 INFO org.apache.hadoop.yarn.server.resourcemanager.scheduler.capacity.LeafQueue: Initializing default
capacity = 1.0 [= (float) configuredCapacity / 100 ]
asboluteCapacity = 1.0 [= parentAbsoluteCapacity * capacity ]
maxCapacity = 1.0 [= configuredMaxCapacity ]
absoluteMaxCapacity = 1.0 [= 1.0 maximumCapacity undefined, (parentAbsoluteMaxCapacity * maximumCapacity) / 100 otherwise ]
userLimit = 100 [= configuredUserLimit ]
userLimitFactor = 1.0 [= configuredUserLimitFactor ]
maxApplications = 10000 [= configuredMaximumSystemApplicationsPerQueue or (int)(configuredMaximumSystemApplications * absoluteCapacity)]
maxApplicationsPerUser = 10000 [= (int)(maxApplications * (userLimit / 100.0f) * userLimitFactor) ]
usedCapacity = 0.0 [= usedResourcesMemory / (clusterResourceMemory * absoluteCapacity)]
absoluteUsedCapacity = 0.0 [= usedResourcesMemory / clusterResourceMemory]
maxAMResourcePerQueuePercent = 0.1 [= configuredMaximumAMResourcePercent ]
minimumAllocationFactor = 0.875 [= (float)(maximumAllocationMemory - minimumAllocationMemory) / maximumAllocationMemory ]
maximumAllocation = <memory:8192, vCores:4> [= configuredMaxAllocation ]
numContainers = 0 [= currentNumContainers ]
state = RUNNING [= configuredState ]
acls = ADMINISTER_QUEUE:*SUBMIT_APP:* [= configuredAcls ]
nodeLocalityDelay = 40
labels=*,
reservationsContinueLooking = true
preemptionDisabled = true
defaultAppPriorityPerQueue = 0
2019-06-07 08:04:40,086 INFO org.apache.hadoop.yarn.server.resourcemanager.scheduler.capacity.LeafQueue: Initializing default
capacity = 1.0 [= (float) configuredCapacity / 100 ]
asboluteCapacity = 1.0 [= parentAbsoluteCapacity * capacity ]
maxCapacity = 1.0 [= configuredMaxCapacity ]
absoluteMaxCapacity = 1.0 [= 1.0 maximumCapacity undefined, (parentAbsoluteMaxCapacity * maximumCapacity) / 100 otherwise ]
userLimit = 100 [= configuredUserLimit ]
userLimitFactor = 1.0 [= configuredUserLimitFactor ]
maxApplications = 10000 [= configuredMaximumSystemApplicationsPerQueue or (int)(configuredMaximumSystemApplications * absoluteCapacity)]
maxApplicationsPerUser = 10000 [= (int)(maxApplications * (userLimit / 100.0f) * userLimitFactor) ]
usedCapacity = 0.0 [= usedResourcesMemory / (clusterResourceMemory * absoluteCapacity)]
absoluteUsedCapacity = 0.0 [= usedResourcesMemory / clusterResourceMemory]
maxAMResourcePerQueuePercent = 0.1 [= configuredMaximumAMResourcePercent ]
minimumAllocationFactor = 0.875 [= (float)(maximumAllocationMemory - minimumAllocationMemory) / maximumAllocationMemory ]
maximumAllocation = <memory:8192, vCores:4> [= configuredMaxAllocation ]
numContainers = 0 [= currentNumContainers ]
state = RUNNING [= configuredState ]
acls = ADMINISTER_QUEUE:*SUBMIT_APP:* [= configuredAcls ]
nodeLocalityDelay = 40
labels=*,
reservationsContinueLooking = true
preemptionDisabled = true
defaultAppPriorityPerQueue = 0
2019-06-07 08:04:40,086 INFO org.apache.hadoop.yarn.server.resourcemanager.scheduler.capacity.CapacityScheduler: Initialized queue: default: capacity=1.0, absoluteCapacity=1.0, usedResources=<memory:0, vCores:0>, usedCapacity=0.0, absoluteUsedCapacity=0.0, numApps=0, numContainers=0
2019-06-07 08:04:40,086 INFO org.apache.hadoop.yarn.server.resourcemanager.scheduler.capacity.CapacityScheduler: Initialized queue: default: capacity=1.0, absoluteCapacity=1.0, usedResources=<memory:0, vCores:0>, usedCapacity=0.0, absoluteUsedCapacity=0.0, numApps=0, numContainers=0
2019-06-07 08:04:40,087 DEBUG org.apache.hadoop.yarn.server.resourcemanager.scheduler.capacity.ParentQueue: setChildQueues: root.defaultusedCapacity=(0.0),  label=(*)
2019-06-07 08:04:40,087 DEBUG org.apache.hadoop.yarn.server.resourcemanager.scheduler.capacity.ParentQueue: setChildQueues: root.defaultusedCapacity=(0.0),  label=(*)
2019-06-07 08:04:40,087 INFO org.apache.hadoop.yarn.server.resourcemanager.scheduler.capacity.CapacityScheduler: Initialized queue: root: numChildQueue= 1, capacity=1.0, absoluteCapacity=1.0, usedResources=<memory:0, vCores:0>usedCapacity=0.0, numApps=0, numContainers=0
2019-06-07 08:04:40,087 INFO org.apache.hadoop.yarn.server.resourcemanager.scheduler.capacity.CapacityScheduler: Initialized queue: root: numChildQueue= 1, capacity=1.0, absoluteCapacity=1.0, usedResources=<memory:0, vCores:0>usedCapacity=0.0, numApps=0, numContainers=0
2019-06-07 08:04:40,088 INFO org.apache.hadoop.yarn.server.resourcemanager.scheduler.capacity.CapacityScheduler: Initialized root queue root: numChildQueue= 1, capacity=1.0, absoluteCapacity=1.0, usedResources=<memory:0, vCores:0>usedCapacity=0.0, numApps=0, numContainers=0
2019-06-07 08:04:40,088 INFO org.apache.hadoop.yarn.server.resourcemanager.scheduler.capacity.CapacityScheduler: Initialized root queue root: numChildQueue= 1, capacity=1.0, absoluteCapacity=1.0, usedResources=<memory:0, vCores:0>usedCapacity=0.0, numApps=0, numContainers=0
2019-06-07 08:04:40,088 INFO org.apache.hadoop.yarn.server.resourcemanager.scheduler.capacity.CapacityScheduler: Initialized queue mappings, override: false
2019-06-07 08:04:40,088 INFO org.apache.hadoop.yarn.server.resourcemanager.scheduler.capacity.CapacityScheduler: Initialized queue mappings, override: false
2019-06-07 08:04:40,089 INFO org.apache.hadoop.yarn.server.resourcemanager.scheduler.capacity.CapacityScheduler: Initialized CapacityScheduler with calculator=class org.apache.hadoop.yarn.util.resource.DefaultResourceCalculator, minimumAllocation=<<memory:1024, vCores:1>>, maximumAllocation=<<memory:8192, vCores:4>>, asynchronousScheduling=false, asyncScheduleInterval=5ms
2019-06-07 08:04:40,089 INFO org.apache.hadoop.yarn.server.resourcemanager.scheduler.capacity.CapacityScheduler: Initialized CapacityScheduler with calculator=class org.apache.hadoop.yarn.util.resource.DefaultResourceCalculator, minimumAllocation=<<memory:1024, vCores:1>>, maximumAllocation=<<memory:8192, vCores:4>>, asynchronousScheduling=false, asyncScheduleInterval=5ms
2019-06-07 08:04:40,091 INFO org.apache.hadoop.conf.Configuration: dynamic-resources.xml not found
2019-06-07 08:04:40,100 INFO org.apache.hadoop.yarn.server.resourcemanager.metrics.SystemMetricsPublisher: YARN system metrics publishing service is not enabled
2019-06-07 08:04:40,100 INFO org.apache.hadoop.yarn.server.resourcemanager.metrics.SystemMetricsPublisher: YARN system metrics publishing service is not enabled
2019-06-07 08:04:40,100 INFO org.apache.hadoop.yarn.server.resourcemanager.ResourceManager: Transitioning to active state
2019-06-07 08:04:40,100 INFO org.apache.hadoop.yarn.server.resourcemanager.ResourceManager: Transitioning to active state
2019-06-07 08:04:40,134 INFO org.apache.hadoop.util.JvmPauseMonitor: Starting JVM pause monitor
2019-06-07 08:04:40,138 DEBUG org.apache.hadoop.yarn.server.resourcemanager.recovery.RMStateStore: Processing event of type UPDATE_AMRM_TOKEN
2019-06-07 08:04:40,138 DEBUG org.apache.hadoop.yarn.server.resourcemanager.recovery.RMStateStore: Processing event of type UPDATE_AMRM_TOKEN
2019-06-07 08:04:40,138 INFO org.apache.hadoop.yarn.server.resourcemanager.recovery.RMStateStore: Updating AMRMToken
2019-06-07 08:04:40,138 INFO org.apache.hadoop.yarn.server.resourcemanager.recovery.RMStateStore: Updating AMRMToken
2019-06-07 08:04:40,138 INFO org.apache.hadoop.yarn.server.resourcemanager.security.RMContainerTokenSecretManager: Rolling master-key for container-tokens
2019-06-07 08:04:40,138 INFO org.apache.hadoop.yarn.server.resourcemanager.security.RMContainerTokenSecretManager: Rolling master-key for container-tokens
2019-06-07 08:04:40,138 INFO org.apache.hadoop.yarn.server.resourcemanager.security.NMTokenSecretManagerInRM: Rolling master-key for nm-tokens
2019-06-07 08:04:40,138 INFO org.apache.hadoop.yarn.server.resourcemanager.security.NMTokenSecretManagerInRM: Rolling master-key for nm-tokens
2019-06-07 08:04:40,138 INFO org.apache.hadoop.security.token.delegation.AbstractDelegationTokenSecretManager: Updating the current master key for generating delegation tokens
2019-06-07 08:04:40,139 INFO org.apache.hadoop.yarn.server.resourcemanager.security.RMDelegationTokenSecretManager: storing master key with keyID 1
2019-06-07 08:04:40,139 INFO org.apache.hadoop.yarn.server.resourcemanager.security.RMDelegationTokenSecretManager: storing master key with keyID 1
2019-06-07 08:04:40,139 DEBUG org.apache.hadoop.yarn.server.resourcemanager.recovery.RMStateStore: Processing event of type STORE_MASTERKEY
2019-06-07 08:04:40,139 DEBUG org.apache.hadoop.yarn.server.resourcemanager.recovery.RMStateStore: Processing event of type STORE_MASTERKEY
2019-06-07 08:04:40,139 INFO org.apache.hadoop.yarn.server.resourcemanager.recovery.RMStateStore: Storing RMDTMasterKey.
2019-06-07 08:04:40,139 INFO org.apache.hadoop.yarn.server.resourcemanager.recovery.RMStateStore: Storing RMDTMasterKey.
2019-06-07 08:04:40,140 INFO org.apache.hadoop.security.token.delegation.AbstractDelegationTokenSecretManager: Starting expired delegation token remover thread, tokenRemoverScanInterval=60 min(s)
2019-06-07 08:04:40,140 INFO org.apache.hadoop.security.token.delegation.AbstractDelegationTokenSecretManager: Updating the current master key for generating delegation tokens
2019-06-07 08:04:40,140 INFO org.apache.hadoop.yarn.server.resourcemanager.security.RMDelegationTokenSecretManager: storing master key with keyID 2
2019-06-07 08:04:40,140 INFO org.apache.hadoop.yarn.server.resourcemanager.security.RMDelegationTokenSecretManager: storing master key with keyID 2
2019-06-07 08:04:40,140 DEBUG org.apache.hadoop.yarn.server.resourcemanager.recovery.RMStateStore: Processing event of type STORE_MASTERKEY
2019-06-07 08:04:40,140 DEBUG org.apache.hadoop.yarn.server.resourcemanager.recovery.RMStateStore: Processing event of type STORE_MASTERKEY
2019-06-07 08:04:40,140 INFO org.apache.hadoop.yarn.server.resourcemanager.recovery.RMStateStore: Storing RMDTMasterKey.
2019-06-07 08:04:40,140 INFO org.apache.hadoop.yarn.server.resourcemanager.recovery.RMStateStore: Storing RMDTMasterKey.
2019-06-07 08:04:40,141 INFO org.apache.hadoop.yarn.event.AsyncDispatcher: Registering class org.apache.hadoop.yarn.nodelabels.event.NodeLabelsStoreEventType for class org.apache.hadoop.yarn.nodelabels.CommonNodeLabelsManager$ForwardingEventHandler
2019-06-07 08:04:40,170 INFO org.apache.hadoop.ipc.CallQueueManager: Using callQueue: class java.util.concurrent.LinkedBlockingQueue queueCapacity: 5000 scheduler: class org.apache.hadoop.ipc.DefaultRpcScheduler
2019-06-07 08:04:40,182 INFO org.apache.hadoop.ipc.Server: Starting Socket Reader #1 for port 8031
2019-06-07 08:04:40,470 INFO org.apache.hadoop.yarn.factories.impl.pb.RpcServerFactoryPBImpl: Adding protocol org.apache.hadoop.yarn.server.api.ResourceTrackerPB to the server
2019-06-07 08:04:40,483 INFO org.apache.hadoop.ipc.Server: IPC Server Responder: starting
2019-06-07 08:04:40,484 INFO org.apache.hadoop.ipc.Server: IPC Server listener on 8031: starting
2019-06-07 08:04:40,540 INFO org.apache.hadoop.ipc.CallQueueManager: Using callQueue: class java.util.concurrent.LinkedBlockingQueue queueCapacity: 5000 scheduler: class org.apache.hadoop.ipc.DefaultRpcScheduler
2019-06-07 08:04:40,669 INFO org.apache.hadoop.ipc.Server: Starting Socket Reader #1 for port 8030
2019-06-07 08:04:40,727 INFO org.apache.hadoop.yarn.factories.impl.pb.RpcServerFactoryPBImpl: Adding protocol org.apache.hadoop.yarn.api.ApplicationMasterProtocolPB to the server
2019-06-07 08:04:40,749 INFO org.apache.hadoop.ipc.Server: IPC Server Responder: starting
2019-06-07 08:04:40,759 INFO org.apache.hadoop.ipc.Server: IPC Server listener on 8030: starting
2019-06-07 08:04:41,058 INFO org.apache.hadoop.ipc.CallQueueManager: Using callQueue: class java.util.concurrent.LinkedBlockingQueue queueCapacity: 5000 scheduler: class org.apache.hadoop.ipc.DefaultRpcScheduler
2019-06-07 08:04:41,065 INFO org.apache.hadoop.ipc.Server: Starting Socket Reader #1 for port 8032
2019-06-07 08:04:41,069 INFO org.apache.hadoop.yarn.factories.impl.pb.RpcServerFactoryPBImpl: Adding protocol org.apache.hadoop.yarn.api.ApplicationClientProtocolPB to the server
2019-06-07 08:04:41,069 INFO org.apache.hadoop.ipc.Server: IPC Server Responder: starting
2019-06-07 08:04:41,069 INFO org.apache.hadoop.ipc.Server: IPC Server listener on 8032: starting
2019-06-07 08:04:41,084 INFO org.apache.hadoop.yarn.server.resourcemanager.ResourceManager: Transitioned to active state
2019-06-07 08:04:41,084 INFO org.apache.hadoop.yarn.server.resourcemanager.ResourceManager: Transitioned to active state
2019-06-07 08:04:41,360 INFO org.mortbay.log: Logging to org.slf4j.impl.Log4jLoggerAdapter(org.mortbay.log) via org.mortbay.log.Slf4jLog
2019-06-07 08:04:41,374 INFO org.apache.hadoop.security.authentication.server.AuthenticationFilter: Unable to initialize FileSignerSecretProvider, falling back to use random secrets.
2019-06-07 08:04:41,382 INFO org.apache.hadoop.http.HttpRequestLog: Http request log for http.requests.resourcemanager is not defined
2019-06-07 08:04:41,402 INFO org.apache.hadoop.http.HttpServer2: Added global filter 'safety' (class=org.apache.hadoop.http.HttpServer2$QuotingInputFilter)
2019-06-07 08:04:41,419 INFO org.apache.hadoop.http.HttpServer2: Added filter RMAuthenticationFilter (class=org.apache.hadoop.yarn.server.security.http.RMAuthenticationFilter) to context cluster
2019-06-07 08:04:41,419 INFO org.apache.hadoop.http.HttpServer2: Added filter RMAuthenticationFilter (class=org.apache.hadoop.yarn.server.security.http.RMAuthenticationFilter) to context logs
2019-06-07 08:04:41,419 INFO org.apache.hadoop.http.HttpServer2: Added filter RMAuthenticationFilter (class=org.apache.hadoop.yarn.server.security.http.RMAuthenticationFilter) to context static
2019-06-07 08:04:41,419 INFO org.apache.hadoop.http.HttpServer2: Added filter static_user_filter (class=org.apache.hadoop.http.lib.StaticUserWebFilter$StaticUserFilter) to context cluster
2019-06-07 08:04:41,419 INFO org.apache.hadoop.http.HttpServer2: Added filter static_user_filter (class=org.apache.hadoop.http.lib.StaticUserWebFilter$StaticUserFilter) to context logs
2019-06-07 08:04:41,419 INFO org.apache.hadoop.http.HttpServer2: Added filter static_user_filter (class=org.apache.hadoop.http.lib.StaticUserWebFilter$StaticUserFilter) to context static
2019-06-07 08:04:41,423 INFO org.apache.hadoop.http.HttpServer2: adding path spec: /cluster/*
2019-06-07 08:04:41,424 INFO org.apache.hadoop.http.HttpServer2: adding path spec: /ws/*
2019-06-07 08:04:43,177 INFO org.apache.hadoop.yarn.webapp.WebApps: Registered webapp guice modules
2019-06-07 08:04:43,181 INFO org.apache.hadoop.http.HttpServer2: Jetty bound to port 8088
2019-06-07 08:04:43,181 INFO org.mortbay.log: jetty-6.1.26
2019-06-07 08:04:43,309 INFO org.mortbay.log: Extract jar:file:/hadoop-2.8.5/share/hadoop/yarn/hadoop-yarn-common-2.8.5.jar!/webapps/cluster to /tmp/Jetty_master_8088_cluster____i4ls4w/webapp
2019-06-07 08:04:43,930 INFO org.apache.hadoop.security.token.delegation.AbstractDelegationTokenSecretManager: Updating the current master key for generating delegation tokens
2019-06-07 08:04:43,949 INFO org.apache.hadoop.security.token.delegation.AbstractDelegationTokenSecretManager: Starting expired delegation token remover thread, tokenRemoverScanInterval=60 min(s)
2019-06-07 08:04:43,951 INFO org.apache.hadoop.security.token.delegation.AbstractDelegationTokenSecretManager: Updating the current master key for generating delegation tokens
2019-06-07 08:04:47,977 INFO org.apache.hadoop.yarn.server.resourcemanager.ResourceTrackerService: NodeManager from node slave2(cmPort: 37804 httpPort: 8042) registered with capability: <memory:4096, vCores:1>, assigned nodeId slave2:37804
2019-06-07 08:04:47,977 INFO org.apache.hadoop.yarn.server.resourcemanager.ResourceTrackerService: NodeManager from node slave2(cmPort: 37804 httpPort: 8042) registered with capability: <memory:4096, vCores:1>, assigned nodeId slave2:37804
2019-06-07 08:04:47,980 INFO org.apache.hadoop.yarn.server.resourcemanager.ResourceTrackerService: NodeManager from node slave1(cmPort: 43282 httpPort: 8042) registered with capability: <memory:4096, vCores:1>, assigned nodeId slave1:43282
2019-06-07 08:04:47,980 INFO org.apache.hadoop.yarn.server.resourcemanager.ResourceTrackerService: NodeManager from node slave1(cmPort: 43282 httpPort: 8042) registered with capability: <memory:4096, vCores:1>, assigned nodeId slave1:43282
2019-06-07 08:04:48,183 INFO org.mortbay.log: Started HttpServer2$SelectChannelConnectorWithSafeStartup@master:8088
2019-06-07 08:04:48,183 INFO org.apache.hadoop.yarn.webapp.WebApps: Web app cluster started at 8088
2019-06-07 08:04:48,191 DEBUG org.apache.hadoop.yarn.server.resourcemanager.rmnode.RMNodeImpl: Processing slave2:37804 of type STARTED
2019-06-07 08:04:48,191 DEBUG org.apache.hadoop.yarn.server.resourcemanager.rmnode.RMNodeImpl: Processing slave2:37804 of type STARTED
2019-06-07 08:04:48,214 INFO org.apache.hadoop.yarn.server.resourcemanager.rmnode.RMNodeImpl: slave2:37804 Node Transitioned from NEW to RUNNING
2019-06-07 08:04:48,214 INFO org.apache.hadoop.yarn.server.resourcemanager.rmnode.RMNodeImpl: slave2:37804 Node Transitioned from NEW to RUNNING
2019-06-07 08:04:48,215 DEBUG org.apache.hadoop.yarn.server.resourcemanager.rmnode.RMNodeImpl: Processing slave1:43282 of type STARTED
2019-06-07 08:04:48,215 DEBUG org.apache.hadoop.yarn.server.resourcemanager.rmnode.RMNodeImpl: Processing slave1:43282 of type STARTED
2019-06-07 08:04:48,215 INFO org.apache.hadoop.yarn.server.resourcemanager.rmnode.RMNodeImpl: slave1:43282 Node Transitioned from NEW to RUNNING
2019-06-07 08:04:48,215 INFO org.apache.hadoop.yarn.server.resourcemanager.rmnode.RMNodeImpl: slave1:43282 Node Transitioned from NEW to RUNNING
2019-06-07 08:04:48,215 DEBUG org.apache.hadoop.yarn.server.resourcemanager.rmnode.RMNodeImpl: Processing slave2:37804 of type STATUS_UPDATE
2019-06-07 08:04:48,215 DEBUG org.apache.hadoop.yarn.server.resourcemanager.rmnode.RMNodeImpl: Processing slave2:37804 of type STATUS_UPDATE
2019-06-07 08:04:48,224 DEBUG org.apache.hadoop.yarn.server.resourcemanager.rmnode.RMNodeImpl: Processing slave1:43282 of type STATUS_UPDATE
2019-06-07 08:04:48,224 DEBUG org.apache.hadoop.yarn.server.resourcemanager.rmnode.RMNodeImpl: Processing slave1:43282 of type STATUS_UPDATE
2019-06-07 08:04:48,225 INFO org.apache.hadoop.ipc.CallQueueManager: Using callQueue: class java.util.concurrent.LinkedBlockingQueue queueCapacity: 100 scheduler: class org.apache.hadoop.ipc.DefaultRpcScheduler
2019-06-07 08:04:48,226 INFO org.apache.hadoop.ipc.Server: Starting Socket Reader #1 for port 8033
2019-06-07 08:04:48,229 INFO org.apache.hadoop.yarn.factories.impl.pb.RpcServerFactoryPBImpl: Adding protocol org.apache.hadoop.yarn.server.api.ResourceManagerAdministrationProtocolPB to the server
2019-06-07 08:04:48,231 INFO org.apache.hadoop.ipc.Server: IPC Server Responder: starting
2019-06-07 08:04:48,232 INFO org.apache.hadoop.ipc.Server: IPC Server listener on 8033: starting
2019-06-07 08:04:48,236 DEBUG org.apache.hadoop.yarn.server.resourcemanager.NodesListManager: slave2:37804 reported usable
2019-06-07 08:04:48,236 DEBUG org.apache.hadoop.yarn.server.resourcemanager.NodesListManager: slave2:37804 reported usable
2019-06-07 08:04:48,237 DEBUG org.apache.hadoop.yarn.server.resourcemanager.NodesListManager: slave1:43282 reported usable
2019-06-07 08:04:48,237 DEBUG org.apache.hadoop.yarn.server.resourcemanager.NodesListManager: slave1:43282 reported usable
2019-06-07 08:04:48,240 INFO org.apache.hadoop.yarn.server.resourcemanager.scheduler.capacity.CapacityScheduler: Added node slave2:37804 clusterResource: <memory:4096, vCores:1>
2019-06-07 08:04:48,240 INFO org.apache.hadoop.yarn.server.resourcemanager.scheduler.capacity.CapacityScheduler: Added node slave2:37804 clusterResource: <memory:4096, vCores:1>
2019-06-07 08:04:48,241 INFO org.apache.hadoop.yarn.server.resourcemanager.scheduler.capacity.CapacityScheduler: Added node slave1:43282 clusterResource: <memory:8192, vCores:2>
2019-06-07 08:04:48,241 INFO org.apache.hadoop.yarn.server.resourcemanager.scheduler.capacity.CapacityScheduler: Added node slave1:43282 clusterResource: <memory:8192, vCores:2>
2019-06-07 08:04:48,241 DEBUG org.apache.hadoop.yarn.server.resourcemanager.scheduler.capacity.CapacityScheduler: nodeUpdate: slave2:37804 clusterResources: <memory:8192, vCores:2>
2019-06-07 08:04:48,241 DEBUG org.apache.hadoop.yarn.server.resourcemanager.scheduler.capacity.CapacityScheduler: nodeUpdate: slave2:37804 clusterResources: <memory:8192, vCores:2>
2019-06-07 08:04:48,241 DEBUG org.apache.hadoop.yarn.server.resourcemanager.scheduler.capacity.CapacityScheduler: Node being looked for scheduling slave2:37804 availableResource: <memory:4096, vCores:1>
2019-06-07 08:04:48,241 DEBUG org.apache.hadoop.yarn.server.resourcemanager.scheduler.capacity.CapacityScheduler: Node being looked for scheduling slave2:37804 availableResource: <memory:4096, vCores:1>
2019-06-07 08:04:48,244 DEBUG org.apache.hadoop.yarn.server.resourcemanager.scheduler.capacity.CapacityScheduler: Trying to schedule on node: slave2, available: <memory:4096, vCores:1>
2019-06-07 08:04:48,244 DEBUG org.apache.hadoop.yarn.server.resourcemanager.scheduler.capacity.CapacityScheduler: Trying to schedule on node: slave2, available: <memory:4096, vCores:1>
2019-06-07 08:04:48,244 DEBUG org.apache.hadoop.yarn.server.resourcemanager.scheduler.capacity.ParentQueue: Skip this queue=root, because it doesn't need more resource, schedulingMode=RESPECT_PARTITION_EXCLUSIVITY node-partition=
2019-06-07 08:04:48,244 DEBUG org.apache.hadoop.yarn.server.resourcemanager.scheduler.capacity.ParentQueue: Skip this queue=root, because it doesn't need more resource, schedulingMode=RESPECT_PARTITION_EXCLUSIVITY node-partition=
2019-06-07 08:04:48,244 DEBUG org.apache.hadoop.yarn.server.resourcemanager.scheduler.capacity.CapacityScheduler: nodeUpdate: slave1:43282 clusterResources: <memory:8192, vCores:2>
2019-06-07 08:04:48,244 DEBUG org.apache.hadoop.yarn.server.resourcemanager.scheduler.capacity.CapacityScheduler: nodeUpdate: slave1:43282 clusterResources: <memory:8192, vCores:2>
2019-06-07 08:04:48,259 DEBUG org.apache.hadoop.yarn.server.resourcemanager.scheduler.capacity.CapacityScheduler: Node being looked for scheduling slave1:43282 availableResource: <memory:4096, vCores:1>
2019-06-07 08:04:48,259 DEBUG org.apache.hadoop.yarn.server.resourcemanager.scheduler.capacity.CapacityScheduler: Node being looked for scheduling slave1:43282 availableResource: <memory:4096, vCores:1>
2019-06-07 08:04:48,259 DEBUG org.apache.hadoop.yarn.server.resourcemanager.scheduler.capacity.CapacityScheduler: Trying to schedule on node: slave1, available: <memory:4096, vCores:1>
2019-06-07 08:04:48,259 DEBUG org.apache.hadoop.yarn.server.resourcemanager.scheduler.capacity.CapacityScheduler: Trying to schedule on node: slave1, available: <memory:4096, vCores:1>
2019-06-07 08:04:48,259 DEBUG org.apache.hadoop.yarn.server.resourcemanager.scheduler.capacity.ParentQueue: Skip this queue=root, because it doesn't need more resource, schedulingMode=RESPECT_PARTITION_EXCLUSIVITY node-partition=
2019-06-07 08:04:48,259 DEBUG org.apache.hadoop.yarn.server.resourcemanager.scheduler.capacity.ParentQueue: Skip this queue=root, because it doesn't need more resource, schedulingMode=RESPECT_PARTITION_EXCLUSIVITY node-partition=
2019-06-07 08:04:49,137 DEBUG org.apache.hadoop.yarn.server.resourcemanager.rmnode.RMNodeImpl: Processing slave2:37804 of type STATUS_UPDATE
2019-06-07 08:04:49,137 DEBUG org.apache.hadoop.yarn.server.resourcemanager.rmnode.RMNodeImpl: Processing slave2:37804 of type STATUS_UPDATE
2019-06-07 08:04:49,143 DEBUG org.apache.hadoop.yarn.server.resourcemanager.scheduler.capacity.CapacityScheduler: nodeUpdate: slave2:37804 clusterResources: <memory:8192, vCores:2>
2019-06-07 08:04:49,143 DEBUG org.apache.hadoop.yarn.server.resourcemanager.scheduler.capacity.CapacityScheduler: nodeUpdate: slave2:37804 clusterResources: <memory:8192, vCores:2>
2019-06-07 08:04:49,143 DEBUG org.apache.hadoop.yarn.server.resourcemanager.scheduler.capacity.CapacityScheduler: Node being looked for scheduling slave2:37804 availableResource: <memory:4096, vCores:1>
2019-06-07 08:04:49,143 DEBUG org.apache.hadoop.yarn.server.resourcemanager.scheduler.capacity.CapacityScheduler: Node being looked for scheduling slave2:37804 availableResource: <memory:4096, vCores:1>
2019-06-07 08:04:49,143 DEBUG org.apache.hadoop.yarn.server.resourcemanager.scheduler.capacity.CapacityScheduler: Trying to schedule on node: slave2, available: <memory:4096, vCores:1>
2019-06-07 08:04:49,143 DEBUG org.apache.hadoop.yarn.server.resourcemanager.scheduler.capacity.CapacityScheduler: Trying to schedule on node: slave2, available: <memory:4096, vCores:1>
2019-06-07 08:04:49,143 DEBUG org.apache.hadoop.yarn.server.resourcemanager.scheduler.capacity.ParentQueue: Skip this queue=root, because it doesn't need more resource, schedulingMode=RESPECT_PARTITION_EXCLUSIVITY node-partition=
2019-06-07 08:04:49,143 DEBUG org.apache.hadoop.yarn.server.resourcemanager.scheduler.capacity.ParentQueue: Skip this queue=root, because it doesn't need more resource, schedulingMode=RESPECT_PARTITION_EXCLUSIVITY node-partition=
2019-06-07 08:04:49,144 DEBUG org.apache.hadoop.yarn.server.resourcemanager.rmnode.RMNodeImpl: Processing slave1:43282 of type STATUS_UPDATE
2019-06-07 08:04:49,144 DEBUG org.apache.hadoop.yarn.server.resourcemanager.rmnode.RMNodeImpl: Processing slave1:43282 of type STATUS_UPDATE
2019-06-07 08:04:49,146 DEBUG org.apache.hadoop.yarn.server.resourcemanager.scheduler.capacity.CapacityScheduler: nodeUpdate: slave1:43282 clusterResources: <memory:8192, vCores:2>
2019-06-07 08:04:49,146 DEBUG org.apache.hadoop.yarn.server.resourcemanager.scheduler.capacity.CapacityScheduler: nodeUpdate: slave1:43282 clusterResources: <memory:8192, vCores:2>
2019-06-07 08:04:49,146 DEBUG org.apache.hadoop.yarn.server.resourcemanager.scheduler.capacity.CapacityScheduler: Node being looked for scheduling slave1:43282 availableResource: <memory:4096, vCores:1>
2019-06-07 08:04:49,146 DEBUG org.apache.hadoop.yarn.server.resourcemanager.scheduler.capacity.CapacityScheduler: Node being looked for scheduling slave1:43282 availableResource: <memory:4096, vCores:1>
2019-06-07 08:04:49,146 DEBUG org.apache.hadoop.yarn.server.resourcemanager.scheduler.capacity.CapacityScheduler: Trying to schedule on node: slave1, available: <memory:4096, vCores:1>
2019-06-07 08:04:49,146 DEBUG org.apache.hadoop.yarn.server.resourcemanager.scheduler.capacity.CapacityScheduler: Trying to schedule on node: slave1, available: <memory:4096, vCores:1>
2019-06-07 08:04:49,146 DEBUG org.apache.hadoop.yarn.server.resourcemanager.scheduler.capacity.ParentQueue: Skip this queue=root, because it doesn't need more resource, schedulingMode=RESPECT_PARTITION_EXCLUSIVITY node-partition=
2019-06-07 08:04:49,146 DEBUG org.apache.hadoop.yarn.server.resourcemanager.scheduler.capacity.ParentQueue: Skip this queue=root, because it doesn't need more resource, schedulingMode=RESPECT_PARTITION_EXCLUSIVITY node-partition=
2019-06-07 08:04:50,140 DEBUG org.apache.hadoop.yarn.server.resourcemanager.rmnode.RMNodeImpl: Processing slave2:37804 of type STATUS_UPDATE
2019-06-07 08:04:50,140 DEBUG org.apache.hadoop.yarn.server.resourcemanager.rmnode.RMNodeImpl: Processing slave2:37804 of type STATUS_UPDATE
2019-06-07 08:04:50,141 DEBUG org.apache.hadoop.yarn.server.resourcemanager.scheduler.capacity.CapacityScheduler: nodeUpdate: slave2:37804 clusterResources: <memory:8192, vCores:2>
2019-06-07 08:04:50,141 DEBUG org.apache.hadoop.yarn.server.resourcemanager.scheduler.capacity.CapacityScheduler: nodeUpdate: slave2:37804 clusterResources: <memory:8192, vCores:2>
2019-06-07 08:04:50,141 DEBUG org.apache.hadoop.yarn.server.resourcemanager.scheduler.capacity.CapacityScheduler: Node being looked for scheduling slave2:37804 availableResource: <memory:4096, vCores:1>
2019-06-07 08:04:50,141 DEBUG org.apache.hadoop.yarn.server.resourcemanager.scheduler.capacity.CapacityScheduler: Node being looked for scheduling slave2:37804 availableResource: <memory:4096, vCores:1>
2019-06-07 08:04:50,141 DEBUG org.apache.hadoop.yarn.server.resourcemanager.scheduler.capacity.CapacityScheduler: Trying to schedule on node: slave2, available: <memory:4096, vCores:1>
2019-06-07 08:04:50,141 DEBUG org.apache.hadoop.yarn.server.resourcemanager.scheduler.capacity.CapacityScheduler: Trying to schedule on node: slave2, available: <memory:4096, vCores:1>
2019-06-07 08:04:50,142 DEBUG org.apache.hadoop.yarn.server.resourcemanager.scheduler.capacity.ParentQueue: Skip this queue=root, because it doesn't need more resource, schedulingMode=RESPECT_PARTITION_EXCLUSIVITY node-partition=
2019-06-07 08:04:50,142 DEBUG org.apache.hadoop.yarn.server.resourcemanager.scheduler.capacity.ParentQueue: Skip this queue=root, because it doesn't need more resource, schedulingMode=RESPECT_PARTITION_EXCLUSIVITY node-partition=
2019-06-07 08:04:50,147 DEBUG org.apache.hadoop.yarn.server.resourcemanager.rmnode.RMNodeImpl: Processing slave1:43282 of type STATUS_UPDATE
2019-06-07 08:04:50,147 DEBUG org.apache.hadoop.yarn.server.resourcemanager.rmnode.RMNodeImpl: Processing slave1:43282 of type STATUS_UPDATE
2019-06-07 08:04:50,150 DEBUG org.apache.hadoop.yarn.server.resourcemanager.scheduler.capacity.CapacityScheduler: nodeUpdate: slave1:43282 clusterResources: <memory:8192, vCores:2>
2019-06-07 08:04:50,150 DEBUG org.apache.hadoop.yarn.server.resourcemanager.scheduler.capacity.CapacityScheduler: nodeUpdate: slave1:43282 clusterResources: <memory:8192, vCores:2>
2019-06-07 08:04:50,150 DEBUG org.apache.hadoop.yarn.server.resourcemanager.scheduler.capacity.CapacityScheduler: Node being looked for scheduling slave1:43282 availableResource: <memory:4096, vCores:1>
2019-06-07 08:04:50,150 DEBUG org.apache.hadoop.yarn.server.resourcemanager.scheduler.capacity.CapacityScheduler: Node being looked for scheduling slave1:43282 availableResource: <memory:4096, vCores:1>
2019-06-07 08:04:50,150 DEBUG org.apache.hadoop.yarn.server.resourcemanager.scheduler.capacity.CapacityScheduler: Trying to schedule on node: slave1, available: <memory:4096, vCores:1>
2019-06-07 08:04:50,150 DEBUG org.apache.hadoop.yarn.server.resourcemanager.scheduler.capacity.CapacityScheduler: Trying to schedule on node: slave1, available: <memory:4096, vCores:1>
2019-06-07 08:04:50,150 DEBUG org.apache.hadoop.yarn.server.resourcemanager.scheduler.capacity.ParentQueue: Skip this queue=root, because it doesn't need more resource, schedulingMode=RESPECT_PARTITION_EXCLUSIVITY node-partition=
2019-06-07 08:04:50,150 DEBUG org.apache.hadoop.yarn.server.resourcemanager.scheduler.capacity.ParentQueue: Skip this queue=root, because it doesn't need more resource, schedulingMode=RESPECT_PARTITION_EXCLUSIVITY node-partition=
2019-06-07 08:04:51,143 DEBUG org.apache.hadoop.yarn.server.resourcemanager.rmnode.RMNodeImpl: Processing slave2:37804 of type STATUS_UPDATE
2019-06-07 08:04:51,143 DEBUG org.apache.hadoop.yarn.server.resourcemanager.rmnode.RMNodeImpl: Processing slave2:37804 of type STATUS_UPDATE
2019-06-07 08:04:51,145 DEBUG org.apache.hadoop.yarn.server.resourcemanager.scheduler.capacity.CapacityScheduler: nodeUpdate: slave2:37804 clusterResources: <memory:8192, vCores:2>
2019-06-07 08:04:51,145 DEBUG org.apache.hadoop.yarn.server.resourcemanager.scheduler.capacity.CapacityScheduler: nodeUpdate: slave2:37804 clusterResources: <memory:8192, vCores:2>
2019-06-07 08:04:51,145 DEBUG org.apache.hadoop.yarn.server.resourcemanager.scheduler.capacity.CapacityScheduler: Node being looked for scheduling slave2:37804 availableResource: <memory:4096, vCores:1>
2019-06-07 08:04:51,145 DEBUG org.apache.hadoop.yarn.server.resourcemanager.scheduler.capacity.CapacityScheduler: Node being looked for scheduling slave2:37804 availableResource: <memory:4096, vCores:1>
2019-06-07 08:04:51,145 DEBUG org.apache.hadoop.yarn.server.resourcemanager.scheduler.capacity.CapacityScheduler: Trying to schedule on node: slave2, available: <memory:4096, vCores:1>
2019-06-07 08:04:51,145 DEBUG org.apache.hadoop.yarn.server.resourcemanager.scheduler.capacity.CapacityScheduler: Trying to schedule on node: slave2, available: <memory:4096, vCores:1>
2019-06-07 08:04:51,145 DEBUG org.apache.hadoop.yarn.server.resourcemanager.scheduler.capacity.ParentQueue: Skip this queue=root, because it doesn't need more resource, schedulingMode=RESPECT_PARTITION_EXCLUSIVITY node-partition=
2019-06-07 08:04:51,145 DEBUG org.apache.hadoop.yarn.server.resourcemanager.scheduler.capacity.ParentQueue: Skip this queue=root, because it doesn't need more resource, schedulingMode=RESPECT_PARTITION_EXCLUSIVITY node-partition=
2019-06-07 08:04:51,150 DEBUG org.apache.hadoop.yarn.server.resourcemanager.rmnode.RMNodeImpl: Processing slave1:43282 of type STATUS_UPDATE
2019-06-07 08:04:51,150 DEBUG org.apache.hadoop.yarn.server.resourcemanager.rmnode.RMNodeImpl: Processing slave1:43282 of type STATUS_UPDATE
2019-06-07 08:04:51,151 DEBUG org.apache.hadoop.yarn.server.resourcemanager.scheduler.capacity.CapacityScheduler: nodeUpdate: slave1:43282 clusterResources: <memory:8192, vCores:2>
2019-06-07 08:04:51,151 DEBUG org.apache.hadoop.yarn.server.resourcemanager.scheduler.capacity.CapacityScheduler: nodeUpdate: slave1:43282 clusterResources: <memory:8192, vCores:2>
2019-06-07 08:04:51,151 DEBUG org.apache.hadoop.yarn.server.resourcemanager.scheduler.capacity.CapacityScheduler: Node being looked for scheduling slave1:43282 availableResource: <memory:4096, vCores:1>
2019-06-07 08:04:51,151 DEBUG org.apache.hadoop.yarn.server.resourcemanager.scheduler.capacity.CapacityScheduler: Node being looked for scheduling slave1:43282 availableResource: <memory:4096, vCores:1>
2019-06-07 08:04:51,151 DEBUG org.apache.hadoop.yarn.server.resourcemanager.scheduler.capacity.CapacityScheduler: Trying to schedule on node: slave1, available: <memory:4096, vCores:1>
2019-06-07 08:04:51,151 DEBUG org.apache.hadoop.yarn.server.resourcemanager.scheduler.capacity.CapacityScheduler: Trying to schedule on node: slave1, available: <memory:4096, vCores:1>
2019-06-07 08:04:51,151 DEBUG org.apache.hadoop.yarn.server.resourcemanager.scheduler.capacity.ParentQueue: Skip this queue=root, because it doesn't need more resource, schedulingMode=RESPECT_PARTITION_EXCLUSIVITY node-partition=
2019-06-07 08:04:51,151 DEBUG org.apache.hadoop.yarn.server.resourcemanager.scheduler.capacity.ParentQueue: Skip this queue=root, because it doesn't need more resource, schedulingMode=RESPECT_PARTITION_EXCLUSIVITY node-partition=
2019-06-07 08:04:52,145 DEBUG org.apache.hadoop.yarn.server.resourcemanager.rmnode.RMNodeImpl: Processing slave2:37804 of type STATUS_UPDATE
2019-06-07 08:04:52,145 DEBUG org.apache.hadoop.yarn.server.resourcemanager.rmnode.RMNodeImpl: Processing slave2:37804 of type STATUS_UPDATE
2019-06-07 08:04:52,146 DEBUG org.apache.hadoop.yarn.server.resourcemanager.scheduler.capacity.CapacityScheduler: nodeUpdate: slave2:37804 clusterResources: <memory:8192, vCores:2>
2019-06-07 08:04:52,146 DEBUG org.apache.hadoop.yarn.server.resourcemanager.scheduler.capacity.CapacityScheduler: nodeUpdate: slave2:37804 clusterResources: <memory:8192, vCores:2>
2019-06-07 08:04:52,146 DEBUG org.apache.hadoop.yarn.server.resourcemanager.scheduler.capacity.CapacityScheduler: Node being looked for scheduling slave2:37804 availableResource: <memory:4096, vCores:1>
2019-06-07 08:04:52,146 DEBUG org.apache.hadoop.yarn.server.resourcemanager.scheduler.capacity.CapacityScheduler: Node being looked for scheduling slave2:37804 availableResource: <memory:4096, vCores:1>
2019-06-07 08:04:52,146 DEBUG org.apache.hadoop.yarn.server.resourcemanager.scheduler.capacity.CapacityScheduler: Trying to schedule on node: slave2, available: <memory:4096, vCores:1>
2019-06-07 08:04:52,146 DEBUG org.apache.hadoop.yarn.server.resourcemanager.scheduler.capacity.CapacityScheduler: Trying to schedule on node: slave2, available: <memory:4096, vCores:1>
2019-06-07 08:04:52,146 DEBUG org.apache.hadoop.yarn.server.resourcemanager.scheduler.capacity.ParentQueue: Skip this queue=root, because it doesn't need more resource, schedulingMode=RESPECT_PARTITION_EXCLUSIVITY node-partition=
2019-06-07 08:04:52,146 DEBUG org.apache.hadoop.yarn.server.resourcemanager.scheduler.capacity.ParentQueue: Skip this queue=root, because it doesn't need more resource, schedulingMode=RESPECT_PARTITION_EXCLUSIVITY node-partition=
2019-06-07 08:04:52,152 DEBUG org.apache.hadoop.yarn.server.resourcemanager.rmnode.RMNodeImpl: Processing slave1:43282 of type STATUS_UPDATE
2019-06-07 08:04:52,152 DEBUG org.apache.hadoop.yarn.server.resourcemanager.rmnode.RMNodeImpl: Processing slave1:43282 of type STATUS_UPDATE
2019-06-07 08:04:52,153 DEBUG org.apache.hadoop.yarn.server.resourcemanager.scheduler.capacity.CapacityScheduler: nodeUpdate: slave1:43282 clusterResources: <memory:8192, vCores:2>
2019-06-07 08:04:52,153 DEBUG org.apache.hadoop.yarn.server.resourcemanager.scheduler.capacity.CapacityScheduler: nodeUpdate: slave1:43282 clusterResources: <memory:8192, vCores:2>
2019-06-07 08:04:52,153 DEBUG org.apache.hadoop.yarn.server.resourcemanager.scheduler.capacity.CapacityScheduler: Node being looked for scheduling slave1:43282 availableResource: <memory:4096, vCores:1>
2019-06-07 08:04:52,153 DEBUG org.apache.hadoop.yarn.server.resourcemanager.scheduler.capacity.CapacityScheduler: Node being looked for scheduling slave1:43282 availableResource: <memory:4096, vCores:1>
2019-06-07 08:04:52,153 DEBUG org.apache.hadoop.yarn.server.resourcemanager.scheduler.capacity.CapacityScheduler: Trying to schedule on node: slave1, available: <memory:4096, vCores:1>
2019-06-07 08:04:52,153 DEBUG org.apache.hadoop.yarn.server.resourcemanager.scheduler.capacity.CapacityScheduler: Trying to schedule on node: slave1, available: <memory:4096, vCores:1>
2019-06-07 08:04:52,153 DEBUG org.apache.hadoop.yarn.server.resourcemanager.scheduler.capacity.ParentQueue: Skip this queue=root, because it doesn't need more resource, schedulingMode=RESPECT_PARTITION_EXCLUSIVITY node-partition=
2019-06-07 08:04:52,153 DEBUG org.apache.hadoop.yarn.server.resourcemanager.scheduler.capacity.ParentQueue: Skip this queue=root, because it doesn't need more resource, schedulingMode=RESPECT_PARTITION_EXCLUSIVITY node-partition=
2019-06-07 08:04:52,230 INFO org.apache.hadoop.yarn.server.resourcemanager.ClientRMService: Allocated new applicationId: 1
2019-06-07 08:04:52,230 INFO org.apache.hadoop.yarn.server.resourcemanager.ClientRMService: Allocated new applicationId: 1
2019-06-07 08:04:53,147 DEBUG org.apache.hadoop.yarn.server.resourcemanager.rmnode.RMNodeImpl: Processing slave2:37804 of type STATUS_UPDATE
2019-06-07 08:04:53,147 DEBUG org.apache.hadoop.yarn.server.resourcemanager.rmnode.RMNodeImpl: Processing slave2:37804 of type STATUS_UPDATE
2019-06-07 08:04:53,151 DEBUG org.apache.hadoop.yarn.server.resourcemanager.scheduler.capacity.CapacityScheduler: nodeUpdate: slave2:37804 clusterResources: <memory:8192, vCores:2>
2019-06-07 08:04:53,151 DEBUG org.apache.hadoop.yarn.server.resourcemanager.scheduler.capacity.CapacityScheduler: nodeUpdate: slave2:37804 clusterResources: <memory:8192, vCores:2>
2019-06-07 08:04:53,151 DEBUG org.apache.hadoop.yarn.server.resourcemanager.scheduler.capacity.CapacityScheduler: Node being looked for scheduling slave2:37804 availableResource: <memory:4096, vCores:1>
2019-06-07 08:04:53,151 DEBUG org.apache.hadoop.yarn.server.resourcemanager.scheduler.capacity.CapacityScheduler: Node being looked for scheduling slave2:37804 availableResource: <memory:4096, vCores:1>
2019-06-07 08:04:53,152 DEBUG org.apache.hadoop.yarn.server.resourcemanager.scheduler.capacity.CapacityScheduler: Trying to schedule on node: slave2, available: <memory:4096, vCores:1>
2019-06-07 08:04:53,152 DEBUG org.apache.hadoop.yarn.server.resourcemanager.scheduler.capacity.CapacityScheduler: Trying to schedule on node: slave2, available: <memory:4096, vCores:1>
2019-06-07 08:04:53,152 DEBUG org.apache.hadoop.yarn.server.resourcemanager.scheduler.capacity.ParentQueue: Skip this queue=root, because it doesn't need more resource, schedulingMode=RESPECT_PARTITION_EXCLUSIVITY node-partition=
2019-06-07 08:04:53,152 DEBUG org.apache.hadoop.yarn.server.resourcemanager.scheduler.capacity.ParentQueue: Skip this queue=root, because it doesn't need more resource, schedulingMode=RESPECT_PARTITION_EXCLUSIVITY node-partition=
2019-06-07 08:04:53,155 DEBUG org.apache.hadoop.yarn.server.resourcemanager.rmnode.RMNodeImpl: Processing slave1:43282 of type STATUS_UPDATE
2019-06-07 08:04:53,155 DEBUG org.apache.hadoop.yarn.server.resourcemanager.rmnode.RMNodeImpl: Processing slave1:43282 of type STATUS_UPDATE
2019-06-07 08:04:53,156 DEBUG org.apache.hadoop.yarn.server.resourcemanager.scheduler.capacity.CapacityScheduler: nodeUpdate: slave1:43282 clusterResources: <memory:8192, vCores:2>
2019-06-07 08:04:53,156 DEBUG org.apache.hadoop.yarn.server.resourcemanager.scheduler.capacity.CapacityScheduler: nodeUpdate: slave1:43282 clusterResources: <memory:8192, vCores:2>
2019-06-07 08:04:53,156 DEBUG org.apache.hadoop.yarn.server.resourcemanager.scheduler.capacity.CapacityScheduler: Node being looked for scheduling slave1:43282 availableResource: <memory:4096, vCores:1>
2019-06-07 08:04:53,156 DEBUG org.apache.hadoop.yarn.server.resourcemanager.scheduler.capacity.CapacityScheduler: Node being looked for scheduling slave1:43282 availableResource: <memory:4096, vCores:1>
2019-06-07 08:04:53,156 DEBUG org.apache.hadoop.yarn.server.resourcemanager.scheduler.capacity.CapacityScheduler: Trying to schedule on node: slave1, available: <memory:4096, vCores:1>
2019-06-07 08:04:53,156 DEBUG org.apache.hadoop.yarn.server.resourcemanager.scheduler.capacity.CapacityScheduler: Trying to schedule on node: slave1, available: <memory:4096, vCores:1>
2019-06-07 08:04:53,156 DEBUG org.apache.hadoop.yarn.server.resourcemanager.scheduler.capacity.ParentQueue: Skip this queue=root, because it doesn't need more resource, schedulingMode=RESPECT_PARTITION_EXCLUSIVITY node-partition=
2019-06-07 08:04:53,156 DEBUG org.apache.hadoop.yarn.server.resourcemanager.scheduler.capacity.ParentQueue: Skip this queue=root, because it doesn't need more resource, schedulingMode=RESPECT_PARTITION_EXCLUSIVITY node-partition=
2019-06-07 08:04:54,151 DEBUG org.apache.hadoop.yarn.server.resourcemanager.rmnode.RMNodeImpl: Processing slave2:37804 of type STATUS_UPDATE
2019-06-07 08:04:54,151 DEBUG org.apache.hadoop.yarn.server.resourcemanager.rmnode.RMNodeImpl: Processing slave2:37804 of type STATUS_UPDATE
2019-06-07 08:04:54,152 DEBUG org.apache.hadoop.yarn.server.resourcemanager.scheduler.capacity.CapacityScheduler: nodeUpdate: slave2:37804 clusterResources: <memory:8192, vCores:2>
2019-06-07 08:04:54,152 DEBUG org.apache.hadoop.yarn.server.resourcemanager.scheduler.capacity.CapacityScheduler: nodeUpdate: slave2:37804 clusterResources: <memory:8192, vCores:2>
2019-06-07 08:04:54,153 DEBUG org.apache.hadoop.yarn.server.resourcemanager.scheduler.capacity.CapacityScheduler: Node being looked for scheduling slave2:37804 availableResource: <memory:4096, vCores:1>
2019-06-07 08:04:54,153 DEBUG org.apache.hadoop.yarn.server.resourcemanager.scheduler.capacity.CapacityScheduler: Node being looked for scheduling slave2:37804 availableResource: <memory:4096, vCores:1>
2019-06-07 08:04:54,153 DEBUG org.apache.hadoop.yarn.server.resourcemanager.scheduler.capacity.CapacityScheduler: Trying to schedule on node: slave2, available: <memory:4096, vCores:1>
2019-06-07 08:04:54,153 DEBUG org.apache.hadoop.yarn.server.resourcemanager.scheduler.capacity.CapacityScheduler: Trying to schedule on node: slave2, available: <memory:4096, vCores:1>
2019-06-07 08:04:54,153 DEBUG org.apache.hadoop.yarn.server.resourcemanager.scheduler.capacity.ParentQueue: Skip this queue=root, because it doesn't need more resource, schedulingMode=RESPECT_PARTITION_EXCLUSIVITY node-partition=
2019-06-07 08:04:54,153 DEBUG org.apache.hadoop.yarn.server.resourcemanager.scheduler.capacity.ParentQueue: Skip this queue=root, because it doesn't need more resource, schedulingMode=RESPECT_PARTITION_EXCLUSIVITY node-partition=
2019-06-07 08:04:54,159 DEBUG org.apache.hadoop.yarn.server.resourcemanager.rmnode.RMNodeImpl: Processing slave1:43282 of type STATUS_UPDATE
2019-06-07 08:04:54,159 DEBUG org.apache.hadoop.yarn.server.resourcemanager.rmnode.RMNodeImpl: Processing slave1:43282 of type STATUS_UPDATE
2019-06-07 08:04:54,161 DEBUG org.apache.hadoop.yarn.server.resourcemanager.scheduler.capacity.CapacityScheduler: nodeUpdate: slave1:43282 clusterResources: <memory:8192, vCores:2>
2019-06-07 08:04:54,161 DEBUG org.apache.hadoop.yarn.server.resourcemanager.scheduler.capacity.CapacityScheduler: nodeUpdate: slave1:43282 clusterResources: <memory:8192, vCores:2>
2019-06-07 08:04:54,161 DEBUG org.apache.hadoop.yarn.server.resourcemanager.scheduler.capacity.CapacityScheduler: Node being looked for scheduling slave1:43282 availableResource: <memory:4096, vCores:1>
2019-06-07 08:04:54,161 DEBUG org.apache.hadoop.yarn.server.resourcemanager.scheduler.capacity.CapacityScheduler: Node being looked for scheduling slave1:43282 availableResource: <memory:4096, vCores:1>
2019-06-07 08:04:54,161 DEBUG org.apache.hadoop.yarn.server.resourcemanager.scheduler.capacity.CapacityScheduler: Trying to schedule on node: slave1, available: <memory:4096, vCores:1>
2019-06-07 08:04:54,161 DEBUG org.apache.hadoop.yarn.server.resourcemanager.scheduler.capacity.CapacityScheduler: Trying to schedule on node: slave1, available: <memory:4096, vCores:1>
2019-06-07 08:04:54,161 DEBUG org.apache.hadoop.yarn.server.resourcemanager.scheduler.capacity.ParentQueue: Skip this queue=root, because it doesn't need more resource, schedulingMode=RESPECT_PARTITION_EXCLUSIVITY node-partition=
2019-06-07 08:04:54,161 DEBUG org.apache.hadoop.yarn.server.resourcemanager.scheduler.capacity.ParentQueue: Skip this queue=root, because it doesn't need more resource, schedulingMode=RESPECT_PARTITION_EXCLUSIVITY node-partition=
2019-06-07 08:04:55,156 DEBUG org.apache.hadoop.yarn.server.resourcemanager.rmnode.RMNodeImpl: Processing slave2:37804 of type STATUS_UPDATE
2019-06-07 08:04:55,156 DEBUG org.apache.hadoop.yarn.server.resourcemanager.rmnode.RMNodeImpl: Processing slave2:37804 of type STATUS_UPDATE
2019-06-07 08:04:55,157 DEBUG org.apache.hadoop.yarn.server.resourcemanager.scheduler.capacity.CapacityScheduler: nodeUpdate: slave2:37804 clusterResources: <memory:8192, vCores:2>
2019-06-07 08:04:55,157 DEBUG org.apache.hadoop.yarn.server.resourcemanager.scheduler.capacity.CapacityScheduler: nodeUpdate: slave2:37804 clusterResources: <memory:8192, vCores:2>
2019-06-07 08:04:55,157 DEBUG org.apache.hadoop.yarn.server.resourcemanager.scheduler.capacity.CapacityScheduler: Node being looked for scheduling slave2:37804 availableResource: <memory:4096, vCores:1>
2019-06-07 08:04:55,157 DEBUG org.apache.hadoop.yarn.server.resourcemanager.scheduler.capacity.CapacityScheduler: Node being looked for scheduling slave2:37804 availableResource: <memory:4096, vCores:1>
2019-06-07 08:04:55,158 DEBUG org.apache.hadoop.yarn.server.resourcemanager.scheduler.capacity.CapacityScheduler: Trying to schedule on node: slave2, available: <memory:4096, vCores:1>
2019-06-07 08:04:55,158 DEBUG org.apache.hadoop.yarn.server.resourcemanager.scheduler.capacity.CapacityScheduler: Trying to schedule on node: slave2, available: <memory:4096, vCores:1>
2019-06-07 08:04:55,158 DEBUG org.apache.hadoop.yarn.server.resourcemanager.scheduler.capacity.ParentQueue: Skip this queue=root, because it doesn't need more resource, schedulingMode=RESPECT_PARTITION_EXCLUSIVITY node-partition=
2019-06-07 08:04:55,158 DEBUG org.apache.hadoop.yarn.server.resourcemanager.scheduler.capacity.ParentQueue: Skip this queue=root, because it doesn't need more resource, schedulingMode=RESPECT_PARTITION_EXCLUSIVITY node-partition=
2019-06-07 08:04:55,163 DEBUG org.apache.hadoop.yarn.server.resourcemanager.rmnode.RMNodeImpl: Processing slave1:43282 of type STATUS_UPDATE
2019-06-07 08:04:55,163 DEBUG org.apache.hadoop.yarn.server.resourcemanager.rmnode.RMNodeImpl: Processing slave1:43282 of type STATUS_UPDATE
2019-06-07 08:04:55,164 DEBUG org.apache.hadoop.yarn.server.resourcemanager.scheduler.capacity.CapacityScheduler: nodeUpdate: slave1:43282 clusterResources: <memory:8192, vCores:2>
2019-06-07 08:04:55,164 DEBUG org.apache.hadoop.yarn.server.resourcemanager.scheduler.capacity.CapacityScheduler: nodeUpdate: slave1:43282 clusterResources: <memory:8192, vCores:2>
2019-06-07 08:04:55,165 DEBUG org.apache.hadoop.yarn.server.resourcemanager.scheduler.capacity.CapacityScheduler: Node being looked for scheduling slave1:43282 availableResource: <memory:4096, vCores:1>
2019-06-07 08:04:55,165 DEBUG org.apache.hadoop.yarn.server.resourcemanager.scheduler.capacity.CapacityScheduler: Node being looked for scheduling slave1:43282 availableResource: <memory:4096, vCores:1>
2019-06-07 08:04:55,165 DEBUG org.apache.hadoop.yarn.server.resourcemanager.scheduler.capacity.CapacityScheduler: Trying to schedule on node: slave1, available: <memory:4096, vCores:1>
2019-06-07 08:04:55,165 DEBUG org.apache.hadoop.yarn.server.resourcemanager.scheduler.capacity.CapacityScheduler: Trying to schedule on node: slave1, available: <memory:4096, vCores:1>
2019-06-07 08:04:55,165 DEBUG org.apache.hadoop.yarn.server.resourcemanager.scheduler.capacity.ParentQueue: Skip this queue=root, because it doesn't need more resource, schedulingMode=RESPECT_PARTITION_EXCLUSIVITY node-partition=
2019-06-07 08:04:55,165 DEBUG org.apache.hadoop.yarn.server.resourcemanager.scheduler.capacity.ParentQueue: Skip this queue=root, because it doesn't need more resource, schedulingMode=RESPECT_PARTITION_EXCLUSIVITY node-partition=
2019-06-07 08:04:56,160 DEBUG org.apache.hadoop.yarn.server.resourcemanager.rmnode.RMNodeImpl: Processing slave2:37804 of type STATUS_UPDATE
2019-06-07 08:04:56,160 DEBUG org.apache.hadoop.yarn.server.resourcemanager.rmnode.RMNodeImpl: Processing slave2:37804 of type STATUS_UPDATE
2019-06-07 08:04:56,162 DEBUG org.apache.hadoop.yarn.server.resourcemanager.scheduler.capacity.CapacityScheduler: nodeUpdate: slave2:37804 clusterResources: <memory:8192, vCores:2>
2019-06-07 08:04:56,162 DEBUG org.apache.hadoop.yarn.server.resourcemanager.scheduler.capacity.CapacityScheduler: nodeUpdate: slave2:37804 clusterResources: <memory:8192, vCores:2>
2019-06-07 08:04:56,162 DEBUG org.apache.hadoop.yarn.server.resourcemanager.scheduler.capacity.CapacityScheduler: Node being looked for scheduling slave2:37804 availableResource: <memory:4096, vCores:1>
2019-06-07 08:04:56,162 DEBUG org.apache.hadoop.yarn.server.resourcemanager.scheduler.capacity.CapacityScheduler: Node being looked for scheduling slave2:37804 availableResource: <memory:4096, vCores:1>
2019-06-07 08:04:56,162 DEBUG org.apache.hadoop.yarn.server.resourcemanager.scheduler.capacity.CapacityScheduler: Trying to schedule on node: slave2, available: <memory:4096, vCores:1>
2019-06-07 08:04:56,162 DEBUG org.apache.hadoop.yarn.server.resourcemanager.scheduler.capacity.CapacityScheduler: Trying to schedule on node: slave2, available: <memory:4096, vCores:1>
2019-06-07 08:04:56,163 DEBUG org.apache.hadoop.yarn.server.resourcemanager.scheduler.capacity.ParentQueue: Skip this queue=root, because it doesn't need more resource, schedulingMode=RESPECT_PARTITION_EXCLUSIVITY node-partition=
2019-06-07 08:04:56,163 DEBUG org.apache.hadoop.yarn.server.resourcemanager.scheduler.capacity.ParentQueue: Skip this queue=root, because it doesn't need more resource, schedulingMode=RESPECT_PARTITION_EXCLUSIVITY node-partition=
2019-06-07 08:04:56,167 DEBUG org.apache.hadoop.yarn.server.resourcemanager.rmnode.RMNodeImpl: Processing slave1:43282 of type STATUS_UPDATE
2019-06-07 08:04:56,167 DEBUG org.apache.hadoop.yarn.server.resourcemanager.rmnode.RMNodeImpl: Processing slave1:43282 of type STATUS_UPDATE
2019-06-07 08:04:56,168 DEBUG org.apache.hadoop.yarn.server.resourcemanager.scheduler.capacity.CapacityScheduler: nodeUpdate: slave1:43282 clusterResources: <memory:8192, vCores:2>
2019-06-07 08:04:56,168 DEBUG org.apache.hadoop.yarn.server.resourcemanager.scheduler.capacity.CapacityScheduler: nodeUpdate: slave1:43282 clusterResources: <memory:8192, vCores:2>
2019-06-07 08:04:56,168 DEBUG org.apache.hadoop.yarn.server.resourcemanager.scheduler.capacity.CapacityScheduler: Node being looked for scheduling slave1:43282 availableResource: <memory:4096, vCores:1>
2019-06-07 08:04:56,168 DEBUG org.apache.hadoop.yarn.server.resourcemanager.scheduler.capacity.CapacityScheduler: Node being looked for scheduling slave1:43282 availableResource: <memory:4096, vCores:1>
2019-06-07 08:04:56,168 DEBUG org.apache.hadoop.yarn.server.resourcemanager.scheduler.capacity.CapacityScheduler: Trying to schedule on node: slave1, available: <memory:4096, vCores:1>
2019-06-07 08:04:56,168 DEBUG org.apache.hadoop.yarn.server.resourcemanager.scheduler.capacity.CapacityScheduler: Trying to schedule on node: slave1, available: <memory:4096, vCores:1>
2019-06-07 08:04:56,168 DEBUG org.apache.hadoop.yarn.server.resourcemanager.scheduler.capacity.ParentQueue: Skip this queue=root, because it doesn't need more resource, schedulingMode=RESPECT_PARTITION_EXCLUSIVITY node-partition=
2019-06-07 08:04:56,168 DEBUG org.apache.hadoop.yarn.server.resourcemanager.scheduler.capacity.ParentQueue: Skip this queue=root, because it doesn't need more resource, schedulingMode=RESPECT_PARTITION_EXCLUSIVITY node-partition=
2019-06-07 08:04:57,173 DEBUG org.apache.hadoop.yarn.server.resourcemanager.rmnode.RMNodeImpl: Processing slave2:37804 of type STATUS_UPDATE
2019-06-07 08:04:57,173 DEBUG org.apache.hadoop.yarn.server.resourcemanager.rmnode.RMNodeImpl: Processing slave2:37804 of type STATUS_UPDATE
2019-06-07 08:04:57,173 DEBUG org.apache.hadoop.yarn.server.resourcemanager.rmnode.RMNodeImpl: Processing slave1:43282 of type STATUS_UPDATE
2019-06-07 08:04:57,173 DEBUG org.apache.hadoop.yarn.server.resourcemanager.rmnode.RMNodeImpl: Processing slave1:43282 of type STATUS_UPDATE
2019-06-07 08:04:57,183 DEBUG org.apache.hadoop.yarn.server.resourcemanager.scheduler.capacity.CapacityScheduler: nodeUpdate: slave2:37804 clusterResources: <memory:8192, vCores:2>
2019-06-07 08:04:57,183 DEBUG org.apache.hadoop.yarn.server.resourcemanager.scheduler.capacity.CapacityScheduler: nodeUpdate: slave2:37804 clusterResources: <memory:8192, vCores:2>
2019-06-07 08:04:57,183 DEBUG org.apache.hadoop.yarn.server.resourcemanager.scheduler.capacity.CapacityScheduler: Node being looked for scheduling slave2:37804 availableResource: <memory:4096, vCores:1>
2019-06-07 08:04:57,183 DEBUG org.apache.hadoop.yarn.server.resourcemanager.scheduler.capacity.CapacityScheduler: Node being looked for scheduling slave2:37804 availableResource: <memory:4096, vCores:1>
2019-06-07 08:04:57,183 DEBUG org.apache.hadoop.yarn.server.resourcemanager.scheduler.capacity.CapacityScheduler: Trying to schedule on node: slave2, available: <memory:4096, vCores:1>
2019-06-07 08:04:57,183 DEBUG org.apache.hadoop.yarn.server.resourcemanager.scheduler.capacity.CapacityScheduler: Trying to schedule on node: slave2, available: <memory:4096, vCores:1>
2019-06-07 08:04:57,183 DEBUG org.apache.hadoop.yarn.server.resourcemanager.scheduler.capacity.ParentQueue: Skip this queue=root, because it doesn't need more resource, schedulingMode=RESPECT_PARTITION_EXCLUSIVITY node-partition=
2019-06-07 08:04:57,183 DEBUG org.apache.hadoop.yarn.server.resourcemanager.scheduler.capacity.ParentQueue: Skip this queue=root, because it doesn't need more resource, schedulingMode=RESPECT_PARTITION_EXCLUSIVITY node-partition=
2019-06-07 08:04:57,183 DEBUG org.apache.hadoop.yarn.server.resourcemanager.scheduler.capacity.CapacityScheduler: nodeUpdate: slave1:43282 clusterResources: <memory:8192, vCores:2>
2019-06-07 08:04:57,183 DEBUG org.apache.hadoop.yarn.server.resourcemanager.scheduler.capacity.CapacityScheduler: nodeUpdate: slave1:43282 clusterResources: <memory:8192, vCores:2>
2019-06-07 08:04:57,183 DEBUG org.apache.hadoop.yarn.server.resourcemanager.scheduler.capacity.CapacityScheduler: Node being looked for scheduling slave1:43282 availableResource: <memory:4096, vCores:1>
2019-06-07 08:04:57,183 DEBUG org.apache.hadoop.yarn.server.resourcemanager.scheduler.capacity.CapacityScheduler: Node being looked for scheduling slave1:43282 availableResource: <memory:4096, vCores:1>
2019-06-07 08:04:57,183 DEBUG org.apache.hadoop.yarn.server.resourcemanager.scheduler.capacity.CapacityScheduler: Trying to schedule on node: slave1, available: <memory:4096, vCores:1>
2019-06-07 08:04:57,183 DEBUG org.apache.hadoop.yarn.server.resourcemanager.scheduler.capacity.CapacityScheduler: Trying to schedule on node: slave1, available: <memory:4096, vCores:1>
2019-06-07 08:04:57,183 DEBUG org.apache.hadoop.yarn.server.resourcemanager.scheduler.capacity.ParentQueue: Skip this queue=root, because it doesn't need more resource, schedulingMode=RESPECT_PARTITION_EXCLUSIVITY node-partition=
2019-06-07 08:04:57,183 DEBUG org.apache.hadoop.yarn.server.resourcemanager.scheduler.capacity.ParentQueue: Skip this queue=root, because it doesn't need more resource, schedulingMode=RESPECT_PARTITION_EXCLUSIVITY node-partition=
2019-06-07 08:04:58,181 DEBUG org.apache.hadoop.yarn.server.resourcemanager.rmnode.RMNodeImpl: Processing slave1:43282 of type STATUS_UPDATE
2019-06-07 08:04:58,181 DEBUG org.apache.hadoop.yarn.server.resourcemanager.rmnode.RMNodeImpl: Processing slave1:43282 of type STATUS_UPDATE
2019-06-07 08:04:58,182 DEBUG org.apache.hadoop.yarn.server.resourcemanager.scheduler.capacity.CapacityScheduler: nodeUpdate: slave1:43282 clusterResources: <memory:8192, vCores:2>
2019-06-07 08:04:58,182 DEBUG org.apache.hadoop.yarn.server.resourcemanager.scheduler.capacity.CapacityScheduler: nodeUpdate: slave1:43282 clusterResources: <memory:8192, vCores:2>
2019-06-07 08:04:58,182 DEBUG org.apache.hadoop.yarn.server.resourcemanager.scheduler.capacity.CapacityScheduler: Node being looked for scheduling slave1:43282 availableResource: <memory:4096, vCores:1>
2019-06-07 08:04:58,182 DEBUG org.apache.hadoop.yarn.server.resourcemanager.scheduler.capacity.CapacityScheduler: Node being looked for scheduling slave1:43282 availableResource: <memory:4096, vCores:1>
2019-06-07 08:04:58,182 DEBUG org.apache.hadoop.yarn.server.resourcemanager.scheduler.capacity.CapacityScheduler: Trying to schedule on node: slave1, available: <memory:4096, vCores:1>
2019-06-07 08:04:58,182 DEBUG org.apache.hadoop.yarn.server.resourcemanager.scheduler.capacity.CapacityScheduler: Trying to schedule on node: slave1, available: <memory:4096, vCores:1>
2019-06-07 08:04:58,182 DEBUG org.apache.hadoop.yarn.server.resourcemanager.scheduler.capacity.ParentQueue: Skip this queue=root, because it doesn't need more resource, schedulingMode=RESPECT_PARTITION_EXCLUSIVITY node-partition=
2019-06-07 08:04:58,182 DEBUG org.apache.hadoop.yarn.server.resourcemanager.scheduler.capacity.ParentQueue: Skip this queue=root, because it doesn't need more resource, schedulingMode=RESPECT_PARTITION_EXCLUSIVITY node-partition=
2019-06-07 08:04:58,190 DEBUG org.apache.hadoop.yarn.server.resourcemanager.rmnode.RMNodeImpl: Processing slave2:37804 of type STATUS_UPDATE
2019-06-07 08:04:58,190 DEBUG org.apache.hadoop.yarn.server.resourcemanager.rmnode.RMNodeImpl: Processing slave2:37804 of type STATUS_UPDATE
2019-06-07 08:04:58,191 DEBUG org.apache.hadoop.yarn.server.resourcemanager.scheduler.capacity.CapacityScheduler: nodeUpdate: slave2:37804 clusterResources: <memory:8192, vCores:2>
2019-06-07 08:04:58,191 DEBUG org.apache.hadoop.yarn.server.resourcemanager.scheduler.capacity.CapacityScheduler: nodeUpdate: slave2:37804 clusterResources: <memory:8192, vCores:2>
2019-06-07 08:04:58,191 DEBUG org.apache.hadoop.yarn.server.resourcemanager.scheduler.capacity.CapacityScheduler: Node being looked for scheduling slave2:37804 availableResource: <memory:4096, vCores:1>
2019-06-07 08:04:58,191 DEBUG org.apache.hadoop.yarn.server.resourcemanager.scheduler.capacity.CapacityScheduler: Node being looked for scheduling slave2:37804 availableResource: <memory:4096, vCores:1>
2019-06-07 08:04:58,191 DEBUG org.apache.hadoop.yarn.server.resourcemanager.scheduler.capacity.CapacityScheduler: Trying to schedule on node: slave2, available: <memory:4096, vCores:1>
2019-06-07 08:04:58,191 DEBUG org.apache.hadoop.yarn.server.resourcemanager.scheduler.capacity.CapacityScheduler: Trying to schedule on node: slave2, available: <memory:4096, vCores:1>
2019-06-07 08:04:58,191 DEBUG org.apache.hadoop.yarn.server.resourcemanager.scheduler.capacity.ParentQueue: Skip this queue=root, because it doesn't need more resource, schedulingMode=RESPECT_PARTITION_EXCLUSIVITY node-partition=
2019-06-07 08:04:58,191 DEBUG org.apache.hadoop.yarn.server.resourcemanager.scheduler.capacity.ParentQueue: Skip this queue=root, because it doesn't need more resource, schedulingMode=RESPECT_PARTITION_EXCLUSIVITY node-partition=
2019-06-07 08:04:59,184 DEBUG org.apache.hadoop.yarn.server.resourcemanager.rmnode.RMNodeImpl: Processing slave1:43282 of type STATUS_UPDATE
2019-06-07 08:04:59,184 DEBUG org.apache.hadoop.yarn.server.resourcemanager.rmnode.RMNodeImpl: Processing slave1:43282 of type STATUS_UPDATE
2019-06-07 08:04:59,186 DEBUG org.apache.hadoop.yarn.server.resourcemanager.scheduler.capacity.CapacityScheduler: nodeUpdate: slave1:43282 clusterResources: <memory:8192, vCores:2>
2019-06-07 08:04:59,186 DEBUG org.apache.hadoop.yarn.server.resourcemanager.scheduler.capacity.CapacityScheduler: nodeUpdate: slave1:43282 clusterResources: <memory:8192, vCores:2>
2019-06-07 08:04:59,187 DEBUG org.apache.hadoop.yarn.server.resourcemanager.scheduler.capacity.CapacityScheduler: Node being looked for scheduling slave1:43282 availableResource: <memory:4096, vCores:1>
2019-06-07 08:04:59,187 DEBUG org.apache.hadoop.yarn.server.resourcemanager.scheduler.capacity.CapacityScheduler: Node being looked for scheduling slave1:43282 availableResource: <memory:4096, vCores:1>
2019-06-07 08:04:59,187 DEBUG org.apache.hadoop.yarn.server.resourcemanager.scheduler.capacity.CapacityScheduler: Trying to schedule on node: slave1, available: <memory:4096, vCores:1>
2019-06-07 08:04:59,187 DEBUG org.apache.hadoop.yarn.server.resourcemanager.scheduler.capacity.CapacityScheduler: Trying to schedule on node: slave1, available: <memory:4096, vCores:1>
2019-06-07 08:04:59,187 DEBUG org.apache.hadoop.yarn.server.resourcemanager.scheduler.capacity.ParentQueue: Skip this queue=root, because it doesn't need more resource, schedulingMode=RESPECT_PARTITION_EXCLUSIVITY node-partition=
2019-06-07 08:04:59,187 DEBUG org.apache.hadoop.yarn.server.resourcemanager.scheduler.capacity.ParentQueue: Skip this queue=root, because it doesn't need more resource, schedulingMode=RESPECT_PARTITION_EXCLUSIVITY node-partition=
2019-06-07 08:04:59,192 DEBUG org.apache.hadoop.yarn.server.resourcemanager.rmnode.RMNodeImpl: Processing slave2:37804 of type STATUS_UPDATE
2019-06-07 08:04:59,192 DEBUG org.apache.hadoop.yarn.server.resourcemanager.rmnode.RMNodeImpl: Processing slave2:37804 of type STATUS_UPDATE
2019-06-07 08:04:59,192 DEBUG org.apache.hadoop.yarn.server.resourcemanager.scheduler.capacity.CapacityScheduler: nodeUpdate: slave2:37804 clusterResources: <memory:8192, vCores:2>
2019-06-07 08:04:59,192 DEBUG org.apache.hadoop.yarn.server.resourcemanager.scheduler.capacity.CapacityScheduler: nodeUpdate: slave2:37804 clusterResources: <memory:8192, vCores:2>
2019-06-07 08:04:59,193 DEBUG org.apache.hadoop.yarn.server.resourcemanager.scheduler.capacity.CapacityScheduler: Node being looked for scheduling slave2:37804 availableResource: <memory:4096, vCores:1>
2019-06-07 08:04:59,193 DEBUG org.apache.hadoop.yarn.server.resourcemanager.scheduler.capacity.CapacityScheduler: Node being looked for scheduling slave2:37804 availableResource: <memory:4096, vCores:1>
2019-06-07 08:04:59,193 DEBUG org.apache.hadoop.yarn.server.resourcemanager.scheduler.capacity.CapacityScheduler: Trying to schedule on node: slave2, available: <memory:4096, vCores:1>
2019-06-07 08:04:59,193 DEBUG org.apache.hadoop.yarn.server.resourcemanager.scheduler.capacity.CapacityScheduler: Trying to schedule on node: slave2, available: <memory:4096, vCores:1>
2019-06-07 08:04:59,193 DEBUG org.apache.hadoop.yarn.server.resourcemanager.scheduler.capacity.ParentQueue: Skip this queue=root, because it doesn't need more resource, schedulingMode=RESPECT_PARTITION_EXCLUSIVITY node-partition=
2019-06-07 08:04:59,193 DEBUG org.apache.hadoop.yarn.server.resourcemanager.scheduler.capacity.ParentQueue: Skip this queue=root, because it doesn't need more resource, schedulingMode=RESPECT_PARTITION_EXCLUSIVITY node-partition=
2019-06-07 08:05:00,188 DEBUG org.apache.hadoop.yarn.server.resourcemanager.rmnode.RMNodeImpl: Processing slave1:43282 of type STATUS_UPDATE
2019-06-07 08:05:00,188 DEBUG org.apache.hadoop.yarn.server.resourcemanager.rmnode.RMNodeImpl: Processing slave1:43282 of type STATUS_UPDATE
2019-06-07 08:05:00,188 DEBUG org.apache.hadoop.yarn.server.resourcemanager.scheduler.capacity.CapacityScheduler: nodeUpdate: slave1:43282 clusterResources: <memory:8192, vCores:2>
2019-06-07 08:05:00,188 DEBUG org.apache.hadoop.yarn.server.resourcemanager.scheduler.capacity.CapacityScheduler: nodeUpdate: slave1:43282 clusterResources: <memory:8192, vCores:2>
2019-06-07 08:05:00,188 DEBUG org.apache.hadoop.yarn.server.resourcemanager.scheduler.capacity.CapacityScheduler: Node being looked for scheduling slave1:43282 availableResource: <memory:4096, vCores:1>
2019-06-07 08:05:00,188 DEBUG org.apache.hadoop.yarn.server.resourcemanager.scheduler.capacity.CapacityScheduler: Node being looked for scheduling slave1:43282 availableResource: <memory:4096, vCores:1>
2019-06-07 08:05:00,189 DEBUG org.apache.hadoop.yarn.server.resourcemanager.scheduler.capacity.CapacityScheduler: Trying to schedule on node: slave1, available: <memory:4096, vCores:1>
2019-06-07 08:05:00,189 DEBUG org.apache.hadoop.yarn.server.resourcemanager.scheduler.capacity.CapacityScheduler: Trying to schedule on node: slave1, available: <memory:4096, vCores:1>
2019-06-07 08:05:00,189 DEBUG org.apache.hadoop.yarn.server.resourcemanager.scheduler.capacity.ParentQueue: Skip this queue=root, because it doesn't need more resource, schedulingMode=RESPECT_PARTITION_EXCLUSIVITY node-partition=
2019-06-07 08:05:00,189 DEBUG org.apache.hadoop.yarn.server.resourcemanager.scheduler.capacity.ParentQueue: Skip this queue=root, because it doesn't need more resource, schedulingMode=RESPECT_PARTITION_EXCLUSIVITY node-partition=
2019-06-07 08:05:00,195 DEBUG org.apache.hadoop.yarn.server.resourcemanager.rmnode.RMNodeImpl: Processing slave2:37804 of type STATUS_UPDATE
2019-06-07 08:05:00,195 DEBUG org.apache.hadoop.yarn.server.resourcemanager.rmnode.RMNodeImpl: Processing slave2:37804 of type STATUS_UPDATE
2019-06-07 08:05:00,196 DEBUG org.apache.hadoop.yarn.server.resourcemanager.scheduler.capacity.CapacityScheduler: nodeUpdate: slave2:37804 clusterResources: <memory:8192, vCores:2>
2019-06-07 08:05:00,196 DEBUG org.apache.hadoop.yarn.server.resourcemanager.scheduler.capacity.CapacityScheduler: nodeUpdate: slave2:37804 clusterResources: <memory:8192, vCores:2>
2019-06-07 08:05:00,196 DEBUG org.apache.hadoop.yarn.server.resourcemanager.scheduler.capacity.CapacityScheduler: Node being looked for scheduling slave2:37804 availableResource: <memory:4096, vCores:1>
2019-06-07 08:05:00,196 DEBUG org.apache.hadoop.yarn.server.resourcemanager.scheduler.capacity.CapacityScheduler: Node being looked for scheduling slave2:37804 availableResource: <memory:4096, vCores:1>
2019-06-07 08:05:00,196 DEBUG org.apache.hadoop.yarn.server.resourcemanager.scheduler.capacity.CapacityScheduler: Trying to schedule on node: slave2, available: <memory:4096, vCores:1>
2019-06-07 08:05:00,196 DEBUG org.apache.hadoop.yarn.server.resourcemanager.scheduler.capacity.CapacityScheduler: Trying to schedule on node: slave2, available: <memory:4096, vCores:1>
2019-06-07 08:05:00,196 DEBUG org.apache.hadoop.yarn.server.resourcemanager.scheduler.capacity.ParentQueue: Skip this queue=root, because it doesn't need more resource, schedulingMode=RESPECT_PARTITION_EXCLUSIVITY node-partition=
2019-06-07 08:05:00,196 DEBUG org.apache.hadoop.yarn.server.resourcemanager.scheduler.capacity.ParentQueue: Skip this queue=root, because it doesn't need more resource, schedulingMode=RESPECT_PARTITION_EXCLUSIVITY node-partition=
2019-06-07 08:05:01,192 DEBUG org.apache.hadoop.yarn.server.resourcemanager.rmnode.RMNodeImpl: Processing slave1:43282 of type STATUS_UPDATE
2019-06-07 08:05:01,192 DEBUG org.apache.hadoop.yarn.server.resourcemanager.rmnode.RMNodeImpl: Processing slave1:43282 of type STATUS_UPDATE
2019-06-07 08:05:01,193 DEBUG org.apache.hadoop.yarn.server.resourcemanager.scheduler.capacity.CapacityScheduler: nodeUpdate: slave1:43282 clusterResources: <memory:8192, vCores:2>
2019-06-07 08:05:01,193 DEBUG org.apache.hadoop.yarn.server.resourcemanager.scheduler.capacity.CapacityScheduler: nodeUpdate: slave1:43282 clusterResources: <memory:8192, vCores:2>
2019-06-07 08:05:01,193 DEBUG org.apache.hadoop.yarn.server.resourcemanager.scheduler.capacity.CapacityScheduler: Node being looked for scheduling slave1:43282 availableResource: <memory:4096, vCores:1>
2019-06-07 08:05:01,193 DEBUG org.apache.hadoop.yarn.server.resourcemanager.scheduler.capacity.CapacityScheduler: Node being looked for scheduling slave1:43282 availableResource: <memory:4096, vCores:1>
2019-06-07 08:05:01,193 DEBUG org.apache.hadoop.yarn.server.resourcemanager.scheduler.capacity.CapacityScheduler: Trying to schedule on node: slave1, available: <memory:4096, vCores:1>
2019-06-07 08:05:01,193 DEBUG org.apache.hadoop.yarn.server.resourcemanager.scheduler.capacity.CapacityScheduler: Trying to schedule on node: slave1, available: <memory:4096, vCores:1>
2019-06-07 08:05:01,193 DEBUG org.apache.hadoop.yarn.server.resourcemanager.scheduler.capacity.ParentQueue: Skip this queue=root, because it doesn't need more resource, schedulingMode=RESPECT_PARTITION_EXCLUSIVITY node-partition=
2019-06-07 08:05:01,193 DEBUG org.apache.hadoop.yarn.server.resourcemanager.scheduler.capacity.ParentQueue: Skip this queue=root, because it doesn't need more resource, schedulingMode=RESPECT_PARTITION_EXCLUSIVITY node-partition=
2019-06-07 08:05:01,201 DEBUG org.apache.hadoop.yarn.server.resourcemanager.rmnode.RMNodeImpl: Processing slave2:37804 of type STATUS_UPDATE
2019-06-07 08:05:01,201 DEBUG org.apache.hadoop.yarn.server.resourcemanager.rmnode.RMNodeImpl: Processing slave2:37804 of type STATUS_UPDATE
2019-06-07 08:05:01,203 DEBUG org.apache.hadoop.yarn.server.resourcemanager.scheduler.capacity.CapacityScheduler: nodeUpdate: slave2:37804 clusterResources: <memory:8192, vCores:2>
2019-06-07 08:05:01,203 DEBUG org.apache.hadoop.yarn.server.resourcemanager.scheduler.capacity.CapacityScheduler: nodeUpdate: slave2:37804 clusterResources: <memory:8192, vCores:2>
2019-06-07 08:05:01,203 DEBUG org.apache.hadoop.yarn.server.resourcemanager.scheduler.capacity.CapacityScheduler: Node being looked for scheduling slave2:37804 availableResource: <memory:4096, vCores:1>
2019-06-07 08:05:01,203 DEBUG org.apache.hadoop.yarn.server.resourcemanager.scheduler.capacity.CapacityScheduler: Node being looked for scheduling slave2:37804 availableResource: <memory:4096, vCores:1>
2019-06-07 08:05:01,203 DEBUG org.apache.hadoop.yarn.server.resourcemanager.scheduler.capacity.CapacityScheduler: Trying to schedule on node: slave2, available: <memory:4096, vCores:1>
2019-06-07 08:05:01,203 DEBUG org.apache.hadoop.yarn.server.resourcemanager.scheduler.capacity.CapacityScheduler: Trying to schedule on node: slave2, available: <memory:4096, vCores:1>
2019-06-07 08:05:01,203 DEBUG org.apache.hadoop.yarn.server.resourcemanager.scheduler.capacity.ParentQueue: Skip this queue=root, because it doesn't need more resource, schedulingMode=RESPECT_PARTITION_EXCLUSIVITY node-partition=
2019-06-07 08:05:01,203 DEBUG org.apache.hadoop.yarn.server.resourcemanager.scheduler.capacity.ParentQueue: Skip this queue=root, because it doesn't need more resource, schedulingMode=RESPECT_PARTITION_EXCLUSIVITY node-partition=
2019-06-07 08:05:02,119 INFO org.apache.hadoop.yarn.server.resourcemanager.scheduler.capacity.CapacityScheduler: Application 'application_1559894680121_0001' is submitted without priority hence considering default queue/cluster priority: 0
2019-06-07 08:05:02,119 INFO org.apache.hadoop.yarn.server.resourcemanager.scheduler.capacity.CapacityScheduler: Application 'application_1559894680121_0001' is submitted without priority hence considering default queue/cluster priority: 0
2019-06-07 08:05:02,119 INFO org.apache.hadoop.yarn.server.resourcemanager.scheduler.capacity.CapacityScheduler: Priority '0' is acceptable in queue : default for application: application_1559894680121_0001 for the user: root
2019-06-07 08:05:02,119 INFO org.apache.hadoop.yarn.server.resourcemanager.scheduler.capacity.CapacityScheduler: Priority '0' is acceptable in queue : default for application: application_1559894680121_0001 for the user: root
2019-06-07 08:05:02,159 WARN org.apache.hadoop.yarn.server.resourcemanager.rmapp.RMAppImpl: The specific max attempts: 0 for application: 1 is invalid, because it is out of the range [1, 2]. Use the global max attempts instead.
2019-06-07 08:05:02,159 WARN org.apache.hadoop.yarn.server.resourcemanager.rmapp.RMAppImpl: The specific max attempts: 0 for application: 1 is invalid, because it is out of the range [1, 2]. Use the global max attempts instead.
2019-06-07 08:05:02,165 DEBUG org.apache.hadoop.yarn.server.resourcemanager.rmapp.RMAppImpl: Processing event for application_1559894680121_0001 of type START
2019-06-07 08:05:02,165 DEBUG org.apache.hadoop.yarn.server.resourcemanager.rmapp.RMAppImpl: Processing event for application_1559894680121_0001 of type START
2019-06-07 08:05:02,165 INFO org.apache.hadoop.yarn.server.resourcemanager.rmapp.RMAppImpl: Storing application with id application_1559894680121_0001
2019-06-07 08:05:02,165 INFO org.apache.hadoop.yarn.server.resourcemanager.rmapp.RMAppImpl: Storing application with id application_1559894680121_0001
2019-06-07 08:05:02,166 INFO org.apache.hadoop.yarn.server.resourcemanager.ClientRMService: Application with id 1 submitted by user root
2019-06-07 08:05:02,166 INFO org.apache.hadoop.yarn.server.resourcemanager.ClientRMService: Application with id 1 submitted by user root
2019-06-07 08:05:02,168 INFO org.apache.hadoop.yarn.server.resourcemanager.RMAuditLogger: USER=root	IP=172.17.0.2	OPERATION=Submit Application Request	TARGET=ClientRMService	RESULT=SUCCESS	APPID=application_1559894680121_0001
2019-06-07 08:05:02,168 INFO org.apache.hadoop.yarn.server.resourcemanager.RMAuditLogger: USER=root	IP=172.17.0.2	OPERATION=Submit Application Request	TARGET=ClientRMService	RESULT=SUCCESS	APPID=application_1559894680121_0001
2019-06-07 08:05:02,171 INFO org.apache.hadoop.yarn.server.resourcemanager.rmapp.RMAppImpl: application_1559894680121_0001 State change from NEW to NEW_SAVING on event=START
2019-06-07 08:05:02,171 INFO org.apache.hadoop.yarn.server.resourcemanager.rmapp.RMAppImpl: application_1559894680121_0001 State change from NEW to NEW_SAVING on event=START
2019-06-07 08:05:02,171 DEBUG org.apache.hadoop.yarn.server.resourcemanager.recovery.RMStateStore: Processing event of type STORE_APP
2019-06-07 08:05:02,171 DEBUG org.apache.hadoop.yarn.server.resourcemanager.recovery.RMStateStore: Processing event of type STORE_APP
2019-06-07 08:05:02,171 INFO org.apache.hadoop.yarn.server.resourcemanager.recovery.RMStateStore: Storing info for app: application_1559894680121_0001
2019-06-07 08:05:02,171 INFO org.apache.hadoop.yarn.server.resourcemanager.recovery.RMStateStore: Storing info for app: application_1559894680121_0001
2019-06-07 08:05:02,172 DEBUG org.apache.hadoop.yarn.server.resourcemanager.rmapp.RMAppImpl: Processing event for application_1559894680121_0001 of type APP_NEW_SAVED
2019-06-07 08:05:02,172 DEBUG org.apache.hadoop.yarn.server.resourcemanager.rmapp.RMAppImpl: Processing event for application_1559894680121_0001 of type APP_NEW_SAVED
2019-06-07 08:05:02,195 INFO org.apache.hadoop.yarn.server.resourcemanager.rmapp.RMAppImpl: application_1559894680121_0001 State change from NEW_SAVING to SUBMITTED on event=APP_NEW_SAVED
2019-06-07 08:05:02,195 INFO org.apache.hadoop.yarn.server.resourcemanager.rmapp.RMAppImpl: application_1559894680121_0001 State change from NEW_SAVING to SUBMITTED on event=APP_NEW_SAVED
2019-06-07 08:05:02,198 INFO org.apache.hadoop.yarn.server.resourcemanager.scheduler.capacity.ParentQueue: Application added - appId: application_1559894680121_0001 user: root leaf-queue of parent: root #applications: 1
2019-06-07 08:05:02,198 INFO org.apache.hadoop.yarn.server.resourcemanager.scheduler.capacity.ParentQueue: Application added - appId: application_1559894680121_0001 user: root leaf-queue of parent: root #applications: 1
2019-06-07 08:05:02,199 INFO org.apache.hadoop.yarn.server.resourcemanager.scheduler.capacity.CapacityScheduler: Accepted application application_1559894680121_0001 from user: root, in queue: default
2019-06-07 08:05:02,199 INFO org.apache.hadoop.yarn.server.resourcemanager.scheduler.capacity.CapacityScheduler: Accepted application application_1559894680121_0001 from user: root, in queue: default
2019-06-07 08:05:02,205 DEBUG org.apache.hadoop.yarn.server.resourcemanager.rmnode.RMNodeImpl: Processing slave1:43282 of type STATUS_UPDATE
2019-06-07 08:05:02,205 DEBUG org.apache.hadoop.yarn.server.resourcemanager.rmnode.RMNodeImpl: Processing slave1:43282 of type STATUS_UPDATE
2019-06-07 08:05:02,217 DEBUG org.apache.hadoop.yarn.server.resourcemanager.rmapp.RMAppImpl: Processing event for application_1559894680121_0001 of type APP_ACCEPTED
2019-06-07 08:05:02,217 DEBUG org.apache.hadoop.yarn.server.resourcemanager.rmapp.RMAppImpl: Processing event for application_1559894680121_0001 of type APP_ACCEPTED
2019-06-07 08:05:02,233 INFO org.apache.hadoop.yarn.server.resourcemanager.rmapp.RMAppImpl: application_1559894680121_0001 State change from SUBMITTED to ACCEPTED on event=APP_ACCEPTED
2019-06-07 08:05:02,233 INFO org.apache.hadoop.yarn.server.resourcemanager.rmapp.RMAppImpl: application_1559894680121_0001 State change from SUBMITTED to ACCEPTED on event=APP_ACCEPTED
2019-06-07 08:05:02,233 DEBUG org.apache.hadoop.yarn.server.resourcemanager.rmnode.RMNodeImpl: Processing slave2:37804 of type STATUS_UPDATE
2019-06-07 08:05:02,233 DEBUG org.apache.hadoop.yarn.server.resourcemanager.rmnode.RMNodeImpl: Processing slave2:37804 of type STATUS_UPDATE
2019-06-07 08:05:02,233 DEBUG org.apache.hadoop.yarn.server.resourcemanager.scheduler.capacity.CapacityScheduler: nodeUpdate: slave1:43282 clusterResources: <memory:8192, vCores:2>
2019-06-07 08:05:02,233 DEBUG org.apache.hadoop.yarn.server.resourcemanager.scheduler.capacity.CapacityScheduler: nodeUpdate: slave1:43282 clusterResources: <memory:8192, vCores:2>
2019-06-07 08:05:02,233 DEBUG org.apache.hadoop.yarn.server.resourcemanager.scheduler.capacity.CapacityScheduler: Node being looked for scheduling slave1:43282 availableResource: <memory:4096, vCores:1>
2019-06-07 08:05:02,233 DEBUG org.apache.hadoop.yarn.server.resourcemanager.scheduler.capacity.CapacityScheduler: Node being looked for scheduling slave1:43282 availableResource: <memory:4096, vCores:1>
2019-06-07 08:05:02,233 DEBUG org.apache.hadoop.yarn.server.resourcemanager.scheduler.capacity.CapacityScheduler: Trying to schedule on node: slave1, available: <memory:4096, vCores:1>
2019-06-07 08:05:02,233 DEBUG org.apache.hadoop.yarn.server.resourcemanager.scheduler.capacity.CapacityScheduler: Trying to schedule on node: slave1, available: <memory:4096, vCores:1>
2019-06-07 08:05:02,233 DEBUG org.apache.hadoop.yarn.server.resourcemanager.scheduler.capacity.ParentQueue: Skip this queue=root, because it doesn't need more resource, schedulingMode=RESPECT_PARTITION_EXCLUSIVITY node-partition=
2019-06-07 08:05:02,233 DEBUG org.apache.hadoop.yarn.server.resourcemanager.scheduler.capacity.ParentQueue: Skip this queue=root, because it doesn't need more resource, schedulingMode=RESPECT_PARTITION_EXCLUSIVITY node-partition=
2019-06-07 08:05:02,234 DEBUG org.apache.hadoop.yarn.server.resourcemanager.rmapp.attempt.RMAppAttemptImpl: Processing event for appattempt_1559894680121_0001_000001 of type START
2019-06-07 08:05:02,234 DEBUG org.apache.hadoop.yarn.server.resourcemanager.rmapp.attempt.RMAppAttemptImpl: Processing event for appattempt_1559894680121_0001_000001 of type START
2019-06-07 08:05:02,255 INFO org.apache.hadoop.yarn.server.resourcemanager.ApplicationMasterService: Registering app attempt : appattempt_1559894680121_0001_000001
2019-06-07 08:05:02,255 INFO org.apache.hadoop.yarn.server.resourcemanager.ApplicationMasterService: Registering app attempt : appattempt_1559894680121_0001_000001
2019-06-07 08:05:02,256 INFO org.apache.hadoop.yarn.server.resourcemanager.rmapp.attempt.RMAppAttemptImpl: appattempt_1559894680121_0001_000001 State change from NEW to SUBMITTED
2019-06-07 08:05:02,256 INFO org.apache.hadoop.yarn.server.resourcemanager.rmapp.attempt.RMAppAttemptImpl: appattempt_1559894680121_0001_000001 State change from NEW to SUBMITTED
2019-06-07 08:05:02,256 DEBUG org.apache.hadoop.yarn.server.resourcemanager.scheduler.capacity.CapacityScheduler: nodeUpdate: slave2:37804 clusterResources: <memory:8192, vCores:2>
2019-06-07 08:05:02,256 DEBUG org.apache.hadoop.yarn.server.resourcemanager.scheduler.capacity.CapacityScheduler: nodeUpdate: slave2:37804 clusterResources: <memory:8192, vCores:2>
2019-06-07 08:05:02,256 DEBUG org.apache.hadoop.yarn.server.resourcemanager.scheduler.capacity.CapacityScheduler: Node being looked for scheduling slave2:37804 availableResource: <memory:4096, vCores:1>
2019-06-07 08:05:02,256 DEBUG org.apache.hadoop.yarn.server.resourcemanager.scheduler.capacity.CapacityScheduler: Node being looked for scheduling slave2:37804 availableResource: <memory:4096, vCores:1>
2019-06-07 08:05:02,256 DEBUG org.apache.hadoop.yarn.server.resourcemanager.scheduler.capacity.CapacityScheduler: Trying to schedule on node: slave2, available: <memory:4096, vCores:1>
2019-06-07 08:05:02,256 DEBUG org.apache.hadoop.yarn.server.resourcemanager.scheduler.capacity.CapacityScheduler: Trying to schedule on node: slave2, available: <memory:4096, vCores:1>
2019-06-07 08:05:02,256 DEBUG org.apache.hadoop.yarn.server.resourcemanager.scheduler.capacity.ParentQueue: Skip this queue=root, because it doesn't need more resource, schedulingMode=RESPECT_PARTITION_EXCLUSIVITY node-partition=
2019-06-07 08:05:02,256 DEBUG org.apache.hadoop.yarn.server.resourcemanager.scheduler.capacity.ParentQueue: Skip this queue=root, because it doesn't need more resource, schedulingMode=RESPECT_PARTITION_EXCLUSIVITY node-partition=
2019-06-07 08:05:02,282 DEBUG org.apache.hadoop.yarn.server.resourcemanager.scheduler.capacity.LeafQueue: application application_1559894680121_0001 AMResource <memory:1024, vCores:1> maxAMResourcePerQueuePercent 0.1 amLimit <memory:1024, vCores:1> lastClusterResource <memory:8192, vCores:2> amIfStarted <memory:1024, vCores:1> AM node-partition name 
2019-06-07 08:05:02,282 DEBUG org.apache.hadoop.yarn.server.resourcemanager.scheduler.capacity.LeafQueue: application application_1559894680121_0001 AMResource <memory:1024, vCores:1> maxAMResourcePerQueuePercent 0.1 amLimit <memory:1024, vCores:1> lastClusterResource <memory:8192, vCores:2> amIfStarted <memory:1024, vCores:1> AM node-partition name 
2019-06-07 08:05:02,282 DEBUG org.apache.hadoop.yarn.server.resourcemanager.scheduler.capacity.LeafQueue: Effective user AM limit for "root":<memory:1024, vCores:1>. Effective weighted user AM limit: <memory:1024, vCores:1>. User weight: 1.0
2019-06-07 08:05:02,282 DEBUG org.apache.hadoop.yarn.server.resourcemanager.scheduler.capacity.LeafQueue: Effective user AM limit for "root":<memory:1024, vCores:1>. Effective weighted user AM limit: <memory:1024, vCores:1>. User weight: 1.0
2019-06-07 08:05:02,286 INFO org.apache.hadoop.yarn.server.resourcemanager.scheduler.capacity.LeafQueue: Application application_1559894680121_0001 from user: root activated in queue: default
2019-06-07 08:05:02,286 INFO org.apache.hadoop.yarn.server.resourcemanager.scheduler.capacity.LeafQueue: Application application_1559894680121_0001 from user: root activated in queue: default
2019-06-07 08:05:02,286 INFO org.apache.hadoop.yarn.server.resourcemanager.scheduler.capacity.LeafQueue: Application added - appId: application_1559894680121_0001 user: root, leaf-queue: default #user-pending-applications: 0 #user-active-applications: 1 #queue-pending-applications: 0 #queue-active-applications: 1
2019-06-07 08:05:02,286 INFO org.apache.hadoop.yarn.server.resourcemanager.scheduler.capacity.LeafQueue: Application added - appId: application_1559894680121_0001 user: root, leaf-queue: default #user-pending-applications: 0 #user-active-applications: 1 #queue-pending-applications: 0 #queue-active-applications: 1
2019-06-07 08:05:02,286 INFO org.apache.hadoop.yarn.server.resourcemanager.scheduler.capacity.CapacityScheduler: Added Application Attempt appattempt_1559894680121_0001_000001 to scheduler from user root in queue default
2019-06-07 08:05:02,286 INFO org.apache.hadoop.yarn.server.resourcemanager.scheduler.capacity.CapacityScheduler: Added Application Attempt appattempt_1559894680121_0001_000001 to scheduler from user root in queue default
2019-06-07 08:05:02,286 DEBUG org.apache.hadoop.yarn.server.resourcemanager.rmapp.attempt.RMAppAttemptImpl: Processing event for appattempt_1559894680121_0001_000001 of type ATTEMPT_ADDED
2019-06-07 08:05:02,286 DEBUG org.apache.hadoop.yarn.server.resourcemanager.rmapp.attempt.RMAppAttemptImpl: Processing event for appattempt_1559894680121_0001_000001 of type ATTEMPT_ADDED
2019-06-07 08:05:02,287 DEBUG org.apache.hadoop.yarn.server.resourcemanager.rmapp.attempt.RMAppAttemptImpl: Using blacklist for AM: additions([]) and removals([])
2019-06-07 08:05:02,287 DEBUG org.apache.hadoop.yarn.server.resourcemanager.rmapp.attempt.RMAppAttemptImpl: Using blacklist for AM: additions([]) and removals([])
2019-06-07 08:05:02,288 DEBUG org.apache.hadoop.yarn.server.resourcemanager.scheduler.capacity.CapacityScheduler: allocate: pre-update appattempt_1559894680121_0001_000001 ask size =1
2019-06-07 08:05:02,288 DEBUG org.apache.hadoop.yarn.server.resourcemanager.scheduler.capacity.CapacityScheduler: allocate: pre-update appattempt_1559894680121_0001_000001 ask size =1
2019-06-07 08:05:02,289 DEBUG org.apache.hadoop.yarn.server.resourcemanager.scheduler.ActiveUsersManager: User root added to activeUsers, currently: 1
2019-06-07 08:05:02,289 DEBUG org.apache.hadoop.yarn.server.resourcemanager.scheduler.ActiveUsersManager: User root added to activeUsers, currently: 1
2019-06-07 08:05:02,289 DEBUG org.apache.hadoop.yarn.server.resourcemanager.scheduler.capacity.CapacityScheduler: allocate: post-update
2019-06-07 08:05:02,289 DEBUG org.apache.hadoop.yarn.server.resourcemanager.scheduler.capacity.CapacityScheduler: allocate: post-update
2019-06-07 08:05:02,289 DEBUG org.apache.hadoop.yarn.server.resourcemanager.scheduler.SchedulerApplicationAttempt: showRequests: application=application_1559894680121_0001 headRoom=<memory:0, vCores:0> currentConsumption=0
2019-06-07 08:05:02,289 DEBUG org.apache.hadoop.yarn.server.resourcemanager.scheduler.SchedulerApplicationAttempt: showRequests: application=application_1559894680121_0001 headRoom=<memory:0, vCores:0> currentConsumption=0
2019-06-07 08:05:02,289 DEBUG org.apache.hadoop.yarn.server.resourcemanager.scheduler.SchedulerApplicationAttempt: showRequests: application=application_1559894680121_0001 request={Priority: 0, Capability: <memory:1024, vCores:1>, # Containers: 1, Location: *, Relax Locality: true, Node Label Expression: }
2019-06-07 08:05:02,289 DEBUG org.apache.hadoop.yarn.server.resourcemanager.scheduler.SchedulerApplicationAttempt: showRequests: application=application_1559894680121_0001 request={Priority: 0, Capability: <memory:1024, vCores:1>, # Containers: 1, Location: *, Relax Locality: true, Node Label Expression: }
2019-06-07 08:05:02,289 INFO org.apache.hadoop.yarn.server.resourcemanager.rmapp.attempt.RMAppAttemptImpl: appattempt_1559894680121_0001_000001 State change from SUBMITTED to SCHEDULED
2019-06-07 08:05:02,289 INFO org.apache.hadoop.yarn.server.resourcemanager.rmapp.attempt.RMAppAttemptImpl: appattempt_1559894680121_0001_000001 State change from SUBMITTED to SCHEDULED
2019-06-07 08:05:03,199 DEBUG org.apache.hadoop.yarn.server.resourcemanager.rmnode.RMNodeImpl: Processing slave1:43282 of type STATUS_UPDATE
2019-06-07 08:05:03,199 DEBUG org.apache.hadoop.yarn.server.resourcemanager.rmnode.RMNodeImpl: Processing slave1:43282 of type STATUS_UPDATE
2019-06-07 08:05:03,201 DEBUG org.apache.hadoop.yarn.server.resourcemanager.scheduler.capacity.CapacityScheduler: nodeUpdate: slave1:43282 clusterResources: <memory:8192, vCores:2>
2019-06-07 08:05:03,201 DEBUG org.apache.hadoop.yarn.server.resourcemanager.scheduler.capacity.CapacityScheduler: nodeUpdate: slave1:43282 clusterResources: <memory:8192, vCores:2>
2019-06-07 08:05:03,201 DEBUG org.apache.hadoop.yarn.server.resourcemanager.scheduler.capacity.CapacityScheduler: Node being looked for scheduling slave1:43282 availableResource: <memory:4096, vCores:1>
2019-06-07 08:05:03,201 DEBUG org.apache.hadoop.yarn.server.resourcemanager.scheduler.capacity.CapacityScheduler: Node being looked for scheduling slave1:43282 availableResource: <memory:4096, vCores:1>
2019-06-07 08:05:03,201 DEBUG org.apache.hadoop.yarn.server.resourcemanager.scheduler.capacity.CapacityScheduler: Trying to schedule on node: slave1, available: <memory:4096, vCores:1>
2019-06-07 08:05:03,201 DEBUG org.apache.hadoop.yarn.server.resourcemanager.scheduler.capacity.CapacityScheduler: Trying to schedule on node: slave1, available: <memory:4096, vCores:1>
2019-06-07 08:05:03,201 DEBUG org.apache.hadoop.yarn.server.resourcemanager.scheduler.capacity.ParentQueue: Trying to assign containers to child-queue of root
2019-06-07 08:05:03,201 DEBUG org.apache.hadoop.yarn.server.resourcemanager.scheduler.capacity.ParentQueue: Trying to assign containers to child-queue of root
2019-06-07 08:05:03,201 DEBUG org.apache.hadoop.yarn.server.resourcemanager.scheduler.capacity.ParentQueue: printChildQueues - queue: root child-queues: root.defaultusedCapacity=(0.0),  label=(*)
2019-06-07 08:05:03,201 DEBUG org.apache.hadoop.yarn.server.resourcemanager.scheduler.capacity.ParentQueue: printChildQueues - queue: root child-queues: root.defaultusedCapacity=(0.0),  label=(*)
2019-06-07 08:05:03,201 DEBUG org.apache.hadoop.yarn.server.resourcemanager.scheduler.capacity.ParentQueue: Trying to assign to queue: root.default stats: default: capacity=1.0, absoluteCapacity=1.0, usedResources=<memory:0, vCores:0>, usedCapacity=0.0, absoluteUsedCapacity=0.0, numApps=1, numContainers=0
2019-06-07 08:05:03,201 DEBUG org.apache.hadoop.yarn.server.resourcemanager.scheduler.capacity.ParentQueue: Trying to assign to queue: root.default stats: default: capacity=1.0, absoluteCapacity=1.0, usedResources=<memory:0, vCores:0>, usedCapacity=0.0, absoluteUsedCapacity=0.0, numApps=1, numContainers=0
2019-06-07 08:05:03,201 DEBUG org.apache.hadoop.yarn.server.resourcemanager.scheduler.capacity.LeafQueue: assignContainers: node=slave1 #applications=1
2019-06-07 08:05:03,201 DEBUG org.apache.hadoop.yarn.server.resourcemanager.scheduler.capacity.LeafQueue: assignContainers: node=slave1 #applications=1
2019-06-07 08:05:03,202 DEBUG org.apache.hadoop.yarn.server.resourcemanager.scheduler.capacity.LeafQueue: User limit computation for root in queue default userLimitPercent=100 userLimitFactor=1.0 required: <memory:1024, vCores:1> consumed: <memory:0, vCores:0> user-limit-resource: <memory:8192, vCores:1> queueCapacity: <memory:8192, vCores:1> qconsumed: <memory:0, vCores:0> consumedRatio: 0.0 currentCapacity: <memory:8192, vCores:1> activeUsers: 1.0 clusterCapacity: <memory:8192, vCores:2> resourceByLabel: <memory:8192, vCores:2> usageratio: 0.0 Partition:  maxUserLimit=<memory:8192, vCores:1> userWeight=1.0
2019-06-07 08:05:03,202 DEBUG org.apache.hadoop.yarn.server.resourcemanager.scheduler.capacity.LeafQueue: User limit computation for root in queue default userLimitPercent=100 userLimitFactor=1.0 required: <memory:1024, vCores:1> consumed: <memory:0, vCores:0> user-limit-resource: <memory:8192, vCores:1> queueCapacity: <memory:8192, vCores:1> qconsumed: <memory:0, vCores:0> consumedRatio: 0.0 currentCapacity: <memory:8192, vCores:1> activeUsers: 1.0 clusterCapacity: <memory:8192, vCores:2> resourceByLabel: <memory:8192, vCores:2> usageratio: 0.0 Partition:  maxUserLimit=<memory:8192, vCores:1> userWeight=1.0
2019-06-07 08:05:03,202 DEBUG org.apache.hadoop.yarn.server.resourcemanager.scheduler.capacity.LeafQueue: Headroom calculation for user root:  userLimit=<memory:8192, vCores:1> queueMaxAvailRes=<memory:8192, vCores:1> consumed=<memory:0, vCores:0>
2019-06-07 08:05:03,202 DEBUG org.apache.hadoop.yarn.server.resourcemanager.scheduler.capacity.LeafQueue: Headroom calculation for user root:  userLimit=<memory:8192, vCores:1> queueMaxAvailRes=<memory:8192, vCores:1> consumed=<memory:0, vCores:0>
2019-06-07 08:05:03,204 DEBUG org.apache.hadoop.yarn.server.resourcemanager.scheduler.common.fica.FiCaSchedulerApp: pre-assignContainers for application application_1559894680121_0001
2019-06-07 08:05:03,204 DEBUG org.apache.hadoop.yarn.server.resourcemanager.scheduler.common.fica.FiCaSchedulerApp: pre-assignContainers for application application_1559894680121_0001
2019-06-07 08:05:03,204 DEBUG org.apache.hadoop.yarn.server.resourcemanager.scheduler.capacity.LeafQueue: User limit computation for root in queue default userLimitPercent=100 userLimitFactor=1.0 required: <memory:1024, vCores:1> consumed: <memory:0, vCores:0> user-limit-resource: <memory:8192, vCores:1> queueCapacity: <memory:8192, vCores:1> qconsumed: <memory:0, vCores:0> consumedRatio: 0.0 currentCapacity: <memory:8192, vCores:1> activeUsers: 1.0 clusterCapacity: <memory:8192, vCores:2> resourceByLabel: <memory:8192, vCores:2> usageratio: 0.0 Partition:  maxUserLimit=<memory:8192, vCores:1> userWeight=1.0
2019-06-07 08:05:03,204 DEBUG org.apache.hadoop.yarn.server.resourcemanager.scheduler.capacity.LeafQueue: User limit computation for root in queue default userLimitPercent=100 userLimitFactor=1.0 required: <memory:1024, vCores:1> consumed: <memory:0, vCores:0> user-limit-resource: <memory:8192, vCores:1> queueCapacity: <memory:8192, vCores:1> qconsumed: <memory:0, vCores:0> consumedRatio: 0.0 currentCapacity: <memory:8192, vCores:1> activeUsers: 1.0 clusterCapacity: <memory:8192, vCores:2> resourceByLabel: <memory:8192, vCores:2> usageratio: 0.0 Partition:  maxUserLimit=<memory:8192, vCores:1> userWeight=1.0
2019-06-07 08:05:03,204 DEBUG org.apache.hadoop.yarn.server.resourcemanager.scheduler.SchedulerApplicationAttempt: showRequests: application=application_1559894680121_0001 headRoom=<memory:8192, vCores:2> currentConsumption=0
2019-06-07 08:05:03,204 DEBUG org.apache.hadoop.yarn.server.resourcemanager.scheduler.SchedulerApplicationAttempt: showRequests: application=application_1559894680121_0001 headRoom=<memory:8192, vCores:2> currentConsumption=0
2019-06-07 08:05:03,205 DEBUG org.apache.hadoop.yarn.server.resourcemanager.scheduler.SchedulerApplicationAttempt: showRequests: application=application_1559894680121_0001 request={Priority: 0, Capability: <memory:1024, vCores:1>, # Containers: 1, Location: *, Relax Locality: true, Node Label Expression: }
2019-06-07 08:05:03,205 DEBUG org.apache.hadoop.yarn.server.resourcemanager.scheduler.SchedulerApplicationAttempt: showRequests: application=application_1559894680121_0001 request={Priority: 0, Capability: <memory:1024, vCores:1>, # Containers: 1, Location: *, Relax Locality: true, Node Label Expression: }
2019-06-07 08:05:03,205 DEBUG org.apache.hadoop.yarn.server.resourcemanager.scheduler.capacity.allocator.IncreaseContainerAllocator: Skip allocating increase request since we don't have any increase request on this node=slave1:43282
2019-06-07 08:05:03,205 DEBUG org.apache.hadoop.yarn.server.resourcemanager.scheduler.capacity.allocator.IncreaseContainerAllocator: Skip allocating increase request since we don't have any increase request on this node=slave1:43282
2019-06-07 08:05:03,208 DEBUG org.apache.hadoop.yarn.server.resourcemanager.scheduler.capacity.allocator.RegularContainerAllocator: assignContainers: node=slave1 application=application_1559894680121_0001 priority=0 request={Priority: 0, Capability: <memory:1024, vCores:1>, # Containers: 1, Location: *, Relax Locality: true, Node Label Expression: } type=OFF_SWITCH
2019-06-07 08:05:03,208 DEBUG org.apache.hadoop.yarn.server.resourcemanager.scheduler.capacity.allocator.RegularContainerAllocator: assignContainers: node=slave1 application=application_1559894680121_0001 priority=0 request={Priority: 0, Capability: <memory:1024, vCores:1>, # Containers: 1, Location: *, Relax Locality: true, Node Label Expression: } type=OFF_SWITCH
2019-06-07 08:05:03,215 DEBUG org.apache.hadoop.yarn.server.resourcemanager.rmnode.RMNodeImpl: Processing slave2:37804 of type STATUS_UPDATE
2019-06-07 08:05:03,215 DEBUG org.apache.hadoop.yarn.server.resourcemanager.rmnode.RMNodeImpl: Processing slave2:37804 of type STATUS_UPDATE
2019-06-07 08:05:03,236 DEBUG org.apache.hadoop.yarn.server.resourcemanager.scheduler.ActiveUsersManager: User root removed from activeUsers, currently: 0
2019-06-07 08:05:03,236 DEBUG org.apache.hadoop.yarn.server.resourcemanager.scheduler.ActiveUsersManager: User root removed from activeUsers, currently: 0
2019-06-07 08:05:03,236 DEBUG org.apache.hadoop.yarn.server.resourcemanager.scheduler.AppSchedulingInfo: allocate: applicationId=application_1559894680121_0001 container=container_1559894680121_0001_01_000001 host=slave1:43282 user=root resource=<memory:1024, vCores:1> type=OFF_SWITCH
2019-06-07 08:05:03,236 DEBUG org.apache.hadoop.yarn.server.resourcemanager.scheduler.AppSchedulingInfo: allocate: applicationId=application_1559894680121_0001 container=container_1559894680121_0001_01_000001 host=slave1:43282 user=root resource=<memory:1024, vCores:1> type=OFF_SWITCH
2019-06-07 08:05:03,236 DEBUG org.apache.hadoop.yarn.server.resourcemanager.rmcontainer.RMContainerImpl: Processing container_1559894680121_0001_01_000001 of type START
2019-06-07 08:05:03,236 DEBUG org.apache.hadoop.yarn.server.resourcemanager.rmcontainer.RMContainerImpl: Processing container_1559894680121_0001_01_000001 of type START
2019-06-07 08:05:03,236 INFO org.apache.hadoop.yarn.server.resourcemanager.rmcontainer.RMContainerImpl: container_1559894680121_0001_01_000001 Container Transitioned from NEW to ALLOCATED
2019-06-07 08:05:03,236 INFO org.apache.hadoop.yarn.server.resourcemanager.rmcontainer.RMContainerImpl: container_1559894680121_0001_01_000001 Container Transitioned from NEW to ALLOCATED
2019-06-07 08:05:03,236 DEBUG org.apache.hadoop.yarn.server.resourcemanager.scheduler.common.fica.FiCaSchedulerApp: allocate: applicationAttemptId=appattempt_1559894680121_0001_000001 container=container_1559894680121_0001_01_000001 host=slave1 type=OFF_SWITCH
2019-06-07 08:05:03,236 DEBUG org.apache.hadoop.yarn.server.resourcemanager.scheduler.common.fica.FiCaSchedulerApp: allocate: applicationAttemptId=appattempt_1559894680121_0001_000001 container=container_1559894680121_0001_01_000001 host=slave1 type=OFF_SWITCH
2019-06-07 08:05:03,236 DEBUG org.apache.hadoop.yarn.server.resourcemanager.rmapp.attempt.RMAppAttemptImpl: Processing event for appattempt_1559894680121_0001_000001 of type CONTAINER_ALLOCATED
2019-06-07 08:05:03,236 DEBUG org.apache.hadoop.yarn.server.resourcemanager.rmapp.attempt.RMAppAttemptImpl: Processing event for appattempt_1559894680121_0001_000001 of type CONTAINER_ALLOCATED
2019-06-07 08:05:03,236 INFO org.apache.hadoop.yarn.server.resourcemanager.RMAuditLogger: USER=root	OPERATION=AM Allocated Container	TARGET=SchedulerApp	RESULT=SUCCESS	APPID=application_1559894680121_0001	CONTAINERID=container_1559894680121_0001_01_000001
2019-06-07 08:05:03,236 INFO org.apache.hadoop.yarn.server.resourcemanager.RMAuditLogger: USER=root	OPERATION=AM Allocated Container	TARGET=SchedulerApp	RESULT=SUCCESS	APPID=application_1559894680121_0001	CONTAINERID=container_1559894680121_0001_01_000001
2019-06-07 08:05:03,237 INFO org.apache.hadoop.yarn.server.resourcemanager.scheduler.SchedulerNode: Assigned container container_1559894680121_0001_01_000001 of capacity <memory:1024, vCores:1> on host slave1:43282, which has 1 containers, <memory:1024, vCores:1> used and <memory:3072, vCores:0> available after allocation
2019-06-07 08:05:03,237 INFO org.apache.hadoop.yarn.server.resourcemanager.scheduler.SchedulerNode: Assigned container container_1559894680121_0001_01_000001 of capacity <memory:1024, vCores:1> on host slave1:43282, which has 1 containers, <memory:1024, vCores:1> used and <memory:3072, vCores:0> available after allocation
2019-06-07 08:05:03,237 INFO org.apache.hadoop.yarn.server.resourcemanager.scheduler.capacity.allocator.AbstractContainerAllocator: assignedContainer application attempt=appattempt_1559894680121_0001_000001 container=container_1559894680121_0001_01_000001 queue=org.apache.hadoop.yarn.server.resourcemanager.scheduler.capacity.allocator.RegularContainerAllocator@530da2a5 clusterResource=<memory:8192, vCores:2> type=OFF_SWITCH requestedPartition=
2019-06-07 08:05:03,237 INFO org.apache.hadoop.yarn.server.resourcemanager.scheduler.capacity.allocator.AbstractContainerAllocator: assignedContainer application attempt=appattempt_1559894680121_0001_000001 container=container_1559894680121_0001_01_000001 queue=org.apache.hadoop.yarn.server.resourcemanager.scheduler.capacity.allocator.RegularContainerAllocator@530da2a5 clusterResource=<memory:8192, vCores:2> type=OFF_SWITCH requestedPartition=
2019-06-07 08:05:03,238 DEBUG org.apache.hadoop.yarn.server.resourcemanager.scheduler.capacity.LeafQueue: post-assignContainers for application application_1559894680121_0001
2019-06-07 08:05:03,238 DEBUG org.apache.hadoop.yarn.server.resourcemanager.scheduler.capacity.LeafQueue: post-assignContainers for application application_1559894680121_0001
2019-06-07 08:05:03,323 INFO org.apache.hadoop.yarn.server.resourcemanager.security.NMTokenSecretManagerInRM: Sending NMToken for nodeId : slave1:43282 for container : container_1559894680121_0001_01_000001
2019-06-07 08:05:03,323 INFO org.apache.hadoop.yarn.server.resourcemanager.security.NMTokenSecretManagerInRM: Sending NMToken for nodeId : slave1:43282 for container : container_1559894680121_0001_01_000001
2019-06-07 08:05:03,330 DEBUG org.apache.hadoop.yarn.server.resourcemanager.rmcontainer.RMContainerImpl: Processing container_1559894680121_0001_01_000001 of type ACQUIRED
2019-06-07 08:05:03,330 DEBUG org.apache.hadoop.yarn.server.resourcemanager.rmcontainer.RMContainerImpl: Processing container_1559894680121_0001_01_000001 of type ACQUIRED
2019-06-07 08:05:03,332 INFO org.apache.hadoop.yarn.server.resourcemanager.rmcontainer.RMContainerImpl: container_1559894680121_0001_01_000001 Container Transitioned from ALLOCATED to ACQUIRED
2019-06-07 08:05:03,332 INFO org.apache.hadoop.yarn.server.resourcemanager.rmcontainer.RMContainerImpl: container_1559894680121_0001_01_000001 Container Transitioned from ALLOCATED to ACQUIRED
2019-06-07 08:05:03,332 DEBUG org.apache.hadoop.yarn.server.resourcemanager.scheduler.capacity.LeafQueue: User limit computation for root in queue default userLimitPercent=100 userLimitFactor=1.0 required: <memory:1024, vCores:1> consumed: <memory:0, vCores:0> user-limit-resource: <memory:8192, vCores:1> queueCapacity: <memory:8192, vCores:1> qconsumed: <memory:0, vCores:0> consumedRatio: 0.0 currentCapacity: <memory:8192, vCores:1> activeUsers: 0.0 clusterCapacity: <memory:8192, vCores:2> resourceByLabel: <memory:8192, vCores:2> usageratio: 0.0 Partition:  maxUserLimit=<memory:8192, vCores:1> userWeight=1.0
2019-06-07 08:05:03,332 DEBUG org.apache.hadoop.yarn.server.resourcemanager.scheduler.capacity.LeafQueue: User limit computation for root in queue default userLimitPercent=100 userLimitFactor=1.0 required: <memory:1024, vCores:1> consumed: <memory:0, vCores:0> user-limit-resource: <memory:8192, vCores:1> queueCapacity: <memory:8192, vCores:1> qconsumed: <memory:0, vCores:0> consumedRatio: 0.0 currentCapacity: <memory:8192, vCores:1> activeUsers: 0.0 clusterCapacity: <memory:8192, vCores:2> resourceByLabel: <memory:8192, vCores:2> usageratio: 0.0 Partition:  maxUserLimit=<memory:8192, vCores:1> userWeight=1.0
2019-06-07 08:05:03,332 DEBUG org.apache.hadoop.yarn.server.resourcemanager.scheduler.capacity.LeafQueue: User limit computation for root in queue default userLimitPercent=100 userLimitFactor=1.0 required: <memory:1024, vCores:1> consumed: <memory:1024, vCores:1> user-limit-resource: <memory:8192, vCores:1> queueCapacity: <memory:8192, vCores:1> qconsumed: <memory:1024, vCores:1> consumedRatio: 0.0 currentCapacity: <memory:8192, vCores:1> activeUsers: 0.0 clusterCapacity: <memory:8192, vCores:2> resourceByLabel: <memory:8192, vCores:2> usageratio: 0.125 Partition:  maxUserLimit=<memory:8192, vCores:1> userWeight=1.0
2019-06-07 08:05:03,332 DEBUG org.apache.hadoop.yarn.server.resourcemanager.scheduler.capacity.LeafQueue: User limit computation for root in queue default userLimitPercent=100 userLimitFactor=1.0 required: <memory:1024, vCores:1> consumed: <memory:1024, vCores:1> user-limit-resource: <memory:8192, vCores:1> queueCapacity: <memory:8192, vCores:1> qconsumed: <memory:1024, vCores:1> consumedRatio: 0.0 currentCapacity: <memory:8192, vCores:1> activeUsers: 0.0 clusterCapacity: <memory:8192, vCores:2> resourceByLabel: <memory:8192, vCores:2> usageratio: 0.125 Partition:  maxUserLimit=<memory:8192, vCores:1> userWeight=1.0
2019-06-07 08:05:03,332 DEBUG org.apache.hadoop.yarn.server.resourcemanager.scheduler.capacity.LeafQueue: User limit computation for root in queue default userLimitPercent=100 userLimitFactor=1.0 required: <memory:1024, vCores:1> consumed: <memory:1024, vCores:1> user-limit-resource: <memory:8192, vCores:1> queueCapacity: <memory:8192, vCores:1> qconsumed: <memory:1024, vCores:1> consumedRatio: 0.0 currentCapacity: <memory:8192, vCores:1> activeUsers: 0.0 clusterCapacity: <memory:8192, vCores:2> resourceByLabel: <memory:8192, vCores:2> usageratio: 0.125 Partition:  maxUserLimit=<memory:8192, vCores:1> userWeight=1.0
2019-06-07 08:05:03,332 DEBUG org.apache.hadoop.yarn.server.resourcemanager.scheduler.capacity.LeafQueue: User limit computation for root in queue default userLimitPercent=100 userLimitFactor=1.0 required: <memory:1024, vCores:1> consumed: <memory:1024, vCores:1> user-limit-resource: <memory:8192, vCores:1> queueCapacity: <memory:8192, vCores:1> qconsumed: <memory:1024, vCores:1> consumedRatio: 0.0 currentCapacity: <memory:8192, vCores:1> activeUsers: 0.0 clusterCapacity: <memory:8192, vCores:2> resourceByLabel: <memory:8192, vCores:2> usageratio: 0.125 Partition:  maxUserLimit=<memory:8192, vCores:1> userWeight=1.0
2019-06-07 08:05:03,332 DEBUG org.apache.hadoop.yarn.server.resourcemanager.scheduler.capacity.LeafQueue: User limit computation for root in queue default userLimitPercent=100 userLimitFactor=1.0 required: <memory:1024, vCores:1> consumed: <memory:1024, vCores:1> user-limit-resource: <memory:8192, vCores:1> queueCapacity: <memory:8192, vCores:1> qconsumed: <memory:1024, vCores:1> consumedRatio: 0.0 currentCapacity: <memory:8192, vCores:1> activeUsers: 0.0 clusterCapacity: <memory:8192, vCores:2> resourceByLabel: <memory:8192, vCores:2> usageratio: 0.125 Partition:  maxUserLimit=<memory:8192, vCores:1> userWeight=1.0
2019-06-07 08:05:03,332 DEBUG org.apache.hadoop.yarn.server.resourcemanager.scheduler.capacity.LeafQueue: User limit computation for root in queue default userLimitPercent=100 userLimitFactor=1.0 required: <memory:1024, vCores:1> consumed: <memory:1024, vCores:1> user-limit-resource: <memory:8192, vCores:1> queueCapacity: <memory:8192, vCores:1> qconsumed: <memory:1024, vCores:1> consumedRatio: 0.0 currentCapacity: <memory:8192, vCores:1> activeUsers: 0.0 clusterCapacity: <memory:8192, vCores:2> resourceByLabel: <memory:8192, vCores:2> usageratio: 0.125 Partition:  maxUserLimit=<memory:8192, vCores:1> userWeight=1.0
2019-06-07 08:05:03,332 DEBUG org.apache.hadoop.yarn.server.resourcemanager.scheduler.capacity.LeafQueue: default user=root used=<memory:1024, vCores:1> numContainers=1 headroom = <memory:7168, vCores:1> user-resources=<memory:1024, vCores:1>
2019-06-07 08:05:03,332 DEBUG org.apache.hadoop.yarn.server.resourcemanager.scheduler.capacity.LeafQueue: default user=root used=<memory:1024, vCores:1> numContainers=1 headroom = <memory:7168, vCores:1> user-resources=<memory:1024, vCores:1>
2019-06-07 08:05:03,333 DEBUG org.apache.hadoop.yarn.server.resourcemanager.scheduler.capacity.ParentQueue: Assigned to queue: root.default stats: default: capacity=1.0, absoluteCapacity=1.0, usedResources=<memory:1024, vCores:1>, usedCapacity=0.125, absoluteUsedCapacity=0.125, numApps=1, numContainers=1 --> <memory:1024, vCores:1>, OFF_SWITCH
2019-06-07 08:05:03,333 DEBUG org.apache.hadoop.yarn.server.resourcemanager.scheduler.capacity.ParentQueue: Assigned to queue: root.default stats: default: capacity=1.0, absoluteCapacity=1.0, usedResources=<memory:1024, vCores:1>, usedCapacity=0.125, absoluteUsedCapacity=0.125, numApps=1, numContainers=1 --> <memory:1024, vCores:1>, OFF_SWITCH
2019-06-07 08:05:03,333 INFO org.apache.hadoop.yarn.server.resourcemanager.scheduler.capacity.ParentQueue: Re-sorting assigned queue: root.default stats: default: capacity=1.0, absoluteCapacity=1.0, usedResources=<memory:1024, vCores:1>, usedCapacity=0.125, absoluteUsedCapacity=0.125, numApps=1, numContainers=1
2019-06-07 08:05:03,333 INFO org.apache.hadoop.yarn.server.resourcemanager.scheduler.capacity.ParentQueue: Re-sorting assigned queue: root.default stats: default: capacity=1.0, absoluteCapacity=1.0, usedResources=<memory:1024, vCores:1>, usedCapacity=0.125, absoluteUsedCapacity=0.125, numApps=1, numContainers=1
2019-06-07 08:05:03,333 DEBUG org.apache.hadoop.yarn.server.resourcemanager.scheduler.capacity.ParentQueue: printChildQueues - queue: root child-queues: root.defaultusedCapacity=(0.125),  label=(*)
2019-06-07 08:05:03,333 DEBUG org.apache.hadoop.yarn.server.resourcemanager.scheduler.capacity.ParentQueue: printChildQueues - queue: root child-queues: root.defaultusedCapacity=(0.125),  label=(*)
2019-06-07 08:05:03,333 INFO org.apache.hadoop.yarn.server.resourcemanager.scheduler.capacity.ParentQueue: assignedContainer queue=root usedCapacity=0.125 absoluteUsedCapacity=0.125 used=<memory:1024, vCores:1> cluster=<memory:8192, vCores:2>
2019-06-07 08:05:03,333 INFO org.apache.hadoop.yarn.server.resourcemanager.scheduler.capacity.ParentQueue: assignedContainer queue=root usedCapacity=0.125 absoluteUsedCapacity=0.125 used=<memory:1024, vCores:1> cluster=<memory:8192, vCores:2>
2019-06-07 08:05:03,333 DEBUG org.apache.hadoop.yarn.server.resourcemanager.scheduler.capacity.ParentQueue: ParentQ=root assignedSoFarInThisIteration=<memory:1024, vCores:1> usedCapacity=0.125 absoluteUsedCapacity=0.125
2019-06-07 08:05:03,333 DEBUG org.apache.hadoop.yarn.server.resourcemanager.scheduler.capacity.ParentQueue: ParentQ=root assignedSoFarInThisIteration=<memory:1024, vCores:1> usedCapacity=0.125 absoluteUsedCapacity=0.125
2019-06-07 08:05:03,333 DEBUG org.apache.hadoop.yarn.server.resourcemanager.scheduler.capacity.ParentQueue: Assigned maximum number of off-switch containers: 1, assignments so far: resource:<memory:1024, vCores:1>; type:OFF_SWITCH; excessReservation:null; applicationid:null; skipped:NONE; fulfilled reservation:false; allocations(count/resource):1/<memory:1024, vCores:1>; reservations(count/resource):0/<memory:0, vCores:0>
2019-06-07 08:05:03,333 DEBUG org.apache.hadoop.yarn.server.resourcemanager.scheduler.capacity.ParentQueue: Assigned maximum number of off-switch containers: 1, assignments so far: resource:<memory:1024, vCores:1>; type:OFF_SWITCH; excessReservation:null; applicationid:null; skipped:NONE; fulfilled reservation:false; allocations(count/resource):1/<memory:1024, vCores:1>; reservations(count/resource):0/<memory:0, vCores:0>
2019-06-07 08:05:03,333 DEBUG org.apache.hadoop.yarn.server.resourcemanager.scheduler.capacity.CapacityScheduler: nodeUpdate: slave2:37804 clusterResources: <memory:8192, vCores:2>
2019-06-07 08:05:03,333 DEBUG org.apache.hadoop.yarn.server.resourcemanager.scheduler.capacity.CapacityScheduler: nodeUpdate: slave2:37804 clusterResources: <memory:8192, vCores:2>
2019-06-07 08:05:03,333 DEBUG org.apache.hadoop.yarn.server.resourcemanager.scheduler.capacity.CapacityScheduler: Node being looked for scheduling slave2:37804 availableResource: <memory:4096, vCores:1>
2019-06-07 08:05:03,333 DEBUG org.apache.hadoop.yarn.server.resourcemanager.scheduler.capacity.CapacityScheduler: Node being looked for scheduling slave2:37804 availableResource: <memory:4096, vCores:1>
2019-06-07 08:05:03,333 DEBUG org.apache.hadoop.yarn.server.resourcemanager.scheduler.capacity.CapacityScheduler: Trying to schedule on node: slave2, available: <memory:4096, vCores:1>
2019-06-07 08:05:03,333 DEBUG org.apache.hadoop.yarn.server.resourcemanager.scheduler.capacity.CapacityScheduler: Trying to schedule on node: slave2, available: <memory:4096, vCores:1>
2019-06-07 08:05:03,333 DEBUG org.apache.hadoop.yarn.server.resourcemanager.scheduler.capacity.ParentQueue: Skip this queue=root, because it doesn't need more resource, schedulingMode=RESPECT_PARTITION_EXCLUSIVITY node-partition=
2019-06-07 08:05:03,333 DEBUG org.apache.hadoop.yarn.server.resourcemanager.scheduler.capacity.ParentQueue: Skip this queue=root, because it doesn't need more resource, schedulingMode=RESPECT_PARTITION_EXCLUSIVITY node-partition=
2019-06-07 08:05:03,333 INFO org.apache.hadoop.yarn.server.resourcemanager.security.NMTokenSecretManagerInRM: Clear node set for appattempt_1559894680121_0001_000001
2019-06-07 08:05:03,333 INFO org.apache.hadoop.yarn.server.resourcemanager.security.NMTokenSecretManagerInRM: Clear node set for appattempt_1559894680121_0001_000001
2019-06-07 08:05:03,334 INFO org.apache.hadoop.yarn.server.resourcemanager.rmapp.attempt.RMAppAttemptImpl: Storing attempt: AppId: application_1559894680121_0001 AttemptId: appattempt_1559894680121_0001_000001 MasterContainer: Container: [ContainerId: container_1559894680121_0001_01_000001, Version: 0, NodeId: slave1:43282, NodeHttpAddress: slave1:8042, Resource: <memory:1024, vCores:1>, Priority: 0, Token: Token { kind: ContainerToken, service: 172.17.0.3:43282 }, ]
2019-06-07 08:05:03,334 INFO org.apache.hadoop.yarn.server.resourcemanager.rmapp.attempt.RMAppAttemptImpl: Storing attempt: AppId: application_1559894680121_0001 AttemptId: appattempt_1559894680121_0001_000001 MasterContainer: Container: [ContainerId: container_1559894680121_0001_01_000001, Version: 0, NodeId: slave1:43282, NodeHttpAddress: slave1:8042, Resource: <memory:1024, vCores:1>, Priority: 0, Token: Token { kind: ContainerToken, service: 172.17.0.3:43282 }, ]
2019-06-07 08:05:03,341 INFO org.apache.hadoop.yarn.server.resourcemanager.rmapp.attempt.RMAppAttemptImpl: appattempt_1559894680121_0001_000001 State change from SCHEDULED to ALLOCATED_SAVING
2019-06-07 08:05:03,341 INFO org.apache.hadoop.yarn.server.resourcemanager.rmapp.attempt.RMAppAttemptImpl: appattempt_1559894680121_0001_000001 State change from SCHEDULED to ALLOCATED_SAVING
2019-06-07 08:05:03,341 DEBUG org.apache.hadoop.yarn.server.resourcemanager.recovery.RMStateStore: Processing event of type STORE_APP_ATTEMPT
2019-06-07 08:05:03,341 DEBUG org.apache.hadoop.yarn.server.resourcemanager.recovery.RMStateStore: Processing event of type STORE_APP_ATTEMPT
2019-06-07 08:05:03,341 DEBUG org.apache.hadoop.yarn.server.resourcemanager.rmapp.RMAppImpl: Processing event for application_1559894680121_0001 of type APP_RUNNING_ON_NODE
2019-06-07 08:05:03,341 DEBUG org.apache.hadoop.yarn.server.resourcemanager.rmapp.RMAppImpl: Processing event for application_1559894680121_0001 of type APP_RUNNING_ON_NODE
2019-06-07 08:05:03,341 DEBUG org.apache.hadoop.yarn.server.resourcemanager.recovery.RMStateStore: Storing info for attempt: appattempt_1559894680121_0001_000001
2019-06-07 08:05:03,341 DEBUG org.apache.hadoop.yarn.server.resourcemanager.recovery.RMStateStore: Storing info for attempt: appattempt_1559894680121_0001_000001
2019-06-07 08:05:03,344 DEBUG org.apache.hadoop.yarn.server.resourcemanager.rmapp.attempt.RMAppAttemptImpl: Processing event for appattempt_1559894680121_0001_000001 of type ATTEMPT_NEW_SAVED
2019-06-07 08:05:03,344 DEBUG org.apache.hadoop.yarn.server.resourcemanager.rmapp.attempt.RMAppAttemptImpl: Processing event for appattempt_1559894680121_0001_000001 of type ATTEMPT_NEW_SAVED
2019-06-07 08:05:03,344 INFO org.apache.hadoop.yarn.server.resourcemanager.rmapp.attempt.RMAppAttemptImpl: appattempt_1559894680121_0001_000001 State change from ALLOCATED_SAVING to ALLOCATED
2019-06-07 08:05:03,344 INFO org.apache.hadoop.yarn.server.resourcemanager.rmapp.attempt.RMAppAttemptImpl: appattempt_1559894680121_0001_000001 State change from ALLOCATED_SAVING to ALLOCATED
2019-06-07 08:05:03,349 INFO org.apache.hadoop.yarn.server.resourcemanager.amlauncher.AMLauncher: Launching masterappattempt_1559894680121_0001_000001
2019-06-07 08:05:03,349 INFO org.apache.hadoop.yarn.server.resourcemanager.amlauncher.AMLauncher: Launching masterappattempt_1559894680121_0001_000001
2019-06-07 08:05:03,386 INFO org.apache.hadoop.yarn.server.resourcemanager.amlauncher.AMLauncher: Setting up container Container: [ContainerId: container_1559894680121_0001_01_000001, Version: 0, NodeId: slave1:43282, NodeHttpAddress: slave1:8042, Resource: <memory:1024, vCores:1>, Priority: 0, Token: Token { kind: ContainerToken, service: 172.17.0.3:43282 }, ] for AM appattempt_1559894680121_0001_000001
2019-06-07 08:05:03,386 INFO org.apache.hadoop.yarn.server.resourcemanager.amlauncher.AMLauncher: Setting up container Container: [ContainerId: container_1559894680121_0001_01_000001, Version: 0, NodeId: slave1:43282, NodeHttpAddress: slave1:8042, Resource: <memory:1024, vCores:1>, Priority: 0, Token: Token { kind: ContainerToken, service: 172.17.0.3:43282 }, ] for AM appattempt_1559894680121_0001_000001
2019-06-07 08:05:03,387 INFO org.apache.hadoop.yarn.server.resourcemanager.security.AMRMTokenSecretManager: Create AMRMToken for ApplicationAttempt: appattempt_1559894680121_0001_000001
2019-06-07 08:05:03,387 INFO org.apache.hadoop.yarn.server.resourcemanager.security.AMRMTokenSecretManager: Create AMRMToken for ApplicationAttempt: appattempt_1559894680121_0001_000001
2019-06-07 08:05:03,389 INFO org.apache.hadoop.yarn.server.resourcemanager.security.AMRMTokenSecretManager: Creating password for appattempt_1559894680121_0001_000001
2019-06-07 08:05:03,389 INFO org.apache.hadoop.yarn.server.resourcemanager.security.AMRMTokenSecretManager: Creating password for appattempt_1559894680121_0001_000001
2019-06-07 08:05:03,699 INFO org.apache.hadoop.yarn.server.resourcemanager.amlauncher.AMLauncher: Done launching container Container: [ContainerId: container_1559894680121_0001_01_000001, Version: 0, NodeId: slave1:43282, NodeHttpAddress: slave1:8042, Resource: <memory:1024, vCores:1>, Priority: 0, Token: Token { kind: ContainerToken, service: 172.17.0.3:43282 }, ] for AM appattempt_1559894680121_0001_000001
2019-06-07 08:05:03,699 INFO org.apache.hadoop.yarn.server.resourcemanager.amlauncher.AMLauncher: Done launching container Container: [ContainerId: container_1559894680121_0001_01_000001, Version: 0, NodeId: slave1:43282, NodeHttpAddress: slave1:8042, Resource: <memory:1024, vCores:1>, Priority: 0, Token: Token { kind: ContainerToken, service: 172.17.0.3:43282 }, ] for AM appattempt_1559894680121_0001_000001
2019-06-07 08:05:03,699 DEBUG org.apache.hadoop.yarn.server.resourcemanager.rmapp.attempt.RMAppAttemptImpl: Processing event for appattempt_1559894680121_0001_000001 of type LAUNCHED
2019-06-07 08:05:03,699 DEBUG org.apache.hadoop.yarn.server.resourcemanager.rmapp.attempt.RMAppAttemptImpl: Processing event for appattempt_1559894680121_0001_000001 of type LAUNCHED
2019-06-07 08:05:03,699 INFO org.apache.hadoop.yarn.server.resourcemanager.rmapp.attempt.RMAppAttemptImpl: appattempt_1559894680121_0001_000001 State change from ALLOCATED to LAUNCHED
2019-06-07 08:05:03,699 INFO org.apache.hadoop.yarn.server.resourcemanager.rmapp.attempt.RMAppAttemptImpl: appattempt_1559894680121_0001_000001 State change from ALLOCATED to LAUNCHED
2019-06-07 08:05:04,223 DEBUG org.apache.hadoop.yarn.server.resourcemanager.rmnode.RMNodeImpl: Processing slave2:37804 of type STATUS_UPDATE
2019-06-07 08:05:04,223 DEBUG org.apache.hadoop.yarn.server.resourcemanager.rmnode.RMNodeImpl: Processing slave2:37804 of type STATUS_UPDATE
2019-06-07 08:05:04,223 DEBUG org.apache.hadoop.yarn.server.resourcemanager.scheduler.capacity.CapacityScheduler: nodeUpdate: slave2:37804 clusterResources: <memory:8192, vCores:2>
2019-06-07 08:05:04,223 DEBUG org.apache.hadoop.yarn.server.resourcemanager.scheduler.capacity.CapacityScheduler: nodeUpdate: slave2:37804 clusterResources: <memory:8192, vCores:2>
2019-06-07 08:05:04,223 DEBUG org.apache.hadoop.yarn.server.resourcemanager.scheduler.capacity.CapacityScheduler: Node being looked for scheduling slave2:37804 availableResource: <memory:4096, vCores:1>
2019-06-07 08:05:04,223 DEBUG org.apache.hadoop.yarn.server.resourcemanager.scheduler.capacity.CapacityScheduler: Node being looked for scheduling slave2:37804 availableResource: <memory:4096, vCores:1>
2019-06-07 08:05:04,223 DEBUG org.apache.hadoop.yarn.server.resourcemanager.scheduler.capacity.CapacityScheduler: Trying to schedule on node: slave2, available: <memory:4096, vCores:1>
2019-06-07 08:05:04,223 DEBUG org.apache.hadoop.yarn.server.resourcemanager.scheduler.capacity.CapacityScheduler: Trying to schedule on node: slave2, available: <memory:4096, vCores:1>
2019-06-07 08:05:04,223 DEBUG org.apache.hadoop.yarn.server.resourcemanager.scheduler.capacity.ParentQueue: Skip this queue=root, because it doesn't need more resource, schedulingMode=RESPECT_PARTITION_EXCLUSIVITY node-partition=
2019-06-07 08:05:04,223 DEBUG org.apache.hadoop.yarn.server.resourcemanager.scheduler.capacity.ParentQueue: Skip this queue=root, because it doesn't need more resource, schedulingMode=RESPECT_PARTITION_EXCLUSIVITY node-partition=
2019-06-07 08:05:04,254 DEBUG org.apache.hadoop.yarn.server.resourcemanager.rmnode.RMNodeImpl: Processing slave1:43282 of type STATUS_UPDATE
2019-06-07 08:05:04,254 DEBUG org.apache.hadoop.yarn.server.resourcemanager.rmnode.RMNodeImpl: Processing slave1:43282 of type STATUS_UPDATE
2019-06-07 08:05:04,255 DEBUG org.apache.hadoop.yarn.server.resourcemanager.rmnode.RMNodeImpl: Container container_1559894680121_0001_01_000001 is the first container get launched for application application_1559894680121_0001
2019-06-07 08:05:04,255 DEBUG org.apache.hadoop.yarn.server.resourcemanager.rmnode.RMNodeImpl: Container container_1559894680121_0001_01_000001 is the first container get launched for application application_1559894680121_0001
2019-06-07 08:05:04,256 DEBUG org.apache.hadoop.yarn.server.resourcemanager.rmapp.RMAppImpl: Processing event for application_1559894680121_0001 of type APP_RUNNING_ON_NODE
2019-06-07 08:05:04,256 DEBUG org.apache.hadoop.yarn.server.resourcemanager.rmapp.RMAppImpl: Processing event for application_1559894680121_0001 of type APP_RUNNING_ON_NODE
2019-06-07 08:05:04,257 DEBUG org.apache.hadoop.yarn.server.resourcemanager.scheduler.capacity.CapacityScheduler: nodeUpdate: slave1:43282 clusterResources: <memory:8192, vCores:2>
2019-06-07 08:05:04,257 DEBUG org.apache.hadoop.yarn.server.resourcemanager.scheduler.capacity.CapacityScheduler: nodeUpdate: slave1:43282 clusterResources: <memory:8192, vCores:2>
2019-06-07 08:05:04,257 DEBUG org.apache.hadoop.yarn.server.resourcemanager.rmcontainer.RMContainerImpl: Processing container_1559894680121_0001_01_000001 of type LAUNCHED
2019-06-07 08:05:04,257 DEBUG org.apache.hadoop.yarn.server.resourcemanager.rmcontainer.RMContainerImpl: Processing container_1559894680121_0001_01_000001 of type LAUNCHED
2019-06-07 08:05:04,257 INFO org.apache.hadoop.yarn.server.resourcemanager.rmcontainer.RMContainerImpl: container_1559894680121_0001_01_000001 Container Transitioned from ACQUIRED to RUNNING
2019-06-07 08:05:04,257 INFO org.apache.hadoop.yarn.server.resourcemanager.rmcontainer.RMContainerImpl: container_1559894680121_0001_01_000001 Container Transitioned from ACQUIRED to RUNNING
2019-06-07 08:05:04,257 DEBUG org.apache.hadoop.yarn.server.resourcemanager.scheduler.capacity.CapacityScheduler: Node being looked for scheduling slave1:43282 availableResource: <memory:3072, vCores:0>
2019-06-07 08:05:04,257 DEBUG org.apache.hadoop.yarn.server.resourcemanager.scheduler.capacity.CapacityScheduler: Node being looked for scheduling slave1:43282 availableResource: <memory:3072, vCores:0>
2019-06-07 08:05:04,257 DEBUG org.apache.hadoop.yarn.server.resourcemanager.scheduler.capacity.CapacityScheduler: Trying to schedule on node: slave1, available: <memory:3072, vCores:0>
2019-06-07 08:05:04,257 DEBUG org.apache.hadoop.yarn.server.resourcemanager.scheduler.capacity.CapacityScheduler: Trying to schedule on node: slave1, available: <memory:3072, vCores:0>
2019-06-07 08:05:04,257 DEBUG org.apache.hadoop.yarn.server.resourcemanager.scheduler.capacity.ParentQueue: Skip this queue=root, because it doesn't need more resource, schedulingMode=RESPECT_PARTITION_EXCLUSIVITY node-partition=
2019-06-07 08:05:04,257 DEBUG org.apache.hadoop.yarn.server.resourcemanager.scheduler.capacity.ParentQueue: Skip this queue=root, because it doesn't need more resource, schedulingMode=RESPECT_PARTITION_EXCLUSIVITY node-partition=
2019-06-07 08:05:05,225 DEBUG org.apache.hadoop.yarn.server.resourcemanager.rmnode.RMNodeImpl: Processing slave2:37804 of type STATUS_UPDATE
2019-06-07 08:05:05,225 DEBUG org.apache.hadoop.yarn.server.resourcemanager.rmnode.RMNodeImpl: Processing slave2:37804 of type STATUS_UPDATE
2019-06-07 08:05:05,226 DEBUG org.apache.hadoop.yarn.server.resourcemanager.scheduler.capacity.CapacityScheduler: nodeUpdate: slave2:37804 clusterResources: <memory:8192, vCores:2>
2019-06-07 08:05:05,226 DEBUG org.apache.hadoop.yarn.server.resourcemanager.scheduler.capacity.CapacityScheduler: nodeUpdate: slave2:37804 clusterResources: <memory:8192, vCores:2>
2019-06-07 08:05:05,226 DEBUG org.apache.hadoop.yarn.server.resourcemanager.scheduler.capacity.CapacityScheduler: Node being looked for scheduling slave2:37804 availableResource: <memory:4096, vCores:1>
2019-06-07 08:05:05,226 DEBUG org.apache.hadoop.yarn.server.resourcemanager.scheduler.capacity.CapacityScheduler: Node being looked for scheduling slave2:37804 availableResource: <memory:4096, vCores:1>
2019-06-07 08:05:05,226 DEBUG org.apache.hadoop.yarn.server.resourcemanager.scheduler.capacity.CapacityScheduler: Trying to schedule on node: slave2, available: <memory:4096, vCores:1>
2019-06-07 08:05:05,226 DEBUG org.apache.hadoop.yarn.server.resourcemanager.scheduler.capacity.CapacityScheduler: Trying to schedule on node: slave2, available: <memory:4096, vCores:1>
2019-06-07 08:05:05,226 DEBUG org.apache.hadoop.yarn.server.resourcemanager.scheduler.capacity.ParentQueue: Skip this queue=root, because it doesn't need more resource, schedulingMode=RESPECT_PARTITION_EXCLUSIVITY node-partition=
2019-06-07 08:05:05,226 DEBUG org.apache.hadoop.yarn.server.resourcemanager.scheduler.capacity.ParentQueue: Skip this queue=root, because it doesn't need more resource, schedulingMode=RESPECT_PARTITION_EXCLUSIVITY node-partition=
2019-06-07 08:05:05,270 DEBUG org.apache.hadoop.yarn.server.resourcemanager.rmnode.RMNodeImpl: Processing slave1:43282 of type STATUS_UPDATE
2019-06-07 08:05:05,270 DEBUG org.apache.hadoop.yarn.server.resourcemanager.rmnode.RMNodeImpl: Processing slave1:43282 of type STATUS_UPDATE
2019-06-07 08:05:05,271 DEBUG org.apache.hadoop.yarn.server.resourcemanager.scheduler.capacity.CapacityScheduler: nodeUpdate: slave1:43282 clusterResources: <memory:8192, vCores:2>
2019-06-07 08:05:05,271 DEBUG org.apache.hadoop.yarn.server.resourcemanager.scheduler.capacity.CapacityScheduler: nodeUpdate: slave1:43282 clusterResources: <memory:8192, vCores:2>
2019-06-07 08:05:05,271 DEBUG org.apache.hadoop.yarn.server.resourcemanager.scheduler.capacity.CapacityScheduler: Node being looked for scheduling slave1:43282 availableResource: <memory:3072, vCores:0>
2019-06-07 08:05:05,271 DEBUG org.apache.hadoop.yarn.server.resourcemanager.scheduler.capacity.CapacityScheduler: Node being looked for scheduling slave1:43282 availableResource: <memory:3072, vCores:0>
2019-06-07 08:05:05,271 DEBUG org.apache.hadoop.yarn.server.resourcemanager.scheduler.capacity.CapacityScheduler: Trying to schedule on node: slave1, available: <memory:3072, vCores:0>
2019-06-07 08:05:05,271 DEBUG org.apache.hadoop.yarn.server.resourcemanager.scheduler.capacity.CapacityScheduler: Trying to schedule on node: slave1, available: <memory:3072, vCores:0>
2019-06-07 08:05:05,271 DEBUG org.apache.hadoop.yarn.server.resourcemanager.scheduler.capacity.ParentQueue: Skip this queue=root, because it doesn't need more resource, schedulingMode=RESPECT_PARTITION_EXCLUSIVITY node-partition=
2019-06-07 08:05:05,271 DEBUG org.apache.hadoop.yarn.server.resourcemanager.scheduler.capacity.ParentQueue: Skip this queue=root, because it doesn't need more resource, schedulingMode=RESPECT_PARTITION_EXCLUSIVITY node-partition=
2019-06-07 08:05:06,229 DEBUG org.apache.hadoop.yarn.server.resourcemanager.rmnode.RMNodeImpl: Processing slave2:37804 of type STATUS_UPDATE
2019-06-07 08:05:06,229 DEBUG org.apache.hadoop.yarn.server.resourcemanager.rmnode.RMNodeImpl: Processing slave2:37804 of type STATUS_UPDATE
2019-06-07 08:05:06,230 DEBUG org.apache.hadoop.yarn.server.resourcemanager.scheduler.capacity.CapacityScheduler: nodeUpdate: slave2:37804 clusterResources: <memory:8192, vCores:2>
2019-06-07 08:05:06,230 DEBUG org.apache.hadoop.yarn.server.resourcemanager.scheduler.capacity.CapacityScheduler: nodeUpdate: slave2:37804 clusterResources: <memory:8192, vCores:2>
2019-06-07 08:05:06,230 DEBUG org.apache.hadoop.yarn.server.resourcemanager.scheduler.capacity.CapacityScheduler: Node being looked for scheduling slave2:37804 availableResource: <memory:4096, vCores:1>
2019-06-07 08:05:06,230 DEBUG org.apache.hadoop.yarn.server.resourcemanager.scheduler.capacity.CapacityScheduler: Node being looked for scheduling slave2:37804 availableResource: <memory:4096, vCores:1>
2019-06-07 08:05:06,230 DEBUG org.apache.hadoop.yarn.server.resourcemanager.scheduler.capacity.CapacityScheduler: Trying to schedule on node: slave2, available: <memory:4096, vCores:1>
2019-06-07 08:05:06,230 DEBUG org.apache.hadoop.yarn.server.resourcemanager.scheduler.capacity.CapacityScheduler: Trying to schedule on node: slave2, available: <memory:4096, vCores:1>
2019-06-07 08:05:06,230 DEBUG org.apache.hadoop.yarn.server.resourcemanager.scheduler.capacity.ParentQueue: Skip this queue=root, because it doesn't need more resource, schedulingMode=RESPECT_PARTITION_EXCLUSIVITY node-partition=
2019-06-07 08:05:06,230 DEBUG org.apache.hadoop.yarn.server.resourcemanager.scheduler.capacity.ParentQueue: Skip this queue=root, because it doesn't need more resource, schedulingMode=RESPECT_PARTITION_EXCLUSIVITY node-partition=
2019-06-07 08:05:06,277 DEBUG org.apache.hadoop.yarn.server.resourcemanager.rmnode.RMNodeImpl: Processing slave1:43282 of type STATUS_UPDATE
2019-06-07 08:05:06,277 DEBUG org.apache.hadoop.yarn.server.resourcemanager.rmnode.RMNodeImpl: Processing slave1:43282 of type STATUS_UPDATE
2019-06-07 08:05:06,278 DEBUG org.apache.hadoop.yarn.server.resourcemanager.scheduler.capacity.CapacityScheduler: nodeUpdate: slave1:43282 clusterResources: <memory:8192, vCores:2>
2019-06-07 08:05:06,278 DEBUG org.apache.hadoop.yarn.server.resourcemanager.scheduler.capacity.CapacityScheduler: nodeUpdate: slave1:43282 clusterResources: <memory:8192, vCores:2>
2019-06-07 08:05:06,278 DEBUG org.apache.hadoop.yarn.server.resourcemanager.scheduler.capacity.CapacityScheduler: Node being looked for scheduling slave1:43282 availableResource: <memory:3072, vCores:0>
2019-06-07 08:05:06,278 DEBUG org.apache.hadoop.yarn.server.resourcemanager.scheduler.capacity.CapacityScheduler: Node being looked for scheduling slave1:43282 availableResource: <memory:3072, vCores:0>
2019-06-07 08:05:06,278 DEBUG org.apache.hadoop.yarn.server.resourcemanager.scheduler.capacity.CapacityScheduler: Trying to schedule on node: slave1, available: <memory:3072, vCores:0>
2019-06-07 08:05:06,278 DEBUG org.apache.hadoop.yarn.server.resourcemanager.scheduler.capacity.CapacityScheduler: Trying to schedule on node: slave1, available: <memory:3072, vCores:0>
2019-06-07 08:05:06,278 DEBUG org.apache.hadoop.yarn.server.resourcemanager.scheduler.capacity.ParentQueue: Skip this queue=root, because it doesn't need more resource, schedulingMode=RESPECT_PARTITION_EXCLUSIVITY node-partition=
2019-06-07 08:05:06,278 DEBUG org.apache.hadoop.yarn.server.resourcemanager.scheduler.capacity.ParentQueue: Skip this queue=root, because it doesn't need more resource, schedulingMode=RESPECT_PARTITION_EXCLUSIVITY node-partition=
2019-06-07 08:05:07,234 DEBUG org.apache.hadoop.yarn.server.resourcemanager.rmnode.RMNodeImpl: Processing slave2:37804 of type STATUS_UPDATE
2019-06-07 08:05:07,234 DEBUG org.apache.hadoop.yarn.server.resourcemanager.rmnode.RMNodeImpl: Processing slave2:37804 of type STATUS_UPDATE
2019-06-07 08:05:07,235 DEBUG org.apache.hadoop.yarn.server.resourcemanager.scheduler.capacity.CapacityScheduler: nodeUpdate: slave2:37804 clusterResources: <memory:8192, vCores:2>
2019-06-07 08:05:07,235 DEBUG org.apache.hadoop.yarn.server.resourcemanager.scheduler.capacity.CapacityScheduler: nodeUpdate: slave2:37804 clusterResources: <memory:8192, vCores:2>
2019-06-07 08:05:07,235 DEBUG org.apache.hadoop.yarn.server.resourcemanager.scheduler.capacity.CapacityScheduler: Node being looked for scheduling slave2:37804 availableResource: <memory:4096, vCores:1>
2019-06-07 08:05:07,235 DEBUG org.apache.hadoop.yarn.server.resourcemanager.scheduler.capacity.CapacityScheduler: Node being looked for scheduling slave2:37804 availableResource: <memory:4096, vCores:1>
2019-06-07 08:05:07,235 DEBUG org.apache.hadoop.yarn.server.resourcemanager.scheduler.capacity.CapacityScheduler: Trying to schedule on node: slave2, available: <memory:4096, vCores:1>
2019-06-07 08:05:07,235 DEBUG org.apache.hadoop.yarn.server.resourcemanager.scheduler.capacity.CapacityScheduler: Trying to schedule on node: slave2, available: <memory:4096, vCores:1>
2019-06-07 08:05:07,235 DEBUG org.apache.hadoop.yarn.server.resourcemanager.scheduler.capacity.ParentQueue: Skip this queue=root, because it doesn't need more resource, schedulingMode=RESPECT_PARTITION_EXCLUSIVITY node-partition=
2019-06-07 08:05:07,235 DEBUG org.apache.hadoop.yarn.server.resourcemanager.scheduler.capacity.ParentQueue: Skip this queue=root, because it doesn't need more resource, schedulingMode=RESPECT_PARTITION_EXCLUSIVITY node-partition=
2019-06-07 08:05:07,287 DEBUG org.apache.hadoop.yarn.server.resourcemanager.rmnode.RMNodeImpl: Processing slave1:43282 of type STATUS_UPDATE
2019-06-07 08:05:07,287 DEBUG org.apache.hadoop.yarn.server.resourcemanager.rmnode.RMNodeImpl: Processing slave1:43282 of type STATUS_UPDATE
2019-06-07 08:05:07,289 DEBUG org.apache.hadoop.yarn.server.resourcemanager.scheduler.capacity.CapacityScheduler: nodeUpdate: slave1:43282 clusterResources: <memory:8192, vCores:2>
2019-06-07 08:05:07,289 DEBUG org.apache.hadoop.yarn.server.resourcemanager.scheduler.capacity.CapacityScheduler: nodeUpdate: slave1:43282 clusterResources: <memory:8192, vCores:2>
2019-06-07 08:05:07,289 DEBUG org.apache.hadoop.yarn.server.resourcemanager.scheduler.capacity.CapacityScheduler: Node being looked for scheduling slave1:43282 availableResource: <memory:3072, vCores:0>
2019-06-07 08:05:07,289 DEBUG org.apache.hadoop.yarn.server.resourcemanager.scheduler.capacity.CapacityScheduler: Node being looked for scheduling slave1:43282 availableResource: <memory:3072, vCores:0>
2019-06-07 08:05:07,289 DEBUG org.apache.hadoop.yarn.server.resourcemanager.scheduler.capacity.CapacityScheduler: Trying to schedule on node: slave1, available: <memory:3072, vCores:0>
2019-06-07 08:05:07,289 DEBUG org.apache.hadoop.yarn.server.resourcemanager.scheduler.capacity.CapacityScheduler: Trying to schedule on node: slave1, available: <memory:3072, vCores:0>
2019-06-07 08:05:07,289 DEBUG org.apache.hadoop.yarn.server.resourcemanager.scheduler.capacity.ParentQueue: Skip this queue=root, because it doesn't need more resource, schedulingMode=RESPECT_PARTITION_EXCLUSIVITY node-partition=
2019-06-07 08:05:07,289 DEBUG org.apache.hadoop.yarn.server.resourcemanager.scheduler.capacity.ParentQueue: Skip this queue=root, because it doesn't need more resource, schedulingMode=RESPECT_PARTITION_EXCLUSIVITY node-partition=
2019-06-07 08:05:08,239 DEBUG org.apache.hadoop.yarn.server.resourcemanager.rmnode.RMNodeImpl: Processing slave2:37804 of type STATUS_UPDATE
2019-06-07 08:05:08,239 DEBUG org.apache.hadoop.yarn.server.resourcemanager.rmnode.RMNodeImpl: Processing slave2:37804 of type STATUS_UPDATE
2019-06-07 08:05:08,239 DEBUG org.apache.hadoop.yarn.server.resourcemanager.scheduler.capacity.CapacityScheduler: nodeUpdate: slave2:37804 clusterResources: <memory:8192, vCores:2>
2019-06-07 08:05:08,239 DEBUG org.apache.hadoop.yarn.server.resourcemanager.scheduler.capacity.CapacityScheduler: nodeUpdate: slave2:37804 clusterResources: <memory:8192, vCores:2>
2019-06-07 08:05:08,239 DEBUG org.apache.hadoop.yarn.server.resourcemanager.scheduler.capacity.CapacityScheduler: Node being looked for scheduling slave2:37804 availableResource: <memory:4096, vCores:1>
2019-06-07 08:05:08,239 DEBUG org.apache.hadoop.yarn.server.resourcemanager.scheduler.capacity.CapacityScheduler: Node being looked for scheduling slave2:37804 availableResource: <memory:4096, vCores:1>
2019-06-07 08:05:08,239 DEBUG org.apache.hadoop.yarn.server.resourcemanager.scheduler.capacity.CapacityScheduler: Trying to schedule on node: slave2, available: <memory:4096, vCores:1>
2019-06-07 08:05:08,239 DEBUG org.apache.hadoop.yarn.server.resourcemanager.scheduler.capacity.CapacityScheduler: Trying to schedule on node: slave2, available: <memory:4096, vCores:1>
2019-06-07 08:05:08,239 DEBUG org.apache.hadoop.yarn.server.resourcemanager.scheduler.capacity.ParentQueue: Skip this queue=root, because it doesn't need more resource, schedulingMode=RESPECT_PARTITION_EXCLUSIVITY node-partition=
2019-06-07 08:05:08,239 DEBUG org.apache.hadoop.yarn.server.resourcemanager.scheduler.capacity.ParentQueue: Skip this queue=root, because it doesn't need more resource, schedulingMode=RESPECT_PARTITION_EXCLUSIVITY node-partition=
2019-06-07 08:05:08,292 DEBUG org.apache.hadoop.yarn.server.resourcemanager.rmnode.RMNodeImpl: Processing slave1:43282 of type STATUS_UPDATE
2019-06-07 08:05:08,292 DEBUG org.apache.hadoop.yarn.server.resourcemanager.rmnode.RMNodeImpl: Processing slave1:43282 of type STATUS_UPDATE
2019-06-07 08:05:08,292 DEBUG org.apache.hadoop.yarn.server.resourcemanager.scheduler.capacity.CapacityScheduler: nodeUpdate: slave1:43282 clusterResources: <memory:8192, vCores:2>
2019-06-07 08:05:08,292 DEBUG org.apache.hadoop.yarn.server.resourcemanager.scheduler.capacity.CapacityScheduler: nodeUpdate: slave1:43282 clusterResources: <memory:8192, vCores:2>
2019-06-07 08:05:08,292 DEBUG org.apache.hadoop.yarn.server.resourcemanager.scheduler.capacity.CapacityScheduler: Node being looked for scheduling slave1:43282 availableResource: <memory:3072, vCores:0>
2019-06-07 08:05:08,292 DEBUG org.apache.hadoop.yarn.server.resourcemanager.scheduler.capacity.CapacityScheduler: Node being looked for scheduling slave1:43282 availableResource: <memory:3072, vCores:0>
2019-06-07 08:05:08,292 DEBUG org.apache.hadoop.yarn.server.resourcemanager.scheduler.capacity.CapacityScheduler: Trying to schedule on node: slave1, available: <memory:3072, vCores:0>
2019-06-07 08:05:08,292 DEBUG org.apache.hadoop.yarn.server.resourcemanager.scheduler.capacity.CapacityScheduler: Trying to schedule on node: slave1, available: <memory:3072, vCores:0>
2019-06-07 08:05:08,293 DEBUG org.apache.hadoop.yarn.server.resourcemanager.scheduler.capacity.ParentQueue: Skip this queue=root, because it doesn't need more resource, schedulingMode=RESPECT_PARTITION_EXCLUSIVITY node-partition=
2019-06-07 08:05:08,293 DEBUG org.apache.hadoop.yarn.server.resourcemanager.scheduler.capacity.ParentQueue: Skip this queue=root, because it doesn't need more resource, schedulingMode=RESPECT_PARTITION_EXCLUSIVITY node-partition=
2019-06-07 08:05:09,242 DEBUG org.apache.hadoop.yarn.server.resourcemanager.rmnode.RMNodeImpl: Processing slave2:37804 of type STATUS_UPDATE
2019-06-07 08:05:09,242 DEBUG org.apache.hadoop.yarn.server.resourcemanager.rmnode.RMNodeImpl: Processing slave2:37804 of type STATUS_UPDATE
2019-06-07 08:05:09,243 DEBUG org.apache.hadoop.yarn.server.resourcemanager.scheduler.capacity.CapacityScheduler: nodeUpdate: slave2:37804 clusterResources: <memory:8192, vCores:2>
2019-06-07 08:05:09,243 DEBUG org.apache.hadoop.yarn.server.resourcemanager.scheduler.capacity.CapacityScheduler: nodeUpdate: slave2:37804 clusterResources: <memory:8192, vCores:2>
2019-06-07 08:05:09,243 DEBUG org.apache.hadoop.yarn.server.resourcemanager.scheduler.capacity.CapacityScheduler: Node being looked for scheduling slave2:37804 availableResource: <memory:4096, vCores:1>
2019-06-07 08:05:09,243 DEBUG org.apache.hadoop.yarn.server.resourcemanager.scheduler.capacity.CapacityScheduler: Node being looked for scheduling slave2:37804 availableResource: <memory:4096, vCores:1>
2019-06-07 08:05:09,243 DEBUG org.apache.hadoop.yarn.server.resourcemanager.scheduler.capacity.CapacityScheduler: Trying to schedule on node: slave2, available: <memory:4096, vCores:1>
2019-06-07 08:05:09,243 DEBUG org.apache.hadoop.yarn.server.resourcemanager.scheduler.capacity.CapacityScheduler: Trying to schedule on node: slave2, available: <memory:4096, vCores:1>
2019-06-07 08:05:09,243 DEBUG org.apache.hadoop.yarn.server.resourcemanager.scheduler.capacity.ParentQueue: Skip this queue=root, because it doesn't need more resource, schedulingMode=RESPECT_PARTITION_EXCLUSIVITY node-partition=
2019-06-07 08:05:09,243 DEBUG org.apache.hadoop.yarn.server.resourcemanager.scheduler.capacity.ParentQueue: Skip this queue=root, because it doesn't need more resource, schedulingMode=RESPECT_PARTITION_EXCLUSIVITY node-partition=
2019-06-07 08:05:09,246 DEBUG org.apache.hadoop.yarn.server.resourcemanager.security.AMRMTokenSecretManager: Trying to retrieve password for appattempt_1559894680121_0001_000001
2019-06-07 08:05:09,246 DEBUG org.apache.hadoop.yarn.server.resourcemanager.security.AMRMTokenSecretManager: Trying to retrieve password for appattempt_1559894680121_0001_000001
2019-06-07 08:05:09,248 INFO SecurityLogger.org.apache.hadoop.ipc.Server: Auth successful for appattempt_1559894680121_0001_000001 (auth:SIMPLE)
2019-06-07 08:05:09,260 INFO org.apache.hadoop.yarn.server.resourcemanager.ApplicationMasterService: AM registration appattempt_1559894680121_0001_000001
2019-06-07 08:05:09,260 INFO org.apache.hadoop.yarn.server.resourcemanager.ApplicationMasterService: AM registration appattempt_1559894680121_0001_000001
2019-06-07 08:05:09,262 DEBUG org.apache.hadoop.yarn.server.resourcemanager.rmapp.attempt.RMAppAttemptImpl: Processing event for appattempt_1559894680121_0001_000001 of type REGISTERED
2019-06-07 08:05:09,262 DEBUG org.apache.hadoop.yarn.server.resourcemanager.rmapp.attempt.RMAppAttemptImpl: Processing event for appattempt_1559894680121_0001_000001 of type REGISTERED
2019-06-07 08:05:09,262 INFO org.apache.hadoop.yarn.server.resourcemanager.rmapp.attempt.RMAppAttemptImpl: appattempt_1559894680121_0001_000001 State change from LAUNCHED to RUNNING
2019-06-07 08:05:09,262 INFO org.apache.hadoop.yarn.server.resourcemanager.rmapp.attempt.RMAppAttemptImpl: appattempt_1559894680121_0001_000001 State change from LAUNCHED to RUNNING
2019-06-07 08:05:09,262 DEBUG org.apache.hadoop.yarn.server.resourcemanager.rmapp.RMAppImpl: Processing event for application_1559894680121_0001 of type ATTEMPT_REGISTERED
2019-06-07 08:05:09,262 DEBUG org.apache.hadoop.yarn.server.resourcemanager.rmapp.RMAppImpl: Processing event for application_1559894680121_0001 of type ATTEMPT_REGISTERED
2019-06-07 08:05:09,262 INFO org.apache.hadoop.yarn.server.resourcemanager.rmapp.RMAppImpl: application_1559894680121_0001 State change from ACCEPTED to RUNNING on event=ATTEMPT_REGISTERED
2019-06-07 08:05:09,262 INFO org.apache.hadoop.yarn.server.resourcemanager.rmapp.RMAppImpl: application_1559894680121_0001 State change from ACCEPTED to RUNNING on event=ATTEMPT_REGISTERED
2019-06-07 08:05:09,262 INFO org.apache.hadoop.yarn.server.resourcemanager.RMAuditLogger: USER=root	IP=172.17.0.3	OPERATION=Register App Master	TARGET=ApplicationMasterService	RESULT=SUCCESS	APPID=application_1559894680121_0001	APPATTEMPTID=appattempt_1559894680121_0001_000001
2019-06-07 08:05:09,262 INFO org.apache.hadoop.yarn.server.resourcemanager.RMAuditLogger: USER=root	IP=172.17.0.3	OPERATION=Register App Master	TARGET=ApplicationMasterService	RESULT=SUCCESS	APPID=application_1559894680121_0001	APPATTEMPTID=appattempt_1559894680121_0001_000001
2019-06-07 08:05:09,296 DEBUG org.apache.hadoop.yarn.server.resourcemanager.rmnode.RMNodeImpl: Processing slave1:43282 of type STATUS_UPDATE
2019-06-07 08:05:09,296 DEBUG org.apache.hadoop.yarn.server.resourcemanager.rmnode.RMNodeImpl: Processing slave1:43282 of type STATUS_UPDATE
2019-06-07 08:05:09,296 DEBUG org.apache.hadoop.yarn.server.resourcemanager.scheduler.capacity.CapacityScheduler: nodeUpdate: slave1:43282 clusterResources: <memory:8192, vCores:2>
2019-06-07 08:05:09,296 DEBUG org.apache.hadoop.yarn.server.resourcemanager.scheduler.capacity.CapacityScheduler: nodeUpdate: slave1:43282 clusterResources: <memory:8192, vCores:2>
2019-06-07 08:05:09,296 DEBUG org.apache.hadoop.yarn.server.resourcemanager.scheduler.capacity.CapacityScheduler: Node being looked for scheduling slave1:43282 availableResource: <memory:3072, vCores:0>
2019-06-07 08:05:09,296 DEBUG org.apache.hadoop.yarn.server.resourcemanager.scheduler.capacity.CapacityScheduler: Node being looked for scheduling slave1:43282 availableResource: <memory:3072, vCores:0>
2019-06-07 08:05:09,296 DEBUG org.apache.hadoop.yarn.server.resourcemanager.scheduler.capacity.CapacityScheduler: Trying to schedule on node: slave1, available: <memory:3072, vCores:0>
2019-06-07 08:05:09,296 DEBUG org.apache.hadoop.yarn.server.resourcemanager.scheduler.capacity.CapacityScheduler: Trying to schedule on node: slave1, available: <memory:3072, vCores:0>
2019-06-07 08:05:09,296 DEBUG org.apache.hadoop.yarn.server.resourcemanager.scheduler.capacity.ParentQueue: Skip this queue=root, because it doesn't need more resource, schedulingMode=RESPECT_PARTITION_EXCLUSIVITY node-partition=
2019-06-07 08:05:09,296 DEBUG org.apache.hadoop.yarn.server.resourcemanager.scheduler.capacity.ParentQueue: Skip this queue=root, because it doesn't need more resource, schedulingMode=RESPECT_PARTITION_EXCLUSIVITY node-partition=
2019-06-07 08:05:09,378 DEBUG org.apache.hadoop.yarn.server.resourcemanager.rmapp.attempt.RMAppAttemptImpl: Processing event for appattempt_1559894680121_0001_000001 of type STATUS_UPDATE
2019-06-07 08:05:09,378 DEBUG org.apache.hadoop.yarn.server.resourcemanager.rmapp.attempt.RMAppAttemptImpl: Processing event for appattempt_1559894680121_0001_000001 of type STATUS_UPDATE
2019-06-07 08:05:09,379 DEBUG org.apache.hadoop.yarn.server.resourcemanager.scheduler.capacity.CapacityScheduler: allocate: pre-update appattempt_1559894680121_0001_000001 ask size =1
2019-06-07 08:05:09,379 DEBUG org.apache.hadoop.yarn.server.resourcemanager.scheduler.capacity.CapacityScheduler: allocate: pre-update appattempt_1559894680121_0001_000001 ask size =1
2019-06-07 08:05:09,379 DEBUG org.apache.hadoop.yarn.server.resourcemanager.scheduler.ActiveUsersManager: User root added to activeUsers, currently: 1
2019-06-07 08:05:09,379 DEBUG org.apache.hadoop.yarn.server.resourcemanager.scheduler.ActiveUsersManager: User root added to activeUsers, currently: 1
2019-06-07 08:05:09,379 DEBUG org.apache.hadoop.yarn.server.resourcemanager.scheduler.capacity.CapacityScheduler: allocate: post-update
2019-06-07 08:05:09,379 DEBUG org.apache.hadoop.yarn.server.resourcemanager.scheduler.capacity.CapacityScheduler: allocate: post-update
2019-06-07 08:05:09,379 DEBUG org.apache.hadoop.yarn.server.resourcemanager.scheduler.capacity.LeafQueue: User limit computation for root in queue default userLimitPercent=100 userLimitFactor=1.0 required: <memory:1024, vCores:1> consumed: <memory:1024, vCores:1> user-limit-resource: <memory:8192, vCores:1> queueCapacity: <memory:8192, vCores:1> qconsumed: <memory:1024, vCores:1> consumedRatio: 0.0 currentCapacity: <memory:8192, vCores:1> activeUsers: 1.0 clusterCapacity: <memory:8192, vCores:2> resourceByLabel: <memory:8192, vCores:2> usageratio: 0.125 Partition:  maxUserLimit=<memory:8192, vCores:1> userWeight=1.0
2019-06-07 08:05:09,379 DEBUG org.apache.hadoop.yarn.server.resourcemanager.scheduler.capacity.LeafQueue: User limit computation for root in queue default userLimitPercent=100 userLimitFactor=1.0 required: <memory:1024, vCores:1> consumed: <memory:1024, vCores:1> user-limit-resource: <memory:8192, vCores:1> queueCapacity: <memory:8192, vCores:1> qconsumed: <memory:1024, vCores:1> consumedRatio: 0.0 currentCapacity: <memory:8192, vCores:1> activeUsers: 1.0 clusterCapacity: <memory:8192, vCores:2> resourceByLabel: <memory:8192, vCores:2> usageratio: 0.125 Partition:  maxUserLimit=<memory:8192, vCores:1> userWeight=1.0
2019-06-07 08:05:09,379 DEBUG org.apache.hadoop.yarn.server.resourcemanager.scheduler.SchedulerApplicationAttempt: showRequests: application=application_1559894680121_0001 headRoom=<memory:7168, vCores:1> currentConsumption=1024
2019-06-07 08:05:09,379 DEBUG org.apache.hadoop.yarn.server.resourcemanager.scheduler.SchedulerApplicationAttempt: showRequests: application=application_1559894680121_0001 headRoom=<memory:7168, vCores:1> currentConsumption=1024
2019-06-07 08:05:09,379 DEBUG org.apache.hadoop.yarn.server.resourcemanager.scheduler.SchedulerApplicationAttempt: showRequests: application=application_1559894680121_0001 request={Priority: 1, Capability: <memory:3072, vCores:1>, # Containers: 2, Location: *, Relax Locality: true, Node Label Expression: }
2019-06-07 08:05:09,379 DEBUG org.apache.hadoop.yarn.server.resourcemanager.scheduler.SchedulerApplicationAttempt: showRequests: application=application_1559894680121_0001 request={Priority: 1, Capability: <memory:3072, vCores:1>, # Containers: 2, Location: *, Relax Locality: true, Node Label Expression: }
2019-06-07 08:05:09,379 DEBUG org.apache.hadoop.yarn.server.resourcemanager.scheduler.capacity.LeafQueue: User limit computation for root in queue default userLimitPercent=100 userLimitFactor=1.0 required: <memory:1024, vCores:1> consumed: <memory:1024, vCores:1> user-limit-resource: <memory:8192, vCores:1> queueCapacity: <memory:8192, vCores:1> qconsumed: <memory:1024, vCores:1> consumedRatio: 0.0 currentCapacity: <memory:8192, vCores:1> activeUsers: 1.0 clusterCapacity: <memory:8192, vCores:2> resourceByLabel: <memory:8192, vCores:2> usageratio: 0.125 Partition:  maxUserLimit=<memory:8192, vCores:1> userWeight=1.0
2019-06-07 08:05:09,379 DEBUG org.apache.hadoop.yarn.server.resourcemanager.scheduler.capacity.LeafQueue: User limit computation for root in queue default userLimitPercent=100 userLimitFactor=1.0 required: <memory:1024, vCores:1> consumed: <memory:1024, vCores:1> user-limit-resource: <memory:8192, vCores:1> queueCapacity: <memory:8192, vCores:1> qconsumed: <memory:1024, vCores:1> consumedRatio: 0.0 currentCapacity: <memory:8192, vCores:1> activeUsers: 1.0 clusterCapacity: <memory:8192, vCores:2> resourceByLabel: <memory:8192, vCores:2> usageratio: 0.125 Partition:  maxUserLimit=<memory:8192, vCores:1> userWeight=1.0
2019-06-07 08:05:09,404 DEBUG org.apache.hadoop.yarn.server.resourcemanager.rmapp.attempt.RMAppAttemptImpl: Processing event for appattempt_1559894680121_0001_000001 of type STATUS_UPDATE
2019-06-07 08:05:09,404 DEBUG org.apache.hadoop.yarn.server.resourcemanager.rmapp.attempt.RMAppAttemptImpl: Processing event for appattempt_1559894680121_0001_000001 of type STATUS_UPDATE
2019-06-07 08:05:09,408 DEBUG org.apache.hadoop.yarn.server.resourcemanager.scheduler.capacity.LeafQueue: User limit computation for root in queue default userLimitPercent=100 userLimitFactor=1.0 required: <memory:1024, vCores:1> consumed: <memory:1024, vCores:1> user-limit-resource: <memory:8192, vCores:1> queueCapacity: <memory:8192, vCores:1> qconsumed: <memory:1024, vCores:1> consumedRatio: 0.0 currentCapacity: <memory:8192, vCores:1> activeUsers: 1.0 clusterCapacity: <memory:8192, vCores:2> resourceByLabel: <memory:8192, vCores:2> usageratio: 0.125 Partition:  maxUserLimit=<memory:8192, vCores:1> userWeight=1.0
2019-06-07 08:05:09,408 DEBUG org.apache.hadoop.yarn.server.resourcemanager.scheduler.capacity.LeafQueue: User limit computation for root in queue default userLimitPercent=100 userLimitFactor=1.0 required: <memory:1024, vCores:1> consumed: <memory:1024, vCores:1> user-limit-resource: <memory:8192, vCores:1> queueCapacity: <memory:8192, vCores:1> qconsumed: <memory:1024, vCores:1> consumedRatio: 0.0 currentCapacity: <memory:8192, vCores:1> activeUsers: 1.0 clusterCapacity: <memory:8192, vCores:2> resourceByLabel: <memory:8192, vCores:2> usageratio: 0.125 Partition:  maxUserLimit=<memory:8192, vCores:1> userWeight=1.0
2019-06-07 08:05:09,620 DEBUG org.apache.hadoop.yarn.server.resourcemanager.rmapp.attempt.RMAppAttemptImpl: Processing event for appattempt_1559894680121_0001_000001 of type STATUS_UPDATE
2019-06-07 08:05:09,620 DEBUG org.apache.hadoop.yarn.server.resourcemanager.rmapp.attempt.RMAppAttemptImpl: Processing event for appattempt_1559894680121_0001_000001 of type STATUS_UPDATE
2019-06-07 08:05:09,621 DEBUG org.apache.hadoop.yarn.server.resourcemanager.scheduler.capacity.LeafQueue: User limit computation for root in queue default userLimitPercent=100 userLimitFactor=1.0 required: <memory:1024, vCores:1> consumed: <memory:1024, vCores:1> user-limit-resource: <memory:8192, vCores:1> queueCapacity: <memory:8192, vCores:1> qconsumed: <memory:1024, vCores:1> consumedRatio: 0.0 currentCapacity: <memory:8192, vCores:1> activeUsers: 1.0 clusterCapacity: <memory:8192, vCores:2> resourceByLabel: <memory:8192, vCores:2> usageratio: 0.125 Partition:  maxUserLimit=<memory:8192, vCores:1> userWeight=1.0
2019-06-07 08:05:09,621 DEBUG org.apache.hadoop.yarn.server.resourcemanager.scheduler.capacity.LeafQueue: User limit computation for root in queue default userLimitPercent=100 userLimitFactor=1.0 required: <memory:1024, vCores:1> consumed: <memory:1024, vCores:1> user-limit-resource: <memory:8192, vCores:1> queueCapacity: <memory:8192, vCores:1> qconsumed: <memory:1024, vCores:1> consumedRatio: 0.0 currentCapacity: <memory:8192, vCores:1> activeUsers: 1.0 clusterCapacity: <memory:8192, vCores:2> resourceByLabel: <memory:8192, vCores:2> usageratio: 0.125 Partition:  maxUserLimit=<memory:8192, vCores:1> userWeight=1.0
2019-06-07 08:05:10,027 DEBUG org.apache.hadoop.yarn.server.resourcemanager.rmapp.attempt.RMAppAttemptImpl: Processing event for appattempt_1559894680121_0001_000001 of type STATUS_UPDATE
2019-06-07 08:05:10,027 DEBUG org.apache.hadoop.yarn.server.resourcemanager.rmapp.attempt.RMAppAttemptImpl: Processing event for appattempt_1559894680121_0001_000001 of type STATUS_UPDATE
2019-06-07 08:05:10,027 DEBUG org.apache.hadoop.yarn.server.resourcemanager.scheduler.capacity.LeafQueue: User limit computation for root in queue default userLimitPercent=100 userLimitFactor=1.0 required: <memory:1024, vCores:1> consumed: <memory:1024, vCores:1> user-limit-resource: <memory:8192, vCores:1> queueCapacity: <memory:8192, vCores:1> qconsumed: <memory:1024, vCores:1> consumedRatio: 0.0 currentCapacity: <memory:8192, vCores:1> activeUsers: 1.0 clusterCapacity: <memory:8192, vCores:2> resourceByLabel: <memory:8192, vCores:2> usageratio: 0.125 Partition:  maxUserLimit=<memory:8192, vCores:1> userWeight=1.0
2019-06-07 08:05:10,027 DEBUG org.apache.hadoop.yarn.server.resourcemanager.scheduler.capacity.LeafQueue: User limit computation for root in queue default userLimitPercent=100 userLimitFactor=1.0 required: <memory:1024, vCores:1> consumed: <memory:1024, vCores:1> user-limit-resource: <memory:8192, vCores:1> queueCapacity: <memory:8192, vCores:1> qconsumed: <memory:1024, vCores:1> consumedRatio: 0.0 currentCapacity: <memory:8192, vCores:1> activeUsers: 1.0 clusterCapacity: <memory:8192, vCores:2> resourceByLabel: <memory:8192, vCores:2> usageratio: 0.125 Partition:  maxUserLimit=<memory:8192, vCores:1> userWeight=1.0
2019-06-07 08:05:10,248 DEBUG org.apache.hadoop.yarn.server.resourcemanager.rmnode.RMNodeImpl: Processing slave2:37804 of type STATUS_UPDATE
2019-06-07 08:05:10,248 DEBUG org.apache.hadoop.yarn.server.resourcemanager.rmnode.RMNodeImpl: Processing slave2:37804 of type STATUS_UPDATE
2019-06-07 08:05:10,249 DEBUG org.apache.hadoop.yarn.server.resourcemanager.scheduler.capacity.CapacityScheduler: nodeUpdate: slave2:37804 clusterResources: <memory:8192, vCores:2>
2019-06-07 08:05:10,249 DEBUG org.apache.hadoop.yarn.server.resourcemanager.scheduler.capacity.CapacityScheduler: nodeUpdate: slave2:37804 clusterResources: <memory:8192, vCores:2>
2019-06-07 08:05:10,250 DEBUG org.apache.hadoop.yarn.server.resourcemanager.scheduler.capacity.CapacityScheduler: Node being looked for scheduling slave2:37804 availableResource: <memory:4096, vCores:1>
2019-06-07 08:05:10,250 DEBUG org.apache.hadoop.yarn.server.resourcemanager.scheduler.capacity.CapacityScheduler: Node being looked for scheduling slave2:37804 availableResource: <memory:4096, vCores:1>
2019-06-07 08:05:10,250 DEBUG org.apache.hadoop.yarn.server.resourcemanager.scheduler.capacity.CapacityScheduler: Trying to schedule on node: slave2, available: <memory:4096, vCores:1>
2019-06-07 08:05:10,250 DEBUG org.apache.hadoop.yarn.server.resourcemanager.scheduler.capacity.CapacityScheduler: Trying to schedule on node: slave2, available: <memory:4096, vCores:1>
2019-06-07 08:05:10,250 DEBUG org.apache.hadoop.yarn.server.resourcemanager.scheduler.capacity.ParentQueue: Trying to assign containers to child-queue of root
2019-06-07 08:05:10,250 DEBUG org.apache.hadoop.yarn.server.resourcemanager.scheduler.capacity.ParentQueue: Trying to assign containers to child-queue of root
2019-06-07 08:05:10,250 DEBUG org.apache.hadoop.yarn.server.resourcemanager.scheduler.capacity.ParentQueue: printChildQueues - queue: root child-queues: root.defaultusedCapacity=(0.125),  label=(*)
2019-06-07 08:05:10,250 DEBUG org.apache.hadoop.yarn.server.resourcemanager.scheduler.capacity.ParentQueue: printChildQueues - queue: root child-queues: root.defaultusedCapacity=(0.125),  label=(*)
2019-06-07 08:05:10,250 DEBUG org.apache.hadoop.yarn.server.resourcemanager.scheduler.capacity.ParentQueue: Trying to assign to queue: root.default stats: default: capacity=1.0, absoluteCapacity=1.0, usedResources=<memory:1024, vCores:1>, usedCapacity=0.125, absoluteUsedCapacity=0.125, numApps=1, numContainers=1
2019-06-07 08:05:10,250 DEBUG org.apache.hadoop.yarn.server.resourcemanager.scheduler.capacity.ParentQueue: Trying to assign to queue: root.default stats: default: capacity=1.0, absoluteCapacity=1.0, usedResources=<memory:1024, vCores:1>, usedCapacity=0.125, absoluteUsedCapacity=0.125, numApps=1, numContainers=1
2019-06-07 08:05:10,250 DEBUG org.apache.hadoop.yarn.server.resourcemanager.scheduler.capacity.LeafQueue: assignContainers: node=slave2 #applications=1
2019-06-07 08:05:10,250 DEBUG org.apache.hadoop.yarn.server.resourcemanager.scheduler.capacity.LeafQueue: assignContainers: node=slave2 #applications=1
2019-06-07 08:05:10,250 DEBUG org.apache.hadoop.yarn.server.resourcemanager.scheduler.capacity.LeafQueue: User limit computation for root in queue default userLimitPercent=100 userLimitFactor=1.0 required: <memory:1024, vCores:1> consumed: <memory:1024, vCores:1> user-limit-resource: <memory:8192, vCores:1> queueCapacity: <memory:8192, vCores:1> qconsumed: <memory:1024, vCores:1> consumedRatio: 0.0 currentCapacity: <memory:8192, vCores:1> activeUsers: 1.0 clusterCapacity: <memory:8192, vCores:2> resourceByLabel: <memory:8192, vCores:2> usageratio: 0.125 Partition:  maxUserLimit=<memory:8192, vCores:1> userWeight=1.0
2019-06-07 08:05:10,250 DEBUG org.apache.hadoop.yarn.server.resourcemanager.scheduler.capacity.LeafQueue: User limit computation for root in queue default userLimitPercent=100 userLimitFactor=1.0 required: <memory:1024, vCores:1> consumed: <memory:1024, vCores:1> user-limit-resource: <memory:8192, vCores:1> queueCapacity: <memory:8192, vCores:1> qconsumed: <memory:1024, vCores:1> consumedRatio: 0.0 currentCapacity: <memory:8192, vCores:1> activeUsers: 1.0 clusterCapacity: <memory:8192, vCores:2> resourceByLabel: <memory:8192, vCores:2> usageratio: 0.125 Partition:  maxUserLimit=<memory:8192, vCores:1> userWeight=1.0
2019-06-07 08:05:10,250 DEBUG org.apache.hadoop.yarn.server.resourcemanager.scheduler.capacity.LeafQueue: Headroom calculation for user root:  userLimit=<memory:8192, vCores:1> queueMaxAvailRes=<memory:8192, vCores:1> consumed=<memory:1024, vCores:1>
2019-06-07 08:05:10,250 DEBUG org.apache.hadoop.yarn.server.resourcemanager.scheduler.capacity.LeafQueue: Headroom calculation for user root:  userLimit=<memory:8192, vCores:1> queueMaxAvailRes=<memory:8192, vCores:1> consumed=<memory:1024, vCores:1>
2019-06-07 08:05:10,250 DEBUG org.apache.hadoop.yarn.server.resourcemanager.scheduler.common.fica.FiCaSchedulerApp: pre-assignContainers for application application_1559894680121_0001
2019-06-07 08:05:10,250 DEBUG org.apache.hadoop.yarn.server.resourcemanager.scheduler.common.fica.FiCaSchedulerApp: pre-assignContainers for application application_1559894680121_0001
2019-06-07 08:05:10,251 DEBUG org.apache.hadoop.yarn.server.resourcemanager.scheduler.capacity.LeafQueue: User limit computation for root in queue default userLimitPercent=100 userLimitFactor=1.0 required: <memory:1024, vCores:1> consumed: <memory:1024, vCores:1> user-limit-resource: <memory:8192, vCores:1> queueCapacity: <memory:8192, vCores:1> qconsumed: <memory:1024, vCores:1> consumedRatio: 0.0 currentCapacity: <memory:8192, vCores:1> activeUsers: 1.0 clusterCapacity: <memory:8192, vCores:2> resourceByLabel: <memory:8192, vCores:2> usageratio: 0.125 Partition:  maxUserLimit=<memory:8192, vCores:1> userWeight=1.0
2019-06-07 08:05:10,251 DEBUG org.apache.hadoop.yarn.server.resourcemanager.scheduler.capacity.LeafQueue: User limit computation for root in queue default userLimitPercent=100 userLimitFactor=1.0 required: <memory:1024, vCores:1> consumed: <memory:1024, vCores:1> user-limit-resource: <memory:8192, vCores:1> queueCapacity: <memory:8192, vCores:1> qconsumed: <memory:1024, vCores:1> consumedRatio: 0.0 currentCapacity: <memory:8192, vCores:1> activeUsers: 1.0 clusterCapacity: <memory:8192, vCores:2> resourceByLabel: <memory:8192, vCores:2> usageratio: 0.125 Partition:  maxUserLimit=<memory:8192, vCores:1> userWeight=1.0
2019-06-07 08:05:10,251 DEBUG org.apache.hadoop.yarn.server.resourcemanager.scheduler.SchedulerApplicationAttempt: showRequests: application=application_1559894680121_0001 headRoom=<memory:7168, vCores:1> currentConsumption=1024
2019-06-07 08:05:10,251 DEBUG org.apache.hadoop.yarn.server.resourcemanager.scheduler.SchedulerApplicationAttempt: showRequests: application=application_1559894680121_0001 headRoom=<memory:7168, vCores:1> currentConsumption=1024
2019-06-07 08:05:10,251 DEBUG org.apache.hadoop.yarn.server.resourcemanager.scheduler.SchedulerApplicationAttempt: showRequests: application=application_1559894680121_0001 request={Priority: 1, Capability: <memory:3072, vCores:1>, # Containers: 2, Location: *, Relax Locality: true, Node Label Expression: }
2019-06-07 08:05:10,251 DEBUG org.apache.hadoop.yarn.server.resourcemanager.scheduler.SchedulerApplicationAttempt: showRequests: application=application_1559894680121_0001 request={Priority: 1, Capability: <memory:3072, vCores:1>, # Containers: 2, Location: *, Relax Locality: true, Node Label Expression: }
2019-06-07 08:05:10,251 DEBUG org.apache.hadoop.yarn.server.resourcemanager.scheduler.capacity.allocator.IncreaseContainerAllocator: Skip allocating increase request since we don't have any increase request on this node=slave2:37804
2019-06-07 08:05:10,251 DEBUG org.apache.hadoop.yarn.server.resourcemanager.scheduler.capacity.allocator.IncreaseContainerAllocator: Skip allocating increase request since we don't have any increase request on this node=slave2:37804
2019-06-07 08:05:10,251 DEBUG org.apache.hadoop.yarn.server.resourcemanager.scheduler.capacity.allocator.RegularContainerAllocator: assignContainers: node=slave2 application=application_1559894680121_0001 priority=1 request={Priority: 1, Capability: <memory:3072, vCores:1>, # Containers: 2, Location: *, Relax Locality: true, Node Label Expression: } type=OFF_SWITCH
2019-06-07 08:05:10,251 DEBUG org.apache.hadoop.yarn.server.resourcemanager.scheduler.capacity.allocator.RegularContainerAllocator: assignContainers: node=slave2 application=application_1559894680121_0001 priority=1 request={Priority: 1, Capability: <memory:3072, vCores:1>, # Containers: 2, Location: *, Relax Locality: true, Node Label Expression: } type=OFF_SWITCH
2019-06-07 08:05:10,252 DEBUG org.apache.hadoop.yarn.server.resourcemanager.scheduler.AppSchedulingInfo: allocate: applicationId=application_1559894680121_0001 container=container_1559894680121_0001_01_000002 host=slave2:37804 user=root resource=<memory:3072, vCores:1> type=OFF_SWITCH
2019-06-07 08:05:10,252 DEBUG org.apache.hadoop.yarn.server.resourcemanager.scheduler.AppSchedulingInfo: allocate: applicationId=application_1559894680121_0001 container=container_1559894680121_0001_01_000002 host=slave2:37804 user=root resource=<memory:3072, vCores:1> type=OFF_SWITCH
2019-06-07 08:05:10,252 DEBUG org.apache.hadoop.yarn.server.resourcemanager.rmcontainer.RMContainerImpl: Processing container_1559894680121_0001_01_000002 of type START
2019-06-07 08:05:10,252 DEBUG org.apache.hadoop.yarn.server.resourcemanager.rmcontainer.RMContainerImpl: Processing container_1559894680121_0001_01_000002 of type START
2019-06-07 08:05:10,252 INFO org.apache.hadoop.yarn.server.resourcemanager.rmcontainer.RMContainerImpl: container_1559894680121_0001_01_000002 Container Transitioned from NEW to ALLOCATED
2019-06-07 08:05:10,252 INFO org.apache.hadoop.yarn.server.resourcemanager.rmcontainer.RMContainerImpl: container_1559894680121_0001_01_000002 Container Transitioned from NEW to ALLOCATED
2019-06-07 08:05:10,252 DEBUG org.apache.hadoop.yarn.server.resourcemanager.scheduler.common.fica.FiCaSchedulerApp: allocate: applicationAttemptId=appattempt_1559894680121_0001_000001 container=container_1559894680121_0001_01_000002 host=slave2 type=OFF_SWITCH
2019-06-07 08:05:10,252 DEBUG org.apache.hadoop.yarn.server.resourcemanager.scheduler.common.fica.FiCaSchedulerApp: allocate: applicationAttemptId=appattempt_1559894680121_0001_000001 container=container_1559894680121_0001_01_000002 host=slave2 type=OFF_SWITCH
2019-06-07 08:05:10,252 INFO org.apache.hadoop.yarn.server.resourcemanager.RMAuditLogger: USER=root	OPERATION=AM Allocated Container	TARGET=SchedulerApp	RESULT=SUCCESS	APPID=application_1559894680121_0001	CONTAINERID=container_1559894680121_0001_01_000002
2019-06-07 08:05:10,252 INFO org.apache.hadoop.yarn.server.resourcemanager.RMAuditLogger: USER=root	OPERATION=AM Allocated Container	TARGET=SchedulerApp	RESULT=SUCCESS	APPID=application_1559894680121_0001	CONTAINERID=container_1559894680121_0001_01_000002
2019-06-07 08:05:10,252 INFO org.apache.hadoop.yarn.server.resourcemanager.scheduler.SchedulerNode: Assigned container container_1559894680121_0001_01_000002 of capacity <memory:3072, vCores:1> on host slave2:37804, which has 1 containers, <memory:3072, vCores:1> used and <memory:1024, vCores:0> available after allocation
2019-06-07 08:05:10,252 INFO org.apache.hadoop.yarn.server.resourcemanager.scheduler.SchedulerNode: Assigned container container_1559894680121_0001_01_000002 of capacity <memory:3072, vCores:1> on host slave2:37804, which has 1 containers, <memory:3072, vCores:1> used and <memory:1024, vCores:0> available after allocation
2019-06-07 08:05:10,252 INFO org.apache.hadoop.yarn.server.resourcemanager.scheduler.capacity.allocator.AbstractContainerAllocator: assignedContainer application attempt=appattempt_1559894680121_0001_000001 container=container_1559894680121_0001_01_000002 queue=org.apache.hadoop.yarn.server.resourcemanager.scheduler.capacity.allocator.RegularContainerAllocator@530da2a5 clusterResource=<memory:8192, vCores:2> type=OFF_SWITCH requestedPartition=
2019-06-07 08:05:10,252 INFO org.apache.hadoop.yarn.server.resourcemanager.scheduler.capacity.allocator.AbstractContainerAllocator: assignedContainer application attempt=appattempt_1559894680121_0001_000001 container=container_1559894680121_0001_01_000002 queue=org.apache.hadoop.yarn.server.resourcemanager.scheduler.capacity.allocator.RegularContainerAllocator@530da2a5 clusterResource=<memory:8192, vCores:2> type=OFF_SWITCH requestedPartition=
2019-06-07 08:05:10,252 DEBUG org.apache.hadoop.yarn.server.resourcemanager.scheduler.capacity.LeafQueue: post-assignContainers for application application_1559894680121_0001
2019-06-07 08:05:10,252 DEBUG org.apache.hadoop.yarn.server.resourcemanager.scheduler.capacity.LeafQueue: post-assignContainers for application application_1559894680121_0001
2019-06-07 08:05:10,252 DEBUG org.apache.hadoop.yarn.server.resourcemanager.scheduler.capacity.LeafQueue: User limit computation for root in queue default userLimitPercent=100 userLimitFactor=1.0 required: <memory:1024, vCores:1> consumed: <memory:1024, vCores:1> user-limit-resource: <memory:8192, vCores:1> queueCapacity: <memory:8192, vCores:1> qconsumed: <memory:1024, vCores:1> consumedRatio: 0.0 currentCapacity: <memory:8192, vCores:1> activeUsers: 1.0 clusterCapacity: <memory:8192, vCores:2> resourceByLabel: <memory:8192, vCores:2> usageratio: 0.125 Partition:  maxUserLimit=<memory:8192, vCores:1> userWeight=1.0
2019-06-07 08:05:10,252 DEBUG org.apache.hadoop.yarn.server.resourcemanager.scheduler.capacity.LeafQueue: User limit computation for root in queue default userLimitPercent=100 userLimitFactor=1.0 required: <memory:1024, vCores:1> consumed: <memory:1024, vCores:1> user-limit-resource: <memory:8192, vCores:1> queueCapacity: <memory:8192, vCores:1> qconsumed: <memory:1024, vCores:1> consumedRatio: 0.0 currentCapacity: <memory:8192, vCores:1> activeUsers: 1.0 clusterCapacity: <memory:8192, vCores:2> resourceByLabel: <memory:8192, vCores:2> usageratio: 0.125 Partition:  maxUserLimit=<memory:8192, vCores:1> userWeight=1.0
2019-06-07 08:05:10,252 DEBUG org.apache.hadoop.yarn.server.resourcemanager.scheduler.SchedulerApplicationAttempt: showRequests: application=application_1559894680121_0001 headRoom=<memory:7168, vCores:1> currentConsumption=4096
2019-06-07 08:05:10,252 DEBUG org.apache.hadoop.yarn.server.resourcemanager.scheduler.SchedulerApplicationAttempt: showRequests: application=application_1559894680121_0001 headRoom=<memory:7168, vCores:1> currentConsumption=4096
2019-06-07 08:05:10,252 DEBUG org.apache.hadoop.yarn.server.resourcemanager.scheduler.SchedulerApplicationAttempt: showRequests: application=application_1559894680121_0001 request={Priority: 1, Capability: <memory:3072, vCores:1>, # Containers: 1, Location: *, Relax Locality: true, Node Label Expression: }
2019-06-07 08:05:10,252 DEBUG org.apache.hadoop.yarn.server.resourcemanager.scheduler.SchedulerApplicationAttempt: showRequests: application=application_1559894680121_0001 request={Priority: 1, Capability: <memory:3072, vCores:1>, # Containers: 1, Location: *, Relax Locality: true, Node Label Expression: }
2019-06-07 08:05:10,252 DEBUG org.apache.hadoop.yarn.server.resourcemanager.scheduler.capacity.LeafQueue: User limit computation for root in queue default userLimitPercent=100 userLimitFactor=1.0 required: <memory:1024, vCores:1> consumed: <memory:4096, vCores:1> user-limit-resource: <memory:8192, vCores:1> queueCapacity: <memory:8192, vCores:1> qconsumed: <memory:4096, vCores:2> consumedRatio: 0.0 currentCapacity: <memory:8192, vCores:1> activeUsers: 1.0 clusterCapacity: <memory:8192, vCores:2> resourceByLabel: <memory:8192, vCores:2> usageratio: 0.5 Partition:  maxUserLimit=<memory:8192, vCores:1> userWeight=1.0
2019-06-07 08:05:10,252 DEBUG org.apache.hadoop.yarn.server.resourcemanager.scheduler.capacity.LeafQueue: User limit computation for root in queue default userLimitPercent=100 userLimitFactor=1.0 required: <memory:1024, vCores:1> consumed: <memory:4096, vCores:1> user-limit-resource: <memory:8192, vCores:1> queueCapacity: <memory:8192, vCores:1> qconsumed: <memory:4096, vCores:2> consumedRatio: 0.0 currentCapacity: <memory:8192, vCores:1> activeUsers: 1.0 clusterCapacity: <memory:8192, vCores:2> resourceByLabel: <memory:8192, vCores:2> usageratio: 0.5 Partition:  maxUserLimit=<memory:8192, vCores:1> userWeight=1.0
2019-06-07 08:05:10,253 DEBUG org.apache.hadoop.yarn.server.resourcemanager.scheduler.capacity.LeafQueue: User limit computation for root in queue default userLimitPercent=100 userLimitFactor=1.0 required: <memory:1024, vCores:1> consumed: <memory:4096, vCores:1> user-limit-resource: <memory:8192, vCores:1> queueCapacity: <memory:8192, vCores:1> qconsumed: <memory:4096, vCores:2> consumedRatio: 0.0 currentCapacity: <memory:8192, vCores:1> activeUsers: 1.0 clusterCapacity: <memory:8192, vCores:2> resourceByLabel: <memory:8192, vCores:2> usageratio: 0.5 Partition:  maxUserLimit=<memory:8192, vCores:1> userWeight=1.0
2019-06-07 08:05:10,253 DEBUG org.apache.hadoop.yarn.server.resourcemanager.scheduler.capacity.LeafQueue: User limit computation for root in queue default userLimitPercent=100 userLimitFactor=1.0 required: <memory:1024, vCores:1> consumed: <memory:4096, vCores:1> user-limit-resource: <memory:8192, vCores:1> queueCapacity: <memory:8192, vCores:1> qconsumed: <memory:4096, vCores:2> consumedRatio: 0.0 currentCapacity: <memory:8192, vCores:1> activeUsers: 1.0 clusterCapacity: <memory:8192, vCores:2> resourceByLabel: <memory:8192, vCores:2> usageratio: 0.5 Partition:  maxUserLimit=<memory:8192, vCores:1> userWeight=1.0
2019-06-07 08:05:10,253 DEBUG org.apache.hadoop.yarn.server.resourcemanager.scheduler.capacity.LeafQueue: User limit computation for root in queue default userLimitPercent=100 userLimitFactor=1.0 required: <memory:1024, vCores:1> consumed: <memory:4096, vCores:1> user-limit-resource: <memory:8192, vCores:1> queueCapacity: <memory:8192, vCores:1> qconsumed: <memory:4096, vCores:2> consumedRatio: 0.0 currentCapacity: <memory:8192, vCores:1> activeUsers: 1.0 clusterCapacity: <memory:8192, vCores:2> resourceByLabel: <memory:8192, vCores:2> usageratio: 0.5 Partition:  maxUserLimit=<memory:8192, vCores:1> userWeight=1.0
2019-06-07 08:05:10,253 DEBUG org.apache.hadoop.yarn.server.resourcemanager.scheduler.capacity.LeafQueue: User limit computation for root in queue default userLimitPercent=100 userLimitFactor=1.0 required: <memory:1024, vCores:1> consumed: <memory:4096, vCores:1> user-limit-resource: <memory:8192, vCores:1> queueCapacity: <memory:8192, vCores:1> qconsumed: <memory:4096, vCores:2> consumedRatio: 0.0 currentCapacity: <memory:8192, vCores:1> activeUsers: 1.0 clusterCapacity: <memory:8192, vCores:2> resourceByLabel: <memory:8192, vCores:2> usageratio: 0.5 Partition:  maxUserLimit=<memory:8192, vCores:1> userWeight=1.0
2019-06-07 08:05:10,253 DEBUG org.apache.hadoop.yarn.server.resourcemanager.scheduler.capacity.LeafQueue: default user=root used=<memory:4096, vCores:2> numContainers=2 headroom = <memory:4096, vCores:1> user-resources=<memory:4096, vCores:2>
2019-06-07 08:05:10,253 DEBUG org.apache.hadoop.yarn.server.resourcemanager.scheduler.capacity.LeafQueue: default user=root used=<memory:4096, vCores:2> numContainers=2 headroom = <memory:4096, vCores:1> user-resources=<memory:4096, vCores:2>
2019-06-07 08:05:10,253 DEBUG org.apache.hadoop.yarn.server.resourcemanager.scheduler.capacity.ParentQueue: Assigned to queue: root.default stats: default: capacity=1.0, absoluteCapacity=1.0, usedResources=<memory:4096, vCores:2>, usedCapacity=0.5, absoluteUsedCapacity=0.5, numApps=1, numContainers=2 --> <memory:3072, vCores:1>, OFF_SWITCH
2019-06-07 08:05:10,253 DEBUG org.apache.hadoop.yarn.server.resourcemanager.scheduler.capacity.ParentQueue: Assigned to queue: root.default stats: default: capacity=1.0, absoluteCapacity=1.0, usedResources=<memory:4096, vCores:2>, usedCapacity=0.5, absoluteUsedCapacity=0.5, numApps=1, numContainers=2 --> <memory:3072, vCores:1>, OFF_SWITCH
2019-06-07 08:05:10,253 INFO org.apache.hadoop.yarn.server.resourcemanager.scheduler.capacity.ParentQueue: Re-sorting assigned queue: root.default stats: default: capacity=1.0, absoluteCapacity=1.0, usedResources=<memory:4096, vCores:2>, usedCapacity=0.5, absoluteUsedCapacity=0.5, numApps=1, numContainers=2
2019-06-07 08:05:10,253 INFO org.apache.hadoop.yarn.server.resourcemanager.scheduler.capacity.ParentQueue: Re-sorting assigned queue: root.default stats: default: capacity=1.0, absoluteCapacity=1.0, usedResources=<memory:4096, vCores:2>, usedCapacity=0.5, absoluteUsedCapacity=0.5, numApps=1, numContainers=2
2019-06-07 08:05:10,253 DEBUG org.apache.hadoop.yarn.server.resourcemanager.scheduler.capacity.ParentQueue: printChildQueues - queue: root child-queues: root.defaultusedCapacity=(0.5),  label=(*)
2019-06-07 08:05:10,253 DEBUG org.apache.hadoop.yarn.server.resourcemanager.scheduler.capacity.ParentQueue: printChildQueues - queue: root child-queues: root.defaultusedCapacity=(0.5),  label=(*)
2019-06-07 08:05:10,253 INFO org.apache.hadoop.yarn.server.resourcemanager.scheduler.capacity.ParentQueue: assignedContainer queue=root usedCapacity=0.5 absoluteUsedCapacity=0.5 used=<memory:4096, vCores:2> cluster=<memory:8192, vCores:2>
2019-06-07 08:05:10,253 INFO org.apache.hadoop.yarn.server.resourcemanager.scheduler.capacity.ParentQueue: assignedContainer queue=root usedCapacity=0.5 absoluteUsedCapacity=0.5 used=<memory:4096, vCores:2> cluster=<memory:8192, vCores:2>
2019-06-07 08:05:10,253 DEBUG org.apache.hadoop.yarn.server.resourcemanager.scheduler.capacity.ParentQueue: ParentQ=root assignedSoFarInThisIteration=<memory:3072, vCores:1> usedCapacity=0.5 absoluteUsedCapacity=0.5
2019-06-07 08:05:10,253 DEBUG org.apache.hadoop.yarn.server.resourcemanager.scheduler.capacity.ParentQueue: ParentQ=root assignedSoFarInThisIteration=<memory:3072, vCores:1> usedCapacity=0.5 absoluteUsedCapacity=0.5
2019-06-07 08:05:10,253 DEBUG org.apache.hadoop.yarn.server.resourcemanager.scheduler.capacity.ParentQueue: Assigned maximum number of off-switch containers: 1, assignments so far: resource:<memory:3072, vCores:1>; type:OFF_SWITCH; excessReservation:null; applicationid:null; skipped:NONE; fulfilled reservation:false; allocations(count/resource):1/<memory:3072, vCores:1>; reservations(count/resource):0/<memory:0, vCores:0>
2019-06-07 08:05:10,253 DEBUG org.apache.hadoop.yarn.server.resourcemanager.scheduler.capacity.ParentQueue: Assigned maximum number of off-switch containers: 1, assignments so far: resource:<memory:3072, vCores:1>; type:OFF_SWITCH; excessReservation:null; applicationid:null; skipped:NONE; fulfilled reservation:false; allocations(count/resource):1/<memory:3072, vCores:1>; reservations(count/resource):0/<memory:0, vCores:0>
2019-06-07 08:05:10,253 DEBUG org.apache.hadoop.yarn.server.resourcemanager.rmapp.attempt.RMAppAttemptImpl: Processing event for appattempt_1559894680121_0001_000001 of type CONTAINER_ALLOCATED
2019-06-07 08:05:10,253 DEBUG org.apache.hadoop.yarn.server.resourcemanager.rmapp.attempt.RMAppAttemptImpl: Processing event for appattempt_1559894680121_0001_000001 of type CONTAINER_ALLOCATED
2019-06-07 08:05:10,303 DEBUG org.apache.hadoop.yarn.server.resourcemanager.rmnode.RMNodeImpl: Processing slave1:43282 of type STATUS_UPDATE
2019-06-07 08:05:10,303 DEBUG org.apache.hadoop.yarn.server.resourcemanager.rmnode.RMNodeImpl: Processing slave1:43282 of type STATUS_UPDATE
2019-06-07 08:05:10,304 DEBUG org.apache.hadoop.yarn.server.resourcemanager.scheduler.capacity.CapacityScheduler: nodeUpdate: slave1:43282 clusterResources: <memory:8192, vCores:2>
2019-06-07 08:05:10,304 DEBUG org.apache.hadoop.yarn.server.resourcemanager.scheduler.capacity.CapacityScheduler: nodeUpdate: slave1:43282 clusterResources: <memory:8192, vCores:2>
2019-06-07 08:05:10,304 DEBUG org.apache.hadoop.yarn.server.resourcemanager.scheduler.capacity.CapacityScheduler: Node being looked for scheduling slave1:43282 availableResource: <memory:3072, vCores:0>
2019-06-07 08:05:10,304 DEBUG org.apache.hadoop.yarn.server.resourcemanager.scheduler.capacity.CapacityScheduler: Node being looked for scheduling slave1:43282 availableResource: <memory:3072, vCores:0>
2019-06-07 08:05:10,304 DEBUG org.apache.hadoop.yarn.server.resourcemanager.scheduler.capacity.CapacityScheduler: Trying to schedule on node: slave1, available: <memory:3072, vCores:0>
2019-06-07 08:05:10,304 DEBUG org.apache.hadoop.yarn.server.resourcemanager.scheduler.capacity.CapacityScheduler: Trying to schedule on node: slave1, available: <memory:3072, vCores:0>
2019-06-07 08:05:10,304 DEBUG org.apache.hadoop.yarn.server.resourcemanager.scheduler.capacity.ParentQueue: Trying to assign containers to child-queue of root
2019-06-07 08:05:10,304 DEBUG org.apache.hadoop.yarn.server.resourcemanager.scheduler.capacity.ParentQueue: Trying to assign containers to child-queue of root
2019-06-07 08:05:10,304 DEBUG org.apache.hadoop.yarn.server.resourcemanager.scheduler.capacity.ParentQueue: printChildQueues - queue: root child-queues: root.defaultusedCapacity=(0.5),  label=(*)
2019-06-07 08:05:10,304 DEBUG org.apache.hadoop.yarn.server.resourcemanager.scheduler.capacity.ParentQueue: printChildQueues - queue: root child-queues: root.defaultusedCapacity=(0.5),  label=(*)
2019-06-07 08:05:10,304 DEBUG org.apache.hadoop.yarn.server.resourcemanager.scheduler.capacity.ParentQueue: Trying to assign to queue: root.default stats: default: capacity=1.0, absoluteCapacity=1.0, usedResources=<memory:4096, vCores:2>, usedCapacity=0.5, absoluteUsedCapacity=0.5, numApps=1, numContainers=2
2019-06-07 08:05:10,304 DEBUG org.apache.hadoop.yarn.server.resourcemanager.scheduler.capacity.ParentQueue: Trying to assign to queue: root.default stats: default: capacity=1.0, absoluteCapacity=1.0, usedResources=<memory:4096, vCores:2>, usedCapacity=0.5, absoluteUsedCapacity=0.5, numApps=1, numContainers=2
2019-06-07 08:05:10,304 DEBUG org.apache.hadoop.yarn.server.resourcemanager.scheduler.capacity.LeafQueue: assignContainers: node=slave1 #applications=1
2019-06-07 08:05:10,304 DEBUG org.apache.hadoop.yarn.server.resourcemanager.scheduler.capacity.LeafQueue: assignContainers: node=slave1 #applications=1
2019-06-07 08:05:10,304 DEBUG org.apache.hadoop.yarn.server.resourcemanager.scheduler.capacity.LeafQueue: User limit computation for root in queue default userLimitPercent=100 userLimitFactor=1.0 required: <memory:1024, vCores:1> consumed: <memory:4096, vCores:1> user-limit-resource: <memory:8192, vCores:1> queueCapacity: <memory:8192, vCores:1> qconsumed: <memory:4096, vCores:2> consumedRatio: 0.0 currentCapacity: <memory:8192, vCores:1> activeUsers: 1.0 clusterCapacity: <memory:8192, vCores:2> resourceByLabel: <memory:8192, vCores:2> usageratio: 0.5 Partition:  maxUserLimit=<memory:8192, vCores:1> userWeight=1.0
2019-06-07 08:05:10,304 DEBUG org.apache.hadoop.yarn.server.resourcemanager.scheduler.capacity.LeafQueue: User limit computation for root in queue default userLimitPercent=100 userLimitFactor=1.0 required: <memory:1024, vCores:1> consumed: <memory:4096, vCores:1> user-limit-resource: <memory:8192, vCores:1> queueCapacity: <memory:8192, vCores:1> qconsumed: <memory:4096, vCores:2> consumedRatio: 0.0 currentCapacity: <memory:8192, vCores:1> activeUsers: 1.0 clusterCapacity: <memory:8192, vCores:2> resourceByLabel: <memory:8192, vCores:2> usageratio: 0.5 Partition:  maxUserLimit=<memory:8192, vCores:1> userWeight=1.0
2019-06-07 08:05:10,304 DEBUG org.apache.hadoop.yarn.server.resourcemanager.scheduler.capacity.LeafQueue: Headroom calculation for user root:  userLimit=<memory:8192, vCores:1> queueMaxAvailRes=<memory:8192, vCores:1> consumed=<memory:4096, vCores:2>
2019-06-07 08:05:10,304 DEBUG org.apache.hadoop.yarn.server.resourcemanager.scheduler.capacity.LeafQueue: Headroom calculation for user root:  userLimit=<memory:8192, vCores:1> queueMaxAvailRes=<memory:8192, vCores:1> consumed=<memory:4096, vCores:2>
2019-06-07 08:05:10,304 DEBUG org.apache.hadoop.yarn.server.resourcemanager.scheduler.common.fica.FiCaSchedulerApp: pre-assignContainers for application application_1559894680121_0001
2019-06-07 08:05:10,304 DEBUG org.apache.hadoop.yarn.server.resourcemanager.scheduler.common.fica.FiCaSchedulerApp: pre-assignContainers for application application_1559894680121_0001
2019-06-07 08:05:10,304 DEBUG org.apache.hadoop.yarn.server.resourcemanager.scheduler.capacity.LeafQueue: User limit computation for root in queue default userLimitPercent=100 userLimitFactor=1.0 required: <memory:1024, vCores:1> consumed: <memory:4096, vCores:1> user-limit-resource: <memory:8192, vCores:1> queueCapacity: <memory:8192, vCores:1> qconsumed: <memory:4096, vCores:2> consumedRatio: 0.0 currentCapacity: <memory:8192, vCores:1> activeUsers: 1.0 clusterCapacity: <memory:8192, vCores:2> resourceByLabel: <memory:8192, vCores:2> usageratio: 0.5 Partition:  maxUserLimit=<memory:8192, vCores:1> userWeight=1.0
2019-06-07 08:05:10,304 DEBUG org.apache.hadoop.yarn.server.resourcemanager.scheduler.capacity.LeafQueue: User limit computation for root in queue default userLimitPercent=100 userLimitFactor=1.0 required: <memory:1024, vCores:1> consumed: <memory:4096, vCores:1> user-limit-resource: <memory:8192, vCores:1> queueCapacity: <memory:8192, vCores:1> qconsumed: <memory:4096, vCores:2> consumedRatio: 0.0 currentCapacity: <memory:8192, vCores:1> activeUsers: 1.0 clusterCapacity: <memory:8192, vCores:2> resourceByLabel: <memory:8192, vCores:2> usageratio: 0.5 Partition:  maxUserLimit=<memory:8192, vCores:1> userWeight=1.0
2019-06-07 08:05:10,305 DEBUG org.apache.hadoop.yarn.server.resourcemanager.scheduler.SchedulerApplicationAttempt: showRequests: application=application_1559894680121_0001 headRoom=<memory:4096, vCores:0> currentConsumption=4096
2019-06-07 08:05:10,305 DEBUG org.apache.hadoop.yarn.server.resourcemanager.scheduler.SchedulerApplicationAttempt: showRequests: application=application_1559894680121_0001 headRoom=<memory:4096, vCores:0> currentConsumption=4096
2019-06-07 08:05:10,305 DEBUG org.apache.hadoop.yarn.server.resourcemanager.scheduler.SchedulerApplicationAttempt: showRequests: application=application_1559894680121_0001 request={Priority: 1, Capability: <memory:3072, vCores:1>, # Containers: 1, Location: *, Relax Locality: true, Node Label Expression: }
2019-06-07 08:05:10,305 DEBUG org.apache.hadoop.yarn.server.resourcemanager.scheduler.SchedulerApplicationAttempt: showRequests: application=application_1559894680121_0001 request={Priority: 1, Capability: <memory:3072, vCores:1>, # Containers: 1, Location: *, Relax Locality: true, Node Label Expression: }
2019-06-07 08:05:10,305 DEBUG org.apache.hadoop.yarn.server.resourcemanager.scheduler.capacity.allocator.IncreaseContainerAllocator: Skip allocating increase request since we don't have any increase request on this node=slave1:43282
2019-06-07 08:05:10,305 DEBUG org.apache.hadoop.yarn.server.resourcemanager.scheduler.capacity.allocator.IncreaseContainerAllocator: Skip allocating increase request since we don't have any increase request on this node=slave1:43282
2019-06-07 08:05:10,305 DEBUG org.apache.hadoop.yarn.server.resourcemanager.scheduler.capacity.allocator.RegularContainerAllocator: assignContainers: node=slave1 application=application_1559894680121_0001 priority=1 request={Priority: 1, Capability: <memory:3072, vCores:1>, # Containers: 1, Location: *, Relax Locality: true, Node Label Expression: } type=OFF_SWITCH
2019-06-07 08:05:10,305 DEBUG org.apache.hadoop.yarn.server.resourcemanager.scheduler.capacity.allocator.RegularContainerAllocator: assignContainers: node=slave1 application=application_1559894680121_0001 priority=1 request={Priority: 1, Capability: <memory:3072, vCores:1>, # Containers: 1, Location: *, Relax Locality: true, Node Label Expression: } type=OFF_SWITCH
2019-06-07 08:05:10,305 DEBUG org.apache.hadoop.yarn.server.resourcemanager.scheduler.ActiveUsersManager: User root removed from activeUsers, currently: 0
2019-06-07 08:05:10,305 DEBUG org.apache.hadoop.yarn.server.resourcemanager.scheduler.ActiveUsersManager: User root removed from activeUsers, currently: 0
2019-06-07 08:05:10,305 DEBUG org.apache.hadoop.yarn.server.resourcemanager.scheduler.AppSchedulingInfo: allocate: applicationId=application_1559894680121_0001 container=container_1559894680121_0001_01_000003 host=slave1:43282 user=root resource=<memory:3072, vCores:1> type=OFF_SWITCH
2019-06-07 08:05:10,305 DEBUG org.apache.hadoop.yarn.server.resourcemanager.scheduler.AppSchedulingInfo: allocate: applicationId=application_1559894680121_0001 container=container_1559894680121_0001_01_000003 host=slave1:43282 user=root resource=<memory:3072, vCores:1> type=OFF_SWITCH
2019-06-07 08:05:10,305 DEBUG org.apache.hadoop.yarn.server.resourcemanager.rmcontainer.RMContainerImpl: Processing container_1559894680121_0001_01_000003 of type START
2019-06-07 08:05:10,305 DEBUG org.apache.hadoop.yarn.server.resourcemanager.rmcontainer.RMContainerImpl: Processing container_1559894680121_0001_01_000003 of type START
2019-06-07 08:05:10,305 DEBUG org.apache.hadoop.yarn.server.resourcemanager.rmapp.attempt.RMAppAttemptImpl: Processing event for appattempt_1559894680121_0001_000001 of type CONTAINER_ALLOCATED
2019-06-07 08:05:10,305 INFO org.apache.hadoop.yarn.server.resourcemanager.rmcontainer.RMContainerImpl: container_1559894680121_0001_01_000003 Container Transitioned from NEW to ALLOCATED
2019-06-07 08:05:10,305 DEBUG org.apache.hadoop.yarn.server.resourcemanager.rmapp.attempt.RMAppAttemptImpl: Processing event for appattempt_1559894680121_0001_000001 of type CONTAINER_ALLOCATED
2019-06-07 08:05:10,305 INFO org.apache.hadoop.yarn.server.resourcemanager.rmcontainer.RMContainerImpl: container_1559894680121_0001_01_000003 Container Transitioned from NEW to ALLOCATED
2019-06-07 08:05:10,307 DEBUG org.apache.hadoop.yarn.server.resourcemanager.scheduler.common.fica.FiCaSchedulerApp: allocate: applicationAttemptId=appattempt_1559894680121_0001_000001 container=container_1559894680121_0001_01_000003 host=slave1 type=OFF_SWITCH
2019-06-07 08:05:10,307 DEBUG org.apache.hadoop.yarn.server.resourcemanager.scheduler.common.fica.FiCaSchedulerApp: allocate: applicationAttemptId=appattempt_1559894680121_0001_000001 container=container_1559894680121_0001_01_000003 host=slave1 type=OFF_SWITCH
2019-06-07 08:05:10,307 INFO org.apache.hadoop.yarn.server.resourcemanager.RMAuditLogger: USER=root	OPERATION=AM Allocated Container	TARGET=SchedulerApp	RESULT=SUCCESS	APPID=application_1559894680121_0001	CONTAINERID=container_1559894680121_0001_01_000003
2019-06-07 08:05:10,307 INFO org.apache.hadoop.yarn.server.resourcemanager.RMAuditLogger: USER=root	OPERATION=AM Allocated Container	TARGET=SchedulerApp	RESULT=SUCCESS	APPID=application_1559894680121_0001	CONTAINERID=container_1559894680121_0001_01_000003
2019-06-07 08:05:10,307 INFO org.apache.hadoop.yarn.server.resourcemanager.scheduler.SchedulerNode: Assigned container container_1559894680121_0001_01_000003 of capacity <memory:3072, vCores:1> on host slave1:43282, which has 2 containers, <memory:4096, vCores:2> used and <memory:0, vCores:-1> available after allocation
2019-06-07 08:05:10,307 INFO org.apache.hadoop.yarn.server.resourcemanager.scheduler.SchedulerNode: Assigned container container_1559894680121_0001_01_000003 of capacity <memory:3072, vCores:1> on host slave1:43282, which has 2 containers, <memory:4096, vCores:2> used and <memory:0, vCores:-1> available after allocation
2019-06-07 08:05:10,307 INFO org.apache.hadoop.yarn.server.resourcemanager.scheduler.capacity.allocator.AbstractContainerAllocator: assignedContainer application attempt=appattempt_1559894680121_0001_000001 container=container_1559894680121_0001_01_000003 queue=org.apache.hadoop.yarn.server.resourcemanager.scheduler.capacity.allocator.RegularContainerAllocator@530da2a5 clusterResource=<memory:8192, vCores:2> type=OFF_SWITCH requestedPartition=
2019-06-07 08:05:10,307 INFO org.apache.hadoop.yarn.server.resourcemanager.scheduler.capacity.allocator.AbstractContainerAllocator: assignedContainer application attempt=appattempt_1559894680121_0001_000001 container=container_1559894680121_0001_01_000003 queue=org.apache.hadoop.yarn.server.resourcemanager.scheduler.capacity.allocator.RegularContainerAllocator@530da2a5 clusterResource=<memory:8192, vCores:2> type=OFF_SWITCH requestedPartition=
2019-06-07 08:05:10,307 DEBUG org.apache.hadoop.yarn.server.resourcemanager.scheduler.capacity.LeafQueue: post-assignContainers for application application_1559894680121_0001
2019-06-07 08:05:10,307 DEBUG org.apache.hadoop.yarn.server.resourcemanager.scheduler.capacity.LeafQueue: post-assignContainers for application application_1559894680121_0001
2019-06-07 08:05:10,307 DEBUG org.apache.hadoop.yarn.server.resourcemanager.scheduler.capacity.LeafQueue: User limit computation for root in queue default userLimitPercent=100 userLimitFactor=1.0 required: <memory:1024, vCores:1> consumed: <memory:7168, vCores:1> user-limit-resource: <memory:8192, vCores:1> queueCapacity: <memory:8192, vCores:1> qconsumed: <memory:7168, vCores:3> consumedRatio: 0.0 currentCapacity: <memory:8192, vCores:1> activeUsers: 0.0 clusterCapacity: <memory:8192, vCores:2> resourceByLabel: <memory:8192, vCores:2> usageratio: 0.875 Partition:  maxUserLimit=<memory:8192, vCores:1> userWeight=1.0
2019-06-07 08:05:10,307 DEBUG org.apache.hadoop.yarn.server.resourcemanager.scheduler.capacity.LeafQueue: User limit computation for root in queue default userLimitPercent=100 userLimitFactor=1.0 required: <memory:1024, vCores:1> consumed: <memory:7168, vCores:1> user-limit-resource: <memory:8192, vCores:1> queueCapacity: <memory:8192, vCores:1> qconsumed: <memory:7168, vCores:3> consumedRatio: 0.0 currentCapacity: <memory:8192, vCores:1> activeUsers: 0.0 clusterCapacity: <memory:8192, vCores:2> resourceByLabel: <memory:8192, vCores:2> usageratio: 0.875 Partition:  maxUserLimit=<memory:8192, vCores:1> userWeight=1.0
2019-06-07 08:05:10,308 DEBUG org.apache.hadoop.yarn.server.resourcemanager.scheduler.capacity.LeafQueue: User limit computation for root in queue default userLimitPercent=100 userLimitFactor=1.0 required: <memory:1024, vCores:1> consumed: <memory:7168, vCores:1> user-limit-resource: <memory:8192, vCores:1> queueCapacity: <memory:8192, vCores:1> qconsumed: <memory:7168, vCores:3> consumedRatio: 0.0 currentCapacity: <memory:8192, vCores:1> activeUsers: 0.0 clusterCapacity: <memory:8192, vCores:2> resourceByLabel: <memory:8192, vCores:2> usageratio: 0.875 Partition:  maxUserLimit=<memory:8192, vCores:1> userWeight=1.0
2019-06-07 08:05:10,308 DEBUG org.apache.hadoop.yarn.server.resourcemanager.scheduler.capacity.LeafQueue: User limit computation for root in queue default userLimitPercent=100 userLimitFactor=1.0 required: <memory:1024, vCores:1> consumed: <memory:7168, vCores:1> user-limit-resource: <memory:8192, vCores:1> queueCapacity: <memory:8192, vCores:1> qconsumed: <memory:7168, vCores:3> consumedRatio: 0.0 currentCapacity: <memory:8192, vCores:1> activeUsers: 0.0 clusterCapacity: <memory:8192, vCores:2> resourceByLabel: <memory:8192, vCores:2> usageratio: 0.875 Partition:  maxUserLimit=<memory:8192, vCores:1> userWeight=1.0
2019-06-07 08:05:10,308 DEBUG org.apache.hadoop.yarn.server.resourcemanager.scheduler.capacity.LeafQueue: User limit computation for root in queue default userLimitPercent=100 userLimitFactor=1.0 required: <memory:1024, vCores:1> consumed: <memory:7168, vCores:1> user-limit-resource: <memory:8192, vCores:1> queueCapacity: <memory:8192, vCores:1> qconsumed: <memory:7168, vCores:3> consumedRatio: 0.0 currentCapacity: <memory:8192, vCores:1> activeUsers: 0.0 clusterCapacity: <memory:8192, vCores:2> resourceByLabel: <memory:8192, vCores:2> usageratio: 0.875 Partition:  maxUserLimit=<memory:8192, vCores:1> userWeight=1.0
2019-06-07 08:05:10,308 DEBUG org.apache.hadoop.yarn.server.resourcemanager.scheduler.capacity.LeafQueue: User limit computation for root in queue default userLimitPercent=100 userLimitFactor=1.0 required: <memory:1024, vCores:1> consumed: <memory:7168, vCores:1> user-limit-resource: <memory:8192, vCores:1> queueCapacity: <memory:8192, vCores:1> qconsumed: <memory:7168, vCores:3> consumedRatio: 0.0 currentCapacity: <memory:8192, vCores:1> activeUsers: 0.0 clusterCapacity: <memory:8192, vCores:2> resourceByLabel: <memory:8192, vCores:2> usageratio: 0.875 Partition:  maxUserLimit=<memory:8192, vCores:1> userWeight=1.0
2019-06-07 08:05:10,308 DEBUG org.apache.hadoop.yarn.server.resourcemanager.scheduler.capacity.LeafQueue: default user=root used=<memory:7168, vCores:3> numContainers=3 headroom = <memory:1024, vCores:1> user-resources=<memory:7168, vCores:3>
2019-06-07 08:05:10,308 DEBUG org.apache.hadoop.yarn.server.resourcemanager.scheduler.capacity.LeafQueue: default user=root used=<memory:7168, vCores:3> numContainers=3 headroom = <memory:1024, vCores:1> user-resources=<memory:7168, vCores:3>
2019-06-07 08:05:10,308 DEBUG org.apache.hadoop.yarn.server.resourcemanager.scheduler.capacity.ParentQueue: Assigned to queue: root.default stats: default: capacity=1.0, absoluteCapacity=1.0, usedResources=<memory:7168, vCores:3>, usedCapacity=0.875, absoluteUsedCapacity=0.875, numApps=1, numContainers=3 --> <memory:3072, vCores:1>, OFF_SWITCH
2019-06-07 08:05:10,308 DEBUG org.apache.hadoop.yarn.server.resourcemanager.scheduler.capacity.ParentQueue: Assigned to queue: root.default stats: default: capacity=1.0, absoluteCapacity=1.0, usedResources=<memory:7168, vCores:3>, usedCapacity=0.875, absoluteUsedCapacity=0.875, numApps=1, numContainers=3 --> <memory:3072, vCores:1>, OFF_SWITCH
2019-06-07 08:05:10,308 INFO org.apache.hadoop.yarn.server.resourcemanager.scheduler.capacity.ParentQueue: Re-sorting assigned queue: root.default stats: default: capacity=1.0, absoluteCapacity=1.0, usedResources=<memory:7168, vCores:3>, usedCapacity=0.875, absoluteUsedCapacity=0.875, numApps=1, numContainers=3
2019-06-07 08:05:10,308 INFO org.apache.hadoop.yarn.server.resourcemanager.scheduler.capacity.ParentQueue: Re-sorting assigned queue: root.default stats: default: capacity=1.0, absoluteCapacity=1.0, usedResources=<memory:7168, vCores:3>, usedCapacity=0.875, absoluteUsedCapacity=0.875, numApps=1, numContainers=3
2019-06-07 08:05:10,308 DEBUG org.apache.hadoop.yarn.server.resourcemanager.scheduler.capacity.ParentQueue: printChildQueues - queue: root child-queues: root.defaultusedCapacity=(0.875),  label=(*)
2019-06-07 08:05:10,308 DEBUG org.apache.hadoop.yarn.server.resourcemanager.scheduler.capacity.ParentQueue: printChildQueues - queue: root child-queues: root.defaultusedCapacity=(0.875),  label=(*)
2019-06-07 08:05:10,308 INFO org.apache.hadoop.yarn.server.resourcemanager.scheduler.capacity.ParentQueue: assignedContainer queue=root usedCapacity=0.875 absoluteUsedCapacity=0.875 used=<memory:7168, vCores:3> cluster=<memory:8192, vCores:2>
2019-06-07 08:05:10,308 INFO org.apache.hadoop.yarn.server.resourcemanager.scheduler.capacity.ParentQueue: assignedContainer queue=root usedCapacity=0.875 absoluteUsedCapacity=0.875 used=<memory:7168, vCores:3> cluster=<memory:8192, vCores:2>
2019-06-07 08:05:10,308 DEBUG org.apache.hadoop.yarn.server.resourcemanager.scheduler.capacity.ParentQueue: ParentQ=root assignedSoFarInThisIteration=<memory:3072, vCores:1> usedCapacity=0.875 absoluteUsedCapacity=0.875
2019-06-07 08:05:10,308 DEBUG org.apache.hadoop.yarn.server.resourcemanager.scheduler.capacity.ParentQueue: ParentQ=root assignedSoFarInThisIteration=<memory:3072, vCores:1> usedCapacity=0.875 absoluteUsedCapacity=0.875
2019-06-07 08:05:10,308 DEBUG org.apache.hadoop.yarn.server.resourcemanager.scheduler.capacity.ParentQueue: Assigned maximum number of off-switch containers: 1, assignments so far: resource:<memory:3072, vCores:1>; type:OFF_SWITCH; excessReservation:null; applicationid:null; skipped:NONE; fulfilled reservation:false; allocations(count/resource):1/<memory:3072, vCores:1>; reservations(count/resource):0/<memory:0, vCores:0>
2019-06-07 08:05:10,308 DEBUG org.apache.hadoop.yarn.server.resourcemanager.scheduler.capacity.ParentQueue: Assigned maximum number of off-switch containers: 1, assignments so far: resource:<memory:3072, vCores:1>; type:OFF_SWITCH; excessReservation:null; applicationid:null; skipped:NONE; fulfilled reservation:false; allocations(count/resource):1/<memory:3072, vCores:1>; reservations(count/resource):0/<memory:0, vCores:0>
2019-06-07 08:05:10,833 DEBUG org.apache.hadoop.yarn.server.resourcemanager.rmapp.attempt.RMAppAttemptImpl: Processing event for appattempt_1559894680121_0001_000001 of type STATUS_UPDATE
2019-06-07 08:05:10,833 DEBUG org.apache.hadoop.yarn.server.resourcemanager.rmapp.attempt.RMAppAttemptImpl: Processing event for appattempt_1559894680121_0001_000001 of type STATUS_UPDATE
2019-06-07 08:05:10,837 INFO org.apache.hadoop.yarn.server.resourcemanager.security.NMTokenSecretManagerInRM: Sending NMToken for nodeId : slave2:37804 for container : container_1559894680121_0001_01_000002
2019-06-07 08:05:10,837 INFO org.apache.hadoop.yarn.server.resourcemanager.security.NMTokenSecretManagerInRM: Sending NMToken for nodeId : slave2:37804 for container : container_1559894680121_0001_01_000002
2019-06-07 08:05:10,838 DEBUG org.apache.hadoop.yarn.server.resourcemanager.rmcontainer.RMContainerImpl: Processing container_1559894680121_0001_01_000002 of type ACQUIRED
2019-06-07 08:05:10,838 DEBUG org.apache.hadoop.yarn.server.resourcemanager.rmcontainer.RMContainerImpl: Processing container_1559894680121_0001_01_000002 of type ACQUIRED
2019-06-07 08:05:10,841 INFO org.apache.hadoop.yarn.server.resourcemanager.rmcontainer.RMContainerImpl: container_1559894680121_0001_01_000002 Container Transitioned from ALLOCATED to ACQUIRED
2019-06-07 08:05:10,841 INFO org.apache.hadoop.yarn.server.resourcemanager.rmcontainer.RMContainerImpl: container_1559894680121_0001_01_000002 Container Transitioned from ALLOCATED to ACQUIRED
2019-06-07 08:05:10,841 DEBUG org.apache.hadoop.yarn.server.resourcemanager.rmapp.RMAppImpl: Processing event for application_1559894680121_0001 of type APP_RUNNING_ON_NODE
2019-06-07 08:05:10,841 DEBUG org.apache.hadoop.yarn.server.resourcemanager.rmapp.RMAppImpl: Processing event for application_1559894680121_0001 of type APP_RUNNING_ON_NODE
2019-06-07 08:05:10,842 INFO org.apache.hadoop.yarn.server.resourcemanager.security.NMTokenSecretManagerInRM: Sending NMToken for nodeId : slave1:43282 for container : container_1559894680121_0001_01_000003
2019-06-07 08:05:10,842 INFO org.apache.hadoop.yarn.server.resourcemanager.security.NMTokenSecretManagerInRM: Sending NMToken for nodeId : slave1:43282 for container : container_1559894680121_0001_01_000003
2019-06-07 08:05:10,843 DEBUG org.apache.hadoop.yarn.server.resourcemanager.rmcontainer.RMContainerImpl: Processing container_1559894680121_0001_01_000003 of type ACQUIRED
2019-06-07 08:05:10,843 DEBUG org.apache.hadoop.yarn.server.resourcemanager.rmcontainer.RMContainerImpl: Processing container_1559894680121_0001_01_000003 of type ACQUIRED
2019-06-07 08:05:10,843 INFO org.apache.hadoop.yarn.server.resourcemanager.rmcontainer.RMContainerImpl: container_1559894680121_0001_01_000003 Container Transitioned from ALLOCATED to ACQUIRED
2019-06-07 08:05:10,843 INFO org.apache.hadoop.yarn.server.resourcemanager.rmcontainer.RMContainerImpl: container_1559894680121_0001_01_000003 Container Transitioned from ALLOCATED to ACQUIRED
2019-06-07 08:05:10,844 DEBUG org.apache.hadoop.yarn.server.resourcemanager.rmapp.RMAppImpl: Processing event for application_1559894680121_0001 of type APP_RUNNING_ON_NODE
2019-06-07 08:05:10,844 DEBUG org.apache.hadoop.yarn.server.resourcemanager.rmapp.RMAppImpl: Processing event for application_1559894680121_0001 of type APP_RUNNING_ON_NODE
2019-06-07 08:05:10,844 DEBUG org.apache.hadoop.yarn.server.resourcemanager.scheduler.capacity.LeafQueue: User limit computation for root in queue default userLimitPercent=100 userLimitFactor=1.0 required: <memory:1024, vCores:1> consumed: <memory:7168, vCores:1> user-limit-resource: <memory:8192, vCores:1> queueCapacity: <memory:8192, vCores:1> qconsumed: <memory:7168, vCores:3> consumedRatio: 0.0 currentCapacity: <memory:8192, vCores:1> activeUsers: 0.0 clusterCapacity: <memory:8192, vCores:2> resourceByLabel: <memory:8192, vCores:2> usageratio: 0.875 Partition:  maxUserLimit=<memory:8192, vCores:1> userWeight=1.0
2019-06-07 08:05:10,844 DEBUG org.apache.hadoop.yarn.server.resourcemanager.scheduler.capacity.LeafQueue: User limit computation for root in queue default userLimitPercent=100 userLimitFactor=1.0 required: <memory:1024, vCores:1> consumed: <memory:7168, vCores:1> user-limit-resource: <memory:8192, vCores:1> queueCapacity: <memory:8192, vCores:1> qconsumed: <memory:7168, vCores:3> consumedRatio: 0.0 currentCapacity: <memory:8192, vCores:1> activeUsers: 0.0 clusterCapacity: <memory:8192, vCores:2> resourceByLabel: <memory:8192, vCores:2> usageratio: 0.875 Partition:  maxUserLimit=<memory:8192, vCores:1> userWeight=1.0
2019-06-07 08:05:11,279 DEBUG org.apache.hadoop.yarn.server.resourcemanager.rmnode.RMNodeImpl: Processing slave2:37804 of type STATUS_UPDATE
2019-06-07 08:05:11,279 DEBUG org.apache.hadoop.yarn.server.resourcemanager.rmnode.RMNodeImpl: Processing slave2:37804 of type STATUS_UPDATE
2019-06-07 08:05:11,279 DEBUG org.apache.hadoop.yarn.server.resourcemanager.rmnode.RMNodeImpl: Container container_1559894680121_0001_01_000002 is the first container get launched for application application_1559894680121_0001
2019-06-07 08:05:11,279 DEBUG org.apache.hadoop.yarn.server.resourcemanager.rmnode.RMNodeImpl: Container container_1559894680121_0001_01_000002 is the first container get launched for application application_1559894680121_0001
2019-06-07 08:05:11,280 DEBUG org.apache.hadoop.yarn.server.resourcemanager.rmapp.RMAppImpl: Processing event for application_1559894680121_0001 of type APP_RUNNING_ON_NODE
2019-06-07 08:05:11,280 DEBUG org.apache.hadoop.yarn.server.resourcemanager.rmapp.RMAppImpl: Processing event for application_1559894680121_0001 of type APP_RUNNING_ON_NODE
2019-06-07 08:05:11,280 DEBUG org.apache.hadoop.yarn.server.resourcemanager.scheduler.capacity.CapacityScheduler: nodeUpdate: slave2:37804 clusterResources: <memory:8192, vCores:2>
2019-06-07 08:05:11,280 DEBUG org.apache.hadoop.yarn.server.resourcemanager.scheduler.capacity.CapacityScheduler: nodeUpdate: slave2:37804 clusterResources: <memory:8192, vCores:2>
2019-06-07 08:05:11,281 DEBUG org.apache.hadoop.yarn.server.resourcemanager.rmcontainer.RMContainerImpl: Processing container_1559894680121_0001_01_000002 of type LAUNCHED
2019-06-07 08:05:11,281 DEBUG org.apache.hadoop.yarn.server.resourcemanager.rmcontainer.RMContainerImpl: Processing container_1559894680121_0001_01_000002 of type LAUNCHED
2019-06-07 08:05:11,281 INFO org.apache.hadoop.yarn.server.resourcemanager.rmcontainer.RMContainerImpl: container_1559894680121_0001_01_000002 Container Transitioned from ACQUIRED to RUNNING
2019-06-07 08:05:11,281 INFO org.apache.hadoop.yarn.server.resourcemanager.rmcontainer.RMContainerImpl: container_1559894680121_0001_01_000002 Container Transitioned from ACQUIRED to RUNNING
2019-06-07 08:05:11,281 DEBUG org.apache.hadoop.yarn.server.resourcemanager.scheduler.capacity.CapacityScheduler: Node being looked for scheduling slave2:37804 availableResource: <memory:1024, vCores:0>
2019-06-07 08:05:11,281 DEBUG org.apache.hadoop.yarn.server.resourcemanager.scheduler.capacity.CapacityScheduler: Node being looked for scheduling slave2:37804 availableResource: <memory:1024, vCores:0>
2019-06-07 08:05:11,281 DEBUG org.apache.hadoop.yarn.server.resourcemanager.scheduler.capacity.CapacityScheduler: Trying to schedule on node: slave2, available: <memory:1024, vCores:0>
2019-06-07 08:05:11,281 DEBUG org.apache.hadoop.yarn.server.resourcemanager.scheduler.capacity.CapacityScheduler: Trying to schedule on node: slave2, available: <memory:1024, vCores:0>
2019-06-07 08:05:11,281 DEBUG org.apache.hadoop.yarn.server.resourcemanager.scheduler.capacity.ParentQueue: Skip this queue=root, because it doesn't need more resource, schedulingMode=RESPECT_PARTITION_EXCLUSIVITY node-partition=
2019-06-07 08:05:11,281 DEBUG org.apache.hadoop.yarn.server.resourcemanager.scheduler.capacity.ParentQueue: Skip this queue=root, because it doesn't need more resource, schedulingMode=RESPECT_PARTITION_EXCLUSIVITY node-partition=
2019-06-07 08:05:11,309 DEBUG org.apache.hadoop.yarn.server.resourcemanager.rmnode.RMNodeImpl: Processing slave1:43282 of type STATUS_UPDATE
2019-06-07 08:05:11,309 DEBUG org.apache.hadoop.yarn.server.resourcemanager.rmnode.RMNodeImpl: Processing slave1:43282 of type STATUS_UPDATE
2019-06-07 08:05:11,310 DEBUG org.apache.hadoop.yarn.server.resourcemanager.scheduler.capacity.CapacityScheduler: nodeUpdate: slave1:43282 clusterResources: <memory:8192, vCores:2>
2019-06-07 08:05:11,310 DEBUG org.apache.hadoop.yarn.server.resourcemanager.scheduler.capacity.CapacityScheduler: nodeUpdate: slave1:43282 clusterResources: <memory:8192, vCores:2>
2019-06-07 08:05:11,310 DEBUG org.apache.hadoop.yarn.server.resourcemanager.rmcontainer.RMContainerImpl: Processing container_1559894680121_0001_01_000003 of type LAUNCHED
2019-06-07 08:05:11,310 DEBUG org.apache.hadoop.yarn.server.resourcemanager.rmcontainer.RMContainerImpl: Processing container_1559894680121_0001_01_000003 of type LAUNCHED
2019-06-07 08:05:11,310 INFO org.apache.hadoop.yarn.server.resourcemanager.rmcontainer.RMContainerImpl: container_1559894680121_0001_01_000003 Container Transitioned from ACQUIRED to RUNNING
2019-06-07 08:05:11,310 INFO org.apache.hadoop.yarn.server.resourcemanager.rmcontainer.RMContainerImpl: container_1559894680121_0001_01_000003 Container Transitioned from ACQUIRED to RUNNING
2019-06-07 08:05:11,310 DEBUG org.apache.hadoop.yarn.server.resourcemanager.scheduler.capacity.CapacityScheduler: Node being looked for scheduling slave1:43282 availableResource: <memory:0, vCores:-1>
2019-06-07 08:05:11,310 DEBUG org.apache.hadoop.yarn.server.resourcemanager.scheduler.capacity.CapacityScheduler: Node being looked for scheduling slave1:43282 availableResource: <memory:0, vCores:-1>
2019-06-07 08:05:12,313 DEBUG org.apache.hadoop.yarn.server.resourcemanager.rmnode.RMNodeImpl: Processing slave1:43282 of type STATUS_UPDATE
2019-06-07 08:05:12,313 DEBUG org.apache.hadoop.yarn.server.resourcemanager.rmnode.RMNodeImpl: Processing slave1:43282 of type STATUS_UPDATE
2019-06-07 08:05:12,313 DEBUG org.apache.hadoop.yarn.server.resourcemanager.scheduler.capacity.CapacityScheduler: nodeUpdate: slave1:43282 clusterResources: <memory:8192, vCores:2>
2019-06-07 08:05:12,313 DEBUG org.apache.hadoop.yarn.server.resourcemanager.scheduler.capacity.CapacityScheduler: nodeUpdate: slave1:43282 clusterResources: <memory:8192, vCores:2>
2019-06-07 08:05:12,313 DEBUG org.apache.hadoop.yarn.server.resourcemanager.scheduler.capacity.CapacityScheduler: Node being looked for scheduling slave1:43282 availableResource: <memory:0, vCores:-1>
2019-06-07 08:05:12,313 DEBUG org.apache.hadoop.yarn.server.resourcemanager.scheduler.capacity.CapacityScheduler: Node being looked for scheduling slave1:43282 availableResource: <memory:0, vCores:-1>
2019-06-07 08:05:12,369 DEBUG org.apache.hadoop.yarn.server.resourcemanager.rmnode.RMNodeImpl: Processing slave2:37804 of type STATUS_UPDATE
2019-06-07 08:05:12,369 DEBUG org.apache.hadoop.yarn.server.resourcemanager.rmnode.RMNodeImpl: Processing slave2:37804 of type STATUS_UPDATE
2019-06-07 08:05:12,369 DEBUG org.apache.hadoop.yarn.server.resourcemanager.scheduler.capacity.CapacityScheduler: nodeUpdate: slave2:37804 clusterResources: <memory:8192, vCores:2>
2019-06-07 08:05:12,369 DEBUG org.apache.hadoop.yarn.server.resourcemanager.scheduler.capacity.CapacityScheduler: nodeUpdate: slave2:37804 clusterResources: <memory:8192, vCores:2>
2019-06-07 08:05:12,369 DEBUG org.apache.hadoop.yarn.server.resourcemanager.scheduler.capacity.CapacityScheduler: Node being looked for scheduling slave2:37804 availableResource: <memory:1024, vCores:0>
2019-06-07 08:05:12,369 DEBUG org.apache.hadoop.yarn.server.resourcemanager.scheduler.capacity.CapacityScheduler: Node being looked for scheduling slave2:37804 availableResource: <memory:1024, vCores:0>
2019-06-07 08:05:12,369 DEBUG org.apache.hadoop.yarn.server.resourcemanager.scheduler.capacity.CapacityScheduler: Trying to schedule on node: slave2, available: <memory:1024, vCores:0>
2019-06-07 08:05:12,369 DEBUG org.apache.hadoop.yarn.server.resourcemanager.scheduler.capacity.CapacityScheduler: Trying to schedule on node: slave2, available: <memory:1024, vCores:0>
2019-06-07 08:05:12,369 DEBUG org.apache.hadoop.yarn.server.resourcemanager.scheduler.capacity.ParentQueue: Skip this queue=root, because it doesn't need more resource, schedulingMode=RESPECT_PARTITION_EXCLUSIVITY node-partition=
2019-06-07 08:05:12,369 DEBUG org.apache.hadoop.yarn.server.resourcemanager.scheduler.capacity.ParentQueue: Skip this queue=root, because it doesn't need more resource, schedulingMode=RESPECT_PARTITION_EXCLUSIVITY node-partition=
2019-06-07 08:05:13,321 DEBUG org.apache.hadoop.yarn.server.resourcemanager.rmnode.RMNodeImpl: Processing slave1:43282 of type STATUS_UPDATE
2019-06-07 08:05:13,321 DEBUG org.apache.hadoop.yarn.server.resourcemanager.rmnode.RMNodeImpl: Processing slave1:43282 of type STATUS_UPDATE
2019-06-07 08:05:13,321 DEBUG org.apache.hadoop.yarn.server.resourcemanager.scheduler.capacity.CapacityScheduler: nodeUpdate: slave1:43282 clusterResources: <memory:8192, vCores:2>
2019-06-07 08:05:13,321 DEBUG org.apache.hadoop.yarn.server.resourcemanager.scheduler.capacity.CapacityScheduler: nodeUpdate: slave1:43282 clusterResources: <memory:8192, vCores:2>
2019-06-07 08:05:13,321 DEBUG org.apache.hadoop.yarn.server.resourcemanager.scheduler.capacity.CapacityScheduler: Node being looked for scheduling slave1:43282 availableResource: <memory:0, vCores:-1>
2019-06-07 08:05:13,321 DEBUG org.apache.hadoop.yarn.server.resourcemanager.scheduler.capacity.CapacityScheduler: Node being looked for scheduling slave1:43282 availableResource: <memory:0, vCores:-1>
2019-06-07 08:05:13,382 DEBUG org.apache.hadoop.yarn.server.resourcemanager.rmnode.RMNodeImpl: Processing slave2:37804 of type STATUS_UPDATE
2019-06-07 08:05:13,382 DEBUG org.apache.hadoop.yarn.server.resourcemanager.rmnode.RMNodeImpl: Processing slave2:37804 of type STATUS_UPDATE
2019-06-07 08:05:13,382 DEBUG org.apache.hadoop.yarn.server.resourcemanager.scheduler.capacity.CapacityScheduler: nodeUpdate: slave2:37804 clusterResources: <memory:8192, vCores:2>
2019-06-07 08:05:13,382 DEBUG org.apache.hadoop.yarn.server.resourcemanager.scheduler.capacity.CapacityScheduler: nodeUpdate: slave2:37804 clusterResources: <memory:8192, vCores:2>
2019-06-07 08:05:13,382 DEBUG org.apache.hadoop.yarn.server.resourcemanager.scheduler.capacity.CapacityScheduler: Node being looked for scheduling slave2:37804 availableResource: <memory:1024, vCores:0>
2019-06-07 08:05:13,382 DEBUG org.apache.hadoop.yarn.server.resourcemanager.scheduler.capacity.CapacityScheduler: Node being looked for scheduling slave2:37804 availableResource: <memory:1024, vCores:0>
2019-06-07 08:05:13,382 DEBUG org.apache.hadoop.yarn.server.resourcemanager.scheduler.capacity.CapacityScheduler: Trying to schedule on node: slave2, available: <memory:1024, vCores:0>
2019-06-07 08:05:13,382 DEBUG org.apache.hadoop.yarn.server.resourcemanager.scheduler.capacity.CapacityScheduler: Trying to schedule on node: slave2, available: <memory:1024, vCores:0>
2019-06-07 08:05:13,382 DEBUG org.apache.hadoop.yarn.server.resourcemanager.scheduler.capacity.ParentQueue: Skip this queue=root, because it doesn't need more resource, schedulingMode=RESPECT_PARTITION_EXCLUSIVITY node-partition=
2019-06-07 08:05:13,382 DEBUG org.apache.hadoop.yarn.server.resourcemanager.scheduler.capacity.ParentQueue: Skip this queue=root, because it doesn't need more resource, schedulingMode=RESPECT_PARTITION_EXCLUSIVITY node-partition=
2019-06-07 08:05:13,865 DEBUG org.apache.hadoop.yarn.server.resourcemanager.scheduler.capacity.CapacityScheduler: allocate: pre-update appattempt_1559894680121_0001_000001 ask size =1
2019-06-07 08:05:13,865 DEBUG org.apache.hadoop.yarn.server.resourcemanager.scheduler.capacity.CapacityScheduler: allocate: pre-update appattempt_1559894680121_0001_000001 ask size =1
2019-06-07 08:05:13,865 DEBUG org.apache.hadoop.yarn.server.resourcemanager.rmapp.attempt.RMAppAttemptImpl: Processing event for appattempt_1559894680121_0001_000001 of type STATUS_UPDATE
2019-06-07 08:05:13,865 DEBUG org.apache.hadoop.yarn.server.resourcemanager.rmapp.attempt.RMAppAttemptImpl: Processing event for appattempt_1559894680121_0001_000001 of type STATUS_UPDATE
2019-06-07 08:05:13,865 INFO org.apache.hadoop.yarn.server.resourcemanager.scheduler.AppSchedulingInfo: checking for deactivate of application :application_1559894680121_0001
2019-06-07 08:05:13,865 INFO org.apache.hadoop.yarn.server.resourcemanager.scheduler.AppSchedulingInfo: checking for deactivate of application :application_1559894680121_0001
2019-06-07 08:05:13,865 DEBUG org.apache.hadoop.yarn.server.resourcemanager.scheduler.capacity.CapacityScheduler: allocate: post-update
2019-06-07 08:05:13,865 DEBUG org.apache.hadoop.yarn.server.resourcemanager.scheduler.capacity.CapacityScheduler: allocate: post-update
2019-06-07 08:05:13,865 DEBUG org.apache.hadoop.yarn.server.resourcemanager.scheduler.capacity.LeafQueue: User limit computation for root in queue default userLimitPercent=100 userLimitFactor=1.0 required: <memory:1024, vCores:1> consumed: <memory:7168, vCores:1> user-limit-resource: <memory:8192, vCores:1> queueCapacity: <memory:8192, vCores:1> qconsumed: <memory:7168, vCores:3> consumedRatio: 0.0 currentCapacity: <memory:8192, vCores:1> activeUsers: 0.0 clusterCapacity: <memory:8192, vCores:2> resourceByLabel: <memory:8192, vCores:2> usageratio: 0.875 Partition:  maxUserLimit=<memory:8192, vCores:1> userWeight=1.0
2019-06-07 08:05:13,865 DEBUG org.apache.hadoop.yarn.server.resourcemanager.scheduler.capacity.LeafQueue: User limit computation for root in queue default userLimitPercent=100 userLimitFactor=1.0 required: <memory:1024, vCores:1> consumed: <memory:7168, vCores:1> user-limit-resource: <memory:8192, vCores:1> queueCapacity: <memory:8192, vCores:1> qconsumed: <memory:7168, vCores:3> consumedRatio: 0.0 currentCapacity: <memory:8192, vCores:1> activeUsers: 0.0 clusterCapacity: <memory:8192, vCores:2> resourceByLabel: <memory:8192, vCores:2> usageratio: 0.875 Partition:  maxUserLimit=<memory:8192, vCores:1> userWeight=1.0
2019-06-07 08:05:14,329 DEBUG org.apache.hadoop.yarn.server.resourcemanager.rmnode.RMNodeImpl: Processing slave1:43282 of type STATUS_UPDATE
2019-06-07 08:05:14,329 DEBUG org.apache.hadoop.yarn.server.resourcemanager.rmnode.RMNodeImpl: Processing slave1:43282 of type STATUS_UPDATE
2019-06-07 08:05:14,329 DEBUG org.apache.hadoop.yarn.server.resourcemanager.scheduler.capacity.CapacityScheduler: nodeUpdate: slave1:43282 clusterResources: <memory:8192, vCores:2>
2019-06-07 08:05:14,329 DEBUG org.apache.hadoop.yarn.server.resourcemanager.scheduler.capacity.CapacityScheduler: nodeUpdate: slave1:43282 clusterResources: <memory:8192, vCores:2>
2019-06-07 08:05:14,330 DEBUG org.apache.hadoop.yarn.server.resourcemanager.scheduler.capacity.CapacityScheduler: Node being looked for scheduling slave1:43282 availableResource: <memory:0, vCores:-1>
2019-06-07 08:05:14,330 DEBUG org.apache.hadoop.yarn.server.resourcemanager.scheduler.capacity.CapacityScheduler: Node being looked for scheduling slave1:43282 availableResource: <memory:0, vCores:-1>
2019-06-07 08:05:14,385 DEBUG org.apache.hadoop.yarn.server.resourcemanager.rmnode.RMNodeImpl: Processing slave2:37804 of type STATUS_UPDATE
2019-06-07 08:05:14,385 DEBUG org.apache.hadoop.yarn.server.resourcemanager.rmnode.RMNodeImpl: Processing slave2:37804 of type STATUS_UPDATE
2019-06-07 08:05:14,386 DEBUG org.apache.hadoop.yarn.server.resourcemanager.scheduler.capacity.CapacityScheduler: nodeUpdate: slave2:37804 clusterResources: <memory:8192, vCores:2>
2019-06-07 08:05:14,386 DEBUG org.apache.hadoop.yarn.server.resourcemanager.scheduler.capacity.CapacityScheduler: nodeUpdate: slave2:37804 clusterResources: <memory:8192, vCores:2>
2019-06-07 08:05:14,386 DEBUG org.apache.hadoop.yarn.server.resourcemanager.scheduler.capacity.CapacityScheduler: Node being looked for scheduling slave2:37804 availableResource: <memory:1024, vCores:0>
2019-06-07 08:05:14,386 DEBUG org.apache.hadoop.yarn.server.resourcemanager.scheduler.capacity.CapacityScheduler: Node being looked for scheduling slave2:37804 availableResource: <memory:1024, vCores:0>
2019-06-07 08:05:14,386 DEBUG org.apache.hadoop.yarn.server.resourcemanager.scheduler.capacity.CapacityScheduler: Trying to schedule on node: slave2, available: <memory:1024, vCores:0>
2019-06-07 08:05:14,386 DEBUG org.apache.hadoop.yarn.server.resourcemanager.scheduler.capacity.CapacityScheduler: Trying to schedule on node: slave2, available: <memory:1024, vCores:0>
2019-06-07 08:05:14,386 DEBUG org.apache.hadoop.yarn.server.resourcemanager.scheduler.capacity.ParentQueue: Skip this queue=root, because it doesn't need more resource, schedulingMode=RESPECT_PARTITION_EXCLUSIVITY node-partition=
2019-06-07 08:05:14,386 DEBUG org.apache.hadoop.yarn.server.resourcemanager.scheduler.capacity.ParentQueue: Skip this queue=root, because it doesn't need more resource, schedulingMode=RESPECT_PARTITION_EXCLUSIVITY node-partition=
2019-06-07 08:05:15,335 DEBUG org.apache.hadoop.yarn.server.resourcemanager.rmnode.RMNodeImpl: Processing slave1:43282 of type STATUS_UPDATE
2019-06-07 08:05:15,335 DEBUG org.apache.hadoop.yarn.server.resourcemanager.rmnode.RMNodeImpl: Processing slave1:43282 of type STATUS_UPDATE
2019-06-07 08:05:15,335 DEBUG org.apache.hadoop.yarn.server.resourcemanager.scheduler.capacity.CapacityScheduler: nodeUpdate: slave1:43282 clusterResources: <memory:8192, vCores:2>
2019-06-07 08:05:15,335 DEBUG org.apache.hadoop.yarn.server.resourcemanager.scheduler.capacity.CapacityScheduler: nodeUpdate: slave1:43282 clusterResources: <memory:8192, vCores:2>
2019-06-07 08:05:15,335 DEBUG org.apache.hadoop.yarn.server.resourcemanager.scheduler.capacity.CapacityScheduler: Node being looked for scheduling slave1:43282 availableResource: <memory:0, vCores:-1>
2019-06-07 08:05:15,335 DEBUG org.apache.hadoop.yarn.server.resourcemanager.scheduler.capacity.CapacityScheduler: Node being looked for scheduling slave1:43282 availableResource: <memory:0, vCores:-1>
2019-06-07 08:05:15,390 DEBUG org.apache.hadoop.yarn.server.resourcemanager.rmnode.RMNodeImpl: Processing slave2:37804 of type STATUS_UPDATE
2019-06-07 08:05:15,390 DEBUG org.apache.hadoop.yarn.server.resourcemanager.rmnode.RMNodeImpl: Processing slave2:37804 of type STATUS_UPDATE
2019-06-07 08:05:15,390 DEBUG org.apache.hadoop.yarn.server.resourcemanager.scheduler.capacity.CapacityScheduler: nodeUpdate: slave2:37804 clusterResources: <memory:8192, vCores:2>
2019-06-07 08:05:15,390 DEBUG org.apache.hadoop.yarn.server.resourcemanager.scheduler.capacity.CapacityScheduler: nodeUpdate: slave2:37804 clusterResources: <memory:8192, vCores:2>
2019-06-07 08:05:15,390 DEBUG org.apache.hadoop.yarn.server.resourcemanager.scheduler.capacity.CapacityScheduler: Node being looked for scheduling slave2:37804 availableResource: <memory:1024, vCores:0>
2019-06-07 08:05:15,390 DEBUG org.apache.hadoop.yarn.server.resourcemanager.scheduler.capacity.CapacityScheduler: Node being looked for scheduling slave2:37804 availableResource: <memory:1024, vCores:0>
2019-06-07 08:05:15,390 DEBUG org.apache.hadoop.yarn.server.resourcemanager.scheduler.capacity.CapacityScheduler: Trying to schedule on node: slave2, available: <memory:1024, vCores:0>
2019-06-07 08:05:15,390 DEBUG org.apache.hadoop.yarn.server.resourcemanager.scheduler.capacity.CapacityScheduler: Trying to schedule on node: slave2, available: <memory:1024, vCores:0>
2019-06-07 08:05:15,390 DEBUG org.apache.hadoop.yarn.server.resourcemanager.scheduler.capacity.ParentQueue: Skip this queue=root, because it doesn't need more resource, schedulingMode=RESPECT_PARTITION_EXCLUSIVITY node-partition=
2019-06-07 08:05:15,390 DEBUG org.apache.hadoop.yarn.server.resourcemanager.scheduler.capacity.ParentQueue: Skip this queue=root, because it doesn't need more resource, schedulingMode=RESPECT_PARTITION_EXCLUSIVITY node-partition=
2019-06-07 08:05:16,343 DEBUG org.apache.hadoop.yarn.server.resourcemanager.rmnode.RMNodeImpl: Processing slave1:43282 of type STATUS_UPDATE
2019-06-07 08:05:16,343 DEBUG org.apache.hadoop.yarn.server.resourcemanager.rmnode.RMNodeImpl: Processing slave1:43282 of type STATUS_UPDATE
2019-06-07 08:05:16,343 DEBUG org.apache.hadoop.yarn.server.resourcemanager.scheduler.capacity.CapacityScheduler: nodeUpdate: slave1:43282 clusterResources: <memory:8192, vCores:2>
2019-06-07 08:05:16,343 DEBUG org.apache.hadoop.yarn.server.resourcemanager.scheduler.capacity.CapacityScheduler: nodeUpdate: slave1:43282 clusterResources: <memory:8192, vCores:2>
2019-06-07 08:05:16,343 DEBUG org.apache.hadoop.yarn.server.resourcemanager.scheduler.capacity.CapacityScheduler: Node being looked for scheduling slave1:43282 availableResource: <memory:0, vCores:-1>
2019-06-07 08:05:16,343 DEBUG org.apache.hadoop.yarn.server.resourcemanager.scheduler.capacity.CapacityScheduler: Node being looked for scheduling slave1:43282 availableResource: <memory:0, vCores:-1>
2019-06-07 08:05:16,401 DEBUG org.apache.hadoop.yarn.server.resourcemanager.rmnode.RMNodeImpl: Processing slave2:37804 of type STATUS_UPDATE
2019-06-07 08:05:16,401 DEBUG org.apache.hadoop.yarn.server.resourcemanager.rmnode.RMNodeImpl: Processing slave2:37804 of type STATUS_UPDATE
2019-06-07 08:05:16,401 DEBUG org.apache.hadoop.yarn.server.resourcemanager.scheduler.capacity.CapacityScheduler: nodeUpdate: slave2:37804 clusterResources: <memory:8192, vCores:2>
2019-06-07 08:05:16,401 DEBUG org.apache.hadoop.yarn.server.resourcemanager.scheduler.capacity.CapacityScheduler: nodeUpdate: slave2:37804 clusterResources: <memory:8192, vCores:2>
2019-06-07 08:05:16,401 DEBUG org.apache.hadoop.yarn.server.resourcemanager.scheduler.capacity.CapacityScheduler: Node being looked for scheduling slave2:37804 availableResource: <memory:1024, vCores:0>
2019-06-07 08:05:16,401 DEBUG org.apache.hadoop.yarn.server.resourcemanager.scheduler.capacity.CapacityScheduler: Node being looked for scheduling slave2:37804 availableResource: <memory:1024, vCores:0>
2019-06-07 08:05:16,401 DEBUG org.apache.hadoop.yarn.server.resourcemanager.scheduler.capacity.CapacityScheduler: Trying to schedule on node: slave2, available: <memory:1024, vCores:0>
2019-06-07 08:05:16,401 DEBUG org.apache.hadoop.yarn.server.resourcemanager.scheduler.capacity.CapacityScheduler: Trying to schedule on node: slave2, available: <memory:1024, vCores:0>
2019-06-07 08:05:16,401 DEBUG org.apache.hadoop.yarn.server.resourcemanager.scheduler.capacity.ParentQueue: Skip this queue=root, because it doesn't need more resource, schedulingMode=RESPECT_PARTITION_EXCLUSIVITY node-partition=
2019-06-07 08:05:16,401 DEBUG org.apache.hadoop.yarn.server.resourcemanager.scheduler.capacity.ParentQueue: Skip this queue=root, because it doesn't need more resource, schedulingMode=RESPECT_PARTITION_EXCLUSIVITY node-partition=
2019-06-07 08:05:16,872 DEBUG org.apache.hadoop.yarn.server.resourcemanager.scheduler.capacity.LeafQueue: User limit computation for root in queue default userLimitPercent=100 userLimitFactor=1.0 required: <memory:1024, vCores:1> consumed: <memory:7168, vCores:1> user-limit-resource: <memory:8192, vCores:1> queueCapacity: <memory:8192, vCores:1> qconsumed: <memory:7168, vCores:3> consumedRatio: 0.0 currentCapacity: <memory:8192, vCores:1> activeUsers: 0.0 clusterCapacity: <memory:8192, vCores:2> resourceByLabel: <memory:8192, vCores:2> usageratio: 0.875 Partition:  maxUserLimit=<memory:8192, vCores:1> userWeight=1.0
2019-06-07 08:05:16,872 DEBUG org.apache.hadoop.yarn.server.resourcemanager.scheduler.capacity.LeafQueue: User limit computation for root in queue default userLimitPercent=100 userLimitFactor=1.0 required: <memory:1024, vCores:1> consumed: <memory:7168, vCores:1> user-limit-resource: <memory:8192, vCores:1> queueCapacity: <memory:8192, vCores:1> qconsumed: <memory:7168, vCores:3> consumedRatio: 0.0 currentCapacity: <memory:8192, vCores:1> activeUsers: 0.0 clusterCapacity: <memory:8192, vCores:2> resourceByLabel: <memory:8192, vCores:2> usageratio: 0.875 Partition:  maxUserLimit=<memory:8192, vCores:1> userWeight=1.0
2019-06-07 08:05:16,873 DEBUG org.apache.hadoop.yarn.server.resourcemanager.rmapp.attempt.RMAppAttemptImpl: Processing event for appattempt_1559894680121_0001_000001 of type STATUS_UPDATE
2019-06-07 08:05:16,873 DEBUG org.apache.hadoop.yarn.server.resourcemanager.rmapp.attempt.RMAppAttemptImpl: Processing event for appattempt_1559894680121_0001_000001 of type STATUS_UPDATE
2019-06-07 08:05:17,352 DEBUG org.apache.hadoop.yarn.server.resourcemanager.rmnode.RMNodeImpl: Processing slave1:43282 of type STATUS_UPDATE
2019-06-07 08:05:17,352 DEBUG org.apache.hadoop.yarn.server.resourcemanager.rmnode.RMNodeImpl: Processing slave1:43282 of type STATUS_UPDATE
2019-06-07 08:05:17,352 DEBUG org.apache.hadoop.yarn.server.resourcemanager.scheduler.capacity.CapacityScheduler: nodeUpdate: slave1:43282 clusterResources: <memory:8192, vCores:2>
2019-06-07 08:05:17,352 DEBUG org.apache.hadoop.yarn.server.resourcemanager.scheduler.capacity.CapacityScheduler: nodeUpdate: slave1:43282 clusterResources: <memory:8192, vCores:2>
2019-06-07 08:05:17,353 DEBUG org.apache.hadoop.yarn.server.resourcemanager.scheduler.capacity.CapacityScheduler: Node being looked for scheduling slave1:43282 availableResource: <memory:0, vCores:-1>
2019-06-07 08:05:17,353 DEBUG org.apache.hadoop.yarn.server.resourcemanager.scheduler.capacity.CapacityScheduler: Node being looked for scheduling slave1:43282 availableResource: <memory:0, vCores:-1>
2019-06-07 08:05:17,405 DEBUG org.apache.hadoop.yarn.server.resourcemanager.rmnode.RMNodeImpl: Processing slave2:37804 of type STATUS_UPDATE
2019-06-07 08:05:17,405 DEBUG org.apache.hadoop.yarn.server.resourcemanager.rmnode.RMNodeImpl: Processing slave2:37804 of type STATUS_UPDATE
2019-06-07 08:05:17,405 DEBUG org.apache.hadoop.yarn.server.resourcemanager.scheduler.capacity.CapacityScheduler: nodeUpdate: slave2:37804 clusterResources: <memory:8192, vCores:2>
2019-06-07 08:05:17,405 DEBUG org.apache.hadoop.yarn.server.resourcemanager.scheduler.capacity.CapacityScheduler: nodeUpdate: slave2:37804 clusterResources: <memory:8192, vCores:2>
2019-06-07 08:05:17,405 DEBUG org.apache.hadoop.yarn.server.resourcemanager.scheduler.capacity.CapacityScheduler: Node being looked for scheduling slave2:37804 availableResource: <memory:1024, vCores:0>
2019-06-07 08:05:17,405 DEBUG org.apache.hadoop.yarn.server.resourcemanager.scheduler.capacity.CapacityScheduler: Node being looked for scheduling slave2:37804 availableResource: <memory:1024, vCores:0>
2019-06-07 08:05:17,405 DEBUG org.apache.hadoop.yarn.server.resourcemanager.scheduler.capacity.CapacityScheduler: Trying to schedule on node: slave2, available: <memory:1024, vCores:0>
2019-06-07 08:05:17,405 DEBUG org.apache.hadoop.yarn.server.resourcemanager.scheduler.capacity.CapacityScheduler: Trying to schedule on node: slave2, available: <memory:1024, vCores:0>
2019-06-07 08:05:17,405 DEBUG org.apache.hadoop.yarn.server.resourcemanager.scheduler.capacity.ParentQueue: Skip this queue=root, because it doesn't need more resource, schedulingMode=RESPECT_PARTITION_EXCLUSIVITY node-partition=
2019-06-07 08:05:17,405 DEBUG org.apache.hadoop.yarn.server.resourcemanager.scheduler.capacity.ParentQueue: Skip this queue=root, because it doesn't need more resource, schedulingMode=RESPECT_PARTITION_EXCLUSIVITY node-partition=
2019-06-07 08:05:18,355 DEBUG org.apache.hadoop.yarn.server.resourcemanager.rmnode.RMNodeImpl: Processing slave1:43282 of type STATUS_UPDATE
2019-06-07 08:05:18,355 DEBUG org.apache.hadoop.yarn.server.resourcemanager.rmnode.RMNodeImpl: Processing slave1:43282 of type STATUS_UPDATE
2019-06-07 08:05:18,356 DEBUG org.apache.hadoop.yarn.server.resourcemanager.scheduler.capacity.CapacityScheduler: nodeUpdate: slave1:43282 clusterResources: <memory:8192, vCores:2>
2019-06-07 08:05:18,356 DEBUG org.apache.hadoop.yarn.server.resourcemanager.scheduler.capacity.CapacityScheduler: nodeUpdate: slave1:43282 clusterResources: <memory:8192, vCores:2>
2019-06-07 08:05:18,356 DEBUG org.apache.hadoop.yarn.server.resourcemanager.scheduler.capacity.CapacityScheduler: Node being looked for scheduling slave1:43282 availableResource: <memory:0, vCores:-1>
2019-06-07 08:05:18,356 DEBUG org.apache.hadoop.yarn.server.resourcemanager.scheduler.capacity.CapacityScheduler: Node being looked for scheduling slave1:43282 availableResource: <memory:0, vCores:-1>
2019-06-07 08:05:18,408 DEBUG org.apache.hadoop.yarn.server.resourcemanager.rmnode.RMNodeImpl: Processing slave2:37804 of type STATUS_UPDATE
2019-06-07 08:05:18,408 DEBUG org.apache.hadoop.yarn.server.resourcemanager.rmnode.RMNodeImpl: Processing slave2:37804 of type STATUS_UPDATE
2019-06-07 08:05:18,408 DEBUG org.apache.hadoop.yarn.server.resourcemanager.scheduler.capacity.CapacityScheduler: nodeUpdate: slave2:37804 clusterResources: <memory:8192, vCores:2>
2019-06-07 08:05:18,408 DEBUG org.apache.hadoop.yarn.server.resourcemanager.scheduler.capacity.CapacityScheduler: nodeUpdate: slave2:37804 clusterResources: <memory:8192, vCores:2>
2019-06-07 08:05:18,408 DEBUG org.apache.hadoop.yarn.server.resourcemanager.scheduler.capacity.CapacityScheduler: Node being looked for scheduling slave2:37804 availableResource: <memory:1024, vCores:0>
2019-06-07 08:05:18,408 DEBUG org.apache.hadoop.yarn.server.resourcemanager.scheduler.capacity.CapacityScheduler: Node being looked for scheduling slave2:37804 availableResource: <memory:1024, vCores:0>
2019-06-07 08:05:18,408 DEBUG org.apache.hadoop.yarn.server.resourcemanager.scheduler.capacity.CapacityScheduler: Trying to schedule on node: slave2, available: <memory:1024, vCores:0>
2019-06-07 08:05:18,408 DEBUG org.apache.hadoop.yarn.server.resourcemanager.scheduler.capacity.CapacityScheduler: Trying to schedule on node: slave2, available: <memory:1024, vCores:0>
2019-06-07 08:05:18,408 DEBUG org.apache.hadoop.yarn.server.resourcemanager.scheduler.capacity.ParentQueue: Skip this queue=root, because it doesn't need more resource, schedulingMode=RESPECT_PARTITION_EXCLUSIVITY node-partition=
2019-06-07 08:05:18,408 DEBUG org.apache.hadoop.yarn.server.resourcemanager.scheduler.capacity.ParentQueue: Skip this queue=root, because it doesn't need more resource, schedulingMode=RESPECT_PARTITION_EXCLUSIVITY node-partition=
2019-06-07 08:05:19,360 DEBUG org.apache.hadoop.yarn.server.resourcemanager.rmnode.RMNodeImpl: Processing slave1:43282 of type STATUS_UPDATE
2019-06-07 08:05:19,360 DEBUG org.apache.hadoop.yarn.server.resourcemanager.rmnode.RMNodeImpl: Processing slave1:43282 of type STATUS_UPDATE
2019-06-07 08:05:19,360 DEBUG org.apache.hadoop.yarn.server.resourcemanager.scheduler.capacity.CapacityScheduler: nodeUpdate: slave1:43282 clusterResources: <memory:8192, vCores:2>
2019-06-07 08:05:19,360 DEBUG org.apache.hadoop.yarn.server.resourcemanager.scheduler.capacity.CapacityScheduler: nodeUpdate: slave1:43282 clusterResources: <memory:8192, vCores:2>
2019-06-07 08:05:19,360 DEBUG org.apache.hadoop.yarn.server.resourcemanager.scheduler.capacity.CapacityScheduler: Node being looked for scheduling slave1:43282 availableResource: <memory:0, vCores:-1>
2019-06-07 08:05:19,360 DEBUG org.apache.hadoop.yarn.server.resourcemanager.scheduler.capacity.CapacityScheduler: Node being looked for scheduling slave1:43282 availableResource: <memory:0, vCores:-1>
2019-06-07 08:05:19,411 DEBUG org.apache.hadoop.yarn.server.resourcemanager.rmnode.RMNodeImpl: Processing slave2:37804 of type STATUS_UPDATE
2019-06-07 08:05:19,411 DEBUG org.apache.hadoop.yarn.server.resourcemanager.rmnode.RMNodeImpl: Processing slave2:37804 of type STATUS_UPDATE
2019-06-07 08:05:19,412 DEBUG org.apache.hadoop.yarn.server.resourcemanager.scheduler.capacity.CapacityScheduler: nodeUpdate: slave2:37804 clusterResources: <memory:8192, vCores:2>
2019-06-07 08:05:19,412 DEBUG org.apache.hadoop.yarn.server.resourcemanager.scheduler.capacity.CapacityScheduler: nodeUpdate: slave2:37804 clusterResources: <memory:8192, vCores:2>
2019-06-07 08:05:19,412 DEBUG org.apache.hadoop.yarn.server.resourcemanager.scheduler.capacity.CapacityScheduler: Node being looked for scheduling slave2:37804 availableResource: <memory:1024, vCores:0>
2019-06-07 08:05:19,412 DEBUG org.apache.hadoop.yarn.server.resourcemanager.scheduler.capacity.CapacityScheduler: Node being looked for scheduling slave2:37804 availableResource: <memory:1024, vCores:0>
2019-06-07 08:05:19,412 DEBUG org.apache.hadoop.yarn.server.resourcemanager.scheduler.capacity.CapacityScheduler: Trying to schedule on node: slave2, available: <memory:1024, vCores:0>
2019-06-07 08:05:19,412 DEBUG org.apache.hadoop.yarn.server.resourcemanager.scheduler.capacity.CapacityScheduler: Trying to schedule on node: slave2, available: <memory:1024, vCores:0>
2019-06-07 08:05:19,412 DEBUG org.apache.hadoop.yarn.server.resourcemanager.scheduler.capacity.ParentQueue: Skip this queue=root, because it doesn't need more resource, schedulingMode=RESPECT_PARTITION_EXCLUSIVITY node-partition=
2019-06-07 08:05:19,412 DEBUG org.apache.hadoop.yarn.server.resourcemanager.scheduler.capacity.ParentQueue: Skip this queue=root, because it doesn't need more resource, schedulingMode=RESPECT_PARTITION_EXCLUSIVITY node-partition=
2019-06-07 08:05:19,878 DEBUG org.apache.hadoop.yarn.server.resourcemanager.scheduler.capacity.LeafQueue: User limit computation for root in queue default userLimitPercent=100 userLimitFactor=1.0 required: <memory:1024, vCores:1> consumed: <memory:7168, vCores:1> user-limit-resource: <memory:8192, vCores:1> queueCapacity: <memory:8192, vCores:1> qconsumed: <memory:7168, vCores:3> consumedRatio: 0.0 currentCapacity: <memory:8192, vCores:1> activeUsers: 0.0 clusterCapacity: <memory:8192, vCores:2> resourceByLabel: <memory:8192, vCores:2> usageratio: 0.875 Partition:  maxUserLimit=<memory:8192, vCores:1> userWeight=1.0
2019-06-07 08:05:19,878 DEBUG org.apache.hadoop.yarn.server.resourcemanager.scheduler.capacity.LeafQueue: User limit computation for root in queue default userLimitPercent=100 userLimitFactor=1.0 required: <memory:1024, vCores:1> consumed: <memory:7168, vCores:1> user-limit-resource: <memory:8192, vCores:1> queueCapacity: <memory:8192, vCores:1> qconsumed: <memory:7168, vCores:3> consumedRatio: 0.0 currentCapacity: <memory:8192, vCores:1> activeUsers: 0.0 clusterCapacity: <memory:8192, vCores:2> resourceByLabel: <memory:8192, vCores:2> usageratio: 0.875 Partition:  maxUserLimit=<memory:8192, vCores:1> userWeight=1.0
2019-06-07 08:05:19,878 DEBUG org.apache.hadoop.yarn.server.resourcemanager.rmapp.attempt.RMAppAttemptImpl: Processing event for appattempt_1559894680121_0001_000001 of type STATUS_UPDATE
2019-06-07 08:05:19,878 DEBUG org.apache.hadoop.yarn.server.resourcemanager.rmapp.attempt.RMAppAttemptImpl: Processing event for appattempt_1559894680121_0001_000001 of type STATUS_UPDATE
2019-06-07 08:05:20,367 DEBUG org.apache.hadoop.yarn.server.resourcemanager.rmnode.RMNodeImpl: Processing slave1:43282 of type STATUS_UPDATE
2019-06-07 08:05:20,367 DEBUG org.apache.hadoop.yarn.server.resourcemanager.rmnode.RMNodeImpl: Processing slave1:43282 of type STATUS_UPDATE
2019-06-07 08:05:20,367 DEBUG org.apache.hadoop.yarn.server.resourcemanager.scheduler.capacity.CapacityScheduler: nodeUpdate: slave1:43282 clusterResources: <memory:8192, vCores:2>
2019-06-07 08:05:20,367 DEBUG org.apache.hadoop.yarn.server.resourcemanager.scheduler.capacity.CapacityScheduler: nodeUpdate: slave1:43282 clusterResources: <memory:8192, vCores:2>
2019-06-07 08:05:20,371 DEBUG org.apache.hadoop.yarn.server.resourcemanager.scheduler.capacity.CapacityScheduler: Node being looked for scheduling slave1:43282 availableResource: <memory:0, vCores:-1>
2019-06-07 08:05:20,371 DEBUG org.apache.hadoop.yarn.server.resourcemanager.scheduler.capacity.CapacityScheduler: Node being looked for scheduling slave1:43282 availableResource: <memory:0, vCores:-1>
2019-06-07 08:05:20,416 DEBUG org.apache.hadoop.yarn.server.resourcemanager.rmnode.RMNodeImpl: Processing slave2:37804 of type STATUS_UPDATE
2019-06-07 08:05:20,416 DEBUG org.apache.hadoop.yarn.server.resourcemanager.rmnode.RMNodeImpl: Processing slave2:37804 of type STATUS_UPDATE
2019-06-07 08:05:20,417 DEBUG org.apache.hadoop.yarn.server.resourcemanager.scheduler.capacity.CapacityScheduler: nodeUpdate: slave2:37804 clusterResources: <memory:8192, vCores:2>
2019-06-07 08:05:20,417 DEBUG org.apache.hadoop.yarn.server.resourcemanager.scheduler.capacity.CapacityScheduler: nodeUpdate: slave2:37804 clusterResources: <memory:8192, vCores:2>
2019-06-07 08:05:20,417 DEBUG org.apache.hadoop.yarn.server.resourcemanager.scheduler.capacity.CapacityScheduler: Node being looked for scheduling slave2:37804 availableResource: <memory:1024, vCores:0>
2019-06-07 08:05:20,417 DEBUG org.apache.hadoop.yarn.server.resourcemanager.scheduler.capacity.CapacityScheduler: Node being looked for scheduling slave2:37804 availableResource: <memory:1024, vCores:0>
2019-06-07 08:05:20,417 DEBUG org.apache.hadoop.yarn.server.resourcemanager.scheduler.capacity.CapacityScheduler: Trying to schedule on node: slave2, available: <memory:1024, vCores:0>
2019-06-07 08:05:20,417 DEBUG org.apache.hadoop.yarn.server.resourcemanager.scheduler.capacity.CapacityScheduler: Trying to schedule on node: slave2, available: <memory:1024, vCores:0>
2019-06-07 08:05:20,417 DEBUG org.apache.hadoop.yarn.server.resourcemanager.scheduler.capacity.ParentQueue: Skip this queue=root, because it doesn't need more resource, schedulingMode=RESPECT_PARTITION_EXCLUSIVITY node-partition=
2019-06-07 08:05:20,417 DEBUG org.apache.hadoop.yarn.server.resourcemanager.scheduler.capacity.ParentQueue: Skip this queue=root, because it doesn't need more resource, schedulingMode=RESPECT_PARTITION_EXCLUSIVITY node-partition=
2019-06-07 08:05:21,366 DEBUG org.apache.hadoop.yarn.server.resourcemanager.rmnode.RMNodeImpl: Processing slave1:43282 of type STATUS_UPDATE
2019-06-07 08:05:21,366 DEBUG org.apache.hadoop.yarn.server.resourcemanager.rmnode.RMNodeImpl: Processing slave1:43282 of type STATUS_UPDATE
2019-06-07 08:05:21,369 DEBUG org.apache.hadoop.yarn.server.resourcemanager.scheduler.capacity.CapacityScheduler: nodeUpdate: slave1:43282 clusterResources: <memory:8192, vCores:2>
2019-06-07 08:05:21,369 DEBUG org.apache.hadoop.yarn.server.resourcemanager.scheduler.capacity.CapacityScheduler: nodeUpdate: slave1:43282 clusterResources: <memory:8192, vCores:2>
2019-06-07 08:05:21,370 DEBUG org.apache.hadoop.yarn.server.resourcemanager.scheduler.capacity.CapacityScheduler: Node being looked for scheduling slave1:43282 availableResource: <memory:0, vCores:-1>
2019-06-07 08:05:21,370 DEBUG org.apache.hadoop.yarn.server.resourcemanager.scheduler.capacity.CapacityScheduler: Node being looked for scheduling slave1:43282 availableResource: <memory:0, vCores:-1>
2019-06-07 08:05:21,419 DEBUG org.apache.hadoop.yarn.server.resourcemanager.rmnode.RMNodeImpl: Processing slave2:37804 of type STATUS_UPDATE
2019-06-07 08:05:21,419 DEBUG org.apache.hadoop.yarn.server.resourcemanager.rmnode.RMNodeImpl: Processing slave2:37804 of type STATUS_UPDATE
2019-06-07 08:05:21,419 DEBUG org.apache.hadoop.yarn.server.resourcemanager.scheduler.capacity.CapacityScheduler: nodeUpdate: slave2:37804 clusterResources: <memory:8192, vCores:2>
2019-06-07 08:05:21,419 DEBUG org.apache.hadoop.yarn.server.resourcemanager.scheduler.capacity.CapacityScheduler: nodeUpdate: slave2:37804 clusterResources: <memory:8192, vCores:2>
2019-06-07 08:05:21,419 DEBUG org.apache.hadoop.yarn.server.resourcemanager.scheduler.capacity.CapacityScheduler: Node being looked for scheduling slave2:37804 availableResource: <memory:1024, vCores:0>
2019-06-07 08:05:21,419 DEBUG org.apache.hadoop.yarn.server.resourcemanager.scheduler.capacity.CapacityScheduler: Node being looked for scheduling slave2:37804 availableResource: <memory:1024, vCores:0>
2019-06-07 08:05:21,419 DEBUG org.apache.hadoop.yarn.server.resourcemanager.scheduler.capacity.CapacityScheduler: Trying to schedule on node: slave2, available: <memory:1024, vCores:0>
2019-06-07 08:05:21,419 DEBUG org.apache.hadoop.yarn.server.resourcemanager.scheduler.capacity.CapacityScheduler: Trying to schedule on node: slave2, available: <memory:1024, vCores:0>
2019-06-07 08:05:21,419 DEBUG org.apache.hadoop.yarn.server.resourcemanager.scheduler.capacity.ParentQueue: Skip this queue=root, because it doesn't need more resource, schedulingMode=RESPECT_PARTITION_EXCLUSIVITY node-partition=
2019-06-07 08:05:21,419 DEBUG org.apache.hadoop.yarn.server.resourcemanager.scheduler.capacity.ParentQueue: Skip this queue=root, because it doesn't need more resource, schedulingMode=RESPECT_PARTITION_EXCLUSIVITY node-partition=
2019-06-07 08:05:22,388 DEBUG org.apache.hadoop.yarn.server.resourcemanager.rmnode.RMNodeImpl: Processing slave1:43282 of type STATUS_UPDATE
2019-06-07 08:05:22,388 DEBUG org.apache.hadoop.yarn.server.resourcemanager.rmnode.RMNodeImpl: Processing slave1:43282 of type STATUS_UPDATE
2019-06-07 08:05:22,388 DEBUG org.apache.hadoop.yarn.server.resourcemanager.scheduler.capacity.CapacityScheduler: nodeUpdate: slave1:43282 clusterResources: <memory:8192, vCores:2>
2019-06-07 08:05:22,388 DEBUG org.apache.hadoop.yarn.server.resourcemanager.scheduler.capacity.CapacityScheduler: nodeUpdate: slave1:43282 clusterResources: <memory:8192, vCores:2>
2019-06-07 08:05:22,388 DEBUG org.apache.hadoop.yarn.server.resourcemanager.scheduler.capacity.CapacityScheduler: Node being looked for scheduling slave1:43282 availableResource: <memory:0, vCores:-1>
2019-06-07 08:05:22,388 DEBUG org.apache.hadoop.yarn.server.resourcemanager.scheduler.capacity.CapacityScheduler: Node being looked for scheduling slave1:43282 availableResource: <memory:0, vCores:-1>
2019-06-07 08:05:22,432 DEBUG org.apache.hadoop.yarn.server.resourcemanager.rmnode.RMNodeImpl: Processing slave2:37804 of type STATUS_UPDATE
2019-06-07 08:05:22,432 DEBUG org.apache.hadoop.yarn.server.resourcemanager.rmnode.RMNodeImpl: Processing slave2:37804 of type STATUS_UPDATE
2019-06-07 08:05:22,433 DEBUG org.apache.hadoop.yarn.server.resourcemanager.scheduler.capacity.CapacityScheduler: nodeUpdate: slave2:37804 clusterResources: <memory:8192, vCores:2>
2019-06-07 08:05:22,433 DEBUG org.apache.hadoop.yarn.server.resourcemanager.scheduler.capacity.CapacityScheduler: nodeUpdate: slave2:37804 clusterResources: <memory:8192, vCores:2>
2019-06-07 08:05:22,433 DEBUG org.apache.hadoop.yarn.server.resourcemanager.scheduler.capacity.CapacityScheduler: Node being looked for scheduling slave2:37804 availableResource: <memory:1024, vCores:0>
2019-06-07 08:05:22,433 DEBUG org.apache.hadoop.yarn.server.resourcemanager.scheduler.capacity.CapacityScheduler: Node being looked for scheduling slave2:37804 availableResource: <memory:1024, vCores:0>
2019-06-07 08:05:22,433 DEBUG org.apache.hadoop.yarn.server.resourcemanager.scheduler.capacity.CapacityScheduler: Trying to schedule on node: slave2, available: <memory:1024, vCores:0>
2019-06-07 08:05:22,433 DEBUG org.apache.hadoop.yarn.server.resourcemanager.scheduler.capacity.CapacityScheduler: Trying to schedule on node: slave2, available: <memory:1024, vCores:0>
2019-06-07 08:05:22,433 DEBUG org.apache.hadoop.yarn.server.resourcemanager.scheduler.capacity.ParentQueue: Skip this queue=root, because it doesn't need more resource, schedulingMode=RESPECT_PARTITION_EXCLUSIVITY node-partition=
2019-06-07 08:05:22,433 DEBUG org.apache.hadoop.yarn.server.resourcemanager.scheduler.capacity.ParentQueue: Skip this queue=root, because it doesn't need more resource, schedulingMode=RESPECT_PARTITION_EXCLUSIVITY node-partition=
2019-06-07 08:05:22,887 DEBUG org.apache.hadoop.yarn.server.resourcemanager.scheduler.capacity.LeafQueue: User limit computation for root in queue default userLimitPercent=100 userLimitFactor=1.0 required: <memory:1024, vCores:1> consumed: <memory:7168, vCores:1> user-limit-resource: <memory:8192, vCores:1> queueCapacity: <memory:8192, vCores:1> qconsumed: <memory:7168, vCores:3> consumedRatio: 0.0 currentCapacity: <memory:8192, vCores:1> activeUsers: 0.0 clusterCapacity: <memory:8192, vCores:2> resourceByLabel: <memory:8192, vCores:2> usageratio: 0.875 Partition:  maxUserLimit=<memory:8192, vCores:1> userWeight=1.0
2019-06-07 08:05:22,887 DEBUG org.apache.hadoop.yarn.server.resourcemanager.scheduler.capacity.LeafQueue: User limit computation for root in queue default userLimitPercent=100 userLimitFactor=1.0 required: <memory:1024, vCores:1> consumed: <memory:7168, vCores:1> user-limit-resource: <memory:8192, vCores:1> queueCapacity: <memory:8192, vCores:1> qconsumed: <memory:7168, vCores:3> consumedRatio: 0.0 currentCapacity: <memory:8192, vCores:1> activeUsers: 0.0 clusterCapacity: <memory:8192, vCores:2> resourceByLabel: <memory:8192, vCores:2> usageratio: 0.875 Partition:  maxUserLimit=<memory:8192, vCores:1> userWeight=1.0
2019-06-07 08:05:22,887 DEBUG org.apache.hadoop.yarn.server.resourcemanager.rmapp.attempt.RMAppAttemptImpl: Processing event for appattempt_1559894680121_0001_000001 of type STATUS_UPDATE
2019-06-07 08:05:22,887 DEBUG org.apache.hadoop.yarn.server.resourcemanager.rmapp.attempt.RMAppAttemptImpl: Processing event for appattempt_1559894680121_0001_000001 of type STATUS_UPDATE
2019-06-07 08:05:23,276 DEBUG org.apache.hadoop.yarn.server.resourcemanager.scheduler.capacity.LeafQueue: User limit computation for root in queue default userLimitPercent=100 userLimitFactor=1.0 required: <memory:1024, vCores:1> consumed: <memory:7168, vCores:1> user-limit-resource: <memory:8192, vCores:1> queueCapacity: <memory:8192, vCores:1> qconsumed: <memory:7168, vCores:3> consumedRatio: 0.0 currentCapacity: <memory:8192, vCores:1> activeUsers: 0.0 clusterCapacity: <memory:8192, vCores:2> resourceByLabel: <memory:8192, vCores:2> usageratio: 0.875 Partition:  maxUserLimit=<memory:8192, vCores:1> userWeight=1.0
2019-06-07 08:05:23,276 DEBUG org.apache.hadoop.yarn.server.resourcemanager.rmapp.attempt.RMAppAttemptImpl: Processing event for appattempt_1559894680121_0001_000001 of type STATUS_UPDATE
2019-06-07 08:05:23,276 DEBUG org.apache.hadoop.yarn.server.resourcemanager.scheduler.capacity.LeafQueue: User limit computation for root in queue default userLimitPercent=100 userLimitFactor=1.0 required: <memory:1024, vCores:1> consumed: <memory:7168, vCores:1> user-limit-resource: <memory:8192, vCores:1> queueCapacity: <memory:8192, vCores:1> qconsumed: <memory:7168, vCores:3> consumedRatio: 0.0 currentCapacity: <memory:8192, vCores:1> activeUsers: 0.0 clusterCapacity: <memory:8192, vCores:2> resourceByLabel: <memory:8192, vCores:2> usageratio: 0.875 Partition:  maxUserLimit=<memory:8192, vCores:1> userWeight=1.0
2019-06-07 08:05:23,276 DEBUG org.apache.hadoop.yarn.server.resourcemanager.rmapp.attempt.RMAppAttemptImpl: Processing event for appattempt_1559894680121_0001_000001 of type STATUS_UPDATE
2019-06-07 08:05:23,385 DEBUG org.apache.hadoop.yarn.server.resourcemanager.rmapp.attempt.RMAppAttemptImpl: Processing event for appattempt_1559894680121_0001_000001 of type UNREGISTERED
2019-06-07 08:05:23,385 DEBUG org.apache.hadoop.yarn.server.resourcemanager.rmapp.attempt.RMAppAttemptImpl: Processing event for appattempt_1559894680121_0001_000001 of type UNREGISTERED
2019-06-07 08:05:23,387 INFO org.apache.hadoop.yarn.server.resourcemanager.rmapp.attempt.RMAppAttemptImpl: Updating application attempt appattempt_1559894680121_0001_000001 with final state: FINISHING, and exit status: -1000
2019-06-07 08:05:23,387 INFO org.apache.hadoop.yarn.server.resourcemanager.rmapp.attempt.RMAppAttemptImpl: Updating application attempt appattempt_1559894680121_0001_000001 with final state: FINISHING, and exit status: -1000
2019-06-07 08:05:23,387 INFO org.apache.hadoop.yarn.server.resourcemanager.rmapp.attempt.RMAppAttemptImpl: appattempt_1559894680121_0001_000001 State change from RUNNING to FINAL_SAVING
2019-06-07 08:05:23,387 INFO org.apache.hadoop.yarn.server.resourcemanager.rmapp.attempt.RMAppAttemptImpl: appattempt_1559894680121_0001_000001 State change from RUNNING to FINAL_SAVING
2019-06-07 08:05:23,387 DEBUG org.apache.hadoop.yarn.server.resourcemanager.rmapp.RMAppImpl: Processing event for application_1559894680121_0001 of type ATTEMPT_UNREGISTERED
2019-06-07 08:05:23,387 DEBUG org.apache.hadoop.yarn.server.resourcemanager.rmapp.RMAppImpl: Processing event for application_1559894680121_0001 of type ATTEMPT_UNREGISTERED
2019-06-07 08:05:23,387 INFO org.apache.hadoop.yarn.server.resourcemanager.rmapp.RMAppImpl: Updating application application_1559894680121_0001 with final state: FINISHING
2019-06-07 08:05:23,387 INFO org.apache.hadoop.yarn.server.resourcemanager.rmapp.RMAppImpl: Updating application application_1559894680121_0001 with final state: FINISHING
2019-06-07 08:05:23,387 INFO org.apache.hadoop.yarn.server.resourcemanager.rmapp.RMAppImpl: application_1559894680121_0001 State change from RUNNING to FINAL_SAVING on event=ATTEMPT_UNREGISTERED
2019-06-07 08:05:23,387 INFO org.apache.hadoop.yarn.server.resourcemanager.rmapp.RMAppImpl: application_1559894680121_0001 State change from RUNNING to FINAL_SAVING on event=ATTEMPT_UNREGISTERED
2019-06-07 08:05:23,389 DEBUG org.apache.hadoop.yarn.server.resourcemanager.recovery.RMStateStore: Processing event of type UPDATE_APP_ATTEMPT
2019-06-07 08:05:23,389 DEBUG org.apache.hadoop.yarn.server.resourcemanager.recovery.RMStateStore: Processing event of type UPDATE_APP_ATTEMPT
2019-06-07 08:05:23,396 DEBUG org.apache.hadoop.yarn.server.resourcemanager.recovery.RMStateStore: Updating info for attempt: appattempt_1559894680121_0001_000001
2019-06-07 08:05:23,396 DEBUG org.apache.hadoop.yarn.server.resourcemanager.recovery.RMStateStore: Updating info for attempt: appattempt_1559894680121_0001_000001
2019-06-07 08:05:23,396 DEBUG org.apache.hadoop.yarn.server.resourcemanager.recovery.RMStateStore: Processing event of type UPDATE_APP
2019-06-07 08:05:23,396 DEBUG org.apache.hadoop.yarn.server.resourcemanager.recovery.RMStateStore: Processing event of type UPDATE_APP
2019-06-07 08:05:23,396 INFO org.apache.hadoop.yarn.server.resourcemanager.recovery.RMStateStore: Updating info for app: application_1559894680121_0001
2019-06-07 08:05:23,396 INFO org.apache.hadoop.yarn.server.resourcemanager.recovery.RMStateStore: Updating info for app: application_1559894680121_0001
2019-06-07 08:05:23,397 DEBUG org.apache.hadoop.yarn.server.resourcemanager.rmnode.RMNodeImpl: Processing slave1:43282 of type STATUS_UPDATE
2019-06-07 08:05:23,397 DEBUG org.apache.hadoop.yarn.server.resourcemanager.rmnode.RMNodeImpl: Processing slave1:43282 of type STATUS_UPDATE
2019-06-07 08:05:23,397 DEBUG org.apache.hadoop.yarn.server.resourcemanager.rmapp.attempt.RMAppAttemptImpl: Processing event for appattempt_1559894680121_0001_000001 of type ATTEMPT_UPDATE_SAVED
2019-06-07 08:05:23,397 DEBUG org.apache.hadoop.yarn.server.resourcemanager.rmapp.attempt.RMAppAttemptImpl: Processing event for appattempt_1559894680121_0001_000001 of type ATTEMPT_UPDATE_SAVED
2019-06-07 08:05:23,397 INFO org.apache.hadoop.yarn.server.resourcemanager.rmapp.attempt.RMAppAttemptImpl: appattempt_1559894680121_0001_000001 State change from FINAL_SAVING to FINISHING
2019-06-07 08:05:23,397 INFO org.apache.hadoop.yarn.server.resourcemanager.rmapp.attempt.RMAppAttemptImpl: appattempt_1559894680121_0001_000001 State change from FINAL_SAVING to FINISHING
2019-06-07 08:05:23,397 DEBUG org.apache.hadoop.yarn.server.resourcemanager.rmapp.RMAppImpl: Processing event for application_1559894680121_0001 of type APP_UPDATE_SAVED
2019-06-07 08:05:23,397 DEBUG org.apache.hadoop.yarn.server.resourcemanager.rmapp.RMAppImpl: Processing event for application_1559894680121_0001 of type APP_UPDATE_SAVED
2019-06-07 08:05:23,397 INFO org.apache.hadoop.yarn.server.resourcemanager.rmapp.RMAppImpl: application_1559894680121_0001 State change from FINAL_SAVING to FINISHING on event=APP_UPDATE_SAVED
2019-06-07 08:05:23,397 INFO org.apache.hadoop.yarn.server.resourcemanager.rmapp.RMAppImpl: application_1559894680121_0001 State change from FINAL_SAVING to FINISHING on event=APP_UPDATE_SAVED
2019-06-07 08:05:23,398 DEBUG org.apache.hadoop.yarn.server.resourcemanager.scheduler.capacity.CapacityScheduler: nodeUpdate: slave1:43282 clusterResources: <memory:8192, vCores:2>
2019-06-07 08:05:23,398 DEBUG org.apache.hadoop.yarn.server.resourcemanager.scheduler.capacity.CapacityScheduler: nodeUpdate: slave1:43282 clusterResources: <memory:8192, vCores:2>
2019-06-07 08:05:23,399 DEBUG org.apache.hadoop.yarn.server.resourcemanager.scheduler.capacity.CapacityScheduler: Node being looked for scheduling slave1:43282 availableResource: <memory:0, vCores:-1>
2019-06-07 08:05:23,399 DEBUG org.apache.hadoop.yarn.server.resourcemanager.scheduler.capacity.CapacityScheduler: Node being looked for scheduling slave1:43282 availableResource: <memory:0, vCores:-1>
2019-06-07 08:05:23,429 DEBUG org.apache.hadoop.yarn.server.resourcemanager.rmnode.RMNodeImpl: Processing slave2:37804 of type STATUS_UPDATE
2019-06-07 08:05:23,429 DEBUG org.apache.hadoop.yarn.server.resourcemanager.rmnode.RMNodeImpl: Processing slave2:37804 of type STATUS_UPDATE
2019-06-07 08:05:23,429 DEBUG org.apache.hadoop.yarn.server.resourcemanager.scheduler.capacity.CapacityScheduler: nodeUpdate: slave2:37804 clusterResources: <memory:8192, vCores:2>
2019-06-07 08:05:23,429 DEBUG org.apache.hadoop.yarn.server.resourcemanager.scheduler.capacity.CapacityScheduler: nodeUpdate: slave2:37804 clusterResources: <memory:8192, vCores:2>
2019-06-07 08:05:23,430 DEBUG org.apache.hadoop.yarn.server.resourcemanager.rmcontainer.RMContainerImpl: Processing container_1559894680121_0001_01_000002 of type FINISHED
2019-06-07 08:05:23,430 DEBUG org.apache.hadoop.yarn.server.resourcemanager.rmcontainer.RMContainerImpl: Processing container_1559894680121_0001_01_000002 of type FINISHED
2019-06-07 08:05:23,430 DEBUG org.apache.hadoop.yarn.server.resourcemanager.rmapp.attempt.RMAppAttemptImpl: Processing event for appattempt_1559894680121_0001_000001 of type CONTAINER_FINISHED
2019-06-07 08:05:23,430 DEBUG org.apache.hadoop.yarn.server.resourcemanager.rmapp.attempt.RMAppAttemptImpl: Processing event for appattempt_1559894680121_0001_000001 of type CONTAINER_FINISHED
2019-06-07 08:05:23,430 INFO org.apache.hadoop.yarn.server.resourcemanager.rmcontainer.RMContainerImpl: container_1559894680121_0001_01_000002 Container Transitioned from RUNNING to COMPLETED
2019-06-07 08:05:23,430 INFO org.apache.hadoop.yarn.server.resourcemanager.rmcontainer.RMContainerImpl: container_1559894680121_0001_01_000002 Container Transitioned from RUNNING to COMPLETED
2019-06-07 08:05:23,430 INFO org.apache.hadoop.yarn.server.resourcemanager.RMAuditLogger: USER=root	OPERATION=AM Released Container	TARGET=SchedulerApp	RESULT=SUCCESS	APPID=application_1559894680121_0001	CONTAINERID=container_1559894680121_0001_01_000002
2019-06-07 08:05:23,430 INFO org.apache.hadoop.yarn.server.resourcemanager.RMAuditLogger: USER=root	OPERATION=AM Released Container	TARGET=SchedulerApp	RESULT=SUCCESS	APPID=application_1559894680121_0001	CONTAINERID=container_1559894680121_0001_01_000002
2019-06-07 08:05:23,430 DEBUG org.apache.hadoop.yarn.server.resourcemanager.scheduler.capacity.LeafQueue: User limit computation for root in queue default userLimitPercent=100 userLimitFactor=1.0 required: <memory:1024, vCores:1> consumed: <memory:4096, vCores:1> user-limit-resource: <memory:8192, vCores:1> queueCapacity: <memory:8192, vCores:1> qconsumed: <memory:4096, vCores:2> consumedRatio: 0.0 currentCapacity: <memory:8192, vCores:1> activeUsers: 0.0 clusterCapacity: <memory:8192, vCores:2> resourceByLabel: <memory:8192, vCores:2> usageratio: 0.5 Partition:  maxUserLimit=<memory:8192, vCores:1> userWeight=1.0
2019-06-07 08:05:23,430 DEBUG org.apache.hadoop.yarn.server.resourcemanager.scheduler.capacity.LeafQueue: User limit computation for root in queue default userLimitPercent=100 userLimitFactor=1.0 required: <memory:1024, vCores:1> consumed: <memory:4096, vCores:1> user-limit-resource: <memory:8192, vCores:1> queueCapacity: <memory:8192, vCores:1> qconsumed: <memory:4096, vCores:2> consumedRatio: 0.0 currentCapacity: <memory:8192, vCores:1> activeUsers: 0.0 clusterCapacity: <memory:8192, vCores:2> resourceByLabel: <memory:8192, vCores:2> usageratio: 0.5 Partition:  maxUserLimit=<memory:8192, vCores:1> userWeight=1.0
2019-06-07 08:05:23,430 DEBUG org.apache.hadoop.yarn.server.resourcemanager.scheduler.capacity.LeafQueue: default used=<memory:4096, vCores:2> numContainers=2 user=root user-resources=<memory:4096, vCores:2>
2019-06-07 08:05:23,430 DEBUG org.apache.hadoop.yarn.server.resourcemanager.scheduler.capacity.LeafQueue: default used=<memory:4096, vCores:2> numContainers=2 user=root user-resources=<memory:4096, vCores:2>
2019-06-07 08:05:23,430 DEBUG org.apache.hadoop.yarn.server.resourcemanager.scheduler.capacity.ParentQueue: completedContainer root: numChildQueue= 1, capacity=1.0, absoluteCapacity=1.0, usedResources=<memory:4096, vCores:2>usedCapacity=0.5, numApps=1, numContainers=2, cluster=<memory:8192, vCores:2>
2019-06-07 08:05:23,430 DEBUG org.apache.hadoop.yarn.server.resourcemanager.scheduler.capacity.ParentQueue: completedContainer root: numChildQueue= 1, capacity=1.0, absoluteCapacity=1.0, usedResources=<memory:4096, vCores:2>usedCapacity=0.5, numApps=1, numContainers=2, cluster=<memory:8192, vCores:2>
2019-06-07 08:05:23,430 DEBUG org.apache.hadoop.yarn.server.resourcemanager.scheduler.capacity.ParentQueue: Re-sorting completed queue: default: capacity=1.0, absoluteCapacity=1.0, usedResources=<memory:4096, vCores:2>, usedCapacity=0.5, absoluteUsedCapacity=0.5, numApps=1, numContainers=2
2019-06-07 08:05:23,430 DEBUG org.apache.hadoop.yarn.server.resourcemanager.scheduler.capacity.ParentQueue: Re-sorting completed queue: default: capacity=1.0, absoluteCapacity=1.0, usedResources=<memory:4096, vCores:2>, usedCapacity=0.5, absoluteUsedCapacity=0.5, numApps=1, numContainers=2
2019-06-07 08:05:23,431 INFO org.apache.hadoop.yarn.server.resourcemanager.scheduler.SchedulerNode: Released container container_1559894680121_0001_01_000002 of capacity <memory:3072, vCores:1> on host slave2:37804, which currently has 0 containers, <memory:0, vCores:0> used and <memory:4096, vCores:1> available, release resources=true
2019-06-07 08:05:23,431 INFO org.apache.hadoop.yarn.server.resourcemanager.scheduler.SchedulerNode: Released container container_1559894680121_0001_01_000002 of capacity <memory:3072, vCores:1> on host slave2:37804, which currently has 0 containers, <memory:0, vCores:0> used and <memory:4096, vCores:1> available, release resources=true
2019-06-07 08:05:23,431 DEBUG org.apache.hadoop.yarn.server.resourcemanager.scheduler.capacity.CapacityScheduler: Node being looked for scheduling slave2:37804 availableResource: <memory:4096, vCores:1>
2019-06-07 08:05:23,431 DEBUG org.apache.hadoop.yarn.server.resourcemanager.scheduler.capacity.CapacityScheduler: Node being looked for scheduling slave2:37804 availableResource: <memory:4096, vCores:1>
2019-06-07 08:05:23,431 DEBUG org.apache.hadoop.yarn.server.resourcemanager.scheduler.capacity.CapacityScheduler: Trying to schedule on node: slave2, available: <memory:4096, vCores:1>
2019-06-07 08:05:23,431 DEBUG org.apache.hadoop.yarn.server.resourcemanager.scheduler.capacity.CapacityScheduler: Trying to schedule on node: slave2, available: <memory:4096, vCores:1>
2019-06-07 08:05:23,431 DEBUG org.apache.hadoop.yarn.server.resourcemanager.scheduler.capacity.ParentQueue: Skip this queue=root, because it doesn't need more resource, schedulingMode=RESPECT_PARTITION_EXCLUSIVITY node-partition=
2019-06-07 08:05:23,431 DEBUG org.apache.hadoop.yarn.server.resourcemanager.scheduler.capacity.ParentQueue: Skip this queue=root, because it doesn't need more resource, schedulingMode=RESPECT_PARTITION_EXCLUSIVITY node-partition=
2019-06-07 08:05:23,437 DEBUG org.apache.hadoop.yarn.server.resourcemanager.rmnode.RMNodeImpl: Processing slave1:43282 of type STATUS_UPDATE
2019-06-07 08:05:23,437 DEBUG org.apache.hadoop.yarn.server.resourcemanager.rmnode.RMNodeImpl: Processing slave1:43282 of type STATUS_UPDATE
2019-06-07 08:05:23,439 DEBUG org.apache.hadoop.yarn.server.resourcemanager.scheduler.capacity.CapacityScheduler: nodeUpdate: slave1:43282 clusterResources: <memory:8192, vCores:2>
2019-06-07 08:05:23,439 DEBUG org.apache.hadoop.yarn.server.resourcemanager.scheduler.capacity.CapacityScheduler: nodeUpdate: slave1:43282 clusterResources: <memory:8192, vCores:2>
2019-06-07 08:05:23,439 DEBUG org.apache.hadoop.yarn.server.resourcemanager.rmcontainer.RMContainerImpl: Processing container_1559894680121_0001_01_000003 of type FINISHED
2019-06-07 08:05:23,439 DEBUG org.apache.hadoop.yarn.server.resourcemanager.rmcontainer.RMContainerImpl: Processing container_1559894680121_0001_01_000003 of type FINISHED
2019-06-07 08:05:23,439 INFO org.apache.hadoop.yarn.server.resourcemanager.rmcontainer.RMContainerImpl: container_1559894680121_0001_01_000003 Container Transitioned from RUNNING to COMPLETED
2019-06-07 08:05:23,439 INFO org.apache.hadoop.yarn.server.resourcemanager.rmcontainer.RMContainerImpl: container_1559894680121_0001_01_000003 Container Transitioned from RUNNING to COMPLETED
2019-06-07 08:05:23,439 INFO org.apache.hadoop.yarn.server.resourcemanager.RMAuditLogger: USER=root	OPERATION=AM Released Container	TARGET=SchedulerApp	RESULT=SUCCESS	APPID=application_1559894680121_0001	CONTAINERID=container_1559894680121_0001_01_000003
2019-06-07 08:05:23,439 INFO org.apache.hadoop.yarn.server.resourcemanager.RMAuditLogger: USER=root	OPERATION=AM Released Container	TARGET=SchedulerApp	RESULT=SUCCESS	APPID=application_1559894680121_0001	CONTAINERID=container_1559894680121_0001_01_000003
2019-06-07 08:05:23,439 DEBUG org.apache.hadoop.yarn.server.resourcemanager.scheduler.capacity.LeafQueue: User limit computation for root in queue default userLimitPercent=100 userLimitFactor=1.0 required: <memory:1024, vCores:1> consumed: <memory:1024, vCores:1> user-limit-resource: <memory:8192, vCores:1> queueCapacity: <memory:8192, vCores:1> qconsumed: <memory:1024, vCores:1> consumedRatio: 0.0 currentCapacity: <memory:8192, vCores:1> activeUsers: 0.0 clusterCapacity: <memory:8192, vCores:2> resourceByLabel: <memory:8192, vCores:2> usageratio: 0.125 Partition:  maxUserLimit=<memory:8192, vCores:1> userWeight=1.0
2019-06-07 08:05:23,439 DEBUG org.apache.hadoop.yarn.server.resourcemanager.scheduler.capacity.LeafQueue: User limit computation for root in queue default userLimitPercent=100 userLimitFactor=1.0 required: <memory:1024, vCores:1> consumed: <memory:1024, vCores:1> user-limit-resource: <memory:8192, vCores:1> queueCapacity: <memory:8192, vCores:1> qconsumed: <memory:1024, vCores:1> consumedRatio: 0.0 currentCapacity: <memory:8192, vCores:1> activeUsers: 0.0 clusterCapacity: <memory:8192, vCores:2> resourceByLabel: <memory:8192, vCores:2> usageratio: 0.125 Partition:  maxUserLimit=<memory:8192, vCores:1> userWeight=1.0
2019-06-07 08:05:23,440 DEBUG org.apache.hadoop.yarn.server.resourcemanager.scheduler.capacity.LeafQueue: default used=<memory:1024, vCores:1> numContainers=1 user=root user-resources=<memory:1024, vCores:1>
2019-06-07 08:05:23,440 DEBUG org.apache.hadoop.yarn.server.resourcemanager.scheduler.capacity.LeafQueue: default used=<memory:1024, vCores:1> numContainers=1 user=root user-resources=<memory:1024, vCores:1>
2019-06-07 08:05:23,440 DEBUG org.apache.hadoop.yarn.server.resourcemanager.scheduler.capacity.ParentQueue: completedContainer root: numChildQueue= 1, capacity=1.0, absoluteCapacity=1.0, usedResources=<memory:1024, vCores:1>usedCapacity=0.125, numApps=1, numContainers=1, cluster=<memory:8192, vCores:2>
2019-06-07 08:05:23,440 DEBUG org.apache.hadoop.yarn.server.resourcemanager.scheduler.capacity.ParentQueue: completedContainer root: numChildQueue= 1, capacity=1.0, absoluteCapacity=1.0, usedResources=<memory:1024, vCores:1>usedCapacity=0.125, numApps=1, numContainers=1, cluster=<memory:8192, vCores:2>
2019-06-07 08:05:23,440 DEBUG org.apache.hadoop.yarn.server.resourcemanager.scheduler.capacity.ParentQueue: Re-sorting completed queue: default: capacity=1.0, absoluteCapacity=1.0, usedResources=<memory:1024, vCores:1>, usedCapacity=0.125, absoluteUsedCapacity=0.125, numApps=1, numContainers=1
2019-06-07 08:05:23,440 DEBUG org.apache.hadoop.yarn.server.resourcemanager.scheduler.capacity.ParentQueue: Re-sorting completed queue: default: capacity=1.0, absoluteCapacity=1.0, usedResources=<memory:1024, vCores:1>, usedCapacity=0.125, absoluteUsedCapacity=0.125, numApps=1, numContainers=1
2019-06-07 08:05:23,440 INFO org.apache.hadoop.yarn.server.resourcemanager.scheduler.SchedulerNode: Released container container_1559894680121_0001_01_000003 of capacity <memory:3072, vCores:1> on host slave1:43282, which currently has 1 containers, <memory:1024, vCores:1> used and <memory:3072, vCores:0> available, release resources=true
2019-06-07 08:05:23,440 INFO org.apache.hadoop.yarn.server.resourcemanager.scheduler.SchedulerNode: Released container container_1559894680121_0001_01_000003 of capacity <memory:3072, vCores:1> on host slave1:43282, which currently has 1 containers, <memory:1024, vCores:1> used and <memory:3072, vCores:0> available, release resources=true
2019-06-07 08:05:23,440 DEBUG org.apache.hadoop.yarn.server.resourcemanager.scheduler.capacity.CapacityScheduler: Node being looked for scheduling slave1:43282 availableResource: <memory:3072, vCores:0>
2019-06-07 08:05:23,440 DEBUG org.apache.hadoop.yarn.server.resourcemanager.scheduler.capacity.CapacityScheduler: Node being looked for scheduling slave1:43282 availableResource: <memory:3072, vCores:0>
2019-06-07 08:05:23,440 DEBUG org.apache.hadoop.yarn.server.resourcemanager.scheduler.capacity.CapacityScheduler: Trying to schedule on node: slave1, available: <memory:3072, vCores:0>
2019-06-07 08:05:23,440 DEBUG org.apache.hadoop.yarn.server.resourcemanager.scheduler.capacity.CapacityScheduler: Trying to schedule on node: slave1, available: <memory:3072, vCores:0>
2019-06-07 08:05:23,440 DEBUG org.apache.hadoop.yarn.server.resourcemanager.scheduler.capacity.ParentQueue: Skip this queue=root, because it doesn't need more resource, schedulingMode=RESPECT_PARTITION_EXCLUSIVITY node-partition=
2019-06-07 08:05:23,440 DEBUG org.apache.hadoop.yarn.server.resourcemanager.scheduler.capacity.ParentQueue: Skip this queue=root, because it doesn't need more resource, schedulingMode=RESPECT_PARTITION_EXCLUSIVITY node-partition=
2019-06-07 08:05:23,440 DEBUG org.apache.hadoop.yarn.server.resourcemanager.rmapp.attempt.RMAppAttemptImpl: Processing event for appattempt_1559894680121_0001_000001 of type CONTAINER_FINISHED
2019-06-07 08:05:23,440 DEBUG org.apache.hadoop.yarn.server.resourcemanager.rmapp.attempt.RMAppAttemptImpl: Processing event for appattempt_1559894680121_0001_000001 of type CONTAINER_FINISHED
2019-06-07 08:05:23,509 INFO org.apache.hadoop.yarn.server.resourcemanager.ApplicationMasterService: application_1559894680121_0001 unregistered successfully. 
2019-06-07 08:05:23,509 INFO org.apache.hadoop.yarn.server.resourcemanager.ApplicationMasterService: application_1559894680121_0001 unregistered successfully. 
2019-06-07 08:05:23,964 DEBUG org.apache.hadoop.yarn.server.resourcemanager.rmnode.RMNodeImpl: Processing slave1:43282 of type STATUS_UPDATE
2019-06-07 08:05:23,964 DEBUG org.apache.hadoop.yarn.server.resourcemanager.rmnode.RMNodeImpl: Processing slave1:43282 of type STATUS_UPDATE
2019-06-07 08:05:23,964 DEBUG org.apache.hadoop.yarn.server.resourcemanager.scheduler.capacity.CapacityScheduler: nodeUpdate: slave1:43282 clusterResources: <memory:8192, vCores:2>
2019-06-07 08:05:23,964 DEBUG org.apache.hadoop.yarn.server.resourcemanager.scheduler.capacity.CapacityScheduler: nodeUpdate: slave1:43282 clusterResources: <memory:8192, vCores:2>
2019-06-07 08:05:23,965 DEBUG org.apache.hadoop.yarn.server.resourcemanager.rmcontainer.RMContainerImpl: Processing container_1559894680121_0001_01_000001 of type FINISHED
2019-06-07 08:05:23,965 DEBUG org.apache.hadoop.yarn.server.resourcemanager.rmcontainer.RMContainerImpl: Processing container_1559894680121_0001_01_000001 of type FINISHED
2019-06-07 08:05:23,965 INFO org.apache.hadoop.yarn.server.resourcemanager.rmcontainer.RMContainerImpl: container_1559894680121_0001_01_000001 Container Transitioned from RUNNING to COMPLETED
2019-06-07 08:05:23,965 INFO org.apache.hadoop.yarn.server.resourcemanager.rmcontainer.RMContainerImpl: container_1559894680121_0001_01_000001 Container Transitioned from RUNNING to COMPLETED
2019-06-07 08:05:23,965 INFO org.apache.hadoop.yarn.server.resourcemanager.RMAuditLogger: USER=root	OPERATION=AM Released Container	TARGET=SchedulerApp	RESULT=SUCCESS	APPID=application_1559894680121_0001	CONTAINERID=container_1559894680121_0001_01_000001
2019-06-07 08:05:23,965 INFO org.apache.hadoop.yarn.server.resourcemanager.RMAuditLogger: USER=root	OPERATION=AM Released Container	TARGET=SchedulerApp	RESULT=SUCCESS	APPID=application_1559894680121_0001	CONTAINERID=container_1559894680121_0001_01_000001
2019-06-07 08:05:23,965 DEBUG org.apache.hadoop.yarn.server.resourcemanager.scheduler.capacity.LeafQueue: User limit computation for root in queue default userLimitPercent=100 userLimitFactor=1.0 required: <memory:1024, vCores:1> consumed: <memory:0, vCores:0> user-limit-resource: <memory:8192, vCores:1> queueCapacity: <memory:8192, vCores:1> qconsumed: <memory:0, vCores:0> consumedRatio: 0.0 currentCapacity: <memory:8192, vCores:1> activeUsers: 0.0 clusterCapacity: <memory:8192, vCores:2> resourceByLabel: <memory:8192, vCores:2> usageratio: 0.0 Partition:  maxUserLimit=<memory:8192, vCores:1> userWeight=1.0
2019-06-07 08:05:23,965 DEBUG org.apache.hadoop.yarn.server.resourcemanager.scheduler.capacity.LeafQueue: User limit computation for root in queue default userLimitPercent=100 userLimitFactor=1.0 required: <memory:1024, vCores:1> consumed: <memory:0, vCores:0> user-limit-resource: <memory:8192, vCores:1> queueCapacity: <memory:8192, vCores:1> qconsumed: <memory:0, vCores:0> consumedRatio: 0.0 currentCapacity: <memory:8192, vCores:1> activeUsers: 0.0 clusterCapacity: <memory:8192, vCores:2> resourceByLabel: <memory:8192, vCores:2> usageratio: 0.0 Partition:  maxUserLimit=<memory:8192, vCores:1> userWeight=1.0
2019-06-07 08:05:23,965 DEBUG org.apache.hadoop.yarn.server.resourcemanager.scheduler.capacity.LeafQueue: default used=<memory:0, vCores:0> numContainers=0 user=root user-resources=<memory:0, vCores:0>
2019-06-07 08:05:23,965 DEBUG org.apache.hadoop.yarn.server.resourcemanager.scheduler.capacity.LeafQueue: default used=<memory:0, vCores:0> numContainers=0 user=root user-resources=<memory:0, vCores:0>
2019-06-07 08:05:23,965 DEBUG org.apache.hadoop.yarn.server.resourcemanager.scheduler.capacity.ParentQueue: completedContainer root: numChildQueue= 1, capacity=1.0, absoluteCapacity=1.0, usedResources=<memory:0, vCores:0>usedCapacity=0.0, numApps=1, numContainers=0, cluster=<memory:8192, vCores:2>
2019-06-07 08:05:23,965 DEBUG org.apache.hadoop.yarn.server.resourcemanager.scheduler.capacity.ParentQueue: completedContainer root: numChildQueue= 1, capacity=1.0, absoluteCapacity=1.0, usedResources=<memory:0, vCores:0>usedCapacity=0.0, numApps=1, numContainers=0, cluster=<memory:8192, vCores:2>
2019-06-07 08:05:23,965 DEBUG org.apache.hadoop.yarn.server.resourcemanager.scheduler.capacity.ParentQueue: Re-sorting completed queue: default: capacity=1.0, absoluteCapacity=1.0, usedResources=<memory:0, vCores:0>, usedCapacity=0.0, absoluteUsedCapacity=0.0, numApps=1, numContainers=0
2019-06-07 08:05:23,965 DEBUG org.apache.hadoop.yarn.server.resourcemanager.scheduler.capacity.ParentQueue: Re-sorting completed queue: default: capacity=1.0, absoluteCapacity=1.0, usedResources=<memory:0, vCores:0>, usedCapacity=0.0, absoluteUsedCapacity=0.0, numApps=1, numContainers=0
2019-06-07 08:05:23,965 INFO org.apache.hadoop.yarn.server.resourcemanager.scheduler.SchedulerNode: Released container container_1559894680121_0001_01_000001 of capacity <memory:1024, vCores:1> on host slave1:43282, which currently has 0 containers, <memory:0, vCores:0> used and <memory:4096, vCores:1> available, release resources=true
2019-06-07 08:05:23,965 INFO org.apache.hadoop.yarn.server.resourcemanager.scheduler.SchedulerNode: Released container container_1559894680121_0001_01_000001 of capacity <memory:1024, vCores:1> on host slave1:43282, which currently has 0 containers, <memory:0, vCores:0> used and <memory:4096, vCores:1> available, release resources=true
2019-06-07 08:05:23,965 DEBUG org.apache.hadoop.yarn.server.resourcemanager.scheduler.capacity.CapacityScheduler: Node being looked for scheduling slave1:43282 availableResource: <memory:4096, vCores:1>
2019-06-07 08:05:23,965 DEBUG org.apache.hadoop.yarn.server.resourcemanager.scheduler.capacity.CapacityScheduler: Node being looked for scheduling slave1:43282 availableResource: <memory:4096, vCores:1>
2019-06-07 08:05:23,965 DEBUG org.apache.hadoop.yarn.server.resourcemanager.scheduler.capacity.CapacityScheduler: Trying to schedule on node: slave1, available: <memory:4096, vCores:1>
2019-06-07 08:05:23,965 DEBUG org.apache.hadoop.yarn.server.resourcemanager.scheduler.capacity.CapacityScheduler: Trying to schedule on node: slave1, available: <memory:4096, vCores:1>
2019-06-07 08:05:23,965 DEBUG org.apache.hadoop.yarn.server.resourcemanager.scheduler.capacity.ParentQueue: Skip this queue=root, because it doesn't need more resource, schedulingMode=RESPECT_PARTITION_EXCLUSIVITY node-partition=
2019-06-07 08:05:23,965 DEBUG org.apache.hadoop.yarn.server.resourcemanager.scheduler.capacity.ParentQueue: Skip this queue=root, because it doesn't need more resource, schedulingMode=RESPECT_PARTITION_EXCLUSIVITY node-partition=
2019-06-07 08:05:23,967 DEBUG org.apache.hadoop.yarn.server.resourcemanager.rmapp.attempt.RMAppAttemptImpl: Processing event for appattempt_1559894680121_0001_000001 of type CONTAINER_FINISHED
2019-06-07 08:05:23,967 DEBUG org.apache.hadoop.yarn.server.resourcemanager.rmapp.attempt.RMAppAttemptImpl: Processing event for appattempt_1559894680121_0001_000001 of type CONTAINER_FINISHED
2019-06-07 08:05:23,967 INFO org.apache.hadoop.yarn.server.resourcemanager.ApplicationMasterService: Unregistering app attempt : appattempt_1559894680121_0001_000001
2019-06-07 08:05:23,967 INFO org.apache.hadoop.yarn.server.resourcemanager.ApplicationMasterService: Unregistering app attempt : appattempt_1559894680121_0001_000001
2019-06-07 08:05:23,968 INFO org.apache.hadoop.yarn.server.resourcemanager.security.AMRMTokenSecretManager: Application finished, removing password for appattempt_1559894680121_0001_000001
2019-06-07 08:05:23,968 INFO org.apache.hadoop.yarn.server.resourcemanager.security.AMRMTokenSecretManager: Application finished, removing password for appattempt_1559894680121_0001_000001
2019-06-07 08:05:23,969 INFO org.apache.hadoop.yarn.server.resourcemanager.rmapp.attempt.RMAppAttemptImpl: appattempt_1559894680121_0001_000001 State change from FINISHING to FINISHED
2019-06-07 08:05:23,969 INFO org.apache.hadoop.yarn.server.resourcemanager.rmapp.attempt.RMAppAttemptImpl: appattempt_1559894680121_0001_000001 State change from FINISHING to FINISHED
2019-06-07 08:05:23,969 DEBUG org.apache.hadoop.yarn.server.resourcemanager.rmapp.RMAppImpl: Processing event for application_1559894680121_0001 of type ATTEMPT_FINISHED
2019-06-07 08:05:23,969 DEBUG org.apache.hadoop.yarn.server.resourcemanager.rmapp.RMAppImpl: Processing event for application_1559894680121_0001 of type ATTEMPT_FINISHED
2019-06-07 08:05:23,970 INFO org.apache.hadoop.yarn.server.resourcemanager.rmapp.RMAppImpl: application_1559894680121_0001 State change from FINISHING to FINISHED on event=ATTEMPT_FINISHED
2019-06-07 08:05:23,970 INFO org.apache.hadoop.yarn.server.resourcemanager.rmapp.RMAppImpl: application_1559894680121_0001 State change from FINISHING to FINISHED on event=ATTEMPT_FINISHED
2019-06-07 08:05:23,970 INFO org.apache.hadoop.yarn.server.resourcemanager.scheduler.capacity.CapacityScheduler: Application Attempt appattempt_1559894680121_0001_000001 is done. finalState=FINISHED
2019-06-07 08:05:23,970 INFO org.apache.hadoop.yarn.server.resourcemanager.scheduler.capacity.CapacityScheduler: Application Attempt appattempt_1559894680121_0001_000001 is done. finalState=FINISHED
2019-06-07 08:05:23,970 INFO org.apache.hadoop.yarn.server.resourcemanager.scheduler.AppSchedulingInfo: Application application_1559894680121_0001 requests cleared
2019-06-07 08:05:23,970 INFO org.apache.hadoop.yarn.server.resourcemanager.scheduler.AppSchedulingInfo: Application application_1559894680121_0001 requests cleared
2019-06-07 08:05:23,970 INFO org.apache.hadoop.yarn.server.resourcemanager.scheduler.capacity.LeafQueue: Application removed - appId: application_1559894680121_0001 user: root queue: default #user-pending-applications: 0 #user-active-applications: 0 #queue-pending-applications: 0 #queue-active-applications: 0
2019-06-07 08:05:23,970 INFO org.apache.hadoop.yarn.server.resourcemanager.scheduler.capacity.LeafQueue: Application removed - appId: application_1559894680121_0001 user: root queue: default #user-pending-applications: 0 #user-active-applications: 0 #queue-pending-applications: 0 #queue-active-applications: 0
2019-06-07 08:05:23,971 DEBUG org.apache.hadoop.yarn.server.resourcemanager.rmnode.RMNodeImpl: Processing slave1:43282 of type FINISHED_CONTAINERS_PULLED_BY_AM
2019-06-07 08:05:23,971 DEBUG org.apache.hadoop.yarn.server.resourcemanager.rmnode.RMNodeImpl: Processing slave1:43282 of type FINISHED_CONTAINERS_PULLED_BY_AM
2019-06-07 08:05:23,971 DEBUG org.apache.hadoop.yarn.server.resourcemanager.rmnode.RMNodeImpl: Processing slave1:43282 of type CLEANUP_APP
2019-06-07 08:05:23,971 DEBUG org.apache.hadoop.yarn.server.resourcemanager.rmnode.RMNodeImpl: Processing slave1:43282 of type CLEANUP_APP
2019-06-07 08:05:23,971 DEBUG org.apache.hadoop.yarn.server.resourcemanager.rmnode.RMNodeImpl: Processing slave2:37804 of type CLEANUP_APP
2019-06-07 08:05:23,971 DEBUG org.apache.hadoop.yarn.server.resourcemanager.rmnode.RMNodeImpl: Processing slave2:37804 of type CLEANUP_APP
2019-06-07 08:05:23,971 DEBUG org.apache.hadoop.yarn.server.resourcemanager.RMAppManager: RMAppManager processing event for application_1559894680121_0001 of type APP_COMPLETED
2019-06-07 08:05:23,971 DEBUG org.apache.hadoop.yarn.server.resourcemanager.RMAppManager: RMAppManager processing event for application_1559894680121_0001 of type APP_COMPLETED
2019-06-07 08:05:23,972 INFO org.apache.hadoop.yarn.server.resourcemanager.RMAuditLogger: USER=root	OPERATION=Application Finished - Succeeded	TARGET=RMAppManager	RESULT=SUCCESS	APPID=application_1559894680121_0001
2019-06-07 08:05:23,972 INFO org.apache.hadoop.yarn.server.resourcemanager.RMAuditLogger: USER=root	OPERATION=Application Finished - Succeeded	TARGET=RMAppManager	RESULT=SUCCESS	APPID=application_1559894680121_0001
2019-06-07 08:05:23,972 INFO org.apache.hadoop.yarn.server.resourcemanager.scheduler.capacity.ParentQueue: Application removed - appId: application_1559894680121_0001 user: root leaf-queue of parent: root #applications: 0
2019-06-07 08:05:23,972 INFO org.apache.hadoop.yarn.server.resourcemanager.scheduler.capacity.ParentQueue: Application removed - appId: application_1559894680121_0001 user: root leaf-queue of parent: root #applications: 0
2019-06-07 08:05:23,973 DEBUG org.apache.hadoop.yarn.server.resourcemanager.scheduler.AbstractYarnScheduler: Request for appInfo of unknown attempt appattempt_1559894680121_0001_000001
2019-06-07 08:05:23,973 DEBUG org.apache.hadoop.yarn.server.resourcemanager.scheduler.AbstractYarnScheduler: Request for appInfo of unknown attempt appattempt_1559894680121_0001_000001
2019-06-07 08:05:23,974 INFO org.apache.hadoop.yarn.server.resourcemanager.RMAppManager$ApplicationSummary: appId=application_1559894680121_0001,name=SparkLR,user=root,queue=default,state=FINISHED,trackingUrl=http://master:8088/proxy/application_1559894680121_0001/,appMasterHost=172.17.0.3,startTime=1559894702159,finishTime=1559894723387,finalStatus=SUCCEEDED,memorySeconds=102059,vcoreSeconds=46,preemptedMemorySeconds=0,preemptedVcoreSeconds=0,preemptedAMContainers=0,preemptedNonAMContainers=0,preemptedResources=<memory:0\, vCores:0>,applicationType=SPARK
2019-06-07 08:05:23,972 INFO org.apache.hadoop.yarn.server.resourcemanager.amlauncher.AMLauncher: Cleaning master appattempt_1559894680121_0001_000001
2019-06-07 08:05:23,972 INFO org.apache.hadoop.yarn.server.resourcemanager.amlauncher.AMLauncher: Cleaning master appattempt_1559894680121_0001_000001
2019-06-07 08:05:24,439 DEBUG org.apache.hadoop.yarn.server.resourcemanager.rmnode.RMNodeImpl: Processing slave2:37804 of type STATUS_UPDATE
2019-06-07 08:05:24,439 DEBUG org.apache.hadoop.yarn.server.resourcemanager.rmnode.RMNodeImpl: Processing slave2:37804 of type STATUS_UPDATE
2019-06-07 08:05:24,441 DEBUG org.apache.hadoop.yarn.server.resourcemanager.scheduler.capacity.CapacityScheduler: nodeUpdate: slave2:37804 clusterResources: <memory:8192, vCores:2>
2019-06-07 08:05:24,441 DEBUG org.apache.hadoop.yarn.server.resourcemanager.scheduler.capacity.CapacityScheduler: nodeUpdate: slave2:37804 clusterResources: <memory:8192, vCores:2>
2019-06-07 08:05:24,441 DEBUG org.apache.hadoop.yarn.server.resourcemanager.scheduler.capacity.CapacityScheduler: Node being looked for scheduling slave2:37804 availableResource: <memory:4096, vCores:1>
2019-06-07 08:05:24,441 DEBUG org.apache.hadoop.yarn.server.resourcemanager.scheduler.capacity.CapacityScheduler: Node being looked for scheduling slave2:37804 availableResource: <memory:4096, vCores:1>
2019-06-07 08:05:24,441 DEBUG org.apache.hadoop.yarn.server.resourcemanager.scheduler.capacity.CapacityScheduler: Trying to schedule on node: slave2, available: <memory:4096, vCores:1>
2019-06-07 08:05:24,441 DEBUG org.apache.hadoop.yarn.server.resourcemanager.scheduler.capacity.CapacityScheduler: Trying to schedule on node: slave2, available: <memory:4096, vCores:1>
2019-06-07 08:05:24,441 DEBUG org.apache.hadoop.yarn.server.resourcemanager.scheduler.capacity.ParentQueue: Skip this queue=root, because it doesn't need more resource, schedulingMode=RESPECT_PARTITION_EXCLUSIVITY node-partition=
2019-06-07 08:05:24,441 DEBUG org.apache.hadoop.yarn.server.resourcemanager.scheduler.capacity.ParentQueue: Skip this queue=root, because it doesn't need more resource, schedulingMode=RESPECT_PARTITION_EXCLUSIVITY node-partition=
2019-06-07 08:05:24,967 DEBUG org.apache.hadoop.yarn.server.resourcemanager.rmnode.RMNodeImpl: Processing slave1:43282 of type STATUS_UPDATE
2019-06-07 08:05:24,967 DEBUG org.apache.hadoop.yarn.server.resourcemanager.rmnode.RMNodeImpl: Processing slave1:43282 of type STATUS_UPDATE
2019-06-07 08:05:24,967 DEBUG org.apache.hadoop.yarn.server.resourcemanager.scheduler.capacity.CapacityScheduler: nodeUpdate: slave1:43282 clusterResources: <memory:8192, vCores:2>
2019-06-07 08:05:24,967 DEBUG org.apache.hadoop.yarn.server.resourcemanager.scheduler.capacity.CapacityScheduler: nodeUpdate: slave1:43282 clusterResources: <memory:8192, vCores:2>
2019-06-07 08:05:24,967 DEBUG org.apache.hadoop.yarn.server.resourcemanager.scheduler.capacity.CapacityScheduler: Node being looked for scheduling slave1:43282 availableResource: <memory:4096, vCores:1>
2019-06-07 08:05:24,967 DEBUG org.apache.hadoop.yarn.server.resourcemanager.scheduler.capacity.CapacityScheduler: Node being looked for scheduling slave1:43282 availableResource: <memory:4096, vCores:1>
2019-06-07 08:05:24,967 DEBUG org.apache.hadoop.yarn.server.resourcemanager.scheduler.capacity.CapacityScheduler: Trying to schedule on node: slave1, available: <memory:4096, vCores:1>
2019-06-07 08:05:24,967 DEBUG org.apache.hadoop.yarn.server.resourcemanager.scheduler.capacity.CapacityScheduler: Trying to schedule on node: slave1, available: <memory:4096, vCores:1>
2019-06-07 08:05:24,967 DEBUG org.apache.hadoop.yarn.server.resourcemanager.scheduler.capacity.ParentQueue: Skip this queue=root, because it doesn't need more resource, schedulingMode=RESPECT_PARTITION_EXCLUSIVITY node-partition=
2019-06-07 08:05:24,967 DEBUG org.apache.hadoop.yarn.server.resourcemanager.scheduler.capacity.ParentQueue: Skip this queue=root, because it doesn't need more resource, schedulingMode=RESPECT_PARTITION_EXCLUSIVITY node-partition=
2019-06-07 08:05:25,446 DEBUG org.apache.hadoop.yarn.server.resourcemanager.rmnode.RMNodeImpl: Processing slave2:37804 of type STATUS_UPDATE
2019-06-07 08:05:25,446 DEBUG org.apache.hadoop.yarn.server.resourcemanager.rmnode.RMNodeImpl: Processing slave2:37804 of type STATUS_UPDATE
2019-06-07 08:05:25,447 DEBUG org.apache.hadoop.yarn.server.resourcemanager.rmnode.RMNodeImpl: Container container_1559894680121_0001_01_000002 is the first container get launched for application application_1559894680121_0001
2019-06-07 08:05:25,447 DEBUG org.apache.hadoop.yarn.server.resourcemanager.rmnode.RMNodeImpl: Container container_1559894680121_0001_01_000002 is the first container get launched for application application_1559894680121_0001
2019-06-07 08:05:25,449 DEBUG org.apache.hadoop.yarn.server.resourcemanager.rmapp.RMAppImpl: Processing event for application_1559894680121_0001 of type APP_RUNNING_ON_NODE
2019-06-07 08:05:25,449 DEBUG org.apache.hadoop.yarn.server.resourcemanager.rmapp.RMAppImpl: Processing event for application_1559894680121_0001 of type APP_RUNNING_ON_NODE
2019-06-07 08:05:25,449 DEBUG org.apache.hadoop.yarn.server.resourcemanager.rmnode.RMNodeImpl: Processing slave2:37804 of type CLEANUP_APP
2019-06-07 08:05:25,449 DEBUG org.apache.hadoop.yarn.server.resourcemanager.rmnode.RMNodeImpl: Processing slave2:37804 of type CLEANUP_APP
2019-06-07 08:05:25,449 DEBUG org.apache.hadoop.yarn.server.resourcemanager.scheduler.capacity.CapacityScheduler: nodeUpdate: slave2:37804 clusterResources: <memory:8192, vCores:2>
2019-06-07 08:05:25,449 DEBUG org.apache.hadoop.yarn.server.resourcemanager.scheduler.capacity.CapacityScheduler: nodeUpdate: slave2:37804 clusterResources: <memory:8192, vCores:2>
2019-06-07 08:05:25,449 INFO org.apache.hadoop.yarn.server.resourcemanager.scheduler.AbstractYarnScheduler: Container container_1559894680121_0001_01_000002 completed with event FINISHED, but corresponding RMContainer doesn't exist.
2019-06-07 08:05:25,449 INFO org.apache.hadoop.yarn.server.resourcemanager.scheduler.AbstractYarnScheduler: Container container_1559894680121_0001_01_000002 completed with event FINISHED, but corresponding RMContainer doesn't exist.
2019-06-07 08:05:25,449 DEBUG org.apache.hadoop.yarn.server.resourcemanager.scheduler.capacity.CapacityScheduler: Node being looked for scheduling slave2:37804 availableResource: <memory:4096, vCores:1>
2019-06-07 08:05:25,449 DEBUG org.apache.hadoop.yarn.server.resourcemanager.scheduler.capacity.CapacityScheduler: Node being looked for scheduling slave2:37804 availableResource: <memory:4096, vCores:1>
2019-06-07 08:05:25,449 DEBUG org.apache.hadoop.yarn.server.resourcemanager.scheduler.capacity.CapacityScheduler: Trying to schedule on node: slave2, available: <memory:4096, vCores:1>
2019-06-07 08:05:25,449 DEBUG org.apache.hadoop.yarn.server.resourcemanager.scheduler.capacity.CapacityScheduler: Trying to schedule on node: slave2, available: <memory:4096, vCores:1>
2019-06-07 08:05:25,449 DEBUG org.apache.hadoop.yarn.server.resourcemanager.scheduler.capacity.ParentQueue: Skip this queue=root, because it doesn't need more resource, schedulingMode=RESPECT_PARTITION_EXCLUSIVITY node-partition=
2019-06-07 08:05:25,449 DEBUG org.apache.hadoop.yarn.server.resourcemanager.scheduler.capacity.ParentQueue: Skip this queue=root, because it doesn't need more resource, schedulingMode=RESPECT_PARTITION_EXCLUSIVITY node-partition=
2019-06-07 08:05:25,973 DEBUG org.apache.hadoop.yarn.server.resourcemanager.rmnode.RMNodeImpl: Processing slave1:43282 of type STATUS_UPDATE
2019-06-07 08:05:25,973 DEBUG org.apache.hadoop.yarn.server.resourcemanager.rmnode.RMNodeImpl: Processing slave1:43282 of type STATUS_UPDATE
2019-06-07 08:05:25,973 DEBUG org.apache.hadoop.yarn.server.resourcemanager.rmnode.RMNodeImpl: Container container_1559894680121_0001_01_000003 is the first container get launched for application application_1559894680121_0001
2019-06-07 08:05:25,973 DEBUG org.apache.hadoop.yarn.server.resourcemanager.rmnode.RMNodeImpl: Container container_1559894680121_0001_01_000003 is the first container get launched for application application_1559894680121_0001
2019-06-07 08:05:25,974 DEBUG org.apache.hadoop.yarn.server.resourcemanager.rmapp.RMAppImpl: Processing event for application_1559894680121_0001 of type APP_RUNNING_ON_NODE
2019-06-07 08:05:25,974 DEBUG org.apache.hadoop.yarn.server.resourcemanager.rmapp.RMAppImpl: Processing event for application_1559894680121_0001 of type APP_RUNNING_ON_NODE
2019-06-07 08:05:25,974 DEBUG org.apache.hadoop.yarn.server.resourcemanager.rmnode.RMNodeImpl: Processing slave1:43282 of type CLEANUP_APP
2019-06-07 08:05:25,974 DEBUG org.apache.hadoop.yarn.server.resourcemanager.rmnode.RMNodeImpl: Processing slave1:43282 of type CLEANUP_APP
2019-06-07 08:05:25,974 DEBUG org.apache.hadoop.yarn.server.resourcemanager.scheduler.capacity.CapacityScheduler: nodeUpdate: slave1:43282 clusterResources: <memory:8192, vCores:2>
2019-06-07 08:05:25,974 DEBUG org.apache.hadoop.yarn.server.resourcemanager.scheduler.capacity.CapacityScheduler: nodeUpdate: slave1:43282 clusterResources: <memory:8192, vCores:2>
2019-06-07 08:05:25,975 INFO org.apache.hadoop.yarn.server.resourcemanager.scheduler.AbstractYarnScheduler: Container container_1559894680121_0001_01_000003 completed with event FINISHED, but corresponding RMContainer doesn't exist.
2019-06-07 08:05:25,975 INFO org.apache.hadoop.yarn.server.resourcemanager.scheduler.AbstractYarnScheduler: Container container_1559894680121_0001_01_000003 completed with event FINISHED, but corresponding RMContainer doesn't exist.
2019-06-07 08:05:25,975 DEBUG org.apache.hadoop.yarn.server.resourcemanager.scheduler.capacity.CapacityScheduler: Node being looked for scheduling slave1:43282 availableResource: <memory:4096, vCores:1>
2019-06-07 08:05:25,975 DEBUG org.apache.hadoop.yarn.server.resourcemanager.scheduler.capacity.CapacityScheduler: Node being looked for scheduling slave1:43282 availableResource: <memory:4096, vCores:1>
2019-06-07 08:05:25,975 DEBUG org.apache.hadoop.yarn.server.resourcemanager.scheduler.capacity.CapacityScheduler: Trying to schedule on node: slave1, available: <memory:4096, vCores:1>
2019-06-07 08:05:25,975 DEBUG org.apache.hadoop.yarn.server.resourcemanager.scheduler.capacity.CapacityScheduler: Trying to schedule on node: slave1, available: <memory:4096, vCores:1>
2019-06-07 08:05:25,975 DEBUG org.apache.hadoop.yarn.server.resourcemanager.scheduler.capacity.ParentQueue: Skip this queue=root, because it doesn't need more resource, schedulingMode=RESPECT_PARTITION_EXCLUSIVITY node-partition=
2019-06-07 08:05:25,975 DEBUG org.apache.hadoop.yarn.server.resourcemanager.scheduler.capacity.ParentQueue: Skip this queue=root, because it doesn't need more resource, schedulingMode=RESPECT_PARTITION_EXCLUSIVITY node-partition=
2019-06-07 08:05:26,453 DEBUG org.apache.hadoop.yarn.server.resourcemanager.rmnode.RMNodeImpl: Processing slave2:37804 of type STATUS_UPDATE
2019-06-07 08:05:26,453 DEBUG org.apache.hadoop.yarn.server.resourcemanager.rmnode.RMNodeImpl: Processing slave2:37804 of type STATUS_UPDATE
2019-06-07 08:05:26,453 DEBUG org.apache.hadoop.yarn.server.resourcemanager.scheduler.capacity.CapacityScheduler: nodeUpdate: slave2:37804 clusterResources: <memory:8192, vCores:2>
2019-06-07 08:05:26,453 DEBUG org.apache.hadoop.yarn.server.resourcemanager.scheduler.capacity.CapacityScheduler: nodeUpdate: slave2:37804 clusterResources: <memory:8192, vCores:2>
2019-06-07 08:05:26,453 DEBUG org.apache.hadoop.yarn.server.resourcemanager.scheduler.capacity.CapacityScheduler: Node being looked for scheduling slave2:37804 availableResource: <memory:4096, vCores:1>
2019-06-07 08:05:26,453 DEBUG org.apache.hadoop.yarn.server.resourcemanager.scheduler.capacity.CapacityScheduler: Node being looked for scheduling slave2:37804 availableResource: <memory:4096, vCores:1>
2019-06-07 08:05:26,454 DEBUG org.apache.hadoop.yarn.server.resourcemanager.scheduler.capacity.CapacityScheduler: Trying to schedule on node: slave2, available: <memory:4096, vCores:1>
2019-06-07 08:05:26,454 DEBUG org.apache.hadoop.yarn.server.resourcemanager.scheduler.capacity.CapacityScheduler: Trying to schedule on node: slave2, available: <memory:4096, vCores:1>
2019-06-07 08:05:26,454 DEBUG org.apache.hadoop.yarn.server.resourcemanager.scheduler.capacity.ParentQueue: Skip this queue=root, because it doesn't need more resource, schedulingMode=RESPECT_PARTITION_EXCLUSIVITY node-partition=
2019-06-07 08:05:26,454 DEBUG org.apache.hadoop.yarn.server.resourcemanager.scheduler.capacity.ParentQueue: Skip this queue=root, because it doesn't need more resource, schedulingMode=RESPECT_PARTITION_EXCLUSIVITY node-partition=
2019-06-07 08:05:26,978 DEBUG org.apache.hadoop.yarn.server.resourcemanager.rmnode.RMNodeImpl: Processing slave1:43282 of type STATUS_UPDATE
2019-06-07 08:05:26,978 DEBUG org.apache.hadoop.yarn.server.resourcemanager.rmnode.RMNodeImpl: Processing slave1:43282 of type STATUS_UPDATE
2019-06-07 08:05:26,978 DEBUG org.apache.hadoop.yarn.server.resourcemanager.scheduler.capacity.CapacityScheduler: nodeUpdate: slave1:43282 clusterResources: <memory:8192, vCores:2>
2019-06-07 08:05:26,978 DEBUG org.apache.hadoop.yarn.server.resourcemanager.scheduler.capacity.CapacityScheduler: nodeUpdate: slave1:43282 clusterResources: <memory:8192, vCores:2>
2019-06-07 08:05:26,978 DEBUG org.apache.hadoop.yarn.server.resourcemanager.scheduler.capacity.CapacityScheduler: Node being looked for scheduling slave1:43282 availableResource: <memory:4096, vCores:1>
2019-06-07 08:05:26,978 DEBUG org.apache.hadoop.yarn.server.resourcemanager.scheduler.capacity.CapacityScheduler: Node being looked for scheduling slave1:43282 availableResource: <memory:4096, vCores:1>
2019-06-07 08:05:26,978 DEBUG org.apache.hadoop.yarn.server.resourcemanager.scheduler.capacity.CapacityScheduler: Trying to schedule on node: slave1, available: <memory:4096, vCores:1>
2019-06-07 08:05:26,978 DEBUG org.apache.hadoop.yarn.server.resourcemanager.scheduler.capacity.CapacityScheduler: Trying to schedule on node: slave1, available: <memory:4096, vCores:1>
2019-06-07 08:05:26,978 DEBUG org.apache.hadoop.yarn.server.resourcemanager.scheduler.capacity.ParentQueue: Skip this queue=root, because it doesn't need more resource, schedulingMode=RESPECT_PARTITION_EXCLUSIVITY node-partition=
2019-06-07 08:05:26,978 DEBUG org.apache.hadoop.yarn.server.resourcemanager.scheduler.capacity.ParentQueue: Skip this queue=root, because it doesn't need more resource, schedulingMode=RESPECT_PARTITION_EXCLUSIVITY node-partition=
2019-06-07 08:05:27,459 DEBUG org.apache.hadoop.yarn.server.resourcemanager.rmnode.RMNodeImpl: Processing slave2:37804 of type STATUS_UPDATE
2019-06-07 08:05:27,459 DEBUG org.apache.hadoop.yarn.server.resourcemanager.rmnode.RMNodeImpl: Processing slave2:37804 of type STATUS_UPDATE
2019-06-07 08:05:27,459 DEBUG org.apache.hadoop.yarn.server.resourcemanager.scheduler.capacity.CapacityScheduler: nodeUpdate: slave2:37804 clusterResources: <memory:8192, vCores:2>
2019-06-07 08:05:27,459 DEBUG org.apache.hadoop.yarn.server.resourcemanager.scheduler.capacity.CapacityScheduler: nodeUpdate: slave2:37804 clusterResources: <memory:8192, vCores:2>
2019-06-07 08:05:27,459 DEBUG org.apache.hadoop.yarn.server.resourcemanager.scheduler.capacity.CapacityScheduler: Node being looked for scheduling slave2:37804 availableResource: <memory:4096, vCores:1>
2019-06-07 08:05:27,459 DEBUG org.apache.hadoop.yarn.server.resourcemanager.scheduler.capacity.CapacityScheduler: Node being looked for scheduling slave2:37804 availableResource: <memory:4096, vCores:1>
2019-06-07 08:05:27,459 DEBUG org.apache.hadoop.yarn.server.resourcemanager.scheduler.capacity.CapacityScheduler: Trying to schedule on node: slave2, available: <memory:4096, vCores:1>
2019-06-07 08:05:27,459 DEBUG org.apache.hadoop.yarn.server.resourcemanager.scheduler.capacity.CapacityScheduler: Trying to schedule on node: slave2, available: <memory:4096, vCores:1>
2019-06-07 08:05:27,459 DEBUG org.apache.hadoop.yarn.server.resourcemanager.scheduler.capacity.ParentQueue: Skip this queue=root, because it doesn't need more resource, schedulingMode=RESPECT_PARTITION_EXCLUSIVITY node-partition=
2019-06-07 08:05:27,459 DEBUG org.apache.hadoop.yarn.server.resourcemanager.scheduler.capacity.ParentQueue: Skip this queue=root, because it doesn't need more resource, schedulingMode=RESPECT_PARTITION_EXCLUSIVITY node-partition=
2019-06-07 08:05:27,980 DEBUG org.apache.hadoop.yarn.server.resourcemanager.rmnode.RMNodeImpl: Processing slave1:43282 of type STATUS_UPDATE
2019-06-07 08:05:27,980 DEBUG org.apache.hadoop.yarn.server.resourcemanager.rmnode.RMNodeImpl: Processing slave1:43282 of type STATUS_UPDATE
2019-06-07 08:05:27,981 DEBUG org.apache.hadoop.yarn.server.resourcemanager.scheduler.capacity.CapacityScheduler: nodeUpdate: slave1:43282 clusterResources: <memory:8192, vCores:2>
2019-06-07 08:05:27,981 DEBUG org.apache.hadoop.yarn.server.resourcemanager.scheduler.capacity.CapacityScheduler: nodeUpdate: slave1:43282 clusterResources: <memory:8192, vCores:2>
2019-06-07 08:05:27,981 DEBUG org.apache.hadoop.yarn.server.resourcemanager.scheduler.capacity.CapacityScheduler: Node being looked for scheduling slave1:43282 availableResource: <memory:4096, vCores:1>
2019-06-07 08:05:27,981 DEBUG org.apache.hadoop.yarn.server.resourcemanager.scheduler.capacity.CapacityScheduler: Node being looked for scheduling slave1:43282 availableResource: <memory:4096, vCores:1>
2019-06-07 08:05:27,981 DEBUG org.apache.hadoop.yarn.server.resourcemanager.scheduler.capacity.CapacityScheduler: Trying to schedule on node: slave1, available: <memory:4096, vCores:1>
2019-06-07 08:05:27,981 DEBUG org.apache.hadoop.yarn.server.resourcemanager.scheduler.capacity.CapacityScheduler: Trying to schedule on node: slave1, available: <memory:4096, vCores:1>
2019-06-07 08:05:27,981 DEBUG org.apache.hadoop.yarn.server.resourcemanager.scheduler.capacity.ParentQueue: Skip this queue=root, because it doesn't need more resource, schedulingMode=RESPECT_PARTITION_EXCLUSIVITY node-partition=
2019-06-07 08:05:27,981 DEBUG org.apache.hadoop.yarn.server.resourcemanager.scheduler.capacity.ParentQueue: Skip this queue=root, because it doesn't need more resource, schedulingMode=RESPECT_PARTITION_EXCLUSIVITY node-partition=
2019-06-07 08:05:28,461 DEBUG org.apache.hadoop.yarn.server.resourcemanager.rmnode.RMNodeImpl: Processing slave2:37804 of type STATUS_UPDATE
2019-06-07 08:05:28,461 DEBUG org.apache.hadoop.yarn.server.resourcemanager.rmnode.RMNodeImpl: Processing slave2:37804 of type STATUS_UPDATE
2019-06-07 08:05:28,461 DEBUG org.apache.hadoop.yarn.server.resourcemanager.scheduler.capacity.CapacityScheduler: nodeUpdate: slave2:37804 clusterResources: <memory:8192, vCores:2>
2019-06-07 08:05:28,461 DEBUG org.apache.hadoop.yarn.server.resourcemanager.scheduler.capacity.CapacityScheduler: nodeUpdate: slave2:37804 clusterResources: <memory:8192, vCores:2>
2019-06-07 08:05:28,462 DEBUG org.apache.hadoop.yarn.server.resourcemanager.scheduler.capacity.CapacityScheduler: Node being looked for scheduling slave2:37804 availableResource: <memory:4096, vCores:1>
2019-06-07 08:05:28,462 DEBUG org.apache.hadoop.yarn.server.resourcemanager.scheduler.capacity.CapacityScheduler: Node being looked for scheduling slave2:37804 availableResource: <memory:4096, vCores:1>
2019-06-07 08:05:28,462 DEBUG org.apache.hadoop.yarn.server.resourcemanager.scheduler.capacity.CapacityScheduler: Trying to schedule on node: slave2, available: <memory:4096, vCores:1>
2019-06-07 08:05:28,462 DEBUG org.apache.hadoop.yarn.server.resourcemanager.scheduler.capacity.CapacityScheduler: Trying to schedule on node: slave2, available: <memory:4096, vCores:1>
2019-06-07 08:05:28,462 DEBUG org.apache.hadoop.yarn.server.resourcemanager.scheduler.capacity.ParentQueue: Skip this queue=root, because it doesn't need more resource, schedulingMode=RESPECT_PARTITION_EXCLUSIVITY node-partition=
2019-06-07 08:05:28,462 DEBUG org.apache.hadoop.yarn.server.resourcemanager.scheduler.capacity.ParentQueue: Skip this queue=root, because it doesn't need more resource, schedulingMode=RESPECT_PARTITION_EXCLUSIVITY node-partition=
2019-06-07 08:05:28,984 DEBUG org.apache.hadoop.yarn.server.resourcemanager.rmnode.RMNodeImpl: Processing slave1:43282 of type STATUS_UPDATE
2019-06-07 08:05:28,984 DEBUG org.apache.hadoop.yarn.server.resourcemanager.rmnode.RMNodeImpl: Processing slave1:43282 of type STATUS_UPDATE
2019-06-07 08:05:28,984 DEBUG org.apache.hadoop.yarn.server.resourcemanager.scheduler.capacity.CapacityScheduler: nodeUpdate: slave1:43282 clusterResources: <memory:8192, vCores:2>
2019-06-07 08:05:28,984 DEBUG org.apache.hadoop.yarn.server.resourcemanager.scheduler.capacity.CapacityScheduler: nodeUpdate: slave1:43282 clusterResources: <memory:8192, vCores:2>
2019-06-07 08:05:28,984 DEBUG org.apache.hadoop.yarn.server.resourcemanager.scheduler.capacity.CapacityScheduler: Node being looked for scheduling slave1:43282 availableResource: <memory:4096, vCores:1>
2019-06-07 08:05:28,984 DEBUG org.apache.hadoop.yarn.server.resourcemanager.scheduler.capacity.CapacityScheduler: Node being looked for scheduling slave1:43282 availableResource: <memory:4096, vCores:1>
2019-06-07 08:05:28,984 DEBUG org.apache.hadoop.yarn.server.resourcemanager.scheduler.capacity.CapacityScheduler: Trying to schedule on node: slave1, available: <memory:4096, vCores:1>
2019-06-07 08:05:28,984 DEBUG org.apache.hadoop.yarn.server.resourcemanager.scheduler.capacity.CapacityScheduler: Trying to schedule on node: slave1, available: <memory:4096, vCores:1>
2019-06-07 08:05:28,984 DEBUG org.apache.hadoop.yarn.server.resourcemanager.scheduler.capacity.ParentQueue: Skip this queue=root, because it doesn't need more resource, schedulingMode=RESPECT_PARTITION_EXCLUSIVITY node-partition=
2019-06-07 08:05:28,984 DEBUG org.apache.hadoop.yarn.server.resourcemanager.scheduler.capacity.ParentQueue: Skip this queue=root, because it doesn't need more resource, schedulingMode=RESPECT_PARTITION_EXCLUSIVITY node-partition=
2019-06-07 08:05:29,465 DEBUG org.apache.hadoop.yarn.server.resourcemanager.rmnode.RMNodeImpl: Processing slave2:37804 of type STATUS_UPDATE
2019-06-07 08:05:29,465 DEBUG org.apache.hadoop.yarn.server.resourcemanager.rmnode.RMNodeImpl: Processing slave2:37804 of type STATUS_UPDATE
2019-06-07 08:05:29,466 DEBUG org.apache.hadoop.yarn.server.resourcemanager.scheduler.capacity.CapacityScheduler: nodeUpdate: slave2:37804 clusterResources: <memory:8192, vCores:2>
2019-06-07 08:05:29,466 DEBUG org.apache.hadoop.yarn.server.resourcemanager.scheduler.capacity.CapacityScheduler: nodeUpdate: slave2:37804 clusterResources: <memory:8192, vCores:2>
2019-06-07 08:05:29,466 DEBUG org.apache.hadoop.yarn.server.resourcemanager.scheduler.capacity.CapacityScheduler: Node being looked for scheduling slave2:37804 availableResource: <memory:4096, vCores:1>
2019-06-07 08:05:29,466 DEBUG org.apache.hadoop.yarn.server.resourcemanager.scheduler.capacity.CapacityScheduler: Node being looked for scheduling slave2:37804 availableResource: <memory:4096, vCores:1>
2019-06-07 08:05:29,466 DEBUG org.apache.hadoop.yarn.server.resourcemanager.scheduler.capacity.CapacityScheduler: Trying to schedule on node: slave2, available: <memory:4096, vCores:1>
2019-06-07 08:05:29,466 DEBUG org.apache.hadoop.yarn.server.resourcemanager.scheduler.capacity.CapacityScheduler: Trying to schedule on node: slave2, available: <memory:4096, vCores:1>
2019-06-07 08:05:29,466 DEBUG org.apache.hadoop.yarn.server.resourcemanager.scheduler.capacity.ParentQueue: Skip this queue=root, because it doesn't need more resource, schedulingMode=RESPECT_PARTITION_EXCLUSIVITY node-partition=
2019-06-07 08:05:29,466 DEBUG org.apache.hadoop.yarn.server.resourcemanager.scheduler.capacity.ParentQueue: Skip this queue=root, because it doesn't need more resource, schedulingMode=RESPECT_PARTITION_EXCLUSIVITY node-partition=
2019-06-07 08:05:29,987 DEBUG org.apache.hadoop.yarn.server.resourcemanager.rmnode.RMNodeImpl: Processing slave1:43282 of type STATUS_UPDATE
2019-06-07 08:05:29,987 DEBUG org.apache.hadoop.yarn.server.resourcemanager.rmnode.RMNodeImpl: Processing slave1:43282 of type STATUS_UPDATE
2019-06-07 08:05:29,988 DEBUG org.apache.hadoop.yarn.server.resourcemanager.scheduler.capacity.CapacityScheduler: nodeUpdate: slave1:43282 clusterResources: <memory:8192, vCores:2>
2019-06-07 08:05:29,988 DEBUG org.apache.hadoop.yarn.server.resourcemanager.scheduler.capacity.CapacityScheduler: nodeUpdate: slave1:43282 clusterResources: <memory:8192, vCores:2>
2019-06-07 08:05:29,988 DEBUG org.apache.hadoop.yarn.server.resourcemanager.scheduler.capacity.CapacityScheduler: Node being looked for scheduling slave1:43282 availableResource: <memory:4096, vCores:1>
2019-06-07 08:05:29,988 DEBUG org.apache.hadoop.yarn.server.resourcemanager.scheduler.capacity.CapacityScheduler: Node being looked for scheduling slave1:43282 availableResource: <memory:4096, vCores:1>
2019-06-07 08:05:29,988 DEBUG org.apache.hadoop.yarn.server.resourcemanager.scheduler.capacity.CapacityScheduler: Trying to schedule on node: slave1, available: <memory:4096, vCores:1>
2019-06-07 08:05:29,988 DEBUG org.apache.hadoop.yarn.server.resourcemanager.scheduler.capacity.CapacityScheduler: Trying to schedule on node: slave1, available: <memory:4096, vCores:1>
2019-06-07 08:05:29,988 DEBUG org.apache.hadoop.yarn.server.resourcemanager.scheduler.capacity.ParentQueue: Skip this queue=root, because it doesn't need more resource, schedulingMode=RESPECT_PARTITION_EXCLUSIVITY node-partition=
2019-06-07 08:05:29,988 DEBUG org.apache.hadoop.yarn.server.resourcemanager.scheduler.capacity.ParentQueue: Skip this queue=root, because it doesn't need more resource, schedulingMode=RESPECT_PARTITION_EXCLUSIVITY node-partition=
2019-06-07 08:05:30,468 DEBUG org.apache.hadoop.yarn.server.resourcemanager.rmnode.RMNodeImpl: Processing slave2:37804 of type STATUS_UPDATE
2019-06-07 08:05:30,468 DEBUG org.apache.hadoop.yarn.server.resourcemanager.rmnode.RMNodeImpl: Processing slave2:37804 of type STATUS_UPDATE
2019-06-07 08:05:30,468 DEBUG org.apache.hadoop.yarn.server.resourcemanager.scheduler.capacity.CapacityScheduler: nodeUpdate: slave2:37804 clusterResources: <memory:8192, vCores:2>
2019-06-07 08:05:30,468 DEBUG org.apache.hadoop.yarn.server.resourcemanager.scheduler.capacity.CapacityScheduler: nodeUpdate: slave2:37804 clusterResources: <memory:8192, vCores:2>
2019-06-07 08:05:30,468 DEBUG org.apache.hadoop.yarn.server.resourcemanager.scheduler.capacity.CapacityScheduler: Node being looked for scheduling slave2:37804 availableResource: <memory:4096, vCores:1>
2019-06-07 08:05:30,468 DEBUG org.apache.hadoop.yarn.server.resourcemanager.scheduler.capacity.CapacityScheduler: Node being looked for scheduling slave2:37804 availableResource: <memory:4096, vCores:1>
2019-06-07 08:05:30,468 DEBUG org.apache.hadoop.yarn.server.resourcemanager.scheduler.capacity.CapacityScheduler: Trying to schedule on node: slave2, available: <memory:4096, vCores:1>
2019-06-07 08:05:30,468 DEBUG org.apache.hadoop.yarn.server.resourcemanager.scheduler.capacity.CapacityScheduler: Trying to schedule on node: slave2, available: <memory:4096, vCores:1>
2019-06-07 08:05:30,468 DEBUG org.apache.hadoop.yarn.server.resourcemanager.scheduler.capacity.ParentQueue: Skip this queue=root, because it doesn't need more resource, schedulingMode=RESPECT_PARTITION_EXCLUSIVITY node-partition=
2019-06-07 08:05:30,468 DEBUG org.apache.hadoop.yarn.server.resourcemanager.scheduler.capacity.ParentQueue: Skip this queue=root, because it doesn't need more resource, schedulingMode=RESPECT_PARTITION_EXCLUSIVITY node-partition=
2019-06-07 08:05:30,991 DEBUG org.apache.hadoop.yarn.server.resourcemanager.rmnode.RMNodeImpl: Processing slave1:43282 of type STATUS_UPDATE
2019-06-07 08:05:30,991 DEBUG org.apache.hadoop.yarn.server.resourcemanager.rmnode.RMNodeImpl: Processing slave1:43282 of type STATUS_UPDATE
2019-06-07 08:05:30,992 DEBUG org.apache.hadoop.yarn.server.resourcemanager.scheduler.capacity.CapacityScheduler: nodeUpdate: slave1:43282 clusterResources: <memory:8192, vCores:2>
2019-06-07 08:05:30,992 DEBUG org.apache.hadoop.yarn.server.resourcemanager.scheduler.capacity.CapacityScheduler: nodeUpdate: slave1:43282 clusterResources: <memory:8192, vCores:2>
2019-06-07 08:05:30,992 DEBUG org.apache.hadoop.yarn.server.resourcemanager.scheduler.capacity.CapacityScheduler: Node being looked for scheduling slave1:43282 availableResource: <memory:4096, vCores:1>
2019-06-07 08:05:30,992 DEBUG org.apache.hadoop.yarn.server.resourcemanager.scheduler.capacity.CapacityScheduler: Node being looked for scheduling slave1:43282 availableResource: <memory:4096, vCores:1>
2019-06-07 08:05:30,992 DEBUG org.apache.hadoop.yarn.server.resourcemanager.scheduler.capacity.CapacityScheduler: Trying to schedule on node: slave1, available: <memory:4096, vCores:1>
2019-06-07 08:05:30,992 DEBUG org.apache.hadoop.yarn.server.resourcemanager.scheduler.capacity.CapacityScheduler: Trying to schedule on node: slave1, available: <memory:4096, vCores:1>
2019-06-07 08:05:30,992 DEBUG org.apache.hadoop.yarn.server.resourcemanager.scheduler.capacity.ParentQueue: Skip this queue=root, because it doesn't need more resource, schedulingMode=RESPECT_PARTITION_EXCLUSIVITY node-partition=
2019-06-07 08:05:30,992 DEBUG org.apache.hadoop.yarn.server.resourcemanager.scheduler.capacity.ParentQueue: Skip this queue=root, because it doesn't need more resource, schedulingMode=RESPECT_PARTITION_EXCLUSIVITY node-partition=
2019-06-07 08:05:31,472 DEBUG org.apache.hadoop.yarn.server.resourcemanager.rmnode.RMNodeImpl: Processing slave2:37804 of type STATUS_UPDATE
2019-06-07 08:05:31,472 DEBUG org.apache.hadoop.yarn.server.resourcemanager.rmnode.RMNodeImpl: Processing slave2:37804 of type STATUS_UPDATE
2019-06-07 08:05:31,472 DEBUG org.apache.hadoop.yarn.server.resourcemanager.scheduler.capacity.CapacityScheduler: nodeUpdate: slave2:37804 clusterResources: <memory:8192, vCores:2>
2019-06-07 08:05:31,472 DEBUG org.apache.hadoop.yarn.server.resourcemanager.scheduler.capacity.CapacityScheduler: nodeUpdate: slave2:37804 clusterResources: <memory:8192, vCores:2>
2019-06-07 08:05:31,472 DEBUG org.apache.hadoop.yarn.server.resourcemanager.scheduler.capacity.CapacityScheduler: Node being looked for scheduling slave2:37804 availableResource: <memory:4096, vCores:1>
2019-06-07 08:05:31,472 DEBUG org.apache.hadoop.yarn.server.resourcemanager.scheduler.capacity.CapacityScheduler: Node being looked for scheduling slave2:37804 availableResource: <memory:4096, vCores:1>
2019-06-07 08:05:31,472 DEBUG org.apache.hadoop.yarn.server.resourcemanager.scheduler.capacity.CapacityScheduler: Trying to schedule on node: slave2, available: <memory:4096, vCores:1>
2019-06-07 08:05:31,472 DEBUG org.apache.hadoop.yarn.server.resourcemanager.scheduler.capacity.CapacityScheduler: Trying to schedule on node: slave2, available: <memory:4096, vCores:1>
2019-06-07 08:05:31,472 DEBUG org.apache.hadoop.yarn.server.resourcemanager.scheduler.capacity.ParentQueue: Skip this queue=root, because it doesn't need more resource, schedulingMode=RESPECT_PARTITION_EXCLUSIVITY node-partition=
2019-06-07 08:05:31,472 DEBUG org.apache.hadoop.yarn.server.resourcemanager.scheduler.capacity.ParentQueue: Skip this queue=root, because it doesn't need more resource, schedulingMode=RESPECT_PARTITION_EXCLUSIVITY node-partition=
2019-06-07 08:05:31,994 DEBUG org.apache.hadoop.yarn.server.resourcemanager.rmnode.RMNodeImpl: Processing slave1:43282 of type STATUS_UPDATE
2019-06-07 08:05:31,994 DEBUG org.apache.hadoop.yarn.server.resourcemanager.rmnode.RMNodeImpl: Processing slave1:43282 of type STATUS_UPDATE
2019-06-07 08:05:31,994 DEBUG org.apache.hadoop.yarn.server.resourcemanager.scheduler.capacity.CapacityScheduler: nodeUpdate: slave1:43282 clusterResources: <memory:8192, vCores:2>
2019-06-07 08:05:31,994 DEBUG org.apache.hadoop.yarn.server.resourcemanager.scheduler.capacity.CapacityScheduler: nodeUpdate: slave1:43282 clusterResources: <memory:8192, vCores:2>
2019-06-07 08:05:31,995 DEBUG org.apache.hadoop.yarn.server.resourcemanager.scheduler.capacity.CapacityScheduler: Node being looked for scheduling slave1:43282 availableResource: <memory:4096, vCores:1>
2019-06-07 08:05:31,995 DEBUG org.apache.hadoop.yarn.server.resourcemanager.scheduler.capacity.CapacityScheduler: Node being looked for scheduling slave1:43282 availableResource: <memory:4096, vCores:1>
2019-06-07 08:05:31,995 DEBUG org.apache.hadoop.yarn.server.resourcemanager.scheduler.capacity.CapacityScheduler: Trying to schedule on node: slave1, available: <memory:4096, vCores:1>
2019-06-07 08:05:31,995 DEBUG org.apache.hadoop.yarn.server.resourcemanager.scheduler.capacity.CapacityScheduler: Trying to schedule on node: slave1, available: <memory:4096, vCores:1>
2019-06-07 08:05:31,995 DEBUG org.apache.hadoop.yarn.server.resourcemanager.scheduler.capacity.ParentQueue: Skip this queue=root, because it doesn't need more resource, schedulingMode=RESPECT_PARTITION_EXCLUSIVITY node-partition=
2019-06-07 08:05:31,995 DEBUG org.apache.hadoop.yarn.server.resourcemanager.scheduler.capacity.ParentQueue: Skip this queue=root, because it doesn't need more resource, schedulingMode=RESPECT_PARTITION_EXCLUSIVITY node-partition=
2019-06-07 08:05:32,475 DEBUG org.apache.hadoop.yarn.server.resourcemanager.rmnode.RMNodeImpl: Processing slave2:37804 of type STATUS_UPDATE
2019-06-07 08:05:32,475 DEBUG org.apache.hadoop.yarn.server.resourcemanager.rmnode.RMNodeImpl: Processing slave2:37804 of type STATUS_UPDATE
2019-06-07 08:05:32,475 DEBUG org.apache.hadoop.yarn.server.resourcemanager.scheduler.capacity.CapacityScheduler: nodeUpdate: slave2:37804 clusterResources: <memory:8192, vCores:2>
2019-06-07 08:05:32,475 DEBUG org.apache.hadoop.yarn.server.resourcemanager.scheduler.capacity.CapacityScheduler: nodeUpdate: slave2:37804 clusterResources: <memory:8192, vCores:2>
2019-06-07 08:05:32,475 DEBUG org.apache.hadoop.yarn.server.resourcemanager.scheduler.capacity.CapacityScheduler: Node being looked for scheduling slave2:37804 availableResource: <memory:4096, vCores:1>
2019-06-07 08:05:32,475 DEBUG org.apache.hadoop.yarn.server.resourcemanager.scheduler.capacity.CapacityScheduler: Node being looked for scheduling slave2:37804 availableResource: <memory:4096, vCores:1>
2019-06-07 08:05:32,475 DEBUG org.apache.hadoop.yarn.server.resourcemanager.scheduler.capacity.CapacityScheduler: Trying to schedule on node: slave2, available: <memory:4096, vCores:1>
2019-06-07 08:05:32,475 DEBUG org.apache.hadoop.yarn.server.resourcemanager.scheduler.capacity.CapacityScheduler: Trying to schedule on node: slave2, available: <memory:4096, vCores:1>
2019-06-07 08:05:32,475 DEBUG org.apache.hadoop.yarn.server.resourcemanager.scheduler.capacity.ParentQueue: Skip this queue=root, because it doesn't need more resource, schedulingMode=RESPECT_PARTITION_EXCLUSIVITY node-partition=
2019-06-07 08:05:32,475 DEBUG org.apache.hadoop.yarn.server.resourcemanager.scheduler.capacity.ParentQueue: Skip this queue=root, because it doesn't need more resource, schedulingMode=RESPECT_PARTITION_EXCLUSIVITY node-partition=
2019-06-07 08:05:33,000 DEBUG org.apache.hadoop.yarn.server.resourcemanager.rmnode.RMNodeImpl: Processing slave1:43282 of type STATUS_UPDATE
2019-06-07 08:05:33,000 DEBUG org.apache.hadoop.yarn.server.resourcemanager.rmnode.RMNodeImpl: Processing slave1:43282 of type STATUS_UPDATE
2019-06-07 08:05:33,000 DEBUG org.apache.hadoop.yarn.server.resourcemanager.scheduler.capacity.CapacityScheduler: nodeUpdate: slave1:43282 clusterResources: <memory:8192, vCores:2>
2019-06-07 08:05:33,000 DEBUG org.apache.hadoop.yarn.server.resourcemanager.scheduler.capacity.CapacityScheduler: nodeUpdate: slave1:43282 clusterResources: <memory:8192, vCores:2>
2019-06-07 08:05:33,000 DEBUG org.apache.hadoop.yarn.server.resourcemanager.scheduler.capacity.CapacityScheduler: Node being looked for scheduling slave1:43282 availableResource: <memory:4096, vCores:1>
2019-06-07 08:05:33,000 DEBUG org.apache.hadoop.yarn.server.resourcemanager.scheduler.capacity.CapacityScheduler: Node being looked for scheduling slave1:43282 availableResource: <memory:4096, vCores:1>
2019-06-07 08:05:33,000 DEBUG org.apache.hadoop.yarn.server.resourcemanager.scheduler.capacity.CapacityScheduler: Trying to schedule on node: slave1, available: <memory:4096, vCores:1>
2019-06-07 08:05:33,000 DEBUG org.apache.hadoop.yarn.server.resourcemanager.scheduler.capacity.CapacityScheduler: Trying to schedule on node: slave1, available: <memory:4096, vCores:1>
2019-06-07 08:05:33,000 DEBUG org.apache.hadoop.yarn.server.resourcemanager.scheduler.capacity.ParentQueue: Skip this queue=root, because it doesn't need more resource, schedulingMode=RESPECT_PARTITION_EXCLUSIVITY node-partition=
2019-06-07 08:05:33,000 DEBUG org.apache.hadoop.yarn.server.resourcemanager.scheduler.capacity.ParentQueue: Skip this queue=root, because it doesn't need more resource, schedulingMode=RESPECT_PARTITION_EXCLUSIVITY node-partition=
2019-06-07 08:05:33,478 DEBUG org.apache.hadoop.yarn.server.resourcemanager.rmnode.RMNodeImpl: Processing slave2:37804 of type STATUS_UPDATE
2019-06-07 08:05:33,478 DEBUG org.apache.hadoop.yarn.server.resourcemanager.rmnode.RMNodeImpl: Processing slave2:37804 of type STATUS_UPDATE
2019-06-07 08:05:33,478 DEBUG org.apache.hadoop.yarn.server.resourcemanager.scheduler.capacity.CapacityScheduler: nodeUpdate: slave2:37804 clusterResources: <memory:8192, vCores:2>
2019-06-07 08:05:33,478 DEBUG org.apache.hadoop.yarn.server.resourcemanager.scheduler.capacity.CapacityScheduler: nodeUpdate: slave2:37804 clusterResources: <memory:8192, vCores:2>
2019-06-07 08:05:33,478 DEBUG org.apache.hadoop.yarn.server.resourcemanager.scheduler.capacity.CapacityScheduler: Node being looked for scheduling slave2:37804 availableResource: <memory:4096, vCores:1>
2019-06-07 08:05:33,478 DEBUG org.apache.hadoop.yarn.server.resourcemanager.scheduler.capacity.CapacityScheduler: Node being looked for scheduling slave2:37804 availableResource: <memory:4096, vCores:1>
2019-06-07 08:05:33,478 DEBUG org.apache.hadoop.yarn.server.resourcemanager.scheduler.capacity.CapacityScheduler: Trying to schedule on node: slave2, available: <memory:4096, vCores:1>
2019-06-07 08:05:33,478 DEBUG org.apache.hadoop.yarn.server.resourcemanager.scheduler.capacity.CapacityScheduler: Trying to schedule on node: slave2, available: <memory:4096, vCores:1>
2019-06-07 08:05:33,478 DEBUG org.apache.hadoop.yarn.server.resourcemanager.scheduler.capacity.ParentQueue: Skip this queue=root, because it doesn't need more resource, schedulingMode=RESPECT_PARTITION_EXCLUSIVITY node-partition=
2019-06-07 08:05:33,478 DEBUG org.apache.hadoop.yarn.server.resourcemanager.scheduler.capacity.ParentQueue: Skip this queue=root, because it doesn't need more resource, schedulingMode=RESPECT_PARTITION_EXCLUSIVITY node-partition=
2019-06-07 08:05:34,003 DEBUG org.apache.hadoop.yarn.server.resourcemanager.rmnode.RMNodeImpl: Processing slave1:43282 of type STATUS_UPDATE
2019-06-07 08:05:34,003 DEBUG org.apache.hadoop.yarn.server.resourcemanager.rmnode.RMNodeImpl: Processing slave1:43282 of type STATUS_UPDATE
2019-06-07 08:05:34,003 DEBUG org.apache.hadoop.yarn.server.resourcemanager.scheduler.capacity.CapacityScheduler: nodeUpdate: slave1:43282 clusterResources: <memory:8192, vCores:2>
2019-06-07 08:05:34,003 DEBUG org.apache.hadoop.yarn.server.resourcemanager.scheduler.capacity.CapacityScheduler: nodeUpdate: slave1:43282 clusterResources: <memory:8192, vCores:2>
2019-06-07 08:05:34,003 DEBUG org.apache.hadoop.yarn.server.resourcemanager.scheduler.capacity.CapacityScheduler: Node being looked for scheduling slave1:43282 availableResource: <memory:4096, vCores:1>
2019-06-07 08:05:34,003 DEBUG org.apache.hadoop.yarn.server.resourcemanager.scheduler.capacity.CapacityScheduler: Node being looked for scheduling slave1:43282 availableResource: <memory:4096, vCores:1>
2019-06-07 08:05:34,003 DEBUG org.apache.hadoop.yarn.server.resourcemanager.scheduler.capacity.CapacityScheduler: Trying to schedule on node: slave1, available: <memory:4096, vCores:1>
2019-06-07 08:05:34,003 DEBUG org.apache.hadoop.yarn.server.resourcemanager.scheduler.capacity.CapacityScheduler: Trying to schedule on node: slave1, available: <memory:4096, vCores:1>
2019-06-07 08:05:34,003 DEBUG org.apache.hadoop.yarn.server.resourcemanager.scheduler.capacity.ParentQueue: Skip this queue=root, because it doesn't need more resource, schedulingMode=RESPECT_PARTITION_EXCLUSIVITY node-partition=
2019-06-07 08:05:34,003 DEBUG org.apache.hadoop.yarn.server.resourcemanager.scheduler.capacity.ParentQueue: Skip this queue=root, because it doesn't need more resource, schedulingMode=RESPECT_PARTITION_EXCLUSIVITY node-partition=
2019-06-07 08:05:34,480 DEBUG org.apache.hadoop.yarn.server.resourcemanager.rmnode.RMNodeImpl: Processing slave2:37804 of type STATUS_UPDATE
2019-06-07 08:05:34,480 DEBUG org.apache.hadoop.yarn.server.resourcemanager.rmnode.RMNodeImpl: Processing slave2:37804 of type STATUS_UPDATE
2019-06-07 08:05:34,481 DEBUG org.apache.hadoop.yarn.server.resourcemanager.scheduler.capacity.CapacityScheduler: nodeUpdate: slave2:37804 clusterResources: <memory:8192, vCores:2>
2019-06-07 08:05:34,481 DEBUG org.apache.hadoop.yarn.server.resourcemanager.scheduler.capacity.CapacityScheduler: nodeUpdate: slave2:37804 clusterResources: <memory:8192, vCores:2>
2019-06-07 08:05:34,481 DEBUG org.apache.hadoop.yarn.server.resourcemanager.scheduler.capacity.CapacityScheduler: Node being looked for scheduling slave2:37804 availableResource: <memory:4096, vCores:1>
2019-06-07 08:05:34,481 DEBUG org.apache.hadoop.yarn.server.resourcemanager.scheduler.capacity.CapacityScheduler: Node being looked for scheduling slave2:37804 availableResource: <memory:4096, vCores:1>
2019-06-07 08:05:34,481 DEBUG org.apache.hadoop.yarn.server.resourcemanager.scheduler.capacity.CapacityScheduler: Trying to schedule on node: slave2, available: <memory:4096, vCores:1>
2019-06-07 08:05:34,481 DEBUG org.apache.hadoop.yarn.server.resourcemanager.scheduler.capacity.CapacityScheduler: Trying to schedule on node: slave2, available: <memory:4096, vCores:1>
2019-06-07 08:05:34,481 DEBUG org.apache.hadoop.yarn.server.resourcemanager.scheduler.capacity.ParentQueue: Skip this queue=root, because it doesn't need more resource, schedulingMode=RESPECT_PARTITION_EXCLUSIVITY node-partition=
2019-06-07 08:05:34,481 DEBUG org.apache.hadoop.yarn.server.resourcemanager.scheduler.capacity.ParentQueue: Skip this queue=root, because it doesn't need more resource, schedulingMode=RESPECT_PARTITION_EXCLUSIVITY node-partition=
2019-06-07 08:05:35,005 DEBUG org.apache.hadoop.yarn.server.resourcemanager.rmnode.RMNodeImpl: Processing slave1:43282 of type STATUS_UPDATE
2019-06-07 08:05:35,005 DEBUG org.apache.hadoop.yarn.server.resourcemanager.rmnode.RMNodeImpl: Processing slave1:43282 of type STATUS_UPDATE
2019-06-07 08:05:35,006 DEBUG org.apache.hadoop.yarn.server.resourcemanager.scheduler.capacity.CapacityScheduler: nodeUpdate: slave1:43282 clusterResources: <memory:8192, vCores:2>
2019-06-07 08:05:35,006 DEBUG org.apache.hadoop.yarn.server.resourcemanager.scheduler.capacity.CapacityScheduler: nodeUpdate: slave1:43282 clusterResources: <memory:8192, vCores:2>
2019-06-07 08:05:35,007 DEBUG org.apache.hadoop.yarn.server.resourcemanager.scheduler.capacity.CapacityScheduler: Node being looked for scheduling slave1:43282 availableResource: <memory:4096, vCores:1>
2019-06-07 08:05:35,007 DEBUG org.apache.hadoop.yarn.server.resourcemanager.scheduler.capacity.CapacityScheduler: Node being looked for scheduling slave1:43282 availableResource: <memory:4096, vCores:1>
2019-06-07 08:05:35,007 DEBUG org.apache.hadoop.yarn.server.resourcemanager.scheduler.capacity.CapacityScheduler: Trying to schedule on node: slave1, available: <memory:4096, vCores:1>
2019-06-07 08:05:35,007 DEBUG org.apache.hadoop.yarn.server.resourcemanager.scheduler.capacity.CapacityScheduler: Trying to schedule on node: slave1, available: <memory:4096, vCores:1>
2019-06-07 08:05:35,007 DEBUG org.apache.hadoop.yarn.server.resourcemanager.scheduler.capacity.ParentQueue: Skip this queue=root, because it doesn't need more resource, schedulingMode=RESPECT_PARTITION_EXCLUSIVITY node-partition=
2019-06-07 08:05:35,007 DEBUG org.apache.hadoop.yarn.server.resourcemanager.scheduler.capacity.ParentQueue: Skip this queue=root, because it doesn't need more resource, schedulingMode=RESPECT_PARTITION_EXCLUSIVITY node-partition=
2019-06-07 08:05:35,482 DEBUG org.apache.hadoop.yarn.server.resourcemanager.rmnode.RMNodeImpl: Processing slave2:37804 of type STATUS_UPDATE
2019-06-07 08:05:35,482 DEBUG org.apache.hadoop.yarn.server.resourcemanager.rmnode.RMNodeImpl: Processing slave2:37804 of type STATUS_UPDATE
2019-06-07 08:05:35,483 DEBUG org.apache.hadoop.yarn.server.resourcemanager.scheduler.capacity.CapacityScheduler: nodeUpdate: slave2:37804 clusterResources: <memory:8192, vCores:2>
2019-06-07 08:05:35,483 DEBUG org.apache.hadoop.yarn.server.resourcemanager.scheduler.capacity.CapacityScheduler: nodeUpdate: slave2:37804 clusterResources: <memory:8192, vCores:2>
2019-06-07 08:05:35,483 DEBUG org.apache.hadoop.yarn.server.resourcemanager.scheduler.capacity.CapacityScheduler: Node being looked for scheduling slave2:37804 availableResource: <memory:4096, vCores:1>
2019-06-07 08:05:35,483 DEBUG org.apache.hadoop.yarn.server.resourcemanager.scheduler.capacity.CapacityScheduler: Node being looked for scheduling slave2:37804 availableResource: <memory:4096, vCores:1>
2019-06-07 08:05:35,483 DEBUG org.apache.hadoop.yarn.server.resourcemanager.scheduler.capacity.CapacityScheduler: Trying to schedule on node: slave2, available: <memory:4096, vCores:1>
2019-06-07 08:05:35,483 DEBUG org.apache.hadoop.yarn.server.resourcemanager.scheduler.capacity.CapacityScheduler: Trying to schedule on node: slave2, available: <memory:4096, vCores:1>
2019-06-07 08:05:35,483 DEBUG org.apache.hadoop.yarn.server.resourcemanager.scheduler.capacity.ParentQueue: Skip this queue=root, because it doesn't need more resource, schedulingMode=RESPECT_PARTITION_EXCLUSIVITY node-partition=
2019-06-07 08:05:35,483 DEBUG org.apache.hadoop.yarn.server.resourcemanager.scheduler.capacity.ParentQueue: Skip this queue=root, because it doesn't need more resource, schedulingMode=RESPECT_PARTITION_EXCLUSIVITY node-partition=
2019-06-07 08:05:36,011 DEBUG org.apache.hadoop.yarn.server.resourcemanager.rmnode.RMNodeImpl: Processing slave1:43282 of type STATUS_UPDATE
2019-06-07 08:05:36,011 DEBUG org.apache.hadoop.yarn.server.resourcemanager.rmnode.RMNodeImpl: Processing slave1:43282 of type STATUS_UPDATE
2019-06-07 08:05:36,011 DEBUG org.apache.hadoop.yarn.server.resourcemanager.scheduler.capacity.CapacityScheduler: nodeUpdate: slave1:43282 clusterResources: <memory:8192, vCores:2>
2019-06-07 08:05:36,011 DEBUG org.apache.hadoop.yarn.server.resourcemanager.scheduler.capacity.CapacityScheduler: nodeUpdate: slave1:43282 clusterResources: <memory:8192, vCores:2>
2019-06-07 08:05:36,011 DEBUG org.apache.hadoop.yarn.server.resourcemanager.scheduler.capacity.CapacityScheduler: Node being looked for scheduling slave1:43282 availableResource: <memory:4096, vCores:1>
2019-06-07 08:05:36,011 DEBUG org.apache.hadoop.yarn.server.resourcemanager.scheduler.capacity.CapacityScheduler: Node being looked for scheduling slave1:43282 availableResource: <memory:4096, vCores:1>
2019-06-07 08:05:36,011 DEBUG org.apache.hadoop.yarn.server.resourcemanager.scheduler.capacity.CapacityScheduler: Trying to schedule on node: slave1, available: <memory:4096, vCores:1>
2019-06-07 08:05:36,011 DEBUG org.apache.hadoop.yarn.server.resourcemanager.scheduler.capacity.CapacityScheduler: Trying to schedule on node: slave1, available: <memory:4096, vCores:1>
2019-06-07 08:05:36,011 DEBUG org.apache.hadoop.yarn.server.resourcemanager.scheduler.capacity.ParentQueue: Skip this queue=root, because it doesn't need more resource, schedulingMode=RESPECT_PARTITION_EXCLUSIVITY node-partition=
2019-06-07 08:05:36,011 DEBUG org.apache.hadoop.yarn.server.resourcemanager.scheduler.capacity.ParentQueue: Skip this queue=root, because it doesn't need more resource, schedulingMode=RESPECT_PARTITION_EXCLUSIVITY node-partition=
2019-06-07 08:05:36,487 DEBUG org.apache.hadoop.yarn.server.resourcemanager.rmnode.RMNodeImpl: Processing slave2:37804 of type STATUS_UPDATE
2019-06-07 08:05:36,487 DEBUG org.apache.hadoop.yarn.server.resourcemanager.rmnode.RMNodeImpl: Processing slave2:37804 of type STATUS_UPDATE
2019-06-07 08:05:36,487 DEBUG org.apache.hadoop.yarn.server.resourcemanager.scheduler.capacity.CapacityScheduler: nodeUpdate: slave2:37804 clusterResources: <memory:8192, vCores:2>
2019-06-07 08:05:36,487 DEBUG org.apache.hadoop.yarn.server.resourcemanager.scheduler.capacity.CapacityScheduler: nodeUpdate: slave2:37804 clusterResources: <memory:8192, vCores:2>
2019-06-07 08:05:36,487 DEBUG org.apache.hadoop.yarn.server.resourcemanager.scheduler.capacity.CapacityScheduler: Node being looked for scheduling slave2:37804 availableResource: <memory:4096, vCores:1>
2019-06-07 08:05:36,487 DEBUG org.apache.hadoop.yarn.server.resourcemanager.scheduler.capacity.CapacityScheduler: Node being looked for scheduling slave2:37804 availableResource: <memory:4096, vCores:1>
2019-06-07 08:05:36,487 DEBUG org.apache.hadoop.yarn.server.resourcemanager.scheduler.capacity.CapacityScheduler: Trying to schedule on node: slave2, available: <memory:4096, vCores:1>
2019-06-07 08:05:36,487 DEBUG org.apache.hadoop.yarn.server.resourcemanager.scheduler.capacity.CapacityScheduler: Trying to schedule on node: slave2, available: <memory:4096, vCores:1>
2019-06-07 08:05:36,487 DEBUG org.apache.hadoop.yarn.server.resourcemanager.scheduler.capacity.ParentQueue: Skip this queue=root, because it doesn't need more resource, schedulingMode=RESPECT_PARTITION_EXCLUSIVITY node-partition=
2019-06-07 08:05:36,487 DEBUG org.apache.hadoop.yarn.server.resourcemanager.scheduler.capacity.ParentQueue: Skip this queue=root, because it doesn't need more resource, schedulingMode=RESPECT_PARTITION_EXCLUSIVITY node-partition=
2019-06-07 08:05:37,014 DEBUG org.apache.hadoop.yarn.server.resourcemanager.rmnode.RMNodeImpl: Processing slave1:43282 of type STATUS_UPDATE
2019-06-07 08:05:37,014 DEBUG org.apache.hadoop.yarn.server.resourcemanager.rmnode.RMNodeImpl: Processing slave1:43282 of type STATUS_UPDATE
2019-06-07 08:05:37,014 DEBUG org.apache.hadoop.yarn.server.resourcemanager.scheduler.capacity.CapacityScheduler: nodeUpdate: slave1:43282 clusterResources: <memory:8192, vCores:2>
2019-06-07 08:05:37,014 DEBUG org.apache.hadoop.yarn.server.resourcemanager.scheduler.capacity.CapacityScheduler: nodeUpdate: slave1:43282 clusterResources: <memory:8192, vCores:2>
2019-06-07 08:05:37,014 DEBUG org.apache.hadoop.yarn.server.resourcemanager.scheduler.capacity.CapacityScheduler: Node being looked for scheduling slave1:43282 availableResource: <memory:4096, vCores:1>
2019-06-07 08:05:37,014 DEBUG org.apache.hadoop.yarn.server.resourcemanager.scheduler.capacity.CapacityScheduler: Node being looked for scheduling slave1:43282 availableResource: <memory:4096, vCores:1>
2019-06-07 08:05:37,014 DEBUG org.apache.hadoop.yarn.server.resourcemanager.scheduler.capacity.CapacityScheduler: Trying to schedule on node: slave1, available: <memory:4096, vCores:1>
2019-06-07 08:05:37,014 DEBUG org.apache.hadoop.yarn.server.resourcemanager.scheduler.capacity.CapacityScheduler: Trying to schedule on node: slave1, available: <memory:4096, vCores:1>
2019-06-07 08:05:37,014 DEBUG org.apache.hadoop.yarn.server.resourcemanager.scheduler.capacity.ParentQueue: Skip this queue=root, because it doesn't need more resource, schedulingMode=RESPECT_PARTITION_EXCLUSIVITY node-partition=
2019-06-07 08:05:37,014 DEBUG org.apache.hadoop.yarn.server.resourcemanager.scheduler.capacity.ParentQueue: Skip this queue=root, because it doesn't need more resource, schedulingMode=RESPECT_PARTITION_EXCLUSIVITY node-partition=
2019-06-07 08:05:37,490 DEBUG org.apache.hadoop.yarn.server.resourcemanager.rmnode.RMNodeImpl: Processing slave2:37804 of type STATUS_UPDATE
2019-06-07 08:05:37,490 DEBUG org.apache.hadoop.yarn.server.resourcemanager.rmnode.RMNodeImpl: Processing slave2:37804 of type STATUS_UPDATE
2019-06-07 08:05:37,490 DEBUG org.apache.hadoop.yarn.server.resourcemanager.scheduler.capacity.CapacityScheduler: nodeUpdate: slave2:37804 clusterResources: <memory:8192, vCores:2>
2019-06-07 08:05:37,490 DEBUG org.apache.hadoop.yarn.server.resourcemanager.scheduler.capacity.CapacityScheduler: nodeUpdate: slave2:37804 clusterResources: <memory:8192, vCores:2>
2019-06-07 08:05:37,490 DEBUG org.apache.hadoop.yarn.server.resourcemanager.scheduler.capacity.CapacityScheduler: Node being looked for scheduling slave2:37804 availableResource: <memory:4096, vCores:1>
2019-06-07 08:05:37,490 DEBUG org.apache.hadoop.yarn.server.resourcemanager.scheduler.capacity.CapacityScheduler: Node being looked for scheduling slave2:37804 availableResource: <memory:4096, vCores:1>
2019-06-07 08:05:37,490 DEBUG org.apache.hadoop.yarn.server.resourcemanager.scheduler.capacity.CapacityScheduler: Trying to schedule on node: slave2, available: <memory:4096, vCores:1>
2019-06-07 08:05:37,490 DEBUG org.apache.hadoop.yarn.server.resourcemanager.scheduler.capacity.CapacityScheduler: Trying to schedule on node: slave2, available: <memory:4096, vCores:1>
2019-06-07 08:05:37,490 DEBUG org.apache.hadoop.yarn.server.resourcemanager.scheduler.capacity.ParentQueue: Skip this queue=root, because it doesn't need more resource, schedulingMode=RESPECT_PARTITION_EXCLUSIVITY node-partition=
2019-06-07 08:05:37,490 DEBUG org.apache.hadoop.yarn.server.resourcemanager.scheduler.capacity.ParentQueue: Skip this queue=root, because it doesn't need more resource, schedulingMode=RESPECT_PARTITION_EXCLUSIVITY node-partition=
2019-06-07 08:05:38,018 DEBUG org.apache.hadoop.yarn.server.resourcemanager.rmnode.RMNodeImpl: Processing slave1:43282 of type STATUS_UPDATE
2019-06-07 08:05:38,018 DEBUG org.apache.hadoop.yarn.server.resourcemanager.rmnode.RMNodeImpl: Processing slave1:43282 of type STATUS_UPDATE
2019-06-07 08:05:38,018 DEBUG org.apache.hadoop.yarn.server.resourcemanager.scheduler.capacity.CapacityScheduler: nodeUpdate: slave1:43282 clusterResources: <memory:8192, vCores:2>
2019-06-07 08:05:38,018 DEBUG org.apache.hadoop.yarn.server.resourcemanager.scheduler.capacity.CapacityScheduler: nodeUpdate: slave1:43282 clusterResources: <memory:8192, vCores:2>
2019-06-07 08:05:38,018 DEBUG org.apache.hadoop.yarn.server.resourcemanager.scheduler.capacity.CapacityScheduler: Node being looked for scheduling slave1:43282 availableResource: <memory:4096, vCores:1>
2019-06-07 08:05:38,018 DEBUG org.apache.hadoop.yarn.server.resourcemanager.scheduler.capacity.CapacityScheduler: Node being looked for scheduling slave1:43282 availableResource: <memory:4096, vCores:1>
2019-06-07 08:05:38,018 DEBUG org.apache.hadoop.yarn.server.resourcemanager.scheduler.capacity.CapacityScheduler: Trying to schedule on node: slave1, available: <memory:4096, vCores:1>
2019-06-07 08:05:38,018 DEBUG org.apache.hadoop.yarn.server.resourcemanager.scheduler.capacity.CapacityScheduler: Trying to schedule on node: slave1, available: <memory:4096, vCores:1>
2019-06-07 08:05:38,018 DEBUG org.apache.hadoop.yarn.server.resourcemanager.scheduler.capacity.ParentQueue: Skip this queue=root, because it doesn't need more resource, schedulingMode=RESPECT_PARTITION_EXCLUSIVITY node-partition=
2019-06-07 08:05:38,018 DEBUG org.apache.hadoop.yarn.server.resourcemanager.scheduler.capacity.ParentQueue: Skip this queue=root, because it doesn't need more resource, schedulingMode=RESPECT_PARTITION_EXCLUSIVITY node-partition=
2019-06-07 08:05:38,492 DEBUG org.apache.hadoop.yarn.server.resourcemanager.rmnode.RMNodeImpl: Processing slave2:37804 of type STATUS_UPDATE
2019-06-07 08:05:38,492 DEBUG org.apache.hadoop.yarn.server.resourcemanager.rmnode.RMNodeImpl: Processing slave2:37804 of type STATUS_UPDATE
2019-06-07 08:05:38,492 DEBUG org.apache.hadoop.yarn.server.resourcemanager.scheduler.capacity.CapacityScheduler: nodeUpdate: slave2:37804 clusterResources: <memory:8192, vCores:2>
2019-06-07 08:05:38,492 DEBUG org.apache.hadoop.yarn.server.resourcemanager.scheduler.capacity.CapacityScheduler: nodeUpdate: slave2:37804 clusterResources: <memory:8192, vCores:2>
2019-06-07 08:05:38,492 DEBUG org.apache.hadoop.yarn.server.resourcemanager.scheduler.capacity.CapacityScheduler: Node being looked for scheduling slave2:37804 availableResource: <memory:4096, vCores:1>
2019-06-07 08:05:38,492 DEBUG org.apache.hadoop.yarn.server.resourcemanager.scheduler.capacity.CapacityScheduler: Node being looked for scheduling slave2:37804 availableResource: <memory:4096, vCores:1>
2019-06-07 08:05:38,492 DEBUG org.apache.hadoop.yarn.server.resourcemanager.scheduler.capacity.CapacityScheduler: Trying to schedule on node: slave2, available: <memory:4096, vCores:1>
2019-06-07 08:05:38,492 DEBUG org.apache.hadoop.yarn.server.resourcemanager.scheduler.capacity.CapacityScheduler: Trying to schedule on node: slave2, available: <memory:4096, vCores:1>
2019-06-07 08:05:38,492 DEBUG org.apache.hadoop.yarn.server.resourcemanager.scheduler.capacity.ParentQueue: Skip this queue=root, because it doesn't need more resource, schedulingMode=RESPECT_PARTITION_EXCLUSIVITY node-partition=
2019-06-07 08:05:38,492 DEBUG org.apache.hadoop.yarn.server.resourcemanager.scheduler.capacity.ParentQueue: Skip this queue=root, because it doesn't need more resource, schedulingMode=RESPECT_PARTITION_EXCLUSIVITY node-partition=
2019-06-07 08:05:39,020 DEBUG org.apache.hadoop.yarn.server.resourcemanager.rmnode.RMNodeImpl: Processing slave1:43282 of type STATUS_UPDATE
2019-06-07 08:05:39,020 DEBUG org.apache.hadoop.yarn.server.resourcemanager.rmnode.RMNodeImpl: Processing slave1:43282 of type STATUS_UPDATE
2019-06-07 08:05:39,020 DEBUG org.apache.hadoop.yarn.server.resourcemanager.scheduler.capacity.CapacityScheduler: nodeUpdate: slave1:43282 clusterResources: <memory:8192, vCores:2>
2019-06-07 08:05:39,020 DEBUG org.apache.hadoop.yarn.server.resourcemanager.scheduler.capacity.CapacityScheduler: nodeUpdate: slave1:43282 clusterResources: <memory:8192, vCores:2>
2019-06-07 08:05:39,021 DEBUG org.apache.hadoop.yarn.server.resourcemanager.scheduler.capacity.CapacityScheduler: Node being looked for scheduling slave1:43282 availableResource: <memory:4096, vCores:1>
2019-06-07 08:05:39,021 DEBUG org.apache.hadoop.yarn.server.resourcemanager.scheduler.capacity.CapacityScheduler: Node being looked for scheduling slave1:43282 availableResource: <memory:4096, vCores:1>
2019-06-07 08:05:39,021 DEBUG org.apache.hadoop.yarn.server.resourcemanager.scheduler.capacity.CapacityScheduler: Trying to schedule on node: slave1, available: <memory:4096, vCores:1>
2019-06-07 08:05:39,021 DEBUG org.apache.hadoop.yarn.server.resourcemanager.scheduler.capacity.CapacityScheduler: Trying to schedule on node: slave1, available: <memory:4096, vCores:1>
2019-06-07 08:05:39,021 DEBUG org.apache.hadoop.yarn.server.resourcemanager.scheduler.capacity.ParentQueue: Skip this queue=root, because it doesn't need more resource, schedulingMode=RESPECT_PARTITION_EXCLUSIVITY node-partition=
2019-06-07 08:05:39,021 DEBUG org.apache.hadoop.yarn.server.resourcemanager.scheduler.capacity.ParentQueue: Skip this queue=root, because it doesn't need more resource, schedulingMode=RESPECT_PARTITION_EXCLUSIVITY node-partition=
2019-06-07 08:05:39,497 DEBUG org.apache.hadoop.yarn.server.resourcemanager.rmnode.RMNodeImpl: Processing slave2:37804 of type STATUS_UPDATE
2019-06-07 08:05:39,497 DEBUG org.apache.hadoop.yarn.server.resourcemanager.rmnode.RMNodeImpl: Processing slave2:37804 of type STATUS_UPDATE
2019-06-07 08:05:39,498 DEBUG org.apache.hadoop.yarn.server.resourcemanager.scheduler.capacity.CapacityScheduler: nodeUpdate: slave2:37804 clusterResources: <memory:8192, vCores:2>
2019-06-07 08:05:39,498 DEBUG org.apache.hadoop.yarn.server.resourcemanager.scheduler.capacity.CapacityScheduler: nodeUpdate: slave2:37804 clusterResources: <memory:8192, vCores:2>
2019-06-07 08:05:39,498 DEBUG org.apache.hadoop.yarn.server.resourcemanager.scheduler.capacity.CapacityScheduler: Node being looked for scheduling slave2:37804 availableResource: <memory:4096, vCores:1>
2019-06-07 08:05:39,498 DEBUG org.apache.hadoop.yarn.server.resourcemanager.scheduler.capacity.CapacityScheduler: Node being looked for scheduling slave2:37804 availableResource: <memory:4096, vCores:1>
2019-06-07 08:05:39,498 DEBUG org.apache.hadoop.yarn.server.resourcemanager.scheduler.capacity.CapacityScheduler: Trying to schedule on node: slave2, available: <memory:4096, vCores:1>
2019-06-07 08:05:39,498 DEBUG org.apache.hadoop.yarn.server.resourcemanager.scheduler.capacity.CapacityScheduler: Trying to schedule on node: slave2, available: <memory:4096, vCores:1>
2019-06-07 08:05:39,498 DEBUG org.apache.hadoop.yarn.server.resourcemanager.scheduler.capacity.ParentQueue: Skip this queue=root, because it doesn't need more resource, schedulingMode=RESPECT_PARTITION_EXCLUSIVITY node-partition=
2019-06-07 08:05:39,498 DEBUG org.apache.hadoop.yarn.server.resourcemanager.scheduler.capacity.ParentQueue: Skip this queue=root, because it doesn't need more resource, schedulingMode=RESPECT_PARTITION_EXCLUSIVITY node-partition=
2019-06-07 08:05:40,023 DEBUG org.apache.hadoop.yarn.server.resourcemanager.rmnode.RMNodeImpl: Processing slave1:43282 of type STATUS_UPDATE
2019-06-07 08:05:40,023 DEBUG org.apache.hadoop.yarn.server.resourcemanager.rmnode.RMNodeImpl: Processing slave1:43282 of type STATUS_UPDATE
2019-06-07 08:05:40,024 DEBUG org.apache.hadoop.yarn.server.resourcemanager.scheduler.capacity.CapacityScheduler: nodeUpdate: slave1:43282 clusterResources: <memory:8192, vCores:2>
2019-06-07 08:05:40,024 DEBUG org.apache.hadoop.yarn.server.resourcemanager.scheduler.capacity.CapacityScheduler: nodeUpdate: slave1:43282 clusterResources: <memory:8192, vCores:2>
2019-06-07 08:05:40,024 DEBUG org.apache.hadoop.yarn.server.resourcemanager.scheduler.capacity.CapacityScheduler: Node being looked for scheduling slave1:43282 availableResource: <memory:4096, vCores:1>
2019-06-07 08:05:40,024 DEBUG org.apache.hadoop.yarn.server.resourcemanager.scheduler.capacity.CapacityScheduler: Node being looked for scheduling slave1:43282 availableResource: <memory:4096, vCores:1>
2019-06-07 08:05:40,024 DEBUG org.apache.hadoop.yarn.server.resourcemanager.scheduler.capacity.CapacityScheduler: Trying to schedule on node: slave1, available: <memory:4096, vCores:1>
2019-06-07 08:05:40,024 DEBUG org.apache.hadoop.yarn.server.resourcemanager.scheduler.capacity.CapacityScheduler: Trying to schedule on node: slave1, available: <memory:4096, vCores:1>
2019-06-07 08:05:40,024 DEBUG org.apache.hadoop.yarn.server.resourcemanager.scheduler.capacity.ParentQueue: Skip this queue=root, because it doesn't need more resource, schedulingMode=RESPECT_PARTITION_EXCLUSIVITY node-partition=
2019-06-07 08:05:40,024 DEBUG org.apache.hadoop.yarn.server.resourcemanager.scheduler.capacity.ParentQueue: Skip this queue=root, because it doesn't need more resource, schedulingMode=RESPECT_PARTITION_EXCLUSIVITY node-partition=
2019-06-07 08:05:40,501 DEBUG org.apache.hadoop.yarn.server.resourcemanager.rmnode.RMNodeImpl: Processing slave2:37804 of type STATUS_UPDATE
2019-06-07 08:05:40,501 DEBUG org.apache.hadoop.yarn.server.resourcemanager.rmnode.RMNodeImpl: Processing slave2:37804 of type STATUS_UPDATE
2019-06-07 08:05:40,501 DEBUG org.apache.hadoop.yarn.server.resourcemanager.scheduler.capacity.CapacityScheduler: nodeUpdate: slave2:37804 clusterResources: <memory:8192, vCores:2>
2019-06-07 08:05:40,501 DEBUG org.apache.hadoop.yarn.server.resourcemanager.scheduler.capacity.CapacityScheduler: nodeUpdate: slave2:37804 clusterResources: <memory:8192, vCores:2>
2019-06-07 08:05:40,501 DEBUG org.apache.hadoop.yarn.server.resourcemanager.scheduler.capacity.CapacityScheduler: Node being looked for scheduling slave2:37804 availableResource: <memory:4096, vCores:1>
2019-06-07 08:05:40,501 DEBUG org.apache.hadoop.yarn.server.resourcemanager.scheduler.capacity.CapacityScheduler: Node being looked for scheduling slave2:37804 availableResource: <memory:4096, vCores:1>
2019-06-07 08:05:40,501 DEBUG org.apache.hadoop.yarn.server.resourcemanager.scheduler.capacity.CapacityScheduler: Trying to schedule on node: slave2, available: <memory:4096, vCores:1>
2019-06-07 08:05:40,501 DEBUG org.apache.hadoop.yarn.server.resourcemanager.scheduler.capacity.CapacityScheduler: Trying to schedule on node: slave2, available: <memory:4096, vCores:1>
2019-06-07 08:05:40,501 DEBUG org.apache.hadoop.yarn.server.resourcemanager.scheduler.capacity.ParentQueue: Skip this queue=root, because it doesn't need more resource, schedulingMode=RESPECT_PARTITION_EXCLUSIVITY node-partition=
2019-06-07 08:05:40,501 DEBUG org.apache.hadoop.yarn.server.resourcemanager.scheduler.capacity.ParentQueue: Skip this queue=root, because it doesn't need more resource, schedulingMode=RESPECT_PARTITION_EXCLUSIVITY node-partition=
2019-06-07 08:05:41,026 DEBUG org.apache.hadoop.yarn.server.resourcemanager.rmnode.RMNodeImpl: Processing slave1:43282 of type STATUS_UPDATE
2019-06-07 08:05:41,026 DEBUG org.apache.hadoop.yarn.server.resourcemanager.rmnode.RMNodeImpl: Processing slave1:43282 of type STATUS_UPDATE
2019-06-07 08:05:41,026 DEBUG org.apache.hadoop.yarn.server.resourcemanager.scheduler.capacity.CapacityScheduler: nodeUpdate: slave1:43282 clusterResources: <memory:8192, vCores:2>
2019-06-07 08:05:41,026 DEBUG org.apache.hadoop.yarn.server.resourcemanager.scheduler.capacity.CapacityScheduler: nodeUpdate: slave1:43282 clusterResources: <memory:8192, vCores:2>
2019-06-07 08:05:41,026 DEBUG org.apache.hadoop.yarn.server.resourcemanager.scheduler.capacity.CapacityScheduler: Node being looked for scheduling slave1:43282 availableResource: <memory:4096, vCores:1>
2019-06-07 08:05:41,026 DEBUG org.apache.hadoop.yarn.server.resourcemanager.scheduler.capacity.CapacityScheduler: Node being looked for scheduling slave1:43282 availableResource: <memory:4096, vCores:1>
2019-06-07 08:05:41,026 DEBUG org.apache.hadoop.yarn.server.resourcemanager.scheduler.capacity.CapacityScheduler: Trying to schedule on node: slave1, available: <memory:4096, vCores:1>
2019-06-07 08:05:41,026 DEBUG org.apache.hadoop.yarn.server.resourcemanager.scheduler.capacity.CapacityScheduler: Trying to schedule on node: slave1, available: <memory:4096, vCores:1>
2019-06-07 08:05:41,026 DEBUG org.apache.hadoop.yarn.server.resourcemanager.scheduler.capacity.ParentQueue: Skip this queue=root, because it doesn't need more resource, schedulingMode=RESPECT_PARTITION_EXCLUSIVITY node-partition=
2019-06-07 08:05:41,026 DEBUG org.apache.hadoop.yarn.server.resourcemanager.scheduler.capacity.ParentQueue: Skip this queue=root, because it doesn't need more resource, schedulingMode=RESPECT_PARTITION_EXCLUSIVITY node-partition=
2019-06-07 08:05:41,504 DEBUG org.apache.hadoop.yarn.server.resourcemanager.rmnode.RMNodeImpl: Processing slave2:37804 of type STATUS_UPDATE
2019-06-07 08:05:41,504 DEBUG org.apache.hadoop.yarn.server.resourcemanager.rmnode.RMNodeImpl: Processing slave2:37804 of type STATUS_UPDATE
2019-06-07 08:05:41,505 DEBUG org.apache.hadoop.yarn.server.resourcemanager.scheduler.capacity.CapacityScheduler: nodeUpdate: slave2:37804 clusterResources: <memory:8192, vCores:2>
2019-06-07 08:05:41,505 DEBUG org.apache.hadoop.yarn.server.resourcemanager.scheduler.capacity.CapacityScheduler: nodeUpdate: slave2:37804 clusterResources: <memory:8192, vCores:2>
2019-06-07 08:05:41,505 DEBUG org.apache.hadoop.yarn.server.resourcemanager.scheduler.capacity.CapacityScheduler: Node being looked for scheduling slave2:37804 availableResource: <memory:4096, vCores:1>
2019-06-07 08:05:41,505 DEBUG org.apache.hadoop.yarn.server.resourcemanager.scheduler.capacity.CapacityScheduler: Node being looked for scheduling slave2:37804 availableResource: <memory:4096, vCores:1>
2019-06-07 08:05:41,505 DEBUG org.apache.hadoop.yarn.server.resourcemanager.scheduler.capacity.CapacityScheduler: Trying to schedule on node: slave2, available: <memory:4096, vCores:1>
2019-06-07 08:05:41,505 DEBUG org.apache.hadoop.yarn.server.resourcemanager.scheduler.capacity.CapacityScheduler: Trying to schedule on node: slave2, available: <memory:4096, vCores:1>
2019-06-07 08:05:41,505 DEBUG org.apache.hadoop.yarn.server.resourcemanager.scheduler.capacity.ParentQueue: Skip this queue=root, because it doesn't need more resource, schedulingMode=RESPECT_PARTITION_EXCLUSIVITY node-partition=
2019-06-07 08:05:41,505 DEBUG org.apache.hadoop.yarn.server.resourcemanager.scheduler.capacity.ParentQueue: Skip this queue=root, because it doesn't need more resource, schedulingMode=RESPECT_PARTITION_EXCLUSIVITY node-partition=
2019-06-07 08:05:42,029 DEBUG org.apache.hadoop.yarn.server.resourcemanager.rmnode.RMNodeImpl: Processing slave1:43282 of type STATUS_UPDATE
2019-06-07 08:05:42,029 DEBUG org.apache.hadoop.yarn.server.resourcemanager.rmnode.RMNodeImpl: Processing slave1:43282 of type STATUS_UPDATE
2019-06-07 08:05:42,029 DEBUG org.apache.hadoop.yarn.server.resourcemanager.scheduler.capacity.CapacityScheduler: nodeUpdate: slave1:43282 clusterResources: <memory:8192, vCores:2>
2019-06-07 08:05:42,029 DEBUG org.apache.hadoop.yarn.server.resourcemanager.scheduler.capacity.CapacityScheduler: nodeUpdate: slave1:43282 clusterResources: <memory:8192, vCores:2>
2019-06-07 08:05:42,029 DEBUG org.apache.hadoop.yarn.server.resourcemanager.scheduler.capacity.CapacityScheduler: Node being looked for scheduling slave1:43282 availableResource: <memory:4096, vCores:1>
2019-06-07 08:05:42,029 DEBUG org.apache.hadoop.yarn.server.resourcemanager.scheduler.capacity.CapacityScheduler: Node being looked for scheduling slave1:43282 availableResource: <memory:4096, vCores:1>
2019-06-07 08:05:42,029 DEBUG org.apache.hadoop.yarn.server.resourcemanager.scheduler.capacity.CapacityScheduler: Trying to schedule on node: slave1, available: <memory:4096, vCores:1>
2019-06-07 08:05:42,029 DEBUG org.apache.hadoop.yarn.server.resourcemanager.scheduler.capacity.CapacityScheduler: Trying to schedule on node: slave1, available: <memory:4096, vCores:1>
2019-06-07 08:05:42,029 DEBUG org.apache.hadoop.yarn.server.resourcemanager.scheduler.capacity.ParentQueue: Skip this queue=root, because it doesn't need more resource, schedulingMode=RESPECT_PARTITION_EXCLUSIVITY node-partition=
2019-06-07 08:05:42,029 DEBUG org.apache.hadoop.yarn.server.resourcemanager.scheduler.capacity.ParentQueue: Skip this queue=root, because it doesn't need more resource, schedulingMode=RESPECT_PARTITION_EXCLUSIVITY node-partition=
2019-06-07 08:05:42,507 DEBUG org.apache.hadoop.yarn.server.resourcemanager.rmnode.RMNodeImpl: Processing slave2:37804 of type STATUS_UPDATE
2019-06-07 08:05:42,507 DEBUG org.apache.hadoop.yarn.server.resourcemanager.rmnode.RMNodeImpl: Processing slave2:37804 of type STATUS_UPDATE
2019-06-07 08:05:42,507 DEBUG org.apache.hadoop.yarn.server.resourcemanager.scheduler.capacity.CapacityScheduler: nodeUpdate: slave2:37804 clusterResources: <memory:8192, vCores:2>
2019-06-07 08:05:42,507 DEBUG org.apache.hadoop.yarn.server.resourcemanager.scheduler.capacity.CapacityScheduler: nodeUpdate: slave2:37804 clusterResources: <memory:8192, vCores:2>
2019-06-07 08:05:42,507 DEBUG org.apache.hadoop.yarn.server.resourcemanager.scheduler.capacity.CapacityScheduler: Node being looked for scheduling slave2:37804 availableResource: <memory:4096, vCores:1>
2019-06-07 08:05:42,507 DEBUG org.apache.hadoop.yarn.server.resourcemanager.scheduler.capacity.CapacityScheduler: Node being looked for scheduling slave2:37804 availableResource: <memory:4096, vCores:1>
2019-06-07 08:05:42,507 DEBUG org.apache.hadoop.yarn.server.resourcemanager.scheduler.capacity.CapacityScheduler: Trying to schedule on node: slave2, available: <memory:4096, vCores:1>
2019-06-07 08:05:42,507 DEBUG org.apache.hadoop.yarn.server.resourcemanager.scheduler.capacity.CapacityScheduler: Trying to schedule on node: slave2, available: <memory:4096, vCores:1>
2019-06-07 08:05:42,507 DEBUG org.apache.hadoop.yarn.server.resourcemanager.scheduler.capacity.ParentQueue: Skip this queue=root, because it doesn't need more resource, schedulingMode=RESPECT_PARTITION_EXCLUSIVITY node-partition=
2019-06-07 08:05:42,507 DEBUG org.apache.hadoop.yarn.server.resourcemanager.scheduler.capacity.ParentQueue: Skip this queue=root, because it doesn't need more resource, schedulingMode=RESPECT_PARTITION_EXCLUSIVITY node-partition=
2019-06-07 08:05:43,033 DEBUG org.apache.hadoop.yarn.server.resourcemanager.rmnode.RMNodeImpl: Processing slave1:43282 of type STATUS_UPDATE
2019-06-07 08:05:43,033 DEBUG org.apache.hadoop.yarn.server.resourcemanager.rmnode.RMNodeImpl: Processing slave1:43282 of type STATUS_UPDATE
2019-06-07 08:05:43,033 DEBUG org.apache.hadoop.yarn.server.resourcemanager.scheduler.capacity.CapacityScheduler: nodeUpdate: slave1:43282 clusterResources: <memory:8192, vCores:2>
2019-06-07 08:05:43,033 DEBUG org.apache.hadoop.yarn.server.resourcemanager.scheduler.capacity.CapacityScheduler: nodeUpdate: slave1:43282 clusterResources: <memory:8192, vCores:2>
2019-06-07 08:05:43,033 DEBUG org.apache.hadoop.yarn.server.resourcemanager.scheduler.capacity.CapacityScheduler: Node being looked for scheduling slave1:43282 availableResource: <memory:4096, vCores:1>
2019-06-07 08:05:43,033 DEBUG org.apache.hadoop.yarn.server.resourcemanager.scheduler.capacity.CapacityScheduler: Node being looked for scheduling slave1:43282 availableResource: <memory:4096, vCores:1>
2019-06-07 08:05:43,033 DEBUG org.apache.hadoop.yarn.server.resourcemanager.scheduler.capacity.CapacityScheduler: Trying to schedule on node: slave1, available: <memory:4096, vCores:1>
2019-06-07 08:05:43,033 DEBUG org.apache.hadoop.yarn.server.resourcemanager.scheduler.capacity.CapacityScheduler: Trying to schedule on node: slave1, available: <memory:4096, vCores:1>
2019-06-07 08:05:43,033 DEBUG org.apache.hadoop.yarn.server.resourcemanager.scheduler.capacity.ParentQueue: Skip this queue=root, because it doesn't need more resource, schedulingMode=RESPECT_PARTITION_EXCLUSIVITY node-partition=
2019-06-07 08:05:43,033 DEBUG org.apache.hadoop.yarn.server.resourcemanager.scheduler.capacity.ParentQueue: Skip this queue=root, because it doesn't need more resource, schedulingMode=RESPECT_PARTITION_EXCLUSIVITY node-partition=
2019-06-07 08:05:43,512 DEBUG org.apache.hadoop.yarn.server.resourcemanager.rmnode.RMNodeImpl: Processing slave2:37804 of type STATUS_UPDATE
2019-06-07 08:05:43,512 DEBUG org.apache.hadoop.yarn.server.resourcemanager.rmnode.RMNodeImpl: Processing slave2:37804 of type STATUS_UPDATE
2019-06-07 08:05:43,512 DEBUG org.apache.hadoop.yarn.server.resourcemanager.scheduler.capacity.CapacityScheduler: nodeUpdate: slave2:37804 clusterResources: <memory:8192, vCores:2>
2019-06-07 08:05:43,512 DEBUG org.apache.hadoop.yarn.server.resourcemanager.scheduler.capacity.CapacityScheduler: nodeUpdate: slave2:37804 clusterResources: <memory:8192, vCores:2>
2019-06-07 08:05:43,512 DEBUG org.apache.hadoop.yarn.server.resourcemanager.scheduler.capacity.CapacityScheduler: Node being looked for scheduling slave2:37804 availableResource: <memory:4096, vCores:1>
2019-06-07 08:05:43,512 DEBUG org.apache.hadoop.yarn.server.resourcemanager.scheduler.capacity.CapacityScheduler: Node being looked for scheduling slave2:37804 availableResource: <memory:4096, vCores:1>
2019-06-07 08:05:43,512 DEBUG org.apache.hadoop.yarn.server.resourcemanager.scheduler.capacity.CapacityScheduler: Trying to schedule on node: slave2, available: <memory:4096, vCores:1>
2019-06-07 08:05:43,512 DEBUG org.apache.hadoop.yarn.server.resourcemanager.scheduler.capacity.CapacityScheduler: Trying to schedule on node: slave2, available: <memory:4096, vCores:1>
2019-06-07 08:05:43,512 DEBUG org.apache.hadoop.yarn.server.resourcemanager.scheduler.capacity.ParentQueue: Skip this queue=root, because it doesn't need more resource, schedulingMode=RESPECT_PARTITION_EXCLUSIVITY node-partition=
2019-06-07 08:05:43,512 DEBUG org.apache.hadoop.yarn.server.resourcemanager.scheduler.capacity.ParentQueue: Skip this queue=root, because it doesn't need more resource, schedulingMode=RESPECT_PARTITION_EXCLUSIVITY node-partition=
2019-06-07 08:05:44,035 DEBUG org.apache.hadoop.yarn.server.resourcemanager.rmnode.RMNodeImpl: Processing slave1:43282 of type STATUS_UPDATE
2019-06-07 08:05:44,035 DEBUG org.apache.hadoop.yarn.server.resourcemanager.rmnode.RMNodeImpl: Processing slave1:43282 of type STATUS_UPDATE
2019-06-07 08:05:44,036 DEBUG org.apache.hadoop.yarn.server.resourcemanager.scheduler.capacity.CapacityScheduler: nodeUpdate: slave1:43282 clusterResources: <memory:8192, vCores:2>
2019-06-07 08:05:44,036 DEBUG org.apache.hadoop.yarn.server.resourcemanager.scheduler.capacity.CapacityScheduler: nodeUpdate: slave1:43282 clusterResources: <memory:8192, vCores:2>
2019-06-07 08:05:44,036 DEBUG org.apache.hadoop.yarn.server.resourcemanager.scheduler.capacity.CapacityScheduler: Node being looked for scheduling slave1:43282 availableResource: <memory:4096, vCores:1>
2019-06-07 08:05:44,036 DEBUG org.apache.hadoop.yarn.server.resourcemanager.scheduler.capacity.CapacityScheduler: Node being looked for scheduling slave1:43282 availableResource: <memory:4096, vCores:1>
2019-06-07 08:05:44,036 DEBUG org.apache.hadoop.yarn.server.resourcemanager.scheduler.capacity.CapacityScheduler: Trying to schedule on node: slave1, available: <memory:4096, vCores:1>
2019-06-07 08:05:44,036 DEBUG org.apache.hadoop.yarn.server.resourcemanager.scheduler.capacity.CapacityScheduler: Trying to schedule on node: slave1, available: <memory:4096, vCores:1>
2019-06-07 08:05:44,036 DEBUG org.apache.hadoop.yarn.server.resourcemanager.scheduler.capacity.ParentQueue: Skip this queue=root, because it doesn't need more resource, schedulingMode=RESPECT_PARTITION_EXCLUSIVITY node-partition=
2019-06-07 08:05:44,036 DEBUG org.apache.hadoop.yarn.server.resourcemanager.scheduler.capacity.ParentQueue: Skip this queue=root, because it doesn't need more resource, schedulingMode=RESPECT_PARTITION_EXCLUSIVITY node-partition=
2019-06-07 08:05:44,515 DEBUG org.apache.hadoop.yarn.server.resourcemanager.rmnode.RMNodeImpl: Processing slave2:37804 of type STATUS_UPDATE
2019-06-07 08:05:44,515 DEBUG org.apache.hadoop.yarn.server.resourcemanager.rmnode.RMNodeImpl: Processing slave2:37804 of type STATUS_UPDATE
2019-06-07 08:05:44,515 DEBUG org.apache.hadoop.yarn.server.resourcemanager.scheduler.capacity.CapacityScheduler: nodeUpdate: slave2:37804 clusterResources: <memory:8192, vCores:2>
2019-06-07 08:05:44,515 DEBUG org.apache.hadoop.yarn.server.resourcemanager.scheduler.capacity.CapacityScheduler: nodeUpdate: slave2:37804 clusterResources: <memory:8192, vCores:2>
2019-06-07 08:05:44,515 DEBUG org.apache.hadoop.yarn.server.resourcemanager.scheduler.capacity.CapacityScheduler: Node being looked for scheduling slave2:37804 availableResource: <memory:4096, vCores:1>
2019-06-07 08:05:44,515 DEBUG org.apache.hadoop.yarn.server.resourcemanager.scheduler.capacity.CapacityScheduler: Node being looked for scheduling slave2:37804 availableResource: <memory:4096, vCores:1>
2019-06-07 08:05:44,515 DEBUG org.apache.hadoop.yarn.server.resourcemanager.scheduler.capacity.CapacityScheduler: Trying to schedule on node: slave2, available: <memory:4096, vCores:1>
2019-06-07 08:05:44,515 DEBUG org.apache.hadoop.yarn.server.resourcemanager.scheduler.capacity.CapacityScheduler: Trying to schedule on node: slave2, available: <memory:4096, vCores:1>
2019-06-07 08:05:44,515 DEBUG org.apache.hadoop.yarn.server.resourcemanager.scheduler.capacity.ParentQueue: Skip this queue=root, because it doesn't need more resource, schedulingMode=RESPECT_PARTITION_EXCLUSIVITY node-partition=
2019-06-07 08:05:44,515 DEBUG org.apache.hadoop.yarn.server.resourcemanager.scheduler.capacity.ParentQueue: Skip this queue=root, because it doesn't need more resource, schedulingMode=RESPECT_PARTITION_EXCLUSIVITY node-partition=
2019-06-07 08:05:45,038 DEBUG org.apache.hadoop.yarn.server.resourcemanager.rmnode.RMNodeImpl: Processing slave1:43282 of type STATUS_UPDATE
2019-06-07 08:05:45,038 DEBUG org.apache.hadoop.yarn.server.resourcemanager.rmnode.RMNodeImpl: Processing slave1:43282 of type STATUS_UPDATE
2019-06-07 08:05:45,038 DEBUG org.apache.hadoop.yarn.server.resourcemanager.scheduler.capacity.CapacityScheduler: nodeUpdate: slave1:43282 clusterResources: <memory:8192, vCores:2>
2019-06-07 08:05:45,038 DEBUG org.apache.hadoop.yarn.server.resourcemanager.scheduler.capacity.CapacityScheduler: nodeUpdate: slave1:43282 clusterResources: <memory:8192, vCores:2>
2019-06-07 08:05:45,038 DEBUG org.apache.hadoop.yarn.server.resourcemanager.scheduler.capacity.CapacityScheduler: Node being looked for scheduling slave1:43282 availableResource: <memory:4096, vCores:1>
2019-06-07 08:05:45,038 DEBUG org.apache.hadoop.yarn.server.resourcemanager.scheduler.capacity.CapacityScheduler: Node being looked for scheduling slave1:43282 availableResource: <memory:4096, vCores:1>
2019-06-07 08:05:45,038 DEBUG org.apache.hadoop.yarn.server.resourcemanager.scheduler.capacity.CapacityScheduler: Trying to schedule on node: slave1, available: <memory:4096, vCores:1>
2019-06-07 08:05:45,038 DEBUG org.apache.hadoop.yarn.server.resourcemanager.scheduler.capacity.CapacityScheduler: Trying to schedule on node: slave1, available: <memory:4096, vCores:1>
2019-06-07 08:05:45,038 DEBUG org.apache.hadoop.yarn.server.resourcemanager.scheduler.capacity.ParentQueue: Skip this queue=root, because it doesn't need more resource, schedulingMode=RESPECT_PARTITION_EXCLUSIVITY node-partition=
2019-06-07 08:05:45,038 DEBUG org.apache.hadoop.yarn.server.resourcemanager.scheduler.capacity.ParentQueue: Skip this queue=root, because it doesn't need more resource, schedulingMode=RESPECT_PARTITION_EXCLUSIVITY node-partition=
2019-06-07 08:05:45,518 DEBUG org.apache.hadoop.yarn.server.resourcemanager.rmnode.RMNodeImpl: Processing slave2:37804 of type STATUS_UPDATE
2019-06-07 08:05:45,518 DEBUG org.apache.hadoop.yarn.server.resourcemanager.rmnode.RMNodeImpl: Processing slave2:37804 of type STATUS_UPDATE
2019-06-07 08:05:45,518 DEBUG org.apache.hadoop.yarn.server.resourcemanager.scheduler.capacity.CapacityScheduler: nodeUpdate: slave2:37804 clusterResources: <memory:8192, vCores:2>
2019-06-07 08:05:45,518 DEBUG org.apache.hadoop.yarn.server.resourcemanager.scheduler.capacity.CapacityScheduler: nodeUpdate: slave2:37804 clusterResources: <memory:8192, vCores:2>
2019-06-07 08:05:45,519 DEBUG org.apache.hadoop.yarn.server.resourcemanager.scheduler.capacity.CapacityScheduler: Node being looked for scheduling slave2:37804 availableResource: <memory:4096, vCores:1>
2019-06-07 08:05:45,519 DEBUG org.apache.hadoop.yarn.server.resourcemanager.scheduler.capacity.CapacityScheduler: Node being looked for scheduling slave2:37804 availableResource: <memory:4096, vCores:1>
2019-06-07 08:05:45,519 DEBUG org.apache.hadoop.yarn.server.resourcemanager.scheduler.capacity.CapacityScheduler: Trying to schedule on node: slave2, available: <memory:4096, vCores:1>
2019-06-07 08:05:45,519 DEBUG org.apache.hadoop.yarn.server.resourcemanager.scheduler.capacity.CapacityScheduler: Trying to schedule on node: slave2, available: <memory:4096, vCores:1>
2019-06-07 08:05:45,519 DEBUG org.apache.hadoop.yarn.server.resourcemanager.scheduler.capacity.ParentQueue: Skip this queue=root, because it doesn't need more resource, schedulingMode=RESPECT_PARTITION_EXCLUSIVITY node-partition=
2019-06-07 08:05:45,519 DEBUG org.apache.hadoop.yarn.server.resourcemanager.scheduler.capacity.ParentQueue: Skip this queue=root, because it doesn't need more resource, schedulingMode=RESPECT_PARTITION_EXCLUSIVITY node-partition=
2019-06-07 08:05:46,046 DEBUG org.apache.hadoop.yarn.server.resourcemanager.rmnode.RMNodeImpl: Processing slave1:43282 of type STATUS_UPDATE
2019-06-07 08:05:46,046 DEBUG org.apache.hadoop.yarn.server.resourcemanager.rmnode.RMNodeImpl: Processing slave1:43282 of type STATUS_UPDATE
2019-06-07 08:05:46,046 DEBUG org.apache.hadoop.yarn.server.resourcemanager.scheduler.capacity.CapacityScheduler: nodeUpdate: slave1:43282 clusterResources: <memory:8192, vCores:2>
2019-06-07 08:05:46,046 DEBUG org.apache.hadoop.yarn.server.resourcemanager.scheduler.capacity.CapacityScheduler: nodeUpdate: slave1:43282 clusterResources: <memory:8192, vCores:2>
2019-06-07 08:05:46,046 DEBUG org.apache.hadoop.yarn.server.resourcemanager.scheduler.capacity.CapacityScheduler: Node being looked for scheduling slave1:43282 availableResource: <memory:4096, vCores:1>
2019-06-07 08:05:46,046 DEBUG org.apache.hadoop.yarn.server.resourcemanager.scheduler.capacity.CapacityScheduler: Node being looked for scheduling slave1:43282 availableResource: <memory:4096, vCores:1>
2019-06-07 08:05:46,046 DEBUG org.apache.hadoop.yarn.server.resourcemanager.scheduler.capacity.CapacityScheduler: Trying to schedule on node: slave1, available: <memory:4096, vCores:1>
2019-06-07 08:05:46,046 DEBUG org.apache.hadoop.yarn.server.resourcemanager.scheduler.capacity.CapacityScheduler: Trying to schedule on node: slave1, available: <memory:4096, vCores:1>
2019-06-07 08:05:46,046 DEBUG org.apache.hadoop.yarn.server.resourcemanager.scheduler.capacity.ParentQueue: Skip this queue=root, because it doesn't need more resource, schedulingMode=RESPECT_PARTITION_EXCLUSIVITY node-partition=
2019-06-07 08:05:46,046 DEBUG org.apache.hadoop.yarn.server.resourcemanager.scheduler.capacity.ParentQueue: Skip this queue=root, because it doesn't need more resource, schedulingMode=RESPECT_PARTITION_EXCLUSIVITY node-partition=
2019-06-07 08:05:46,521 DEBUG org.apache.hadoop.yarn.server.resourcemanager.rmnode.RMNodeImpl: Processing slave2:37804 of type STATUS_UPDATE
2019-06-07 08:05:46,521 DEBUG org.apache.hadoop.yarn.server.resourcemanager.rmnode.RMNodeImpl: Processing slave2:37804 of type STATUS_UPDATE
2019-06-07 08:05:46,521 DEBUG org.apache.hadoop.yarn.server.resourcemanager.scheduler.capacity.CapacityScheduler: nodeUpdate: slave2:37804 clusterResources: <memory:8192, vCores:2>
2019-06-07 08:05:46,521 DEBUG org.apache.hadoop.yarn.server.resourcemanager.scheduler.capacity.CapacityScheduler: nodeUpdate: slave2:37804 clusterResources: <memory:8192, vCores:2>
2019-06-07 08:05:46,521 DEBUG org.apache.hadoop.yarn.server.resourcemanager.scheduler.capacity.CapacityScheduler: Node being looked for scheduling slave2:37804 availableResource: <memory:4096, vCores:1>
2019-06-07 08:05:46,521 DEBUG org.apache.hadoop.yarn.server.resourcemanager.scheduler.capacity.CapacityScheduler: Node being looked for scheduling slave2:37804 availableResource: <memory:4096, vCores:1>
2019-06-07 08:05:46,521 DEBUG org.apache.hadoop.yarn.server.resourcemanager.scheduler.capacity.CapacityScheduler: Trying to schedule on node: slave2, available: <memory:4096, vCores:1>
2019-06-07 08:05:46,521 DEBUG org.apache.hadoop.yarn.server.resourcemanager.scheduler.capacity.CapacityScheduler: Trying to schedule on node: slave2, available: <memory:4096, vCores:1>
2019-06-07 08:05:46,521 DEBUG org.apache.hadoop.yarn.server.resourcemanager.scheduler.capacity.ParentQueue: Skip this queue=root, because it doesn't need more resource, schedulingMode=RESPECT_PARTITION_EXCLUSIVITY node-partition=
2019-06-07 08:05:46,521 DEBUG org.apache.hadoop.yarn.server.resourcemanager.scheduler.capacity.ParentQueue: Skip this queue=root, because it doesn't need more resource, schedulingMode=RESPECT_PARTITION_EXCLUSIVITY node-partition=
2019-06-07 08:05:47,052 DEBUG org.apache.hadoop.yarn.server.resourcemanager.rmnode.RMNodeImpl: Processing slave1:43282 of type STATUS_UPDATE
2019-06-07 08:05:47,052 DEBUG org.apache.hadoop.yarn.server.resourcemanager.rmnode.RMNodeImpl: Processing slave1:43282 of type STATUS_UPDATE
2019-06-07 08:05:47,052 DEBUG org.apache.hadoop.yarn.server.resourcemanager.scheduler.capacity.CapacityScheduler: nodeUpdate: slave1:43282 clusterResources: <memory:8192, vCores:2>
2019-06-07 08:05:47,052 DEBUG org.apache.hadoop.yarn.server.resourcemanager.scheduler.capacity.CapacityScheduler: nodeUpdate: slave1:43282 clusterResources: <memory:8192, vCores:2>
2019-06-07 08:05:47,052 DEBUG org.apache.hadoop.yarn.server.resourcemanager.scheduler.capacity.CapacityScheduler: Node being looked for scheduling slave1:43282 availableResource: <memory:4096, vCores:1>
2019-06-07 08:05:47,052 DEBUG org.apache.hadoop.yarn.server.resourcemanager.scheduler.capacity.CapacityScheduler: Node being looked for scheduling slave1:43282 availableResource: <memory:4096, vCores:1>
2019-06-07 08:05:47,052 DEBUG org.apache.hadoop.yarn.server.resourcemanager.scheduler.capacity.CapacityScheduler: Trying to schedule on node: slave1, available: <memory:4096, vCores:1>
2019-06-07 08:05:47,052 DEBUG org.apache.hadoop.yarn.server.resourcemanager.scheduler.capacity.CapacityScheduler: Trying to schedule on node: slave1, available: <memory:4096, vCores:1>
2019-06-07 08:05:47,052 DEBUG org.apache.hadoop.yarn.server.resourcemanager.scheduler.capacity.ParentQueue: Skip this queue=root, because it doesn't need more resource, schedulingMode=RESPECT_PARTITION_EXCLUSIVITY node-partition=
2019-06-07 08:05:47,052 DEBUG org.apache.hadoop.yarn.server.resourcemanager.scheduler.capacity.ParentQueue: Skip this queue=root, because it doesn't need more resource, schedulingMode=RESPECT_PARTITION_EXCLUSIVITY node-partition=
2019-06-07 08:05:47,525 DEBUG org.apache.hadoop.yarn.server.resourcemanager.rmnode.RMNodeImpl: Processing slave2:37804 of type STATUS_UPDATE
2019-06-07 08:05:47,525 DEBUG org.apache.hadoop.yarn.server.resourcemanager.rmnode.RMNodeImpl: Processing slave2:37804 of type STATUS_UPDATE
2019-06-07 08:05:47,525 DEBUG org.apache.hadoop.yarn.server.resourcemanager.scheduler.capacity.CapacityScheduler: nodeUpdate: slave2:37804 clusterResources: <memory:8192, vCores:2>
2019-06-07 08:05:47,525 DEBUG org.apache.hadoop.yarn.server.resourcemanager.scheduler.capacity.CapacityScheduler: nodeUpdate: slave2:37804 clusterResources: <memory:8192, vCores:2>
2019-06-07 08:05:47,525 DEBUG org.apache.hadoop.yarn.server.resourcemanager.scheduler.capacity.CapacityScheduler: Node being looked for scheduling slave2:37804 availableResource: <memory:4096, vCores:1>
2019-06-07 08:05:47,525 DEBUG org.apache.hadoop.yarn.server.resourcemanager.scheduler.capacity.CapacityScheduler: Node being looked for scheduling slave2:37804 availableResource: <memory:4096, vCores:1>
2019-06-07 08:05:47,525 DEBUG org.apache.hadoop.yarn.server.resourcemanager.scheduler.capacity.CapacityScheduler: Trying to schedule on node: slave2, available: <memory:4096, vCores:1>
2019-06-07 08:05:47,525 DEBUG org.apache.hadoop.yarn.server.resourcemanager.scheduler.capacity.CapacityScheduler: Trying to schedule on node: slave2, available: <memory:4096, vCores:1>
2019-06-07 08:05:47,525 DEBUG org.apache.hadoop.yarn.server.resourcemanager.scheduler.capacity.ParentQueue: Skip this queue=root, because it doesn't need more resource, schedulingMode=RESPECT_PARTITION_EXCLUSIVITY node-partition=
2019-06-07 08:05:47,525 DEBUG org.apache.hadoop.yarn.server.resourcemanager.scheduler.capacity.ParentQueue: Skip this queue=root, because it doesn't need more resource, schedulingMode=RESPECT_PARTITION_EXCLUSIVITY node-partition=
2019-06-07 08:05:48,054 DEBUG org.apache.hadoop.yarn.server.resourcemanager.rmnode.RMNodeImpl: Processing slave1:43282 of type STATUS_UPDATE
2019-06-07 08:05:48,054 DEBUG org.apache.hadoop.yarn.server.resourcemanager.rmnode.RMNodeImpl: Processing slave1:43282 of type STATUS_UPDATE
2019-06-07 08:05:48,055 DEBUG org.apache.hadoop.yarn.server.resourcemanager.scheduler.capacity.CapacityScheduler: nodeUpdate: slave1:43282 clusterResources: <memory:8192, vCores:2>
2019-06-07 08:05:48,055 DEBUG org.apache.hadoop.yarn.server.resourcemanager.scheduler.capacity.CapacityScheduler: nodeUpdate: slave1:43282 clusterResources: <memory:8192, vCores:2>
2019-06-07 08:05:48,055 DEBUG org.apache.hadoop.yarn.server.resourcemanager.scheduler.capacity.CapacityScheduler: Node being looked for scheduling slave1:43282 availableResource: <memory:4096, vCores:1>
2019-06-07 08:05:48,055 DEBUG org.apache.hadoop.yarn.server.resourcemanager.scheduler.capacity.CapacityScheduler: Node being looked for scheduling slave1:43282 availableResource: <memory:4096, vCores:1>
2019-06-07 08:05:48,055 DEBUG org.apache.hadoop.yarn.server.resourcemanager.scheduler.capacity.CapacityScheduler: Trying to schedule on node: slave1, available: <memory:4096, vCores:1>
2019-06-07 08:05:48,055 DEBUG org.apache.hadoop.yarn.server.resourcemanager.scheduler.capacity.CapacityScheduler: Trying to schedule on node: slave1, available: <memory:4096, vCores:1>
2019-06-07 08:05:48,055 DEBUG org.apache.hadoop.yarn.server.resourcemanager.scheduler.capacity.ParentQueue: Skip this queue=root, because it doesn't need more resource, schedulingMode=RESPECT_PARTITION_EXCLUSIVITY node-partition=
2019-06-07 08:05:48,055 DEBUG org.apache.hadoop.yarn.server.resourcemanager.scheduler.capacity.ParentQueue: Skip this queue=root, because it doesn't need more resource, schedulingMode=RESPECT_PARTITION_EXCLUSIVITY node-partition=
2019-06-07 08:05:48,527 DEBUG org.apache.hadoop.yarn.server.resourcemanager.rmnode.RMNodeImpl: Processing slave2:37804 of type STATUS_UPDATE
2019-06-07 08:05:48,527 DEBUG org.apache.hadoop.yarn.server.resourcemanager.rmnode.RMNodeImpl: Processing slave2:37804 of type STATUS_UPDATE
2019-06-07 08:05:48,527 DEBUG org.apache.hadoop.yarn.server.resourcemanager.scheduler.capacity.CapacityScheduler: nodeUpdate: slave2:37804 clusterResources: <memory:8192, vCores:2>
2019-06-07 08:05:48,527 DEBUG org.apache.hadoop.yarn.server.resourcemanager.scheduler.capacity.CapacityScheduler: nodeUpdate: slave2:37804 clusterResources: <memory:8192, vCores:2>
2019-06-07 08:05:48,527 DEBUG org.apache.hadoop.yarn.server.resourcemanager.scheduler.capacity.CapacityScheduler: Node being looked for scheduling slave2:37804 availableResource: <memory:4096, vCores:1>
2019-06-07 08:05:48,527 DEBUG org.apache.hadoop.yarn.server.resourcemanager.scheduler.capacity.CapacityScheduler: Node being looked for scheduling slave2:37804 availableResource: <memory:4096, vCores:1>
2019-06-07 08:05:48,527 DEBUG org.apache.hadoop.yarn.server.resourcemanager.scheduler.capacity.CapacityScheduler: Trying to schedule on node: slave2, available: <memory:4096, vCores:1>
2019-06-07 08:05:48,527 DEBUG org.apache.hadoop.yarn.server.resourcemanager.scheduler.capacity.CapacityScheduler: Trying to schedule on node: slave2, available: <memory:4096, vCores:1>
2019-06-07 08:05:48,527 DEBUG org.apache.hadoop.yarn.server.resourcemanager.scheduler.capacity.ParentQueue: Skip this queue=root, because it doesn't need more resource, schedulingMode=RESPECT_PARTITION_EXCLUSIVITY node-partition=
2019-06-07 08:05:48,527 DEBUG org.apache.hadoop.yarn.server.resourcemanager.scheduler.capacity.ParentQueue: Skip this queue=root, because it doesn't need more resource, schedulingMode=RESPECT_PARTITION_EXCLUSIVITY node-partition=
2019-06-07 08:05:49,057 DEBUG org.apache.hadoop.yarn.server.resourcemanager.rmnode.RMNodeImpl: Processing slave1:43282 of type STATUS_UPDATE
2019-06-07 08:05:49,057 DEBUG org.apache.hadoop.yarn.server.resourcemanager.rmnode.RMNodeImpl: Processing slave1:43282 of type STATUS_UPDATE
2019-06-07 08:05:49,058 DEBUG org.apache.hadoop.yarn.server.resourcemanager.scheduler.capacity.CapacityScheduler: nodeUpdate: slave1:43282 clusterResources: <memory:8192, vCores:2>
2019-06-07 08:05:49,058 DEBUG org.apache.hadoop.yarn.server.resourcemanager.scheduler.capacity.CapacityScheduler: nodeUpdate: slave1:43282 clusterResources: <memory:8192, vCores:2>
2019-06-07 08:05:49,058 DEBUG org.apache.hadoop.yarn.server.resourcemanager.scheduler.capacity.CapacityScheduler: Node being looked for scheduling slave1:43282 availableResource: <memory:4096, vCores:1>
2019-06-07 08:05:49,058 DEBUG org.apache.hadoop.yarn.server.resourcemanager.scheduler.capacity.CapacityScheduler: Node being looked for scheduling slave1:43282 availableResource: <memory:4096, vCores:1>
2019-06-07 08:05:49,058 DEBUG org.apache.hadoop.yarn.server.resourcemanager.scheduler.capacity.CapacityScheduler: Trying to schedule on node: slave1, available: <memory:4096, vCores:1>
2019-06-07 08:05:49,058 DEBUG org.apache.hadoop.yarn.server.resourcemanager.scheduler.capacity.CapacityScheduler: Trying to schedule on node: slave1, available: <memory:4096, vCores:1>
2019-06-07 08:05:49,058 DEBUG org.apache.hadoop.yarn.server.resourcemanager.scheduler.capacity.ParentQueue: Skip this queue=root, because it doesn't need more resource, schedulingMode=RESPECT_PARTITION_EXCLUSIVITY node-partition=
2019-06-07 08:05:49,058 DEBUG org.apache.hadoop.yarn.server.resourcemanager.scheduler.capacity.ParentQueue: Skip this queue=root, because it doesn't need more resource, schedulingMode=RESPECT_PARTITION_EXCLUSIVITY node-partition=
2019-06-07 08:05:49,531 DEBUG org.apache.hadoop.yarn.server.resourcemanager.rmnode.RMNodeImpl: Processing slave2:37804 of type STATUS_UPDATE
2019-06-07 08:05:49,531 DEBUG org.apache.hadoop.yarn.server.resourcemanager.rmnode.RMNodeImpl: Processing slave2:37804 of type STATUS_UPDATE
2019-06-07 08:05:49,531 DEBUG org.apache.hadoop.yarn.server.resourcemanager.scheduler.capacity.CapacityScheduler: nodeUpdate: slave2:37804 clusterResources: <memory:8192, vCores:2>
2019-06-07 08:05:49,531 DEBUG org.apache.hadoop.yarn.server.resourcemanager.scheduler.capacity.CapacityScheduler: nodeUpdate: slave2:37804 clusterResources: <memory:8192, vCores:2>
2019-06-07 08:05:49,531 DEBUG org.apache.hadoop.yarn.server.resourcemanager.scheduler.capacity.CapacityScheduler: Node being looked for scheduling slave2:37804 availableResource: <memory:4096, vCores:1>
2019-06-07 08:05:49,531 DEBUG org.apache.hadoop.yarn.server.resourcemanager.scheduler.capacity.CapacityScheduler: Node being looked for scheduling slave2:37804 availableResource: <memory:4096, vCores:1>
2019-06-07 08:05:49,531 DEBUG org.apache.hadoop.yarn.server.resourcemanager.scheduler.capacity.CapacityScheduler: Trying to schedule on node: slave2, available: <memory:4096, vCores:1>
